File: Data/KMK242S/ZFCFC/KMK242S_ZFCFC.dat
[Header]
; MPMS3 Data File (default extension .dat)
; Copyright (c) 2007, Quantum Design, Inc. All rights reserved.
TITLE,
FILEOPENTIME,3870533346.2059,08/24/2022,8:09 pm
BYAPP,MPMS3 w/ AC,1.0,1.1
INFO,MPMS3 Measurement Release 1.1.16 Build 424, MultiVu Release 2.3.4.19,APPNAME
INFO,Linear Motor Servo Controller,MOTOR_MODULE_NAME
INFO,3101-100 J0,MOTOR_HW_VERSION
INFO,MMC721,MOTOR_SERIAL_NUMBER
INFO,01.04.28,MOTOR_SOFTWARE_VERSION
INFO,Quantum Design Squid Module,SQUID_MODULE_NAME
INFO,3101-501 B0,SQUID_HW_VERSION
INFO,SQM195,SQUID_SERIAL_NUMBER
INFO,01.03.04,SQUID_SOFTWARE_VERSION
INFO,SQUID AC,AC_MODULE_NAME
INFO,3101-401 f1,AC_HW_VERSION
INFO,SAC107,AC_SERIAL_NUMBER
INFO,SQUID AC 00.95.07,AC_SOFTWARE_VERSION
INFO,TCI166,COIL_SERIAL_NUMBER
INFO,0,MOMENT_UNITS
INFO,KMK242S,SAMPLE_MATERIAL
INFO,,SAMPLE_COMMENT
INFO,1.9,SAMPLE_MASS
INFO,,SAMPLE_VOLUME
INFO,,SAMPLE_MOLECULAR_WEIGHT
INFO,,SAMPLE_SIZE
INFO,,SAMPLE_SHAPE
INFO,Straw,SAMPLE_HOLDER
INFO,Standard,SAMPLE_HOLDER_DETAIL
INFO,66.09,SAMPLE_OFFSET
DATATYPE,COMMENT,1
DATATYPE,TIME,2
STARTUPAXIS,X,2
STARTUPAXIS,Y1,5
FIELDGROUP, VSM,2,3,4,5,6,8,9,10,11,14,15
FIELDGROUP, DC, 2,3,4,14,56,57,58,59,60,61,62,63,64,65,66,67,68,69
FIELDGROUP, AC, 2,3,4,11,16,17,18,19,20,21,22,23,24,25,26,27,28,29,30
STARTUPGROUP, All
[Data]
Comment,Time Stamp (sec),Temperature (K),Magnetic Field (Oe),Moment (emu),M. Std. Err. (emu),Transport Action,Averaging Time (sec),Frequency (Hz),Peak Amplitude (mm),Center Position (mm),Lockin Signal' (V),Lockin Signal (V),Range,M. Quad. Signal (emu),AC Moment (emu),AC M. Std Err. (emu),AC Phase (deg),AC Phase Std. Err. (deg),AC Susceptibility (emu/Oe),AC Suscept. Std Err. (emu/Oe),AC X' (emu/Oe),AC X' Std Err. (emu/Oe),AC X'' (emu/Oe),AC X'' Std Err. (emu/Oe),AC Drive (Oe),AC Frequency (Hz),AC Averaging Time (sec),AC Cycles,AC Range,AC Measure Type,AC Signal' (V),AC Signal'' (V),AC Trim Coil Ratio,AC Trim Coil Phase,Min. Temperature (K),Max. Temperature (K),Min. Field (Oe),Max. Field (Oe),Mass (grams),Motor Lag (deg),Pressure (Torr),Measure Count,Measurement Number,SQUID Status (code),Motor Status (code),Measure Status (code),Motor Current (amps),Motor Temp. (C),Temp. Status (code),Field Status (code),Chamber Status (code),Chamber Temp (K),Redirection State,Evercool Status,Average Temp (K),Rotation Angle (deg),Rotator state,DC Moment Fixed Ctr (emu),DC Moment Err Fixed Ctr (emu),DC Moment Free Ctr (emu),DC Moment Err Free Ctr (emu),DC Fixed Fit,DC Free Fit,DC Calculated Center (mm),DC Calculated Center Err (mm),DC Scan Length (mm),DC Scan Time (s),DC Number of Points,DC Squid Drift,DC Min V (V),DC Max V (V),DC Scans per Measure,Map 01,Map 02,Map 03,Map 04,Map 05,Map 06,Map 07,Map 08,Map 09,Map 10,Map 11,Map 12,Map 13,Map 14,Map 15,Map 16
,3870534571.8451,5.00217628479004,100.060424804688,,,6,,,,32.7238930119957,,,10,,,,,,,,,,,,,,,,,,,,,,4.99782228469849,5.00204467773438,100.060424804688,100.060424804688,,,3.41630530357361,,1,0,0,0,0.0145721435546875,31.2805480957031,1,1,1,5.00237607955933,0,4232058688,5.00008430480957,,,0.000319900217498457,1.58917180656288E-5,0.000320979197800451,1.58923974454438E-5,0.917407631874084,0.986001074314117,32.4129371643066,0,35,4,200,5.7394034229219E-5,-0.105255030095577,0.0501189269125462,1,,,,,,,,,,,,,,,,
,3870534637.3484,9.38486099243164,100.060424804688,,,6,,,,32.7238930119957,,,10,,,,,,,,,,,,,,,,,,,,,,9.00840663909912,9.71422672271729,100.060424804688,100.060424804688,,,4.17262315750122,,1,0,0,0,0.0145721435546875,31.2805480957031,6,1,1,9.76131534576416,0,4232058752,9.3572699546814,,,0.000342352570637558,1.70067846875323E-5,0.000343500352470959,1.700764265299E-5,0.917620122432709,0.985289454460144,32.4142608642578,0.0546048656105995,35,4,200,9.53114722506143E-5,-0.110244795680046,0.0565534718334675,1,,,,,,,,,,,,,,,,
,3870534704.50778,14.6704306602478,100.060424804688,,,6,,,,32.728931825031,,,10,,,,,,,,,,,,,,,,,,,,,,14.2914686203003,15.0206356048584,100.060424804688,100.060424804688,,,4.61990165710449,,1,0,0,0,0.0145721435546875,30.7917900085449,6,1,1,15.0493927001953,0,4232058752,14.6522485733032,,,0.000385486032046978,1.91504635759499E-5,0.000386796855287839,1.91514084102812E-5,0.917012393474579,0.985165238380432,32.4170379638672,INF,35,4,200,7.39512906875461E-5,-0.123525239527226,0.064383752644062,1,,,,,,,,,,,,,,,,
,3870534763.34841,19.4321050643921,100.060424804688,,,6,,,,32.728931825031,,,10,,,,,,,,,,,,,,,,,,,,,,19.0514659881592,19.7795658111572,100.060424804688,100.060424804688,,,4.83684206008911,,1,0,0,0,0.0145721435546875,30.3030319213867,2,1,1,19.812744140625,0,4232058656,19.4121562957764,,,0.00043179485182821,2.14491604035512E-5,0.00043322479874641,2.14501157650232E-5,0.918056726455688,0.98536866903305,32.4209365844727,0,35,4,200,4.62276111647952E-5,-0.140368416905403,0.0700429677963257,1,,,,,,,,,,,,,,,,
,3870534830.98155,24.8149147033691,100.060424804688,,,6,,,,32.7343975905918,,,10,,,,,,,,,,,,,,,,,,,,,,24.5133514404297,25.1507606506348,100.060424804688,100.060424804688,,,5.9002799987793,,1,0,0,0,0.0145721435546875,30.7917900085449,2,1,1,25.1950988769531,0,4232058784,24.8318386077881,,,0.000487822674411067,2.42320415303261E-5,0.000489439282323502,2.42333378348043E-5,0.918192982673645,0.985683619976044,32.4267082214355,INF,35,4,200,5.34624668944161E-5,-0.161628246307373,0.0759462937712669,1,,,,,,,,,,,,,,,,
,3870534890.01131,29.5472297668457,100.060424804688,,,6,,,,32.7343975905918,,,10,,,,,,,,,,,,,,,,,,,,,,29.1417827606201,29.9270324707031,100.060424804688,100.060424804688,,,6.01877403259277,,1,0,0,0,0.0145721435546875,31.2805480957031,2,1,1,29.9526767730713,0,4232058848,29.5624282836914,,,0.000537253740160894,2.66836425689481E-5,0.000538955493161324,2.66849039288837E-5,0.919955611228943,0.985955536365509,32.4333763122559,5.25329065322876,35,4,200,5.91858224652242E-5,-0.180447682738304,0.0810074433684349,1,,,,,,,,,,,,,,,,
,3870534957.16426,34.9243125915527,100.060424804688,,,6,,,,32.7399216632823,,,10,,,,,,,,,,,,,,,,,,,,,,34.5588150024414,35.270824432373,100.060424804688,100.060424804688,,,6.14987468719482,,1,0,0,0,0.0145721435546875,30.7917900085449,2,1,1,35.2898101806641,0,4232058624,34.9036994934082,,,0.00059347863180978,2.94739596676505E-5,0.000595316234326424,2.94753524086997E-5,0.920883357524872,0.986196994781494,32.4423065185547,0,35,4,200,5.01845934195444E-5,-0.201689898967743,0.0869841501116753,1,,,,,,,,,,,,,,,,
,3870535024.50417,40.3016471862793,100.060424804688,,,6,,,,32.7451880229517,,,10,,,,,,,,,,,,,,,,,,,,,,39.9182014465332,40.6503067016602,100.060424804688,100.060424804688,,,6.18630695343018,,1,0,0,0,0.0145721435546875,30.7917900085449,2,1,1,40.6850929260254,0,4232058656,40.2898315429687,,,0.000650410579068977,3.22979968589071E-5,0.000652351959295349,3.22992170707033E-5,0.922207951545715,0.986409187316895,32.4525680541992,7.50985191189102E-6,35,4,200,6.95979979354888E-5,-0.222923263907433,0.0932457372546196,1,,,,,,,,,,,,,,,,
,3870535091.60076,45.67626953125,100.060424804688,,,6,,,,32.7505432453547,,,10,,,,,,,,,,,,,,,,,,,,,,45.3311805725098,46.0213584899902,100.060424804688,100.060424804688,,,6.27992868423462,,1,0,0,0,0.0145721435546875,30.7917900085449,2,1,1,46.0962982177734,0,4232058688,45.6952030181885,,,0.00070729931001677,3.51185358055164E-5,0.000709324123345113,3.51199482753281E-5,0.923839569091797,0.986567854881287,32.4641532897949,5.25453042984009,35,4,200,5.53786485397723E-5,-0.243935942649841,0.0997491851449013,1,,,,,,,,,,,,,,,,
,3870535158.81702,51.1290397644043,100.060424804688,,,6,,,,32.7557038641232,,,10,,,,,,,,,,,,,,,,,,,,,,50.7265968322754,51.4762954711914,100.060424804688,100.060424804688,,,6.33567571640015,,1,0,0,0,0.0145721435546875,30.7917900085449,2,1,1,51.5314826965332,0,4232058720,51.1012229919434,,,0.000763725428096589,3.79146426356796E-5,0.000765803816044515,3.7916274639875E-5,0.925771415233612,0.986740231513977,32.4767150878906,0,35,4,200,7.73929350543767E-5,-0.264538258314133,0.106351383030415,1,,,,,,,,,,,,,,,,
,3870535226.13582,56.5944194793701,100.060424804688,,,6,,,,32.7615324724081,,,10,,,,,,,,,,,,,,,,,,,,,,56.2177124023438,56.9548301696777,100.060424804688,100.060424804688,,,6.35192823410034,,1,0,0,0,0.0145721435546875,30.7917900085449,2,1,1,56.9711265563965,0,4232058720,56.5842632293701,,,0.000817947470253056,4.06004168249645E-5,0.000820052416721514,4.06021479088189E-5,0.92779278755188,0.986866533756256,32.4903221130371,0,35,4,200,7.84613730502315E-5,-0.284245848655701,0.112792707979679,1,,,,,,,,,,,,,,,,
,3870535293.21606,62.0607128143311,100.060424804688,,,6,,,,32.7668265651245,,,10,,,,,,,,,,,,,,,,,,,,,,61.6703147888184,62.4028854370117,100.060424804688,100.060424804688,,,6.4080696105957,,1,0,0,0,0.0145721435546875,30.3030319213867,2,1,1,62.4511108398438,0,4232058592,62.0468036651611,,,0.000869753831747097,4.31647288987183E-5,0.000871838467660301,4.31660858259806E-5,0.930128872394562,0.987003862857819,32.5046005249023,5.25732564926147,35,4,200,7.7506534580607E-5,-0.302948027849197,0.119025856256485,1,,,,,,,,,,,,,,,,
,3870535360.58358,67.4991760253906,100.060424804688,,,6,,,,32.7725159825467,,,10,,,,,,,,,,,,,,,,,,,,,,67.0969772338867,67.8261337280273,100.060424804688,100.060424804688,,,6.43461132049561,,1,0,0,0,0.0145721435546875,30.7917900085449,2,1,1,67.9013748168945,0,4232058656,67.4741859436035,,,0.000918564022358528,4.55794931807462E-5,0.000920613115659473,4.55809153112512E-5,0.932550072669983,0.98712682723999,32.5196189880371,5.2580828666687,35,4,200,7.63995267334394E-5,-0.320608705282211,0.124855317175388,1,,,,,,,,,,,,,,,,
,3870535436.071,73.6442565917969,100.060424804688,,,6,,,,32.7827866070617,,,10,,,,,,,,,,,,,,,,,,,,,,73.2598648071289,73.9755706787109,100.060424804688,100.060424804688,,,6.42337274551392,,1,0,0,0,0.0138092041015625,30.7917900085449,2,1,1,74.0286483764648,0,4232058784,73.6230712890625,,,0.000968853773156152,4.80687072944848E-5,0.000970888796936355,4.80700827784094E-5,0.93447881937027,0.987232863903046,32.5373229980469,0,35,4,200,7.35474313842133E-5,-0.338788837194443,0.130878895521164,1,,,,,,,,,,,,,,,,
,3870535503.40414,79.1210784912109,100.060424804688,,,6,,,,32.7883694514318,,,10,,,,,,,,,,,,,,,,,,,,,,78.7222518920898,79.468864440918,100.060424804688,100.060424804688,,,6.44287300109863,,1,0,0,0,0.0138092041015625,30.7917900085449,2,1,1,79.519905090332,0,4232058784,79.0945541381836,,,0.00100958654936977,5.00808205029207E-5,0.00101152381722377,5.00819195186222E-5,0.937209010124207,0.987338602542877,32.5534782409668,5.70556545257568,35,4,200,6.84263650327921E-5,-0.461134672164917,0.135696783661842,1,,,,,,,,,,,,,,,,
,3870535579.50273,85.3315811157227,100.060424804688,,,6,,,,32.8002494162526,,,10,,,,,,,,,,,,,,,,,,,,,,84.9972610473633,85.6920547485352,100.060424804688,100.060424804688,,,6.49274492263794,,1,0,0,0,0.0145721435546875,30.7917900085449,2,1,1,85.7430038452148,0,4232058720,85.3429811265734,,,0.00105058569365935,5.21085375532669E-5,0.00105248559751404,5.21099274239923E-5,0.939079821109772,0.987433195114136,32.5725708007812,,35,4,200,3.97059884562623E-5,-0.476106107234955,0.140533894300461,1,,,,,,,,,,,,,,,,
,3870535655.34985,91.6118927001953,100.060424804688,,,6,,,,32.8104821046881,,,10,,,,,,,,,,,,,,,,,,,,,,91.2186584472656,91.9550857543945,100.060424804688,100.060424804688,,,6.47295475006104,,1,0,0,0,0.0138092041015625,30.7917900085449,2,1,1,92.005126953125,0,4232058656,91.5854873657227,,,0.00108642520323869,5.38785629566031E-5,0.00108823033605801,5.38796297328889E-5,0.941427946090698,0.98751574754715,32.5919303894043,4.35004221799318E-6,35,4,200,3.49368092429359E-5,-0.489190667867661,0.144711568951607,1,,,,,,,,,,,,,,,,
,3870535729.34089,97.7327079772949,100.060424804688,,,6,,,,32.8211676790716,,,10,,,,,,,,,,,,,,,,,,,,,,97.5828857421875,98.0798110961914,100.060424804688,100.060424804688,,,6.49859762191772,,1,0,0,0,0.0138092041015625,30.7917900085449,2,1,1,98.1294250488281,0,4232058656,97.8296225411551,,,0.00111658575827278,5.53669251946225E-5,0.00111829402216982,5.53680565961829E-5,0.943737506866455,0.987594962120056,32.611572265625,0,35,4,200,3.05536996165756E-5,-0.500269412994385,0.148199141025543,1,,,,,,,,,,,,,,,,
,3870535804.99001,103.992698669434,100.060424804688,,,6,,,,32.832622649664,,,10,,,,,,,,,,,,,,,,,,,,,,103.603935241699,104.360870361328,100.060424804688,100.060424804688,,,6.5434398651123,,1,0,0,0,0.0138092041015625,30.7917900085449,2,1,1,104.381462097168,0,4232058656,103.982312011719,,,0.00114281913363135,5.66605383002059E-5,0.00114442065188647,5.66615727174237E-5,0.946036040782929,0.98766827583313,32.6319885253906,0,35,4,200,5.38330641575158E-5,-0.509902656078339,0.151175826787949,1,,,,,,,,,,,,,,,,
,3870535881.0993,110.281532287598,100.060424804688,,,6,,,,32.8437591705393,,,10,,,,,,,,,,,,,,,,,,,,,,109.887214660645,110.630638122559,100.060424804688,100.060424804688,,,6.58773136138916,,1,0,0,0,0.0138092041015625,30.7917900085449,2,1,1,110.675849914551,0,4232057824,110.273216247559,,,0.00116472133261475,5.77381614404392E-5,0.00116618062578454,5.77388672792344E-5,0.948751330375671,0.987749993801117,32.6537170410156,INF,35,4,200,5.57622697670013E-5,-0.517957985401154,0.153677582740784,1,,,,,,,,,,,,,,,,
,3870535966.34406,117.329872131348,100.060424804688,,,6,,,,32.8603970928081,,,10,,,,,,,,,,,,,,,,,,,,,,116.930213928223,117.712844848633,100.060424804688,100.060424804688,,,6.59143447875977,,1,0,0,0,0.0138092041015625,30.7917900085449,2,1,1,117.729530334473,0,4232058656,117.328884887695,,,0.00118426539318234,5.87006156195161E-5,0.00118562702522453,5.87016119717098E-5,0.950915992259979,0.987840116024017,32.6787872314453,3.92875838279724,35,4,200,1.53218006744282E-5,-0.525661945343018,0.0470225848257542,1,,,,,,,,,,,,,,,,
,3870536050.41282,124.308448791504,100.060424804688,,,6,,,,32.8780224319107,,,10,,,,,,,,,,,,,,,,,,,,,,123.91919708252,124.647521972656,100.060424804688,100.060424804688,,,6.58157157897949,,1,0,0,0,0.0138092041015625,31.2805480957031,2,1,1,124.697700500488,0,4232058688,124.278087615967,,,0.00119872549699783,5.94118548842627E-5,0.00119998945444494,5.94126796144673E-5,0.952840864658356,0.987896680831909,32.7039680480957,5.26437139511108,35,4,200,4.39807263319381E-5,-0.530742466449738,0.157219186425209,1,,,,,,,,,,,,,,,,
,3870536134.62685,131.262649536133,100.060424804688,,,6,,,,32.896615346312,,,10,,,,,,,,,,,,,,,,,,,,,,130.860397338867,131.632110595703,100.060424804688,100.060424804688,,,6.57507181167603,,1,0,0,0,0.0138092041015625,31.2805480957031,2,1,1,131.664901733398,0,4232058720,131.259594726563,,,0.00120869256581335,5.9900723967665E-5,0.00120986028348645,5.99013691058072E-5,0.954688429832458,0.987937271595001,32.7298278808594,INF,35,4,200,4.17741648561787E-5,-0.534746289253235,0.0494581162929535,1,,,,,,,,,,,,,,,,
,3870536219.15902,138.304916381836,100.060424804688,,,6,,,,32.9162499179802,,,10,,,,,,,,,,,,,,,,,,,,,,137.910385131836,138.668838500977,100.060424804688,100.060424804688,,,6.57520771026611,,1,0,0,0,0.0138092041015625,30.7917900085449,2,1,1,138.699447631836,0,4232058720,138.295489501953,,,0.00121440998076182,6.01793217263588E-5,0.00121548594520363,6.0179871380772E-5,0.956458628177643,0.987971067428589,32.756462097168,0,35,4,200,3.58723555109464E-5,-0.536888301372528,0.158581867814064,1,,,,,,,,,,,,,,,,
,3870536303.46014,145.268112182617,100.060424804688,,,6,,,,32.9368981003384,,,10,,,,,,,,,,,,,,,,,,,,,,144.867752075195,145.625381469727,100.060424804688,100.060424804688,,,6.59225654602051,,1,0,0,0,0.0138092041015625,30.7917900085449,2,1,1,145.668472290039,0,4232058720,145.262295532227,,,0.00121615944940186,6.02617662404695E-5,0.00121715225860279,6.02623458657677E-5,0.958105564117432,0.988004922866821,32.783618927002,INF,35,4,200,3.49576439475641E-5,-0.537752747535706,0.0498577058315277,1,,,,,,,,,,,,,,,,
,3870536387.77117,152.250205993652,100.060424804688,,,6,,,,32.958546061285,,,10,,,,,,,,,,,,,,,,,,,,,,151.845672607422,152.612045288086,100.060424804688,100.060424804688,,,6.58379030227661,,1,0,0,0,0.0145721435546875,31.2805480957031,2,1,1,152.654739379883,0,4232058752,152.232304382324,,,0.00121428640716777,6.0165115021756E-5,0.0012151954701966,6.01654836165564E-5,0.959663033485413,0.988003313541412,32.8114852905273,0.104546613991261,35,4,200,3.15326142299455E-5,-0.537311911582947,0.158035486936569,1,,,,,,,,,,,,,,,,
,3870536480.61072,160.007347106934,100.060424804688,,,6,,,,32.9862797011254,,,10,,,,,,,,,,,,,,,,,,,,,,159.621505737305,160.352569580078,100.060424804688,100.060424804688,,,6.58133888244629,,1,0,0,0,0.0138092041015625,31.2805480957031,2,1,1,160.393188476562,0,4232058688,159.987596130371,,,0.00120836182778796,5.9869331433318E-5,0.00120922147763651,5.98697012498838E-5,0.960588157176971,0.987978637218475,32.8429641723633,0,35,4,200,2.62377707258565E-5,-0.535448431968689,0.157019063830376,1,,,,,,,,,,,,,,,,
,3870536590.63308,169.134124755859,100.060424804688,,,6,,,,33.0177729413064,,,10,,,,,,,,,,,,,,,,,,,,,,168.740386962891,169.480880737305,100.060424804688,100.060424804688,,,6.62596130371094,,1,0,0,0,0.0138092041015625,31.2805480957031,2,1,1,169.527862548828,0,4232058656,169.112826538086,,,0.00119675107213444,5.92902751391098E-5,0.00119752465508061,5.92906049484687E-5,0.962245523929596,0.987952470779419,32.8811454772949,2.64148875430692E-5,35,4,200,2.25408421101747E-5,-0.531568109989166,0.155254170298576,1,,,,,,,,,,,,,,,,
,3870536700.70938,178.27075958252,100.060424804688,,,6,,,,33.0511264348449,,,10,,,,,,,,,,,,,,,,,,,,,,177.869812011719,178.607528686523,100.060424804688,100.060424804688,,,6.67612743377686,,1,0,0,0,0.0138092041015625,30.7917900085449,2,1,1,178.67170715332,0,4232058688,178.255583190918,,,0.00118068908256557,5.84915652222406E-5,0.00118139180455973,5.84918965431286E-5,0.963607966899872,0.987893402576447,32.9200782775879,0,35,4,200,-8.48278341436526E-6,-0.526089131832123,0.152932435274124,1,,,,,,,,,,,,,,,,
,3870536810.64247,187.353340148926,100.060424804688,,,6,,,,33.085911097953,,,10,,,,,,,,,,,,,,,,,,,,,,186.949188232422,187.719970703125,100.060424804688,100.060424804688,,,6.69758796691895,,1,0,0,0,0.0138092041015625,30.7917900085449,2,1,1,187.75749206543,0,4232058624,187.342175292969,,,0.00116089178089371,5.75082981222273E-5,0.00116153270625836,5.75086921099365E-5,0.964825809001923,0.987843155860901,32.9598960876465,0,35,4,200,1.83754436875461E-5,-0.519257664680481,0.150201126933098,1,,,,,,,,,,,,,,,,
,3870536921.44615,196.557716369629,100.060424804688,,,6,,,,33.122909603448,,,10,,,,,,,,,,,,,,,,,,,,,,196.170989990234,196.906997680664,100.060424804688,100.060424804688,,,6.70456790924072,,1,0,0,0,0.0138092041015625,31.2805480957031,2,1,1,196.944442749023,0,4232058656,196.544534301758,,,0.00113773137105869,5.63589479367092E-5,0.00113831588934693,5.63592483210597E-5,0.965865135192871,0.987782597541809,33.001220703125,,35,4,200,1.36257222038694E-5,-0.40250888466835,0.147289514541626,1,,,,,,,,,,,,,,,,
,3870537031.477,205.737167358398,100.060424804688,,,6,,,,33.1613858945582,,,10,,,,,,,,,,,,,,,,,,,,,,205.349197387695,206.084884643555,100.060424804688,100.060424804688,,,6.70331907272339,,1,0,0,0,0.0138092041015625,30.3030319213867,2,1,1,206.125137329102,0,4232058752,205.70710144043,,,0.00111239515831586,5.51022999568192E-5,0.00111293123753592,5.5102447395248E-5,0.966707348823547,0.987721681594849,33.0432434082031,0,35,4,200,-1.6693333236617E-5,-0.393619745969772,0.143948584794998,1,,,,,,,,,,,,,,,,
,3870537141.9038,214.864898681641,100.060424804688,,,6,,,,33.2015989653741,,,10,,,,,,,,,,,,,,,,,,,,,,214.457550048828,215.204696655273,100.060424804688,100.060424804688,,,6.69794988632202,,1,0,0,0,0.0138092041015625,30.7917900085449,2,1,1,215.272247314453,0,4232058848,214.8337890625,,,0.00108533690623945,5.37606881163777E-5,0.0010858361407984,5.3760981119246E-5,0.967431247234344,0.987653970718384,33.0865516662598,0.189824089407921,35,4,200,6.93003903506906E-6,-0.38417449593544,0.140351206064224,1,,,,,,,,,,,,,,,,
,3870537248.01843,223.676536560059,100.060424804688,,,6,,,,33.2428140633542,,,10,,,,,,,,,,,,,,,,,,,,,,223.277069091797,224.014999389648,100.060424804688,100.060424804688,,,6.70103168487549,,1,0,0,0,0.0138092041015625,31.2805480957031,2,1,1,224.07600402832,0,4232058720,223.676030476888,,,0.00105816193619904,5.24141051251067E-5,0.00105863603688272,5.24143522729481E-5,0.967737913131714,0.987553298473358,33.1291923522949,0,35,4,200,8.06108891993063E-6,-0.374618113040924,0.136795476078987,1,,,,,,,,,,,,,,,,
,3870537354.26735,232.486030578613,100.060424804688,,,6,,,,33.284591098366,,,10,,,,,,,,,,,,,,,,,,,,,,232.077819824219,232.850921630859,100.060424804688,100.060424804688,,,6.71107482910156,,1,0,0,0,0.0138092041015625,30.7917900085449,2,1,1,232.894241333008,0,4232058688,232.479591369629,,,0.00103028597654437,5.10324469720612E-5,0.00103072909000771,5.10327249736904E-5,0.968288004398346,0.987468123435974,33.1734008789063,1.21973125715158E-5,35,4,200,5.72939643461723E-6,-0.364757925271988,0.133184373378754,1,,,,,,,,,,,,,,,,
,3870537464.28711,241.632614135742,100.060424804688,,,6,,,,33.3298082029401,,,10,,,,,,,,,,,,,,,,,,,,,,241.244369506836,241.989166259766,100.060424804688,100.060424804688,,,6.75976800918579,,1,0,0,0,0.0138092041015625,30.7917900085449,2,1,1,242.020858764648,0,4232058656,241.622276306152,,,0.00100098986891366,4.95805915880649E-5,0.00100140304534772,4.95807858342371E-5,0.968756377696991,0.987386584281921,33.2206993103027,3.98812437057495,35,4,200,-1.66394875122933E-5,-0.354358702898026,0.129436865448952,1,,,,,,,,,,,,,,,,
,3870537574.75222,250.811279296875,100.060424804688,,,6,,,,33.3768962800968,,,10,,,,,,,,,,,,,,,,,,,,,,250.407379150391,251.172256469727,100.060424804688,100.060424804688,,,6.85014343261719,,1,0,0,0,0.0138092041015625,30.3030319213867,2,1,1,251.215179443359,0,4232058688,250.7875,,,0.000971407357535858,4.81144336634683E-5,0.000971788383889948,4.8114577673601E-5,0.969356775283814,0.987307727336884,33.2704315185547,2.44285929511534E-5,35,4,200,8.0431227615918E-6,-0.343793779611588,0.12567612528801,1,,,,,,,,,,,,,,,,
,3870537685.23709,260.000640869141,100.060424804688,,,6,,,,33.4261750701736,,,10,,,,,,,,,,,,,,,,,,,,,,259.595031738281,260.371307373047,100.060424804688,100.060424804688,,,6.85286378860474,,1,0,0,0,0.0138092041015625,30.7917900085449,2,1,1,260.40625,0,4232058688,259.976281738281,,,0.000941730367886866,4.66434353468412E-5,0.0009420795679157,4.66436782911562E-5,0.970099925994873,0.987219393253326,33.3230018615723,0,35,4,200,7.7395361586241E-6,-0.333234965801239,0.121931441128254,1,,,,,,,,,,,,,,,,
,3870537795.58179,269.105743408203,100.060424804688,,,6,,,,33.4770947948578,,,10,,,,,,,,,,,,,,,,,,,,,,268.718841552734,269.458801269531,100.060424804688,100.060424804688,,,6.81030511856079,,1,0,0,0,0.0138092041015625,30.7917900085449,2,1,1,269.492645263672,0,4232058688,269.090628051758,,,0.000912372310521413,4.51874608544303E-5,0.000912667270652269,4.51875064073164E-5,0.971542179584503,0.987127423286438,33.3802375793457,2.36009091167944E-5,35,4,200,5.98262568018981E-6,-0.322723954916,0.11824793368578,1,,,,,,,,,,,,,,,,
,3870537905.3662,278.248168945313,100.060424804688,,,6,,,,33.5291741760028,,,10,,,,,,,,,,,,,,,,,,,,,,277.856903076172,278.588409423828,100.060424804688,100.060424804688,,,6.8065824508667,,1,0,0,0,0.0138092041015625,30.7917900085449,2,1,1,278.639434814453,0,4232058752,278.22571105957,,,0.000883443382898934,4.37509333438637E-5,0.000883653597765855,4.37510273425017E-5,0.974726796150207,0.987062454223633,33.4463195800781,,35,4,200,-1.76454232132528E-5,-0.312394946813583,0.114567182958126,1,,,,,,,,,,,,,,,,
,3870538015.71114,287.389633178711,100.060424804688,,,6,,,,33.5836365967233,,,10,,,,,,,,,,,,,,,,,,,,,,286.998016357422,287.747314453125,100.060424804688,100.060424804688,,,6.85392761230469,,1,0,0,0,0.0138092041015625,30.3030319213867,2,1,1,287.78125,0,4232058656,287.37682800293,,,0.000854717956710085,4.23235786376892E-5,0.000854822739781456,4.23235908152499E-5,0.979678988456726,0.987022399902344,33.5239562988281,1.7057288914657E-6,35,4,200,9.32660896069137E-6,-0.3021060526371,0.110971018671989,1,,,,,,,,,,,,,,,,
,3870538125.76839,296.54573059082,100.060424804688,,,6,,,,33.6394510609492,,,10,,,,,,,,,,,,,,,,,,,,,,296.1611328125,296.905883789063,100.060424804688,100.060424804688,,,7.00385236740112,,1,0,0,0,0.0138092041015625,31.2805480957031,2,1,1,296.930328369141,0,4232058656,296.533749389648,,,0.000826580871132982,4.09264497897196E-5,0.000826603666348368,4.09264270724517E-5,0.985011339187622,0.987022876739502,33.6108322143555,0,35,4,200,-1.21324328574701E-5,-0.292041659355164,0.107407785952091,1,,,,,,,,,,,,,,,,
,3870538201.50467,299.769683837891,100.060424804688,,,6,,,,33.6575688110473,,,10,,,,,,,,,,,,,,,,,,,,,,299.738861083984,299.798858642578,100.060424804688,100.060424804688,,,7.18556022644043,,1,0,0,0,0.0138092041015625,30.7917900085449,5,1,1,299.802490234375,0,4232058720,299.773065185547,,,0.000815236940868911,4.03642014011636E-5,0.000815248783312033,4.03641767061775E-5,0.985982716083527,0.987107634544373,33.6365737915039,0,35,4,200,1.84922064363491E-5,-0.288287222385406,0.105460196733475,1,,,,,,,,,,,,,,,,
,3870538279.84013,299.971130371094,100.060424804688,,,6,,,,33.6575688110473,,,10,,,,,,,,,,,,,,,,,,,,,,299.970062255859,299.976196289063,100.060424804688,100.060424804688,,,7.44564437866211,,1,0,0,0,0.0138092041015625,30.7917900085449,1,1,1,299.972198486328,0,4232058624,299.973474121094,,,0.00081406032193094,4.03055988875237E-5,0.000814065271010623,4.03055714859257E-5,0.986624121665955,0.987139284610748,33.6435394287109,5.27025127410889,35,4,200,2.72335073532304E-5,-0.287743180990219,0.105418778955936,1,,,,,,,,,,,,,,,,
,3870538379.63742,293.606246948242,100.060424804688,,,6,,,,33.6219020940155,,,10,,,,,,,,,,,,,,,,,,,,,,293.223815917969,294.061889648438,100.060424804688,100.060424804688,,,7.81969404220581,,1,0,0,0,0.0138092041015625,30.3030319213867,2,1,1,293.150604248047,0,4232058304,293.643621826172,,,0.000833804872534173,4.12829761432939E-5,0.000833809083121963,4.12829653606995E-5,0.987000584602356,0.987415671348572,33.6094627380371,INF,35,4,200,8.0556477769278E-5,-0.294396668672562,0.108496896922588,1,,,,,,,,,,,,,,,,
,3870538490.08229,284.439834594727,100.060424804688,,,6,,,,33.5738635275453,,,10,,,,,,,,,,,,,,,,,,,,,,284.089263916016,284.833251953125,100.060424804688,100.060424804688,,,7.65193128585815,,1,0,0,0,0.0138092041015625,30.7917900085449,2,1,1,284.046417236328,0,4232058624,284.477227783203,,,0.000868302228116155,4.29910595562269E-5,0.000868312598386051,4.29910491749643E-5,0.986903011798859,0.987868845462799,33.5550231933594,8.67819107952528E-6,35,4,200,5.74162768316455E-5,-0.306676238775253,0.112649723887444,1,,,,,,,,,,,,,,,,
,3870538600.0247,275.482192993164,100.060424804688,,,6,,,,33.5279510574569,,,10,,,,,,,,,,,,,,,,,,,,,,275.119720458984,275.866149902344,100.060424804688,100.060424804688,,,7.48953628540039,,1,0,0,0,0.0138092041015625,30.7917900085449,2,1,1,275.098236083984,0,4232058560,275.504193115234,,,0.00089579731044334,4.43561548230675E-5,0.000895883538097059,4.43561335587467E-5,0.981512308120728,0.987819075584412,33.4748649597168,1.3672586192115E-6,35,4,200,6.39910067548044E-5,-0.316886603832245,0.115780629217625,1,,,,,,,,,,,,,,,,
,3870538710.24737,266.249603271484,100.060424804688,,,6,,,,33.4829650452641,,,10,,,,,,,,,,,,,,,,,,,,,,265.903839111328,266.6533203125,100.060424804688,100.060424804688,,,7.38096904754639,,1,0,0,0,0.0138092041015625,30.7917900085449,2,1,1,265.845886230469,0,4232058592,266.293307495117,,,0.000925611949199073,4.58369678545702E-5,0.000925793022356291,4.58370352452482E-5,0.976797759532929,0.987744152545929,33.4077644348145,5.26919412612915,35,4,200,6.33427043794654E-5,-0.327390551567078,0.119724452495575,1,,,,,,,,,,,,,,,,
,3870538820.52409,257.129013061523,100.060424804688,,,6,,,,33.4407001341866,,,10,,,,,,,,,,,,,,,,,,,,,,256.766937255859,257.532073974609,100.060424804688,100.060424804688,,,7.29024314880371,,1,0,0,0,0.0138092041015625,31.2805480957031,2,1,1,256.725952148438,0,4232058720,257.155642700195,,,0.000955360858930073,4.73140253192243E-5,0.000955626771078263,4.73140808641107E-5,0.973512291908264,0.987851560115814,33.3508377075195,2.02110531972721E-5,35,4,200,4.52286149084102E-5,-0.337845295667648,0.123606093227863,1,,,,,,,,,,,,,,,,
,3870538930.79074,247.985710144043,100.060424804688,,,6,,,,33.4006830741107,,,10,,,,,,,,,,,,,,,,,,,,,,247.591949462891,248.396347045898,100.060424804688,100.060424804688,,,7.23165512084961,,1,0,0,0,0.0138092041015625,30.7917900085449,2,1,1,247.575073242187,0,4232058592,248.004318237305,,,0.000985156737095049,4.87929281004956E-5,0.000985500633756448,4.87930332363613E-5,0.971074342727661,0.988028883934021,33.3001518249512,0,35,4,200,3.42409184668213E-5,-0.348375767469406,0.127414599061012,1,,,,,,,,,,,,,,,,
,3870539040.66659,238.77555847168,100.060424804688,,,6,,,,33.3618529883436,,,10,,,,,,,,,,,,,,,,,,,,,,238.397506713867,239.174285888672,100.060424804688,100.060424804688,,,7.16982460021973,,1,0,0,0,0.0138092041015625,31.2805480957031,2,1,1,238.376831054687,0,4232058688,238.799142456055,,,0.00101529923826332,5.02890366437726E-5,0.00101572131224042,5.02892055888523E-5,0.968954801559448,0.988179504871368,33.2522430419922,0,35,4,200,6.13472002441995E-5,-0.359103739261627,0.13134877383709,1,,,,,,,,,,,,,,,,
,3870539151.07666,229.60506439209,100.060424804688,,,6,,,,33.3242994373049,,,10,,,,,,,,,,,,,,,,,,,,,,229.248306274414,229.94677734375,100.060424804688,100.060424804688,,,7.10825681686401,,1,0,0,0,0.0138092041015625,31.2805480957031,2,1,1,229.197692871094,0,4232058592,229.601340399848,,,0.00104515958295553,5.17711505055474E-5,0.00104565913121916,5.17713774622568E-5,0.967095613479614,0.988323330879211,33.2068252563477,0,35,4,200,6.59709039609879E-5,-0.369597911834717,0.135325908660889,1,,,,,,,,,,,,,,,,
,3870539261.22465,220.453773498535,100.060424804688,,,6,,,,33.2883094343468,,,10,,,,,,,,,,,,,,,,,,,,,,220.096649169922,220.862091064453,100.060424804688,100.060424804688,,,7.05632638931274,,1,0,0,0,0.0138092041015625,30.7917900085449,2,1,1,220.045455932617,0,4232058688,220.47926940918,,,0.00107466611714168,5.32363038651975E-5,0.00107525580998469,5.32366237060783E-5,0.965112745761871,0.988479316234589,33.1625595092773,,35,4,200,6.51618902338669E-5,-0.379691421985626,0.139492318034172,1,,,,,,,,,,,,,,,,
,3870539371.10016,211.164649963379,100.060424804688,,,6,,,,33.2527733569094,,,10,,,,,,,,,,,,,,,,,,,,,,210.807037353516,211.570190429687,100.060424804688,100.060424804688,,,7.02105903625488,,1,0,0,0,0.0138092041015625,30.7917900085449,2,1,1,210.75910949707,0,4232058592,211.193634033203,,,0.00110435645796489,5.47109765287114E-5,0.00110504744999658,5.4711529688315E-5,0.963140487670898,0.988652765750885,33.1188278198242,0,35,4,200,7.85516531323083E-5,-0.389658242464066,0.143800869584084,1,,,,,,,,,,,,,,,,
,3870539481.09161,202.031616210938,100.060424804688,,,6,,,,33.2188551604428,,,10,,,,,,,,,,,,,,,,,,,,,,201.649749755859,202.450286865234,100.060424804688,100.060424804688,,,6.98097276687622,,1,0,0,0,0.0138092041015625,30.3030319213867,2,1,1,201.612945556641,0,4232058112,202.055346679687,,,0.00113329044942852,5.61489526879624E-5,0.00113409298891555,5.61494724190813E-5,0.961005389690399,0.988844633102417,33.0761413574219,5.75118589401245,35,4,200,5.13460217916872E-5,-0.508581519126892,0.147617816925049,1,,,,,,,,,,,,,,,,
,3870539590.99391,192.901947021484,100.060424804688,,,6,,,,33.1857171742358,,,10,,,,,,,,,,,,,,,,,,,,,,192.533966064453,193.313385009766,100.060424804688,100.060424804688,,,6.94116353988647,,1,0,0,0,0.0138092041015625,30.7917900085449,2,1,1,192.490509033203,0,4232058624,192.940789794922,,,0.00116143304093486,5.75483965600132E-5,0.00116236423661904,5.75490632199106E-5,0.958785176277161,0.989028215408325,33.0339775085449,5.26617288589478,35,4,200,7.90312114986591E-5,-0.518530547618866,0.151279091835022,1,,,,,,,,,,,,,,,,
,3870539701.53922,183.621032714844,100.060424804688,,,6,,,,33.1527043766238,,,10,,,,,,,,,,,,,,,,,,,,,,183.224365234375,184.050537109375,100.060424804688,100.060424804688,,,6.89935111999512,,1,0,0,0,0.0138092041015625,30.7917900085449,2,1,1,183.191528320313,0,4232058560,183.636465454102,,,0.00118938231953393,5.89388058891151E-5,0.00119044863257726,5.89394198439686E-5,0.956573843955994,0.989221036434174,32.9920043945313,0.189913868904114,35,4,200,8.48611307446845E-5,-0.528390347957611,0.154976859688759,1,,,,,,,,,,,,,,,,
,3870539811.84537,174.432014465332,100.060424804688,,,6,,,,33.1209366158226,,,10,,,,,,,,,,,,,,,,,,,,,,174.024841308594,174.873031616211,100.060424804688,100.060424804688,,,6.86332511901855,,1,0,0,0,0.0138092041015625,30.7917900085449,2,1,1,173.990997314453,0,4232058720,174.474942016602,,,0.00121615512891912,6.02714254697612E-5,0.00121736840076329,6.02721155992507E-5,0.954371452331543,0.989380776882172,32.9513931274414,0,35,4,200,5.55857041035779E-5,-0.537892282009125,0.158475518226624,1,,,,,,,,,,,,,,,,
,3870539921.85994,165.299240112305,100.060424804688,,,6,,,,33.0898323121937,,,10,,,,,,,,,,,,,,,,,,,,,,164.926818847656,165.706192016602,100.060424804688,100.060424804688,,,6.82749557495117,,1,0,0,0,0.0138092041015625,29.8142719268799,2,1,1,164.892288208008,0,4232058720,165.330596923828,,,0.00124205892635469,6.1561493124011E-5,0.00124342850485764,6.15622797618866E-5,0.95218700170517,0.98950582742691,32.9115905761719,0,35,4,200,4.49485851277132E-5,-0.547019004821777,0.0531570948660374,1,,,,,,,,,,,,,,,,
,3870540023.34609,156.743843078613,100.060424804688,,,6,,,,33.0616062178567,,,10,,,,,,,,,,,,,,,,,,,,,,156.346878051758,157.154830932617,100.060424804688,100.060424804688,,,6.81354188919067,,1,0,0,0,0.0138092041015625,30.3030319213867,2,1,1,156.332855224609,0,4232058720,156.748057556152,,,0.0012654778366316,6.27283511909408E-5,0.00126700020819565,6.27292998743837E-5,0.950192987918854,0.989535570144653,32.8755416870117,2.43734803007101E-6,35,4,200,7.72416824474931E-5,-0.554805517196655,0.0566582567989826,1,,,,,,,,,,,,,,,,
,3870540116.87964,148.956130981445,100.060424804688,,,6,,,,33.0360792315658,,,10,,,,,,,,,,,,,,,,,,,,,,148.576644897461,149.369003295898,100.060424804688,100.060424804688,,,6.80432796478271,,1,0,0,0,0.0138092041015625,29.8142719268799,2,1,1,148.543258666992,0,4232058848,148.978457641602,,,0.00128596686578986,6.37500614957615E-5,0.00128764055747103,6.37512136181363E-5,0.948317170143127,0.989535391330719,32.8426933288574,,35,4,200,7.79524998506531E-5,-0.562172114849091,0.0592720359563827,1,,,,,,,,,,,,,,,,
,3870540201.33805,141.898986816406,100.060424804688,,,6,,,,33.0138010872218,,,10,,,,,,,,,,,,,,,,,,,,,,141.521408081055,142.306716918945,100.060424804688,100.060424804688,,,6.76853513717651,,1,0,0,0,0.0138092041015625,30.7917900085449,2,1,1,141.491256713867,0,4232058560,141.927339172363,,,0.00130337069583661,6.46188981748022E-5,0.00130518794704646,6.46199548181347E-5,0.946527123451233,0.98953366279602,32.8134269714355,5.72830057144165,35,4,200,7.99730769358575E-5,-0.568146824836731,0.0615918375551701,1,,,,,,,,,,,,,,,,
,3870540285.46511,134.927261352539,100.060424804688,,,6,,,,32.9920580818644,,,10,,,,,,,,,,,,,,,,,,,,,,134.546905517578,135.331832885742,100.060424804688,100.060424804688,,,6.70961952209473,,1,0,0,0,0.0138092041015625,30.3030319213867,2,1,1,134.522689819336,0,4232058688,134.945602416992,,,0.00131992306276507,6.54458861194311E-5,0.00132189844648139,6.54473322119105E-5,0.94474858045578,0.989481925964355,32.7847785949707,0.000159735092893243,35,4,200,8.09374178061262E-5,-0.574257731437683,0.0637919753789902,1,,,,,,,,,,,,,,,,
,3870540369.95108,127.916797637939,100.060424804688,,,6,,,,32.970737624338,,,10,,,,,,,,,,,,,,,,,,,,,,127.545913696289,128.30810546875,100.060424804688,100.060424804688,,,6.67841815948486,,1,0,0,0,0.0138092041015625,30.3030319213867,2,1,1,127.525489807129,0,4232058624,127.93765335083,,,0.00133561868148087,6.62309984932592E-5,0.0013377559882642,6.62324329281484E-5,0.942904531955719,0.989482760429382,32.7562866210937,2.95282325168955E-6,35,4,200,4.76204149890691E-5,-0.579668939113617,0.0659222304821014,1,,,,,,,,,,,,,,,,
,3870540454.39201,120.918865203857,100.060424804688,,,6,,,,32.9500310596932,,,10,,,,,,,,,,,,,,,,,,,,,,120.563438415527,121.319129943848,100.060424804688,100.060424804688,,,6.66571712493896,,1,0,0,0,0.0138092041015625,30.7917900085449,2,1,1,120.518600463867,0,4232058752,120.942860412598,,,0.00135036167204712,6.69692136529768E-5,0.0013526708452748,6.69709920976218E-5,0.941084325313568,0.989367961883545,32.7285919189453,,35,4,200,5.17954686074518E-5,-0.584896326065063,0.0679831877350807,1,,,,,,,,,,,,,,,,
,3870540539.20137,113.89380645752,100.060424804688,,,6,,,,32.9298414171168,,,10,,,,,,,,,,,,,,,,,,,,,,113.51953125,114.30883026123,100.060424804688,100.060424804688,,,6.66602468490601,,1,0,0,0,0.0138092041015625,30.7917900085449,2,1,1,113.478782653809,0,4232058624,113.913011169434,,,0.00136412998368827,6.76595343403226E-5,0.00136661155087131,6.76612123630554E-5,0.939234256744385,0.989327728748322,32.7012214660645,0.0293356720358133,35,4,200,4.59455222880933E-5,-0.58954656124115,0.069998987019062,1,,,,,,,,,,,,,,,,
,3870540623.63289,106.877376556396,100.060424804688,,,6,,,,32.9105008485834,,,10,,,,,,,,,,,,,,,,,,,,,,106.527824401855,107.292068481445,100.060424804688,100.060424804688,,,6.64508295059204,,1,0,0,0,0.0138092041015625,31.2805480957031,2,1,1,106.462684631348,0,4232058592,106.887619018555,,,0.00137695739804757,6.83036070755524E-5,0.00137962338069117,6.83055286523044E-5,0.937376439571381,0.989176630973816,32.6747741699219,0.209439978003502,35,4,200,4.96295870107133E-5,-0.594199597835541,0.0718052759766579,1,,,,,,,,,,,,,,,,
,3870540707.95191,99.7876434326172,100.060424804688,,,6,,,,32.8914775796317,,,10,,,,,,,,,,,,,,,,,,,,,,99.3983459472656,100.235496520996,100.060424804688,100.060424804688,,,6.58697032928467,,1,0,0,0,0.0138092041015625,30.7917900085449,2,1,1,99.3397903442383,0,4232058656,99.8323959350586,,,0.00138866787299833,6.88923298358344E-5,0.00139151302331892,6.88942399143258E-5,0.935597598552704,0.98912525177002,32.6488952636719,0,35,4,200,7.41307740099728E-5,-0.597871482372284,0.0737070292234421,1,,,,,,,,,,,,,,,,
,3870540792.47021,92.8067321777344,100.060424804688,,,6,,,,32.8729513213729,,,10,,,,,,,,,,,,,,,,,,,,,,92.430778503418,93.2177505493164,100.060424804688,100.060424804688,,,6.55350208282471,,1,0,0,0,0.0138092041015625,30.7917900085449,2,1,1,92.3957138061523,0,4232058688,92.8327026367187,,,0.00139914645289514,6.94210739463874E-5,0.00140219082382484,6.94229764772008E-5,0.933647155761719,0.989036619663239,32.6228828430176,,35,4,200,8.19322813185863E-5,-0.601609945297241,0.0751362144947052,1,,,,,,,,,,,,,,,,
,3870540876.99077,85.751651763916,100.060424804688,,,6,,,,32.8550196677236,,,10,,,,,,,,,,,,,,,,,,,,,,85.3875961303711,86.1752700805664,100.060424804688,100.060424804688,,,6.52604389190674,,1,0,0,0,0.0138092041015625,30.3030319213867,2,1,1,85.3280334472656,0,4232058656,85.7966583251953,,,0.00140853724392929,6.98958405279952E-5,0.00141179637834529,6.98985815212982E-5,0.93177318572998,0.988961756229401,32.5977249145508,0,35,4,200,8.12658327049576E-5,-0.604864954948425,0.0766331851482391,1,,,,,,,,,,,,,,,,
,3870540961.75667,78.6238708496094,100.060424804688,,,6,,,,32.8379003138662,,,10,,,,,,,,,,,,,,,,,,,,,,78.2543411254883,79.0292892456055,100.060424804688,100.060424804688,,,6.49787664413452,,1,0,0,0,0.0145721435546875,30.7917900085449,2,1,1,78.2184524536133,0,4232058560,78.6558471679687,,,0.00141684038989752,7.0317653181281E-5,0.00142031018943568,7.03202043677672E-5,0.929773211479187,0.988837242126465,32.5729103088379,0.111624963581562,35,4,200,6.8039953475818E-5,-0.607518136501312,0.077958919107914,1,,,,,,,,,,,,,,,,
,3870541046.36813,71.4500427246094,100.060424804688,,,6,,,,32.8216997653112,,,10,,,,,,,,,,,,,,,,,,,,,,71.0596618652344,71.8567886352539,100.060424804688,100.060424804688,,,6.45457696914673,,1,0,0,0,0.0145721435546875,30.7917900085449,2,1,1,71.0432968139648,0,4232058528,71.4773681640625,,,0.00142422934429848,7.06945902078991E-5,0.00142792230107816,7.06971929841145E-5,0.927752912044525,0.988697588443756,32.5489921569824,0,35,4,200,6.67540880385786E-5,-0.609964668750763,0.0793059468269348,1,,,,,,,,,,,,,,,,
,3870541122.04256,65.1086883544922,100.060424804688,,,6,,,,32.8113655458719,,,10,,,,,,,,,,,,,,,,,,,,,,64.7432022094727,65.5060272216797,100.060424804688,100.060424804688,,,6.3633599281311,,1,0,0,0,0.0145721435546875,30.7917900085449,2,1,1,64.7113494873047,0,4232058560,65.1238105773926,,,0.00142957634257037,7.09738890465713E-5,0.00143356488854905,7.09765720490686E-5,0.925110697746277,0.988707363605499,32.5284118652344,0,35,4,200,4.48678292741533E-5,-0.61182165145874,0.0803036987781525,1,,,,,,,,,,,,,,,,
,3870541197.98002,58.7166004180908,100.060424804688,,,6,,,,32.7981791773152,,,10,,,,,,,,,,,,,,,,,,,,,,58.3490257263184,59.1214828491211,100.060424804688,100.060424804688,,,6.30375957489014,,1,0,0,0,0.0138092041015625,30.7917900085449,2,1,1,58.3117179870605,0,4232058752,58.7429862976074,,,0.00143468370676497,7.12369962970654E-5,0.00143889102570404,7.12404281814879E-5,0.923347175121307,0.988477945327759,32.5085487365723,5.70162677764893,35,4,200,6.62448146613315E-5,-0.613406896591187,0.08134725689888,1,,,,,,,,,,,,,,,,
,3870541273.50806,52.3597545623779,100.060424804688,,,6,,,,32.7857146087236,,,10,,,,,,,,,,,,,,,,,,,,,,51.9818992614746,52.7699279785156,100.060424804688,100.060424804688,,,6.25403118133545,,1,0,0,0,0.0138092041015625,30.7917900085449,2,1,1,51.9495811462402,0,4232058624,52.3705905914307,,,0.00143878890872708,7.14503197932911E-5,0.00144319322515373,7.14535001002257E-5,0.921649277210236,0.988430082798004,32.4895210266113,0,35,4,200,5.52304700249806E-5,-0.614506721496582,0.0822113677859306,1,,,,,,,,,,,,,,,,
,3870541349.14475,45.9595050811768,100.060424804688,,,6,,,,32.7741832207055,,,10,,,,,,,,,,,,,,,,,,,,,,45.5683555603027,46.3782234191895,100.060424804688,100.060424804688,,,6.18311452865601,,1,0,0,0,0.0145721435546875,30.3030319213867,2,1,1,45.5407867431641,0,4232058656,45.9673267364502,,,0.00144233693818479,7.16358558920205E-5,0.0014469380320738,7.16389720724403E-5,0.92001074552536,0.98834103345871,32.4717216491699,0,35,4,200,4.79089248983655E-5,-0.615408062934876,0.0830887109041214,1,,,,,,,,,,,,,,,,
,3870541425.13987,39.5584926605225,100.060424804688,,,6,,,,32.7634562727196,,,10,,,,,,,,,,,,,,,,,,,,,,39.1723327636719,39.944652557373,100.060424804688,100.060424804688,,,6.0720911026001,,1,0,0,0,0.0145721435546875,30.3030319213867,2,1,1,39.1723327636719,0,4232058624,39.5570575714111,,,0.00144524929471996,7.17893639050736E-5,0.0014500600547406,7.1793623728058E-5,0.918491780757904,0.988247215747833,32.4551582336426,5.6969428062439,35,4,200,4.68485959572718E-5,-0.616089940071106,0.0840034857392311,1,,,,,,,,,,,,,,,,
,3870541500.81287,33.1581153869629,100.060424804688,,,6,,,,32.7523153358278,,,10,,,,,,,,,,,,,,,,,,,,,,32.7485694885254,33.5676612854004,100.060424804688,100.060424804688,,,5.96322011947632,,1,0,0,0,0.0145721435546875,30.3030319213867,2,1,1,32.7485694885254,0,4232058592,33.1473602294922,,,0.00144764102572493,7.19140813014757E-5,0.00145256139050322,7.19175463241702E-5,0.917498111724854,0.988170325756073,32.4402389526367,0.1903977394104,35,4,200,4.81098904856481E-5,-0.616601467132568,0.0848586186766625,1,,,,,,,,,,,,,,,,
,3870541568.08845,27.5084419250488,100.060424804688,,,6,,,,32.7466145274036,,,10,,,,,,,,,,,,,,,,,,,,,,27.1360263824463,27.9221210479736,100.060424804688,100.060424804688,,,5.85930442810059,,1,0,0,0,0.0145721435546875,30.7917900085449,2,1,1,27.094762802124,0,4232058560,27.531595993042,,,0.00144884843520073,7.19831028712946E-5,0.00145396571611038,7.19869888038812E-5,0.915997266769409,0.988254725933075,32.4286727905273,,35,4,200,5.33327911398374E-5,-0.616517841815949,0.085559070110321,1,,,,,,,,,,,,,,,,
,3870541644.06419,21.1744832992554,100.060424804688,,,6,,,,32.7361040319309,,,10,,,,,,,,,,,,,,,,,,,,,,20.8112258911133,21.5694904327393,100.060424804688,100.060424804688,,,4.94002056121826,,1,0,0,0,0.0138092041015625,30.3030319213867,2,1,1,20.7794761657715,0,4232058688,21.1952938079834,,,0.00145029576148892,7.20568312295626E-5,0.00145545320391041,7.2060742642585E-5,0.915702342987061,0.988152146339416,32.4170761108398,,35,4,200,5.47746094525792E-5,-0.616359412670136,0.086363285779953,1,,,,,,,,,,,,,,,,
,3870541711.38115,15.6093506813049,100.060424804688,,,6,,,,32.731068022811,,,10,,,,,,,,,,,,,,,,,,,,,,15.2696762084961,15.9894561767578,100.060424804688,100.060424804688,,,4.56562900543213,,1,0,0,0,0.0145721435546875,30.7917900085449,2,1,1,15.2292451858521,0,4232058848,15.6267094612122,,,0.00145074074573035,7.20841292663023E-5,0.00145599226316374,7.20874461735448E-5,0.91485607624054,0.988116919994354,32.4087982177734,0,35,4,200,2.33210703299846E-5,-0.615904092788696,0.0870558097958565,1,,,,,,,,,,,,,,,,
,3870541786.99509,9.75835227966309,100.060424804688,,,6,,,,32.7200970830087,,,10,,,,,,,,,,,,,,,,,,,,,,9.49475574493408,10.0454244613647,100.060424804688,100.060424804688,,,3.92464637756348,,1,0,0,0,0.0138092041015625,30.3030319213867,6,1,1,9.47128009796143,0,4232059296,9.77549180984497,,,0.00145086086694876,7.20828206245404E-5,0.00145597771812162,7.20867475435714E-5,0.916043341159821,0.988104999065399,32.4024238586426,0.190426513552666,35,4,200,-1.90757382370066E-5,-0.61572128534317,0.0874669253826141,1,,,,,,,,,,,,,,,,
,3870541845.87609,5.19068360328674,100.060424804688,,,6,,,,32.7200970830087,,,10,,,,,,,,,,,,,,,,,,,,,,5.00235986709595,5.37789011001587,100.060424804688,100.060424804688,,,3.34448409080505,,1,0,0,0,0.0138092041015625,30.7917900085449,2,1,1,5.00347709655762,0,4232058816,5.10408010482788,,,0.00145081203563961,7.20799557300972E-5,0.00145592602124614,7.20840585751267E-5,0.916117191314697,0.988269746303558,32.4026184082031,0,35,4,200,2.50830016739201E-5,-0.61580502986908,0.0871114432811737,1,,,,,,,,,,,,,,,,
,3870541904.71041,5.001957654953,100.060424804688,,,6,,,,32.7200970830087,,,10,,,,,,,,,,,,,,,,,,,,,,4.99818849563599,5.00194311141968,100.060424804688,100.060424804688,,,3.24306535720825,,1,0,0,0,0.0138092041015625,30.7917900085449,5,1,1,5.00198411941528,0,4232058720,5.00007510185242,,,0.00145111461050435,7.20936149984996E-5,0.00145617862556201,7.20966250568278E-5,0.916339635848999,0.988175272941589,32.4035110473633,0,35,4,200,1.32535624288721E-5,-0.615948379039764,0.0871297717094421,1,,,,,,,,,,,,,,,,
,3870541914.4483,5.00218033790588,100.060424804688,,,6,,,,32.7200970830087,,,10,,,,,,,,,,,,,,,,,,,,,,4.99801921844482,5.00198411941528,100.060424804688,100.060424804688,,,3.2438051700592,,1,0,0,0,0.0138092041015625,30.7917900085449,1,1,1,5.00237655639648,0,4232058784,5.00011410713196,,,0.00145109790095533,7.20925515149465E-5,0.00145616776928038,7.20960897018598E-5,0.91637796163559,0.988172054290771,32.4036674499512,7.10185577190714E-6,35,4,200,1.21437497000443E-5,-0.615965127944946,0.0871086046099663,1,,,,,,,,,,,,,,,,