File: Data/KMK316/ZFCFC/KMK316_ZFCFC.dat
[Header]
; MPMS3 Data File (default extension .dat)
; Copyright (c) 2007, Quantum Design, Inc. All rights reserved.
TITLE,
FILEOPENTIME,3885200059.74211,02/10/2023,2:14 pm
BYAPP,MPMS3 w/ AC,1.0,1.1
INFO,MPMS3 Measurement Release 1.1.16 Build 424, MultiVu Release 2.3.4.19,APPNAME
INFO,Linear Motor Servo Controller,MOTOR_MODULE_NAME
INFO,3101-100 J0,MOTOR_HW_VERSION
INFO,MMC721,MOTOR_SERIAL_NUMBER
INFO,01.04.28,MOTOR_SOFTWARE_VERSION
INFO,Quantum Design Squid Module,SQUID_MODULE_NAME
INFO,3101-501 B0,SQUID_HW_VERSION
INFO,SQM195,SQUID_SERIAL_NUMBER
INFO,01.03.04,SQUID_SOFTWARE_VERSION
INFO,SQUID AC,AC_MODULE_NAME
INFO,3101-401 f1,AC_HW_VERSION
INFO,SAC107,AC_SERIAL_NUMBER
INFO,SQUID AC 00.95.07,AC_SOFTWARE_VERSION
INFO,TCI166,COIL_SERIAL_NUMBER
INFO,0,MOMENT_UNITS
INFO,KMK316,SAMPLE_MATERIAL
INFO,0.7 mg KMK273S + 0.8 mg KMK245S,SAMPLE_COMMENT
INFO,1.5,SAMPLE_MASS
INFO,,SAMPLE_VOLUME
INFO,,SAMPLE_MOLECULAR_WEIGHT
INFO,,SAMPLE_SIZE
INFO,,SAMPLE_SHAPE
INFO,Standard,SAMPLE_HOLDER
INFO,Standard,SAMPLE_HOLDER_DETAIL
INFO,67.04,SAMPLE_OFFSET
DATATYPE,COMMENT,1
DATATYPE,TIME,2
STARTUPAXIS,X,2
STARTUPAXIS,Y1,5
FIELDGROUP, VSM,2,3,4,5,6,8,9,10,11,14,15
FIELDGROUP, DC, 2,3,4,14,56,57,58,59,60,61,62,63,64,65,66,67,68,69
FIELDGROUP, AC, 2,3,4,11,16,17,18,19,20,21,22,23,24,25,26,27,28,29,30
STARTUPGROUP, All
[Data]
Comment,Time Stamp (sec),Temperature (K),Magnetic Field (Oe),Moment (emu),M. Std. Err. (emu),Transport Action,Averaging Time (sec),Frequency (Hz),Peak Amplitude (mm),Center Position (mm),Lockin Signal' (V),Lockin Signal (V),Range,M. Quad. Signal (emu),AC Moment (emu),AC M. Std Err. (emu),AC Phase (deg),AC Phase Std. Err. (deg),AC Susceptibility (emu/Oe),AC Suscept. Std Err. (emu/Oe),AC X' (emu/Oe),AC X' Std Err. (emu/Oe),AC X'' (emu/Oe),AC X'' Std Err. (emu/Oe),AC Drive (Oe),AC Frequency (Hz),AC Averaging Time (sec),AC Cycles,AC Range,AC Measure Type,AC Signal' (V),AC Signal'' (V),AC Trim Coil Ratio,AC Trim Coil Phase,Min. Temperature (K),Max. Temperature (K),Min. Field (Oe),Max. Field (Oe),Mass (grams),Motor Lag (deg),Pressure (Torr),Measure Count,Measurement Number,SQUID Status (code),Motor Status (code),Measure Status (code),Motor Current (amps),Motor Temp. (C),Temp. Status (code),Field Status (code),Chamber Status (code),Chamber Temp (K),Redirection State,Evercool Status,Average Temp (K),Rotation Angle (deg),Rotator state,DC Moment Fixed Ctr (emu),DC Moment Err Fixed Ctr (emu),DC Moment Free Ctr (emu),DC Moment Err Free Ctr (emu),DC Fixed Fit,DC Free Fit,DC Calculated Center (mm),DC Calculated Center Err (mm),DC Scan Length (mm),DC Scan Time (s),DC Number of Points,DC Squid Drift,DC Min V (V),DC Max V (V),DC Scans per Measure,Map 01,Map 02,Map 03,Map 04,Map 05,Map 06,Map 07,Map 08,Map 09,Map 10,Map 11,Map 12,Map 13,Map 14,Map 15,Map 16
,3885201198.73341,5.00261688232422,100.133750915527,,,6,,,,31.3492940071624,,,10,,,,,,,,,,,,,,,,,,,,,,4.9978814125061,5.00251054763794,100.133750915527,100.133750915527,,,4.23084211349487,,1,0,0,0,0.0191497802734375,31.7693061828613,1,1,1,5.0027232170105,0,4232058752,5.00026021003723,,,0.00135259786022317,6.75917341113881E-5,0.0013547866806535,6.75930035670263E-5,0.937942862510681,0.974270403385162,31.1345596313477,0,35,4,200,0.000170725717907771,-0.500984668731689,0.157454580068588,1,,,,,,,,,,,,,,,,
,3885201284.25087,10.9306683540344,100.133750915527,,,6,,,,31.3492940071624,,,10,,,,,,,,,,,,,,,,,,,,,,10.5593366622925,11.2616376876831,100.133750915527,100.133750915527,,,5.40571880340576,,1,0,0,0,0.014801025390625,31.7693061828613,6,1,1,11.3020000457764,0,4232058656,10.9065872192383,,,0.00207399799018677,0.000103637468634914,0.00207718332744796,0.000103640626318091,0.938550412654877,0.972170114517212,31.1409912109375,0,35,4,200,0.000770704122260213,-0.869376659393311,0.148750826716423,1,,,,,,,,,,,,,,,,
,3885201362.71503,17.1975994110107,100.133750915527,,,6,,,,31.3492940071624,,,10,,,,,,,,,,,,,,,,,,,,,,16.8159732818604,17.5440635681152,100.133750915527,100.133750915527,,,5.93159198760986,,1,0,0,0,0.0186920166015625,31.7693061828613,2,1,1,17.5792255401611,0,4232058656,17.1662034988403,,,0.00240937198491823,0.000120380582953864,0.00241283229354951,0.000120381940531151,0.940672755241394,0.973962664604187,31.1466217041016,0.146158486604691,35,4,200,0.000270534015726298,-0.981359541416168,0.192478999495506,1,,,,,,,,,,,,,,,,
,3885201440.97008,23.428689956665,100.133750915527,,,6,,,,31.3492940071624,,,10,,,,,,,,,,,,,,,,,,,,,,23.0495128631592,23.78515625,100.133750915527,100.133750915527,,,6.2058367729187,,1,0,0,0,0.01983642578125,31.2805480957031,2,1,1,23.8078670501709,0,4232058656,23.4165626525879,,,0.00241096341897564,0.000120452888967581,0.00241430392972724,0.000120454799671121,0.941690742969513,0.974152684211731,31.1505756378174,0.191457077860832,35,4,200,9.27870569285005E-5,-0.983474135398865,0.190458625555038,1,,,,,,,,,,,,,,,,
,3885201519.76799,29.7195110321045,100.133750915527,,,6,,,,31.3492940071624,,,10,,,,,,,,,,,,,,,,,,,,,,29.3338279724121,30.0708656311035,100.133750915527,100.133750915527,,,6.3982982635498,,1,0,0,0,0.017852783203125,31.7693061828613,2,1,1,30.1051940917969,0,4232058656,29.7123392105103,,,0.00233163836752018,0.000116480652066541,0.0023347138573759,0.000116483508191977,0.943037688732147,0.974261164665222,31.156078338623,0,35,4,200,5.06030373799149E-5,-0.958339750766754,0.177272722125053,1,,,,,,,,,,,,,,,,
,3885201597.6204,35.9633483886719,100.133750915527,,,6,,,,31.3492940071624,,,10,,,,,,,,,,,,,,,,,,,,,,35.569034576416,36.2941474914551,100.133750915527,100.133750915527,,,6.53766107559204,,1,0,0,0,0.013885498046875,31.2805480957031,2,1,1,36.3576622009277,0,4232058624,35.9348148345947,,,0.0022380048674313,0.000111791662776692,0.00224070555705284,0.000111792908266791,0.944850921630859,0.974385619163513,31.1635818481445,0,35,4,200,3.38893951266073E-5,-0.927214741706848,0.162465408444405,1,,,,,,,,,,,,,,,,
,3885201676.15722,42.2743740081787,100.133750915527,,,6,,,,31.3492940071624,,,10,,,,,,,,,,,,,,,,,,,,,,41.906494140625,42.5927352905273,100.133750915527,100.133750915527,,,6.6314263343811,,1,0,0,0,0.01495361328125,30.7917900085449,2,1,1,42.6422538757324,0,4232058656,42.2510746002197,,,0.00214741910164349,0.00010725396065831,0.00214978173138026,0.000107256210198879,0.94705194234848,0.974505960941315,31.1728363037109,0,35,4,200,3.68310829799157E-5,-0.896902024745941,0.148467823863029,1,,,,,,,,,,,,,,,,
,3885201754.26733,48.5631294250488,100.133750915527,,,6,,,,31.3492940071624,,,10,,,,,,,,,,,,,,,,,,,,,,48.2352828979492,48.9363288879395,100.133750915527,100.133750915527,,,6.71368598937988,,1,0,0,0,0,31.7693061828613,2,1,1,48.9695930480957,0,4232058624,48.5912034776476,,,0.00206834026637871,0.000103290719798191,0.00207033371916692,0.000103292080321655,0.949601590633392,0.974648237228394,31.1836700439453,0,35,4,200,6.39896679786034E-5,-0.870279312133789,0.136398270726204,1,,,,,,,,,,,,,,,,
,3885201832.66056,54.8874778747559,100.133750915527,,,6,,,,31.3492940071624,,,10,,,,,,,,,,,,,,,,,,,,,,54.5009765625,55.2467880249023,100.133750915527,100.133750915527,,,6.78798723220825,,1,0,0,0,0,31.7693061828613,2,1,1,55.2739791870117,0,4232058688,54.8676670074463,,,0.00200208678213443,9.99683103842084E-5,0.00200373423424754,9.99689246856863E-5,0.952396869659424,0.974787712097168,31.1957607269287,0,35,4,200,6.96201095706783E-5,-0.847843706607819,0.12620148062706,1,,,,,,,,,,,,,,,,
,3885201910.89669,61.2234039306641,100.133750915527,,,6,,,,31.3492940071624,,,10,,,,,,,,,,,,,,,,,,,,,,60.8287200927734,61.5856513977051,100.133750915527,100.133750915527,,,6.85621643066406,,1,0,0,0,0.001373291015625,31.7693061828613,2,1,1,61.6180877685547,0,4232058592,61.217720413208,,,0.00194857798136965,9.72832181655343E-5,0.00194992288131431,9.72838301395002E-5,0.955357074737549,0.974951028823853,31.2087955474854,0.191324442625046,35,4,200,7.33667475287802E-5,-0.829832553863525,0.226380333304405,1,,,,,,,,,,,,,,,,
,3885201989.30049,67.6172676086426,100.133750915527,,,6,,,,31.3492940071624,,,10,,,,,,,,,,,,,,,,,,,,,,67.2125396728516,67.9779434204102,100.133750915527,100.133750915527,,,6.89147710800171,,1,0,0,0,0.013885498046875,32.7468223571777,2,1,1,68.0219955444336,0,4232058656,67.5911476135254,,,0.00190691023384771,9.51898543803274E-5,0.00190797150936916,9.51903747431687E-5,0.958544313907623,0.97513997554779,31.2231464385986,5.58776760101318,35,4,200,8.8995773694478E-5,-0.707141399383545,0.220006227493286,1,,,,,,,,,,,,,,,,
,3885202067.38823,73.9775123596191,100.133750915527,,,6,,,,31.3492940071624,,,10,,,,,,,,,,,,,,,,,,,,,,73.5704040527344,74.32861328125,100.133750915527,100.133750915527,,,6.92855405807495,,1,0,0,0,0.013885498046875,31.2805480957031,2,1,1,74.3846206665039,0,4232058656,73.9546157836914,,,0.00187578755565738,9.36240885464954E-5,0.00187659673265095,9.36246877405998E-5,0.961807429790497,0.975306332111359,31.2385082244873,0,35,4,200,9.74249269347638E-5,-0.696849524974823,0.214841067790985,1,,,,,,,,,,,,,,,,
,3885202145.69288,80.3368453979492,100.133750915527,,,6,,,,31.3492940071624,,,10,,,,,,,,,,,,,,,,,,,,,,79.9434432983398,80.6966705322266,100.133750915527,100.133750915527,,,6.96998119354248,,1,0,0,0,0.013885498046875,31.7693061828613,2,1,1,80.7302474975586,0,4232058656,80.3108818054199,,,0.00185313147260022,9.24823016409826E-5,0.00185370687256377,9.24823315415953E-5,0.965050578117371,0.975469052791596,31.2546405792236,,35,4,200,9.39872479648329E-5,-0.689533472061157,0.210889965295792,1,,,,,,,,,,,,,,,,
,3885202223.73636,86.7282409667969,100.133750915527,,,6,,,,31.3492940071624,,,10,,,,,,,,,,,,,,,,,,,,,,86.3285217285156,87.0769271850586,100.133750915527,100.133750915527,,,7.00918388366699,,1,0,0,0,0.013885498046875,31.7693061828613,2,1,1,87.1279602050781,0,4232058784,86.7052856445312,,,0.00183710674828276,9.16727999738134E-5,0.0018374833525792,9.16725170238817E-5,0.968245565891266,0.97565770149231,31.2717571258545,0,35,4,200,0.00011195385013707,-0.684530913829804,0.207823783159256,1,,,,,,,,,,,,,,,,
,3885202301.75362,93.1895790100098,100.133750915527,,,6,,,,31.3492940071624,,,10,,,,,,,,,,,,,,,,,,,,,,92.7988815307617,93.5466003417969,100.133750915527,100.133750915527,,,7.02626323699951,,1,0,0,0,0.0128936767578125,31.7693061828613,2,1,1,93.5802764892578,0,4232058656,93.1807067871094,,,0.00182605937660565,9.11133663500425E-5,0.00182628315502183,9.11132842508582E-5,0.971182644367218,0.97583943605423,31.2895641326904,8.40719712869031E-6,35,4,200,0.000109315500594676,-0.681278049945831,0.205431208014488,1,,,,,,,,,,,,,,,,
,3885202379.82954,99.6720199584961,100.133750915527,,,6,,,,31.3492940071624,,,10,,,,,,,,,,,,,,,,,,,,,,99.2640914916992,100.058181762695,100.133750915527,100.133750915527,,,7.04903697967529,,1,0,0,0,0,31.7693061828613,2,1,1,100.079948425293,0,4232058656,99.6878120422363,,,0.00181840473019624,9.07250804656355E-5,0.00181850968200077,9.07250695488521E-5,0.973733723163605,0.976034998893738,31.3084087371826,1,35,4,200,0.000104510683740955,-0.679235398769379,0.20352566242218,1,,,,,,,,,,,,,,,,
,3885202458.11814,106.147083282471,100.133750915527,,,6,,,,31.3492940071624,,,10,,,,,,,,,,,,,,,,,,,,,,105.729873657227,106.532257080078,100.133750915527,100.133750915527,,,7.07465696334839,,1,0,0,0,0.0147247314453125,31.7693061828613,2,1,1,106.564292907715,0,4232058688,106.161734771729,,,0.00181302245152945,9.04523859889381E-5,0.00181304952646849,9.04523172427161E-5,0.975550651550293,0.976200819015503,31.327995300293,5.5971417427063,35,4,200,0.000103492275229655,-0.677965879440308,0.201956808567047,1,,,,,,,,,,,,,,,,
,3885202536.04535,112.604991912842,100.133750915527,,,6,,,,31.3492940071624,,,10,,,,,,,,,,,,,,,,,,,,,,112.20873260498,112.951377868652,100.133750915527,100.133750915527,,,7.10852003097534,,1,0,0,0,0.013885498046875,31.7693061828613,2,1,1,113.001251220703,0,4232058688,112.573097991943,,,0.00180881011666702,9.02404819788903E-5,0.00180881009724838,9.02404806244785E-5,0.97635281085968,0.976352989673614,31.3489418029785,,35,4,200,0.000103943202702794,-0.677204132080078,0.200561612844467,1,,,,,,,,,,,,,,,,
,3885202614.43002,119.072872161865,100.133750915527,,,6,,,,31.3492940071624,,,10,,,,,,,,,,,,,,,,,,,,,,118.67000579834,119.431442260742,100.133750915527,100.133750915527,,,7.13961553573608,,1,0,0,0,0.013885498046875,31.7693061828613,2,1,1,119.475738525391,0,4232058624,119.052369689941,,,0.00180508213274672,9.00556729693278E-5,0.00180511423391471,9.00558207043204E-5,0.97581535577774,0.976491928100586,31.3708992004395,1,35,4,200,0.000108627384179272,-0.676664590835571,0.199241206049919,1,,,,,,,,,,,,,,,,
,3885202692.41163,125.599925994873,100.133750915527,,,6,,,,31.3492940071624,,,10,,,,,,,,,,,,,,,,,,,,,,125.214149475098,125.951332092285,100.133750915527,100.133750915527,,,7.15647888183594,,1,0,0,0,0.013885498046875,31.7693061828613,2,1,1,125.985702514648,0,4232058624,125.593039703369,,,0.00180112635537491,8.98625793269767E-5,0.00180125234372259,8.98628833587088E-5,0.973922431468964,0.976612150669098,31.3931636810303,1,35,4,200,0.000101786725281272,-0.676068365573883,0.197949126362801,1,,,,,,,,,,,,,,,,
,3885202770.23719,132.019477844238,100.133750915527,,,6,,,,31.3492940071624,,,10,,,,,,,,,,,,,,,,,,,,,,131.641555786133,132.383941650391,100.133750915527,100.133750915527,,,7.16416025161743,,1,0,0,0,0.013885498046875,31.7693061828613,2,1,1,132.397399902344,0,4232058560,132.009278869629,,,0.00179655561183653,8.96421008888659E-5,0.00179684142671288,8.96426121031764E-5,0.970870316028595,0.976719081401825,31.4158897399902,0,35,4,200,0.000106688792584464,-0.67523854970932,0.196629047393799,1,,,,,,,,,,,,,,,,
,3885202848.34061,138.484069824219,100.133750915527,,,6,,,,31.3492940071624,,,10,,,,,,,,,,,,,,,,,,,,,,138.090545654297,138.845199584961,100.133750915527,100.133750915527,,,7.17819881439209,,1,0,0,0,0.013885498046875,31.7693061828613,2,1,1,138.877593994141,0,4232058656,138.470381164551,,,0.0017910999810398,8.93810359629226E-5,0.00179161661919329,8.93817975010347E-5,0.966858446598053,0.976782560348511,31.4392604827881,0,35,4,200,0.000102131212770473,-0.674109816551208,0.195215299725533,1,,,,,,,,,,,,,,,,
,3885202926.66024,145.001617431641,100.133750915527,,,6,,,,31.3492940071624,,,10,,,,,,,,,,,,,,,,,,,,,,144.609603881836,145.393630981445,100.133750915527,100.133750915527,,,7.19178771972656,,1,0,0,0,0.013885498046875,31.7693061828613,2,1,1,145.393630981445,0,4232058624,145.013897705078,,,0.00178461560227691,8.90723941068853E-5,0.00178543449882775,8.90732398442037E-5,0.962145626544952,0.976863265037537,31.4632759094238,5.22767210006714,35,4,200,0.000101884012110531,-0.672573864459991,0.193705186247826,1,,,,,,,,,,,,,,,,
,3885203004.74425,151.494934082031,100.133750915527,,,6,,,,31.3492940071624,,,10,,,,,,,,,,,,,,,,,,,,,,151.111923217773,151.857559204102,100.133750915527,100.133750915527,,,7.20731449127197,,1,0,0,0,0.013885498046875,31.7693061828613,2,1,1,151.877944946289,0,4232058656,151.482797241211,,,0.00177715033088545,8.87187018519794E-5,0.00177836272565424,8.87203894929153E-5,0.95687872171402,0.976867437362671,31.4877433776855,0,35,4,200,9.94318979792297E-5,-0.670646607875824,0.192099198698998,1,,,,,,,,,,,,,,,,
,3885203082.65045,157.885734558105,100.133750915527,,,6,,,,31.3492940071624,,,10,,,,,,,,,,,,,,,,,,,,,,157.49250793457,158.236953735352,100.133750915527,100.133750915527,,,7.22734546661377,,1,0,0,0,0.013885498046875,33.2355842590332,2,1,1,158.278961181641,0,4232058624,157.864241027832,,,0.00176855286464471,8.83125910234855E-5,0.00177023331753477,8.83148130298701E-5,0.951209902763367,0.976891100406647,31.5127964019775,0,35,4,200,9.90852568065748E-5,-0.668349325656891,0.19036391377449,1,,,,,,,,,,,,,,,,
,3885203160.1256,164.308380126953,100.133750915527,,,6,,,,31.3492940071624,,,10,,,,,,,,,,,,,,,,,,,,,,163.91227722168,164.661315917969,100.133750915527,100.133750915527,,,7.23700761795044,,1,0,0,0,0.013885498046875,32.2580642700195,2,1,1,164.704483032227,0,4232058592,164.295806884766,,,0.00175882783428134,8.78541477179733E-5,0.00176106933749178,8.78576035079292E-5,0.945245623588562,0.976895093917847,31.5381965637207,0,35,4,200,0.000100030178145971,-0.665843605995178,0.188479453325272,1,,,,,,,,,,,,,,,,
,3885203238.00895,170.767639160156,100.133750915527,,,6,,,,31.3492940071624,,,10,,,,,,,,,,,,,,,,,,,,,,170.379196166992,171.117706298828,100.133750915527,100.133750915527,,,7.25012588500977,,1,0,0,0,0.013885498046875,31.7693061828613,2,1,1,171.15608215332,0,4232058656,170.746208190918,,,0.001747999200165,8.7345012479922E-5,0.0017508673191713,8.73486616747776E-5,0.938982248306274,0.976878225803375,31.5641899108887,5.22194242477417,35,4,200,8.91552772372961E-5,-0.662940144538879,0.186487480998039,1,,,,,,,,,,,,,,,,
,3885203316.12396,177.271820068359,100.133750915527,,,6,,,,31.3492940071624,,,10,,,,,,,,,,,,,,,,,,,,,,176.886077880859,177.608413696289,100.133750915527,100.133750915527,,,7.26780939102173,,1,0,0,0,0.013885498046875,31.7693061828613,2,1,1,177.657562255859,0,4232058656,177.248468017578,,,0.00173593821556351,8.67787942378627E-5,0.0017395238786784,8.67827881872812E-5,0.932475030422211,0.976867496967316,31.5907783508301,0,35,4,200,8.07448450359516E-5,-0.659598410129547,0.184431493282318,1,,,,,,,,,,,,,,,,
,3885203394.53648,183.758911132813,100.133750915527,,,6,,,,31.3492940071624,,,10,,,,,,,,,,,,,,,,,,,,,,183.370254516602,184.108657836914,100.133750915527,100.133750915527,,,7.28601026535034,,1,0,0,0,0.0139617919921875,31.2805480957031,2,1,1,184.147567749023,0,4232058656,183.732073974609,,,0.00172261666697509,8.61543091266501E-5,0.00172701849063587,8.6159010987529E-5,0.925723671913147,0.976823687553406,31.6179389953613,0.191679462790489,35,4,200,8.17850159364753E-5,-0.655803442001343,0.182210296392441,1,,,,,,,,,,,,,,,,
,3885203472.27348,190.223724365234,100.133750915527,,,6,,,,31.3492940071624,,,10,,,,,,,,,,,,,,,,,,,,,,189.812240600586,190.603134155273,100.133750915527,100.133750915527,,,7.30690288543701,,1,0,0,0,0.0147247314453125,31.7693061828613,2,1,1,190.635208129883,0,4232058624,190.196827697754,,,0.00170812358074398,8.54755880922156E-5,0.00171343574996013,8.54814105279154E-5,0.918820381164551,0.976809620857239,31.6455039978027,0,35,4,200,8.87760761543177E-5,-0.651557505130768,0.179851740598679,1,,,,,,,,,,,,,,,,
,3885203549.96023,196.674880981445,100.133750915527,,,6,,,,31.3492940071624,,,10,,,,,,,,,,,,,,,,,,,,,,196.253540039062,197.075836181641,100.133750915527,100.133750915527,,,7.30815505981445,,1,0,0,0,0,31.7693061828613,2,1,1,197.096221923828,0,4232058656,196.680212402344,,,0.00169262610438817,8.47511210255051E-5,0.00169893374933937,8.47580791608913E-5,0.911757171154022,0.976717293262482,31.6734523773193,5.21084022521973,35,4,200,8.23321315692738E-5,-0.647092580795288,0.177337482571602,1,,,,,,,,,,,,,,,,
,3885203628.02631,203.127914428711,100.133750915527,,,6,,,,31.3492940071624,,,10,,,,,,,,,,,,,,,,,,,,,,202.73567199707,203.470550537109,100.133750915527,100.133750915527,,,7.32033920288086,,1,0,0,0,0.013885498046875,31.7693061828613,2,1,1,203.520156860352,0,4232058624,203.100646972656,,,0.00167542137457188,8.39456115729604E-5,0.0016827904662084,8.39526659839798E-5,0.904561281204224,0.976745009422302,31.7019062042236,0,35,4,200,7.48422462493181E-5,-0.641651570796967,0.174750849604607,1,,,,,,,,,,,,,,,,
,3885203705.99187,209.606491088867,100.133750915527,,,6,,,,31.3492940071624,,,10,,,,,,,,,,,,,,,,,,,,,,209.280914306641,209.9208984375,100.133750915527,100.133750915527,,,7.33440780639648,,1,0,0,0,0.013885498046875,31.7693061828613,2,1,1,209.986328125,0,4232058624,209.608361138238,,,0.00165731281044528,8.30998377239095E-5,0.0016658553270475,8.31078383587596E-5,0.897159814834595,0.976710021495819,31.7309913635254,0.19219346344471,35,4,200,7.9157565778587E-5,-0.636362969875336,0.171968594193459,1,,,,,,,,,,,,,,,,
,3885203784.02357,216.101600646973,100.133750915527,,,6,,,,31.3492940071624,,,10,,,,,,,,,,,,,,,,,,,,,,215.689086914062,216.483367919922,100.133750915527,100.133750915527,,,7.34723138809204,,1,0,0,0,0.0165557861328125,31.7693061828613,2,1,1,216.514114379883,0,4232058720,216.090316772461,,,0.00163798204847716,8.21980484678968E-5,0.00164779303138246,8.22068683704095E-5,0.889548480510712,0.976646542549133,31.7607402801514,0.044987216591835,35,4,200,7.11825050530024E-5,-0.630592584609985,0.169084057211876,1,,,,,,,,,,,,,,,,
,3885203862.06404,222.610290527344,100.133750915527,,,6,,,,31.3492940071624,,,10,,,,,,,,,,,,,,,,,,,,,,222.197540283203,222.998977661133,100.133750915527,100.133750915527,,,7.36654710769653,,1,0,0,0,0.013885498046875,32.2580642700195,2,1,1,223.023040771484,0,4232058624,222.60111541748,,,0.00161733069486521,8.12345115144525E-5,0.00162848377167169,8.12435708619701E-5,0.881807506084442,0.976628601551056,31.7910346984863,,35,4,200,6.56299453112297E-5,-0.624309659004211,0.16609114408493,1,,,,,,,,,,,,,,,,
,3885203940.08422,229.124549865723,100.133750915527,,,6,,,,31.3492940071624,,,10,,,,,,,,,,,,,,,,,,,,,,228.753372192383,229.458541870117,100.133750915527,100.133750915527,,,7.37614583969116,,1,0,0,0,0.013885498046875,31.2805480957031,2,1,1,229.495727539062,0,4232058560,229.109803771973,,,0.00159550352685829,8.02170523844976E-5,0.00160813363769727,8.02284120701919E-5,0.873875439167023,0.976579189300537,31.8219566345215,0,35,4,200,6.70516092213802E-5,-0.617585003376007,0.162947833538055,1,,,,,,,,,,,,,,,,
,3885204018.17272,235.57689666748,100.133750915527,,,6,,,,31.3492940071624,,,10,,,,,,,,,,,,,,,,,,,,,,235.196807861328,235.935104370117,100.133750915527,100.133750915527,,,7.38934469223022,,1,0,0,0,0.0147247314453125,31.7693061828613,2,1,1,235.956985473633,0,4232058656,235.566506958008,,,0.00157309161430248,7.91755091866257E-5,0.00158732755507613,7.91905156243617E-5,0.865741848945618,0.976533949375153,31.8536128997803,,35,4,200,6.98867515893653E-5,-0.610617637634277,0.159768626093864,1,,,,,,,,,,,,,,,,
,3885204096.00079,241.988754272461,100.133750915527,,,6,,,,31.3492940071624,,,10,,,,,,,,,,,,,,,,,,,,,,241.572570800781,242.338668823242,100.133750915527,100.133750915527,,,7.41656017303467,,1,0,0,0,0.0147247314453125,31.2805480957031,2,1,1,242.404937744141,0,4232058688,241.957528686523,,,0.00154925790933023,7.80683325459061E-5,0.00156513301735028,7.80834806502471E-5,0.857352674007416,0.976410090923309,31.8862361907959,0,35,4,200,6.32901137578301E-5,-0.603305459022522,0.156373172998428,1,,,,,,,,,,,,,,,,
,3885204174.23602,248.459022521973,100.133750915527,,,6,,,,31.3492940071624,,,10,,,,,,,,,,,,,,,,,,,,,,248.070648193359,248.820434570313,100.133750915527,100.133750915527,,,7.4554386138916,,1,0,0,0,0.013885498046875,31.7693061828613,2,1,1,248.847396850586,0,4232058624,248.442926025391,,,0.00152474706122677,7.69333149532165E-5,0.00154240870711492,7.69499617627012E-5,0.84868460893631,0.976302146911621,31.9199199676514,7.64862634241581E-5,35,4,200,6.39655481791124E-5,-0.595817565917969,0.152929425239563,1,,,,,,,,,,,,,,,,
,3885204252.07468,254.941345214844,100.133750915527,,,6,,,,31.3492940071624,,,10,,,,,,,,,,,,,,,,,,,,,,254.534881591797,255.302719116211,100.133750915527,100.133750915527,,,7.45901441574097,,1,0,0,0,0.013885498046875,31.7693061828613,2,1,1,255.347808837891,0,4232058112,254.924821472168,,,0.00149971483909084,7.57779882948083E-5,0.00151931686030228,7.57981540023007E-5,0.839775145053864,0.976174592971802,31.9545269012451,0.146759524941444,35,4,200,6.33474410278723E-5,-0.588130056858063,0.149514973163605,1,,,,,,,,,,,,,,,,
,3885204330.0529,261.366683959961,100.133750915527,,,6,,,,31.3492940071624,,,10,,,,,,,,,,,,,,,,,,,,,,260.993743896484,261.739624023438,100.133750915527,100.133750915527,,,7.444739818573,,1,0,0,0,0.013885498046875,31.2805480957031,2,1,1,261.756164550781,0,4232058592,261.370880126953,,,0.00147382854066624,7.4588510092889E-5,0.00149551544621521,7.46109418906951E-5,0.830396294593811,0.976050972938538,31.9910163879395,5.15484714508057,35,4,200,4.95141648571007E-5,-0.580152928829193,0.146000474691391,1,,,,,,,,,,,,,,,,
,3885204407.76453,267.835311889648,100.133750915527,,,6,,,,31.3492940071624,,,10,,,,,,,,,,,,,,,,,,,,,,267.443695068359,268.176696777344,100.133750915527,100.133750915527,,,7.45337057113647,,1,0,0,0,0.013885498046875,31.2805480957031,2,1,1,268.226928710938,0,4232058880,267.809317016602,,,0.00144738999571145,7.33823699853395E-5,0.00147137836626442,7.34069478507437E-5,0.820407748222351,0.975934267044067,32.0298461914063,,35,4,200,6.34817915852182E-5,-0.571936845779419,0.14243458211422,1,,,,,,,,,,,,,,,,
,3885204486.304,274.364410400391,100.133750915527,,,6,,,,31.3492940071624,,,10,,,,,,,,,,,,,,,,,,,,,,273.942260742187,274.730133056641,100.133750915527,100.133750915527,,,7.47858476638794,,1,0,0,0,0.013885498046875,31.7693061828613,2,1,1,274.786560058594,0,4232058624,274.366564941406,,,0.00142002630083266,7.21494404814259E-5,0.0014466690316824,7.21743661262323E-5,0.80923593044281,0.975841104984283,32.073429107666,0.000172544721863233,35,4,200,5.78602048335597E-5,-0.563670098781586,0.138764306902885,1,,,,,,,,,,,,,,,,
,3885204564.47402,280.840774536133,100.133750915527,,,6,,,,31.3492940071624,,,10,,,,,,,,,,,,,,,,,,,,,,280.449523925781,281.182708740234,100.133750915527,100.133750915527,,,7.48932075500488,,1,0,0,0,0.013885498046875,31.7693061828613,2,1,1,281.232025146484,0,4232058656,280.824588012695,,,0.00139218706677919,7.0917035642035E-5,0.0014220071783592,7.09440971399311E-5,0.796695291996002,0.975766003131866,32.1224517822266,5.66766738891602,35,4,200,4.81601382489316E-5,-0.555430769920349,0.135161250829697,1,,,,,,,,,,,,,,,,
,3885204642.41126,287.297988891602,100.133750915527,,,6,,,,31.3492940071624,,,10,,,,,,,,,,,,,,,,,,,,,,286.896759033203,287.665710449219,100.133750915527,100.133750915527,,,7.53353404998779,,1,0,0,0,0.0017547607421875,31.2805480957031,2,1,1,287.69921875,0,4232058656,287.290966796875,,,0.00136377661811243,6.96835298268482E-5,0.00139734182105049,6.9713679456459E-5,0.782737076282501,0.975696802139282,32.1770973205566,5.68422510696109E-5,35,4,200,4.64652985101566E-5,-0.547022581100464,0.131620064377785,1,,,,,,,,,,,,,,,,
,3885204720.28778,293.804306030273,100.133750915527,,,6,,,,31.3492940071624,,,10,,,,,,,,,,,,,,,,,,,,,,293.430511474609,294.161926269531,100.133750915527,100.133750915527,,,7.63737773895264,,1,0,0,0,0.013885498046875,31.2805480957031,2,1,1,294.178100585937,0,4232058656,293.80397644043,,,0.00133498398855591,6.84580884066332E-5,0.00137283996863797,6.84914535773141E-5,0.767553806304932,0.975596129894257,32.2366485595703,0,35,4,200,4.69721926492639E-5,-0.538702726364136,0.128008350729942,1,,,,,,,,,,,,,,,,
,3885204798.25027,299.375823974609,100.133750915527,,,6,,,,31.3492940071624,,,10,,,,,,,,,,,,,,,,,,,,,,299.263031005859,299.480346679687,100.133750915527,100.133750915527,,,7.77125358581543,,1,0,0,0,0.013885498046875,31.7693061828613,6,1,1,299.488616943359,0,4232058656,299.380279541016,,,0.00131019215058811,6.74024186277796E-5,0.00135177852192703,6.74412069703284E-5,0.754895985126495,0.975262045860291,32.2862548828125,,35,4,200,6.86700077494606E-5,-0.532078206539154,0.124351114034653,1,,,,,,,,,,,,,,,,
,3885204876.3219,299.940567016602,100.133750915527,,,6,,,,31.3492940071624,,,10,,,,,,,,,,,,,,,,,,,,,,299.932739257812,299.947021484375,100.133750915527,100.133750915527,,,7.94735670089722,,1,0,0,0,0.013885498046875,31.7693061828613,1,1,1,299.948394775391,0,4232058624,299.941641235352,,,0.00130681468479069,6.72655438367451E-5,0.00134902049550173,6.73037529714715E-5,0.752804100513458,0.97518527507782,32.2945137023926,0,35,4,200,8.23140289867297E-5,-0.531457662582397,0.123555123806,1,,,,,,,,,,,,,,,,
,3885204978.11143,295.745086669922,100.133750915527,,,6,,,,31.3492940071624,,,10,,,,,,,,,,,,,,,,,,,,,,295.316619873047,296.195556640625,100.133750915527,100.133750915527,,,8.24381065368652,,1,0,0,0,0.0139617919921875,31.7693061828613,2,1,1,295.294616699219,0,4232058688,295.755865478516,,,0.00132455418374951,6.80799447194728E-5,0.00136531359481072,6.81167391648343E-5,0.758376598358154,0.975110173225403,32.2724723815918,9.30934766074643E-5,35,4,200,0.000154366382048465,-0.537700593471527,0.125318467617035,1,,,,,,,,,,,,,,,,
,3885205056.52448,288.838119506836,100.133750915527,,,6,,,,31.3492940071624,,,10,,,,,,,,,,,,,,,,,,,,,,288.470428466797,289.236602783203,100.133750915527,100.133750915527,,,8.52023887634277,,1,0,0,0,0.013885498046875,31.7693061828613,2,1,1,288.439636230469,0,4232059008,288.852786254883,,,0.00135871534643639,6.97110884607169E-5,0.00139797093722595,6.97454999886999E-5,0.765457570552826,0.975433111190796,32.2447204589844,8.01653150119819E-5,35,4,200,0.000145428610267118,-0.548540592193604,0.130207568407059,1,,,,,,,,,,,,,,,,
,3885205134.46709,282.59553527832,100.133750915527,,,6,,,,31.3492940071624,,,10,,,,,,,,,,,,,,,,,,,,,,282.247497558594,282.980255126953,100.133750915527,100.133750915527,,,8.35599613189697,,1,0,0,0,0.013885498046875,31.7693061828613,2,1,1,282.210815429687,0,4232058592,282.621740722656,,,0.00138805402100855,7.09889506484403E-5,0.00142354322373896,7.10207263678777E-5,0.77876204252243,0.975769281387329,32.1926307678223,6.12016010563821E-5,35,4,200,0.000126935468870215,-0.559378564357758,0.131766185164452,1,,,,,,,,,,,,,,,,
,3885205212.88534,276.133010864258,100.133750915527,,,6,,,,31.3492940071624,,,10,,,,,,,,,,,,,,,,,,,,,,275.738311767578,276.48583984375,100.133750915527,100.133750915527,,,8.24172019958496,,1,0,0,0,0.013885498046875,31.7693061828613,2,1,1,275.738311767578,0,4232058688,276.12751159668,,,0.00141641107543783,7.22086292248189E-5,0.00144795684408132,7.22385180041216E-5,0.792967557907105,0.975891888141632,32.1370735168457,0,35,4,200,0.000137175666168332,-0.568534433841705,0.134506925940514,1,,,,,,,,,,,,,,,,
,3885205291.0077,269.610107421875,100.133750915527,,,6,,,,31.3492940071624,,,10,,,,,,,,,,,,,,,,,,,,,,269.237426757813,270.019439697266,100.133750915527,100.133750915527,,,8.16061019897461,,1,0,0,0,0.013885498046875,31.7693061828613,2,1,1,269.200775146484,0,4232058592,269.618359375,,,0.00144476060071831,7.34634198729851E-5,0.00147304122459707,7.34895537043863E-5,0.805339932441711,0.976139068603516,32.0888748168945,0,35,4,200,0.000142344710184261,-0.577723920345306,0.137378856539726,1,,,,,,,,,,,,,,,,
,3885205369.15483,263.202896118164,100.133750915527,,,6,,,,31.3492940071624,,,10,,,,,,,,,,,,,,,,,,,,,,262.845275878906,263.599395751953,100.133750915527,100.133750915527,,,8.09497547149658,,1,0,0,0,0.013885498046875,31.7693061828613,2,1,1,262.806396484375,0,4232058624,263.233700561523,,,0.00147272993773702,7.47234316791602E-5,0.00149823792408924,7.47461089398401E-5,0.816392362117767,0.976420402526855,32.0459213256836,2.81262600765331E-5,35,4,200,0.000165137782460079,-0.586694538593292,0.140355825424194,1,,,,,,,,,,,,,,,,
,3885205447.43917,256.676483154297,100.133750915527,,,6,,,,31.3492940071624,,,10,,,,,,,,,,,,,,,,,,,,,,256.311553955078,257.07373046875,100.133750915527,100.133750915527,,,8.02937507629395,,1,0,0,0,0.013885498046875,31.7693061828613,2,1,1,256.279235839844,0,4232058624,256.701419067383,,,0.00150047091640692,7.59913831801521E-5,0.00152361252313212,7.60115263332008E-5,0.82633650302887,0.976703345775604,32.0072860717773,0,35,4,200,0.000131364620756358,-0.596191108226776,0.143233314156532,1,,,,,,,,,,,,,,,,
,3885205525.70205,250.106819152832,100.133750915527,,,6,,,,31.3492940071624,,,10,,,,,,,,,,,,,,,,,,,,,,249.740768432617,250.50553894043,100.133750915527,100.133750915527,,,8.0018482208252,,1,0,0,0,0.013885498046875,31.7693061828613,2,1,1,249.708099365234,0,4232058592,250.132534790039,,,0.00152844077006872,7.72817780841885E-5,0.00154949704670652,7.7302537894673E-5,0.835712134838104,0.976893484592438,31.970817565918,0,35,4,200,0.000155601082951762,-0.605768442153931,0.146242126822472,1,,,,,,,,,,,,,,,,
,3885205603.75482,243.547004699707,100.133750915527,,,6,,,,31.3492940071624,,,10,,,,,,,,,,,,,,,,,,,,,,243.237121582031,243.943588256836,100.133750915527,100.133750915527,,,7.94453573226929,,1,0,0,0,0.013885498046875,31.7693061828613,2,1,1,243.150421142578,0,4232058720,243.616582234701,,,0.00155677636018981,7.85988067822622E-5,0.00157586171244458,7.86173970394317E-5,0.844680786132813,0.977138102054596,31.9360752105713,0,35,4,200,0.000136740534799173,-0.61545342206955,0.149220556020737,1,,,,,,,,,,,,,,,,
,3885205681.8457,236.996170043945,100.133750915527,,,6,,,,31.3492940071624,,,10,,,,,,,,,,,,,,,,,,,,,,236.634536743164,237.39192199707,100.133750915527,100.133750915527,,,7.90495252609253,,1,0,0,0,0.013885498046875,31.7693061828613,2,1,1,236.60041809082,0,4232058624,237.024388122559,,,0.00158504444651816,7.99244798873763E-5,0.00160240781953952,7.99417341183922E-5,0.852884829044342,0.977147698402405,31.9041843414307,0,35,4,200,0.000143739307532087,-0.625046193599701,0.152370691299438,1,,,,,,,,,,,,,,,,
,3885205759.55858,230.532752990723,100.133750915527,,,6,,,,31.3492940071624,,,10,,,,,,,,,,,,,,,,,,,,,,230.180038452148,230.935256958008,100.133750915527,100.133750915527,,,7.88793230056763,,1,0,0,0,0.013885498046875,31.7693061828613,2,1,1,230.130249023438,0,4232058592,230.557527160645,,,0.00161296709717277,8.1235707927581E-5,0.00162865994049984,8.12510769330232E-5,0.86103218793869,0.977309286594391,31.8725605010986,,35,4,200,0.000132306769955903,-0.634531378746033,0.155458807945251,1,,,,,,,,,,,,,,,,
,3885205837.35181,224.052200317383,100.133750915527,,,6,,,,31.3492940071624,,,10,,,,,,,,,,,,,,,,,,,,,,223.704971313477,224.447784423828,100.133750915527,100.133750915527,,,7.84110116958618,,1,0,0,0,0.013885498046875,31.7693061828613,2,1,1,223.656616210938,0,4232058656,224.081646728516,,,0.00164095261140146,8.2555403383299E-5,0.00165505902720264,8.25680163665947E-5,0.868935286998749,0.977347493171692,31.841796875,0,35,4,200,0.000148894861922599,-0.644382119178772,0.158601403236389,1,,,,,,,,,,,,,,,,
,3885205915.70641,217.491729736328,100.133750915527,,,6,,,,31.3492940071624,,,10,,,,,,,,,,,,,,,,,,,,,,217.139389038086,217.894119262695,100.133750915527,100.133750915527,,,7.81249332427978,,1,0,0,0,0.013885498046875,31.7693061828613,2,1,1,217.089340209961,0,4232058624,217.530374145508,,,0.00166942621186535,8.39042150146482E-5,0.00168210452475998,8.3917188859175E-5,0.876645386219025,0.977395176887512,31.811767578125,3.99024866055697E-5,35,4,200,0.000161485018907115,-0.653711438179016,0.162406042218208,1,,,,,,,,,,,,,,,,
,3885205993.60339,211.021553039551,100.133750915527,,,6,,,,31.3492940071624,,,10,,,,,,,,,,,,,,,,,,,,,,210.662796020508,211.4130859375,100.133750915527,100.133750915527,,,7.79564476013184,,1,0,0,0,0.013885498046875,30.3030319213867,2,1,1,210.630020141602,0,4232058592,211.05460357666,,,0.00169857857228275,8.52920152607072E-5,0.00170986404726764,8.53019836250795E-5,0.884117126464844,0.977433800697327,31.7826957702637,0,35,4,200,0.000162742187967524,-0.663668096065521,0.165854349732399,1,,,,,,,,,,,,,,,,
,3885206071.57445,204.434097290039,100.133750915527,,,6,,,,31.3492940071624,,,10,,,,,,,,,,,,,,,,,,,,,,204.059967041016,204.840286254883,100.133750915527,100.133750915527,,,7.7584342956543,,1,0,0,0,0.00091552734375,31.7693061828613,2,1,1,204.027908325195,0,4232058624,204.472659301758,,,0.00172816951526573,8.67040644200989E-5,0.00173814795191006,8.67132757460732E-5,0.891609907150269,0.97729480266571,31.7532806396484,5.63500499725342,35,4,200,0.00015851813077461,-0.673992574214935,0.169252708554268,1,,,,,,,,,,,,,,,,
,3885206149.72233,197.947311401367,100.133750915527,,,6,,,,31.3492940071624,,,10,,,,,,,,,,,,,,,,,,,,,,197.583953857422,198.352813720703,100.133750915527,100.133750915527,,,7.7280387878418,,1,0,0,0,0.013885498046875,31.2805480957031,2,1,1,197.541809082031,0,4232058592,197.977912902832,,,0.00175803876625424,8.81326199185975E-5,0.00176674879586925,8.81402751927879E-5,0.89911812543869,0.97722864151001,31.7238063812256,0,35,4,200,0.000154176304931752,-0.684310495853424,0.172691524028778,1,,,,,,,,,,,,,,,,
,3885206227.84339,191.454521179199,100.133750915527,,,6,,,,31.3492940071624,,,10,,,,,,,,,,,,,,,,,,,,,,191.112503051758,191.84504699707,100.133750915527,100.133750915527,,,7.717529296875,,1,0,0,0,0.013885498046875,31.7693061828613,2,1,1,191.063995361328,0,4232058624,191.487194824219,,,0.00178781917589834,8.95613394910552E-5,0.00179537040110151,8.95682982098695E-5,0.906419575214386,0.977163791656494,31.6950206756592,,35,4,200,0.000187582190847024,-0.694462954998016,0.176378473639488,1,,,,,,,,,,,,,,,,
,3885206305.95956,184.973480224609,100.133750915527,,,6,,,,31.3492940071624,,,10,,,,,,,,,,,,,,,,,,,,,,184.601745605469,185.404724121094,100.133750915527,100.133750915527,,,7.68311929702759,,1,0,0,0,0.001068115234375,31.7693061828613,2,1,1,184.542236328125,0,4232058560,185.023614501953,,,0.00181804150670307,9.10160504317493E-5,0.00182452055157754,9.10225022917597E-5,0.913594305515289,0.977179884910584,31.6667041778564,0,35,4,200,0.000158780560013838,-0.705337882041931,0.179725542664528,1,,,,,,,,,,,,,,,,
,3885206383.81512,178.463363647461,100.133750915527,,,6,,,,31.3492940071624,,,10,,,,,,,,,,,,,,,,,,,,,,178.059417724609,178.91259765625,100.133750915527,100.133750915527,,,7.65594482421875,,1,0,0,0,0.013885498046875,31.7693061828613,2,1,1,178.014129638672,0,4232058656,178.48589630127,,,0.00184879790219248,9.25012297266858E-5,0.00185428855383547,9.25077186016102E-5,0.92066764831543,0.97713577747345,31.6385440826416,0,35,4,200,0.000187822064617649,-0.716189801692963,0.183473289012909,1,,,,,,,,,,,,,,,,
,3885206461.95961,171.915710449219,100.133750915527,,,6,,,,31.3492940071624,,,10,,,,,,,,,,,,,,,,,,,,,,171.563735961914,172.304611206055,100.133750915527,100.133750915527,,,7.64195823669434,,1,0,0,0,0.013885498046875,31.7693061828613,2,1,1,171.526809692383,0,4232058624,171.944853210449,,,0.00188040455780118,9.40325688231729E-5,0.00188495125863378,9.40372929675343E-5,0.927637696266174,0.977188467979431,31.6107234954834,0,35,4,200,0.000168071041116491,-0.727262556552887,0.187252029776573,1,,,,,,,,,,,,,,,,
,3885206540.50561,165.390754699707,100.133750915527,,,6,,,,31.3492940071624,,,10,,,,,,,,,,,,,,,,,,,,,,165.035781860352,165.778015136719,100.133750915527,100.133750915527,,,7.61518430709839,,1,0,0,0,0.013885498046875,31.7693061828613,2,1,1,165.003494262695,0,4232058592,165.417283630371,,,0.00191301516341732,9.56188605532992E-5,0.00191672355154596,9.5622491308071E-5,0.93433552980423,0.977115631103516,31.5835552215576,0,35,4,200,0.000170507817529142,-0.738913834095001,0.191117599606514,1,,,,,,,,,,,,,,,,
,3885206618.49874,158.858345031738,100.133750915527,,,6,,,,31.3492940071624,,,10,,,,,,,,,,,,,,,,,,,,,,158.484191894531,159.263595581055,100.133750915527,100.133750915527,,,7.59042739868164,,1,0,0,0,0.013885498046875,31.2805480957031,2,1,1,158.453094482422,0,4232058528,158.886367797852,,,0.0019463150307819,9.72433304002224E-5,0.00194926025337384,9.72457987453063E-5,0.940913021564484,0.977112591266632,31.5566177368164,0,35,4,200,0.000194033302250318,-0.749848663806915,0.19574573636055,1,,,,,,,,,,,,,,,,
,3885206696.32745,152.261001586914,100.133750915527,,,6,,,,31.3492940071624,,,10,,,,,,,,,,,,,,,,,,,,,,151.911666870117,152.600311279297,100.133750915527,100.133750915527,,,7.58224201202393,,1,0,0,0,0.013885498046875,31.7693061828613,2,1,1,151.856292724609,0,4232058592,152.273327297635,,,0.00198156357962128,9.89696640537099E-5,0.00198386254923042,9.89717846849704E-5,0.947161912918091,0.977208077907562,31.5307006835937,0,35,4,200,0.000175666471477598,-0.762061953544617,0.200195670127869,1,,,,,,,,,,,,,,,,
,3885206775.03471,145.706695556641,100.133750915527,,,6,,,,31.3492940071624,,,10,,,,,,,,,,,,,,,,,,,,,,145.359497070313,146.103179931641,100.133750915527,100.133750915527,,,7.56227827072144,,1,0,0,0,0.013885498046875,31.7693061828613,2,1,1,145.310211181641,0,4232058688,145.738618469238,,,0.00201741037984992,0.000100729041564497,0.00201912474349979,0.000100730961479408,0.953331053256989,0.977207362651825,31.5042552947998,0,35,4,200,0.00018267628911417,-0.774836421012878,0.204636082053185,1,,,,,,,,,,,,,,,,
,3885206853.09581,139.234130859375,100.133750915527,,,6,,,,31.3492940071624,,,10,,,,,,,,,,,,,,,,,,,,,,138.848999023438,139.643447875977,100.133750915527,100.133750915527,,,7.530113697052,,1,0,0,0,0.013885498046875,31.7693061828613,2,1,1,138.824813842773,0,4232058560,139.259921264648,,,0.00205461693427284,0.000102560476249389,0.00205582065321483,0.000102561735200284,0.959180355072022,0.977181851863861,31.4780693054199,5.6105318069458,35,4,200,0.000196384731680155,-0.788310825824738,0.209166213870049,1,,,,,,,,,,,,,,,,
,3885206931.13162,132.774742126465,100.133750915527,,,6,,,,31.3492940071624,,,10,,,,,,,,,,,,,,,,,,,,,,132.395797729492,133.185363769531,100.133750915527,100.133750915527,,,7.50974559783935,,1,0,0,0,0.013885498046875,31.7693061828613,2,1,1,132.364120483398,0,4232058816,132.808992004395,,,0.00209337745369251,0.000104473643030203,0.00209417010593988,0.000104474843343841,0.964608788490295,0.977218151092529,31.4523315429687,0,35,4,200,0.000197534769540653,-0.802091777324676,0.214135184884071,1,,,,,,,,,,,,,,,,
,3885207008.82326,126.279930114746,100.133750915527,,,6,,,,31.3492940071624,,,10,,,,,,,,,,,,,,,,,,,,,,125.904319763184,126.688507080078,100.133750915527,100.133750915527,,,7.49204158782959,,1,0,0,0,0.0139617919921875,31.2805480957031,2,1,1,125.871353149414,0,4232058560,126.29326171875,,,0.00213496467373279,0.000106532568542634,0.00213542332917076,0.000106533127807856,0.969300270080566,0.977116227149963,31.4271450042725,,35,4,200,0.00020323961507529,-0.816758334636688,0.21940940618515,1,,,,,,,,,,,,,,,,
,3885207086.91648,119.762992858887,100.133750915527,,,6,,,,31.3492940071624,,,10,,,,,,,,,,,,,,,,,,,,,,119.399040222168,120.159278869629,100.133750915527,100.133750915527,,,7.44964647293091,,1,0,0,0,0.013885498046875,31.7693061828613,2,1,1,119.366706848145,0,4232058592,119.791856384277,,,0.00217893138984712,0.000108714466771794,0.0021791511682118,0.000108714723893127,0.973137021064758,0.977092564105988,31.4026660919189,0.142636403441429,35,4,200,0.000219187946640886,-0.832078218460083,0.225043728947639,1,,,,,,,,,,,,,,,,
,3885207164.60289,113.313545227051,100.133750915527,,,6,,,,31.3492940071624,,,10,,,,,,,,,,,,,,,,,,,,,,112.938049316406,113.716506958008,100.133750915527,100.133750915527,,,7.41934490203857,,1,0,0,0,0.013885498046875,31.7693061828613,2,1,1,112.910583496094,0,4232058208,113.329490661621,,,0.00222547634687958,0.000111029081654408,0.00222554526226118,0.00011102923559825,0.975839078426361,0.977095305919647,31.3785419464111,5.08078846905846E-6,35,4,200,0.000231169775361195,-0.848841428756714,0.230883583426476,1,,,,,,,,,,,,,,,,
,3885207242.98772,106.830509185791,100.133750915527,,,6,,,,31.3492940071624,,,10,,,,,,,,,,,,,,,,,,,,,,106.464820861816,107.229789733887,100.133750915527,100.133750915527,,,7.39801073074341,,1,0,0,0,0.013885498046875,31.2805480957031,2,1,1,106.431228637695,0,4232058624,106.84878616333,,,0.0022761744064456,0.000113555533216102,0.00227617735845027,0.000113555541624456,0.976911664009094,0.9769646525383,31.3552398681641,0,35,4,200,0.000225372568820603,-0.86659163236618,0.23786860704422,1,,,,,,,,,,,,,,,,
,3885207321.43854,100.225910186768,100.133750915527,,,6,,,,31.3492940071624,,,10,,,,,,,,,,,,,,,,,,,,,,99.866096496582,100.618545532227,100.133750915527,100.133750915527,,,7.35680246353149,,1,0,0,0,0.013885498046875,31.2805480957031,2,1,1,99.8332748413086,0,4232058624,100.244909667969,,,0.0023318436916817,0.000116334044270757,0.00233186670027225,0.000116333975691133,0.976455509662628,0.976903676986694,31.3319053649902,0,35,4,200,0.00024715147446841,-0.886496305465698,0.24516972899437,1,,,,,,,,,,,,,,,,
,3885207399.20957,93.7317085266113,100.133750915527,,,6,,,,31.3492940071624,,,10,,,,,,,,,,,,,,,,,,,,,,93.3395919799805,94.1543884277344,100.133750915527,100.133750915527,,,7.31917524337769,,1,0,0,0,0.013885498046875,32.2580642700195,2,1,1,93.3090286254883,0,4232058592,93.7363952636719,,,0.00239169138161263,0.000119325265926247,0.00239182319244115,0.000119325384671428,0.974583268165588,0.976808547973633,31.3097343444824,0.191205203533173,35,4,200,0.00024532014504075,-0.907670557498932,0.253197193145752,1,,,,,,,,,,,,,,,,
,3885207477.09759,87.292236328125,100.133750915527,,,6,,,,31.3492940071624,,,10,,,,,,,,,,,,,,,,,,,,,,86.9293670654297,87.6868133544922,100.133750915527,100.133750915527,,,7.29231882095337,,1,0,0,0,0.013885498046875,31.7693061828613,2,1,1,86.8976593017578,0,4232058624,87.3106964111328,,,0.00245752472379383,0.000122619529045098,0.00245784311019929,0.000122619468593923,0.971638083457947,0.976665675640106,31.2879772186279,7.82608276495012E-6,35,4,200,0.000270176300546154,-0.93111789226532,0.261932045221329,1,,,,,,,,,,,,,,,,
,3885207555.00741,80.8081245422363,100.133750915527,,,6,,,,31.3492940071624,,,10,,,,,,,,,,,,,,,,,,,,,,80.4344482421875,81.2144470214844,100.133750915527,100.133750915527,,,7.26226854324341,,1,0,0,0,0.013885498046875,31.7693061828613,2,1,1,80.4018020629883,0,4232058624,80.8150016784668,,,0.00252994397909868,0.00012624648125936,0.00253054214993322,0.000126246584056791,0.968078017234802,0.9765864610672,31.2667636871338,0,35,4,200,0.000257376435911283,-0.956226408481598,0.271804958581924,1,,,,,,,,,,,,,,,,
,3885207633.11297,74.1819725036621,100.133750915527,,,6,,,,31.3492940071624,,,10,,,,,,,,,,,,,,,,,,,,,,73.8185195922852,74.5870132446289,100.133750915527,100.133750915527,,,7.2075982093811,,1,0,0,0,0.0139617919921875,31.2805480957031,2,1,1,73.7769317626953,0,4232058592,74.1955902099609,,,0.00261161059864913,0.000130339651420136,0.00261258497389057,0.000130340173526351,0.964025735855103,0.976403474807739,31.2460193634033,1.0816167559824E-5,35,4,200,0.000280170439509675,-0.98530113697052,0.282828867435455,1,,,,,,,,,,,,,,,,
,3885207710.96869,67.6059226989746,100.133750915527,,,6,,,,31.3492940071624,,,10,,,,,,,,,,,,,,,,,,,,,,67.2539978027344,68.0134582519531,100.133750915527,100.133750915527,,,7.16228437423706,,1,0,0,0,0.013885498046875,31.2805480957031,2,1,1,67.1983871459961,0,4232058560,67.6274322509766,,,0.00270045253278789,0.000134793794954329,0.0027018709118231,0.000134794546728947,0.9600750207901,0.976418673992157,31.2267570495605,0,35,4,200,0.000304284796584398,-1.12469840049744,0.295046955347061,1,,,,,,,,,,,,,,,,
,3885207788.95386,61.0253467559814,100.133750915527,,,6,,,,31.3492940071624,,,10,,,,,,,,,,,,,,,,,,,,,,60.6682968139648,61.4223136901855,100.133750915527,100.133750915527,,,7.12244510650635,,1,0,0,0,0.013885498046875,31.7693061828613,2,1,1,60.6283798217773,0,4232058592,61.0424259185791,,,0.00280086008831689,0.000139830064378273,0.00280283368705014,0.000139831528799637,0.955928802490234,0.976416826248169,31.2076854705811,0,35,4,200,0.000283046712866053,-1.16152000427246,0.199947118759155,1,,,,,,,,,,,,,,,,
,3885207866.91654,54.4615020751953,100.133750915527,,,6,,,,31.3492940071624,,,10,,,,,,,,,,,,,,,,,,,,,,54.0788345336914,54.8770980834961,100.133750915527,100.133750915527,,,7.04270935058594,,1,0,0,0,0.013885498046875,31.7693061828613,2,1,1,54.0459060668945,0,4232058784,54.4783821105957,,,0.00291262647066983,0.00014543719615866,0.00291522218337125,0.000145438722639511,0.951864719390869,0.97635817527771,31.1897869110107,1.4004523109179E-5,35,4,200,0.000318488077027723,-1.2004417181015,0.215146750211716,1,,,,,,,,,,,,,,,,
,3885207945.32571,47.8307609558105,100.133750915527,,,6,,,,31.3492940071624,,,10,,,,,,,,,,,,,,,,,,,,,,47.4721069335937,48.2308578491211,100.133750915527,100.133750915527,,,6.96844959259033,,1,0,0,0,0.013885498046875,31.7693061828613,2,1,1,47.4306640625,0,4232058880,47.8582981109619,,,0.00303792456071898,0.000151723226853402,0.00304123278817453,0.000151725775066125,0.947994232177734,0.976231813430786,31.1733264923096,0,35,4,200,0.000328821945004165,-1.24475240707397,0.23233437538147,1,,,,,,,,,,,,,,,,
,3885208023.26634,41.256628036499,100.133750915527,,,6,,,,31.3492940071624,,,10,,,,,,,,,,,,,,,,,,,,,,40.9038467407227,41.6611289978027,100.133750915527,100.133750915527,,,6.8878870010376,,1,0,0,0,0.013885498046875,31.7693061828613,2,1,1,40.8521270751953,0,4232058528,41.288306427002,,,0.00317449191886395,0.000158573901963562,0.00317855265005593,0.000158577039533594,0.94447535276413,0.976116061210632,31.1585960388184,0,35,4,200,0.000342007871950045,-1.2930109500885,0.251054465770721,1,,,,,,,,,,,,,,,,
,3885208101.29416,34.6594848632812,100.133750915527,,,6,,,,31.3492940071624,,,10,,,,,,,,,,,,,,,,,,,,,,34.2932014465332,35.0587348937988,100.133750915527,100.133750915527,,,6.75483465194702,,1,0,0,0,0.013885498046875,31.2805480957031,2,1,1,34.2602348327637,0,4232058592,34.6730571746826,,,0.00332080999702448,0.000165913048852532,0.00332568767343614,0.000165918132171177,0.941303312778473,0.975981891155243,31.1455421447754,0.191468626260757,35,4,200,0.0003551603294909,-1.34457802772522,0.271186947822571,1,,,,,,,,,,,,,,,,
,3885208179.13924,28.1099729537964,100.133750915527,,,6,,,,31.3492940071624,,,10,,,,,,,,,,,,,,,,,,,,,,27.7437610626221,28.5160312652588,100.133750915527,100.133750915527,,,6.58606147766113,,1,0,0,0,0.013885498046875,31.7693061828613,2,1,1,27.703914642334,0,4232058592,28.1425413131714,,,0.00347099395556771,0.000173445744882129,0.00347665840003876,0.000173450566657119,0.938505709171295,0.975856006145477,31.1341361999512,,35,4,200,0.000358413206413388,-1.39757513999939,0.29184901714325,1,,,,,,,,,,,,,,,,
,3885208257.18308,21.5695695877075,100.133750915527,,,6,,,,31.3492940071624,,,10,,,,,,,,,,,,,,,,,,,,,,21.21484375,21.9723606109619,100.133750915527,100.133750915527,,,6.31753301620483,,1,0,0,0,0.013885498046875,31.7693061828613,2,1,1,21.1667785644531,0,4232058656,21.6009016036987,,,0.00361509048865258,0.000180672864575617,0.00362153075394825,0.000180678706173603,0.936158001422882,0.975734829902649,31.1246318817139,0,35,4,200,0.000365854997653514,-1.4481748342514,0.311683773994446,1,,,,,,,,,,,,,,,,
,3885208335.66672,15.0672626495361,100.133750915527,,,6,,,,31.3492940071624,,,10,,,,,,,,,,,,,,,,,,,,,,14.7059936523438,15.4487924575806,100.133750915527,100.133750915527,,,5.76390361785889,,1,0,0,0,0.013885498046875,31.7693061828613,2,1,1,14.6857328414917,0,4232058592,15.0798245429993,,,0.00373566471574674,0.000186722198266411,0.00374277167271221,0.000186727609224563,0.934240579605103,0.975706994533539,31.1168060302734,0.231647953391075,35,4,200,0.000352304807165638,-1.49001455307007,0.328294336795807,1,,,,,,,,,,,,,,,,
,3885208413.48288,9.13442087173462,100.133750915527,,,6,,,,31.3492940071624,,,10,,,,,,,,,,,,,,,,,,,,,,8.78678607940674,9.50398254394531,100.133750915527,100.133750915527,,,4.92640924453735,,1,0,0,0,0.013885498046875,30.7917900085449,6,1,1,8.76485919952393,0,4232059168,9.15961627960205,,,0.00380623279143961,0.000190264651190772,0.00381377349346364,0.0001902700764407,0.933042824268341,0.975672483444214,31.1119365692139,0,35,4,200,0.000238061023992486,-1.51512503623962,0.33704149723053,1,,,,,,,,,,,,,,,,
,3885208491.59034,5.00245642662048,100.133750915527,,,6,,,,31.3492940071624,,,10,,,,,,,,,,,,,,,,,,,,,,4.99780035018921,5.00275278091431,100.133750915527,100.133750915527,,,4.1560697555542,,1,0,0,0,0.013885498046875,31.7693061828613,5,1,1,5.00216007232666,0,4232058784,5.00009846687317,,,0.00383024839795954,0.000191463385548973,0.00383782316748463,0.00019147017126323,0.933174788951874,0.975607693195343,31.112585067749,5.21981525421143,35,4,200,0.000272481905994937,-1.52287542819977,0.340263456106186,1,,,,,,,,,,,,,,,,
,3885208530.65784,5.0008111000061,100.133750915527,,,6,,,,31.3492940071624,,,10,,,,,,,,,,,,,,,,,,,,,,4.99672174453735,5.00170230865479,100.133750915527,100.133750915527,,,4.13169765472412,,1,0,0,0,0.013885498046875,31.7693061828613,1,1,1,4.99991989135742,0,4232058752,4.99853415489197,,,0.00383054245687661,0.000191477091959471,0.00383806166642654,0.000191482246705787,0.933257102966309,0.975583732128143,31.1129703521729,,35,4,200,0.00027508707717061,-1.52304887771606,0.34022057056427,1,,,,,,,,,,,,,,,,