File: Data/KMK273/TGA/KMK273_1000c_air.txt
Filename	kmk273_1000c_air
Instrument name	0650-0588 (172.23.191.35)
Operator	Kyle Kirkpatrick
rundate	1/18/2023
Sample name	KMK273_1000C_Air
proceduresegments	Blend Channel B (Air) at 100% with Channel A (N2); Equilibrate 30.00 °C; Ramp 10.00 °C/min to 1000.00 °C
[File Parameters]
Run date	1/18/2023 11:33:23 AM
Trios version	5.5.1.5
Original File Name	C:\Users\ucsdi\OneDrive\Desktop\Data\Rinehart\Kyle\Jan 18 2023\KMK273_1000C_Air.tri
Current File Name	c:\users\ucsdi\onedrive\desktop\data\rinehart\kyle\jan 18 2023\kmk273_1000c_air.tri
User at run start	DESKTOP-JSQIMO4\ucsdi
[Procedure]
Procedure Name
Sample Name	KMK273_1000C_Air
Sample Mass	7.869686 mg
Pan Number	5
Reference Pan Number	30
Pan Type	Alumina 90 ul
Comments
Project Name
Operator	Kyle Kirkpatrick
Skip Weight Stabilization	False
Enable Air Cool	True
Air Cool Until Temperature Is Below	50
End of Test Delay	0
Stop on Gas Flow Error	No
Sample mass pre-weigh	Not Available
[Signal List]
Signal #1	Time (min)
Signal #2	Temperature (°C)
Signal #3	Sample Flow (mL/min)
Signal #4	Balance Flow (mL/min)
Signal #5	Set Point (°C)
Signal #6	Power Requested (W)
Signal #7	Power Delivered (W)
Signal #8	Temperature Rate (°C/min)
Signal #9	Weight (mg)
Signal #10	Heat Flow (mW)
Signal #11	Weight Corrected Heat Flow (W/g)
Signal #12	Weight Change (%)
Signal #13	Temperature Difference (°C)
Signal #14	Channel A Flow (mL/min)
Signal #15	Channel A Flow (%)
Signal #16	Channel B Flow (mL/min)
Signal #17	Channel B Flow (%)
[Configuration]
Company Name
Instrument Name	0650-0588
Instrument Type	SDT650
Serial Number	0650-0588
IP	172.23.191.35
Location of Instrument	MFG
DisplayType	TianmaV2andV3
Sample Interval 	0.1 s/pt
Gas 1	Nitrogen
Gas 2	Air
Gas 3	Oxygen
Gas 4	Nitrogen
Total Sample Flow	100
Channel B	0%
Channel A Gas Selected	1
Channel B Gas Selected	4
Thermocouple Type	Type R
Exotherm Direction	Up
Sampling Mode	Single Sample Mode
[Versions]
Common IDD Version	1
Cortex Version	VER 1.3.3.11
Driver	5.0.0.7
GDM Version	1.2.1.2
Blending GDM Version	1.2.1.2
Blending GDM Bootloader	2.0.0.5
TouchscreenVersion	1.0.3.1817
Transducer Version	1.1.0.32
Transducer Bootloader	2.0.0.5
PCU Version	1.2.0.15
PCU Bootloader	2.0.0.5
AutoSampler Version	2.0.4.19
Auto Sampler Bootloader	2.0.0.5
[Experiment Logs]
Experiment Log Entry # 1	Blending segment primary gas 4, percent 0, secondary gas 2
Experiment Log Entry # 3	Equilibrate Segment 30 (C) Started
Experiment Log Entry # 5	Ramp Segment 10 C/min to 1000 C Started
[Method Log]
Method Log Entry # 1	Blend Channel B at 100% with Channel A
Method Log Entry # 2	Equilibrate 30 °C
Method Log Entry # 3	(Ramp 601253) Ramp 10 °C/minute to 1000 °C
[Room Temperature Calibration]
Date Applied	2/24/2021 3:27:30 AM
Measured	22.351
Correct	22.200
[Furnace Room Temperature Calibration]
Date Applied	2/24/2021 3:27:30 AM
Measured	24.159
Correct	22.200
[DTA Signal Setup]
Date Applied	1/11/2023 5:48:48 PM
Description	From 200.000 °C to 1,450.000 °C at 20.000°C/min
Source Files 1	C:\Users\ucsdi\OneDrive\Desktop\Data\Sailor\Ricardo\Calibrations\1-11-23\Weight Calibration.tri
[Weight Calibration]
Date Applied	1/11/2023 5:48:48 PM
Reference Beam Weight	4892.573
Reference Beam Weight at 200 °C	435.1747
Reference Beam Gain	0.09938934
Sample Beam Weight	5794.918
Sample Beam Weight at 200 °C	439.0667
Sample Beam Gain	0.09625536
Weight Ratio	0.9274598
Reference Weight	341.1444
Sample Weight	336.5152
[Heat Flow Calibration]
Date Applied	1/12/2023 4:18:26 AM
Description	From 100.000 °C to 1,450.000 °C at 20.000°C/min
Source Files 1	C:\Users\ucsdi\OneDrive\Desktop\Data\Sailor\Ricardo\Calibrations\1-11-23\Heat Flow Sapphire Calibration(1).tri
Source Files 2	C:\Users\ucsdi\OneDrive\Desktop\Data\Sailor\Ricardo\Calibrations\1-11-23\Heat Flow Sapphire Calibration.tri
[Temperature Calibration]
Date Applied	1/11/2023 9:24:14 PM
Description	From 107.000 °C to 227.000 °C at 10.000°C/min
Gas Type	Nitrogen
Pan Type	Alumina 90 ul
Source Files 1	C:\Users\ucsdi\OneDrive\Desktop\Data\Sailor\Ricardo\Calibrations\1-11-23\Indium.tri
Source Files 2	C:\Users\ucsdi\OneDrive\Desktop\Data\Sailor\Ricardo\Calibrations\1-11-23\Zinc.tri
Source Files 3	C:\Users\ucsdi\OneDrive\Desktop\Data\Sailor\Ricardo\Calibrations\1-11-23\Tin.tri
Measured 1	155.275
Known 1	156.6
Measured 2	230.5534
Known 2	231.93
Measured 3	418.0948
Known 3	419.53
[Dual Weight]
Date Applied	1/12/2023 4:18:26 AM
[Dual DeltaT]
Date Applied	1/12/2023 4:18:26 AM
[Cell Constant Calibration]
Date Applied	4/21/2022 4:38:29 AM
Description	From 370.000 °C to 480.000 °C at 10.000°C/min
Gas Type	Nitrogen
Pan Type	Alumina 90 ul
Source Files 1	C:\Users\ucsdi\OneDrive\Desktop\Sailor\Ricardo\Calibrations\Zinc(2).tri
Cell Constant	1.029587
Temperature	419.53
[Rev Cp Calibration]
Date Applied	1/12/2023 5:11:31 PM
Description	From 210.000 °C to 1,500.000 °C at 2.000°C/min
Gas Type	Nitrogen
Pan Type	Alumina 90 ul
Source Files 1	C:\Users\ucsdi\OneDrive\Desktop\Data\Sailor\Ricardo\Calibrations\1-11-23\Sappphire calibration.tri
[step]
Ramp 10.00 °C/min to 1000.00 °C
Time	Temperature	Heat Flow (Normalized)	Weight	Heat Flow	Weight
min	°C	W/g	%	mW	mg
0.00			99.603		7.838
0.08	30.71	0.741	99.601	5.830	7.838
0.15	30.67	0.741	99.598	5.835	7.838
0.23	30.64	0.742	99.596	5.839	7.838
0.31	30.63	0.741	99.595	5.834	7.838
0.38	30.68	0.736	99.596	5.789	7.838
0.46	30.81	0.721	99.599	5.678	7.838
0.54	31.01	0.702	99.601	5.524	7.838
0.61	31.30	0.679	99.604	5.341	7.839
0.69	31.68	0.651	99.606	5.124	7.839
0.77	32.13	0.622	99.609	4.898	7.839
0.84	32.67	0.592	99.611	4.658	7.839
0.92	33.29	0.562	99.613	4.419	7.839
1.00	33.96	0.532	99.614	4.186	7.839
1.07	34.70	0.504	99.615	3.964	7.839
1.15	35.48	0.479	99.615	3.767	7.839
1.23	36.30	0.455	99.614	3.584	7.839
1.30	37.15	0.434	99.613	3.418	7.839
1.38	38.02	0.416	99.611	3.275	7.839
1.46	38.91	0.400	99.608	3.148	7.839
1.53	39.79	0.386	99.605	3.037	7.839
1.61	40.69	0.375	99.601	2.948	7.838
1.69	41.57	0.365	99.598	2.872	7.838
1.76	42.45	0.358	99.593	2.821	7.838
1.84	43.32	0.352	99.588	2.773	7.837
1.92	44.17	0.348	99.583	2.740	7.837
1.99	45.00	0.346	99.576	2.722	7.836
2.07	45.83	0.344	99.570	2.711	7.836
2.15	46.63	0.344	99.562	2.705	7.835
2.22	47.42	0.344	99.555	2.705	7.835
2.30	48.20	0.345	99.547	2.715	7.834
2.38	48.97	0.347	99.539	2.733	7.833
2.45	49.72	0.351	99.530	2.761	7.833
2.53	50.46	0.355	99.521	2.796	7.832
2.61	51.20	0.361	99.512	2.844	7.831
2.68	51.93	0.368	99.503	2.898	7.831
2.76	52.65	0.375	99.493	2.948	7.830
2.84	53.37	0.382	99.484	3.006	7.829
2.91	54.09	0.388	99.474	3.054	7.828
2.99	54.81	0.395	99.464	3.105	7.828
3.07	55.53	0.402	99.454	3.161	7.827
3.14	56.25	0.409	99.444	3.216	7.826
3.22	56.98	0.415	99.434	3.268	7.825
3.30	57.70	0.422	99.423	3.324	7.824
3.37	58.44	0.428	99.413	3.370	7.823
3.45	59.17	0.435	99.402	3.421	7.823
3.53	59.91	0.441	99.392	3.473	7.822
3.60	60.65	0.447	99.381	3.517	7.821
3.68	61.40	0.454	99.370	3.571	7.820
3.76	62.15	0.460	99.358	3.624	7.819
3.83	62.90	0.467	99.347	3.676	7.818
3.91	63.66	0.473	99.336	3.723	7.817
3.99	64.42	0.481	99.324	3.782	7.816
4.06	65.18	0.487	99.312	3.836	7.816
4.14	65.95	0.494	99.300	3.884	7.815
4.22	66.71	0.500	99.288	3.931	7.814
4.29	67.48	0.507	99.276	3.989	7.813
4.37	68.25	0.513	99.264	4.037	7.812
4.45	69.02	0.520	99.251	4.090	7.811
4.52	69.79	0.528	99.239	4.153	7.810
4.60	70.56	0.535	99.226	4.209	7.809
4.68	71.33	0.542	99.213	4.263	7.808
4.75	72.10	0.549	99.200	4.317	7.807
4.83	72.87	0.556	99.187	4.374	7.806
4.91	73.64	0.565	99.174	4.443	7.805
4.98	74.41	0.572	99.161	4.499	7.804
5.06	75.18	0.579	99.148	4.555	7.803
5.14	75.95	0.587	99.134	4.617	7.802
5.21	76.72	0.595	99.121	4.681	7.801
5.29	77.48	0.603	99.108	4.744	7.799
5.37	78.25	0.612	99.094	4.814	7.798
5.44	79.01	0.619	99.081	4.873	7.797
5.52	79.78	0.628	99.067	4.942	7.796
5.60	80.54	0.636	99.054	5.006	7.795
5.67	81.31	0.645	99.041	5.077	7.794
5.75	82.07	0.654	99.027	5.146	7.793
5.83	82.83	0.663	99.014	5.217	7.792
5.90	83.60	0.672	99.000	5.290	7.791
5.98	84.36	0.681	98.987	5.359	7.790
6.06	85.13	0.691	98.973	5.435	7.789
6.13	85.89	0.699	98.959	5.502	7.788
6.21	86.66	0.708	98.946	5.575	7.787
6.29	87.42	0.718	98.933	5.650	7.786
6.36	88.19	0.728	98.920	5.726	7.785
6.44	88.96	0.737	98.907	5.803	7.784
6.52	89.72	0.748	98.893	5.885	7.783
6.59	90.49	0.758	98.880	5.962	7.782
6.67	91.25	0.767	98.868	6.033	7.781
6.75	92.02	0.776	98.855	6.109	7.780
6.82	92.79	0.787	98.843	6.194	7.779
6.90	93.56	0.798	98.830	6.277	7.778
6.98	94.33	0.806	98.817	6.343	7.777
7.05	95.09	0.817	98.805	6.428	7.776
7.13	95.86	0.828	98.792	6.516	7.775
7.21	96.63	0.838	98.780	6.594	7.774
7.28	97.40	0.848	98.768	6.671	7.773
7.36	98.17	0.859	98.756	6.758	7.772
7.44	98.94	0.868	98.744	6.833	7.771
7.51	99.71	0.879	98.732	6.918	7.770
7.59	100.48	0.890	98.719	7.005	7.769
7.67	101.25	0.901	98.707	7.091	7.768
7.74	102.01	0.911	98.695	7.173	7.767
7.82	102.78	0.922	98.684	7.254	7.766
7.90	103.55	0.933	98.672	7.343	7.765
7.97	104.32	0.944	98.661	7.433	7.764
8.05	105.09	0.955	98.649	7.519	7.763
8.13	105.86	0.966	98.637	7.602	7.762
8.20	106.63	0.977	98.626	7.692	7.762
8.28	107.40	0.989	98.614	7.782	7.761
8.36	108.17	1.000	98.603	7.873	7.760
8.43	108.94	1.012	98.592	7.964	7.759
8.51	109.71	1.023	98.581	8.049	7.758
8.59	110.48	1.035	98.570	8.144	7.757
8.66	111.25	1.047	98.559	8.238	7.756
8.74	112.02	1.058	98.548	8.328	7.755
8.82	112.79	1.070	98.538	8.423	7.755
8.89	113.56	1.082	98.527	8.518	7.754
8.97	114.33	1.094	98.516	8.607	7.753
9.05	115.10	1.106	98.506	8.704	7.752
9.12	115.87	1.118	98.495	8.799	7.751
9.20	116.64	1.130	98.485	8.895	7.750
9.28	117.41	1.142	98.475	8.989	7.750
9.35	118.18	1.155	98.465	9.086	7.749
9.43	118.95	1.168	98.455	9.189	7.748
9.51	119.71	1.179	98.446	9.277	7.747
9.58	120.49	1.192	98.436	9.380	7.747
9.66	121.26	1.204	98.426	9.477	7.746
9.74	122.02	1.216	98.417	9.573	7.745
9.81	122.79	1.228	98.407	9.663	7.744
9.89	123.56	1.241	98.398	9.765	7.744
9.97	124.33	1.252	98.389	9.856	7.743
10.04	125.10	1.265	98.379	9.955	7.742
10.12	125.87	1.278	98.370	10.056	7.741
10.20	126.64	1.291	98.361	10.159	7.741
10.27	127.41	1.303	98.352	10.257	7.740
10.35	128.18	1.317	98.343	10.363	7.739
10.43	128.95	1.330	98.334	10.467	7.739
10.50	129.72	1.342	98.325	10.563	7.738
10.58	130.49	1.355	98.316	10.663	7.737
10.66	131.26	1.368	98.307	10.765	7.736
10.73	132.03	1.381	98.298	10.872	7.736
10.81	132.80	1.395	98.289	10.980	7.735
10.89	133.57	1.408	98.281	11.083	7.734
10.96	134.34	1.421	98.272	11.181	7.734
11.04	135.11	1.435	98.264	11.289	7.733
11.12	135.88	1.448	98.255	11.395	7.732
11.19	136.65	1.462	98.247	11.502	7.732
11.27	137.42	1.475	98.239	11.609	7.731
11.35	138.19	1.488	98.231	11.709	7.730
11.42	138.96	1.502	98.222	11.820	7.730
11.50	139.73	1.515	98.214	11.926	7.729
11.58	140.50	1.529	98.206	12.030	7.728
11.65	141.27	1.543	98.198	12.140	7.728
11.73	142.04	1.556	98.190	12.245	7.727
11.81	142.81	1.570	98.182	12.353	7.727
11.88	143.58	1.583	98.174	12.460	7.726
11.96	144.35	1.597	98.166	12.571	7.725
12.04	145.12	1.611	98.159	12.678	7.725
12.11	145.88	1.625	98.151	12.785	7.724
12.19	146.65	1.638	98.144	12.891	7.724
12.27	147.42	1.651	98.136	12.997	7.723
12.34	148.19	1.666	98.129	13.112	7.722
12.42	148.96	1.680	98.121	13.218	7.722
12.50	149.73	1.694	98.113	13.330	7.721
12.57	150.50	1.708	98.105	13.442	7.721
12.65	151.27	1.722	98.098	13.550	7.720
12.73	152.04	1.736	98.090	13.659	7.719
12.80	152.81	1.749	98.083	13.766	7.719
12.88	153.58	1.765	98.075	13.888	7.718
12.96	154.35	1.779	98.067	14.001	7.718
13.03	155.12	1.794	98.060	14.115	7.717
13.11	155.89	1.808	98.052	14.228	7.716
13.19	156.66	1.823	98.044	14.345	7.716
13.26	157.43	1.837	98.036	14.457	7.715
13.34	158.20	1.852	98.029	14.575	7.715
13.42	158.97	1.867	98.021	14.694	7.714
13.49	159.74	1.882	98.013	14.811	7.713
13.57	160.51	1.897	98.005	14.931	7.713
13.65	161.28	1.912	97.997	15.050	7.712
13.72	162.05	1.927	97.989	15.166	7.711
13.80	162.82	1.943	97.982	15.288	7.711
13.88	163.59	1.958	97.974	15.407	7.710
13.95	164.36	1.972	97.966	15.521	7.710
14.03	165.12	1.987	97.958	15.640	7.709
14.11	165.89	2.002	97.950	15.758	7.708
14.18	166.66	2.017	97.941	15.874	7.708
14.26	167.43	2.033	97.933	16.000	7.707
14.34	168.20	2.049	97.925	16.126	7.706
14.41	168.97	2.064	97.917	16.242	7.706
14.49	169.74	2.080	97.909	16.371	7.705
14.57	170.51	2.095	97.900	16.489	7.704
14.64	171.28	2.111	97.892	16.617	7.704
14.72	172.05	2.127	97.884	16.741	7.703
14.80	172.82	2.144	97.875	16.874	7.702
14.87	173.59	2.159	97.867	16.994	7.702
14.95	174.36	2.176	97.858	17.126	7.701
15.03	175.13	2.193	97.849	17.256	7.700
15.10	175.90	2.209	97.840	17.387	7.700
15.18	176.67	2.226	97.831	17.520	7.699
15.26	177.44	2.243	97.822	17.650	7.698
15.33	178.21	2.260	97.813	17.782	7.698
15.41	178.98	2.276	97.804	17.910	7.697
15.49	179.75	2.294	97.795	18.050	7.696
15.56	180.52	2.311	97.785	18.184	7.695
15.64	181.29	2.327	97.776	18.311	7.695
15.72	182.06	2.343	97.766	18.439	7.694
15.79	182.83	2.361	97.756	18.584	7.693
15.87	183.61	2.379	97.746	18.722	7.692
15.95	184.38	2.397	97.736	18.863	7.692
16.02	185.15	2.414	97.726	19.000	7.691
16.10	185.92	2.432	97.715	19.136	7.690
16.18	186.69	2.450	97.705	19.278	7.689
16.25	187.46	2.468	97.694	19.425	7.688
16.33	188.23	2.487	97.683	19.572	7.687
16.41	189.00	2.505	97.672	19.713	7.686
16.48	189.77	2.524	97.661	19.861	7.686
16.56	190.54	2.542	97.649	20.008	7.685
16.64	191.31	2.561	97.637	20.152	7.684
16.71	192.08	2.581	97.625	20.309	7.683
16.79	192.85	2.600	97.613	20.461	7.682
16.87	193.63	2.619	97.601	20.612	7.681
16.94	194.40	2.639	97.588	20.765	7.680
17.02	195.17	2.658	97.576	20.921	7.679
17.10	195.94	2.678	97.563	21.077	7.678
17.17	196.71	2.698	97.549	21.233	7.677
17.25	197.48	2.717	97.536	21.385	7.676
17.33	198.26	2.738	97.522	21.546	7.675
17.40	199.03	2.758	97.508	21.706	7.674
17.48	199.80	2.778	97.494	21.863	7.672
17.56	200.57	2.800	97.479	22.033	7.671
17.63	201.35	2.821	97.464	22.202	7.670
17.71	202.12	2.842	97.448	22.363	7.669
17.79	202.89	2.863	97.433	22.534	7.668
17.86	203.67	2.885	97.417	22.706	7.666
17.94	204.44	2.907	97.401	22.879	7.665
18.02	205.21	2.929	97.384	23.051	7.664
18.09	205.99	2.952	97.367	23.234	7.662
18.17	206.76	2.975	97.350	23.413	7.661
18.25	207.54	2.997	97.332	23.589	7.660
18.32	208.31	3.020	97.314	23.763	7.658
18.40	209.08	3.042	97.296	23.942	7.657
18.48	209.86	3.065	97.277	24.120	7.655
18.55	210.63	3.089	97.258	24.309	7.654
18.63	211.41	3.113	97.238	24.496	7.652
18.71	212.18	3.136	97.218	24.681	7.651
18.78	212.96	3.160	97.198	24.869	7.649
18.86	213.73	3.184	97.176	25.057	7.647
18.94	214.51	3.208	97.155	25.248	7.646
19.01	215.28	3.233	97.132	25.446	7.644
19.09	216.06	3.259	97.110	25.645	7.642
19.17	216.83	3.284	97.087	25.841	7.640
19.24	217.61	3.309	97.063	26.043	7.639
19.32	218.38	3.336	97.039	26.253	7.637
19.40	219.16	3.362	97.014	26.460	7.635
19.47	219.93	3.389	96.989	26.668	7.633
19.55	220.71	3.415	96.963	26.879	7.631
19.63	221.49	3.443	96.937	27.097	7.629
19.70	222.26	3.471	96.910	27.314	7.627
19.78	223.04	3.499	96.882	27.538	7.624
19.86	223.81	3.527	96.854	27.759	7.622
19.93	224.59	3.556	96.826	27.984	7.620
20.01	225.37	3.585	96.797	28.210	7.618
20.09	226.14	3.613	96.767	28.437	7.615
20.16	226.92	3.643	96.737	28.668	7.613
20.24	227.70	3.673	96.706	28.903	7.610
20.32	228.47	3.702	96.675	29.136	7.608
20.39	229.25	3.733	96.643	29.375	7.606
20.47	230.03	3.763	96.611	29.615	7.603
20.55	230.81	3.794	96.579	29.858	7.600
20.62	231.58	3.826	96.545	30.110	7.598
20.70	232.36	3.858	96.512	30.360	7.595
20.78	233.14	3.891	96.478	30.619	7.592
20.85	233.92	3.924	96.443	30.878	7.590
20.93	234.70	3.957	96.409	31.142	7.587
21.01	235.48	3.991	96.374	31.407	7.584
21.08	236.26	4.026	96.339	31.681	7.582
21.16	237.04	4.061	96.304	31.962	7.579
21.24	237.82	4.098	96.269	32.249	7.576
21.31	238.60	4.134	96.234	32.530	7.573
21.39	239.38	4.171	96.198	32.822	7.571
21.47	240.16	4.208	96.163	33.120	7.568
21.54	240.94	4.247	96.127	33.422	7.565
21.62	241.72	4.286	96.092	33.726	7.562
21.70	242.50	4.325	96.056	34.036	7.559
21.77	243.28	4.365	96.020	34.352	7.556
21.85	244.07	4.406	95.984	34.675	7.554
21.93	244.85	4.447	95.947	34.996	7.551
22.00	245.63	4.489	95.911	35.330	7.548
22.08	246.42	4.533	95.874	35.670	7.545
22.16	247.20	4.575	95.836	36.006	7.542
22.23	247.98	4.620	95.799	36.356	7.539
22.31	248.77	4.665	95.761	36.710	7.536
22.39	249.55	4.710	95.722	37.064	7.533
22.46	250.34	4.757	95.684	37.434	7.530
22.54	251.13	4.803	95.645	37.798	7.527
22.62	251.91	4.851	95.605	38.175	7.524
22.69	252.70	4.900	95.566	38.562	7.521
22.77	253.49	4.950	95.526	38.954	7.518
22.85	254.27	5.000	95.485	39.351	7.514
22.92	255.06	5.051	95.445	39.750	7.511
23.00	255.85	5.103	95.403	40.158	7.508
23.08	256.64	5.156	95.361	40.573	7.505
23.15	257.42	5.209	95.319	40.989	7.501
23.23	258.21	5.264	95.277	41.422	7.498
23.31	259.00	5.319	95.233	41.861	7.495
23.38	259.79	5.376	95.190	42.306	7.491
23.46	260.58	5.432	95.145	42.751	7.488
23.54	261.38	5.491	95.101	43.209	7.484
23.61	262.17	5.551	95.055	43.686	7.481
23.69	262.96	5.611	95.009	44.158	7.477
23.77	263.75	5.672	94.963	44.638	7.473
23.84	264.54	5.735	94.916	45.135	7.470
23.92	265.34	5.799	94.869	45.637	7.466
24.00	266.13	5.864	94.821	46.146	7.462
24.07	266.93	5.929	94.772	46.662	7.458
24.15	267.72	5.996	94.723	47.188	7.454
24.23	268.52	6.063	94.673	47.715	7.450
24.30	269.32	6.132	94.623	48.257	7.446
24.38	270.11	6.202	94.571	48.805	7.442
24.46	270.91	6.272	94.519	49.363	7.438
24.53	271.71	6.344	94.467	49.927	7.434
24.61	272.51	6.417	94.413	50.500	7.430
24.69	273.30	6.491	94.359	51.082	7.426
24.76	274.10	6.566	94.304	51.672	7.421
24.84	274.90	6.641	94.249	52.265	7.417
24.92	275.70	6.718	94.193	52.870	7.413
24.99	276.50	6.795	94.136	53.474	7.408
25.07	277.30	6.873	94.078	54.092	7.404
25.15	278.10	6.953	94.019	54.716	7.399
25.22	278.90	7.033	93.959	55.345	7.394
25.30	279.71	7.114	93.899	55.985	7.390
25.38	280.51	7.196	93.837	56.628	7.385
25.45	281.31	7.278	93.774	57.278	7.380
25.53	282.11	7.361	93.711	57.926	7.375
25.61	282.92	7.444	93.646	58.580	7.370
25.68	283.72	7.527	93.580	59.232	7.364
25.76	284.52	7.610	93.513	59.888	7.359
25.84	285.32	7.692	93.445	60.532	7.354
25.91	286.12	7.774	93.376	61.182	7.348
25.99	286.92	7.856	93.305	61.828	7.343
26.07	287.72	7.937	93.234	62.465	7.337
26.14	288.52	8.018	93.162	63.095	7.332
26.22	289.32	8.096	93.088	63.716	7.326
26.30	290.12	8.175	93.014	64.337	7.320
26.37	290.92	8.252	92.937	64.941	7.314
26.45	291.72	8.328	92.860	65.539	7.308
26.53	292.51	8.402	92.781	66.123	7.302
26.60	293.31	8.475	92.702	66.698	7.295
26.68	294.10	8.548	92.621	67.266	7.289
26.76	294.90	8.619	92.538	67.825	7.282
26.83	295.69	8.688	92.455	68.373	7.276
26.91	296.48	8.756	92.370	68.906	7.269
26.99	297.27	8.823	92.284	69.433	7.262
27.06	298.07	8.889	92.197	69.950	7.256
27.14	298.86	8.953	92.108	70.461	7.249
27.22	299.65	9.018	92.019	70.965	7.242
27.29	300.44	9.080	91.928	71.454	7.234
27.37	301.23	9.141	91.836	71.938	7.227
27.45	302.02	9.202	91.743	72.413	7.220
27.52	302.80	9.261	91.648	72.878	7.212
27.60	303.59	9.320	91.552	73.347	7.205
27.68	304.38	9.379	91.455	73.808	7.197
27.75	305.17	9.437	91.357	74.263	7.189
27.83	305.95	9.495	91.257	74.719	7.182
27.91	306.74	9.552	91.156	75.170	7.174
27.98	307.53	9.610	91.053	75.626	7.166
28.06	308.32	9.667	90.949	76.078	7.157
28.14	309.10	9.725	90.843	76.535	7.149
28.21	309.89	9.783	90.735	76.990	7.141
28.29	310.68	9.841	90.627	77.448	7.132
28.37	311.47	9.900	90.517	77.913	7.123
28.44	312.25	9.959	90.402	78.378	7.114
28.52	313.04	10.020	90.288	78.856	7.105
28.60	313.83	10.081	90.172	79.333	7.096
28.67	314.62	10.143	90.054	79.823	7.087
28.75	315.41	10.205	89.933	80.312	7.077
28.83	316.20	10.268	89.807	80.809	7.068
28.90	316.99	10.332	89.679	81.311	7.057
28.98	317.78	10.397	89.549	81.823	7.047
29.06	318.57	10.463	89.418	82.342	7.037
29.13	319.36	10.529	89.284	82.857	7.026
29.21	320.15	10.595	89.150	83.379	7.016
29.29	320.94	10.663	89.012	83.914	7.005
29.36	321.74	10.731	88.872	84.449	6.994
29.44	322.53	10.799	88.731	84.982	6.983
29.52	323.32	10.867	88.589	85.520	6.972
29.59	324.11	10.935	88.446	86.054	6.960
29.67	324.90	11.002	88.300	86.580	6.949
29.75	325.69	11.067	88.153	87.097	6.937
29.82	326.48	11.133	88.004	87.612	6.926
29.90	327.27	11.197	87.855	88.119	6.914
29.98	328.06	11.260	87.704	88.612	6.902
30.05	328.85	11.321	87.552	89.096	6.890
30.13	329.63	11.382	87.400	89.569	6.878
30.21	330.42	11.440	87.248	90.028	6.866
30.28	331.20	11.494	87.095	90.457	6.854
30.36	331.98	11.546	86.940	90.864	6.842
30.44	332.76	11.594	86.785	91.242	6.830
30.51	333.54	11.638	86.631	91.588	6.818
30.59	334.32	11.677	86.476	91.895	6.805
30.67	335.09	11.712	86.321	92.167	6.793
30.74	335.86	11.740	86.167	92.392	6.781
30.82	336.63	11.764	86.013	92.575	6.769
30.90	337.40	11.780	85.860	92.708	6.757
30.97	338.16	11.792	85.707	92.798	6.745
31.05	338.91	11.799	85.556	92.851	6.733
31.13	339.67	11.796	85.406	92.827	6.721
31.20	340.42	11.782	85.260	92.717	6.710
31.28	341.17	11.762	85.112	92.563	6.698
31.36	341.91	11.735	84.967	92.353	6.687
31.43	342.65	11.701	84.824	92.083	6.675
31.51	343.38	11.659	84.683	91.755	6.664
31.59	344.12	11.610	84.544	91.369	6.653
31.66	344.84	11.555	84.407	90.934	6.643
31.74	345.57	11.493	84.274	90.444	6.632
31.82	346.29	11.423	84.143	89.895	6.622
31.89	347.01	11.348	84.013	89.302	6.612
31.97	347.73	11.267	83.886	88.664	6.602
32.05	348.44	11.180	83.763	87.982	6.592
32.12	349.16	11.087	83.641	87.250	6.582
32.20	349.87	10.990	83.522	86.488	6.573
32.28	350.58	10.888	83.403	85.688	6.564
32.35	351.28	10.783	83.290	84.856	6.555
32.43	351.98	10.672	83.179	83.989	6.546
32.51	352.69	10.559	83.068	83.098	6.537
32.58	353.39	10.444	82.957	82.188	6.528
32.66	354.09	10.325	82.847	81.258	6.520
32.74	354.79	10.204	82.738	80.302	6.511
32.81	355.49	10.082	82.630	79.339	6.503
32.89	356.19	9.957	82.525	78.359	6.494
32.97	356.89	9.831	82.421	77.369	6.486
33.04	357.59	9.704	82.319	76.366	6.478
33.12	358.28	9.575	82.218	75.349	6.470
33.20	358.98	9.445	82.121	74.329	6.463
33.27	359.68	9.315	82.025	73.305	6.455
33.35	360.38	9.184	81.932	72.277	6.448
33.43	361.08	9.053	81.841	71.242	6.441
33.50	361.77	8.922	81.752	70.214	6.434
33.58	362.47	8.790	81.665	69.178	6.427
33.66	363.17	8.658	81.581	68.137	6.420
33.73	363.87	8.527	81.498	67.102	6.414
33.81	364.57	8.396	81.418	66.071	6.407
33.89	365.27	8.264	81.339	65.035	6.401
33.96	365.96	8.133	81.263	64.003	6.395
34.04	366.66	8.002	81.188	62.976	6.389
34.12	367.36	7.871	81.116	61.945	6.384
34.19	368.06	7.742	81.046	60.928	6.378
34.27	368.76	7.613	80.977	59.911	6.373
34.35	369.46	7.485	80.911	58.903	6.367
34.42	370.16	7.357	80.846	57.894	6.362
34.50	370.87	7.229	80.783	56.891	6.357
34.58	371.57	7.102	80.721	55.893	6.353
34.65	372.27	6.976	80.662	54.902	6.348
34.73	372.98	6.852	80.604	53.925	6.343
34.81	373.68	6.730	80.548	52.959	6.339
34.88	374.39	6.607	80.494	51.997	6.335
34.96	375.09	6.486	80.441	51.046	6.330
35.04	375.80	6.366	80.390	50.097	6.326
35.11	376.51	6.247	80.341	49.162	6.323
35.19	377.22	6.130	80.293	48.241	6.319
35.27	377.92	6.014	80.247	47.330	6.315
35.34	378.63	5.899	80.202	46.427	6.312
35.42	379.35	5.788	80.159	45.547	6.308
35.50	380.06	5.677	80.118	44.677	6.305
35.57	380.77	5.568	80.078	43.817	6.302
35.65	381.48	5.460	80.039	42.972	6.299
35.73	382.20	5.356	80.001	42.149	6.296
35.80	382.92	5.254	79.965	41.344	6.293
35.88	383.63	5.154	79.930	40.557	6.290
35.96	384.35	5.056	79.897	39.791	6.288
36.03	385.07	4.962	79.865	39.046	6.285
36.11	385.79	4.870	79.834	38.322	6.283
36.19	386.52	4.781	79.804	37.621	6.280
36.26	387.24	4.694	79.775	36.938	6.278
36.34	387.96	4.610	79.747	36.283	6.276
36.42	388.69	4.531	79.720	35.656	6.274
36.49	389.42	4.453	79.694	35.046	6.272
36.57	390.15	4.380	79.669	34.467	6.270
36.65	390.89	4.309	79.645	33.908	6.268
36.72	391.62	4.241	79.622	33.378	6.266
36.80	392.35	4.176	79.599	32.866	6.264
36.88	393.09	4.114	79.578	32.375	6.263
36.95	393.82	4.055	79.557	31.910	6.261
37.03	394.56	3.999	79.536	31.471	6.259
37.11	395.30	3.945	79.517	31.044	6.258
37.18	396.04	3.894	79.498	30.645	6.256
37.26	396.78	3.846	79.480	30.265	6.255
37.34	397.53	3.798	79.462	29.891	6.253
37.41	398.27	3.753	79.445	29.536	6.252
37.49	399.02	3.710	79.427	29.193	6.251
37.57	399.76	3.668	79.411	28.866	6.249
37.64	400.51	3.628	79.395	28.548	6.248
37.72	401.26	3.588	79.379	28.239	6.247
37.80	402.01	3.551	79.364	27.947	6.246
37.87	402.75	3.515	79.349	27.659	6.245
37.95	403.50	3.479	79.334	27.375	6.243
38.03	404.25	3.443	79.320	27.095	6.242
38.10	405.00	3.407	79.306	26.815	6.241
38.18	405.75	3.374	79.292	26.552	6.240
38.26	406.50	3.339	79.279	26.281	6.239
38.33	407.25	3.305	79.267	26.011	6.238
38.41	408.00	3.271	79.254	25.738	6.237
38.49	408.75	3.235	79.242	25.457	6.236
38.56	409.50	3.199	79.231	25.176	6.235
38.64	410.24	3.163	79.219	24.888	6.234
38.72	410.99	3.126	79.208	24.599	6.233
38.79	411.74	3.089	79.197	24.310	6.233
38.87	412.49	3.050	79.186	24.006	6.232
38.95	413.24	3.013	79.176	23.714	6.231
39.02	413.98	2.975	79.167	23.415	6.230
39.10	414.73	2.937	79.157	23.115	6.229
39.18	415.48	2.899	79.148	22.814	6.229
39.25	416.23	2.861	79.139	22.514	6.228
39.33	416.98	2.823	79.131	22.215	6.227
39.41	417.72	2.785	79.123	21.918	6.227
39.48	418.47	2.748	79.115	21.626	6.226
39.56	419.22	2.712	79.107	21.344	6.225
39.64	419.97	2.677	79.100	21.069	6.225
39.71	420.72	2.643	79.093	20.796	6.224
39.79	421.47	2.608	79.086	20.527	6.224
39.87	422.22	2.574	79.080	20.255	6.223
39.94	422.97	2.541	79.073	19.997	6.223
40.02	423.72	2.508	79.068	19.736	6.222
40.10	424.47	2.476	79.062	19.485	6.222
40.17	425.22	2.445	79.056	19.240	6.221
40.25	425.97	2.415	79.051	19.008	6.221
40.33	426.73	2.386	79.046	18.776	6.221
40.40	427.48	2.359	79.041	18.561	6.220
40.48	428.23	2.333	79.037	18.361	6.220
40.56	428.99	2.307	79.033	18.157	6.220
40.63	429.74	2.283	79.029	17.963	6.219
40.71	430.50	2.260	79.025	17.782	6.219
40.79	431.25	2.238	79.021	17.614	6.219
40.86	432.01	2.217	79.017	17.450	6.218
40.94	432.77	2.199	79.014	17.306	6.218
41.02	433.52	2.181	79.011	17.161	6.218
41.09	434.28	2.162	79.007	17.017	6.218
41.17	435.04	2.146	79.004	16.888	6.217
41.25	435.80	2.131	79.001	16.769	6.217
41.32	436.55	2.116	78.998	16.654	6.217
41.40	437.31	2.102	78.995	16.542	6.217
41.48	438.07	2.089	78.992	16.437	6.216
41.55	438.83	2.077	78.990	16.345	6.216
41.63	439.59	2.064	78.987	16.245	6.216
41.71	440.35	2.053	78.985	16.156	6.216
41.78	441.11	2.041	78.982	16.066	6.216
41.86	441.88	2.032	78.980	15.993	6.215
41.94	442.63	2.022	78.977	15.911	6.215
42.01	443.40	2.012	78.975	15.836	6.215
42.09	444.16	2.004	78.973	15.768	6.215
42.17	444.92	1.995	78.971	15.696	6.215
42.24	445.68	1.987	78.969	15.640	6.215
42.32	446.44	1.979	78.967	15.575	6.214
42.40	447.20	1.972	78.965	15.517	6.214
42.47	447.96	1.964	78.963	15.457	6.214
42.55	448.72	1.956	78.961	15.397	6.214
42.63	449.49	1.949	78.959	15.339	6.214
42.70	450.25	1.943	78.957	15.292	6.214
42.78	451.01	1.937	78.955	15.245	6.213
42.86	451.77	1.931	78.953	15.194	6.213
42.93	452.53	1.923	78.951	15.134	6.213
43.01	453.30	1.918	78.949	15.091	6.213
43.09	454.06	1.912	78.947	15.044	6.213
43.16	454.82	1.905	78.945	14.994	6.213
43.24	455.58	1.898	78.943	14.940	6.213
43.32	456.35	1.893	78.941	14.901	6.212
43.39	457.11	1.889	78.939	14.864	6.212
43.47	457.87	1.883	78.937	14.815	6.212
43.55	458.64	1.876	78.936	14.764	6.212
43.62	459.40	1.870	78.934	14.716	6.212
43.70	460.16	1.865	78.932	14.673	6.212
43.78	460.92	1.857	78.930	14.612	6.212
43.85	461.69	1.851	78.929	14.564	6.211
43.93	462.45	1.844	78.927	14.511	6.211
44.01	463.21	1.838	78.925	14.468	6.211
44.08	463.97	1.832	78.923	14.414	6.211
44.16	464.73	1.826	78.922	14.367	6.211
44.24	465.50	1.821	78.920	14.328	6.211
44.31	466.26	1.814	78.918	14.279	6.211
44.39	467.02	1.807	78.917	14.224	6.211
44.47	467.78	1.802	78.915	14.179	6.210
44.54	468.55	1.796	78.914	14.136	6.210
44.62	469.31	1.790	78.912	14.089	6.210
44.70	470.07	1.783	78.911	14.034	6.210
44.77	470.83	1.777	78.909	13.985	6.210
44.85	471.60	1.770	78.908	13.932	6.210
44.93	472.36	1.765	78.906	13.891	6.210
45.00	473.12	1.759	78.904	13.846	6.210
45.08	473.88	1.753	78.903	13.799	6.209
45.16	474.65	1.747	78.901	13.747	6.209
45.23	475.41	1.741	78.900	13.698	6.209
45.31	476.17	1.735	78.898	13.651	6.209
45.39	476.93	1.728	78.897	13.601	6.209
45.46	477.70	1.722	78.895	13.551	6.209
45.54	478.46	1.716	78.894	13.501	6.209
45.62	479.22	1.709	78.893	13.448	6.209
45.69	479.98	1.703	78.891	13.404	6.208
45.77	480.75	1.697	78.890	13.353	6.208
45.85	481.51	1.690	78.888	13.303	6.208
45.92	482.27	1.684	78.886	13.249	6.208
46.00	483.04	1.678	78.885	13.209	6.208
46.08	483.80	1.672	78.883	13.155	6.208
46.15	484.56	1.665	78.882	13.102	6.208
46.23	485.32	1.658	78.881	13.052	6.208
46.31	486.09	1.653	78.879	13.009	6.208
46.38	486.85	1.646	78.878	12.954	6.207
46.46	487.61	1.639	78.877	12.897	6.207
46.54	488.37	1.633	78.875	12.850	6.207
46.61	489.14	1.626	78.874	12.798	6.207
46.69	489.90	1.618	78.873	12.737	6.207
46.77	490.66	1.611	78.871	12.681	6.207
46.84	491.42	1.605	78.870	12.634	6.207
46.92	492.19	1.598	78.868	12.572	6.207
47.00	492.95	1.591	78.867	12.521	6.207
47.07	493.71	1.585	78.865	12.472	6.206
47.15	494.48	1.579	78.864	12.425	6.206
47.23	495.24	1.571	78.863	12.362	6.206
47.30	496.00	1.563	78.861	12.299	6.206
47.38	496.76	1.556	78.860	12.246	6.206
47.46	497.53	1.550	78.859	12.195	6.206
47.53	498.29	1.542	78.857	12.136	6.206
47.61	499.05	1.534	78.856	12.072	6.206
47.69	499.82	1.527	78.855	12.017	6.206
47.76	500.58	1.520	78.854	11.962	6.206
47.84	501.34	1.513	78.852	11.906	6.205
47.92	502.10	1.506	78.851	11.852	6.205
47.99	502.87	1.499	78.850	11.800	6.205
48.07	503.63	1.491	78.849	11.736	6.205
48.15	504.39	1.484	78.848	11.679	6.205
48.22	505.16	1.477	78.847	11.625	6.205
48.30	505.92	1.470	78.845	11.570	6.205
48.38	506.68	1.463	78.844	11.513	6.205
48.45	507.45	1.454	78.843	11.444	6.205
48.53	508.21	1.448	78.842	11.393	6.205
48.61	508.97	1.441	78.841	11.341	6.205
48.68	509.73	1.434	78.839	11.286	6.204
48.76	510.50	1.425	78.838	11.214	6.204
48.84	511.26	1.418	78.837	11.157	6.204
48.91	512.02	1.410	78.836	11.098	6.204
48.99	512.78	1.403	78.835	11.039	6.204
49.07	513.55	1.394	78.834	10.970	6.204
49.14	514.31	1.387	78.833	10.913	6.204
49.22	515.07	1.380	78.831	10.860	6.204
49.30	515.84	1.372	78.831	10.800	6.204
49.37	516.60	1.365	78.830	10.743	6.204
49.45	517.36	1.357	78.828	10.679	6.204
49.53	518.13	1.349	78.827	10.613	6.203
49.60	518.89	1.340	78.826	10.546	6.203
49.68	519.65	1.333	78.825	10.490	6.203
49.76	520.41	1.325	78.823	10.425	6.203
49.83	521.18	1.317	78.822	10.368	6.203
49.91	521.94	1.308	78.821	10.297	6.203
49.99	522.70	1.300	78.820	10.230	6.203
50.06	523.47	1.293	78.819	10.179	6.203
50.14	524.23	1.286	78.818	10.122	6.203
50.22	524.99	1.279	78.817	10.065	6.203
50.29	525.75	1.270	78.816	9.994	6.203
50.37	526.52	1.262	78.815	9.929	6.202
50.45	527.28	1.254	78.814	9.868	6.202
50.52	528.04	1.245	78.813	9.799	6.202
50.60	528.81	1.237	78.812	9.736	6.202
50.68	529.57	1.230	78.811	9.677	6.202
50.75	530.33	1.221	78.809	9.611	6.202
50.83	531.09	1.213	78.808	9.542	6.202
50.91	531.86	1.204	78.807	9.473	6.202
50.98	532.62	1.195	78.806	9.404	6.202
51.06	533.38	1.188	78.805	9.349	6.202
51.14	534.15	1.180	78.804	9.283	6.202
51.21	534.91	1.171	78.803	9.218	6.202
51.29	535.67	1.164	78.802	9.159	6.201
51.37	536.44	1.155	78.801	9.086	6.201
51.44	537.20	1.147	78.800	9.027	6.201
51.52	537.96	1.138	78.799	8.958	6.201
51.60	538.72	1.129	78.798	8.883	6.201
51.67	539.49	1.121	78.797	8.825	6.201
51.75	540.25	1.114	78.796	8.763	6.201
51.83	541.01	1.105	78.795	8.697	6.201
51.90	541.78	1.099	78.794	8.647	6.201
51.98	542.54	1.090	78.793	8.576	6.201
52.06	543.30	1.083	78.792	8.524	6.201
52.13	544.07	1.077	78.791	8.474	6.201
52.21	544.83	1.070	78.790	8.423	6.201
52.29	545.59	1.064	78.789	8.376	6.200
52.36	546.36	1.059	78.788	8.332	6.200
52.44	547.12	1.053	78.787	8.284	6.200
52.52	547.89	1.047	78.786	8.242	6.200
52.59	548.65	1.042	78.786	8.202	6.200
52.67	549.42	1.039	78.785	8.180	6.200
52.75	550.18	1.038	78.784	8.167	6.200
52.82	550.95	1.036	78.783	8.155	6.200
52.90	551.71	1.036	78.782	8.151	6.200
52.98	552.48	1.037	78.781	8.158	6.200
53.05	553.25	1.040	78.780	8.188	6.200
53.13	554.02	1.052	78.780	8.280	6.200
53.21	554.79	1.069	78.779	8.414	6.200
53.28	555.56	1.092	78.778	8.595	6.200
53.36	556.34	1.123	78.778	8.834	6.200
53.44	557.12	1.164	78.777	9.158	6.199
53.51	557.90	1.215	78.776	9.562	6.199
53.59	558.69	1.283	78.776	10.098	6.199
53.67	559.49	1.370	78.775	10.785	6.199
53.74	560.29	1.476	78.774	11.613	6.199
53.82	561.10	1.600	78.774	12.591	6.199
53.90	561.92	1.734	78.774	13.645	6.199
53.97	562.72	1.858	78.773	14.625	6.199
54.05	563.52	1.961	78.773	15.433	6.199
54.13	564.31	2.031	78.773	15.980	6.199
54.20	565.09	2.066	78.773	16.255	6.199
54.28	565.86	2.070	78.773	16.291	6.199
54.36	566.62	2.047	78.773	16.111	6.199
54.43	567.37	2.000	78.774	15.740	6.199
54.51	568.11	1.940	78.774	15.264	6.199
54.59	568.85	1.872	78.774	14.729	6.199
54.66	569.59	1.798	78.773	14.150	6.199
54.74	570.33	1.724	78.773	13.569	6.199
54.82	571.07	1.651	78.773	12.989	6.199
54.89	571.81	1.580	78.772	12.435	6.199
54.97	572.55	1.512	78.772	11.901	6.199
55.05	573.29	1.449	78.771	11.404	6.199
55.12	574.04	1.390	78.771	10.935	6.199
55.20	574.78	1.334	78.770	10.501	6.199
55.28	575.53	1.283	78.770	10.099	6.199
55.35	576.28	1.235	78.769	9.719	6.199
55.43	577.03	1.189	78.768	9.359	6.199
55.51	577.78	1.144	78.767	9.005	6.199
55.58	578.54	1.102	78.766	8.669	6.199
55.66	579.29	1.061	78.765	8.347	6.199
55.74	580.04	1.020	78.765	8.031	6.199
55.81	580.80	0.982	78.764	7.728	6.198
55.89	581.55	0.946	78.763	7.444	6.198
55.97	582.31	0.912	78.762	7.179	6.198
56.04	583.07	0.881	78.761	6.936	6.198
56.12	583.82	0.852	78.760	6.705	6.198
56.20	584.58	0.824	78.759	6.486	6.198
56.27	585.34	0.799	78.758	6.287	6.198
56.35	586.10	0.775	78.757	6.098	6.198
56.43	586.86	0.754	78.757	5.931	6.198
56.50	587.62	0.733	78.756	5.770	6.198
56.58	588.38	0.715	78.755	5.624	6.198
56.66	589.14	0.696	78.754	5.479	6.198
56.73	589.90	0.682	78.753	5.368	6.198
56.81	590.66	0.667	78.752	5.248	6.198
56.89	591.42	0.653	78.751	5.136	6.197
56.96	592.19	0.639	78.750	5.032	6.197
57.04	592.95	0.626	78.749	4.926	6.197
57.12	593.71	0.614	78.749	4.829	6.197
57.19	594.47	0.600	78.748	4.725	6.197
57.27	595.24	0.589	78.747	4.639	6.197
57.35	596.00	0.577	78.747	4.542	6.197
57.42	596.76	0.564	78.746	4.436	6.197
57.50	597.52	0.553	78.745	4.355	6.197
57.58	598.29	0.541	78.744	4.260	6.197
57.65	599.05	0.531	78.743	4.178	6.197
57.73	599.82	0.520	78.743	4.089	6.197
57.81	600.58	0.508	78.742	3.997	6.197
57.88	601.34	0.497	78.741	3.913	6.197
57.96	602.10	0.486	78.741	3.828	6.197
58.04	602.87	0.476	78.740	3.748	6.197
58.11	603.63	0.465	78.739	3.657	6.197
58.19	604.39	0.455	78.738	3.577	6.196
58.27	605.16	0.443	78.737	3.487	6.196
58.34	605.92	0.434	78.737	3.412	6.196
58.42	606.68	0.424	78.736	3.337	6.196
58.50	607.45	0.414	78.735	3.262	6.196
58.57	608.21	0.404	78.735	3.177	6.196
58.65	608.98	0.394	78.734	3.100	6.196
58.73	609.74	0.383	78.733	3.011	6.196
58.80	610.50	0.372	78.732	2.928	6.196
58.88	611.26	0.361	78.731	2.842	6.196
58.96	612.03	0.352	78.731	2.768	6.196
59.03	612.79	0.342	78.730	2.692	6.196
59.11	613.55	0.333	78.729	2.618	6.196
59.19	614.32	0.321	78.729	2.527	6.196
59.26	615.08	0.311	78.728	2.450	6.196
59.34	615.85	0.301	78.727	2.365	6.196
59.42	616.61	0.290	78.726	2.285	6.195
59.49	617.37	0.279	78.725	2.198	6.195
59.57	618.14	0.270	78.724	2.124	6.195
59.65	618.90	0.260	78.723	2.043	6.195
59.72	619.66	0.248	78.723	1.951	6.195
59.80	620.43	0.237	78.722	1.865	6.195
59.88	621.19	0.227	78.722	1.784	6.195
59.95	621.95	0.217	78.721	1.705	6.195
60.03	622.72	0.205	78.720	1.614	6.195
60.11	623.48	0.194	78.720	1.525	6.195
60.18	624.24	0.184	78.719	1.447	6.195
60.26	625.01	0.173	78.718	1.359	6.195
60.34	625.77	0.161	78.718	1.269	6.195
60.41	626.53	0.151	78.717	1.184	6.195
60.49	627.30	0.139	78.716	1.090	6.195
60.57	628.06	0.128	78.716	1.008	6.195
60.64	628.82	0.118	78.715	0.925	6.195
60.72	629.59	0.106	78.715	0.831	6.195
60.80	630.35	0.095	78.714	0.749	6.195
60.87	631.11	0.085	78.713	0.670	6.194
60.95	631.88	0.075	78.712	0.586	6.194
61.03	632.64	0.062	78.712	0.489	6.194
61.10	633.41	0.052	78.711	0.412	6.194
61.18	634.17	0.039	78.711	0.306	6.194
61.26	634.93	0.028	78.710	0.220	6.194
61.33	635.70	0.016	78.709	0.128	6.194
61.41	636.46	0.006	78.709	0.051	6.194
61.49	637.22	-0.005	78.708	-0.040	6.194
61.56	637.99	-0.017	78.707	-0.133	6.194
61.64	638.75	-0.028	78.706	-0.224	6.194
61.72	639.51	-0.041	78.706	-0.324	6.194
61.79	640.28	-0.052	78.705	-0.410	6.194
61.87	641.04	-0.063	78.705	-0.493	6.194
61.95	641.80	-0.075	78.704	-0.593	6.194
62.02	642.57	-0.088	78.703	-0.692	6.194
62.10	643.33	-0.099	78.703	-0.781	6.194
62.18	644.09	-0.112	78.702	-0.880	6.194
62.25	644.86	-0.124	78.701	-0.974	6.194
62.33	645.62	-0.136	78.701	-1.070	6.194
62.41	646.38	-0.149	78.700	-1.169	6.193
62.48	647.15	-0.161	78.699	-1.268	6.193
62.56	647.91	-0.173	78.699	-1.361	6.193
62.64	648.67	-0.186	78.698	-1.467	6.193
62.71	649.44	-0.198	78.698	-1.557	6.193
62.79	650.20	-0.208	78.697	-1.636	6.193
62.87	650.96	-0.223	78.696	-1.752	6.193
62.94	651.73	-0.235	78.696	-1.848	6.193
63.02	652.49	-0.248	78.695	-1.949	6.193
63.10	653.25	-0.261	78.693	-2.055	6.193
63.17	654.01	-0.275	78.692	-2.161	6.193
63.25	654.78	-0.289	78.691	-2.272	6.193
63.33	655.54	-0.300	78.690	-2.360	6.193
63.40	656.31	-0.314	78.689	-2.473	6.193
63.48	657.07	-0.328	78.688	-2.580	6.193
63.56	657.83	-0.340	78.687	-2.674	6.192
63.63	658.60	-0.352	78.687	-2.770	6.192
63.71	659.36	-0.366	78.686	-2.879	6.192
63.79	660.12	-0.379	78.685	-2.984	6.192
63.86	660.89	-0.392	78.685	-3.083	6.192
63.94	661.65	-0.404	78.684	-3.182	6.192
64.02	662.41	-0.419	78.684	-3.296	6.192
64.09	663.18	-0.432	78.683	-3.399	6.192
64.17	663.94	-0.447	78.682	-3.514	6.192
64.25	664.70	-0.458	78.682	-3.608	6.192
64.32	665.46	-0.474	78.681	-3.733	6.192
64.40	666.23	-0.487	78.680	-3.836	6.192
64.48	666.99	-0.500	78.680	-3.931	6.192
64.55	667.75	-0.515	78.679	-4.051	6.192
64.63	668.52	-0.527	78.679	-4.145	6.192
64.71	669.28	-0.540	78.678	-4.251	6.192
64.78	670.04	-0.552	78.678	-4.343	6.192
64.86	670.81	-0.564	78.677	-4.437	6.192
64.94	671.57	-0.579	78.676	-4.553	6.192
65.01	672.33	-0.593	78.676	-4.663	6.192
65.09	673.10	-0.604	78.675	-4.755	6.191
65.17	673.86	-0.617	78.674	-4.856	6.191
65.24	674.63	-0.632	78.673	-4.976	6.191
65.32	675.39	-0.645	78.673	-5.072	6.191
65.40	676.15	-0.659	78.672	-5.183	6.191
65.47	676.92	-0.671	78.671	-5.282	6.191
65.55	677.68	-0.686	78.671	-5.398	6.191
65.63	678.44	-0.698	78.670	-5.495	6.191
65.70	679.21	-0.711	78.670	-5.599	6.191
65.78	679.97	-0.726	78.669	-5.716	6.191
65.86	680.73	-0.742	78.668	-5.843	6.191
65.93	681.50	-0.753	78.668	-5.929	6.191
66.01	682.26	-0.767	78.667	-6.034	6.191
66.09	683.03	-0.780	78.666	-6.140	6.191
66.16	683.79	-0.795	78.665	-6.253	6.191
66.24	684.55	-0.806	78.664	-6.345	6.191
66.32	685.32	-0.820	78.664	-6.451	6.191
66.39	686.08	-0.834	78.663	-6.563	6.191
66.47	686.84	-0.848	78.662	-6.670	6.190
66.55	687.61	-0.861	78.662	-6.779	6.190
66.62	688.37	-0.876	78.661	-6.894	6.190
66.70	689.13	-0.888	78.660	-6.988	6.190
66.78	689.90	-0.902	78.659	-7.100	6.190
66.85	690.66	-0.918	78.658	-7.221	6.190
66.93	691.42	-0.932	78.657	-7.335	6.190
67.01	692.19	-0.947	78.656	-7.454	6.190
67.08	692.95	-0.961	78.656	-7.565	6.190
67.16	693.71	-0.976	78.655	-7.682	6.190
67.24	694.48	-0.990	78.654	-7.794	6.190
67.31	695.24	-1.005	78.653	-7.908	6.190
67.39	696.01	-1.019	78.653	-8.019	6.190
67.47	696.77	-1.033	78.652	-8.128	6.190
67.54	697.54	-1.047	78.651	-8.243	6.190
67.62	698.30	-1.062	78.650	-8.359	6.190
67.70	699.06	-1.077	78.650	-8.476	6.189
67.77	699.82	-1.091	78.649	-8.585	6.189
67.85	700.59	-1.105	78.648	-8.693	6.189
67.93	701.35	-1.119	78.647	-8.805	6.189
68.00	702.12	-1.134	78.647	-8.925	6.189
68.08	702.88	-1.148	78.646	-9.035	6.189
68.16	703.65	-1.163	78.645	-9.154	6.189
68.23	704.41	-1.180	78.644	-9.284	6.189
68.31	705.18	-1.194	78.643	-9.398	6.189
68.39	705.94	-1.209	78.642	-9.517	6.189
68.46	706.70	-1.223	78.641	-9.628	6.189
68.54	707.47	-1.240	78.641	-9.756	6.189
68.62	708.23	-1.254	78.640	-9.871	6.189
68.69	709.00	-1.272	78.639	-10.013	6.189
68.77	709.76	-1.285	78.638	-10.110	6.189
68.85	710.52	-1.299	78.638	-10.223	6.189
68.92	711.29	-1.315	78.637	-10.350	6.188
69.00	712.05	-1.329	78.636	-10.462	6.188
69.08	712.81	-1.344	78.635	-10.576	6.188
69.15	713.58	-1.358	78.634	-10.690	6.188
69.23	714.34	-1.373	78.633	-10.807	6.188
69.31	715.10	-1.390	78.633	-10.939	6.188
69.38	715.87	-1.405	78.632	-11.053	6.188
69.46	716.63	-1.422	78.631	-11.188	6.188
69.54	717.40	-1.435	78.630	-11.295	6.188
69.61	718.16	-1.451	78.629	-11.417	6.188
69.69	718.93	-1.466	78.628	-11.537	6.188
69.77	719.69	-1.483	78.628	-11.667	6.188
69.84	720.46	-1.497	78.627	-11.780	6.188
69.92	721.22	-1.515	78.626	-11.920	6.188
70.00	721.98	-1.529	78.625	-12.034	6.188
70.07	722.75	-1.545	78.624	-12.157	6.187
70.15	723.51	-1.563	78.623	-12.298	6.187
70.23	724.27	-1.578	78.623	-12.416	6.187
70.30	725.04	-1.594	78.622	-12.548	6.187
70.38	725.80	-1.610	78.621	-12.667	6.187
70.46	726.56	-1.625	78.620	-12.791	6.187
70.53	727.33	-1.641	78.619	-12.910	6.187
70.61	728.09	-1.658	78.618	-13.051	6.187
70.69	728.86	-1.674	78.617	-13.173	6.187
70.76	729.62	-1.691	78.616	-13.306	6.187
70.84	730.38	-1.708	78.616	-13.444	6.187
70.92	731.15	-1.724	78.615	-13.569	6.187
70.99	731.91	-1.738	78.614	-13.680	6.187
71.07	732.67	-1.756	78.613	-13.815	6.187
71.15	733.44	-1.772	78.612	-13.943	6.187
71.22	734.20	-1.788	78.611	-14.071	6.186
71.30	734.97	-1.804	78.610	-14.198	6.186
71.38	735.73	-1.819	78.609	-14.315	6.186
71.45	736.49	-1.838	78.609	-14.464	6.186
71.53	737.26	-1.855	78.608	-14.602	6.186
71.61	738.02	-1.871	78.607	-14.722	6.186
71.68	738.78	-1.885	78.606	-14.836	6.186
71.76	739.55	-1.901	78.605	-14.959	6.186
71.84	740.31	-1.920	78.604	-15.106	6.186
71.91	741.08	-1.936	78.603	-15.238	6.186
71.99	741.84	-1.952	78.602	-15.359	6.186
72.07	742.60	-1.968	78.601	-15.489	6.186
72.14	743.37	-1.984	78.600	-15.616	6.186
72.22	744.13	-1.999	78.599	-15.732	6.185
72.30	744.90	-2.015	78.598	-15.860	6.185
72.37	745.66	-2.032	78.597	-15.988	6.185
72.45	746.43	-2.047	78.596	-16.107	6.185
72.53	747.19	-2.064	78.595	-16.240	6.185
72.60	747.95	-2.080	78.594	-16.373	6.185
72.68	748.72	-2.097	78.592	-16.501	6.185
72.76	749.48	-2.114	78.591	-16.639	6.185
72.83	750.24	-2.129	78.590	-16.758	6.185
72.91	751.01	-2.147	78.589	-16.899	6.185
72.99	751.77	-2.164	78.588	-17.027	6.185
73.06	752.54	-2.180	78.587	-17.155	6.185
73.14	753.30	-2.199	78.586	-17.302	6.185
73.22	754.06	-2.215	78.586	-17.430	6.184
73.29	754.83	-2.231	78.585	-17.558	6.184
73.37	755.59	-2.248	78.584	-17.691	6.184
73.45	756.36	-2.266	78.583	-17.832	6.184
73.52	757.12	-2.283	78.582	-17.970	6.184
73.60	757.88	-2.300	78.581	-18.101	6.184
73.68	758.65	-2.316	78.580	-18.229	6.184
73.75	759.41	-2.332	78.579	-18.351	6.184
73.83	760.17	-2.351	78.578	-18.500	6.184
73.91	760.94	-2.366	78.577	-18.620	6.184
73.98	761.70	-2.381	78.575	-18.740	6.184
74.06	762.47	-2.400	78.574	-18.890	6.184
74.14	763.23	-2.419	78.573	-19.039	6.183
74.21	764.00	-2.435	78.572	-19.160	6.183
74.29	764.76	-2.451	78.571	-19.288	6.183
74.37	765.52	-2.470	78.569	-19.438	6.183
74.44	766.29	-2.488	78.568	-19.579	6.183
74.52	767.05	-2.504	78.567	-19.703	6.183
74.60	767.82	-2.522	78.566	-19.846	6.183
74.67	768.58	-2.539	78.565	-19.980	6.183
74.75	769.34	-2.555	78.563	-20.107	6.183
74.83	770.11	-2.575	78.562	-20.262	6.183
74.90	770.87	-2.592	78.561	-20.396	6.183
74.98	771.64	-2.609	78.560	-20.536	6.182
75.06	772.40	-2.628	78.559	-20.685	6.182
75.13	773.16	-2.646	78.558	-20.821	6.182
75.21	773.93	-2.662	78.557	-20.951	6.182
75.29	774.69	-2.681	78.556	-21.097	6.182
75.36	775.46	-2.700	78.555	-21.246	6.182
75.44	776.22	-2.717	78.554	-21.384	6.182
75.52	776.98	-2.734	78.553	-21.519	6.182
75.59	777.75	-2.752	78.552	-21.659	6.182
75.67	778.51	-2.771	78.551	-21.804	6.182
75.75	779.28	-2.788	78.550	-21.937	6.182
75.82	780.05	-2.804	78.549	-22.065	6.182
75.90	780.81	-2.823	78.548	-22.219	6.181
75.98	781.57	-2.845	78.546	-22.386	6.181
76.05	782.33	-2.862	78.545	-22.526	6.181
76.13	783.09	-2.880	78.544	-22.666	6.181
76.21	783.86	-2.897	78.543	-22.802	6.181
76.28	784.62	-2.914	78.542	-22.929	6.181
76.36	785.39	-2.931	78.541	-23.063	6.181
76.44	786.15	-2.949	78.539	-23.207	6.181
76.51	786.92	-2.968	78.538	-23.354	6.181
76.59	787.68	-2.986	78.537	-23.503	6.181
76.67	788.44	-3.005	78.536	-23.646	6.181
76.74	789.21	-3.021	78.535	-23.773	6.180
76.82	789.97	-3.039	78.534	-23.920	6.180
76.90	790.75	-3.057	78.533	-24.057	6.180
76.97	791.51	-3.074	78.531	-24.193	6.180
77.05	792.27	-3.097	78.530	-24.372	6.180
77.13	793.03	-3.117	78.529	-24.529	6.180
77.20	793.80	-3.134	78.528	-24.667	6.180
77.28	794.56	-3.152	78.526	-24.807	6.180
77.36	795.32	-3.171	78.525	-24.956	6.180
77.43	796.09	-3.189	78.524	-25.097	6.180
77.51	796.85	-3.207	78.523	-25.237	6.179
77.59	797.62	-3.227	78.522	-25.397	6.179
77.66	798.39	-3.243	78.520	-25.523	6.179
77.74	799.15	-3.264	78.519	-25.687	6.179
77.82	799.91	-3.286	78.518	-25.856	6.179
77.89	800.67	-3.307	78.517	-26.022	6.179
77.97	801.44	-3.325	78.516	-26.169	6.179
78.05	802.20	-3.342	78.514	-26.297	6.179
78.12	802.97	-3.359	78.513	-26.438	6.179
78.20	803.74	-3.378	78.512	-26.587	6.179
78.28	804.50	-3.399	78.511	-26.748	6.179
78.35	805.26	-3.418	78.510	-26.900	6.178
78.43	806.03	-3.440	78.508	-27.070	6.178
78.51	806.80	-3.457	78.507	-27.204	6.178
78.58	807.56	-3.476	78.506	-27.355	6.178
78.66	808.32	-3.497	78.505	-27.517	6.178
78.74	809.09	-3.517	78.503	-27.675	6.178
78.81	809.85	-3.537	78.502	-27.833	6.178
78.89	810.62	-3.557	78.501	-27.993	6.178
78.97	811.38	-3.576	78.500	-28.145	6.178
79.04	812.15	-3.595	78.499	-28.291	6.178
79.12	812.91	-3.617	78.497	-28.466	6.177
79.20	813.67	-3.637	78.496	-28.620	6.177
79.27	814.44	-3.657	78.495	-28.781	6.177
79.35	815.20	-3.676	78.494	-28.928	6.177
79.43	815.97	-3.696	78.493	-29.087	6.177
79.50	816.73	-3.718	78.491	-29.260	6.177
79.58	817.50	-3.737	78.490	-29.411	6.177
79.66	818.26	-3.759	78.489	-29.579	6.177
79.73	819.03	-3.778	78.488	-29.728	6.177
79.81	819.79	-3.799	78.487	-29.897	6.177
79.89	820.55	-3.822	78.485	-30.079	6.177
79.96	821.32	-3.842	78.484	-30.233	6.176
80.04	822.08	-3.861	78.483	-30.381	6.176
80.12	822.85	-3.880	78.482	-30.535	6.176
80.19	823.61	-3.904	78.480	-30.723	6.176
80.27	824.38	-3.924	78.479	-30.880	6.176
80.35	825.14	-3.943	78.478	-31.033	6.176
80.42	825.90	-3.965	78.477	-31.205	6.176
80.50	826.67	-3.985	78.476	-31.361	6.176
80.58	827.43	-4.006	78.475	-31.528	6.176
80.65	828.20	-4.029	78.473	-31.703	6.176
80.73	828.96	-4.051	78.472	-31.881	6.176
80.81	829.73	-4.072	78.471	-32.049	6.175
80.88	830.49	-4.093	78.470	-32.213	6.175
80.96	831.26	-4.116	78.469	-32.392	6.175
81.04	832.02	-4.138	78.467	-32.565	6.175
81.11	832.79	-4.158	78.466	-32.719	6.175
81.19	833.55	-4.183	78.465	-32.919	6.175
81.27	834.31	-4.205	78.464	-33.095	6.175
81.34	835.08	-4.226	78.463	-33.257	6.175
81.42	835.84	-4.247	78.461	-33.423	6.175
81.50	836.61	-4.268	78.460	-33.587	6.175
81.57	837.37	-4.289	78.459	-33.751	6.174
81.65	838.14	-4.308	78.458	-33.905	6.174
81.73	838.90	-4.332	78.457	-34.092	6.174
81.80	839.66	-4.355	78.455	-34.273	6.174
81.88	840.43	-4.373	78.454	-34.418	6.174
81.96	841.19	-4.398	78.453	-34.608	6.174
82.03	841.96	-4.418	78.452	-34.770	6.174
82.11	842.72	-4.439	78.451	-34.935	6.174
82.19	843.49	-4.459	78.450	-35.093	6.174
82.26	844.25	-4.483	78.449	-35.276	6.174
82.34	845.01	-4.506	78.448	-35.460	6.174
82.42	845.78	-4.529	78.446	-35.640	6.173
82.49	846.54	-4.551	78.445	-35.816	6.173
82.57	847.31	-4.572	78.444	-35.983	6.173
82.65	848.07	-4.593	78.443	-36.145	6.173
82.72	848.83	-4.614	78.442	-36.314	6.173
82.80	849.60	-4.637	78.441	-36.489	6.173
82.88	850.36	-4.660	78.440	-36.670	6.173
82.95	851.13	-4.681	78.440	-36.840	6.173
83.03	851.89	-4.703	78.439	-37.013	6.173
83.11	852.66	-4.726	78.437	-37.189	6.173
83.18	853.42	-4.748	78.436	-37.369	6.173
83.26	854.19	-4.770	78.435	-37.541	6.173
83.34	854.95	-4.795	78.434	-37.734	6.173
83.41	855.71	-4.817	78.433	-37.910	6.172
83.49	856.48	-4.841	78.432	-38.093	6.172
83.57	857.24	-4.863	78.431	-38.267	6.172
83.64	858.01	-4.887	78.430	-38.459	6.172
83.72	858.77	-4.910	78.429	-38.642	6.172
83.80	859.54	-4.931	78.428	-38.806	6.172
83.87	860.30	-4.954	78.427	-38.985	6.172
83.95	861.06	-4.978	78.426	-39.172	6.172
84.03	861.83	-5.000	78.425	-39.345	6.172
84.10	862.59	-5.024	78.424	-39.537	6.172
84.18	863.36	-5.045	78.424	-39.703	6.172
84.26	864.12	-5.070	78.423	-39.899	6.172
84.33	864.88	-5.094	78.422	-40.090	6.172
84.41	865.65	-5.116	78.421	-40.262	6.171
84.49	866.41	-5.139	78.420	-40.446	6.171
84.56	867.18	-5.161	78.419	-40.612	6.171
84.64	867.94	-5.184	78.418	-40.800	6.171
84.72	868.70	-5.208	78.417	-40.982	6.171
84.79	869.47	-5.230	78.415	-41.156	6.171
84.87	870.23	-5.255	78.414	-41.355	6.171
84.95	870.99	-5.279	78.413	-41.543	6.171
85.02	871.76	-5.304	78.412	-41.740	6.171
85.10	872.52	-5.327	78.411	-41.923	6.171
85.18	873.29	-5.352	78.410	-42.118	6.171
85.25	874.05	-5.376	78.410	-42.306	6.171
85.33	874.82	-5.399	78.409	-42.492	6.171
85.41	875.58	-5.422	78.408	-42.673	6.170
85.48	876.35	-5.448	78.407	-42.871	6.170
85.56	877.11	-5.470	78.406	-43.046	6.170
85.64	877.87	-5.492	78.405	-43.222	6.170
85.71	878.64	-5.517	78.404	-43.415	6.170
85.79	879.40	-5.542	78.404	-43.614	6.170
85.87	880.17	-5.565	78.403	-43.798	6.170
85.94	880.93	-5.590	78.402	-43.990	6.170
86.02	881.69	-5.614	78.401	-44.183	6.170
86.10	882.46	-5.638	78.400	-44.368	6.170
86.17	883.22	-5.661	78.399	-44.551	6.170
86.25	883.98	-5.686	78.398	-44.745	6.170
86.33	884.75	-5.709	78.397	-44.925	6.170
86.40	885.51	-5.732	78.396	-45.106	6.170
86.48	886.28	-5.754	78.396	-45.286	6.169
86.56	887.04	-5.779	78.395	-45.478	6.169
86.63	887.81	-5.804	78.394	-45.675	6.169
86.71	888.57	-5.829	78.393	-45.875	6.169
86.79	889.33	-5.854	78.392	-46.071	6.169
86.86	890.10	-5.879	78.391	-46.263	6.169
86.94	890.86	-5.901	78.390	-46.437	6.169
87.02	891.63	-5.925	78.389	-46.628	6.169
87.09	892.39	-5.949	78.388	-46.821	6.169
87.17	893.16	-5.974	78.387	-47.012	6.169
87.25	893.92	-5.997	78.386	-47.192	6.169
87.32	894.68	-6.019	78.386	-47.367	6.169
87.40	895.45	-6.044	78.385	-47.565	6.169
87.48	896.21	-6.068	78.384	-47.756	6.169
87.55	896.98	-6.090	78.383	-47.929	6.169
87.63	897.74	-6.114	78.382	-48.117	6.168
87.71	898.51	-6.139	78.382	-48.314	6.168
87.78	899.27	-6.164	78.381	-48.510	6.168
87.86	900.04	-6.187	78.380	-48.687	6.168
87.94	900.80	-6.209	78.379	-48.860	6.168
88.01	901.57	-6.235	78.378	-49.070	6.168
88.09	902.33	-6.258	78.378	-49.251	6.168
88.17	903.09	-6.282	78.377	-49.435	6.168
88.24	903.86	-6.304	78.376	-49.611	6.168
88.32	904.62	-6.327	78.375	-49.793	6.168
88.40	905.39	-6.350	78.374	-49.969	6.168
88.47	906.15	-6.374	78.373	-50.159	6.168
88.55	906.92	-6.398	78.372	-50.348	6.168
88.63	907.68	-6.419	78.371	-50.516	6.168
88.70	908.45	-6.444	78.370	-50.712	6.168
88.78	909.21	-6.470	78.370	-50.915	6.167
88.86	909.98	-6.493	78.369	-51.098	6.167
88.93	910.74	-6.518	78.368	-51.291	6.167
89.01	911.50	-6.542	78.367	-51.487	6.167
89.09	912.27	-6.565	78.366	-51.661	6.167
89.16	913.03	-6.586	78.365	-51.833	6.167
89.24	913.80	-6.613	78.364	-52.039	6.167
89.32	914.56	-6.637	78.364	-52.230	6.167
89.39	915.33	-6.660	78.363	-52.409	6.167
89.47	916.09	-6.685	78.362	-52.610	6.167
89.55	916.86	-6.709	78.361	-52.796	6.167
89.62	917.62	-6.732	78.361	-52.979	6.167
89.70	918.38	-6.757	78.360	-53.178	6.167
89.78	919.15	-6.780	78.359	-53.358	6.167
89.85	919.91	-6.803	78.358	-53.535	6.167
89.93	920.68	-6.825	78.357	-53.714	6.166
90.01	921.44	-6.848	78.356	-53.894	6.166
90.08	922.21	-6.871	78.355	-54.076	6.166
90.16	922.97	-6.895	78.355	-54.261	6.166
90.24	923.74	-6.919	78.354	-54.450	6.166
90.31	924.50	-6.945	78.353	-54.651	6.166
90.39	925.27	-6.967	78.352	-54.828	6.166
90.47	926.03	-6.991	78.351	-55.018	6.166
90.54	926.80	-7.016	78.350	-55.212	6.166
90.62	927.56	-7.041	78.349	-55.412	6.166
90.70	928.33	-7.064	78.349	-55.590	6.166
90.77	929.09	-7.088	78.348	-55.779	6.166
90.85	929.85	-7.112	78.347	-55.973	6.166
90.93	930.62	-7.138	78.346	-56.172	6.166
91.00	931.38	-7.160	78.346	-56.346	6.166
91.08	932.15	-7.182	78.345	-56.522	6.165
91.16	932.91	-7.206	78.344	-56.705	6.165
91.23	933.68	-7.229	78.343	-56.888	6.165
91.31	934.44	-7.253	78.342	-57.078	6.165
91.39	935.21	-7.277	78.341	-57.270	6.165
91.46	935.97	-7.300	78.340	-57.448	6.165
91.54	936.74	-7.323	78.339	-57.629	6.165
91.62	937.50	-7.345	78.338	-57.805	6.165
91.69	938.27	-7.371	78.337	-58.008	6.165
91.77	939.03	-7.396	78.337	-58.202	6.165
91.85	939.79	-7.419	78.336	-58.389	6.165
91.92	940.56	-7.443	78.335	-58.575	6.165
92.00	941.32	-7.468	78.334	-58.768	6.165
92.08	942.09	-7.491	78.333	-58.954	6.165
92.15	942.85	-7.517	78.332	-59.155	6.164
92.23	943.62	-7.540	78.331	-59.334	6.164
92.31	944.38	-7.563	78.331	-59.521	6.164
92.38	945.15	-7.587	78.330	-59.704	6.164
92.46	945.91	-7.610	78.329	-59.890	6.164
92.54	946.68	-7.633	78.328	-60.072	6.164
92.61	947.44	-7.658	78.327	-60.267	6.164
92.69	948.20	-7.682	78.326	-60.454	6.164
92.77	948.97	-7.707	78.325	-60.651	6.164
92.84	949.73	-7.730	78.324	-60.835	6.164
92.92	950.50	-7.754	78.323	-61.019	6.164
93.00	951.26	-7.777	78.322	-61.204	6.164
93.07	952.03	-7.801	78.321	-61.388	6.164
93.15	952.79	-7.827	78.320	-61.593	6.164
93.23	953.56	-7.849	78.319	-61.770	6.163
93.30	954.32	-7.871	78.318	-61.946	6.163
93.38	955.09	-7.895	78.317	-62.131	6.163
93.46	955.85	-7.919	78.316	-62.317	6.163
93.53	956.62	-7.943	78.315	-62.509	6.163
93.61	957.38	-7.966	78.314	-62.686	6.163
93.69	958.15	-7.990	78.313	-62.876	6.163
93.76	958.91	-8.013	78.312	-63.063	6.163
93.84	959.68	-8.035	78.311	-63.234	6.163
93.92	960.44	-8.060	78.310	-63.431	6.163
93.99	961.20	-8.086	78.308	-63.635	6.163
94.07	961.97	-8.110	78.307	-63.823	6.163
94.15	962.73	-8.134	78.306	-64.008	6.162
94.22	963.50	-8.158	78.305	-64.199	6.162
94.30	964.26	-8.179	78.304	-64.369	6.162
94.38	965.03	-8.204	78.303	-64.562	6.162
94.45	965.79	-8.228	78.302	-64.754	6.162
94.53	966.56	-8.254	78.301	-64.957	6.162
94.61	967.33	-8.279	78.300	-65.150	6.162
94.68	968.09	-8.303	78.299	-65.339	6.162
94.76	968.86	-8.326	78.298	-65.523	6.162
94.84	969.62	-8.352	78.297	-65.727	6.162
94.91	970.38	-8.376	78.296	-65.913	6.162
94.99	971.15	-8.402	78.295	-66.118	6.162
95.07	971.91	-8.425	78.294	-66.302	6.162
95.14	972.68	-8.449	78.293	-66.489	6.161
95.22	973.44	-8.472	78.292	-66.671	6.161
95.30	974.21	-8.497	78.291	-66.868	6.161
95.37	974.97	-8.521	78.290	-67.057	6.161
95.45	975.74	-8.545	78.289	-67.248	6.161
95.53	976.50	-8.570	78.288	-67.446	6.161
95.60	977.27	-8.596	78.287	-67.648	6.161
95.68	978.03	-8.622	78.286	-67.851	6.161
95.76	978.80	-8.644	78.285	-68.026	6.161
95.83	979.56	-8.669	78.283	-68.223	6.161
95.91	980.33	-8.695	78.282	-68.425	6.161
95.99	981.09	-8.718	78.281	-68.608	6.160
96.06	981.86	-8.743	78.280	-68.802	6.160
96.14	982.62	-8.767	78.278	-68.990	6.160
96.22	983.39	-8.792	78.276	-69.187	6.160
96.29	984.15	-8.815	78.275	-69.372	6.160
96.37	984.92	-8.841	78.274	-69.574	6.160
96.45	985.68	-8.868	78.272	-69.790	6.160
96.52	986.45	-8.890	78.271	-69.961	6.160
96.60	987.21	-8.917	78.270	-70.174	6.160
96.68	987.97	-8.942	78.269	-70.368	6.160
96.75	988.74	-8.969	78.268	-70.584	6.159
96.83	989.50	-8.992	78.266	-70.761	6.159
96.91	990.27	-9.018	78.265	-70.968	6.159
96.98			78.264		6.159
97.00			78.264		6.159