File: Data/KMK273/ZFCFC/KMK273_ZFCFC.dat
[Header]
; MPMS3 Data File (default extension .dat)
; Copyright (c) 2007, Quantum Design, Inc. All rights reserved.
TITLE,
FILEOPENTIME,3870609856.80008,08/25/2022,5:24 pm
BYAPP,MPMS3 w/ AC,1.0,1.1
INFO,MPMS3 Measurement Release 1.1.16 Build 424, MultiVu Release 2.3.4.19,APPNAME
INFO,Linear Motor Servo Controller,MOTOR_MODULE_NAME
INFO,3101-100 J0,MOTOR_HW_VERSION
INFO,MMC721,MOTOR_SERIAL_NUMBER
INFO,01.04.28,MOTOR_SOFTWARE_VERSION
INFO,Quantum Design Squid Module,SQUID_MODULE_NAME
INFO,3101-501 B0,SQUID_HW_VERSION
INFO,SQM195,SQUID_SERIAL_NUMBER
INFO,01.03.04,SQUID_SOFTWARE_VERSION
INFO,SQUID AC,AC_MODULE_NAME
INFO,3101-401 f1,AC_HW_VERSION
INFO,SAC107,AC_SERIAL_NUMBER
INFO,SQUID AC 00.95.07,AC_SOFTWARE_VERSION
INFO,TCI166,COIL_SERIAL_NUMBER
INFO,0,MOMENT_UNITS
INFO,KMK273,SAMPLE_MATERIAL
INFO,,SAMPLE_COMMENT
INFO,2.3,SAMPLE_MASS
INFO,,SAMPLE_VOLUME
INFO,,SAMPLE_MOLECULAR_WEIGHT
INFO,,SAMPLE_SIZE
INFO,,SAMPLE_SHAPE
INFO,Straw,SAMPLE_HOLDER
INFO,Standard,SAMPLE_HOLDER_DETAIL
INFO,66.53,SAMPLE_OFFSET
DATATYPE,COMMENT,1
DATATYPE,TIME,2
STARTUPAXIS,X,2
STARTUPAXIS,Y1,5
FIELDGROUP, VSM,2,3,4,5,6,8,9,10,11,14,15
FIELDGROUP, DC, 2,3,4,14,56,57,58,59,60,61,62,63,64,65,66,67,68,69
FIELDGROUP, AC, 2,3,4,11,16,17,18,19,20,21,22,23,24,25,26,27,28,29,30
STARTUPGROUP, All
[Data]
Comment,Time Stamp (sec),Temperature (K),Magnetic Field (Oe),Moment (emu),M. Std. Err. (emu),Transport Action,Averaging Time (sec),Frequency (Hz),Peak Amplitude (mm),Center Position (mm),Lockin Signal' (V),Lockin Signal (V),Range,M. Quad. Signal (emu),AC Moment (emu),AC M. Std Err. (emu),AC Phase (deg),AC Phase Std. Err. (deg),AC Susceptibility (emu/Oe),AC Suscept. Std Err. (emu/Oe),AC X' (emu/Oe),AC X' Std Err. (emu/Oe),AC X'' (emu/Oe),AC X'' Std Err. (emu/Oe),AC Drive (Oe),AC Frequency (Hz),AC Averaging Time (sec),AC Cycles,AC Range,AC Measure Type,AC Signal' (V),AC Signal'' (V),AC Trim Coil Ratio,AC Trim Coil Phase,Min. Temperature (K),Max. Temperature (K),Min. Field (Oe),Max. Field (Oe),Mass (grams),Motor Lag (deg),Pressure (Torr),Measure Count,Measurement Number,SQUID Status (code),Motor Status (code),Measure Status (code),Motor Current (amps),Motor Temp. (C),Temp. Status (code),Field Status (code),Chamber Status (code),Chamber Temp (K),Redirection State,Evercool Status,Average Temp (K),Rotation Angle (deg),Rotator state,DC Moment Fixed Ctr (emu),DC Moment Err Fixed Ctr (emu),DC Moment Free Ctr (emu),DC Moment Err Free Ctr (emu),DC Fixed Fit,DC Free Fit,DC Calculated Center (mm),DC Calculated Center Err (mm),DC Scan Length (mm),DC Scan Time (s),DC Number of Points,DC Squid Drift,DC Min V (V),DC Max V (V),DC Scans per Measure,Map 01,Map 02,Map 03,Map 04,Map 05,Map 06,Map 07,Map 08,Map 09,Map 10,Map 11,Map 12,Map 13,Map 14,Map 15,Map 16
,3870611081.82637,5.00204157829285,100.133750915527,,,6,,,,32.3865288327249,,,100,,,,,,,,,,,,,,,,,,,,,,4.99775457382202,5.00224018096924,100.133750915527,100.133750915527,,,3.97921633720398,,1,0,0,0,0.0138092041015625,30.7917900085449,1,1,1,5.00238084793091,0,4232058752,5.00000967979431,,,0.00671559053448812,0.00033364861318201,0.0067369358008028,0.000333663979561951,0.916065216064453,0.971453309059143,32.0864486694336,0,35,4,200,3.27347224811092E-5,-0.264727920293808,0.063031405210495,1,,,,,,,,,,,,,,,,
,3870611147.2924,9.3744330406189,100.133750915527,,,6,,,,32.3865288327249,,,100,,,,,,,,,,,,,,,,,,,,,,8.992919921875,9.70904064178467,100.133750915527,100.133750915527,,,4.84660339355469,,1,0,0,0,0.0145721435546875,31.7693061828613,6,1,1,9.75594615936279,0,4232058752,9.35474319458008,,,0.00793141604005781,0.000394045853604956,0.00795609511257101,0.000394064698028033,0.916311085224152,0.969829678535461,32.089771270752,INF,35,4,200,0.000250307843089104,-0.320802301168442,0.0702016204595566,1,,,,,,,,,,,,,,,,
,3870611214.54996,14.6750888824463,100.133750915527,,,6,,,,32.391594454286,,,100,,,,,,,,,,,,,,,,,,,,,,14.2780017852783,14.998363494873,100.133750915527,100.133750915527,,,5.84413003921509,,1,0,0,0,0.0138092041015625,31.2805480957031,6,1,1,15.0721759796143,0,4232058688,14.6345289230347,,,0.0101983367049945,0.000506642566276198,0.0102295584999145,0.000506666930273683,0.916964471340179,0.969983637332916,32.097282409668,INF,35,4,200,0.000291647884296253,-0.406140476465225,0.100874863564968,1,,,,,,,,,,,,,,,,
,3870611273.26205,19.4234924316406,100.133750915527,,,6,,,,32.391594454286,,,100,,,,,,,,,,,,,,,,,,,,,,19.0367126464844,19.7657699584961,100.133750915527,100.133750915527,,,6.08786487579346,,1,0,0,0,0.0145721435546875,30.7917900085449,2,1,1,19.8102722167969,0,4232058784,19.4033100128174,,,0.0120321231683918,0.000597611834382704,0.0120664559107445,0.000597639328280579,0.919637799263,0.970471382141113,32.1075096130371,INF,35,4,200,0.000236027350183576,-0.476403146982193,0.114059701561928,1,,,,,,,,,,,,,,,,
,3870611341.78903,24.8751049041748,100.133750915527,,,6,,,,32.3966158059939,,,100,,,,,,,,,,,,,,,,,,,,,,24.47336769104,25.2116394042969,100.133750915527,100.133750915527,,,6.30577993392944,,1,0,0,0,0.0145721435546875,30.7917900085449,2,1,1,25.2768421173096,0,4232058624,24.8457056045532,,,0.0133985537658723,0.000665377741016569,0.0134347181759659,0.000665403969978199,0.921556651592255,0.970676720142365,32.1201171875,0,35,4,200,0.000145576952490956,-0.532256901264191,0.131595402956009,1,,,,,,,,,,,,,,,,
,3870611400.56749,29.5649814605713,100.133750915527,,,6,,,,32.3966158059939,,,100,,,,,,,,,,,,,,,,,,,,,,29.1856937408447,29.9116096496582,100.133750915527,100.133750915527,,,6.45336198806763,,1,0,0,0,0.0138092041015625,30.7917900085449,2,1,1,29.9442691802978,0,4232058720,29.5422454833984,,,0.0140034650296563,0.000695274581380859,0.0140383553467347,0.000695300012952027,0.924211740493774,0.970737338066101,32.1309623718262,0,35,4,200,9.67820087680593E-5,-0.555575430393219,0.128286883234978,1,,,,,,,,,,,,,,,,
,3870611467.90488,34.9535999298096,100.133750915527,,,6,,,,32.4018800613404,,,100,,,,,,,,,,,,,,,,,,,,,,34.5647430419922,35.3076934814453,100.133750915527,100.133750915527,,,6.55060195922852,,1,0,0,0,0.0146484375,30.7917900085449,2,1,1,35.342456817627,0,4232056992,34.9375961303711,,,0.0142996326525421,0.000709896362309149,0.0143335107515672,0.000709919805267921,0.925757944583893,0.970672726631165,32.1427230834961,0,35,4,200,6.55338153592311E-5,-0.565795481204987,0.13181708753109,1,,,,,,,,,,,,,,,,
,3870611533.9686,40.2596817016602,100.133750915527,,,6,,,,32.4069783756977,,,100,,,,,,,,,,,,,,,,,,,,,,39.8665199279785,40.6026649475098,100.133750915527,100.133750915527,,,6.66098403930664,,1,0,0,0,0.0146484375,30.7917900085449,2,1,1,40.6528434753418,0,4232058560,40.2466247558594,,,0.0143809341485453,0.000713858958121075,0.0144133840636914,0.000713877879858846,0.927150547504425,0.970572292804718,32.1537933349609,0,35,4,200,4.99566158396192E-5,-0.56852400302887,0.132712513208389,1,,,,,,,,,,,,,,,,
,3870611601.26869,45.6630096435547,100.133750915527,,,6,,,,32.4120400143008,,,100,,,,,,,,,,,,,,,,,,,,,,45.285041809082,46.0320472717285,100.133750915527,100.133750915527,,,6.72789716720581,,1,0,0,0,0.0145721435546875,30.7917900085449,2,1,1,46.0409774780273,0,4232058752,45.6577224731445,,,0.0143612888752213,0.000712805856513451,0.014392168015139,0.000712829503382721,0.928664028644562,0.970469295978546,32.1653327941895,0,35,4,200,3.86900610465091E-5,-0.5679652094841,0.132371991872787,1,,,,,,,,,,,,,,,,
,3870611668.61571,51.1510429382324,100.133750915527,,,6,,,,32.4171115390358,,,100,,,,,,,,,,,,,,,,,,,,,,50.7702827453613,51.4725494384766,100.133750915527,100.133750915527,,,6.77917051315308,,1,0,0,0,0.0138092041015625,31.2805480957031,2,1,1,51.5318031311035,0,4232058592,51.1292469024658,,,0.0142564691952536,0.000707522828380125,0.014285394037976,0.000707542330514697,0.930266857147217,0.97040867805481,32.1772270202637,3.50092159351334E-5,35,4,200,3.13883792841807E-5,-0.56445974111557,0.130867838859558,1,,,,,,,,,,,,,,,,
,3870611735.88887,56.5730667114258,100.133750915527,,,6,,,,32.4227295895936,,,100,,,,,,,,,,,,,,,,,,,,,,56.1738395690918,56.9081001281738,100.133750915527,100.133750915527,,,6.85563898086548,,1,0,0,0,0.0145721435546875,30.7917900085449,2,1,1,56.9722938537598,0,4232058592,56.55217628479,,,0.0140736042160703,0.000698371633384407,0.0141005873503533,0.000698390993372108,0.931837320327759,0.970316171646118,32.1896209716797,0,35,4,200,2.19952453335281E-5,-0.55800199508667,0.128439322113991,1,,,,,,,,,,,,,,,,
,3870611803.02781,62.0500030517578,100.133750915527,,,6,,,,32.4279353947416,,,100,,,,,,,,,,,,,,,,,,,,,,61.6771087646484,62.3891639709473,100.133750915527,100.133750915527,,,6.89644718170166,,1,0,0,0,0.0145721435546875,30.3030319213867,2,1,1,62.4228973388672,0,4232058656,62.0347030639648,,,0.0138313854174974,0.00068627340754207,0.0138562230830363,0.000686288540415249,0.933526694774628,0.970269083976746,32.2020874023438,INF,35,4,200,1.1743645700335E-5,-0.549661457538605,0.125143140554428,1,,,,,,,,,,,,,,,,
,3870611870.46749,67.4727592468262,100.133750915527,,,6,,,,32.4335019029994,,,100,,,,,,,,,,,,,,,,,,,,,,67.078369140625,67.8295440673828,100.133750915527,100.133750915527,,,6.91578388214111,,1,0,0,0,0.0145721435546875,30.7917900085449,2,1,1,67.8671493530273,0,4232058688,67.4591987609863,,,0.0135542157472886,0.000672439466299704,0.0135768873624778,0.00067245513868266,0.935370445251465,0.970176994800568,32.2157096862793,INF,35,4,200,1.0528842722124E-5,-0.539861142635345,0.131742000579834,1,,,,,,,,,,,,,,,,
,3870611946.05435,73.6495361328125,100.133750915527,,,6,,,,32.4447028116358,,,100,,,,,,,,,,,,,,,,,,,,,,73.2792892456055,73.9872589111328,100.133750915527,100.133750915527,,,6.97648239135742,,1,0,0,0,0.0145721435546875,30.7917900085449,2,1,1,74.0197830200195,0,4232058752,73.634806060791,,,0.0132157715272184,0.00065560409452542,0.0132369048610361,0.000655617721516226,0.936435520648956,0.970097661018372,32.2316589355469,0,35,4,200,4.59098373539746E-6,-0.52797532081604,0.127170294523239,1,,,,,,,,,,,,,,,,
,3870612013.08775,79.1051177978516,100.133750915527,,,6,,,,32.4501866161382,,,100,,,,,,,,,,,,,,,,,,,,,,78.7207641601562,79.4541473388672,100.133750915527,100.133750915527,,,7.00377321243286,,1,0,0,0,0.0145721435546875,30.7917900085449,2,1,1,79.4894714355469,0,4232058688,79.0891464233398,,,0.0129062391171146,0.000640164862498288,0.0129251123223093,0.000640176742112279,0.93852573633194,0.969992876052856,32.246410369873,INF,35,4,200,-2.61701188719599E-5,-0.517038643360138,0.12297285348177,1,,,,,,,,,,,,,,,,
,3870612088.83484,85.2857360839844,100.133750915527,,,6,,,,32.4620235491578,,,100,,,,,,,,,,,,,,,,,,,,,,84.8793792724609,85.6667251586914,100.133750915527,100.133750915527,,,7.02001333236694,,1,0,0,0,0.0145721435546875,31.2805480957031,2,1,1,85.6920928955078,0,4232058656,85.2627250671387,,,0.012552349543624,0.000622564407270128,0.0125697037187072,0.000622574431136532,0.939763307571411,0.96993887424469,32.2637939453125,INF,35,4,200,2.0261068129912E-6,-0.504562079906464,0.118134595453739,1,,,,,,,,,,,,,,,,
,3870612164.54026,91.5905342102051,100.133750915527,,,6,,,,32.4721145932394,,,100,,,,,,,,,,,,,,,,,,,,,,91.2119140625,91.9417190551758,100.133750915527,100.133750915527,,,7.05280590057373,,1,0,0,0,0.013885498046875,30.7917900085449,2,1,1,91.9691543579102,0,4232058720,91.5784805297852,,,0.0122010598678948,0.000605077056496333,0.0122166309829483,0.000605088278748939,0.941550076007843,0.969864845275879,32.281925201416,INF,35,4,200,2.10623866792048E-7,-0.481297671794891,0.11393728852272,1,,,,,,,,,,,,,,,,
,3870612240.43688,97.8037643432617,100.133750915527,,,6,,,,32.4829533062537,,,100,,,,,,,,,,,,,,,,,,,,,,97.3977279663086,98.1921768188477,100.133750915527,100.133750915527,,,7.09994888305664,,1,0,0,0,0.0145721435546875,30.3030319213867,2,1,1,98.2098007202148,0,4232058816,97.8154777526856,,,0.0118545543703167,0.000587833310708738,0.0118684150718162,0.000587841724807592,0.943308174610138,0.969829499721527,32.3006973266602,INF,35,4,200,1.44643991006888E-7,-0.46900537610054,0.10920076072216,1,,,,,,,,,,,,,,,,
,3870612316.12128,104.107204437256,100.133750915527,,,6,,,,32.4944804109889,,,100,,,,,,,,,,,,,,,,,,,,,,103.723373413086,104.47435760498,100.133750915527,100.133750915527,,,7.11547470092773,,1,0,0,0,0.0146484375,30.7917900085449,2,1,1,104.491035461426,0,4232058816,104.101376342773,,,0.0115176816109788,0.000571073289989414,0.0115300165263721,0.000571082399870341,0.945046126842499,0.969747364521027,32.3202781677246,0,35,4,200,-1.12872521640384E-6,-0.45711088180542,0.104693792760372,1,,,,,,,,,,,,,,,,
,3870612400.55766,111.106838226318,100.133750915527,,,6,,,,32.5103048098553,,,100,,,,,,,,,,,,,,,,,,,,,,110.704963684082,111.448051452637,100.133750915527,100.133750915527,,,7.12687683105469,,1,0,0,0,0.0138092041015625,30.7917900085449,2,1,1,111.508712768555,0,4232058720,111.083639526367,,,0.0111523590872572,0.00055291330353615,0.0111632995916931,0.000552919884037046,0.946591794490814,0.969687581062317,32.3433570861816,INF,35,4,200,-2.76253904303303E-5,-0.444146007299423,0.0997650325298309,1,,,,,,,,,,,,,,,,
,3870612484.24839,118.053195953369,100.133750915527,,,6,,,,32.5268719167121,,,100,,,,,,,,,,,,,,,,,,,,,,117.661781311035,118.388946533203,100.133750915527,100.133750915527,,,7.15011882781982,,1,0,0,0,0.0138092041015625,30.7917900085449,2,1,1,118.444610595703,0,4232058688,118.025386810303,,,0.0108030901236505,0.000535555985265532,0.0108128200867236,0.000535561704117118,0.948045015335083,0.969612777233124,32.3668594360352,0,35,4,200,-1.53373889588693E-6,-0.431836992502213,0.0950442105531693,1,,,,,,,,,,,,,,,,
,3870612568.48551,125.043495178223,100.133750915527,,,6,,,,32.544752802821,,,100,,,,,,,,,,,,,,,,,,,,,,124.655937194824,125.389747619629,100.133750915527,100.133750915527,,,7.1708722114563,,1,0,0,0,0.0145721435546875,30.7917900085449,2,1,1,125.431053161621,0,4232058720,125.022388458252,,,0.0104640862495753,0.000518715654205221,0.0104727867883481,0.000518721421187309,0.949338734149933,0.969513595104217,32.3911361694336,5.69132089614868,35,4,200,-1.45901879022858E-6,-0.419866532087326,0.100904867053032,1,,,,,,,,,,,,,,,,
,3870612652.96551,132.034378051758,100.133750915527,,,6,,,,32.5635983985439,,,100,,,,,,,,,,,,,,,,,,,,,,131.634140014648,132.39599609375,100.133750915527,100.133750915527,,,7.21565008163452,,1,0,0,0,0.0138092041015625,30.7917900085449,2,1,1,132.434616088867,0,4232058720,132.013081359863,,,0.0101360146326456,0.000502421830931577,0.0101437670837195,0.00050242600458029,0.95056676864624,0.969443261623383,32.4160766601562,0,35,4,200,-1.69482893852546E-6,-0.397400349378586,0.0969286561012268,1,,,,,,,,,,,,,,,,
,3870612737.34947,139.032409667969,100.133750915527,,,6,,,,32.5834299686848,,,100,,,,,,,,,,,,,,,,,,,,,,138.640518188477,139.390747070312,100.133750915527,100.133750915527,,,7.22583961486816,,1,0,0,0,0.0145721435546875,30.3030319213867,2,1,1,139.424301147461,0,4232058688,139.016178894043,,,0.00982026588090311,0.000486743277034262,0.00982719083480642,0.000486746579694302,0.951718688011169,0.969388008117676,32.4416999816895,INF,35,4,200,-2.28343787966878E-6,-0.386196941137314,0.0926617309451103,1,,,,,,,,,,,,,,,,
,3870612822.20628,146.061676025391,100.133750915527,,,6,,,,32.6043868753855,,,100,,,,,,,,,,,,,,,,,,,,,,145.665817260742,146.417434692383,100.133750915527,100.133750915527,,,7.2263240814209,,1,0,0,0,0.0145721435546875,30.7917900085449,2,1,1,146.457534790039,0,4232058592,146.043252563477,,,0.00951378367918707,0.000471528166796345,0.00951998440159565,0.000471531124233907,0.95279461145401,0.969343245029449,32.4681205749512,3.89681172370911,35,4,200,-4.60753835795913E-6,-0.375356435775757,0.0885496735572815,1,,,,,,,,,,,,,,,,
,3870612906.52475,153.055503845215,100.133750915527,,,6,,,,32.6263446090926,,,100,,,,,,,,,,,,,,,,,,,,,,152.662017822266,153.429809570313,100.133750915527,100.133750915527,,,7.22530031204224,,1,0,0,0,0.0138092041015625,30.7917900085449,2,1,1,153.448989868164,0,4232058720,153.049935913086,,,0.00921955063824696,0.000456924736502848,0.00922511880774838,0.00045692664427674,0.953756392002106,0.969322204589844,32.4949913024902,INF,35,4,200,-2.92889717457001E-6,-0.364926964044571,0.0846205502748489,1,,,,,,,,,,,,,,,,
,3870612990.94002,160.067886352539,100.133750915527,,,6,,,,32.6465865958543,,,100,,,,,,,,,,,,,,,,,,,,,,159.676162719727,160.421005249023,100.133750915527,100.133750915527,,,7.23648118972778,,1,0,0,0,0.0138092041015625,30.7917900085449,2,1,1,160.459609985352,0,4232058560,160.043428039551,,,0.0089351315554541,0.000442800433700993,0.00893996238513872,0.000442802021231543,0.955154418945313,0.969359159469604,32.5222854614258,INF,35,4,200,-2.8183703761897E-6,-0.354869872331619,0.0807602480053902,1,,,,,,,,,,,,,,,,
,3870613101.15198,169.189491271973,100.133750915527,,,6,,,,32.6807284713391,,,100,,,,,,,,,,,,,,,,,,,,,,168.785385131836,169.543045043945,100.133750915527,100.133750915527,,,7.25052690505981,,1,0,0,0,0.0146484375,31.2805480957031,2,1,1,169.593597412109,0,4232058688,169.168968200684,,,0.00857840059538039,0.0004251093449252,0.00858283770160175,0.000425111988749476,0.955809712409973,0.969463527202606,32.5594749450684,0.000119823431305122,35,4,200,-1.99603819055483E-5,-0.342216938734055,0.0759715288877487,1,,,,,,,,,,,,,,,,
,3870613210.96832,178.310600280762,100.133750915527,,,6,,,,32.7139723809319,,,100,,,,,,,,,,,,,,,,,,,,,,177.913238525391,178.686782836914,100.133750915527,100.133750915527,,,7.26460981369018,,1,0,0,0,0.0138092041015625,30.7917900085449,2,1,1,178.707962036133,0,4232058752,178.301487731934,,,0.00823731796373099,0.00040818946576744,0.00824124307227641,0.000408191184205849,0.95677375793457,0.969578504562378,32.5973968505859,INF,35,4,200,-2.50476341534522E-6,-0.330284237861633,0.0714381337165833,1,,,,,,,,,,,,,,,,
,3870613321.33632,187.478233337402,100.133750915527,,,6,,,,32.7491092111212,,,100,,,,,,,,,,,,,,,,,,,,,,187.072799682617,187.86442565918,100.133750915527,100.133750915527,,,7.2927508354187,,1,0,0,0,0.0138092041015625,30.7917900085449,2,1,1,187.883666992187,0,4232058656,187.464526367187,,,0.00791002060951807,0.000391956180880496,0.00791354130197458,0.000391958140367314,0.957644283771515,0.969747543334961,32.6365699768066,INF,35,4,200,-2.45366427407134E-5,-0.318614453077316,0.0775952264666557,1,,,,,,,,,,,,,,,,
,3870613431.30971,196.614311218262,100.133750915527,,,6,,,,32.7858686290221,,,100,,,,,,,,,,,,,,,,,,,,,,196.211669921875,196.97688293457,100.133750915527,100.133750915527,,,7.31382942199707,,1,0,0,0,0.0138092041015625,30.7917900085449,2,1,1,197.016952514648,0,4232058688,196.585827636719,,,0.00759770421081115,0.00037646973790494,0.00760087977168918,0.000376470433285406,0.958307027816772,0.969877779483795,32.6764373779297,2.06545373657718E-5,35,4,200,-8.98158020845585E-7,-0.296618849039078,0.0737398937344551,1,,,,,,,,,,,,,,,,
,3870613541.27111,205.741157531738,100.133750915527,,,6,,,,32.824323991633,,,100,,,,,,,,,,,,,,,,,,,,,,205.351348876953,206.092208862305,100.133750915527,100.133750915527,,,7.34089088439941,,1,0,0,0,0.0138092041015625,30.7917900085449,2,1,1,206.130966186523,0,4232058624,205.720222473145,,,0.0073000365828454,0.000361713005594821,0.00730294365703603,0.000361714049676266,0.958783626556397,0.969845473766327,32.717658996582,0,35,4,200,-1.18572199880873E-6,-0.286046534776688,0.0697642266750336,1,,,,,,,,,,,,,,,,
,3870613651.87574,214.976783752441,100.133750915527,,,6,,,,32.8646876951256,,,100,,,,,,,,,,,,,,,,,,,,,,214.603515625,215.327667236328,100.133750915527,100.133750915527,,,7.37082529067993,,1,0,0,0,0.0138092041015625,30.7917900085449,2,1,1,215.350051879883,0,4232058656,214.965492248535,,,0.00701232033727961,0.000347450330532631,0.00701501339501806,0.000347451603456963,0.959241926670074,0.969973683357239,32.7600517272949,INF,35,4,200,-4.2737228795886E-6,-0.275825351476669,0.0658946931362152,1,,,,,,,,,,,,,,,,
,3870613762.01186,224.040634155273,100.133750915527,,,6,,,,32.9067373987424,,,100,,,,,,,,,,,,,,,,,,,,,,223.647720336914,224.39631652832,100.133750915527,100.133750915527,,,7.39546585083008,,1,0,0,0,0.0138092041015625,30.7917900085449,2,1,1,224.433547973633,0,4232058656,224.018057250977,,,0.00673838615152805,0.000333872690888259,0.0067409064887952,0.00033387411830477,0.959582209587097,0.970080614089966,32.8035774230957,INF,35,4,200,-3.0226151466195E-6,-0.266105204820633,0.0622347965836525,1,,,,,,,,,,,,,,,,
,3870613869.24152,232.941398620605,100.133750915527,,,6,,,,32.9492182125302,,,100,,,,,,,,,,,,,,,,,,,,,,232.550979614258,233.306503295898,100.133750915527,100.133750915527,,,7.41461992263794,,1,0,0,0,0.0138092041015625,30.7917900085449,2,1,1,233.331817626953,0,4232058656,232.926795959473,,,0.00648223133448819,0.000321176903608385,0.00648458770146913,0.000321177821369663,0.959877192974091,0.970174491405487,32.8473358154297,0.0766535624861717,35,4,200,-1.89813945326023E-5,-0.257006108760834,0.0588179044425487,1,,,,,,,,,,,,,,,,
,3870613979.27356,242.049560546875,100.133750915527,,,6,,,,32.9945521662833,,,100,,,,,,,,,,,,,,,,,,,,,,241.646728515625,242.414825439453,100.133750915527,100.133750915527,,,7.4548454284668,,1,0,0,0,0.0138092041015625,30.3030319213867,2,1,1,242.452392578125,0,4232058688,242.031117248535,,,0.00622938981109129,0.000308645315124458,0.00623159965496267,0.000308646296538074,0.960200488567352,0.97030383348465,32.8939437866211,5.73532438278198,35,4,200,-1.35629716169206E-6,-0.248048350214958,0.0554370619356632,1,,,,,,,,,,,,,,,,
,3870614089.91166,251.239723205566,100.133750915527,,,6,,,,33.0422191131469,,,100,,,,,,,,,,,,,,,,,,,,,,250.816864013672,251.62956237793,100.133750915527,100.133750915527,,,7.55379581451416,,1,0,0,0,0.0138092041015625,30.7917900085449,2,1,1,251.662582397461,0,4232058688,251.224130249023,,,0.00598571260498495,0.000296568387944421,0.00598778771205928,0.000296569470053307,0.960497736930847,0.970414042472839,32.9428329467773,0.18990932404995,35,4,200,-1.86730005680147E-6,-0.239408299326897,0.0521937310695648,1,,,,,,,,,,,,,,,,
,3870614200.03055,260.38623046875,100.133750915527,,,6,,,,33.0910670939807,,,100,,,,,,,,,,,,,,,,,,,,,,259.9892578125,260.747589111328,100.133750915527,100.133750915527,,,7.64437818527222,,1,0,0,0,0.0138092041015625,30.7917900085449,2,1,1,260.783203125,0,4232058656,260.377398681641,,,0.00575258443780088,0.000285011632982915,0.00575446784747734,0.00028501237179207,0.961048424243927,0.970529854297638,32.9943656921387,0.189870536327362,35,4,200,-1.55442576215137E-5,-0.231114789843559,0.0490991920232773,1,,,,,,,,,,,,,,,,
,3870614309.99526,269.514205932617,100.133750915527,,,6,,,,33.1418114611092,,,100,,,,,,,,,,,,,,,,,,,,,,269.129119873047,269.865936279297,100.133750915527,100.133750915527,,,7.57751655578613,,1,0,0,0,0.0138092041015625,30.3030319213867,2,1,1,269.899291992187,0,4232058720,269.499325561523,,,0.00552935952716293,0.000273941781527236,0.00553098261336691,0.000273942785295736,0.96201765537262,0.970611810684204,33.0504493713379,3.98507928848267,35,4,200,-3.32063200403354E-6,-0.223198309540749,0.0461225360631943,1,,,,,,,,,,,,,,,,
,3870614420.90726,278.707077026367,100.133750915527,,,6,,,,33.1944898709591,,,100,,,,,,,,,,,,,,,,,,,,,,278.302185058594,279.030181884766,100.133750915527,100.133750915527,,,7.57676410675049,,1,0,0,0,0.0138092041015625,30.7917900085449,2,1,1,279.111968994141,0,4232058656,278.681256103516,,,0.00531380954322736,0.000263241774176652,0.0053149411903591,0.000263241945012318,0.964173436164856,0.970684230327606,33.1162948608398,,35,4,200,-1.51804852066562E-6,-0.215531259775162,0.0432534590363503,1,,,,,,,,,,,,,,,,
,3870614531.07251,287.883392333984,100.133750915527,,,6,,,,33.2489839766383,,,100,,,,,,,,,,,,,,,,,,,,,,287.476470947266,288.249053955078,100.133750915527,100.133750915527,,,7.62010431289673,,1,0,0,0,0.0138092041015625,30.7917900085449,2,1,1,288.290313720703,0,4232058688,287.873315429688,,,0.00510708950178108,0.000252972855330825,0.00510763435392175,0.000252972852539983,0.967415452003479,0.970869660377502,33.1935424804687,0,35,4,200,-1.32346476675593E-5,-0.208209082484245,0.0404941886663437,1,,,,,,,,,,,,,,,,
,3870614641.39492,297.022506713867,100.133750915527,,,6,,,,33.3051063348195,,,100,,,,,,,,,,,,,,,,,,,,,,296.614715576172,297.397644042969,100.133750915527,100.133750915527,,,7.75939655303955,,1,0,0,0,0.0138092041015625,31.2805480957031,2,1,1,297.430297851562,0,4232058592,297.007641601562,,,0.00490858309663207,0.00024311714872136,0.00490868638262363,0.000243117127404745,0.970471262931824,0.971195042133331,33.2804336547852,5.96382269577589E-5,35,4,200,-6.07796891927137E-7,-0.190257146954536,0.048710860311985,1,,,,,,,,,,,,,,,,
,3870614717.3953,299.80810546875,100.133750915527,,,6,,,,33.3205884587295,,,100,,,,,,,,,,,,,,,,,,,,,,299.781188964844,299.833587646484,100.133750915527,100.133750915527,,,7.92284870147705,,1,0,0,0,0.0138092041015625,31.2805480957031,5,1,1,299.835021972656,0,4232058720,299.811825561523,,,0.00484125004058567,0.000239778384587563,0.00484131042991953,0.00023977823540415,0.971013188362122,0.971468210220337,33.3011627197266,7.24266192264622E-6,35,4,200,-1.92797210729623E-6,-0.18775562942028,0.0477006994187832,1,,,,,,,,,,,,,,,,
,3870614800.59043,299.901306152344,100.133750915527,,,6,,,,33.3205884587295,,,100,,,,,,,,,,,,,,,,,,,,,,299.830993652344,299.977172851562,100.133750915527,100.133750915527,,,8.18744850158691,,1,0,0,0,0.0138092041015625,30.7917900085449,2,1,1,299.825439453125,0,4232057920,299.922036743164,,,0.0048358513501851,0.000239509010000499,0.00483588924955741,0.000239508863325773,0.971301198005676,0.971596896648407,33.3049812316895,5.26776742935181,35,4,200,2.22769614310891E-7,-0.187774762511253,0.0474044121801853,1,,,,,,,,,,,,,,,,
,3870614902.30237,292.299621582031,100.133750915527,,,6,,,,33.2774229744383,,,100,,,,,,,,,,,,,,,,,,,,,,291.914001464844,292.736419677734,100.133750915527,100.133750915527,,,8.5144100189209,,1,0,0,0,0.0138092041015625,30.7917900085449,2,1,1,291.862823486328,0,4232058784,292.330020141602,,,0.00501050881369101,0.000248157798460144,0.00501053194745015,0.000248157694676765,0.971520781517029,0.971697986125946,33.2653770446777,INF,35,4,200,4.25493963120971E-5,-0.193813234567642,0.0500517599284649,1,,,,,,,,,,,,,,,,
,3870615012.35614,282.973999023438,100.133750915527,,,6,,,,33.2286012111004,,,100,,,,,,,,,,,,,,,,,,,,,,282.585906982422,283.354034423828,100.133750915527,100.133750915527,,,8.4674825668335,,1,0,0,0,0.0138092041015625,30.7917900085449,2,1,1,282.571472167969,0,4232058976,282.993481445313,,,0.00525475325448035,0.000260255932972534,0.00525481567589985,0.000260255845401241,0.971339643001556,0.971768736839294,33.2098388671875,3.97558689117432,35,4,200,2.40974222833756E-5,-0.213274225592613,0.0422862805426121,1,,,,,,,,,,,,,,,,
,3870615122.28642,273.981506347656,100.133750915527,,,6,,,,33.1833643049874,,,100,,,,,,,,,,,,,,,,,,,,,,273.579132080078,274.415130615234,100.133750915527,100.133750915527,,,8.29906463623047,,1,0,0,0,0.0138092041015625,30.7917900085449,2,1,1,273.547882080078,0,4232058624,274.012524414062,,,0.00545023813797687,0.000269967083815098,0.0054508441170221,0.000269967199744238,0.96779465675354,0.971436142921448,33.1268730163574,5.75559520721436,35,4,200,3.91576832043938E-5,-0.220255702733994,0.0449264943599701,1,,,,,,,,,,,,,,,,
,3870615232.3364,264.73583984375,100.133750915527,,,6,,,,33.1383641271233,,,100,,,,,,,,,,,,,,,,,,,,,,264.367492675781,265.137329101562,100.133750915527,100.133750915527,,,8.16744041442871,,1,0,0,0,0.0138092041015625,30.7917900085449,2,1,1,264.334350585938,0,4232058752,264.766595458984,,,0.00568577763129287,0.000281656900724146,0.00568681083404683,0.000281656918611758,0.965362668037415,0.971071839332581,33.0660247802734,0,35,4,200,3.99886375817005E-5,-0.228566765785217,0.0481331199407578,1,,,,,,,,,,,,,,,,
,3870615342.22666,255.55712890625,100.133750915527,,,6,,,,33.0966851193117,,,100,,,,,,,,,,,,,,,,,,,,,,255.218948364258,255.971282958984,100.133750915527,100.133750915527,,,8.07649517059326,,1,0,0,0,0.0138092041015625,30.3030319213867,2,1,1,255.142974853516,0,4232058496,255.595622253418,,,0.00592278854885822,0.000293419270543305,0.0059242541512291,0.000293419749066616,0.963314592838287,0.970763385295868,33.0125465393066,0,35,4,200,4.30216787208337E-5,-0.236911743879318,0.0513190403580666,1,,,,,,,,,,,,,,,,
,3870615452.41229,246.364471435547,100.133750915527,,,6,,,,33.0570816761199,,,100,,,,,,,,,,,,,,,,,,,,,,245.979919433594,246.788955688477,100.133750915527,100.133750915527,,,8.01388931274414,,1,0,0,0,0.0138092041015625,30.3030319213867,2,1,1,245.939987182617,0,4232058688,246.388407897949,,,0.00616765822679172,0.000305572488589505,0.0061695900103486,0.000305573280315776,0.961382925510407,0.97048956155777,32.9625091552734,0,35,4,200,4.46106641902588E-5,-0.245574459433556,0.0545930601656437,1,,,,,,,,,,,,,,,,
,3870615563.04023,237.14427947998,100.133750915527,,,6,,,,33.0191642842069,,,100,,,,,,,,,,,,,,,,,,,,,,236.750793457031,237.567001342773,100.133750915527,100.133750915527,,,7.96818971633911,,1,0,0,0,0.0138092041015625,31.2805480957031,2,1,1,236.721557617187,0,4232058656,237.175341796875,,,0.00642389283152968,0.000318291377896794,0.00642634211647761,0.000318292254124068,0.959487318992615,0.970245480537415,32.9147796630859,,35,4,200,2.78037823591148E-5,-0.254659324884415,0.057988379150629,1,,,,,,,,,,,,,,,,
,3870615673.0321,228.002075195313,100.133750915527,,,6,,,,32.9829582371308,,,100,,,,,,,,,,,,,,,,,,,,,,227.629776000977,228.410766601562,100.133750915527,100.133750915527,,,7.93107414245606,,1,0,0,0,0.0138092041015625,30.7917900085449,2,1,1,227.593383789062,0,4232058592,228.034133911133,,,0.00668623630307113,0.000331316358472133,0.00668929841371066,0.000331318323194325,0.957569003105164,0.970037817955017,32.8688926696777,0,35,4,200,4.35050169471651E-5,-0.264010101556778,0.0614701546728611,1,,,,,,,,,,,,,,,,
,3870615783.56188,218.74201965332,100.133750915527,,,6,,,,32.9469686520318,,,100,,,,,,,,,,,,,,,,,,,,,,218.371185302734,219.130905151367,100.133750915527,100.133750915527,,,7.9048957824707,,1,0,0,0,0.0138092041015625,30.3030319213867,2,1,1,218.353134155273,0,4232058656,218.761685180664,,,0.00696234771626541,0.000345023220096367,0.00696600968427603,0.00034502508260288,0.955899357795715,0.969908654689789,32.8245735168457,0,35,4,200,4.35913898400031E-5,-0.273816525936127,0.0651654377579689,1,,,,,,,,,,,,,,,,
,3870615893.53614,209.592277526855,100.133750915527,,,6,,,,32.9125534941376,,,100,,,,,,,,,,,,,,,,,,,,,,209.195358276367,210.025543212891,100.133750915527,100.133750915527,,,7.87475776672363,,1,0,0,0,0.0138092041015625,30.7917900085449,2,1,1,209.15901184082,0,4232058784,209.636616516113,,,0.00724629962051333,0.000359124032197806,0.00725067466178473,0.00035912692823752,0.954087674617767,0.969689786434174,32.7816429138184,0,35,4,200,4.44373181380797E-5,-0.283910095691681,0.0690584927797318,1,,,,,,,,,,,,,,,,
,3870616003.61212,200.404090881348,100.133750915527,,,6,,,,32.8781175142715,,,100,,,,,,,,,,,,,,,,,,,,,,200.030212402344,200.810424804687,100.133750915527,100.133750915527,,,7.83198976516724,,1,0,0,0,0.0138092041015625,30.7917900085449,2,1,1,199.997756958008,0,4232058720,200.428678894043,,,0.00754774205416493,0.000374090795594811,0.00755275940542214,0.000374092969235553,0.952525854110718,0.96936571598053,32.7404441833496,0,35,4,200,4.9551650590729E-5,-0.294613689184189,0.0731192603707314,1,,,,,,,,,,,,,,,,
,3870616113.52859,191.275436401367,100.133750915527,,,6,,,,32.8449665153182,,,100,,,,,,,,,,,,,,,,,,,,,,190.898391723633,191.685119628906,100.133750915527,100.133750915527,,,7.78551626205444,,1,0,0,0,0.0138092041015625,30.7917900085449,2,1,1,190.865753173828,0,4232058624,191.288768005371,,,0.00785846720766325,0.000389527379796456,0.00786435646584821,0.000389531023163929,0.950616240501404,0.968988597393036,32.6990928649902,2.66599290625891E-5,35,4,200,5.07269905938301E-5,-0.316625654697418,0.077237568795681,1,,,,,,,,,,,,,,,,
,3870616223.81736,182.102462768555,100.133750915527,,,6,,,,32.8122791260832,,,100,,,,,,,,,,,,,,,,,,,,,,181.758651733398,182.514602661133,100.133750915527,100.133750915527,,,7.7378101348877,,1,0,0,0,0.0138092041015625,30.7917900085449,2,1,1,181.690322875977,0,4232058720,182.146250915527,,,0.0081823016602282,0.000405613195532192,0.00818905753100128,0.000405615288417182,0.94894927740097,0.968874871730804,32.6586837768555,0.000146494145155884,35,4,200,5.51399098185357E-5,-0.328125447034836,0.0706854090094566,1,,,,,,,,,,,,,,,,
,3870616334.10015,172.873588562012,100.133750915527,,,6,,,,32.7799116344296,,,100,,,,,,,,,,,,,,,,,,,,,,172.496826171875,173.276458740234,100.133750915527,100.133750915527,,,7.69084405899048,,1,0,0,0,0.0138092041015625,30.7917900085449,2,1,1,172.470718383789,0,4232058752,172.897074890137,,,0.00852315913540879,0.000422544426356328,0.00853088496803322,0.00042254778408685,0.947392225265503,0.96877908706665,32.6191940307617,5.26261329650879,35,4,200,3.87291620427277E-5,-0.340229839086533,0.0752598270773888,1,,,,,,,,,,,,,,,,
,3870616444.23076,163.71257019043,100.133750915527,,,6,,,,32.7487771658553,,,100,,,,,,,,,,,,,,,,,,,,,,163.356414794922,164.119781494141,100.133750915527,100.133750915527,,,7.649573802948,,1,0,0,0,0.0008392333984375,30.7917900085449,2,1,1,163.305358886719,0,4232058688,163.761180114746,,,0.0088744548408733,0.000439997238359878,0.00888328353012085,0.000440003927710577,0.945825099945068,0.96868771314621,32.5809707641602,0,35,4,200,3.96515461034142E-5,-0.352820008993149,0.0799173712730408,1,,,,,,,,,,,,,,,,
,3870616545.57603,155.270378112793,100.133750915527,,,6,,,,32.7206437779185,,,100,,,,,,,,,,,,,,,,,,,,,,154.91145324707,155.679473876953,100.133750915527,100.133750915527,,,7.61659479141235,,1,0,0,0,0.0138092041015625,29.8142719268799,2,1,1,154.861282348633,0,4232058624,155.306176757812,,,0.00921455362526171,0.000456896373391285,0.00922443347305588,0.0004569026044492,0.944352030754089,0.96861469745636,32.5462265014648,0,35,4,200,4.31051958003081E-5,-0.364791989326477,0.084516279399395,1,,,,,,,,,,,,,,,,
,3870616645.37547,146.870475769043,100.133750915527,,,6,,,,32.6930439039544,,,100,,,,,,,,,,,,,,,,,,,,,,146.502517700195,147.270462036133,100.133750915527,100.133750915527,,,7.57559680938721,,1,0,0,0,0.0138092041015625,30.7917900085449,2,1,1,146.470489501953,0,4232058624,146.892962646484,,,0.00957156212803637,0.000474631921122201,0.00958251810510799,0.000474639165277537,0.943105697631836,0.968626737594605,32.5128860473633,3.17805934173521E-5,35,4,200,7.07348954165354E-5,-0.377489745616913,0.0892765820026398,1,,,,,,,,,,,,,,,,
,3870616730.14071,139.804748535156,100.133750915527,,,6,,,,32.6707184820433,,,100,,,,,,,,,,,,,,,,,,,,,,139.437393188477,140.213775634766,100.133750915527,100.133750915527,,,7.55555963516235,,1,0,0,0,0.0145721435546875,30.7917900085449,2,1,1,139.395721435547,0,4232058624,139.832057189941,,,0.0098769749130068,0.000489810441526927,0.0098889796818706,0.000489817142373046,0.94190526008606,0.968723773956299,32.4848709106445,0,35,4,200,4.46982448920608E-5,-0.388224422931671,0.0933803394436836,1,,,,,,,,,,,,,,,,
,3870616813.38153,132.903503417969,100.133750915527,,,6,,,,32.6492567142217,,,100,,,,,,,,,,,,,,,,,,,,,,132.540420532227,133.297821044922,100.133750915527,100.133750915527,,,7.53822946548462,,1,0,0,0,0.0138092041015625,30.7917900085449,2,1,1,132.509185791016,0,4232058688,132.927685546875,,,0.0101874472958305,0.00050524527698314,0.0102006645699069,0.000505254994732946,0.940625905990601,0.968753159046173,32.4575996398926,3.29937647620682E-5,35,4,200,4.82722862216178E-5,-0.410110890865326,0.0974836945533752,1,,,,,,,,,,,,,,,,
,3870616897.7411,125.953617095947,100.133750915527,,,6,,,,32.6279300588875,,,100,,,,,,,,,,,,,,,,,,,,,,125.578514099121,126.328720092773,100.133750915527,100.133750915527,,,7.49908828735352,,1,0,0,0,0.0138092041015625,30.7917900085449,2,1,1,125.578514099121,0,4232058656,125.952507019043,,,0.0105151528605302,0.000521537516069909,0.0105296747854848,0.00052154884560591,0.93935638666153,0.96889990568161,32.4302864074707,5.2603874206543,35,4,200,7.33899214537814E-5,-0.42184841632843,0.101872757077217,1,,,,,,,,,,,,,,,,
,3870616979.02559,119.167358398438,100.133750915527,,,6,,,,32.6075590078785,,,100,,,,,,,,,,,,,,,,,,,,,,118.774467468262,119.594215393066,100.133750915527,100.133750915527,,,7.44672584533691,,1,0,0,0,0.0138092041015625,30.7917900085449,2,1,1,118.740501403809,0,4232058752,119.17667388916,,,0.0108431224996264,0.000537839640954669,0.0108589119240762,0.00053785343436597,0.938287436962128,0.969075560569763,32.4048042297363,,35,4,200,7.01363169355318E-5,-0.433588981628418,0.106173656880856,1,,,,,,,,,,,,,,,,
,3870617060.09301,112.427360534668,100.133750915527,,,6,,,,32.5881809692622,,,100,,,,,,,,,,,,,,,,,,,,,,112.058044433594,112.829162597656,100.133750915527,100.133750915527,,,7.41697406768799,,1,0,0,0,0.0145721435546875,30.7917900085449,2,1,1,112.02555847168,0,4232058688,112.44912109375,,,0.0111834968854242,0.000554763263605199,0.0112005425289172,0.000554773613981175,0.937125504016876,0.969147741794586,32.380184173584,0,35,4,200,8.35106911836192E-5,-0.44537827372551,0.100012615323067,1,,,,,,,,,,,,,,,,
,3870617141.24784,105.684734344482,100.133750915527,,,6,,,,32.5695259865165,,,100,,,,,,,,,,,,,,,,,,,,,,105.315902709961,106.10033416748,100.133750915527,100.133750915527,,,7.3982892036438,,1,0,0,0,0.0138092041015625,30.3030319213867,2,1,1,105.269134521484,0,4232058720,105.711206817627,,,0.0115354947051207,0.000572266877705849,0.0115540852827487,0.000572280394034592,0.935959100723267,0.969408094882965,32.355899810791,0,35,4,200,4.63911310362164E-5,-0.458094090223312,0.104616582393646,1,,,,,,,,,,,,,,,,
,3870617222.44861,98.9120635986328,100.133750915527,,,6,,,,32.5513298613726,,,100,,,,,,,,,,,,,,,,,,,,,,98.5496520996094,99.3334808349609,100.133750915527,100.133750915527,,,7.38653564453125,,1,0,0,0,0.0145721435546875,30.7917900085449,2,1,1,98.4906463623047,0,4232058688,98.9392776489258,,,0.0119012482994752,0.000590457406357911,0.0119214247612971,0.000590473046048516,0.934762001037598,0.969506621360779,32.3323135375977,,35,4,200,4.31562621088233E-5,-0.470916628837585,0.109535858035088,1,,,,,,,,,,,,,,,,
,3870617305.82689,91.9551010131836,100.133750915527,,,6,,,,32.5337087805639,,,100,,,,,,,,,,,,,,,,,,,,,,91.5729293823242,92.3590774536133,100.133750915527,100.133750915527,,,7.33647298812866,,1,0,0,0,0.0138092041015625,30.7917900085449,2,1,1,91.5511245727539,0,4232058592,91.9771049499512,,,0.0122738956031737,0.000608993685770757,0.012295798315643,0.000609009353514171,0.933567404747009,0.969862222671509,32.3088531494141,0.000181407856871374,35,4,200,8.01676724222489E-5,-0.483913868665695,0.114579200744629,1,,,,,,,,,,,,,,,,
,3870617390.47268,84.9115943908691,100.133750915527,,,6,,,,32.5163504560097,,,100,,,,,,,,,,,,,,,,,,,,,,84.5331802368164,85.3396301269531,100.133750915527,100.133750915527,,,7.27315664291382,,1,0,0,0,0.0145721435546875,30.3030319213867,2,1,1,84.4835586547852,0,4232058688,84.9298599243164,,,0.0126762922826236,0.000629023473457219,0.01270020418897,0.000629040976264652,0.932057023048401,0.969783663749695,32.2852058410645,3.55828124156687E-5,35,4,200,8.33559170132503E-5,-0.509120941162109,0.120073564350605,1,,,,,,,,,,,,,,,,
,3870617475.05829,77.7625274658203,100.133750915527,,,6,,,,32.4996037893746,,,100,,,,,,,,,,,,,,,,,,,,,,77.3862915039063,78.1655502319336,100.133750915527,100.133750915527,,,7.21643781661987,,1,0,0,0,0.0138092041015625,29.8142719268799,2,1,1,77.359504699707,0,4232058752,77.7734939575195,,,0.0130671278513555,0.000648473852923015,0.0130930811771939,0.000648492090094253,0.930798172950745,0.970202744007111,32.262336730957,0.274903982877731,35,4,200,4.44687575509306E-5,-0.522768378257751,0.125296249985695,1,,,,,,,,,,,,,,,,
,3870617558.26768,70.7692375183105,100.133750915527,,,6,,,,32.48353363967,,,100,,,,,,,,,,,,,,,,,,,,,,70.3886032104492,71.1826095581055,100.133750915527,100.133750915527,,,7.16029739379883,,1,0,0,0,0.0145721435546875,30.3030319213867,2,1,1,70.3558654785156,0,4232058720,70.8038856506348,,,0.0134480461279098,0.000667434486969564,0.0134759287071707,0.000667452690586675,0.929579854011536,0.970283508300781,32.2410011291504,,35,4,200,7.54528373363428E-5,-0.5361447930336,0.130488499999046,1,,,,,,,,,,,,,,,,
,3870617633.88983,64.4155941009522,100.133750915527,,,6,,,,32.4717398224712,,,100,,,,,,,,,,,,,,,,,,,,,,64.0467834472656,64.7432556152344,100.133750915527,100.133750915527,,,7.13348388671875,,1,0,0,0,0.0145721435546875,30.7917900085449,2,1,1,63.998233795166,0,4232058624,64.3987536960178,,,0.0137716630182208,0.000683572490335426,0.0138019100947108,0.000683594882645597,0.928009569644928,0.970446705818176,32.2223320007324,0,35,4,200,7.72200219216756E-5,-0.547690987586975,0.123959265649319,1,,,,,,,,,,,,,,,,
,3870617710.59936,57.9575233459473,100.133750915527,,,6,,,,32.458651265933,,,100,,,,,,,,,,,,,,,,,,,,,,57.5838012695313,58.3618240356445,100.133750915527,100.133750915527,,,7.05409479141235,,1,0,0,0,0.0145721435546875,30.3030319213867,2,1,1,57.55322265625,0,4232058464,57.9597072601318,,,0.0140644426746159,0.000698166823596067,0.0140966634642957,0.000698190442475388,0.926793813705444,0.970602631568909,32.2039070129395,0,35,4,200,3.6027795431437E-5,-0.558019995689392,0.127926498651505,1,,,,,,,,,,,,,,,,
,3870617786.50058,51.5545845031738,100.133750915527,,,6,,,,32.4462676862555,,,100,,,,,,,,,,,,,,,,,,,,,,51.1745262145996,51.9568634033203,100.133750915527,100.133750915527,,,6.97350788116455,,1,0,0,0,0.0138092041015625,30.7917900085449,2,1,1,51.1523056030273,0,4232058560,51.5614101409912,,,0.0142867513516595,0.000709263578190441,0.014320772268721,0.000709288040640649,0.925627887248993,0.970703959465027,32.1864967346191,0,35,4,200,6.62285819998942E-5,-0.565894842147827,0.130927801132202,1,,,,,,,,,,,,,,,,
,3870617862.42829,45.1282653808594,100.133750915527,,,6,,,,32.4347892850847,,,100,,,,,,,,,,,,,,,,,,,,,,44.7639808654785,45.5430183410645,100.133750915527,100.133750915527,,,6.8903021812439,,1,0,0,0,0.0145721435546875,30.7917900085449,2,1,1,44.7135124206543,0,4232058752,45.1440155029297,,,0.0144146819889396,0.000715677297693491,0.0144503760929947,0.000715705260156761,0.92447167634964,0.970805883407593,32.1700782775879,3.7388159398688E-5,35,4,200,5.20826251886319E-5,-0.570314288139343,0.132672414183617,1,,,,,,,,,,,,,,,,
,3870617938.25787,38.7438259124756,100.133750915527,,,6,,,,32.4241541954959,,,100,,,,,,,,,,,,,,,,,,,,,,38.4037055969238,39.1467056274414,100.133750915527,100.133750915527,,,6.80618858337402,,1,0,0,0,0.0138092041015625,30.7917900085449,2,1,1,38.3409461975098,0,4232058496,38.7761375427246,,,0.0144526752276325,0.000717637252694378,0.0144898799469709,0.000717661101767501,0.923132181167603,0.970838010311127,32.1539001464844,0,35,4,200,4.58623690064996E-5,-0.571654140949249,0.133228451013565,1,,,,,,,,,,,,,,,,
,3870618005.3224,33.0777282714844,100.133750915527,,,6,,,,32.4178983543103,,,100,,,,,,,,,,,,,,,,,,,,,,32.7235679626465,33.4809455871582,100.133750915527,100.133750915527,,,6.67059087753296,,1,0,0,0,0.0145721435546875,30.7917900085449,2,1,1,32.6745109558105,0,4232058688,33.0947772979736,,,0.0144387699459041,0.000717035018958088,0.0144778089855667,0.000717060649842325,0.921554088592529,0.97095400094986,32.1409568786621,5.66929912567139,35,4,200,4.01241595682222E-5,-0.571292400360107,0.133139759302139,1,,,,,,,,,,,,,,,,
,3870618081.55824,26.6993494033813,100.133750915527,,,6,,,,32.406365998292,,,100,,,,,,,,,,,,,,,,,,,,,,26.3243217468262,27.0992908477783,100.133750915527,100.133750915527,,,6.46606206893921,,1,0,0,0,0.0145721435546875,30.3030319213867,2,1,1,26.2994079589844,0,4232058816,26.7142059326172,,,0.0144163514408827,0.000715943865065486,0.014455826396701,0.000715970560726873,0.921174347400665,0.971049010753632,32.127742767334,0,35,4,200,4.26183250965551E-5,-0.570454299449921,0.132923811674118,1,,,,,,,,,,,,,,,,
,3870618147.70725,21.1804389953613,100.133750915527,,,6,,,,32.401069953589,,,100,,,,,,,,,,,,,,,,,,,,,,20.8146953582764,21.578010559082,100.133750915527,100.133750915527,,,6.21368360519409,,1,0,0,0,0.0145721435546875,30.7917900085449,2,1,1,20.7828674316406,0,4232058624,21.2046161651611,,,0.0144076939964196,0.000715573768645625,0.0144484759119333,0.000715603394973395,0.920118868350983,0.971176981925964,32.1178970336914,0,35,4,200,9.06005789147457E-6,-0.570141971111298,0.132839381694794,1,,,,,,,,,,,,,,,,
,3870618221.18539,15.1140508651733,100.133750915527,,,6,,,,32.3898510555697,,,100,,,,,,,,,,,,,,,,,,,,,,14.7727212905884,15.5052785873413,100.133750915527,100.133750915527,,,5.68412733078003,,1,0,0,0,0.0138092041015625,30.7917900085449,2,1,1,14.7228231430054,0,4232058592,15.1379286766052,,,0.0144253183106006,0.000716418124251081,0.014465419509221,0.000716443417343042,0.92066365480423,0.971150636672974,32.1089401245117,0,35,4,200,1.26131026263465E-5,-0.570599257946014,0.133120194077492,1,,,,,,,,,,,,,,,,
,3870618287.05577,9.94027614593506,100.133750915527,,,6,,,,32.3845012545328,,,100,,,,,,,,,,,,,,,,,,,,,,9.70707321166992,10.2096004486084,100.133750915527,100.133750915527,,,4.57567310333252,,1,0,0,0,0.0145721435546875,30.7917900085449,2,1,1,9.67095184326172,0,4232059104,9.95093240737915,,,0.0144541458340048,0.000717851909885651,0.0144944442145422,0.000717880246496391,0.92062121629715,0.971168458461762,32.1034126281738,0,35,4,200,4.56713896710426E-5,-0.571525514125824,0.133573457598686,1,,,,,,,,,,,,,,,,
,3870618345.43082,5.36449337005615,100.133750915527,,,6,,,,32.3845012545328,,,100,,,,,,,,,,,,,,,,,,,,,,5.0245509147644,5.71313524246216,100.133750915527,100.133750915527,,,3.89743638038635,,1,0,0,0,0.0146484375,30.7917900085449,6,1,1,5.01585149765015,0,4232058816,5.33361387252808,,,0.0144856351188422,0.000719417077223243,0.0145260552038065,0.000719445002894358,0.920601069927216,0.971216380596161,32.1032333374023,0.112650215625763,35,4,200,5.03954470332246E-5,-0.57273930311203,0.133979603648186,1,,,,,,,,,,,,,,,,
,3870618403.91204,5.00215530395508,100.133750915527,,,6,,,,32.3845012545328,,,100,,,,,,,,,,,,,,,,,,,,,,4.99900579452515,5.0042986869812,100.133750915527,100.133750915527,,,3.763827085495,,1,0,0,0,0.0145721435546875,30.7917900085449,5,1,1,5.00283622741699,0,4232058784,5.00268242094252,,,0.0144873284148476,0.000719488956836537,0.014527575257346,0.000719519922547814,0.920809805393219,0.971222877502441,32.1040802001953,0,35,4,200,4.45772166131064E-5,-0.572657227516174,0.133990675210953,1,,,,,,,,,,,,,,,,
,3870618423.34161,5.00123167037964,100.133750915527,,,6,,,,32.3845012545328,,,100,,,,,,,,,,,,,,,,,,,,,,4.99730730056763,5.00170278549194,100.133750915527,100.133750915527,,,3.76775074005127,,1,0,0,0,0.0145721435546875,30.7917900085449,1,1,1,5.00187110900879,0,4232058752,4.99942312240601,,,0.0144878281037292,0.000719510133530153,0.014527979002155,0.000719540413058447,0.920879244804382,0.971215426921844,32.1043586730957,INF,35,4,200,4.76783570775297E-5,-0.572721719741821,0.134001776576042,1,,,,,,,,,,,,,,,,