File: Data/KMK273/MvsH/KMK273_MvsH_300K.dat
[Header]
; MPMS3 Data File (default extension .dat)
; Copyright (c) 2007, Quantum Design, Inc. All rights reserved.
TITLE,
FILEOPENTIME,3870598780.98006,08/25/2022,2:19 pm
BYAPP,MPMS3 w/ AC,1.0,1.1
INFO,MPMS3 Measurement Release 1.1.16 Build 424, MultiVu Release 2.3.4.19,APPNAME
INFO,Linear Motor Servo Controller,MOTOR_MODULE_NAME
INFO,3101-100 J0,MOTOR_HW_VERSION
INFO,MMC721,MOTOR_SERIAL_NUMBER
INFO,01.04.28,MOTOR_SOFTWARE_VERSION
INFO,Quantum Design Squid Module,SQUID_MODULE_NAME
INFO,3101-501 B0,SQUID_HW_VERSION
INFO,SQM195,SQUID_SERIAL_NUMBER
INFO,01.03.04,SQUID_SOFTWARE_VERSION
INFO,SQUID AC,AC_MODULE_NAME
INFO,3101-401 f1,AC_HW_VERSION
INFO,SAC107,AC_SERIAL_NUMBER
INFO,SQUID AC 00.95.07,AC_SOFTWARE_VERSION
INFO,TCI166,COIL_SERIAL_NUMBER
INFO,0,MOMENT_UNITS
INFO,KMK273,SAMPLE_MATERIAL
INFO,,SAMPLE_COMMENT
INFO,2.3,SAMPLE_MASS
INFO,,SAMPLE_VOLUME
INFO,,SAMPLE_MOLECULAR_WEIGHT
INFO,,SAMPLE_SIZE
INFO,,SAMPLE_SHAPE
INFO,Straw,SAMPLE_HOLDER
INFO,Standard,SAMPLE_HOLDER_DETAIL
INFO,66.53,SAMPLE_OFFSET
DATATYPE,COMMENT,1
DATATYPE,TIME,2
STARTUPAXIS,X,2
STARTUPAXIS,Y1,5
FIELDGROUP, VSM,2,3,4,5,6,8,9,10,11,14,15
FIELDGROUP, DC, 2,3,4,14,56,57,58,59,60,61,62,63,64,65,66,67,68,69
FIELDGROUP, AC, 2,3,4,11,16,17,18,19,20,21,22,23,24,25,26,27,28,29,30
STARTUPGROUP, All
[Data]
Comment,Time Stamp (sec),Temperature (K),Magnetic Field (Oe),Moment (emu),M. Std. Err. (emu),Transport Action,Averaging Time (sec),Frequency (Hz),Peak Amplitude (mm),Center Position (mm),Lockin Signal' (V),Lockin Signal (V),Range,M. Quad. Signal (emu),AC Moment (emu),AC M. Std Err. (emu),AC Phase (deg),AC Phase Std. Err. (deg),AC Susceptibility (emu/Oe),AC Suscept. Std Err. (emu/Oe),AC X' (emu/Oe),AC X' Std Err. (emu/Oe),AC X'' (emu/Oe),AC X'' Std Err. (emu/Oe),AC Drive (Oe),AC Frequency (Hz),AC Averaging Time (sec),AC Cycles,AC Range,AC Measure Type,AC Signal' (V),AC Signal'' (V),AC Trim Coil Ratio,AC Trim Coil Phase,Min. Temperature (K),Max. Temperature (K),Min. Field (Oe),Max. Field (Oe),Mass (grams),Motor Lag (deg),Pressure (Torr),Measure Count,Measurement Number,SQUID Status (code),Motor Status (code),Measure Status (code),Motor Current (amps),Motor Temp. (C),Temp. Status (code),Field Status (code),Chamber Status (code),Chamber Temp (K),Redirection State,Evercool Status,Average Temp (K),Rotation Angle (deg),Rotator state,DC Moment Fixed Ctr (emu),DC Moment Err Fixed Ctr (emu),DC Moment Free Ctr (emu),DC Moment Err Free Ctr (emu),DC Fixed Fit,DC Free Fit,DC Calculated Center (mm),DC Calculated Center Err (mm),DC Scan Length (mm),DC Scan Time (s),DC Number of Points,DC Squid Drift,DC Min V (V),DC Max V (V),DC Scans per Measure,Map 01,Map 02,Map 03,Map 04,Map 05,Map 06,Map 07,Map 08,Map 09,Map 10,Map 11,Map 12,Map 13,Map 14,Map 15,Map 16
,3870598925.33135,299.995223999023,-70000.375,,,6,,,,33.3224563598633,,,100,,,,,,,,,,,,,,,,,,,,,,299.989440917969,300.007873535156,-70000.375,-70000.375,,,7.52901315689087,,1,0,0,0,0.0138092041015625,30.3030319213867,1,1,1,299.994415283203,0,4232058624,299.999000950863,,,-0.123237890580536,0.00610471135657362,-0.123242401185821,0.00610472254783408,0.966021955013275,0.967059910297394,33.3540687561035,0,35,4,200,-0.00227928441017866,-4.78715467453003,4.8359808921814,1,,,,,,,,,,,,,,,,
,3870599089.51437,300.073471069336,-45000.328125,,,6,,,,33.3224563598633,,,100,,,,,,,,,,,,,,,,,,,,,,300.066253662109,300.086212158203,-45000.328125,-45000.328125,,,7.6514949798584,,1,0,0,0,0.0138092041015625,30.7917900085449,1,1,1,300.067016601562,0,4232058688,300.077877807617,,,-0.121865445079003,0.0060361957864878,-0.121865859478625,0.00603619808213925,0.968698501586914,0.96879506111145,33.3317756652832,,35,4,200,0.00271851732395589,-1.15951824188232,4.79222345352173,1,,,,,,,,,,,,,,,,
,3870599239.1298,300.019744873047,-20000.36328125,,,6,,,,33.3224563598633,,,100,,,,,,,,,,,,,,,,,,,,,,300.012451171875,300.032409667969,-20000.36328125,-20000.36328125,,,7.70045518875122,,1,0,0,0,0.0018310546875,31.2805480957031,1,1,1,300.012603759766,0,4232058656,300.023635864258,,,-0.118441649300967,0.00586633985052592,-0.118441647180225,0.00586633954915918,0.970212161540985,0.970213294029236,33.321475982666,5.26804685592651,35,4,200,0.0028436672873795,-1.11091148853302,4.66942119598389,1,,,,,,,,,,,,,,,,
,3870599391.86359,300.071640014648,-8500.4794921875,,,6,,,,33.3224563598633,,,100,,,,,,,,,,,,,,,,,,,,,,300.051208496094,300.092468261719,-8500.4794921875,-8500.4794921875,,,7.77863454818726,,1,0,0,0,0.0138092041015625,30.7917900085449,1,1,1,300.050811767578,0,4232058592,300.073846435547,,,-0.11102492091439,0.00549888160485925,-0.11102492236611,0.00549888136925756,0.970903635025024,0.970905542373657,33.3211860656738,0.189816698431969,35,4,200,0.00346492417156696,-1.03506076335907,4.3790922164917,1,,,,,,,,,,,,,,,,
,3870599510.36887,299.962249755859,-6000.32568359375,,,6,,,,33.3224563598633,,,100,,,,,,,,,,,,,,,,,,,,,,299.958984375,299.974212646484,-6000.32568359375,-6000.32568359375,,,7.78759336471558,,1,0,0,0,0.0138092041015625,30.7917900085449,1,1,1,299.965515136719,0,4232058656,299.966455078125,,,-0.105637063939669,0.00523200820315747,-0.105637069513981,0.00523200827332334,0.971029698848724,0.971031069755554,33.3235206604004,0,35,4,200,0.00268668471835554,-0.980067908763885,4.16503143310547,1,,,,,,,,,,,,,,,,
,3870599635.89218,299.952819824219,-3500.4892578125,,,6,,,,33.3224563598633,,,100,,,,,,,,,,,,,,,,,,,,,,299.949340820313,299.966064453125,-3500.4892578125,-3500.4892578125,,,7.79760599136353,,1,0,0,0,0.0138092041015625,30.7917900085449,1,1,1,299.949340820313,0,4232058624,299.957708740234,,,-0.0921782770303551,0.00456541072370995,-0.0921783185858674,0.00456541132165364,0.971109211444855,0.971120297908783,33.3254928588867,0,35,4,200,0.00248208618722856,-0.853822886943817,3.6383421421051,1,,,,,,,,,,,,,,,,
,3870599752.06114,300.111297607422,-1000.26202392578,,,6,,,,33.3224563598633,,,100,,,,,,,,,,,,,,,,,,,,,,300.102752685547,300.125122070313,-1000.26202392578,-1000.26202392578,,,7.81987380981445,,1,0,0,0,0.0138092041015625,31.2805480957031,1,1,1,300.119842529297,0,4232058624,300.117816162109,,,-0.0412398391959968,0.00204253865799369,-0.0412399096789586,0.00204253919956153,0.970932900905609,0.970982551574707,33.3289070129395,3.08134585793596E-5,35,4,200,0.00155722268391401,-0.383276492357254,1.62602412700653,1,,,,,,,,,,,,,,,,
,3870599873.84109,300.142501831055,-760.383422851562,,,6,,,,33.3224563598633,,,100,,,,,,,,,,,,,,,,,,,,,,300.1318359375,300.158142089844,-760.383422851562,-760.383422851562,,,7.85740375518799,,1,0,0,0,0.0138092041015625,30.7917900085449,1,1,1,300.132080078125,0,4232058688,300.147875976562,,,-0.0319501106519563,0.00158243945786739,-0.031950141052797,0.00158243981211591,0.97083455324173,0.970859467983246,33.327033996582,5.77295732498169,35,4,200,-0.00189814169425517,-0.300388932228088,1.25644636154175,1,,,,,,,,,,,,,,,,
,3870599989.4969,300.136047363281,-710.334899902344,,,6,,,,33.3224563598633,,,100,,,,,,,,,,,,,,,,,,,,,,300.135406494141,300.146209716797,-710.334899902344,-710.334899902344,,,7.87202215194702,,1,0,0,0,0.0138092041015625,30.7917900085449,1,1,1,300.136688232422,0,4232058752,300.139819335937,,,-0.0299085617524167,0.00148132169118956,-0.0299085910748988,0.00148132195179308,0.970898866653442,0.970926523208618,33.3272705078125,0,35,4,200,-0.00152433931361884,-0.288883328437805,1.1749312877655,1,,,,,,,,,,,,,,,,
,3870600104.81856,300.012847900391,-660.335266113281,,,6,,,,33.3224563598633,,,100,,,,,,,,,,,,,,,,,,,,,,300.012176513672,300.026885986328,-660.335266113281,-660.335266113281,,,7.87530088424683,,1,0,0,0,0.0138092041015625,30.3030319213867,1,1,1,300.012969970703,0,4232058720,300.018807983398,,,-0.0278613488977546,0.00137992777308228,-0.0278613735705433,0.00137992793165135,0.970870137214661,0.970896601676941,33.3271675109863,0,35,4,200,-0.00153555138967931,-0.271058231592178,1.09332716464996,1,,,,,,,,,,,,,,,,
,3870600220.8696,300.160720825195,-610.384460449219,,,6,,,,33.3224563598633,,,100,,,,,,,,,,,,,,,,,,,,,,300.1552734375,300.174621582031,-610.384460449219,-610.384460449219,,,7.87937450408936,,1,0,0,0,0.0138092041015625,30.7917900085449,1,1,1,300.166168212891,0,4232058720,300.166693115234,,,-0.0257523673410547,0.00127547639954343,-0.0257524003552984,0.00127547658996302,0.970797717571258,0.970836520195007,33.3281669616699,0,35,4,200,-0.00147070013917983,-0.249947309494019,1.01119744777679,1,,,,,,,,,,,,,,,,
,3870600332.60145,300.064483642578,-560.409240722656,,,6,,,,33.3224563598633,,,100,,,,,,,,,,,,,,,,,,,,,,300.062652587891,300.074340820313,-560.409240722656,-560.409240722656,,,7.89670705795288,,1,0,0,0,0.0138092041015625,30.7917900085449,1,1,1,300.063903808594,0,4232058624,300.068685913086,,,-0.023626920811419,0.0011702055534974,-0.0236269382068139,0.00117020574268157,0.970801532268524,0.9708212018013,33.3265228271484,0,35,4,200,-0.00174022978171706,-0.225712820887566,0.926306784152985,1,,,,,,,,,,,,,,,,
,3870600440.45441,299.995574951172,-510.360717773438,,,6,,,,33.3224563598633,,,100,,,,,,,,,,,,,,,,,,,,,,299.972503662109,300.015838623047,-510.360717773438,-510.360717773438,,,7.91215372085571,,1,0,0,0,0.0138092041015625,30.7917900085449,1,1,1,300.018646240234,0,4232058688,300.000531005859,,,-0.02147047931109,0.00106340139929694,-0.0214704940912387,0.00106340146302559,0.970762431621551,0.970783948898315,33.3267097473145,,35,4,200,-0.00176406954415143,-0.21047742664814,0.837079167366028,1,,,,,,,,,,,,,,,,
,3870600551.03606,300.120498657227,-460.336608886719,,,6,,,,33.3224563598633,,,100,,,,,,,,,,,,,,,,,,,,,,300.107421875,300.134307861328,-460.336608886719,-460.336608886719,,,7.92356729507446,,1,0,0,0,0.0138092041015625,30.7917900085449,1,1,1,300.108123779297,0,4232058688,300.124533081055,,,-0.0192779076183429,0.00095481033493597,-0.0192779321021978,0.000954810569104543,0.970641911029816,0.970676779747009,33.3278884887695,0,35,4,200,-0.00176351959817111,-0.189597204327583,0.75118613243103,1,,,,,,,,,,,,,,,,
,3870600667.01894,300.183670043945,-410.275848388672,,,6,,,,33.3224563598633,,,100,,,,,,,,,,,,,,,,,,,,,,300.170166015625,300.203063964844,-410.275848388672,-410.275848388672,,,7.95083475112915,,1,0,0,0,0.0138092041015625,30.7917900085449,1,1,1,300.197174072266,0,4232056832,300.193505859375,,,-0.0170682542175376,0.000845369721207118,-0.0170682919606764,0.000845369888402091,0.97060626745224,0.970674753189087,33.3300704956055,0,35,4,200,-0.00165613181889057,-0.170765802264214,0.669086933135986,1,,,,,,,,,,,,,,,,
,3870600782.23575,300.227767944336,-360.190643310547,,,6,,,,33.3224563598633,,,100,,,,,,,,,,,,,,,,,,,,,,300.210327148438,300.245727539063,-360.190643310547,-360.190643310547,,,7.97059679031372,,1,0,0,0,0.0138092041015625,30.7917900085449,1,1,1,300.209808349609,0,4232058720,300.233526611328,,,-0.0148249220159482,0.000734261165386143,-0.0148249470238702,0.000734261306873045,0.970566332340241,0.970617115497589,33.3290176391602,0,35,4,200,-0.00179438898339868,-0.147668391466141,0.577201962471008,1,,,,,,,,,,,,,,,,
,3870600892.36672,300.25798034668,-310.215423583984,,,6,,,,33.3224563598633,,,100,,,,,,,,,,,,,,,,,,,,,,300.243927001953,300.278381347656,-310.215423583984,-310.215423583984,,,7.9825611114502,,1,0,0,0,0.0138092041015625,30.7917900085449,1,1,1,300.272033691406,0,4232058624,300.268008422852,,,-0.0125813348245401,0.000623139947871194,-0.0125813618775255,0.000623140054963449,0.970507442951202,0.970574557781219,33.330005645752,0.189821049571037,35,4,200,-0.00166879245080054,-0.122068606317043,0.494132846593857,1,,,,,,,,,,,,,,,,
,3870601000.62341,300.135772705078,-260.191314697266,,,6,,,,33.3224563598633,,,100,,,,,,,,,,,,,,,,,,,,,,300.117858886719,300.152282714844,-260.191314697266,-260.191314697266,,,7.98544263839722,,1,0,0,0,0.0138092041015625,30.3030319213867,1,1,1,300.153686523438,0,4232058624,300.143151855469,,,-0.0103129954934293,0.000510795646640831,-0.0103130213999687,0.000510795735396773,0.970237016677856,0.970315635204315,33.3306617736816,0,35,4,200,-0.00197804742492735,-0.101394556462765,0.403861403465271,1,,,,,,,,,,,,,,,,
,3870601109.72312,300.117874145508,-210.093887329102,,,6,,,,33.3224563598633,,,100,,,,,,,,,,,,,,,,,,,,,,300.116638183594,300.130554199219,-210.093887329102,-210.093887329102,,,7.98820495605469,,1,0,0,0,0.0138092041015625,30.7917900085449,1,1,1,300.117919921875,0,4232058720,300.123245239258,,,-0.00802900521098195,0.000397673839510654,-0.0080290255151036,0.000397673954408012,0.970017015933991,0.970091700553894,33.3304862976074,0.000193221800145693,35,4,200,-0.00180842308327556,-0.0799646079540253,0.314829677343369,1,,,,,,,,,,,,,,,,
,3870601224.14132,300.068817138672,-160.106460571289,,,6,,,,33.3224563598633,,,100,,,,,,,,,,,,,,,,,,,,,,300.057403564453,300.080749511719,-160.106460571289,-160.106460571289,,,7.98173046112061,,1,0,0,0,0.0138092041015625,30.7917900085449,1,1,1,300.080230712891,0,4232058784,300.073733520508,,,-0.00573854460783534,0.000284231884371946,-0.00573856022021613,0.00028423196574015,0.969581067562103,0.969661116600037,33.3308258056641,,35,4,200,-0.00186716893222183,-0.0629212930798531,0.220823258161545,1,,,,,,,,,,,,,,,,
,3870601337.49216,300.13623046875,-110.229011535645,,,6,,,,33.3224563598633,,,100,,,,,,,,,,,,,,,,,,,,,,300.122039794922,300.151885986328,-110.229011535645,-110.229011535645,,,7.98712635040283,,1,0,0,0,0.0138092041015625,30.7917900085449,1,1,1,300.150421142578,0,4232058688,300.143814086914,,,-0.00344161476978909,0.000170470219091348,-0.00344162928916389,0.000170470270624321,0.968454658985138,0.968578934669495,33.3330726623535,,35,4,200,-0.00176632381044328,-0.0406625978648663,0.13203002512455,1,,,,,,,,,,,,,,,,
,3870601467.16635,300.224227905273,-60.2049140930176,,,6,,,,33.3224563598633,,,10,,,,,,,,,,,,,,,,,,,,,,300.221160888672,300.242065429687,-60.2049140930176,-60.2049140930176,,,7.99395179748535,,1,0,0,0,0.0138092041015625,30.3030319213867,1,1,1,300.227294921875,0,4232058624,300.233139038086,,,-0.001137414885685,5.6349218026213E-5,-0.00113743517046098,5.63492670640554E-5,0.962903141975403,0.963362634181976,33.3445167541504,0.197649255394936,35,4,200,-0.0156538058072329,-0.147436290979385,0.464163601398468,1,,,,,,,,,,,,,,,,
,3870601595.61151,300.169418334961,-10.1563711166382,,,6,,,,33.3224563598633,,,10,,,,,,,,,,,,,,,,,,,,,,300.152526855469,300.201477050781,-10.1563711166382,-10.1563711166382,,,8.023193359375,,1,0,0,0,0.0138092041015625,30.7917900085449,1,1,1,300.186309814453,0,4232058688,300.18505859375,,,0.00114276714058807,5.6594185069048E-5,0.00114276842603932,5.65941748596733E-5,0.97424042224884,0.974291086196899,33.3163108825684,5.26855516433716,35,4,200,-0.0116947237402201,-4.81412172317505,4.8636040687561,1,,,,,,,,,,,,,,,,
,3870601711.62027,300.174789428711,39.9410591125488,,,6,,,,33.3224563598633,,,10,,,,,,,,,,,,,,,,,,,,,,300.172210693359,300.187713623047,39.9410591125488,39.9410591125488,,,8.02401733398438,,1,0,0,0,0.0138092041015625,30.3030319213867,1,1,1,300.172576904297,0,4232058752,300.180520629883,,,0.00348755703596063,0.000172723746280695,0.00348755725240447,0.000172723750169869,0.972784340381622,0.972785770893097,33.3235244750977,,35,4,200,-0.0172665510326624,-1.46398448944092,0.330242961645126,1,,,,,,,,,,,,,,,,
,3870601827.11842,300.060180664063,89.9896087646484,,,6,,,,33.3224563598633,,,10,,,,,,,,,,,,,,,,,,,,,,300.044250488281,300.074279785156,89.9896087646484,89.9896087646484,,,8.03170871734619,,1,0,0,0,0.0138092041015625,30.3030319213867,1,1,1,300.076110839844,0,4232058592,300.065118408203,,,0.00579096781985211,0.000286808630704638,0.00579097236196221,0.000286808670428322,0.971932709217071,0.971955716609955,33.3267707824707,,35,4,200,-0.0176907274872065,-2.33102059364319,0.52804559469223,1,,,,,,,,,,,,,,,,
,3870601942.86248,300.033447265625,140.062591552734,,,6,,,,33.3224563598633,,,10,,,,,,,,,,,,,,,,,,,,,,300.02783203125,300.047119140625,140.062591552734,140.062591552734,,,8.03816699981689,,1,0,0,0,0.0138092041015625,30.7917900085449,1,1,1,300.028961181641,0,4232058656,300.038278198242,,,0.00808979552949426,0.000400665062089684,0.0080898038996849,0.000400665131568043,0.971705436706543,0.971735835075378,33.3274383544922,0,35,4,200,-0.0183125212788582,-3.20158743858337,0.767908632755279,1,,,,,,,,,,,,,,,,
,3870602058.55367,300.103073120117,190.135589599609,,,6,,,,33.3224563598633,,,10,,,,,,,,,,,,,,,,,,,,,,300.082214355469,300.124237060547,190.135589599609,190.135589599609,,,8.04539966583252,,1,0,0,0,0.0138092041015625,30.7917900085449,1,1,1,300.123931884766,0,4232058624,300.113116455078,,,0.0103619151415827,0.000513200222253627,0.0103619375442981,0.000513200365615673,0.971468329429626,0.971534311771393,33.3298225402832,0,35,4,200,-0.0166476015001535,-4.12608432769775,0.947172343730926,1,,,,,,,,,,,,,,,,
,3870602177.19083,299.979583740234,240.025238037109,,,6,,,,33.3224563598633,,,100,,,,,,,,,,,,,,,,,,,,,,299.971313476562,299.988128662109,240.025238037109,240.025238037109,,,8.07908439636231,,1,0,0,0,0.0138092041015625,30.3030319213867,1,1,1,299.976928710937,0,4232058720,299.981499922903,,,0.0126038635168074,0.000624237126818386,0.0126038765078699,0.000624237204592079,0.971542537212372,0.971574366092682,33.3275680541992,5.77300310134888,35,4,200,-0.00136277638375759,-4.89412689208984,4.86507844924927,1,,,,,,,,,,,,,,,,
,3870602295.4558,300.187683105469,290.073791503906,,,6,,,,33.3224563598633,,,100,,,,,,,,,,,,,,,,,,,,,,300.172515869141,300.202331542969,290.073791503906,290.073791503906,,,8.07759857177734,,1,0,0,0,0.0138092041015625,30.3030319213867,1,1,1,300.202850341797,0,4232058656,300.193878173828,,,0.0148839965214,0.000737164677027797,0.0148840378632014,0.000737164910659253,0.971610367298126,0.971697151660919,33.3308792114258,0,35,4,200,-0.00209719780832529,-0.593669295310974,0.133991613984108,1,,,,,,,,,,,,,,,,
,3870602409.58018,300.029632568359,340.183441162109,,,6,,,,33.3224563598633,,,100,,,,,,,,,,,,,,,,,,,,,,300.022033691406,300.04150390625,340.183441162109,340.183441162109,,,8.07044982910156,,1,0,0,0,0.0138092041015625,30.7917900085449,1,1,1,300.022583007812,0,4232058752,300.033743286133,,,0.0171295477344817,0.000848385860526204,0.0171295702199263,0.000848386064365978,0.971401989459991,0.971439480781555,33.3280143737793,0,35,4,200,-0.00205089244991541,-0.681065201759338,0.156001850962639,1,,,,,,,,,,,,,,,,
,3870602524.93077,300.248962402344,390.244201660156,,,6,,,,33.3224563598633,,,100,,,,,,,,,,,,,,,,,,,,,,300.236785888672,300.269287109375,390.244201660156,390.244201660156,,,8.07154560089111,,1,0,0,0,0.0138092041015625,30.7917900085449,1,1,1,300.261138916016,0,4232058592,300.259677124023,,,0.0193001924513908,0.000955896727355334,0.0193002410104871,0.000955896964103905,0.971256792545319,0.971335709095001,33.3305435180664,0,35,4,200,-0.0020149415358901,-0.764168679714203,0.178694874048233,1,,,,,,,,,,,,,,,,
,3870602639.44522,300.181106567383,440.133850097656,,,6,,,,33.3224563598633,,,100,,,,,,,,,,,,,,,,,,,,,,300.16845703125,300.196472167969,440.133850097656,440.133850097656,,,8.08265018463135,,1,0,0,0,0.0138092041015625,30.7917900085449,1,1,1,300.193756103516,0,4232058656,300.188055419922,,,0.0215051308086302,0.00106509872821431,0.021505171408987,0.00106509894298142,0.971387684345245,0.971446633338928,33.3294258117676,4.28512066719122E-6,35,4,200,-0.00202140561304986,-0.856772303581238,0.193165242671967,1,,,,,,,,,,,,,,,,
,3870602755.99804,300.152236938477,490.182434082031,,,6,,,,33.3224563598633,,,100,,,,,,,,,,,,,,,,,,,,,,300.137847900391,300.173034667969,490.182434082031,490.182434082031,,,8.09951210021973,,1,0,0,0,0.0138092041015625,30.3030319213867,1,1,1,300.166625976562,0,4232058816,300.162582397461,,,0.0236353766010608,0.00117060765958123,0.0236354189755659,0.00117060798517463,0.971309304237366,0.971362113952637,33.3290634155273,0,35,4,200,-0.000430862215580419,-0.935013473033905,0.217160999774933,1,,,,,,,,,,,,,,,,
,3870602871.48465,300.143676757812,540.21875,,,6,,,,33.3224563598633,,,100,,,,,,,,,,,,,,,,,,,,,,300.120483398438,300.166900634766,540.21875,540.21875,,,8.11719703674316,,1,0,0,0,0.0138092041015625,30.3030319213867,1,1,1,300.120452880859,0,4232058656,300.14606628418,,,0.0257724749711904,0.00127645183048891,0.0257725105012008,0.00127645195819483,0.971344470977783,0.97138911485672,33.3285255432129,0.154491305351257,35,4,200,-0.00202778284437954,-1.01873707771301,0.239092260599136,1,,,,,,,,,,,,,,,,
,3870602985.21315,300.064514160156,590.328369140625,,,6,,,,33.3224563598633,,,100,,,,,,,,,,,,,,,,,,,,,,300.051910400391,300.077545166016,590.328369140625,590.328369140625,,,8.13450717926025,,1,0,0,0,0.0138092041015625,30.3030319213867,1,1,1,300.077117919922,0,4232058656,300.069769287109,,,0.0278948265298316,0.00138156675219259,0.0278948802823413,0.00138156716885151,0.971355855464935,0.971412599086761,33.3292999267578,0.189823403954506,35,4,200,-0.00250840466469526,-1.10234260559082,0.25932788848877,1,,,,,,,,,,,,,,,,
,3870603099.89737,300.171630859375,640.376892089844,,,6,,,,33.3224563598633,,,100,,,,,,,,,,,,,,,,,,,,,,300.170104980469,300.186309814453,640.376892089844,640.376892089844,,,8.12836265563965,,1,0,0,0,0.0138092041015625,30.3030319213867,1,1,1,300.170074462891,0,4232058848,300.178192138672,,,0.029950054747855,0.00148336039862244,0.0299501271376053,0.0014833607330705,0.971277952194214,0.971354305744171,33.3304023742676,0.0422720909118652,35,4,200,-0.00280031282454729,-1.18980479240417,0.276565283536911,1,,,,,,,,,,,,,,,,
,3870603213.94709,300.009307861328,690.27880859375,,,6,,,,33.3224563598633,,,100,,,,,,,,,,,,,,,,,,,,,,299.995666503906,300.02294921875,690.27880859375,690.27880859375,,,8.1180477142334,,1,0,0,0,0.0138092041015625,29.8142719268799,1,1,1,299.995666503906,0,4232058752,300.011828613281,,,0.031992929109165,0.00158453356447575,0.0319929609945382,0.00158453373432825,0.97141170501709,0.971442818641663,33.3275184631348,0,35,4,200,-0.00306027615442872,-1.27515017986298,0.288903564214706,1,,,,,,,,,,,,,,,,
,3870603327.75234,299.91276550293,740.315124511719,,,6,,,,33.3224563598633,,,100,,,,,,,,,,,,,,,,,,,,,,299.902099609375,299.923126220703,740.315124511719,740.315124511719,,,8.11996173858643,,1,0,0,0,0.0138092041015625,30.3030319213867,1,1,1,299.902404785156,0,4232058624,299.914761352539,,,0.0340143567381125,0.00168464851599479,0.0340143939314359,0.00168464884782923,0.97143828868866,0.971469700336456,33.3275375366211,0,35,4,200,-0.00335388444364071,-1.34884059429169,0.312439888715744,1,,,,,,,,,,,,,,,,
,3870603441.54265,299.983306884766,790.412536621094,,,6,,,,33.3224563598633,,,100,,,,,,,,,,,,,,,,,,,,,,299.966094970703,300.000061035156,790.412536621094,790.412536621094,,,8.13244724273682,,1,0,0,0,0.0138092041015625,30.7917900085449,1,1,1,299.966552734375,0,4232058656,299.985821533203,,,0.0359703647538933,0.00178153234053613,0.0359704086917553,0.00178153245905285,0.971293151378632,0.971333384513855,33.3282241821289,0,35,4,200,-0.00291649368591607,-1.42922580242157,0.328612804412842,1,,,,,,,,,,,,,,,,
,3870603583.99092,300.230346679687,2500.20288085938,,,6,,,,33.3224563598633,,,100,,,,,,,,,,,,,,,,,,,,,,300.208709716797,300.251953125,2500.20288085938,2500.20288085938,,,8.1763277053833,,1,0,0,0,0.0138092041015625,30.3030319213867,1,1,1,300.208740234375,0,4232058560,300.236083984375,,,0.0808093632705812,0.00400233537571179,0.0808095169146957,0.00400233635716963,0.971067309379578,0.971124529838562,33.3293647766113,5.77315902709961,35,4,200,0.000526592193637043,-3.17696499824524,0.757316887378693,1,,,,,,,,,,,,,,,,
,3870603727.49431,300.070938110352,5000.515625,,,6,,,,33.3224563598633,,,100,,,,,,,,,,,,,,,,,,,,,,300.056823730469,300.087188720703,5000.515625,5000.515625,,,8.13146781921387,,1,0,0,0,0.0138092041015625,30.7917900085449,1,1,1,300.057403564453,0,4232058720,300.075430297852,,,0.102142244527924,0.00505892331858316,0.102142322848634,0.00505892404143697,0.970992982387543,0.971014499664307,33.3266944885254,5.26807117462158,35,4,200,0.00160732690710574,-4.01946020126343,0.954936563968658,1,,,,,,,,,,,,,,,,
,3870603868.37006,300.192535400391,7500.3642578125,,,6,,,,33.3224563598633,,,100,,,,,,,,,,,,,,,,,,,,,,300.180114746094,300.212463378906,7500.3642578125,7500.3642578125,,,8.15135669708252,,1,0,0,0,0.0138092041015625,30.3030319213867,1,1,1,300.204956054687,0,4232058560,300.202935791016,,,0.109435963488526,0.0054201821581813,0.109436004651287,0.00542018248299019,0.970908582210541,0.97091943025589,33.3254737854004,5.77282190322876,35,4,200,0.00201529124751687,-4.30262327194214,1.02492392063141,1,,,,,,,,,,,,,,,,
,3870604021.05526,300.115676879883,10000.3349609375,,,6,,,,33.3224563598633,,,100,,,,,,,,,,,,,,,,,,,,,,300.095245361328,300.137023925781,10000.3349609375,10000.3349609375,,,8.13528633117676,,1,0,0,0,0.0138092041015625,30.3030319213867,1,1,1,300.094329833984,0,4232058592,300.120657348633,,,0.113057919382728,0.00559958291444894,0.113057939624428,0.00559958331822189,0.970832169055939,0.97083580493927,33.3242111206055,0,35,4,200,0.00125282676890492,-4.44443845748901,1.06302583217621,1,,,,,,,,,,,,,,,,
,3870604169.67548,300.075714111328,35000.40625,,,6,,,,33.3224563598633,,,100,,,,,,,,,,,,,,,,,,,,,,300.074157714844,300.088653564453,35000.40625,35000.40625,,,8.16141986846924,,1,0,0,0,0.0138092041015625,30.3030319213867,1,1,1,300.077270507812,0,4232058624,300.081274414062,,,0.121079029681409,0.00599710366733732,0.12107938188336,0.0059971051717023,0.969451427459717,0.969538450241089,33.3312034606934,,35,4,200,0.00172589579597116,-4.7619514465332,1.15268838405609,1,,,,,,,,,,,,,,,,
,3870604323.97253,300.230850219727,60000.34375,,,6,,,,33.3224563598633,,,100,,,,,,,,,,,,,,,,,,,,,,300.227813720703,300.247222900391,60000.34375,60000.34375,,,8.15900421142578,,1,0,0,0,0.0138092041015625,30.3030319213867,1,1,1,300.227508544922,0,4232058656,300.238925170898,,,0.122872869299674,0.00608637196130549,0.122875798442958,0.00608637711028247,0.967277109622955,0.967986702919006,33.3481712341309,5.77478742599487,35,4,200,0.00183003768324852,-4.82164859771729,1.19590699672699,1,,,,,,,,,,,,,,,,
,3870604483.54823,300.17951965332,55000.3203125,,,6,,,,33.3224563598633,,,100,,,,,,,,,,,,,,,,,,,,,,300.174957275391,300.198211669922,55000.3203125,55000.3203125,,,8.19146537780762,,1,0,0,0,0.0138092041015625,30.3030319213867,1,1,1,300.18408203125,0,4232058496,300.188726806641,,,0.12262483456521,0.0060739653135498,0.122626579461417,0.00607397028546023,0.967881977558136,0.968301832675934,33.342098236084,0,35,4,200,-0.0020074169151485,-4.83159494400024,1.1737642288208,1,,,,,,,,,,,,,,,,
,3870604640.92152,300.147201538086,30000.259765625,,,6,,,,33.3224563598633,,,100,,,,,,,,,,,,,,,,,,,,,,300.132415771484,300.168304443359,30000.259765625,30000.259765625,,,8.16935539245606,,1,0,0,0,0.0138092041015625,30.7917900085449,1,1,1,300.161987304687,0,4232058592,300.157550048828,,,0.12048423154786,0.00596758734794964,0.120484414759945,0.00596758858902903,0.969773650169373,0.969817042350769,33.3286018371582,0,35,4,200,-0.0027320827357471,-4.74843740463257,1.132732629776,1,,,,,,,,,,,,,,,,
,3870604799.62325,300.206420898438,9500.2890625,,,6,,,,33.3224563598633,,,100,,,,,,,,,,,,,,,,,,,,,,300.205108642578,300.225433349609,9500.2890625,9500.2890625,,,8.2107515335083,,1,0,0,0,0.0138092041015625,30.7917900085449,1,1,1,300.207733154297,0,4232058656,300.214865112305,,,0.112445388573759,0.00556922911438655,0.112445442813238,0.00556922961613783,0.970939755439758,0.970953285694122,33.3258171081543,,35,4,200,-0.00493046920746565,-4.44285202026367,1.03635120391846,1,,,,,,,,,,,,,,,,
,3870604945.09704,300.166290283203,7000.31884765625,,,6,,,,33.3224563598633,,,100,,,,,,,,,,,,,,,,,,,,,,300.161773681641,300.185699462891,7000.31884765625,7000.31884765625,,,8.19213962554932,,1,0,0,0,0.0138092041015625,31.2805480957031,1,1,1,300.170806884766,0,4232058848,300.175830078125,,,0.108336314363261,0.0053657069082809,0.108336406083246,0.00536570757761721,0.970986723899841,0.971011579036713,33.3270149230957,0,35,4,200,-0.0028368653729558,-4.27721309661865,0.999400675296783,1,,,,,,,,,,,,,,,,
,3870605091.39513,300.072204589844,4500.384765625,,,6,,,,33.3224563598633,,,100,,,,,,,,,,,,,,,,,,,,,,300.055145263672,300.088714599609,4500.384765625,4500.384765625,,,8.22217464447021,,1,0,0,0,0.0138092041015625,31.2805480957031,1,1,1,300.055694580078,0,4232058624,300.075158691406,,,0.0994132582244194,0.00492374312633239,0.0994133092868304,0.00492374368525505,0.971122324466705,0.971136152744293,33.3258514404297,3.98812437057495,35,4,200,-0.00298438547179103,-3.92152285575867,0.924235761165619,1,,,,,,,,,,,,,,,,
,3870605231.35375,300.151062011719,2000.20629882813,,,6,,,,33.3224563598633,,,100,,,,,,,,,,,,,,,,,,,,,,300.144470214844,300.169036865234,2000.20629882813,2000.20629882813,,,8.18652629852295,,1,0,0,0,0.0138092041015625,31.2805480957031,1,1,1,300.157653808594,0,4232058848,300.160015869141,,,0.0704028241205653,0.00348691630764023,0.070402951536925,0.0034869166505916,0.971093118190765,0.971152365207672,33.3294792175293,0,35,4,200,-0.00285369902849197,-2.78332710266113,0.647563517093658,1,,,,,,,,,,,,,,,,
,3870605363.4116,299.997146606445,780.060668945313,,,6,,,,33.3224563598633,,,100,,,,,,,,,,,,,,,,,,,,,,299.988464355469,300.009490966797,780.060668945313,780.060668945313,,,8.1895637512207,,1,0,0,0,0.0138092041015625,31.2805480957031,1,1,1,299.989898681641,0,4232058624,300.001379394531,,,0.0328222914835236,0.00162562974622115,0.0328223402148833,0.0016256300593641,0.970990657806397,0.971035182476044,33.328556060791,5.77308893203735,35,4,200,0.00018360183457844,-1.29858207702637,0.299650371074677,1,,,,,,,,,,,,,,,,
,3870605480.24702,300.141464233398,730.158752441406,,,6,,,,33.3224563598633,,,100,,,,,,,,,,,,,,,,,,,,,,300.137542724609,300.157135009766,730.158752441406,730.158752441406,,,8.19520568847656,,1,0,0,0,0.0138092041015625,31.2805480957031,1,1,1,300.145385742188,0,4232058624,300.148934936523,,,0.0307964194093872,0.00152529730782152,0.030796507915646,0.0015252978084434,0.970871686935425,0.970959186553955,33.3310203552246,5.77330255508423,35,4,200,0.00138302042614669,-1.2151597738266,0.286691516637802,1,,,,,,,,,,,,,,,,
,3870605594.20638,300.096908569336,680.036865234375,,,6,,,,33.3224563598633,,,100,,,,,,,,,,,,,,,,,,,,,,300.083374023438,300.111236572266,680.036865234375,680.036865234375,,,8.208176612854,,1,0,0,0,0.0138092041015625,31.2805480957031,1,1,1,300.084014892578,0,4232058688,300.101171875,,,0.0287449028276422,0.00142368849239683,0.0287449624642212,0.00142368869259661,0.970870673656464,0.970937073230743,33.3299217224121,0,35,4,200,0.00164136535022408,-1.12726068496704,0.273335188627243,1,,,,,,,,,,,,,,,,
,3870605705.00167,300.119674682617,630.159484863281,,,6,,,,33.3224563598633,,,100,,,,,,,,,,,,,,,,,,,,,,300.117309570313,300.129974365234,630.159484863281,630.159484863281,,,8.21269607543945,,1,0,0,0,0.0138092041015625,31.2805480957031,1,1,1,300.119476318359,0,4232058624,300.12350769043,,,0.0266524639829248,0.00132005561969136,0.0266525169906978,0.00132005591951115,0.970819652080536,0.970880031585693,33.3295783996582,0,35,4,200,0.00163510045967996,-1.0461813211441,0.252919107675552,1,,,,,,,,,,,,,,,,
,3870605815.59693,300.039199829102,580.123107910156,,,6,,,,33.3224563598633,,,100,,,,,,,,,,,,,,,,,,,,,,300.020233154297,300.058013916016,580.123107910156,580.123107910156,,,8.20982456207275,,1,0,0,0,0.0138092041015625,30.7917900085449,1,1,1,300.020385742188,0,4232058592,300.04055480957,,,0.0245404945241033,0.00121545379214386,0.0245405360764051,0.00121545410451562,0.970800280570984,0.970849454402924,33.3288879394531,,35,4,200,0.00165938620921224,-0.966777265071869,0.236726403236389,1,,,,,,,,,,,,,,,,
,3870605928.71336,300.171310424805,530.050109863281,,,6,,,,33.3224563598633,,,100,,,,,,,,,,,,,,,,,,,,,,300.155395507812,300.190002441406,530.050109863281,530.050109863281,,,8.19166946411133,,1,0,0,0,0.0138092041015625,30.7917900085449,1,1,1,300.154846191406,0,4232058624,300.177319335938,,,0.0223739446541527,0.00110814709784277,0.0223739890388783,0.00110814725546309,0.970816969871521,0.970880091190338,33.3297386169434,5.26792812347412,35,4,200,0.00168979249428958,-0.878732860088348,0.2126235216856,1,,,,,,,,,,,,,,,,
,3870606043.21074,300.225631713867,480.087127685547,,,6,,,,33.3224563598633,,,100,,,,,,,,,,,,,,,,,,,,,,300.219909667969,300.244689941406,480.087127685547,480.087127685547,,,8.17810821533203,,1,0,0,0,0.0138092041015625,30.7917900085449,1,1,1,300.231353759766,0,4232058752,300.235241699219,,,0.0202045994186917,0.00100070560707458,0.0202046650322314,0.00100070586601725,0.970729172229767,0.970831334590912,33.3317337036133,0,35,4,200,0.00157700560521334,-0.796322107315063,0.195667520165443,1,,,,,,,,,,,,,,,,
,3870606152.06689,300.161651611328,430.063018798828,,,6,,,,33.3224563598633,,,100,,,,,,,,,,,,,,,,,,,,,,300.138000488281,300.183929443359,430.063018798828,430.063018798828,,,8.18064880371094,,1,0,0,0,0.0138092041015625,30.7917900085449,1,1,1,300.185302734375,0,4232058752,300.169552612305,,,0.0180076299640527,0.000891896549391567,0.0180076855047582,0.000891896699626683,0.970584809780121,0.970684051513672,33.3316192626953,5.77335453033447,35,4,200,0.00187214557081461,-0.707836389541626,0.17102462053299,1,,,,,,,,,,,,,,,,
,3870606268.55217,300.155410766602,380.063385009766,,,6,,,,33.3224563598633,,,100,,,,,,,,,,,,,,,,,,,,,,300.127960205078,300.183441162109,380.063385009766,380.063385009766,,,8.17085647583008,,1,0,0,0,0.0138092041015625,31.2805480957031,1,1,1,300.127380371094,0,4232058656,300.158850097656,,,0.0157741823448099,0.000781273211876375,0.0157742192955166,0.00078127344210246,0.97073632478714,0.970806300640106,33.330135345459,5.26787853240967,35,4,200,0.00179935095366091,-0.61621230840683,0.15457558631897,1,,,,,,,,,,,,,,,,
,3870606381.55771,300.167938232422,330.039306640625,,,6,,,,33.3224563598633,,,100,,,,,,,,,,,,,,,,,,,,,,300.165740966797,300.179565429687,330.039306640625,330.039306640625,,,8.19103908538818,,1,0,0,0,0.0138092041015625,30.7917900085449,1,1,1,300.170135498047,0,4232058816,300.172769165039,,,0.0135355088952624,0.00067040041123206,0.0135355604683184,0.000670400675434438,0.970440089702606,0.970555782318115,33.3323745727539,0,35,4,200,0.00174086971674114,-0.531106293201447,0.131423771381378,1,,,,,,,,,,,,,,,,
,3870606496.11275,300.242980957031,279.905181884766,,,6,,,,33.3224563598633,,,100,,,,,,,,,,,,,,,,,,,,,,300.240814208984,300.261871337891,279.905181884766,279.905181884766,,,8.19964027404785,,1,0,0,0,0.0138092041015625,30.7917900085449,1,1,1,300.245147705078,0,4232058688,300.252151489258,,,0.0112715087597231,0.000558267280973128,0.01127156184887,0.000558267431267287,0.970415890216827,0.970566213130951,33.3337669372559,0,35,4,200,0.00160677498206496,-0.446540027856827,0.106666840612888,1,,,,,,,,,,,,,,,,
,3870606613.33537,300.154647827148,230.10107421875,,,6,,,,33.3224563598633,,,100,,,,,,,,,,,,,,,,,,,,,,300.138763427734,300.171447753906,230.10107421875,230.10107421875,,,8.22312355041504,,1,0,0,0,0.0138092041015625,30.7917900085449,1,1,1,300.13916015625,0,4232058592,300.159368896484,,,0.00899548175765867,0.000445542583802959,0.00899551847510222,0.000445542707436419,0.970047295093536,0.970174491405487,33.3329238891602,0,35,4,200,0.00178340380080044,-0.350051432847977,0.0921297669410706,1,,,,,,,,,,,,,,,,
,3870606730.14878,300.282257080078,180.21142578125,,,6,,,,33.3224563598633,,,100,,,,,,,,,,,,,,,,,,,,,,300.278076171875,300.302429199219,180.21142578125,180.21142578125,,,8.21960735321045,,1,0,0,0,0.0138092041015625,31.2805480957031,1,1,1,300.286437988281,0,4232058592,300.292388916016,,,0.00671359688239952,0.000332522867444182,0.00671363546176178,0.000332522971907807,0.969936549663544,0.970117628574371,33.3349609375,0,35,4,200,0.00163542199879885,-0.268121421337128,0.0633914321660995,1,,,,,,,,,,,,,,,,
,3870606842.36513,300.163803100586,130.126220703125,,,6,,,,33.3224563598633,,,100,,,,,,,,,,,,,,,,,,,,,,300.146362304687,300.179901123047,130.126220703125,130.126220703125,,,8.20871067047119,,1,0,0,0,0.0138092041015625,30.7917900085449,1,1,1,300.181243896484,0,4232058688,300.170855712891,,,0.0044129935319224,0.000218579219006942,0.00441302218168097,0.000218579311549452,0.96923041343689,0.969428062438965,33.3356704711914,7.05761067365529E-6,35,4,200,0.00186098087579012,-0.171622961759567,0.0475302301347256,1,,,,,,,,,,,,,,,,
,3870606958.16151,300.108123779297,80.0532302856445,,,6,,,,33.3224563598633,,,10,,,,,,,,,,,,,,,,,,,,,,300.1044921875,300.130279541016,80.0532302856445,80.0532302856445,,,8.2004508972168,,1,0,0,0,0.0138092041015625,30.7917900085449,1,1,1,300.114349365234,0,4232058720,300.120139227973,,,0.0021366168763543,0.000105834492307359,0.00213663253511337,0.000105834532978648,0.967408537864685,0.967622101306915,33.3365859985352,0,35,4,200,0.01189324259758,-0.83728438615799,0.270265430212021,1,,,,,,,,,,,,,,,,
,3870607083.80598,300.250854492188,30.016902923584,,,6,,,,33.3224563598633,,,1,,,,,,,,,,,,,,,,,,,,,,300.244781494141,300.264831542969,30.016902923584,30.016902923584,,,8.20268535614014,,1,0,0,0,0.0138092041015625,30.7917900085449,1,1,1,300.244934082031,0,4232058720,300.256799316406,,,-0.000217621474469579,1.08245974991104E-5,-0.000217626615140936,1.08245922039096E-5,0.903299868106842,0.903547167778015,33.2958374023438,0,35,4,200,0.154610767960548,-0.231352016329765,1.38761842250824,1,,,,,,,,,,,,,,,,
,3870607206.97531,300.101303100586,-20.0316410064697,,,6,,,,33.3224563598633,,,10,,,,,,,,,,,,,,,,,,,,,,300.089904785156,300.112518310547,-20.0316410064697,-20.0316410064697,,,8.22802352905273,,1,0,0,0,0.0138092041015625,30.3030319213867,1,1,1,300.112701416016,0,4232058656,300.105261230469,,,-0.00252303217104544,0.000124955853931586,-0.00252303485343905,0.000124955870820401,0.972530782222748,0.972564518451691,33.3276329040527,2.70358873422083E-6,35,4,200,0.0177021138370037,-0.246101766824722,1.02403295040131,1,,,,,,,,,,,,,,,,
,3870607320.21424,300.044799804687,-70.0312957763672,,,6,,,,33.3224563598633,,,10,,,,,,,,,,,,,,,,,,,,,,300.035858154297,300.058044433594,-70.0312957763672,-70.0312957763672,,,8.23147964477539,,1,0,0,0,0.0138092041015625,30.7917900085449,1,1,1,300.035919189453,0,4232058816,300.049154663086,,,-0.00483162163954692,0.000239294712942141,-0.00483163059538677,0.000239294751141389,0.972003936767578,0.97206449508667,33.3294486999512,0,35,4,200,0.018073245882988,-0.482996910810471,1.97548627853394,1,,,,,,,,,,,,,,,,
,3870607433.60863,300.119888305664,-120.128723144531,,,6,,,,33.3224563598633,,,10,,,,,,,,,,,,,,,,,,,,,,300.105194091797,300.136047363281,-120.128723144531,-120.128723144531,,,8.23291778564453,,1,0,0,0,0.0138092041015625,30.7917900085449,1,1,1,300.104553222656,0,4232058624,300.124661254883,,,-0.00713078955415049,0.000353165430692533,-0.00713079983871798,0.000353165481241949,0.971973359584808,0.972019731998444,33.3285789489746,0,35,4,200,0.01858383230865,-0.60649585723877,2.89681005477905,1,,,,,,,,,,,,,,,,
,3870607548.65233,300.180206298828,-169.920608520508,,,6,,,,33.3224563598633,,,10,,,,,,,,,,,,,,,,,,,,,,300.166381835937,300.196502685547,-169.920608520508,-169.920608520508,,,8.21624183654785,,1,0,0,0,0.0138092041015625,31.7693061828613,1,1,1,300.166381835937,0,4232058656,300.185559082031,,,-0.00940532453430235,0.0004658219062247,-0.00940534405393369,0.000465821986764795,0.971522450447082,0.971589267253876,33.3298606872559,0.189719423651695,35,4,200,0.0202209688723087,-0.897575736045837,3.71358776092529,1,,,,,,,,,,,,,,,,
,3870607661.9839,300.169158935547,-219.981384277344,,,6,,,,33.3224563598633,,,10,,,,,,,,,,,,,,,,,,,,,,300.163604736328,300.182495117188,-219.981384277344,-219.981384277344,,,8.21682739257812,,1,0,0,0,0.0138092041015625,30.7917900085449,1,1,1,300.174713134766,0,4232058656,300.175479125977,,,-0.0116805430991844,0.000578504550198405,-0.0116805639568803,0.000578504649295244,0.971718788146973,0.971775889396668,33.3292770385742,5.77314329147339,35,4,200,0.0201927572488785,-1.04600048065186,4.67084693908691,1,,,,,,,,,,,,,,,,
,3870607784.82091,300.002655029297,-269.981048583984,,,6,,,,33.3224563598633,,,100,,,,,,,,,,,,,,,,,,,,,,299.977691650391,300.026763916016,-269.981048583984,-269.981048583984,,,8.21982192993164,,1,0,0,0,0.0138092041015625,30.7917900085449,1,1,1,300.027618408203,0,4232058784,300.009494018555,,,-0.0139539579780622,0.000691103951502905,-0.0139539819442346,0.000691104116267863,0.971521198749542,0.971573114395142,33.328987121582,0,35,4,200,0.00203015399165452,-0.131108149886131,0.551234602928162,1,,,,,,,,,,,,,,,,
,3870607898.0811,300.084762573242,-319.992919921875,,,6,,,,33.3224563598633,,,100,,,,,,,,,,,,,,,,,,,,,,300.065704345703,300.102355957031,-319.992919921875,-319.992919921875,,,8.23257350921631,,1,0,0,0,0.0138092041015625,30.7917900085449,1,1,1,300.103820800781,0,4232058816,300.090454101562,,,-0.0161911717582812,0.000801909025722771,-0.0161912093736472,0.000801909229442582,0.9714635014534,0.971536040306091,33.3301773071289,0,35,4,200,0.00194473634473979,-0.145031735301018,0.646259605884552,1,,,,,,,,,,,,,,,,
,3870608011.51377,300.029556274414,-370.004791259766,,,6,,,,33.3224563598633,,,100,,,,,,,,,,,,,,,,,,,,,,300.010070800781,300.049041748047,-370.004791259766,-370.004791259766,,,8.25223159790039,,1,0,0,0,0.0138092041015625,30.7917900085449,1,1,1,300.010070800781,0,4232058656,300.031759643555,,,-0.0184105864053848,0.000911833312051627,-0.018410617629141,0.000911833498546423,0.971383929252625,0.971436083316803,33.3290138244629,0,35,4,200,0.00185866456013173,-0.181316033005714,0.72526353597641,1,,,,,,,,,,,,,,,,
,3870608128.16229,300.226028442383,-420.053314208984,,,6,,,,33.3224563598633,,,100,,,,,,,,,,,,,,,,,,,,,,300.207672119141,300.245788574219,-420.053314208984,-420.053314208984,,,8.24878120422363,,1,0,0,0,0.0138092041015625,30.7917900085449,1,1,1,300.206909179687,0,4232058720,300.233151245117,,,-0.020592231709086,0.00101988410265951,-0.020592285900494,0.00101988431939462,0.971419990062714,0.971504688262939,33.3308067321777,,35,4,200,0.00185670307837427,-0.189173460006714,0.816067039966583,1,,,,,,,,,,,,,,,,
,3870608243.06154,300.09260559082,-470.040740966797,,,6,,,,33.3224563598633,,,100,,,,,,,,,,,,,,,,,,,,,,300.091186523438,300.103881835937,-470.040740966797,-470.040740966797,,,8.23340034484863,,1,0,0,0,0.0138092041015625,30.7917900085449,1,1,1,300.094024658203,0,4232058752,300.097161865234,,,-0.0227776472404204,0.00112812397298607,-0.0227777240381145,0.00112812450626256,0.971374332904816,0.971475720405579,33.3315963745117,0,35,4,200,0.00197212537750602,-0.209423810243607,0.902357339859009,1,,,,,,,,,,,,,,,,
,3870608359.43822,300.12077331543,-520.077087402344,,,6,,,,33.3224563598633,,,100,,,,,,,,,,,,,,,,,,,,,,300.117523193359,300.136871337891,-520.077087402344,-520.077087402344,,,8.22249507904053,,1,0,0,0,0.0138092041015625,30.7917900085449,1,1,1,300.1240234375,0,4232058656,300.128839111328,,,-0.0249102906378984,0.00123374976451754,-0.0249103801438971,0.00123375020356197,0.971354186534882,0.97146737575531,33.3321151733398,5.03962519360357E-6,35,4,200,0.00192673061974347,-0.231306806206703,0.984253883361816,1,,,,,,,,,,,,,,,,
,3870608472.99221,300.143020629883,-570.137878417969,,,6,,,,33.3224563598633,,,100,,,,,,,,,,,,,,,,,,,,,,300.128479003906,300.158874511719,-570.137878417969,-570.137878417969,,,8.22300624847412,,1,0,0,0,0.0138092041015625,30.7917900085449,1,1,1,300.128997802734,0,4232058656,300.148263549805,,,-0.0270354891927973,0.00133900627750151,-0.0270355965290511,0.00133900685627343,0.971332192420959,0.971455752849579,33.3325538635254,0,35,4,200,0.00237552030012012,-0.255641937255859,1.06392884254456,1,,,,,,,,,,,,,,,,
,3870608586.70056,299.995574951172,-620.113098144531,,,6,,,,33.3224563598633,,,100,,,,,,,,,,,,,,,,,,,,,,299.975311279297,300.015380859375,-620.113098144531,-620.113098144531,,,8.23266220092773,,1,0,0,0,0.0138092041015625,32.7468223571777,1,1,1,299.975769042969,0,4232058560,299.997064208984,,,-0.0291241828652038,0.00144244843034899,-0.0291242466067596,0.00144244868824644,0.971484482288361,0.97155499458313,33.3300666809082,0,35,4,200,0.00275886058807373,-0.271026015281677,1.15495574474335,1,,,,,,,,,,,,,,,,
,3870608699.96633,299.981979370117,-670.173828125,,,6,,,,33.3224563598633,,,100,,,,,,,,,,,,,,,,,,,,,,299.971923828125,299.993133544922,-670.173828125,-670.173828125,,,8.2554292678833,,1,0,0,0,0.0138092041015625,29.8142719268799,1,1,1,299.972412109375,0,4232058624,299.984573364258,,,-0.0311888336850894,0.00154470709359146,-0.0311889155639726,0.00154470758831715,0.971450805664062,0.971531569957733,33.3306083679199,0,35,4,200,0.00278452900238335,-0.292338222265244,1.23003780841827,1,,,,,,,,,,,,,,,,
,3870608817.49764,300.178344726562,-719.953491210937,,,6,,,,33.3224563598633,,,100,,,,,,,,,,,,,,,,,,,,,,300.171508789063,300.197509765625,-719.953491210937,-719.953491210937,,,8.25871849060059,,1,0,0,0,0.0138092041015625,30.7917900085449,1,1,1,300.185180664063,0,4232058624,300.187637329102,,,-0.0331363836770944,0.00164117309933804,-0.0331364795520758,0.00164117340997913,0.971264898777008,0.971359074115753,33.3312835693359,,35,4,200,0.00059932516887784,-0.313851416110992,1.30624127388,1,,,,,,,,,,,,,,,,
,3870608933.14512,300.056716918945,-770.063171386719,,,6,,,,33.3224563598633,,,100,,,,,,,,,,,,,,,,,,,,,,300.050537109375,300.067047119141,-770.063171386719,-770.063171386719,,,8.23611450195313,,1,0,0,0,0.0138092041015625,30.7917900085449,1,1,1,300.062896728516,0,4232058720,300.060543823242,,,-0.0351366093961545,0.00174023456335537,-0.0351367062952259,0.00174023513366381,0.97138112783432,0.971466064453125,33.3308258056641,,35,4,200,0.00316670187748969,-0.327274590730667,1.3887996673584,1,,,,,,,,,,,,,,,,
,3870609057.26381,300.078796386719,-1499.83081054687,,,6,,,,33.3224563598633,,,100,,,,,,,,,,,,,,,,,,,,,,300.077545166016,300.092987060547,-1499.83081054687,-1499.83081054687,,,8.2175931930542,,1,0,0,0,0.0138092041015625,30.7917900085449,1,1,1,300.080047607422,0,4232058624,300.085159301758,,,-0.0596041642883798,0.00295207899859179,-0.0596042967057037,0.00295207991524357,0.971103847026825,0.971170008182526,33.3298759460449,0,35,4,200,0.000174483328009956,-0.559846580028534,2.35016679763794,1,,,,,,,,,,,,,,,,
,3870609175.745,300.223892211914,-4000.31494140625,,,6,,,,33.3224563598633,,,100,,,,,,,,,,,,,,,,,,,,,,300.221252441406,300.241943359375,-4000.31494140625,-4000.31494140625,,,8.21619987487793,,1,0,0,0,0.0138092041015625,30.7917900085449,1,1,1,300.226531982422,0,4232058816,300.232708740234,,,-0.0965818266268689,0.00478351532224699,-0.0965819554174987,0.00478351614266279,0.97106659412384,0.971106767654419,33.3282432556152,5.77306175231934,35,4,200,-0.000341747247148305,-0.90919679403305,3.80212712287903,1,,,,,,,,,,,,,,,,
,3870609295.34402,300.1240234375,-6500.3466796875,,,6,,,,33.3224563598633,,,100,,,,,,,,,,,,,,,,,,,,,,300.116577148438,300.140167236328,-6500.3466796875,-6500.3466796875,,,8.1995792388916,,1,0,0,0,0.013885498046875,30.7917900085449,1,1,1,300.131469726562,0,4232058688,300.131970214844,,,-0.107231936226645,0.00531100403727573,-0.107232019795208,0.00531100468650971,0.971013426780701,0.97103613615036,33.3268089294434,0,35,4,200,-0.000884090724866837,-1.01046514511108,4.21116733551025,1,,,,,,,,,,,,,,,,
,3870609408.87745,300.153671264648,-9000.390625,,,6,,,,33.3224563598633,,,100,,,,,,,,,,,,,,,,,,,,,,300.148834228516,300.167602539063,-9000.390625,-9000.390625,,,8.21280670166016,,1,0,0,0,0.0138092041015625,30.7917900085449,1,1,1,300.158508300781,0,4232058720,300.159930419922,,,-0.111894825269584,0.00554196960400296,-0.111894900496481,0.00554197014774783,0.970883905887604,0.970903635025024,33.3265228271484,0,35,4,200,-0.00139460782520473,-1.05188298225403,4.40003299713135,1,,,,,,,,,,,,,,,,
,3870609568.90752,300.155059814453,-25000.3046875,,,6,,,,33.3224563598633,,,100,,,,,,,,,,,,,,,,,,,,,,300.141448974609,300.171051025391,-25000.3046875,-25000.3046875,,,8.20333290100098,,1,0,0,0,0.0138092041015625,30.3030319213867,1,1,1,300.141265869141,0,4232058432,300.16032409668,,,-0.119699434766684,0.0059286745555798,-0.119699692399919,0.00592867635587879,0.969996869564056,0.970058500766754,33.3297538757324,0,35,4,200,-0.00210490147583187,-1.14507246017456,4.70355415344238,1,,,,,,,,,,,,,,,,
,3870609720.88896,300.163177490234,-50000.26953125,,,6,,,,33.3224563598633,,,100,,,,,,,,,,,,,,,,,,,,,,300.151489257812,300.182098388672,-50000.26953125,-50000.26953125,,,8.23510646820068,,1,0,0,0,0.0138092041015625,30.7917900085449,1,1,1,300.174865722656,0,4232058496,300.172946166992,,,-0.122339913118043,0.00605979001921117,-0.122341622917928,0.00605979853891871,0.968214571475983,0.96861207485199,33.3414726257324,0,35,4,200,-0.00157196505460888,-1.18141889572144,4.80780029296875,1,,,,,,,,,,,,,,,,
,3870609843.69342,300.066162109375,-70000.4609375,,,6,,,,33.3224563598633,,,100,,,,,,,,,,,,,,,,,,,,,,300.057678222656,300.080932617188,-70000.4609375,-70000.4609375,,,8.2200870513916,,1,0,0,0,0.0138092041015625,30.7917900085449,1,1,1,300.058197021484,0,4232058656,300.071493530273,,,-0.123384081654055,0.00611191421456782,-0.123389063833191,0.00611192158133784,0.966199457645416,0.967377662658691,33.356014251709,0,35,4,200,-0.00261588930152357,-1.2147821187973,4.83412837982178,1,,,,,,,,,,,,,,,,