File: Data/KMK249/ZFCFC/KMK249_ZFCFC.dat
[Header]
; MPMS3 Data File (default extension .dat)
; Copyright (c) 2007, Quantum Design, Inc. All rights reserved.
TITLE,
FILEOPENTIME,3842843141.88594,10/08/2021,8:25 am
BYAPP,MPMS3 w/ AC,1.0,1.1
INFO,MPMS3 Measurement Release 1.1.16 Build 424, MultiVu Release 2.3.4.19,APPNAME
INFO,Linear Motor Servo Controller,MOTOR_MODULE_NAME
INFO,3101-100 J0,MOTOR_HW_VERSION
INFO,MMC721,MOTOR_SERIAL_NUMBER
INFO,01.04.28,MOTOR_SOFTWARE_VERSION
INFO,Quantum Design Squid Module,SQUID_MODULE_NAME
INFO,3101-501 B0,SQUID_HW_VERSION
INFO,SQM195,SQUID_SERIAL_NUMBER
INFO,01.03.04,SQUID_SOFTWARE_VERSION
INFO,SQUID AC,AC_MODULE_NAME
INFO,3101-401 f1,AC_HW_VERSION
INFO,SAC107,AC_SERIAL_NUMBER
INFO,SQUID AC 00.95.07,AC_SOFTWARE_VERSION
INFO,TCI166,COIL_SERIAL_NUMBER
INFO,0,MOMENT_UNITS
INFO,KMK249,SAMPLE_MATERIAL
INFO,powder in VSM,SAMPLE_COMMENT
INFO,2.4,SAMPLE_MASS
INFO,,SAMPLE_VOLUME
INFO,,SAMPLE_MOLECULAR_WEIGHT
INFO,,SAMPLE_SIZE
INFO,,SAMPLE_SHAPE
INFO,Straw,SAMPLE_HOLDER
INFO,Standard,SAMPLE_HOLDER_DETAIL
INFO,64.92,SAMPLE_OFFSET
DATATYPE,COMMENT,1
DATATYPE,TIME,2
STARTUPAXIS,X,2
STARTUPAXIS,Y1,5
FIELDGROUP, VSM,2,3,4,5,6,8,9,10,11,14,15
FIELDGROUP, DC, 2,3,4,14,56,57,58,59,60,61,62,63,64,65,66,67,68,69
FIELDGROUP, AC, 2,3,4,11,16,17,18,19,20,21,22,23,24,25,26,27,28,29,30
STARTUPGROUP, All
[Data]
Comment,Time Stamp (sec),Temperature (K),Magnetic Field (Oe),Moment (emu),M. Std. Err. (emu),Transport Action,Averaging Time (sec),Frequency (Hz),Peak Amplitude (mm),Center Position (mm),Lockin Signal' (V),Lockin Signal (V),Range,M. Quad. Signal (emu),AC Moment (emu),AC M. Std Err. (emu),AC Phase (deg),AC Phase Std. Err. (deg),AC Susceptibility (emu/Oe),AC Suscept. Std Err. (emu/Oe),AC X' (emu/Oe),AC X' Std Err. (emu/Oe),AC X'' (emu/Oe),AC X'' Std Err. (emu/Oe),AC Drive (Oe),AC Frequency (Hz),AC Averaging Time (sec),AC Cycles,AC Range,AC Measure Type,AC Signal' (V),AC Signal'' (V),AC Trim Coil Ratio,AC Trim Coil Phase,Min. Temperature (K),Max. Temperature (K),Min. Field (Oe),Max. Field (Oe),Mass (grams),Motor Lag (deg),Pressure (Torr),Measure Count,Measurement Number,SQUID Status (code),Motor Status (code),Measure Status (code),Motor Current (amps),Motor Temp. (C),Temp. Status (code),Field Status (code),Chamber Status (code),Chamber Temp (K),Redirection State,Evercool Status,Average Temp (K),Rotation Angle (deg),Rotator state,DC Moment Fixed Ctr (emu),DC Moment Err Fixed Ctr (emu),DC Moment Free Ctr (emu),DC Moment Err Free Ctr (emu),DC Fixed Fit,DC Free Fit,DC Calculated Center (mm),DC Calculated Center Err (mm),DC Scan Length (mm),DC Scan Time (s),DC Number of Points,DC Squid Drift,DC Min V (V),DC Max V (V),DC Scans per Measure,Map 01,Map 02,Map 03,Map 04,Map 05,Map 06,Map 07,Map 08,Map 09,Map 10,Map 11,Map 12,Map 13,Map 14,Map 15,Map 16
,3842844063.75025,5.00210285186768,100.035980224609,,,6,,,,33.7073998435395,,,10,,,,,,,,,,,,,,,,,,,,,,4.99810981750488,5.0020489692688,100.035980224609,100.035980224609,,,4.28024244308472,,1,0,0,0,0,32.7468223571777,1,1,1,5.00229501724243,0,2084573184,5.00020575523376,,,0.0046233014930554,0.000232914609999655,0.00466624488522879,0.000232946207022867,0.859048902988434,0.957039296627045,33.1982231140137,0,35,4,200,0.000615703582298011,-1.90112817287445,0.493674606084824,1,,,,,,,,,,,,,,,,
,3842844119.48275,8.55950021743774,100.035980224609,,,6,,,,33.7073998435395,,,10,,,,,,,,,,,,,,,,,,,,,,8.18575477600098,8.90476036071777,100.035980224609,100.035980224609,,,5.09097576141357,,1,0,0,0,0,31.7693061828613,6,1,1,8.93324565887451,0,2084573184,8.54676828384399,,,0.00484822282564423,0.000244231703283259,0.00489297627572114,0.000244266543690883,0.85944938659668,0.956887900829315,33.1999702453613,0,35,4,200,0.000947178050410002,-1.97257947921753,0.53098863363266,1,,,,,,,,,,,,,,,,
,3842844168.20952,12.3492317199707,100.035980224609,,,6,,,,33.7073998435395,,,10,,,,,,,,,,,,,,,,,,,,,,11.9663915634155,12.7091960906982,100.035980224609,100.035980224609,,,5.56534051895142,,1,0,0,0,0,32.2580642700195,6,1,1,12.7320718765259,0,2084573184,12.3433974266052,,,0.00519242654498118,0.000261547510716955,0.00523982504184382,0.000261583313720226,0.860080301761627,0.956759393215179,33.2026863098145,5.17996788024902,35,4,200,0.00110826536547393,-2.105877161026,0.471780955791473,1,,,,,,,,,,,,,,,,
,3842844225.41397,16.9888439178467,100.035980224609,,,6,,,,33.7127563422103,,,10,,,,,,,,,,,,,,,,,,,,,,16.6208229064941,17.3148746490479,100.035980224609,100.035980224609,,,5.90862894058228,,1,0,0,0,0.013885498046875,32.7468223571777,2,1,1,17.3568649291992,0,2084573184,16.9665298461914,,,0.00572082237002255,0.00028816672637967,0.00577315719873957,0.000288211270053433,0.859997093677521,0.956529021263123,33.2079925537109,,35,4,200,0.00125705648679286,-2.29634714126587,0.545392632484436,1,,,,,,,,,,,,,,,,
,3842844273.99828,20.8457221984863,100.035980224609,,,6,,,,33.7127563422103,,,10,,,,,,,,,,,,,,,,,,,,,,20.4583339691162,21.2050762176514,100.035980224609,100.035980224609,,,6.09395885467529,,1,0,0,0,0.013885498046875,31.7693061828613,2,1,1,21.2331104278564,0,2084573184,20.8270137786865,,,0.00621060296817883,0.000312776245936299,0.0062659382370588,0.000312814061474584,0.861383140087128,0.956400573253632,33.2137222290039,0,35,4,200,0.00126907497178763,-2.47202253341675,0.611009299755096,1,,,,,,,,,,,,,,,,
,3842844331.22562,25.4092330932617,100.035980224609,,,6,,,,33.7181134656451,,,10,,,,,,,,,,,,,,,,,,,,,,25.0367832183838,25.749044418335,100.035980224609,100.035980224609,,,6.25762701034546,,1,0,0,0,0.013885498046875,31.7693061828613,2,1,1,25.7816829681396,0,2084573184,25.3910026550293,,,0.00677505698099998,0.000341176252989091,0.00683491920496084,0.000341223184423817,0.861940622329712,0.956137895584106,33.221752166748,5.18135166168213,35,4,200,0.00132401974406093,-2.76760149002075,0.686843276023865,1,,,,,,,,,,,,,,,,
,3842844379.73903,29.2748079299927,100.035980224609,,,6,,,,33.7181134656451,,,10,,,,,,,,,,,,,,,,,,,,,,28.9131813049316,29.6364345550537,100.035980224609,100.035980224609,,,6.36571979522705,,1,0,0,0,0.013885498046875,31.7693061828613,2,1,1,29.6364345550537,0,2084573184,29.2630828857422,,,0.00728925017534088,0.000366970940151572,0.00735152699112934,0.000367018242277953,0.863871693611145,0.955887377262115,33.2298812866211,5.76453638076782,35,4,200,0.00145343178883195,-2.95165657997131,0.756120979785919,1,,,,,,,,,,,,,,,,
,3842844437.42723,33.8984451293945,100.035980224609,,,6,,,,33.7231284610132,,,10,,,,,,,,,,,,,,,,,,,,,,33.5148773193359,34.2330856323242,100.035980224609,100.035980224609,,,6.46716690063477,,1,0,0,0,0.012969970703125,32.2580642700195,2,1,1,34.2820129394531,0,2084573184,33.8829360961914,,,0.00797820200267456,0.000401575465549305,0.00804463555561394,0.000401627413591593,0.865317404270172,0.95552670955658,33.2412528991699,4.03811407089233,35,4,200,0.00164678529836237,-3.1979603767395,0.849628448486328,1,,,,,,,,,,,,,,,,
,3842844486.16938,37.8140449523926,100.035980224609,,,6,,,,33.7231284610132,,,10,,,,,,,,,,,,,,,,,,,,,,37.4302787780762,38.1509857177734,100.035980224609,100.035980224609,,,6.53553199768066,,1,0,0,0,0.013885498046875,32.2580642700195,2,1,1,38.197811126709,0,2084573184,37.8082050323486,,,0.008624283330443,0.000433940267119922,0.00869289748588076,0.000433997806045875,0.86794900894165,0.955216586589813,33.2523345947266,0,35,4,200,0.00176151201594621,-3.45148849487305,0.828249394893646,1,,,,,,,,,,,,,,,,
,3842844543.45496,42.4092559814453,100.035980224609,,,6,,,,33.7284810944253,,,10,,,,,,,,,,,,,,,,,,,,,,42.0680503845215,42.7091102600098,100.035980224609,100.035980224609,,,6.60445356369018,,1,0,0,0,0.013885498046875,31.7693061828613,2,1,1,42.7819404602051,0,2084573920,42.3830265469021,,,0.00942356732264422,0.000474020675351442,0.00949543107504733,0.000474072277926276,0.870107710361481,0.954860985279083,33.2670249938965,0.367883294820786,35,4,200,0.0018774620257318,-3.82391738891602,0.93633097410202,1,,,,,,,,,,,,,,,,
,3842844601.41427,47.0728645324707,100.035980224609,,,6,,,,33.7339304051969,,,10,,,,,,,,,,,,,,,,,,,,,,46.6867256164551,47.4158210754395,100.035980224609,100.035980224609,,,6.6608738899231,,1,0,0,0,0.013885498046875,32.2580642700195,2,1,1,47.4590034484863,0,2084573824,47.0559307098389,,,0.0102337734575273,0.000514596624782284,0.0103080662882816,0.000514651653377006,0.872763991355896,0.954541325569153,33.283763885498,,35,4,200,0.00192999211139977,-4.11430025100708,1.04560828208923,1,,,,,,,,,,,,,,,,
,3842844658.71194,51.7054977416992,100.035980224609,,,6,,,,33.7391817473282,,,10,,,,,,,,,,,,,,,,,,,,,,51.3193855285645,52.0293655395508,100.035980224609,100.035980224609,,,6.70890665054321,,1,0,0,0,0.013885498046875,32.2580642700195,2,1,1,52.091609954834,0,2084574048,51.670902633667,,,0.0109902968376602,0.000552425393457055,0.0110656323336752,0.000552481773549819,0.875773012638092,0.954262733459473,33.3017616271973,,35,4,200,0.00166639278177172,-4.38561677932739,1.1472442150116,1,,,,,,,,,,,,,,,,
,3842844716.07148,56.3391017913818,100.035980224609,,,6,,,,33.7449796042319,,,10,,,,,,,,,,,,,,,,,,,,,,55.955997467041,56.6892242431641,100.035980224609,100.035980224609,,,6.7498631477356,,1,0,0,0,0,31.7693061828613,2,1,1,56.7222061157227,0,2084574048,56.3260585784912,,,0.0116711885610148,0.000586422966670047,0.0117466079446057,0.000586487610857173,0.878884255886078,0.954027712345123,33.3207588195801,3.44825857609976E-5,35,4,200,0.00185380119364709,-4.64700651168823,1.12955725193024,1,,,,,,,,,,,,,,,,
,3842844773.4637,61.0022869110107,100.035980224609,,,6,,,,33.7502817465609,,,10,,,,,,,,,,,,,,,,,,,,,,60.5985488891602,61.3713912963867,100.035980224609,100.035980224609,,,6.78616285324097,,1,0,0,0,0,32.2580642700195,2,1,1,61.4060249328613,0,2084574144,60.9777183532715,,,0.0122588337880401,0.000615693417988332,0.0123325127810945,0.000615746439517524,0.882316648960114,0.953831315040588,33.340461730957,5.77411985397339,35,4,200,0.00152875366620719,-4.94896221160889,1.20815253257751,1,,,,,,,,,,,,,,,,
,3842844849.81791,67.1882095336914,100.035980224609,,,6,,,,33.7559315966718,,,100,,,,,,,,,,,,,,,,,,,,,,66.7970962524414,67.5294570922852,100.035980224609,100.035980224609,,,6.82769775390625,,1,0,0,0,0,32.2580642700195,2,1,1,67.5793228149414,0,2084574304,67.1624755859375,,,0.0128909096310461,0.000647064420385266,0.012960635058909,0.000647115888241453,0.887275218963623,0.953562676906586,33.3672065734863,0,35,4,200,0.000169399296282791,-0.517312824726105,0.129423528909683,1,,,,,,,,,,,,,,,,
,3842844930.00226,73.7073364257812,100.035980224609,,,6,,,,33.7662596438894,,,100,,,,,,,,,,,,,,,,,,,,,,72.9278564453125,74.4326782226563,100.035980224609,100.035980224609,,,6.86845970153809,,1,0,0,0,0.013885498046875,31.7693061828613,2,1,1,74.48681640625,0,2084574272,73.6804239373458,,,0.0133995696670623,0.000672254313851294,0.013464765551612,0.000672294691120285,0.891832292079926,0.953314542770386,33.3970603942871,5.77901887893677,35,4,200,0.000159236224135384,-4.88149642944336,4.83960723876953,1,,,,,,,,,,,,,,,,
,3842845001.73803,79.5562210083008,100.035980224609,,,6,,,,33.7718320432574,,,100,,,,,,,,,,,,,,,,,,,,,,79.1662368774414,79.9133071899414,100.035980224609,100.035980224609,,,6.89571189880371,,1,0,0,0,0.013885498046875,32.2580642700195,2,1,1,79.9462051391602,0,2084574496,79.5446716308594,,,0.0136861145896988,0.000686330241967897,0.0137466359966834,0.000686374468518021,0.895903706550598,0.953128576278686,33.4202270507812,0.108709678053856,35,4,200,0.000148808830999769,-0.545604884624481,0.139986723661423,1,,,,,,,,,,,,,,,,
,3842845086.84208,86.4903793334961,100.035980224609,,,6,,,,33.7836083630799,,,100,,,,,,,,,,,,,,,,,,,,,,86.1133651733398,86.8673934936523,100.035980224609,100.035980224609,,,6.92914533615112,,1,0,0,0,0.013885498046875,32.2580642700195,2,1,1,86.8673934936523,0,2084574240,86.4889503479004,,,0.0139385143711478,0.000698703336863953,0.0139940688603316,0.000698736361594562,0.899840772151947,0.952893018722534,33.4492950439453,0.000140146439662203,35,4,200,0.000144136836752295,-0.554812550544739,0.132440954446793,1,,,,,,,,,,,,,,,,
,3842845172.16652,93.5919075012207,100.035980224609,,,6,,,,33.7952254278391,,,100,,,,,,,,,,,,,,,,,,,,,,93.1890716552734,93.9529571533203,100.035980224609,100.035980224609,,,6.95586442947388,,1,0,0,0,0.013885498046875,31.7693061828613,2,1,1,93.994743347168,0,2084574304,93.5643676757813,,,0.0141020871254448,0.00070663430675123,0.0141527095904758,0.000706665517219824,0.903673827648163,0.952657699584961,33.4779930114746,0.0509720295667648,35,4,200,0.000139567564474419,-0.560494124889374,0.134576559066772,1,,,,,,,,,,,,,,,,
,3842845270.87386,101.757461547852,100.035980224609,,,6,,,,33.8117960938082,,,100,,,,,,,,,,,,,,,,,,,,,,100.965606689453,102.484619140625,100.035980224609,100.035980224609,,,6.98456287384033,,1,0,0,0,0.013885498046875,31.7693061828613,2,1,1,102.54931640625,0,2084574336,101.739276685213,,,0.0142260987978773,0.000712580344467645,0.0142715121980955,0.000712607534877431,0.907622456550598,0.95235949754715,33.5125389099121,0.111400127410889,35,4,200,0.000135826805490069,-4.861496925354,4.75854301452637,1,,,,,,,,,,,,,,,,
,3842845374.27688,110.342628479004,100.035980224609,,,6,,,,33.8288522498759,,,100,,,,,,,,,,,,,,,,,,,,,,109.54182434082,111.094871520996,100.035980224609,100.035980224609,,,7.01994276046753,,1,0,0,0,0.0139617919921875,32.2580642700195,2,1,1,111.143432617187,0,2084574336,110.307120875308,,,0.0143080125396948,0.000716430164906893,0.0143483334329697,0.000716453813179385,0.911494970321655,0.952050626277924,33.5476837158203,2.35810057347408E-5,35,4,200,0.000102346937637776,-4.86720323562622,4.73554420471191,1,,,,,,,,,,,,,,,,
,3842845514.15913,121.903221130371,100.035980224609,,,6,,,,33.8568824730103,,,100,,,,,,,,,,,,,,,,,,,,,,121.122512817383,122.621772766113,100.035980224609,100.035980224609,,,7.06156349182129,,1,0,0,0,0.013885498046875,32.2580642700195,2,1,1,122.683929443359,0,2084574400,121.871704101562,,,0.014383561699512,0.000719940024433461,0.0144182549530718,0.000719958487015366,0.915854036808014,0.951667010784149,33.5965919494629,0,35,4,200,0.000134378336952068,-4.87016820907593,4.72467470169067,1,,,,,,,,,,,,,,,,
,3842845653.91002,133.498756408691,100.035980224609,,,6,,,,33.8877138732815,,,100,,,,,,,,,,,,,,,,,,,,,,132.683792114258,134.275909423828,100.035980224609,100.035980224609,,,7.09475660324097,,1,0,0,0,0.013885498046875,30.3030319213867,2,1,1,134.313720703125,0,2084574368,133.484367370605,,,0.0144173351808432,0.000721397261933304,0.0144471787287767,0.000721412384572706,0.91975998878479,0.9513920545578,33.6465148925781,,35,4,200,0.00012719031656161,-4.86427545547485,4.86508321762085,1,,,,,,,,,,,,,,,,
,3842845793.6327,145.089797973633,100.035980224609,,,6,,,,33.9215260692634,,,100,,,,,,,,,,,,,,,,,,,,,,144.30419921875,145.83952331543,100.035980224609,100.035980224609,,,7.12214088439941,,1,0,0,0,0.013885498046875,31.7693061828613,2,1,1,145.875396728516,0,2084574336,145.066368504574,,,0.0143912698828929,0.000719904460366665,0.0144172070098987,0.000719924949189361,0.923076272010803,0.951137065887451,33.6970863342285,0,35,4,200,0.000121990073239431,-4.84900093078613,4.85977363586426,1,,,,,,,,,,,,,,,,
,3842845933.38616,156.654808044434,100.035980224609,,,6,,,,33.9580491647918,,,100,,,,,,,,,,,,,,,,,,,,,,155.856155395508,157.402862548828,100.035980224609,100.035980224609,,,7.14828109741211,,1,0,0,0,0.013885498046875,33.7243423461914,2,1,1,157.453460693359,0,2084574368,156.633063065378,,,0.0142974987303017,0.000715060367719726,0.0143198231493769,0.00071506923379883,0.925897002220154,0.950929880142212,33.7483444213867,0,35,4,200,0.000120764256280381,-4.80280637741089,4.83693599700928,1,,,,,,,,,,,,,,,,
,3842846073.70066,168.321350097656,100.035980224609,,,6,,,,33.9975536317156,,,100,,,,,,,,,,,,,,,,,,,,,,167.508331298828,169.108749389648,100.035980224609,100.035980224609,,,7.17101669311523,,1,0,0,0,0.013885498046875,31.7693061828613,2,1,1,169.134368896484,0,2084574656,168.321464137027,,,0.0141418950510204,0.000707156389759882,0.0141613959787028,0.000707165348818926,0.928243339061737,0.95071804523468,33.8006057739258,9.89194886642508E-5,35,4,200,0.000108400439785328,-4.74719095230103,4.82769250869751,1,,,,,,,,,,,,,,,,
,3842846213.61168,179.970375061035,100.035980224609,,,6,,,,34.0399174107512,,,100,,,,,,,,,,,,,,,,,,,,,,179.178817749023,180.727249145508,100.035980224609,100.035980224609,,,7.19561576843262,,1,0,0,0,0.013885498046875,32.2580642700195,2,1,1,180.761932373047,0,2084574176,179.937484741211,,,0.0139373839283009,0.000696831373015111,0.0139545390880726,0.000696839007555766,0.930232882499695,0.950623512268066,33.8538017272949,0,35,4,200,7.60661787353456E-5,-4.81161403656006,4.81136322021484,1,,,,,,,,,,,,,,,,
,3842846353.35397,191.558700561523,100.035980224609,,,6,,,,34.0850076109484,,,100,,,,,,,,,,,,,,,,,,,,,,190.776672363281,192.340728759766,100.035980224609,100.035980224609,,,7.21856212615967,,1,0,0,0,0.013885498046875,32.2580642700195,2,1,1,192.340728759766,0,2084574432,191.580137553968,,,0.0136961257921443,0.000684687664384353,0.0137112713701685,0.000684694466477686,0.931955099105835,0.950529873371124,33.9086151123047,9.49184250202961E-5,35,4,200,0.00010411512630526,-4.86753559112549,4.79925203323364,1,,,,,,,,,,,,,,,,
,3842846492.90935,203.155776977539,100.035980224609,,,6,,,,34.1328293909168,,,100,,,,,,,,,,,,,,,,,,,,,,202.349502563477,203.914566040039,100.035980224609,100.035980224609,,,7.24262619018555,,1,0,0,0,0.0017547607421875,31.7693061828613,2,1,1,203.962051391602,0,2084574368,203.144179494757,,,0.0134282936674095,0.000671228667867999,0.0134417319232111,0.000671234733688764,0.933487176895142,0.950519144535065,33.9650230407715,0,35,4,200,0.000101432007795665,-4.89064264297485,4.82529306411743,1,,,,,,,,,,,,,,,,
,3842846632.91387,214.808349609375,100.035980224609,,,6,,,,34.1835265255511,,,100,,,,,,,,,,,,,,,,,,,,,,214.000274658203,215.572265625,100.035980224609,100.035980224609,,,7.26815319061279,,1,0,0,0,0.013885498046875,32.2580642700195,2,1,1,215.616424560547,0,2084574464,214.827680085835,,,0.0131405499736404,0.000656783811812168,0.0131525153196208,0.000656791176792225,0.934912383556366,0.950557827949524,34.0237274169922,5.22076892852783,35,4,200,9.3917224148754E-5,-4.89306163787842,4.81159210205078,1,,,,,,,,,,,,,,,,
,3842846771.56567,226.250595092773,100.035980224609,,,6,,,,34.2367135006748,,,100,,,,,,,,,,,,,,,,,,,,,,225.439117431641,226.97802734375,100.035980224609,100.035980224609,,,7.29948806762695,,1,0,0,0,0.013885498046875,32.2580642700195,2,1,1,227.062072753906,0,2084574368,226.227225052683,,,0.0128412341381678,0.000641769389117532,0.012851913355286,0.000641774562214393,0.936211049556732,0.95072603225708,34.0837745666504,,35,4,200,9.12365358090028E-5,-4.87924575805664,4.79385280609131,1,,,,,,,,,,,,,,,,
,3842846906.36186,237.459266662598,100.035980224609,,,6,,,,34.2929936605324,,,10,,,,,,,,,,,,,,,,,,,,,,237.041549682617,237.860855102539,100.035980224609,100.035980224609,,,7.34368419647217,,1,0,0,0,0.013885498046875,31.2805480957031,2,1,1,237.876983642578,0,2084574432,237.442742919922,,,0.0125487582271793,0.000627126958042624,0.0125587740714903,0.000627131965903597,0.93684846162796,0.950872898101807,34.1431655883789,,35,4,200,0.00088809325825423,-4.93511247634888,1.23931264877319,1,,,,,,,,,,,,,,,,
,3842846998.03414,245.045280456543,100.035980224609,,,6,,,,34.3313167456723,,,10,,,,,,,,,,,,,,,,,,,,,,244.656051635742,245.400207519531,100.035980224609,100.035980224609,,,7.39856815338135,,1,0,0,0,0.013885498046875,31.7693061828613,2,1,1,245.434509277344,0,2084574400,245.023643493652,,,0.0123434483394074,0.000616830497824572,0.0123525814335276,0.000616832400508439,0.937781870365143,0.950983643531799,34.1866226196289,0.191539481282234,35,4,200,0.000578102306462824,-4.86197662353516,1.21119058132172,1,,,,,,,,,,,,,,,,
,3842847090.35154,252.713012695313,100.035980224609,,,6,,,,34.3711810593558,,,10,,,,,,,,,,,,,,,,,,,,,,252.293884277344,253.079864501953,100.035980224609,100.035980224609,,,7.49538469314575,,1,0,0,0,0.013885498046875,33.2355842590332,2,1,1,253.132141113281,0,2084574560,252.696171569824,,,0.0121348547140264,0.000606368667382755,0.0121431936022422,0.000606373357976705,0.938784420490265,0.951080739498138,34.2322158813477,0,35,4,200,0.000544628186617047,-4.78718042373657,1.18269622325897,1,,,,,,,,,,,,,,,,
,3842847182.66648,260.376266479492,100.035980224609,,,6,,,,34.4124185920821,,,10,,,,,,,,,,,,,,,,,,,,,,259.978424072266,260.739562988281,100.035980224609,100.035980224609,,,7.59852743148804,,1,0,0,0,0.013885498046875,31.7693061828613,2,1,1,260.774108886719,0,2084574528,260.364282226563,,,0.011924669059589,0.000595829572880161,0.0119321486151152,0.00059583273303527,0.939784228801727,0.951151132583618,34.2794799804687,0,35,4,200,0.00084035110194236,-4.71186065673828,1.15397799015045,1,,,,,,,,,,,,,,,,
,3842847274.48751,267.994689941406,100.035980224609,,,6,,,,34.4546205723871,,,10,,,,,,,,,,,,,,,,,,,,,,267.604644775391,268.367919921875,100.035980224609,100.035980224609,,,7.52691698074341,,1,0,0,0,0.013885498046875,31.7693061828613,2,1,1,268.384735107422,0,2084574592,267.987573242188,,,0.0117166069090775,0.000585386550676978,0.0117230115430906,0.000585388128557412,0.941125571727753,0.951196253299713,34.3302917480469,0,35,4,200,0.000796808919403702,-4.63754367828369,1.12552428245544,1,,,,,,,,,,,,,,,,
,3842847366.42573,275.629867553711,100.035980224609,,,6,,,,34.4981221606518,,,10,,,,,,,,,,,,,,,,,,,,,,275.241973876953,275.977844238281,100.035980224609,100.035980224609,,,7.51448249816895,,1,0,0,0,0.013885498046875,31.7693061828613,2,1,1,276.017761230469,0,2084574368,275.603555297852,,,0.0115095316845809,0.000574975065240753,0.0115145136715536,0.000574975906703313,0.943094611167908,0.951234817504883,34.387393951416,,35,4,200,0.000806548807304353,-4.56344509124756,1.09710264205933,1,,,,,,,,,,,,,,,,
,3842847458.31271,283.254135131836,100.035980224609,,,6,,,,34.542666672131,,,10,,,,,,,,,,,,,,,,,,,,,,282.865447998047,283.614379882813,100.035980224609,100.035980224609,,,7.52733945846558,,1,0,0,0,0.013885498046875,31.7693061828613,2,1,1,283.642822265625,0,2084574336,283.239422607422,,,0.0113019040133939,0.000564513870648613,0.0113051123025166,0.000564513897233196,0.945913314819336,0.951427400112152,34.4528503417969,6.11442374065518E-5,35,4,200,0.000798306777141988,-4.48873138427734,1.06851637363434,1,,,,,,,,,,,,,,,,
,3842847550.11975,290.879852294922,100.035980224609,,,6,,,,34.5885714623804,,,10,,,,,,,,,,,,,,,,,,,,,,290.470611572266,291.289093017578,100.035980224609,100.035980224609,,,7.57714462280273,,1,0,0,0,0.013885498046875,31.7693061828613,2,1,1,291.289093017578,0,2084574592,290.859899902344,,,0.0110908567654796,0.000553878019183895,0.0110923680863387,0.000553877868979597,0.949152588844299,0.951905608177185,34.5262603759766,0,35,4,200,0.000779146095737815,-4.41201972961426,1.03894972801208,1,,,,,,,,,,,,,,,,
,3842847641.97496,298.446304321289,100.035980224609,,,6,,,,34.6356949541709,,,10,,,,,,,,,,,,,,,,,,,,,,298.098083496094,298.765838623047,100.035980224609,100.035980224609,,,7.69727277755737,,1,0,0,0,0.013885498046875,31.7693061828613,2,1,1,298.794525146484,0,2084574272,298.455395507812,,,0.0108770989364654,0.00054312434790997,0.0108774532877442,0.00054312437928043,0.952077150344849,0.952759027481079,34.6052780151367,0,35,4,200,0.000686328217852861,-4.33406829833984,1.00906956195831,1,,,,,,,,,,,,,,,,
,3842847699.2237,299.812057495117,100.035980224609,,,6,,,,34.6418749595941,,,10,,,,,,,,,,,,,,,,,,,,,,299.785888671875,299.836151123047,100.035980224609,100.035980224609,,,7.80525016784668,,1,0,0,0,0.013885498046875,31.7693061828613,5,1,1,299.838226318359,0,2084574368,299.815258789063,,,0.0108296631596209,0.000540744593626384,0.010829980943491,0.000540744503449278,0.952510714530945,0.953134834766388,34.6128921508789,0,35,4,200,0.000899405451491475,-4.31448316574097,1.00082695484161,1,,,,,,,,,,,,,,,,
,3842848648.52252,5.00203275680542,100.035980224609,,,6,,,,33.7073184824919,,,100,,,,,,,,,,,,,,,,,,,,,,4.99785137176514,5.00205898284912,100.035980224609,100.035980224609,,,4.28949737548828,,1,0,0,0,0.013885498046875,31.7693061828613,1,1,1,5.00216817855835,0,2084573184,5.00010927099931,,,0.0139862207905123,0.000703019335047533,0.0140837388603613,0.000703095963097753,0.875721573829651,0.956579267978668,33.2660026550293,0,35,4,200,0.000128826781292446,-4.77112770080566,4.86688280105591,1,,,,,,,,,,,,,,,,
,3842848708.84374,8.55300140380859,100.035980224609,,,6,,,,33.7073184824919,,,100,,,,,,,,,,,,,,,,,,,,,,8.18602848052979,8.90163707733154,100.035980224609,100.035980224609,,,5.0896692276001,,1,0,0,0,0.0139617919921875,31.7693061828613,6,1,1,8.9199743270874,0,2084573184,8.54253816604614,,,0.0139838907176651,0.00070288519636943,0.0140809144147007,0.000702955537908205,0.875919640064239,0.956578075885773,33.2668266296387,,35,4,200,0.000131422086269595,-0.567551672458649,0.133282944560051,1,,,,,,,,,,,,,,,,
,3842848757.64238,12.3741698265076,100.035980224609,,,6,,,,33.7073184824919,,,100,,,,,,,,,,,,,,,,,,,,,,12.0066394805908,12.7116718292236,100.035980224609,100.035980224609,,,5.56010770797729,,1,0,0,0,0.012969970703125,31.7693061828613,6,1,1,12.7417001724243,0,2084573184,12.3522553443909,,,0.0139848632136486,0.000702896212003985,0.014081265553693,0.000702969549869605,0.876342475414276,0.956677615642548,33.2684020996094,5.76787662506104,35,4,200,0.000130129934404977,-0.56744372844696,0.133241698145866,1,,,,,,,,,,,,,,,,
,3842848824.38224,17.7301568984985,100.035980224609,,,6,,,,33.7124137038093,,,100,,,,,,,,,,,,,,,,,,,,,,17.3513927459717,18.0678081512451,100.035980224609,100.035980224609,,,5.94529056549072,,1,0,0,0,0.013885498046875,31.7693061828613,2,1,1,18.1089210510254,0,2084573184,17.7115381240845,,,0.0139839887892897,0.000702868600257867,0.0140805867710934,0.000702939382716661,0.876157999038696,0.956557333469391,33.2728958129883,3.16327750624623E-5,35,4,200,0.000127046558191068,-0.567473530769348,0.133245512843132,1,,,,,,,,,,,,,,,,
,3842848873.05552,21.6013898849487,100.035980224609,,,6,,,,33.7124137038093,,,100,,,,,,,,,,,,,,,,,,,,,,21.2185363769531,21.9643478393555,100.035980224609,100.035980224609,,,6.11742115020752,,1,0,0,0,0.013885498046875,31.7693061828613,2,1,1,21.9842433929443,0,2084573184,21.5929130554199,,,0.0139890191415365,0.00070303046575308,0.0140836770722191,0.000703094234789561,0.877191364765167,0.956538796424866,33.2770843505859,0,35,4,200,0.000122653160360642,-0.567845523357391,0.133172109723091,1,,,,,,,,,,,,,,,,
,3842848940.15887,26.9595680236816,100.035980224609,,,6,,,,33.7178323009232,,,100,,,,,,,,,,,,,,,,,,,,,,26.5708026885986,27.3195915222168,100.035980224609,100.035980224609,,,6.28889513015747,,1,0,0,0,0.013885498046875,31.7693061828613,2,1,1,27.3483333587646,0,2084573184,26.9521709442139,,,0.0139911425529397,0.000703094080257846,0.0140850661285679,0.000703163829013161,0.877683341503143,0.956528842449188,33.2845916748047,5.76927995681763,35,4,200,0.000128220053738914,-0.567937016487122,0.133075386285782,1,,,,,,,,,,,,,,,,
,3842848988.73531,30.8422212600708,100.035980224609,,,6,,,,33.7178323009232,,,100,,,,,,,,,,,,,,,,,,,,,,30.4453010559082,31.2188949584961,100.035980224609,100.035980224609,,,6.38232040405273,,1,0,0,0,0.013885498046875,30.7917900085449,2,1,1,31.2391414642334,0,2084573184,30.8493408203125,,,0.0139968028496073,0.000703237572859357,0.0140877636893753,0.000703301004134613,0.87931215763092,0.956457495689392,33.2913513183594,0.141779720783234,35,4,200,0.000130565313156694,-0.557282626628876,0.133102595806122,1,,,,,,,,,,,,,,,,
,3842849055.58375,36.1826648712158,100.035980224609,,,6,,,,33.7233566082576,,,100,,,,,,,,,,,,,,,,,,,,,,35.7828369140625,36.5351486206055,100.035980224609,100.035980224609,,,6.48688983917236,,1,0,0,0,0.013885498046875,32.7468223571777,2,1,1,36.5824928283691,0,2084573184,36.186404800415,,,0.0140038218658599,0.000703484015347527,0.0140926109039232,0.000703545613318595,0.880548775196075,0.956365048885345,33.3020401000977,5.77079200744629,35,4,200,0.000128582119941711,-0.557579636573791,0.133086159825325,1,,,,,,,,,,,,,,,,
,3842849122.95241,41.6107749938965,100.035980224609,,,6,,,,33.7286588514227,,,100,,,,,,,,,,,,,,,,,,,,,,41.2152061462402,41.9674072265625,100.035980224609,100.035980224609,,,6.56918525695801,,1,0,0,0,0.013885498046875,32.2580642700195,2,1,1,42.0063438415527,0,2084573184,41.5998832702637,,,0.0140128522038256,0.00070379690581309,0.0140987833523602,0.00070385760351125,0.882213056087494,0.956246316432953,33.3143577575684,2.93884659186006E-5,35,4,200,9.37542063184083E-5,-0.557899534702301,0.13311193883419,1,,,,,,,,,,,,,,,,
,3842849189.74381,46.9781017303467,100.035980224609,,,6,,,,33.7339979056141,,,100,,,,,,,,,,,,,,,,,,,,,,46.6094703674316,47.3330688476562,100.035980224609,100.035980224609,,,6.63447570800781,,1,0,0,0,0.0139617919921875,31.7693061828613,2,1,1,47.3467330932617,0,2084573952,46.9669330596924,,,0.0140236843439212,0.000704177731580135,0.0141062344605388,0.000704232911651815,0.884166479110718,0.956129193305969,33.3278999328613,2.87071379716508E-5,35,4,200,0.000132411849335767,-0.5582435131073,0.13319705426693,1,,,,,,,,,,,,,,,,
,3842849256.54848,52.4121379852295,100.035980224609,,,6,,,,33.7392472371618,,,100,,,,,,,,,,,,,,,,,,,,,,52.0327033996582,52.7260246276855,100.035980224609,100.035980224609,,,6.69236326217651,,1,0,0,0,0.013885498046875,31.2805480957031,2,1,1,52.7915725708008,0,2084574176,52.3712837219238,,,0.0140369540982625,0.00070466237858344,0.0141158710777013,0.000704718070575603,0.886384725570679,0.956000328063965,33.3424835205078,0.141987219452858,35,4,200,0.000100000055681448,-0.558633029460907,0.133320868015289,1,,,,,,,,,,,,,,,,
,3842849323.42002,57.8144588470459,100.035980224609,,,6,,,,33.7449720181255,,,100,,,,,,,,,,,,,,,,,,,,,,57.4214134216309,58.1457786560059,100.035980224609,100.035980224609,,,6.74056148529053,,1,0,0,0,0.013885498046875,32.2580642700195,2,1,1,58.2075042724609,0,2084574016,57.7998218536377,,,0.0140534599440385,0.000705303541828478,0.0141286068186841,0.000705358449887411,0.888718545436859,0.955855488777161,33.3580932617188,,35,4,200,0.000130382308270782,-0.559119164943695,0.133496999740601,1,,,,,,,,,,,,,,,,
,3842849390.65266,63.2428245544434,100.035980224609,,,6,,,,33.7503096122791,,,100,,,,,,,,,,,,,,,,,,,,,,62.8442611694336,63.5999641418457,100.035980224609,100.035980224609,,,6.78044080734253,,1,0,0,0,0.013885498046875,32.2580642700195,2,1,1,63.6413879394531,0,2084574048,63.2322441101074,,,0.014073419055716,0.000706096835979962,0.0141444977525681,0.000706156544857191,0.891369938850403,0.955703794956207,33.3747520446777,0,35,4,200,9.93516441667452E-5,-0.559691905975342,0.133721768856049,1,,,,,,,,,,,,,,,,
,3842849457.53473,68.7207183837891,100.035980224609,,,6,,,,33.7559383317705,,,100,,,,,,,,,,,,,,,,,,,,,,68.3554306030273,69.056022644043,100.035980224609,100.035980224609,,,6.81480169296265,,1,0,0,0,0.013885498046875,31.2805480957031,2,1,1,69.0860061645508,0,2084574112,68.6978225708008,,,0.0140982785296859,0.000707134687534496,0.0141648103825852,0.000707175561357411,0.894099950790405,0.955550849437714,33.392032623291,0.192246913909912,35,4,200,0.000132170229335316,-0.560420513153076,0.134045362472534,1,,,,,,,,,,,,,,,,
,3842849543.17815,75.640495300293,100.035980224609,,,6,,,,33.767423989483,,,100,,,,,,,,,,,,,,,,,,,,,,75.2509765625,75.9973220825195,100.035980224609,100.035980224609,,,6.8518705368042,,1,0,0,0,0.013885498046875,32.2580642700195,2,1,1,76.0300140380859,0,2084574208,75.6317451477051,,,0.0141336530048411,0.000708705700640983,0.0141960897787822,0.000708743964288543,0.896813035011292,0.955335795879364,33.4153213500977,0.110522001981735,35,4,200,0.000134450092446059,-0.561519682407379,0.134534627199173,1,,,,,,,,,,,,,,,,
,3842849623.80422,82.2195854187012,100.035980224609,,,6,,,,33.778894189754,,,100,,,,,,,,,,,,,,,,,,,,,,81.4452438354492,82.9574356079102,100.035980224609,100.035980224609,,,6.8853120803833,,1,0,0,0,0.013885498046875,31.7693061828613,2,1,1,82.9939270019531,0,2084574176,82.1884753578588,,,0.0141748186788896,0.000710554157259455,0.0142329144649705,0.000710589291909904,0.8997642993927,0.955115973949432,33.4396820068359,0,35,4,200,0.000101746547443327,-4.8739333152771,4.77756309509277,1,,,,,,,,,,,,,,,,
,3842849709.03011,89.2366523742676,100.035980224609,,,6,,,,33.7900319031852,,,100,,,,,,,,,,,,,,,,,,,,,,88.4492263793945,89.9932861328125,100.035980224609,100.035980224609,,,6.91574668884277,,1,0,0,0,0.013885498046875,31.7693061828613,2,1,1,90.0240783691406,0,2084574144,89.2253345690276,,,0.0142216541256609,0.000712671983561186,0.0142750791150123,0.000712701884861086,0.903006613254547,0.954889237880707,33.4651107788086,5.78490352630615,35,4,200,0.000102846446679905,-4.87734079360962,4.76330232620239,1,,,,,,,,,,,,,,,,
,3842849798.77833,96.6595306396484,100.035980224609,,,6,,,,33.8005761629971,,,100,,,,,,,,,,,,,,,,,,,,,,96.2662582397461,97.0145416259766,100.035980224609,100.035980224609,,,6.9414324760437,,1,0,0,0,0.013885498046875,31.7693061828613,2,1,1,97.0528030395508,0,2084573952,96.6439796447754,,,0.0142720629592023,0.000714956246496692,0.0143206429447857,0.000714984561886105,0.906522870063782,0.954642355442047,33.4913444519043,,35,4,200,0.000101912657555658,-0.566113173961639,0.13637375831604,1,,,,,,,,,,,,,,,,
,3842849897.39303,104.82933807373,100.035980224609,,,6,,,,33.8176162030256,,,100,,,,,,,,,,,,,,,,,,,,,,104.04044342041,105.55623626709,100.035980224609,100.035980224609,,,6.96897840499878,,1,0,0,0,0,31.7693061828613,2,1,1,105.618232727051,0,2084574272,104.798610084935,,,0.0143333949078082,0.000717790578997963,0.0143772003859112,0.000717817327380433,0.910110890865326,0.954369068145752,33.5246620178223,,35,4,200,0.000131526234326884,-4.73619604110718,4.73921346664429,1,,,,,,,,,,,,,,,,
,3842850018.8549,114.895263671875,100.035980224609,,,6,,,,33.8396264791135,,,100,,,,,,,,,,,,,,,,,,,,,,114.109565734863,115.653968811035,100.035980224609,100.035980224609,,,7.0114893913269,,1,0,0,0,0.013885498046875,32.2580642700195,2,1,1,115.680961608887,0,2084574336,114.881433587325,,,0.0143992046399624,0.000720816775766992,0.0144375464106232,0.000720840352734772,0.914333343505859,0.954059183597565,33.5661964416504,0,35,4,200,0.000103824815596454,-4.74169206619263,4.72219896316528,1,,,,,,,,,,,,,,,,
,3842850158.84699,126.486183166504,100.035980224609,,,6,,,,33.8687476294162,,,100,,,,,,,,,,,,,,,,,,,,,,125.67813873291,127.209373474121,100.035980224609,100.035980224609,,,7.04795551300049,,1,0,0,0,0.013885498046875,31.7693061828613,2,1,1,127.294227600098,0,2084574400,126.441874453896,,,0.0144519695116007,0.000723200691233366,0.0144849768837542,0.000723220586621119,0.918565690517426,0.953700006008148,33.6154823303223,4.05496215820313,35,4,200,9.59537283051759E-5,-4.73815774917603,4.87011384963989,1,,,,,,,,,,,,,,,,
,3842850298.59797,138.083694458008,100.035980224609,,,6,,,,33.9008043147174,,,100,,,,,,,,,,,,,,,,,,,,,,137.302536010742,138.832061767578,100.035980224609,100.035980224609,,,7.07794141769409,,1,0,0,0,0.013885498046875,32.7468223571777,2,1,1,138.864852905273,0,2084574176,138.073011699476,,,0.0144579421579568,0.000723284341314724,0.0144863381585327,0.000723297660971798,0.92228364944458,0.95343405008316,33.6656188964844,,35,4,200,9.61644109338522E-5,-4.8703875541687,4.85242938995361,1,,,,,,,,,,,,,,,,
,3842850438.63817,149.731071472168,100.035980224609,,,6,,,,33.9356945382494,,,100,,,,,,,,,,,,,,,,,,,,,,148.896881103516,150.469665527344,100.035980224609,100.035980224609,,,7.10643672943115,,1,0,0,0,0.013885498046875,32.2580642700195,2,1,1,150.56526184082,0,2084574528,149.66241053531,,,0.0144007696156116,0.000720245924737701,0.0144253146957283,0.000720260657823203,0.925513207912445,0.95313560962677,33.7168655395508,1.77503607119434E-5,35,4,200,0.0001256960676983,-4.84596920013428,4.84040069580078,1,,,,,,,,,,,,,,,,
,3842850578.6098,161.308815002441,100.035980224609,,,6,,,,33.9735040585283,,,100,,,,,,,,,,,,,,,,,,,,,,160.486282348633,162.098876953125,100.035980224609,100.035980224609,,,7.13166761398315,,1,0,0,0,0.013885498046875,31.7693061828613,2,1,1,162.13134765625,0,2084574336,161.31191133198,,,0.0142784892394845,0.000713989787943842,0.0142997520635125,0.000714000379894105,0.928185701370239,0.952864587306976,33.7687606811523,INF,35,4,200,0.000123735895613208,-4.79805326461792,4.83129453659058,1,,,,,,,,,,,,,,,,
,3842850718.65714,172.972030639648,100.035980224609,,,6,,,,34.0140262545119,,,100,,,,,,,,,,,,,,,,,,,,,,172.216995239258,173.701644897461,100.035980224609,100.035980224609,,,7.15488958358765,,1,0,0,0,0.013885498046875,31.7693061828613,2,1,1,173.727066040039,0,2084574464,172.949427554482,,,0.0141006853563167,0.000704985274225175,0.0141192404810797,0.00070499833379473,0.930453479290009,0.952535450458527,33.8219604492188,1.66964146046666E-5,35,4,200,0.00012118746235501,-4.8706521987915,4.81643104553223,1,,,,,,,,,,,,,,,,
,3842850858.84699,184.595336914062,100.035980224609,,,6,,,,34.0575960885256,,,100,,,,,,,,,,,,,,,,,,,,,,183.805633544922,185.301940917969,100.035980224609,100.035980224609,,,7.17753982543945,,1,0,0,0,0.013885498046875,32.2580642700195,2,1,1,185.385040283203,0,2084574400,184.552421168277,,,0.0138701736980364,0.000693363217428953,0.0138864993609389,0.000693372377060265,0.932491660118103,0.952681720256805,33.8756828308105,0.000453361892141402,35,4,200,0.000106939405668527,-4.79347944259644,4.7951602935791,1,,,,,,,,,,,,,,,,
,3842850998.69907,196.20174407959,100.035980224609,,,6,,,,34.1037331631082,,,100,,,,,,,,,,,,,,,,,,,,,,195.399520874023,196.9130859375,100.035980224609,100.035980224609,,,7.19926452636719,,1,0,0,0,0.013885498046875,31.7693061828613,2,1,1,197.003967285156,0,2084574400,196.173725328947,,,0.0136129951174306,0.000680427079364587,0.0136273666548189,0.000680434719278695,0.934239327907562,0.952634990215302,33.9313850402832,1,35,4,200,0.000103317346656695,-4.83675050735474,4.79039764404297,1,,,,,,,,,,,,,,,,
,3842851138.27892,207.79280090332,100.035980224609,,,6,,,,34.1528667924961,,,100,,,,,,,,,,,,,,,,,,,,,,207.001358032227,208.504547119141,100.035980224609,100.035980224609,,,7.22154521942139,,1,0,0,0,0.013885498046875,32.2580642700195,2,1,1,208.584243774414,0,2084574336,207.753483822471,,,0.0133325868990598,0.000666344780149311,0.0133452588002399,0.000666349301769673,0.935773551464081,0.952622473239899,33.9890403747559,,35,4,200,9.70491601037793E-5,-4.85400056838989,4.81409502029419,1,,,,,,,,,,,,,,,,
,3842851277.79303,219.394592285156,100.035980224609,,,6,,,,34.2046555472505,,,100,,,,,,,,,,,,,,,,,,,,,,218.603881835938,220.134170532227,100.035980224609,100.035980224609,,,7.24548530578613,,1,0,0,0,0.013885498046875,31.7693061828613,2,1,1,220.185302734375,0,2084574560,219.35717291581,,,0.0130380187292732,0.000651567463736238,0.0130492944963444,0.000651572634846461,0.937101244926453,0.952581465244293,34.0485610961914,5.83511447906494,35,4,200,9.24284759094007E-5,-4.85510730743408,4.80289793014526,1,,,,,,,,,,,,,,,,
,3842851417.37758,230.984802246094,100.035980224609,,,6,,,,34.2592647132556,,,100,,,,,,,,,,,,,,,,,,,,,,230.210327148438,231.709259033203,100.035980224609,100.035980224609,,,7.27912092208862,,1,0,0,0,0.013885498046875,31.7693061828613,2,1,1,231.75927734375,0,2084574400,230.953078420539,,,0.0127292646190697,0.000636084333265605,0.0127393012034679,0.000636091102423175,0.938442349433899,0.952681839466095,34.1105270385742,0,35,4,200,6.44934480078518E-5,-4.91115617752075,4.78026485443115,1,,,,,,,,,,,,,,,,
,3842851533.80562,240.646957397461,100.035980224609,,,6,,,,34.3088844600584,,,10,,,,,,,,,,,,,,,,,,,,,,240.264892578125,241.013687133789,100.035980224609,100.035980224609,,,7.32548999786377,,1,0,0,0,0.013885498046875,31.7693061828613,2,1,1,241.029022216797,0,2084574304,240.636320495605,,,0.012474424041424,0.000623330499862043,0.0124838493216917,0.000623334098144685,0.938953459262848,0.952754616737366,34.1628456115723,0,35,4,200,0.000588488532230258,-4.90454769134521,1.22681987285614,1,,,,,,,,,,,,,,,,
,3842851625.79912,248.27912902832,100.035980224609,,,6,,,,34.3478032185153,,,10,,,,,,,,,,,,,,,,,,,,,,247.875091552734,248.635391235352,100.035980224609,100.035980224609,,,7.3921160697937,,1,0,0,0,0.013885498046875,31.7693061828613,2,1,1,248.683166503906,0,2084574240,248.266030883789,,,0.0122747939576209,0.000613320708133802,0.0122834715991321,0.00061332804608122,0.939872980117798,0.952778697013855,34.2071876525879,0.243540838360786,35,4,200,0.000856285507325083,-4.83270692825317,1.19965362548828,1,,,,,,,,,,,,,,,,
,3842851717.6249,255.91024017334,100.035980224609,,,6,,,,34.3884043718066,,,10,,,,,,,,,,,,,,,,,,,,,,255.516677856445,256.303802490234,100.035980224609,100.035980224609,,,7.48647117614746,,1,0,0,0,0.013885498046875,31.7693061828613,2,1,1,256.303802490234,0,2084574272,255.911735534668,,,0.0120611809801681,0.000602614843534851,0.0120690222291556,0.000602618342455033,0.940779387950897,0.952855944633484,34.2530059814453,0,35,4,200,0.000826047675218433,-4.75710344314575,1.17078590393066,1,,,,,,,,,,,,,,,,
,3842851809.58476,263.562423706055,100.035980224609,,,6,,,,34.4297890471294,,,10,,,,,,,,,,,,,,,,,,,,,,263.176422119141,263.930541992187,100.035980224609,100.035980224609,,,7.461181640625,,1,0,0,0,0.013885498046875,31.7693061828613,2,1,1,263.948425292969,0,2084574208,263.552481079102,,,0.0118513614866688,0.000592092806747269,0.0118582665068278,0.00059209447066599,0.941883981227875,0.952868163585663,34.3013496398926,,35,4,200,0.000563417968805879,-4.68218612670898,1.14219069480896,1,,,,,,,,,,,,,,,,
,3842851901.53445,271.198120117187,100.035980224609,,,6,,,,34.4726737102777,,,10,,,,,,,,,,,,,,,,,,,,,,270.788238525391,271.542633056641,100.035980224609,100.035980224609,,,7.45198345184326,,1,0,0,0,0.013885498046875,31.7693061828613,2,1,1,271.608001708984,0,2084574272,271.168878173828,,,0.0116465869988115,0.000581813212799301,0.0116523903829074,0.000581815711409132,0.943349123001099,0.952837944030762,34.3541259765625,0,35,4,200,0.000839611864648759,-4.60865020751953,1.11436998844147,1,,,,,,,,,,,,,,,,
,3842851993.7566,278.838653564453,100.035980224609,,,6,,,,34.5167837255716,,,10,,,,,,,,,,,,,,,,,,,,,,278.443603515625,279.169219970703,100.035980224609,100.035980224609,,,7.456214427948,,1,0,0,0,0.013885498046875,32.2580642700195,2,1,1,279.233703613281,0,2084574560,278.815097045898,,,0.0114472524076439,0.000571782551456427,0.0114514579641268,0.000571782634732205,0.945638358592987,0.952854037284851,34.4145622253418,4.13461017608643,35,4,200,0.000810098019428551,-4.53706693649292,1.08709359169006,1,,,,,,,,,,,,,,,,
,3842852085.81418,286.482955932617,100.035980224609,,,6,,,,34.5620889031376,,,10,,,,,,,,,,,,,,,,,,,,,,286.081604003906,286.840057373047,100.035980224609,100.035980224609,,,7.47903490066528,,1,0,0,0,0.013885498046875,31.7693061828613,2,1,1,286.884307861328,0,2084574368,286.462789916992,,,0.0112193815225557,0.000560305041711921,0.011221753183605,0.000560306109749015,0.948865115642548,0.953129351139069,34.4848785400391,0.782111644744873,35,4,200,0.000788824865594506,-4.45550346374512,1.05593681335449,1,,,,,,,,,,,,,,,,
,3842852177.77067,294.148239135742,100.035980224609,,,6,,,,34.6085453572201,,,10,,,,,,,,,,,,,,,,,,,,,,293.754028320313,294.509704589844,100.035980224609,100.035980224609,,,7.56025457382202,,1,0,0,0,0.013885498046875,31.2805480957031,2,1,1,294.542449951172,0,2084574528,294.135842895508,,,0.011005222787196,0.000549523690798463,0.0110060597550751,0.000549523204193359,0.952019989490509,0.953647494316101,34.5617408752441,0,35,4,200,0.000780922593548894,-4.37742280960083,1.02599692344666,1,,,,,,,,,,,,,,,,
,3842852260.82876,299.550003051758,100.035980224609,,,6,,,,34.6423689794433,,,10,,,,,,,,,,,,,,,,,,,,,,299.478515625,299.616455078125,100.035980224609,100.035980224609,,,7.69862747192383,,1,0,0,0,0.013885498046875,31.7693061828613,6,1,1,299.621490478516,0,2084574304,299.553604125977,,,0.0108452555627927,0.000541491928490749,0.0108455826123232,0.000541491742773182,0.95373672246933,0.954399347305298,34.6128883361816,0,35,4,200,0.000824305403511971,-4.31772994995117,1.00221729278564,1,,,,,,,,,,,,,,,,
,3842852309.46972,299.891815185547,100.035980224609,,,6,,,,34.6423689794433,,,10,,,,,,,,,,,,,,,,,,,,,,299.877960205078,299.904205322266,100.035980224609,100.035980224609,,,7.80267715454102,,1,0,0,0,0.013885498046875,32.2580642700195,5,1,1,299.905670166016,0,2084574304,299.89348449707,,,0.0108305857110202,0.000540751011670382,0.0108308153526908,0.000540750702212106,0.954076409339905,0.954552054405212,34.6174621582031,0,35,4,200,0.000886402442120016,-4.31143951416016,0.999857902526855,1,,,,,,,,,,,,,,,,
,3842852328.96632,299.934616088867,100.035980224609,,,6,,,,34.6423689794433,,,10,,,,,,,,,,,,,,,,,,,,,,299.927093505859,299.941345214844,100.035980224609,100.035980224609,,,7.84771871566772,,1,0,0,0,0.013885498046875,31.7693061828613,1,1,1,299.942138671875,0,2084574368,299.936273193359,,,0.0108289561426407,0.000540667309860211,0.0108291581915058,0.000540667097022237,0.954168617725372,0.954585373401642,34.619068145752,2.57841984421248E-5,35,4,200,0.000926508626434952,-4.31070804595947,0.999689877033234,1,,,,,,,,,,,,,,,,