File: Data/KMK249/TGA/KMK249_1000C_Air.txt
Filename	KMK249_1000C_Air
Instrument name	0650-0588 (172.23.191.35)
Operator	Kyle Kirkpatrick
rundate	1/18/2023
Sample name	KMK249_1000C_Air
proceduresegments	Blend Channel B (Air) at 100% with Channel A (N2); Equilibrate 30.00 °C; Ramp 10.00 °C/min to 1000.00 °C
[File Parameters]
Run date	1/18/2023 2:41:50 PM
Trios version	5.5.1.5
Original File Name
Current File Name	C:\Users\ucsdi\OneDrive\Desktop\Data\Rinehart\Kyle\Jan 18 2023\KMK249_1000C_Air.tri
User at run start	DESKTOP-JSQIMO4\ucsdi
[Procedure]
Procedure Name
Sample Name	KMK249_1000C_Air
Sample Mass	4.829638 mg
Pan Number	6
Reference Pan Number	30
Pan Type	Alumina 90 ul
Comments
Project Name
Operator	Kyle Kirkpatrick
Skip Weight Stabilization	False
Enable Air Cool	True
Air Cool Until Temperature Is Below	50
End of Test Delay	0
Stop on Gas Flow Error	No
Sample mass pre-weigh	Not Available
[Signal List]
Signal #1	Time (min)
Signal #2	Temperature (°C)
Signal #3	Sample Flow (mL/min)
Signal #4	Balance Flow (mL/min)
Signal #5	Set Point (°C)
Signal #6	Power Requested (W)
Signal #7	Power Delivered (W)
Signal #8	Temperature Rate (°C/min)
Signal #9	Weight (mg)
Signal #10	Heat Flow (mW)
Signal #11	Weight Corrected Heat Flow (W/g)
Signal #12	Weight Change (%)
Signal #13	Temperature Difference (°C)
Signal #14	Channel A Flow (mL/min)
Signal #15	Channel A Flow (%)
Signal #16	Channel B Flow (mL/min)
Signal #17	Channel B Flow (%)
[Configuration]
Company Name
Instrument Name	0650-0588
Instrument Type	SDT650
Serial Number	0650-0588
IP	172.23.191.35
Location of Instrument	MFG
DisplayType	TianmaV2andV3
Sample Interval 	0.1 s/pt
Gas 1	Nitrogen
Gas 2	Air
Gas 3	Oxygen
Gas 4	Nitrogen
Total Sample Flow	100
Channel B	0%
Channel A Gas Selected	1
Channel B Gas Selected	4
Thermocouple Type	Type R
Exotherm Direction	Up
Sampling Mode	Single Sample Mode
[Versions]
Common IDD Version	1
Cortex Version	VER 1.3.3.11
Driver	5.0.0.7
GDM Version	1.2.1.2
Blending GDM Version	1.2.1.2
Blending GDM Bootloader	2.0.0.5
TouchscreenVersion	1.0.3.1817
Transducer Version	1.1.0.32
Transducer Bootloader	2.0.0.5
PCU Version	1.2.0.15
PCU Bootloader	2.0.0.5
AutoSampler Version	2.0.4.19
Auto Sampler Bootloader	2.0.0.5
[Experiment Logs]
Experiment Log Entry # 1	Blending segment primary gas 4, percent 0, secondary gas 2
Experiment Log Entry # 3	Equilibrate Segment 30 (C) Started
Experiment Log Entry # 5	Ramp Segment 10 C/min to 1000 C Started
[Method Log]
Method Log Entry # 1	Blend Channel B at 100% with Channel A
Method Log Entry # 2	Equilibrate 30 °C
Method Log Entry # 3	(Ramp 628393) Ramp 10 °C/minute to 1000 °C
[Room Temperature Calibration]
Date Applied	2/24/2021 3:27:30 AM
Measured	22.351
Correct	22.200
[Furnace Room Temperature Calibration]
Date Applied	2/24/2021 3:27:30 AM
Measured	24.159
Correct	22.200
[DTA Signal Setup]
Date Applied	1/11/2023 5:48:48 PM
Description	From 200.000 °C to 1,450.000 °C at 20.000°C/min
Source Files 1	C:\Users\ucsdi\OneDrive\Desktop\Data\Sailor\Ricardo\Calibrations\1-11-23\Weight Calibration.tri
[Weight Calibration]
Date Applied	1/11/2023 5:48:48 PM
Reference Beam Weight	4892.573
Reference Beam Weight at 200 °C	435.1747
Reference Beam Gain	0.09938934
Sample Beam Weight	5794.918
Sample Beam Weight at 200 °C	439.0667
Sample Beam Gain	0.09625536
Weight Ratio	0.9274598
Reference Weight	341.1444
Sample Weight	336.5152
[Heat Flow Calibration]
Date Applied	1/12/2023 4:18:26 AM
Description	From 100.000 °C to 1,450.000 °C at 20.000°C/min
Source Files 1	C:\Users\ucsdi\OneDrive\Desktop\Data\Sailor\Ricardo\Calibrations\1-11-23\Heat Flow Sapphire Calibration(1).tri
Source Files 2	C:\Users\ucsdi\OneDrive\Desktop\Data\Sailor\Ricardo\Calibrations\1-11-23\Heat Flow Sapphire Calibration.tri
[Temperature Calibration]
Date Applied	1/11/2023 9:24:14 PM
Description	From 107.000 °C to 227.000 °C at 10.000°C/min
Gas Type	Nitrogen
Pan Type	Alumina 90 ul
Source Files 1	C:\Users\ucsdi\OneDrive\Desktop\Data\Sailor\Ricardo\Calibrations\1-11-23\Indium.tri
Source Files 2	C:\Users\ucsdi\OneDrive\Desktop\Data\Sailor\Ricardo\Calibrations\1-11-23\Zinc.tri
Source Files 3	C:\Users\ucsdi\OneDrive\Desktop\Data\Sailor\Ricardo\Calibrations\1-11-23\Tin.tri
Measured 1	155.275
Known 1	156.6
Measured 2	230.5534
Known 2	231.93
Measured 3	418.0948
Known 3	419.53
[Dual Weight]
Date Applied	1/12/2023 4:18:26 AM
[Dual DeltaT]
Date Applied	1/12/2023 4:18:26 AM
[Cell Constant Calibration]
Date Applied	4/21/2022 4:38:29 AM
Description	From 370.000 °C to 480.000 °C at 10.000°C/min
Gas Type	Nitrogen
Pan Type	Alumina 90 ul
Source Files 1	C:\Users\ucsdi\OneDrive\Desktop\Sailor\Ricardo\Calibrations\Zinc(2).tri
Cell Constant	1.029587
Temperature	419.53
[Rev Cp Calibration]
Date Applied	1/12/2023 5:11:31 PM
Description	From 210.000 °C to 1,500.000 °C at 2.000°C/min
Gas Type	Nitrogen
Pan Type	Alumina 90 ul
Source Files 1	C:\Users\ucsdi\OneDrive\Desktop\Data\Sailor\Ricardo\Calibrations\1-11-23\Sappphire calibration.tri
[step]
Ramp 10.00 °C/min to 1000.00 °C
Time	Temperature	Heat Flow (Normalized)	Weight	Heat Flow	Weight
min	°C	W/g	%	mW	mg
0.00			99.365		4.799
0.08	31.02	1.240	99.365	5.987	4.799
0.15	31.01	1.239	99.365	5.984	4.799
0.23	31.00	1.239	99.366	5.982	4.799
0.31	31.01	1.237	99.368	5.975	4.799
0.38	31.05	1.230	99.373	5.939	4.799
0.46	31.16	1.211	99.381	5.847	4.800
0.54	31.35	1.182	99.391	5.707	4.800
0.61	31.61	1.147	99.401	5.538	4.801
0.69	31.96	1.109	99.411	5.354	4.801
0.77	32.39	1.064	99.420	5.139	4.802
0.84	32.90	1.018	99.429	4.915	4.802
0.92	33.49	0.972	99.436	4.696	4.802
1.00	34.14	0.928	99.442	4.481	4.803
1.07	34.85	0.887	99.447	4.285	4.803
1.15	35.61	0.848	99.450	4.098	4.803
1.23	36.41	0.814	99.453	3.933	4.803
1.30	37.24	0.786	99.456	3.795	4.803
1.38	38.10	0.763	99.457	3.685	4.803
1.46	38.98	0.744	99.458	3.593	4.803
1.53	39.86	0.729	99.459	3.523	4.804
1.61	40.75	0.719	99.459	3.472	4.804
1.69	41.64	0.713	99.459	3.443	4.804
1.76	42.52	0.707	99.458	3.416	4.803
1.84	43.39	0.705	99.457	3.405	4.803
1.92	44.25	0.704	99.455	3.402	4.803
1.99	45.09	0.705	99.453	3.405	4.803
2.07	45.92	0.708	99.451	3.420	4.803
2.15	46.73	0.716	99.449	3.459	4.803
2.22	47.53	0.724	99.447	3.497	4.803
2.30	48.32	0.734	99.445	3.547	4.803
2.38	49.09	0.749	99.443	3.618	4.803
2.45	49.86	0.763	99.442	3.686	4.803
2.53	50.61	0.777	99.440	3.753	4.803
2.61	51.35	0.794	99.438	3.832	4.803
2.68	52.09	0.808	99.437	3.902	4.802
2.76	52.82	0.824	99.435	3.978	4.802
2.84	53.54	0.840	99.433	4.056	4.802
2.91	54.27	0.855	99.431	4.128	4.802
2.99	54.99	0.871	99.429	4.208	4.802
3.07	55.72	0.888	99.427	4.288	4.802
3.14	56.44	0.904	99.425	4.365	4.802
3.22	57.16	0.918	99.423	4.434	4.802
3.30	57.89	0.934	99.421	4.512	4.802
3.37	58.62	0.951	99.418	4.594	4.802
3.45	59.36	0.966	99.416	4.667	4.801
3.53	60.10	0.980	99.414	4.731	4.801
3.60	60.84	0.996	99.411	4.809	4.801
3.68	61.59	1.011	99.409	4.881	4.801
3.76	62.34	1.025	99.406	4.951	4.801
3.83	63.09	1.041	99.402	5.029	4.801
3.91	63.85	1.055	99.399	5.097	4.801
3.99	64.61	1.070	99.396	5.169	4.800
4.06	65.37	1.084	99.393	5.235	4.800
4.14	66.14	1.098	99.389	5.304	4.800
4.22	66.90	1.111	99.386	5.365	4.800
4.29	67.67	1.126	99.382	5.438	4.800
4.37	68.44	1.140	99.378	5.504	4.800
4.45	69.21	1.154	99.375	5.575	4.799
4.52	69.98	1.169	99.371	5.644	4.799
4.60	70.75	1.184	99.367	5.716	4.799
4.68	71.52	1.198	99.363	5.786	4.799
4.75	72.29	1.213	99.359	5.858	4.799
4.83	73.07	1.226	99.354	5.922	4.798
4.91	73.84	1.240	99.350	5.990	4.798
4.98	74.61	1.256	99.345	6.065	4.798
5.06	75.38	1.271	99.340	6.139	4.798
5.14	76.14	1.285	99.335	6.205	4.798
5.21	76.91	1.300	99.330	6.278	4.797
5.29	77.68	1.315	99.325	6.350	4.797
5.37	78.45	1.329	99.319	6.420	4.797
5.44	79.21	1.344	99.314	6.490	4.797
5.52	79.98	1.360	99.308	6.568	4.796
5.60	80.74	1.372	99.303	6.625	4.796
5.67	81.51	1.387	99.297	6.699	4.796
5.75	82.27	1.404	99.291	6.781	4.795
5.83	83.04	1.419	99.286	6.852	4.795
5.90	83.80	1.433	99.280	6.922	4.795
5.98	84.56	1.448	99.273	6.992	4.795
6.06	85.33	1.463	99.267	7.067	4.794
6.13	86.09	1.479	99.261	7.144	4.794
6.21	86.86	1.496	99.255	7.224	4.794
6.29	87.62	1.510	99.249	7.294	4.793
6.36	88.39	1.525	99.243	7.364	4.793
6.44	89.15	1.541	99.237	7.444	4.793
6.52	89.92	1.557	99.230	7.520	4.792
6.59	90.68	1.572	99.224	7.592	4.792
6.67	91.45	1.587	99.218	7.663	4.792
6.75	92.22	1.602	99.212	7.739	4.792
6.82	92.98	1.618	99.206	7.817	4.791
6.90	93.75	1.634	99.199	7.892	4.791
6.98	94.52	1.650	99.194	7.969	4.791
7.05	95.29	1.666	99.187	8.045	4.790
7.13	96.05	1.683	99.181	8.130	4.790
7.21	96.82	1.699	99.175	8.207	4.790
7.28	97.59	1.715	99.169	8.281	4.790
7.36	98.36	1.732	99.163	8.363	4.789
7.44	99.12	1.748	99.157	8.440	4.789
7.51	99.89	1.764	99.151	8.520	4.789
7.59	100.66	1.780	99.145	8.596	4.788
7.67	101.43	1.797	99.139	8.678	4.788
7.74	102.20	1.814	99.133	8.762	4.788
7.82	102.97	1.831	99.128	8.843	4.788
7.90	103.74	1.847	99.122	8.922	4.787
7.97	104.51	1.863	99.116	8.998	4.787
8.05	105.27	1.881	99.110	9.085	4.787
8.13	106.04	1.896	99.105	9.159	4.786
8.20	106.81	1.915	99.099	9.248	4.786
8.28	107.58	1.932	99.094	9.330	4.786
8.36	108.35	1.951	99.089	9.421	4.786
8.43	109.12	1.966	99.083	9.496	4.785
8.51	109.89	1.983	99.077	9.577	4.785
8.59	110.66	2.001	99.072	9.663	4.785
8.66	111.43	2.018	99.068	9.744	4.785
8.74	112.20	2.036	99.063	9.832	4.784
8.82	112.96	2.053	99.059	9.915	4.784
8.89	113.73	2.072	99.055	10.007	4.784
8.97	114.50	2.089	99.050	10.090	4.784
9.05	115.27	2.106	99.045	10.170	4.784
9.12	116.04	2.122	99.040	10.251	4.783
9.20	116.81	2.142	99.035	10.343	4.783
9.28	117.57	2.158	99.030	10.424	4.783
9.35	118.34	2.177	99.025	10.513	4.783
9.43	119.11	2.196	99.020	10.605	4.782
9.51	119.88	2.212	99.016	10.683	4.782
9.58	120.65	2.231	99.011	10.776	4.782
9.66	121.42	2.250	99.006	10.865	4.782
9.74	122.19	2.268	99.002	10.954	4.781
9.81	122.96	2.287	98.997	11.047	4.781
9.89	123.73	2.306	98.993	11.137	4.781
9.97	124.50	2.324	98.988	11.224	4.781
10.04	125.26	2.342	98.983	11.311	4.781
10.12	126.03	2.361	98.979	11.402	4.780
10.20	126.80	2.380	98.974	11.495	4.780
10.27	127.57	2.399	98.970	11.585	4.780
10.35	128.34	2.418	98.966	11.679	4.780
10.43	129.11	2.438	98.962	11.773	4.780
10.50	129.88	2.456	98.958	11.863	4.779
10.58	130.65	2.476	98.954	11.960	4.779
10.66	131.41	2.495	98.950	12.048	4.779
10.73	132.18	2.514	98.946	12.142	4.779
10.81	132.95	2.533	98.942	12.235	4.779
10.89	133.72	2.551	98.938	12.322	4.778
10.96	134.49	2.571	98.934	12.419	4.778
11.04	135.26	2.591	98.931	12.513	4.778
11.12	136.03	2.611	98.927	12.608	4.778
11.19	136.80	2.630	98.923	12.704	4.778
11.27	137.57	2.651	98.919	12.804	4.777
11.35	138.34	2.671	98.915	12.902	4.777
11.42	139.10	2.691	98.911	12.998	4.777
11.50	139.87	2.712	98.907	13.096	4.777
11.58	140.64	2.733	98.903	13.197	4.777
11.65	141.41	2.752	98.900	13.292	4.777
11.73	142.18	2.772	98.896	13.386	4.776
11.81	142.95	2.792	98.893	13.484	4.776
11.88	143.72	2.813	98.890	13.586	4.776
11.96	144.49	2.834	98.887	13.685	4.776
12.04	145.25	2.854	98.883	13.784	4.776
12.11	146.02	2.876	98.881	13.890	4.776
12.19	146.79	2.895	98.877	13.982	4.775
12.27	147.56	2.915	98.874	14.080	4.775
12.34	148.33	2.936	98.871	14.181	4.775
12.42	149.10	2.957	98.867	14.283	4.775
12.50	149.87	2.977	98.863	14.380	4.775
12.57	150.64	2.999	98.859	14.482	4.775
12.65	151.40	3.018	98.855	14.575	4.774
12.73	152.17	3.040	98.851	14.682	4.774
12.80	152.94	3.061	98.848	14.783	4.774
12.88	153.71	3.084	98.845	14.897	4.774
12.96	154.48	3.105	98.842	14.994	4.774
13.03	155.25	3.126	98.839	15.097	4.774
13.11	156.02	3.148	98.836	15.202	4.773
13.19	156.79	3.169	98.833	15.307	4.773
13.26	157.56	3.191	98.831	15.412	4.773
13.34	158.32	3.214	98.828	15.520	4.773
13.42	159.09	3.235	98.825	15.624	4.773
13.49	159.86	3.257	98.822	15.729	4.773
13.57	160.63	3.280	98.819	15.840	4.773
13.65	161.40	3.304	98.816	15.957	4.772
13.72	162.17	3.326	98.813	16.065	4.772
13.80	162.94	3.349	98.811	16.176	4.772
13.88	163.71	3.372	98.809	16.286	4.772
13.95	164.48	3.395	98.806	16.396	4.772
14.03	165.24	3.419	98.804	16.513	4.772
14.11	166.01	3.443	98.802	16.629	4.772
14.18	166.78	3.467	98.799	16.744	4.772
14.26	167.55	3.491	98.797	16.860	4.772
14.34	168.32	3.515	98.794	16.975	4.771
14.41	169.09	3.540	98.792	17.096	4.771
14.49	169.86	3.565	98.789	17.216	4.771
14.57	170.63	3.590	98.786	17.337	4.771
14.64	171.40	3.614	98.784	17.456	4.771
14.72	172.17	3.640	98.781	17.578	4.771
14.80	172.94	3.665	98.779	17.702	4.771
14.87	173.71	3.689	98.777	17.816	4.771
14.95	174.48	3.715	98.774	17.944	4.770
15.03	175.24	3.740	98.772	18.064	4.770
15.10	176.01	3.767	98.769	18.192	4.770
15.18	176.78	3.793	98.766	18.317	4.770
15.26	177.55	3.819	98.764	18.447	4.770
15.33	178.32	3.846	98.761	18.574	4.770
15.41	179.09	3.873	98.759	18.706	4.770
15.49	179.86	3.901	98.756	18.841	4.770
15.56	180.63	3.928	98.753	18.973	4.769
15.64	181.40	3.955	98.750	19.102	4.769
15.72	182.17	3.983	98.747	19.235	4.769
15.79	182.94	4.010	98.744	19.366	4.769
15.87	183.71	4.038	98.741	19.501	4.769
15.95	184.48	4.065	98.738	19.631	4.769
16.02	185.26	4.093	98.735	19.770	4.769
16.10	186.02	4.122	98.732	19.909	4.768
16.18	186.79	4.150	98.729	20.045	4.768
16.25	187.56	4.179	98.726	20.182	4.768
16.33	188.34	4.209	98.723	20.326	4.768
16.41	189.11	4.238	98.720	20.466	4.768
16.48	189.88	4.267	98.716	20.609	4.768
16.56	190.65	4.296	98.712	20.747	4.767
16.64	191.42	4.328	98.709	20.903	4.767
16.71	192.19	4.357	98.705	21.042	4.767
16.79	192.96	4.388	98.701	21.190	4.767
16.87	193.73	4.418	98.697	21.338	4.767
16.94	194.50	4.449	98.693	21.488	4.767
17.02	195.27	4.480	98.688	21.637	4.766
17.10	196.05	4.511	98.684	21.789	4.766
17.17	196.82	4.544	98.680	21.944	4.766
17.25	197.59	4.575	98.675	22.098	4.766
17.33	198.36	4.608	98.670	22.257	4.765
17.40	199.13	4.641	98.665	22.414	4.765
17.48	199.90	4.675	98.660	22.579	4.765
17.56	200.68	4.709	98.654	22.741	4.765
17.63	201.45	4.742	98.649	22.901	4.764
17.71	202.22	4.776	98.643	23.068	4.764
17.79	202.99	4.810	98.637	23.232	4.764
17.86	203.77	4.846	98.630	23.403	4.763
17.94	204.54	4.880	98.623	23.570	4.763
18.02	205.31	4.915	98.616	23.738	4.763
18.09	206.09	4.952	98.609	23.917	4.762
18.17	206.86	4.988	98.601	24.091	4.762
18.25	207.63	5.024	98.593	24.266	4.762
18.32	208.41	5.062	98.584	24.447	4.761
18.40	209.18	5.101	98.575	24.634	4.761
18.48	209.96	5.139	98.566	24.818	4.760
18.55	210.73	5.179	98.557	25.011	4.760
18.63	211.51	5.218	98.547	25.201	4.759
18.71	212.28	5.258	98.537	25.393	4.759
18.78	213.06	5.298	98.526	25.589	4.758
18.86	213.83	5.340	98.515	25.792	4.758
18.94	214.61	5.382	98.503	25.991	4.757
19.01	215.38	5.425	98.491	26.199	4.757
19.09	216.16	5.469	98.479	26.414	4.756
19.17	216.94	5.513	98.466	26.627	4.756
19.24	217.71	5.557	98.454	26.840	4.755
19.32	218.49	5.604	98.440	27.065	4.754
19.40	219.27	5.649	98.426	27.285	4.754
19.47	220.05	5.697	98.412	27.516	4.753
19.55	220.82	5.746	98.397	27.753	4.752
19.63	221.60	5.794	98.382	27.984	4.751
19.70	222.38	5.844	98.366	28.224	4.751
19.78	223.16	5.895	98.350	28.471	4.750
19.86	223.93	5.946	98.333	28.719	4.749
19.93	224.71	6.000	98.315	28.976	4.748
20.01	225.49	6.054	98.297	29.236	4.747
20.09	226.27	6.108	98.278	29.500	4.746
20.16	227.05	6.165	98.258	29.774	4.746
20.24	227.83	6.222	98.239	30.048	4.745
20.32	228.61	6.280	98.218	30.331	4.744
20.39	229.39	6.340	98.197	30.621	4.743
20.47	230.17	6.401	98.175	30.914	4.742
20.55	230.95	6.464	98.153	31.219	4.740
20.62	231.74	6.528	98.130	31.526	4.739
20.70	232.52	6.592	98.106	31.836	4.738
20.78	233.30	6.659	98.082	32.159	4.737
20.85	234.09	6.727	98.056	32.489	4.736
20.93	234.87	6.796	98.030	32.821	4.734
21.01	235.65	6.866	98.003	33.160	4.733
21.08	236.44	6.939	97.975	33.512	4.732
21.16	237.22	7.011	97.947	33.861	4.730
21.24	238.01	7.087	97.918	34.229	4.729
21.31	238.80	7.164	97.888	34.600	4.728
21.39	239.58	7.242	97.858	34.977	4.726
21.47	240.37	7.322	97.826	35.361	4.725
21.54	241.16	7.403	97.793	35.754	4.723
21.62	241.95	7.487	97.759	36.158	4.721
21.70	242.74	7.571	97.725	36.566	4.720
21.77	243.53	7.656	97.689	36.976	4.718
21.85	244.32	7.744	97.653	37.401	4.716
21.93	245.11	7.833	97.616	37.832	4.714
22.00	245.90	7.925	97.577	38.273	4.713
22.08	246.69	8.017	97.538	38.719	4.711
22.16	247.48	8.112	97.497	39.177	4.709
22.23	248.27	8.208	97.455	39.643	4.707
22.31	249.06	8.308	97.412	40.122	4.705
22.39	249.86	8.406	97.368	40.598	4.703
22.46	250.65	8.507	97.323	41.085	4.700
22.54	251.45	8.610	97.276	41.585	4.698
22.62	252.24	8.714	97.229	42.087	4.696
22.69	253.03	8.819	97.180	42.594	4.693
22.77	253.83	8.926	97.130	43.111	4.691
22.85	254.63	9.033	97.079	43.626	4.689
22.92	255.42	9.141	97.026	44.147	4.686
23.00	256.22	9.250	96.972	44.672	4.683
23.08	257.02	9.359	96.917	45.201	4.681
23.15	257.81	9.467	96.860	45.724	4.678
23.23	258.61	9.576	96.802	46.248	4.675
23.31	259.40	9.684	96.742	46.771	4.672
23.38	260.20	9.793	96.680	47.294	4.669
23.46	260.99	9.902	96.618	47.822	4.666
23.54	261.79	10.010	96.554	48.346	4.663
23.61	262.58	10.118	96.488	48.865	4.660
23.69	263.38	10.224	96.421	49.377	4.657
23.77	264.17	10.327	96.353	49.876	4.654
23.84	264.96	10.430	96.283	50.372	4.650
23.92	265.75	10.529	96.212	50.850	4.647
24.00	266.54	10.626	96.139	51.322	4.643
24.07	267.33	10.723	96.065	51.788	4.640
24.15	268.12	10.815	95.990	52.232	4.636
24.23	268.91	10.904	95.913	52.661	4.632
24.30	269.70	10.989	95.835	53.072	4.628
24.38	270.48	11.069	95.756	53.459	4.625
24.46	271.26	11.146	95.675	53.832	4.621
24.53	272.04	11.220	95.593	54.186	4.617
24.61	272.82	11.288	95.509	54.516	4.613
24.69	273.60	11.350	95.425	54.815	4.609
24.76	274.38	11.407	95.339	55.090	4.605
24.84	275.15	11.458	95.252	55.338	4.600
24.92	275.92	11.505	95.164	55.566	4.596
24.99	276.69	11.545	95.075	55.759	4.592
25.07	277.46	11.581	94.985	55.930	4.587
25.15	278.23	11.610	94.894	56.070	4.583
25.22	278.99	11.633	94.801	56.184	4.579
25.30	279.76	11.652	94.708	56.273	4.574
25.38	280.52	11.666	94.615	56.342	4.570
25.45	281.28	11.677	94.520	56.396	4.565
25.53	282.04	11.685	94.424	56.436	4.560
25.61	282.80	11.690	94.328	56.458	4.556
25.68	283.55	11.685	94.231	56.434	4.551
25.76	284.31	11.676	94.132	56.391	4.546
25.84	285.06	11.661	94.034	56.317	4.541
25.91	285.81	11.643	93.934	56.232	4.537
25.99	286.56	11.622	93.834	56.128	4.532
26.07	287.31	11.599	93.734	56.019	4.527
26.14	288.06	11.572	93.633	55.888	4.522
26.22	288.81	11.543	93.531	55.748	4.517
26.30	289.56	11.513	93.428	55.602	4.512
26.37	290.31	11.480	93.325	55.446	4.507
26.45	291.05	11.446	93.221	55.281	4.502
26.53	291.80	11.410	93.117	55.108	4.497
26.60	292.55	11.373	93.012	54.926	4.492
26.68	293.29	11.335	92.907	54.746	4.487
26.76	294.04	11.297	92.801	54.559	4.482
26.83	294.78	11.257	92.695	54.370	4.477
26.91	295.53	11.217	92.588	54.174	4.472
26.99	296.28	11.176	92.481	53.978	4.467
27.06	297.02	11.136	92.374	53.783	4.461
27.14	297.77	11.093	92.266	53.578	4.456
27.22	298.51	11.051	92.157	53.374	4.451
27.29	299.26	11.010	92.047	53.176	4.446
27.37	300.01	10.969	91.938	52.976	4.440
27.45	300.75	10.926	91.828	52.769	4.435
27.52	301.50	10.884	91.718	52.568	4.430
27.60	302.24	10.843	91.607	52.366	4.424
27.68	302.99	10.799	91.496	52.158	4.419
27.75	303.74	10.759	91.384	51.962	4.414
27.83	304.48	10.718	91.272	51.764	4.408
27.91	305.23	10.677	91.159	51.568	4.403
27.98	305.98	10.637	91.047	51.374	4.397
28.06	306.73	10.597	90.934	51.182	4.392
28.14	307.47	10.556	90.821	50.984	4.386
28.21	308.22	10.517	90.708	50.795	4.381
28.29	308.97	10.479	90.595	50.611	4.375
28.37	309.72	10.440	90.481	50.424	4.370
28.44	310.47	10.402	90.367	50.239	4.364
28.52	311.21	10.364	90.253	50.056	4.359
28.60	311.96	10.326	90.138	49.873	4.353
28.67	312.71	10.289	90.024	49.694	4.348
28.75	313.46	10.252	89.910	49.514	4.342
28.83	314.21	10.215	89.796	49.335	4.337
28.90	314.96	10.179	89.681	49.160	4.331
28.98	315.71	10.143	89.567	48.985	4.326
29.06	316.46	10.106	89.452	48.810	4.320
29.13	317.21	10.070	89.337	48.633	4.315
29.21	317.96	10.033	89.223	48.458	4.309
29.29	318.71	9.997	89.109	48.283	4.304
29.36	319.46	9.960	88.995	48.105	4.298
29.44	320.20	9.923	88.882	47.923	4.293
29.52	320.95	9.885	88.769	47.740	4.287
29.59	321.70	9.846	88.656	47.555	4.282
29.67	322.45	9.807	88.543	47.365	4.276
29.75	323.20	9.767	88.431	47.169	4.271
29.82	323.95	9.725	88.319	46.970	4.266
29.90	324.70	9.683	88.208	46.765	4.260
29.98	325.44	9.638	88.097	46.548	4.255
30.05	326.19	9.593	87.987	46.332	4.249
30.13	326.94	9.547	87.878	46.109	4.244
30.21	327.68	9.497	87.770	45.869	4.239
30.28	328.43	9.446	87.663	45.622	4.234
30.36	329.17	9.395	87.557	45.372	4.229
30.44	329.92	9.340	87.451	45.108	4.224
30.51	330.66	9.282	87.347	44.831	4.219
30.59	331.40	9.223	87.244	44.546	4.214
30.67	332.15	9.164	87.142	44.258	4.209
30.74	332.89	9.100	87.041	43.951	4.204
30.82	333.63	9.033	86.941	43.628	4.199
30.90	334.37	8.965	86.843	43.300	4.194
30.97	335.11	8.896	86.747	42.963	4.190
31.05	335.85	8.824	86.652	42.618	4.185
31.13	336.59	8.749	86.558	42.253	4.180
31.20	337.32	8.673	86.466	41.889	4.176
31.28	338.06	8.597	86.376	41.521	4.172
31.36	338.80	8.518	86.289	41.141	4.167
31.43	339.54	8.438	86.202	40.754	4.163
31.51	340.27	8.356	86.118	40.358	4.159
31.59	341.01	8.275	86.035	39.964	4.155
31.66	341.75	8.191	85.954	39.559	4.151
31.74	342.48	8.107	85.874	39.154	4.147
31.82	343.22	8.023	85.797	38.747	4.144
31.89	343.95	7.938	85.722	38.337	4.140
31.97	344.69	7.853	85.648	37.926	4.136
32.05	345.43	7.769	85.576	37.520	4.133
32.12	346.17	7.684	85.506	37.110	4.130
32.20	346.90	7.601	85.437	36.709	4.126
32.28	347.64	7.516	85.371	36.301	4.123
32.35	348.38	7.431	85.306	35.890	4.120
32.43	349.12	7.349	85.243	35.492	4.117
32.51	349.85	7.266	85.182	35.090	4.114
32.58	350.59	7.183	85.122	34.690	4.111
32.66	351.33	7.100	85.064	34.290	4.108
32.74	352.07	7.016	85.007	33.887	4.106
32.81	352.80	6.931	84.952	33.474	4.103
32.89	353.54	6.849	84.899	33.078	4.100
32.97	354.28	6.764	84.848	32.670	4.098
33.04	355.02	6.681	84.798	32.267	4.095
33.12	355.75	6.596	84.750	31.854	4.093
33.20	356.49	6.510	84.704	31.439	4.091
33.27	357.23	6.421	84.660	31.011	4.089
33.35	357.96	6.333	84.617	30.586	4.087
33.43	358.70	6.244	84.576	30.156	4.085
33.50	359.43	6.155	84.537	29.727	4.083
33.58	360.17	6.065	84.499	29.290	4.081
33.66	360.91	5.973	84.464	28.848	4.079
33.73	361.64	5.882	84.430	28.408	4.078
33.81	362.38	5.792	84.398	27.972	4.076
33.89	363.11	5.701	84.368	27.532	4.075
33.96	363.85	5.611	84.340	27.098	4.073
34.04	364.59	5.522	84.313	26.668	4.072
34.12	365.33	5.435	84.289	26.250	4.071
34.19	366.06	5.350	84.266	25.840	4.070
34.27	366.81	5.268	84.244	25.444	4.069
34.35	367.55	5.188	84.224	25.058	4.068
34.42	368.29	5.112	84.206	24.691	4.067
34.50	369.03	5.040	84.189	24.343	4.066
34.58	369.77	4.973	84.173	24.017	4.065
34.65	370.52	4.908	84.158	23.703	4.065
34.73	371.27	4.847	84.144	23.408	4.064
34.81	372.01	4.791	84.131	23.137	4.063
34.88	372.76	4.738	84.119	22.883	4.063
34.96	373.51	4.688	84.107	22.641	4.062
35.04	374.26	4.641	84.095	22.414	4.062
35.11	375.01	4.598	84.085	22.206	4.061
35.19	375.77	4.556	84.075	22.003	4.060
35.27	376.52	4.518	84.065	21.822	4.060
35.34	377.27	4.482	84.056	21.645	4.060
35.42	378.03	4.447	84.047	21.478	4.059
35.50	378.78	4.415	84.038	21.325	4.059
35.57	379.53	4.386	84.031	21.184	4.058
35.65	380.29	4.357	84.023	21.043	4.058
35.73	381.04	4.330	84.016	20.911	4.058
35.80	381.80	4.303	84.009	20.783	4.057
35.88	382.56	4.279	84.002	20.664	4.057
35.96	383.32	4.255	83.996	20.549	4.057
36.03	384.07	4.233	83.990	20.445	4.056
36.11	384.83	4.212	83.983	20.344	4.056
36.19	385.59	4.190	83.978	20.236	4.056
36.26	386.35	4.173	83.972	20.152	4.056
36.34	387.11	4.153	83.967	20.056	4.055
36.42	387.87	4.134	83.962	19.966	4.055
36.49	388.62	4.117	83.957	19.884	4.055
36.57	389.38	4.100	83.953	19.804	4.055
36.65	390.14	4.084	83.948	19.725	4.054
36.72	390.90	4.069	83.943	19.653	4.054
36.80	391.66	4.055	83.939	19.584	4.054
36.88	392.42	4.039	83.935	19.506	4.054
36.95	393.18	4.024	83.931	19.436	4.054
37.03	393.94	4.011	83.927	19.370	4.053
37.11	394.70	3.998	83.923	19.307	4.053
37.18	395.46	3.986	83.919	19.250	4.053
37.26	396.22	3.973	83.916	19.187	4.053
37.34	396.98	3.961	83.912	19.130	4.053
37.41	397.74	3.949	83.909	19.070	4.052
37.49	398.50	3.936	83.906	19.011	4.052
37.57	399.26	3.926	83.902	18.962	4.052
37.64	400.02	3.915	83.899	18.906	4.052
37.72	400.78	3.903	83.896	18.850	4.052
37.80	401.55	3.892	83.893	18.795	4.052
37.87	402.31	3.881	83.891	18.746	4.052
37.95	403.07	3.872	83.888	18.700	4.051
38.03	403.83	3.861	83.884	18.647	4.051
38.10	404.59	3.849	83.881	18.590	4.051
38.18	405.36	3.840	83.878	18.545	4.051
38.26	406.12	3.830	83.876	18.498	4.051
38.33	406.88	3.819	83.873	18.446	4.051
38.41	407.64	3.810	83.870	18.403	4.051
38.49	408.41	3.800	83.868	18.354	4.051
38.56	409.17	3.789	83.865	18.297	4.050
38.64	409.93	3.781	83.863	18.260	4.050
38.72	410.69	3.771	83.861	18.214	4.050
38.79	411.45	3.760	83.858	18.162	4.050
38.87	412.22	3.754	83.856	18.130	4.050
38.95	412.98	3.745	83.854	18.088	4.050
39.02	413.74	3.734	83.852	18.033	4.050
39.10	414.50	3.726	83.850	17.997	4.050
39.18	415.26	3.716	83.848	17.946	4.050
39.25	416.02	3.706	83.846	17.901	4.049
39.33	416.78	3.699	83.844	17.863	4.049
39.41	417.54	3.690	83.842	17.821	4.049
39.48	418.31	3.682	83.840	17.782	4.049
39.56	419.07	3.674	83.838	17.745	4.049
39.64	419.83	3.664	83.836	17.694	4.049
39.71	420.59	3.655	83.834	17.654	4.049
39.79	421.36	3.648	83.833	17.617	4.049
39.87	422.12	3.637	83.831	17.565	4.049
39.94	422.88	3.631	83.829	17.535	4.049
40.02	423.65	3.622	83.827	17.492	4.049
40.10	424.41	3.612	83.825	17.446	4.048
40.17	425.17	3.604	83.823	17.404	4.048
40.25	425.93	3.596	83.821	17.365	4.048
40.33	426.70	3.587	83.819	17.324	4.048
40.40	427.46	3.578	83.817	17.282	4.048
40.48	428.22	3.569	83.816	17.235	4.048
40.56	428.98	3.561	83.814	17.197	4.048
40.63	429.74	3.552	83.812	17.156	4.048
40.71	430.51	3.543	83.811	17.112	4.048
40.79	431.27	3.536	83.809	17.076	4.048
40.86	432.03	3.527	83.808	17.036	4.048
40.94	432.79	3.519	83.806	16.994	4.048
41.02	433.55	3.507	83.804	16.939	4.047
41.09	434.32	3.498	83.803	16.896	4.047
41.17	435.08	3.491	83.802	16.859	4.047
41.25	435.84	3.480	83.800	16.806	4.047
41.32	436.60	3.472	83.798	16.771	4.047
41.40	437.37	3.464	83.797	16.729	4.047
41.48	438.13	3.455	83.795	16.686	4.047
41.55	438.89	3.446	83.794	16.644	4.047
41.63	439.65	3.436	83.792	16.593	4.047
41.71	440.42	3.426	83.791	16.546	4.047
41.78	441.18	3.417	83.789	16.505	4.047
41.86	441.94	3.409	83.788	16.462	4.047
41.94	442.71	3.399	83.787	16.414	4.047
42.01	443.47	3.390	83.785	16.373	4.047
42.09	444.23	3.381	83.784	16.329	4.046
42.17	444.99	3.372	83.782	16.285	4.046
42.24	445.75	3.363	83.781	16.240	4.046
42.32	446.52	3.355	83.780	16.202	4.046
42.40	447.28	3.345	83.778	16.156	4.046
42.47	448.04	3.334	83.777	16.104	4.046
42.55	448.80	3.327	83.776	16.067	4.046
42.63	449.56	3.318	83.774	16.024	4.046
42.70	450.32	3.309	83.773	15.982	4.046
42.78	451.09	3.302	83.772	15.950	4.046
42.86	451.85	3.292	83.770	15.899	4.046
42.93	452.61	3.281	83.769	15.846	4.046
43.01	453.38	3.274	83.768	15.810	4.046
43.09	454.14	3.267	83.766	15.778	4.046
43.16	454.90	3.257	83.765	15.731	4.046
43.24	455.67	3.248	83.764	15.688	4.045
43.32	456.43	3.240	83.763	15.646	4.045
43.39	457.19	3.230	83.761	15.599	4.045
43.47	457.95	3.223	83.760	15.567	4.045
43.55	458.72	3.215	83.759	15.525	4.045
43.62	459.48	3.204	83.757	15.476	4.045
43.70	460.24	3.196	83.756	15.437	4.045
43.78	461.01	3.187	83.755	15.390	4.045
43.85	461.77	3.178	83.754	15.346	4.045
43.93	462.53	3.167	83.753	15.296	4.045
44.01	463.30	3.158	83.752	15.252	4.045
44.08	464.06	3.150	83.751	15.211	4.045
44.16	464.82	3.141	83.750	15.168	4.045
44.24	465.58	3.132	83.749	15.126	4.045
44.31	466.34	3.124	83.747	15.087	4.045
44.39	467.11	3.113	83.746	15.036	4.045
44.47	467.87	3.104	83.745	14.989	4.045
44.54	468.63	3.096	83.744	14.951	4.045
44.62	469.40	3.086	83.743	14.902	4.044
44.70	470.16	3.078	83.742	14.866	4.044
44.77	470.92	3.069	83.741	14.823	4.044
44.85	471.68	3.059	83.740	14.776	4.044
44.93	472.45	3.050	83.739	14.729	4.044
45.00	473.21	3.041	83.738	14.689	4.044
45.08	473.97	3.033	83.736	14.651	4.044
45.16	474.74	3.025	83.735	14.611	4.044
45.23	475.50	3.015	83.734	14.560	4.044
45.31	476.26	3.005	83.733	14.512	4.044
45.39	477.02	2.994	83.732	14.462	4.044
45.46	477.79	2.988	83.731	14.429	4.044
45.54	478.55	2.978	83.730	14.385	4.044
45.62	479.31	2.967	83.729	14.332	4.044
45.69	480.08	2.958	83.727	14.284	4.044
45.77	480.84	2.948	83.727	14.236	4.044
45.85	481.60	2.938	83.726	14.191	4.044
45.92	482.36	2.930	83.725	14.149	4.044
46.00	483.12	2.919	83.724	14.099	4.044
46.08	483.89	2.910	83.723	14.053	4.044
46.15	484.65	2.902	83.722	14.014	4.043
46.23	485.41	2.892	83.721	13.969	4.043
46.31	486.18	2.880	83.720	13.912	4.043
46.38	486.94	2.872	83.719	13.873	4.043
46.46	487.70	2.864	83.718	13.834	4.043
46.54	488.47	2.855	83.717	13.789	4.043
46.61	489.23	2.844	83.716	13.737	4.043
46.69	489.99	2.836	83.715	13.697	4.043
46.77	490.76	2.824	83.714	13.637	4.043
46.84	491.52	2.816	83.712	13.601	4.043
46.92	492.28	2.805	83.711	13.549	4.043
47.00	493.05	2.797	83.710	13.508	4.043
47.07	493.81	2.786	83.709	13.456	4.043
47.15	494.57	2.774	83.708	13.396	4.043
47.23	495.34	2.765	83.707	13.353	4.043
47.30	496.10	2.754	83.706	13.303	4.043
47.38	496.86	2.746	83.705	13.262	4.043
47.46	497.62	2.735	83.704	13.208	4.043
47.53	498.38	2.725	83.703	13.160	4.043
47.61	499.15	2.715	83.703	13.114	4.043
47.69	499.91	2.706	83.701	13.068	4.042
47.76	500.67	2.695	83.700	13.016	4.042
47.84	501.44	2.685	83.699	12.969	4.042
47.92	502.20	2.674	83.698	12.915	4.042
47.99	502.96	2.664	83.698	12.867	4.042
48.07	503.73	2.652	83.697	12.810	4.042
48.15	504.49	2.642	83.696	12.762	4.042
48.22	505.25	2.634	83.695	12.719	4.042
48.30	506.02	2.623	83.693	12.666	4.042
48.38	506.78	2.612	83.693	12.614	4.042
48.45	507.54	2.602	83.692	12.568	4.042
48.53	508.31	2.591	83.691	12.515	4.042
48.61	509.07	2.581	83.690	12.464	4.042
48.68	509.84	2.571	83.689	12.417	4.042
48.76	510.60	2.560	83.688	12.363	4.042
48.84	511.36	2.548	83.687	12.308	4.042
48.91	512.13	2.538	83.685	12.256	4.042
48.99	512.89	2.525	83.684	12.194	4.042
49.07	513.65	2.515	83.683	12.145	4.042
49.14	514.41	2.503	83.682	12.091	4.042
49.22	515.18	2.491	83.681	12.031	4.042
49.30	515.94	2.483	83.681	11.991	4.041
49.37	516.70	2.471	83.680	11.932	4.041
49.45	517.47	2.458	83.679	11.871	4.041
49.53	518.23	2.447	83.679	11.816	4.041
49.60	518.99	2.433	83.678	11.752	4.041
49.68	519.75	2.423	83.677	11.703	4.041
49.76	520.52	2.412	83.677	11.650	4.041
49.83	521.28	2.401	83.676	11.594	4.041
49.91	522.04	2.392	83.675	11.552	4.041
49.99	522.81	2.379	83.674	11.491	4.041
50.06	523.57	2.367	83.673	11.430	4.041
50.14	524.33	2.357	83.672	11.385	4.041
50.22	525.09	2.346	83.671	11.330	4.041
50.29	525.86	2.334	83.670	11.273	4.041
50.37	526.62	2.320	83.669	11.206	4.041
50.45	527.39	2.309	83.668	11.154	4.041
50.52	528.15	2.299	83.667	11.102	4.041
50.60	528.91	2.286	83.666	11.041	4.041
50.68	529.68	2.275	83.665	10.987	4.041
50.75	530.44	2.265	83.664	10.941	4.041
50.83	531.20	2.253	83.664	10.881	4.041
50.91	531.97	2.242	83.663	10.827	4.041
50.98	532.73	2.228	83.662	10.762	4.041
51.06	533.49	2.217	83.661	10.709	4.041
51.14	534.26	2.206	83.660	10.653	4.040
51.21	535.02	2.196	83.659	10.605	4.040
51.29	535.78	2.185	83.658	10.555	4.040
51.37	536.54	2.174	83.657	10.499	4.040
51.44	537.31	2.164	83.657	10.453	4.040
51.52	538.07	2.155	83.656	10.407	4.040
51.60	538.84	2.146	83.655	10.362	4.040
51.67	539.60	2.136	83.654	10.315	4.040
51.75	540.36	2.128	83.653	10.276	4.040
51.83	541.13	2.120	83.652	10.238	4.040
51.90	541.89	2.111	83.651	10.195	4.040
51.98	542.66	2.104	83.650	10.164	4.040
52.06	543.42	2.099	83.650	10.140	4.040
52.13	544.19	2.095	83.649	10.117	4.040
52.21	544.95	2.092	83.649	10.102	4.040
52.29	545.72	2.091	83.648	10.097	4.040
52.36	546.49	2.091	83.647	10.098	4.040
52.44	547.26	2.094	83.646	10.112	4.040
52.52	548.03	2.100	83.645	10.144	4.040
52.59	548.79	2.111	83.644	10.196	4.040
52.67	549.56	2.134	83.643	10.305	4.040
52.75	550.34	2.165	83.642	10.454	4.040
52.82	551.11	2.206	83.641	10.652	4.040
52.90	551.88	2.257	83.639	10.901	4.039
52.98	552.66	2.325	83.638	11.229	4.039
53.05	553.45	2.411	83.637	11.642	4.039
53.13	554.24	2.517	83.636	12.158	4.039
53.21	555.03	2.648	83.635	12.790	4.039
53.28	555.83	2.802	83.633	13.534	4.039
53.36	556.63	2.968	83.632	14.333	4.039
53.44	557.43	3.123	83.631	15.084	4.039
53.51	558.22	3.241	83.630	15.653	4.039
53.59	559.00	3.303	83.628	15.950	4.039
53.67	559.77	3.313	83.626	16.000	4.039
53.74	560.52	3.276	83.625	15.822	4.039
53.82	561.27	3.197	83.624	15.443	4.039
53.90	562.02	3.102	83.622	14.980	4.039
53.97	562.76	2.993	83.621	14.456	4.039
54.05	563.50	2.880	83.620	13.907	4.039
54.13	564.24	2.767	83.618	13.365	4.038
54.20	564.99	2.655	83.616	12.825	4.038
54.28	565.73	2.550	83.615	12.318	4.038
54.36	566.47	2.452	83.613	11.844	4.038
54.43	567.22	2.361	83.611	11.403	4.038
54.51	567.96	2.278	83.610	11.002	4.038
54.59	568.71	2.203	83.609	10.641	4.038
54.66	569.46	2.135	83.607	10.313	4.038
54.74	570.22	2.076	83.606	10.026	4.038
54.82	570.97	2.024	83.605	9.774	4.038
54.89	571.73	1.975	83.604	9.537	4.038
54.97	572.49	1.932	83.603	9.329	4.038
55.05	573.24	1.892	83.602	9.140	4.038
55.12	574.00	1.857	83.601	8.968	4.038
55.20	574.76	1.826	83.600	8.818	4.038
55.28	575.52	1.799	83.599	8.687	4.038
55.35	576.29	1.773	83.598	8.564	4.037
55.43	577.05	1.749	83.597	8.448	4.037
55.51	577.81	1.728	83.596	8.345	4.037
55.58	578.58	1.710	83.595	8.260	4.037
55.66	579.34	1.690	83.594	8.163	4.037
55.74	580.10	1.670	83.594	8.067	4.037
55.81	580.87	1.656	83.593	7.999	4.037
55.89	581.63	1.639	83.592	7.914	4.037
55.97	582.39	1.623	83.591	7.840	4.037
56.04	583.16	1.611	83.591	7.782	4.037
56.12	583.92	1.596	83.590	7.707	4.037
56.20	584.68	1.582	83.590	7.641	4.037
56.27	585.44	1.572	83.589	7.590	4.037
56.35	586.21	1.558	83.588	7.527	4.037
56.43	586.97	1.545	83.588	7.464	4.037
56.50	587.73	1.536	83.587	7.418	4.037
56.58	588.50	1.522	83.587	7.351	4.037
56.66	589.26	1.512	83.586	7.302	4.037
56.73	590.02	1.502	83.585	7.255	4.037
56.81	590.79	1.491	83.584	7.201	4.037
56.89	591.55	1.482	83.583	7.155	4.037
56.96	592.32	1.468	83.583	7.088	4.037
57.04	593.08	1.458	83.582	7.043	4.037
57.12	593.85	1.449	83.582	6.996	4.037
57.19	594.61	1.435	83.581	6.929	4.037
57.27	595.38	1.424	83.580	6.880	4.037
57.35	596.14	1.416	83.580	6.837	4.037
57.42	596.91	1.405	83.579	6.783	4.037
57.50	597.67	1.392	83.579	6.725	4.037
57.58	598.43	1.383	83.579	6.681	4.037
57.65	599.20	1.373	83.578	6.630	4.037
57.73	599.96	1.362	83.578	6.580	4.037
57.81	600.73	1.354	83.577	6.538	4.036
57.88	601.49	1.342	83.577	6.483	4.036
57.96	602.26	1.331	83.576	6.427	4.036
58.04	603.02	1.321	83.576	6.380	4.036
58.11	603.78	1.310	83.575	6.328	4.036
58.19	604.55	1.301	83.575	6.282	4.036
58.27	605.31	1.290	83.575	6.232	4.036
58.34	606.08	1.279	83.574	6.175	4.036
58.42	606.84	1.265	83.573	6.111	4.036
58.50	607.61	1.256	83.573	6.068	4.036
58.57	608.37	1.245	83.572	6.015	4.036
58.65	609.13	1.235	83.571	5.966	4.036
58.73	609.90	1.226	83.571	5.922	4.036
58.80	610.67	1.216	83.570	5.872	4.036
58.88	611.43	1.206	83.570	5.826	4.036
58.96	612.20	1.197	83.569	5.781	4.036
59.03	612.96	1.186	83.569	5.729	4.036
59.11	613.73	1.174	83.568	5.669	4.036
59.19	614.49	1.160	83.568	5.604	4.036
59.26	615.26	1.150	83.567	5.556	4.036
59.34	616.02	1.138	83.567	5.497	4.036
59.42	616.78	1.128	83.566	5.446	4.036
59.49	617.55	1.116	83.566	5.388	4.036
59.57	618.31	1.106	83.565	5.343	4.036
59.65	619.07	1.096	83.565	5.292	4.036
59.72	619.84	1.086	83.564	5.245	4.036
59.80	620.60	1.072	83.563	5.178	4.036
59.88	621.36	1.062	83.563	5.127	4.036
59.95	622.13	1.052	83.563	5.082	4.036
60.03	622.89	1.039	83.562	5.016	4.036
60.11	623.66	1.027	83.562	4.961	4.036
60.18	624.42	1.016	83.561	4.909	4.036
60.26	625.19	1.005	83.561	4.855	4.036
60.34	625.95	0.996	83.561	4.810	4.036
60.41	626.72	0.985	83.560	4.756	4.036
60.49	627.48	0.974	83.559	4.705	4.036
60.57	628.25	0.964	83.559	4.656	4.036
60.64	629.02	0.954	83.558	4.606	4.036
60.72	629.78	0.942	83.557	4.550	4.035
60.80	630.55	0.929	83.556	4.484	4.035
60.87	631.31	0.919	83.555	4.438	4.035
60.95	632.08	0.909	83.555	4.388	4.035
61.03	632.84	0.896	83.554	4.325	4.035
61.10	633.60	0.885	83.554	4.272	4.035
61.18	634.37	0.871	83.553	4.207	4.035
61.26	635.13	0.860	83.553	4.155	4.035
61.33	635.90	0.848	83.552	4.095	4.035
61.41	636.66	0.836	83.552	4.040	4.035
61.49	637.42	0.826	83.551	3.987	4.035
61.56	638.19	0.816	83.550	3.939	4.035
61.64	638.95	0.801	83.550	3.871	4.035
61.72	639.72	0.789	83.550	3.810	4.035
61.79	640.48	0.775	83.549	3.742	4.035
61.87	641.24	0.764	83.549	3.690	4.035
61.95	642.01	0.750	83.548	3.623	4.035
62.02	642.77	0.737	83.547	3.560	4.035
62.10	643.54	0.726	83.547	3.505	4.035
62.18	644.30	0.714	83.546	3.446	4.035
62.25	645.07	0.700	83.546	3.381	4.035
62.33	645.83	0.691	83.545	3.336	4.035
62.41	646.60	0.678	83.545	3.276	4.035
62.48	647.37	0.665	83.544	3.213	4.035
62.56	648.13	0.652	83.544	3.149	4.035
62.64	648.90	0.639	83.543	3.086	4.035
62.71	649.66	0.627	83.543	3.030	4.035
62.79	650.42	0.615	83.543	2.968	4.035
62.87	651.19	0.599	83.542	2.894	4.035
62.94	651.95	0.588	83.542	2.839	4.035
63.02	652.72	0.574	83.542	2.773	4.035
63.10	653.48	0.564	83.541	2.723	4.035
63.17	654.24	0.550	83.540	2.659	4.035
63.25	655.01	0.536	83.539	2.588	4.035
63.33	655.77	0.524	83.538	2.532	4.035
63.40	656.53	0.509	83.538	2.460	4.035
63.48	657.30	0.496	83.537	2.395	4.035
63.56	658.06	0.483	83.537	2.334	4.035
63.63	658.83	0.470	83.536	2.271	4.034
63.71	659.59	0.458	83.536	2.210	4.034
63.79	660.35	0.443	83.535	2.138	4.034
63.86	661.12	0.430	83.534	2.077	4.034
63.94	661.88	0.415	83.534	2.003	4.034
64.02	662.65	0.401	83.533	1.937	4.034
64.09	663.42	0.389	83.532	1.877	4.034
64.17	664.18	0.374	83.531	1.804	4.034
64.25	664.95	0.362	83.531	1.746	4.034
64.32	665.71	0.349	83.530	1.683	4.034
64.40	666.48	0.335	83.530	1.618	4.034
64.48	667.24	0.318	83.530	1.538	4.034
64.55	668.01	0.305	83.529	1.471	4.034
64.63	668.77	0.286	83.529	1.382	4.034
64.71	669.53	0.274	83.528	1.323	4.034
64.78	670.30	0.261	83.527	1.261	4.034
64.86	671.06	0.246	83.527	1.189	4.034
64.94	671.82	0.231	83.526	1.117	4.034
65.01	672.59	0.219	83.525	1.056	4.034
65.09	673.35	0.204	83.525	0.985	4.034
65.17	674.11	0.187	83.524	0.902	4.034
65.24	674.88	0.175	83.524	0.844	4.034
65.32	675.64	0.159	83.523	0.767	4.034
65.40	676.41	0.143	83.522	0.689	4.034
65.47	677.17	0.127	83.522	0.613	4.034
65.55	677.94	0.112	83.521	0.543	4.034
65.63	678.70	0.099	83.520	0.477	4.034
65.70	679.47	0.086	83.520	0.415	4.034
65.78	680.23	0.073	83.519	0.352	4.034
65.86	681.00	0.059	83.519	0.284	4.034
65.93	681.76	0.044	83.518	0.213	4.034
66.01	682.53	0.032	83.518	0.155	4.034
66.09	683.30	0.015	83.517	0.073	4.034
66.16	684.06	-0.004	83.517	-0.018	4.034
66.24	684.82	-0.016	83.516	-0.077	4.034
66.32	685.59	-0.027	83.515	-0.130	4.033
66.39	686.35	-0.040	83.515	-0.193	4.033
66.47	687.12	-0.054	83.514	-0.261	4.033
66.55	687.88	-0.070	83.514	-0.339	4.033
66.62	688.64	-0.085	83.513	-0.412	4.033
66.70	689.41	-0.099	83.512	-0.480	4.033
66.78	690.17	-0.116	83.512	-0.560	4.033
66.85	690.94	-0.130	83.511	-0.627	4.033
66.93	691.70	-0.142	83.511	-0.688	4.033
67.01	692.46	-0.156	83.510	-0.754	4.033
67.08	693.23	-0.171	83.509	-0.825	4.033
67.16	693.99	-0.186	83.509	-0.897	4.033
67.24	694.76	-0.201	83.508	-0.969	4.033
67.31	695.52	-0.215	83.507	-1.040	4.033
67.39	696.29	-0.230	83.507	-1.111	4.033
67.47	697.06	-0.243	83.506	-1.174	4.033
67.54	697.82	-0.260	83.505	-1.254	4.033
67.62	698.59	-0.274	83.505	-1.324	4.033
67.70	699.36	-0.290	83.505	-1.402	4.033
67.77	700.12	-0.307	83.504	-1.484	4.033
67.85	700.89	-0.325	83.504	-1.569	4.033
67.93	701.65	-0.342	83.503	-1.650	4.033
68.00	702.42	-0.357	83.502	-1.723	4.033
68.08	703.18	-0.371	83.501	-1.791	4.033
68.16	703.94	-0.388	83.501	-1.875	4.033
68.23	704.71	-0.405	83.500	-1.954	4.033
68.31	705.47	-0.422	83.499	-2.039	4.033
68.39	706.24	-0.440	83.499	-2.127	4.033
68.46	707.00	-0.456	83.498	-2.201	4.033
68.54	707.77	-0.474	83.497	-2.288	4.033
68.62	708.53	-0.492	83.497	-2.375	4.033
68.69	709.29	-0.508	83.496	-2.454	4.033
68.77	710.06	-0.523	83.495	-2.524	4.033
68.85	710.82	-0.539	83.495	-2.603	4.032
68.92	711.59	-0.554	83.494	-2.675	4.032
69.00	712.36	-0.568	83.494	-2.741	4.032
69.08	713.12	-0.587	83.493	-2.834	4.032
69.15	713.89	-0.604	83.493	-2.916	4.032
69.23	714.65	-0.621	83.492	-2.997	4.032
69.31	715.42	-0.636	83.491	-3.074	4.032
69.38	716.19	-0.651	83.490	-3.146	4.032
69.46	716.95	-0.665	83.489	-3.212	4.032
69.54	717.72	-0.684	83.489	-3.304	4.032
69.61	718.48	-0.703	83.488	-3.395	4.032
69.69	719.25	-0.722	83.488	-3.489	4.032
69.77	720.01	-0.739	83.487	-3.571	4.032
69.84	720.78	-0.756	83.486	-3.649	4.032
69.92	721.54	-0.772	83.485	-3.726	4.032
70.00	722.30	-0.790	83.485	-3.813	4.032
70.07	723.07	-0.808	83.484	-3.904	4.032
70.15	723.83	-0.825	83.483	-3.982	4.032
70.23	724.60	-0.842	83.483	-4.068	4.032
70.30	725.36	-0.862	83.483	-4.165	4.032
70.38	726.12	-0.879	83.482	-4.247	4.032
70.46	726.89	-0.899	83.481	-4.341	4.032
70.53	727.65	-0.915	83.480	-4.421	4.032
70.61	728.42	-0.933	83.480	-4.505	4.032
70.69	729.18	-0.953	83.479	-4.601	4.032
70.76	729.95	-0.970	83.478	-4.683	4.032
70.84	730.72	-0.988	83.477	-4.773	4.032
70.92	731.48	-1.007	83.476	-4.862	4.032
70.99	732.25	-1.025	83.475	-4.951	4.032
71.07	733.02	-1.042	83.475	-5.032	4.032
71.15	733.79	-1.059	83.474	-5.117	4.031
71.22	734.54	-1.086	83.473	-5.244	4.031
71.30	735.31	-1.105	83.473	-5.339	4.031
71.38	736.07	-1.124	83.472	-5.428	4.031
71.45	736.83	-1.144	83.472	-5.524	4.031
71.53	737.60	-1.162	83.471	-5.611	4.031
71.61	738.36	-1.180	83.470	-5.699	4.031
71.68	739.13	-1.201	83.469	-5.799	4.031
71.76	739.89	-1.221	83.468	-5.897	4.031
71.84	740.65	-1.241	83.467	-5.994	4.031
71.91	741.42	-1.257	83.466	-6.071	4.031
71.99	742.18	-1.279	83.466	-6.176	4.031
72.07	742.94	-1.299	83.465	-6.276	4.031
72.14	743.71	-1.317	83.464	-6.362	4.031
72.22	744.47	-1.336	83.463	-6.455	4.031
72.30	745.24	-1.357	83.462	-6.556	4.031
72.37	746.00	-1.374	83.461	-6.637	4.031
72.45	746.77	-1.390	83.461	-6.713	4.031
72.53	747.54	-1.408	83.460	-6.800	4.031
72.60	748.31	-1.429	83.459	-6.901	4.031
72.68	749.07	-1.450	83.459	-7.004	4.031
72.76	749.84	-1.468	83.458	-7.091	4.031
72.83	750.60	-1.488	83.456	-7.187	4.031
72.91	751.37	-1.510	83.456	-7.295	4.031
72.99	752.13	-1.531	83.455	-7.393	4.031
73.06	752.89	-1.549	83.454	-7.481	4.031
73.14	753.66	-1.572	83.453	-7.594	4.030
73.22	754.42	-1.589	83.453	-7.673	4.030
73.29	755.18	-1.610	83.452	-7.777	4.030
73.37	755.95	-1.630	83.451	-7.871	4.030
73.45	756.71	-1.646	83.450	-7.952	4.030
73.52	757.48	-1.669	83.449	-8.062	4.030
73.60	758.24	-1.694	83.449	-8.183	4.030
73.68	759.01	-1.715	83.448	-8.281	4.030
73.75	759.77	-1.736	83.447	-8.384	4.030
73.83	760.53	-1.758	83.446	-8.488	4.030
73.91	761.30	-1.778	83.445	-8.586	4.030
73.98	762.06	-1.799	83.444	-8.688	4.030
74.06	762.83	-1.819	83.443	-8.787	4.030
74.14	763.59	-1.840	83.443	-8.887	4.030
74.21	764.36	-1.861	83.442	-8.989	4.030
74.29	765.13	-1.881	83.441	-9.086	4.030
74.37	765.89	-1.904	83.440	-9.194	4.030
74.44	766.66	-1.924	83.439	-9.295	4.030
74.52	767.42	-1.950	83.438	-9.416	4.030
74.60	768.19	-1.971	83.437	-9.517	4.030
74.67	768.95	-1.997	83.436	-9.644	4.030
74.75	769.71	-2.020	83.435	-9.755	4.030
74.83	770.48	-2.043	83.435	-9.868	4.030
74.90	771.24	-2.066	83.434	-9.976	4.030
74.98	772.01	-2.087	83.432	-10.078	4.029
75.06	772.77	-2.106	83.431	-10.169	4.029
75.13	773.53	-2.131	83.430	-10.290	4.029
75.21	774.30	-2.153	83.428	-10.398	4.029
75.29	775.06	-2.175	83.427	-10.505	4.029
75.36	775.83	-2.200	83.426	-10.624	4.029
75.44	776.59	-2.223	83.425	-10.736	4.029
75.52	777.35	-2.244	83.425	-10.837	4.029
75.59	778.12	-2.268	83.424	-10.955	4.029
75.67	778.88	-2.289	83.423	-11.057	4.029
75.75	779.65	-2.312	83.423	-11.167	4.029
75.82	780.41	-2.335	83.422	-11.280	4.029
75.90	781.18	-2.361	83.421	-11.401	4.029
75.98	781.95	-2.381	83.421	-11.501	4.029
76.05	782.71	-2.401	83.420	-11.598	4.029
76.13	783.48	-2.427	83.419	-11.724	4.029
76.21	784.24	-2.453	83.418	-11.849	4.029
76.28	785.01	-2.479	83.417	-11.972	4.029
76.36	785.77	-2.502	83.416	-12.082	4.029
76.44	786.53	-2.527	83.415	-12.204	4.029
76.51	787.30	-2.551	83.414	-12.321	4.029
76.59	788.06	-2.574	83.413	-12.430	4.029
76.67	788.83	-2.601	83.412	-12.560	4.029
76.74	789.59	-2.625	83.411	-12.679	4.028
76.82	790.35	-2.648	83.410	-12.789	4.028
76.90	791.12	-2.674	83.409	-12.914	4.028
76.97	791.88	-2.697	83.408	-13.027	4.028
77.05	792.65	-2.724	83.407	-13.154	4.028
77.13	793.41	-2.748	83.406	-13.273	4.028
77.20	794.17	-2.774	83.405	-13.399	4.028
77.28	794.94	-2.799	83.404	-13.519	4.028
77.36	795.70	-2.826	83.403	-13.647	4.028
77.43	796.47	-2.847	83.402	-13.751	4.028
77.51	797.23	-2.875	83.401	-13.886	4.028
77.59	798.00	-2.900	83.400	-14.006	4.028
77.66	798.76	-2.926	83.399	-14.130	4.028
77.74	799.53	-2.951	83.398	-14.251	4.028
77.82	800.30	-2.979	83.397	-14.390	4.028
77.89	801.06	-3.001	83.396	-14.493	4.028
77.97	801.83	-3.028	83.395	-14.622	4.028
78.05	802.60	-3.055	83.394	-14.755	4.028
78.12	803.36	-3.085	83.393	-14.900	4.028
78.20	804.12	-3.111	83.392	-15.026	4.028
78.28	804.89	-3.139	83.390	-15.163	4.027
78.35	805.66	-3.168	83.389	-15.299	4.027
78.43	806.42	-3.198	83.388	-15.446	4.027
78.51	807.18	-3.228	83.387	-15.588	4.027
78.58	807.94	-3.255	83.385	-15.721	4.027
78.66	808.71	-3.280	83.384	-15.841	4.027
78.74	809.47	-3.308	83.383	-15.978	4.027
78.81	810.24	-3.339	83.382	-16.126	4.027
78.89	811.00	-3.369	83.381	-16.273	4.027
78.97	811.77	-3.395	83.380	-16.397	4.027
79.04	812.54	-3.424	83.379	-16.536	4.027
79.12	813.30	-3.453	83.377	-16.679	4.027
79.20	814.06	-3.487	83.376	-16.843	4.027
79.27	814.82	-3.517	83.375	-16.986	4.027
79.35	815.59	-3.544	83.373	-17.115	4.027
79.43	816.35	-3.574	83.372	-17.262	4.027
79.50	817.12	-3.602	83.371	-17.397	4.027
79.58	817.88	-3.630	83.370	-17.533	4.026
79.66	818.65	-3.659	83.369	-17.671	4.026
79.73	819.42	-3.689	83.368	-17.816	4.026
79.81	820.18	-3.719	83.367	-17.961	4.026
79.89	820.95	-3.748	83.366	-18.103	4.026
79.96	821.71	-3.779	83.365	-18.253	4.026
80.04	822.48	-3.804	83.364	-18.373	4.026
80.12	823.24	-3.843	83.363	-18.561	4.026
80.19	824.00	-3.872	83.363	-18.702	4.026
80.27	824.77	-3.902	83.362	-18.844	4.026
80.35	825.53	-3.930	83.361	-18.980	4.026
80.42	826.30	-3.957	83.360	-19.110	4.026
80.50	827.06	-3.990	83.359	-19.271	4.026
80.58	827.82	-4.020	83.360	-19.414	4.026
80.65	828.59	-4.047	83.361	-19.548	4.026
80.73	829.36	-4.079	83.361	-19.701	4.026
80.81	830.12	-4.115	83.360	-19.872	4.026
80.88	830.88	-4.147	83.360	-20.027	4.026
80.96	831.65	-4.178	83.359	-20.179	4.026
81.04	832.41	-4.211	83.359	-20.335	4.026
81.11	833.18	-4.240	83.359	-20.478	4.026
81.19	833.94	-4.272	83.359	-20.634	4.026
81.27	834.70	-4.301	83.358	-20.773	4.026
81.34	835.47	-4.332	83.357	-20.923	4.026
81.42	836.23	-4.363	83.357	-21.074	4.026
81.50	837.00	-4.395	83.356	-21.227	4.026
81.57	837.76	-4.427	83.355	-21.380	4.026
81.65	838.53	-4.456	83.354	-21.521	4.026
81.73	839.30	-4.486	83.357	-21.664	4.026
81.80	840.06	-4.519	83.367	-21.824	4.026
81.88	840.83	-4.551	83.375	-21.979	4.027
81.96	841.59	-4.583	83.380	-22.132	4.027
82.03	842.36	-4.614	83.383	-22.285	4.027
82.11	843.13	-4.642	83.385	-22.421	4.027
82.19	843.88	-4.687	83.385	-22.636	4.027
82.26	844.64	-4.720	83.385	-22.797	4.027
82.34	845.41	-4.748	83.384	-22.932	4.027
82.42	846.17	-4.782	83.383	-23.093	4.027
82.49	846.94	-4.813	83.382	-23.244	4.027
82.57	847.70	-4.845	83.381	-23.399	4.027
82.65	848.47	-4.878	83.380	-23.558	4.027
82.72	849.23	-4.910	83.379	-23.714	4.027
82.80	849.99	-4.942	83.377	-23.867	4.027
82.88	850.76	-4.973	83.376	-24.020	4.027
82.95	851.52	-5.007	83.375	-24.182	4.027
83.03	852.29	-5.038	83.373	-24.330	4.027
83.11	853.05	-5.068	83.372	-24.475	4.027
83.18	853.82	-5.102	83.370	-24.641	4.026
83.26	854.58	-5.131	83.369	-24.780	4.026
83.34	855.35	-5.164	83.367	-24.939	4.026
83.41	856.11	-5.199	83.366	-25.107	4.026
83.49	856.87	-5.229	83.364	-25.256	4.026
83.57	857.64	-5.260	83.363	-25.404	4.026
83.64	858.41	-5.293	83.362	-25.561	4.026
83.72	859.17	-5.326	83.361	-25.724	4.026
83.80	859.94	-5.359	83.359	-25.883	4.026
83.87	860.70	-5.392	83.358	-26.040	4.026
83.95	861.47	-5.424	83.357	-26.196	4.026
84.03	862.23	-5.455	83.356	-26.346	4.026
84.10	863.00	-5.489	83.354	-26.508	4.026
84.18	863.76	-5.521	83.353	-26.663	4.026
84.26	864.52	-5.552	83.351	-26.814	4.026
84.33	865.29	-5.588	83.350	-26.987	4.026
84.41	866.05	-5.618	83.349	-27.134	4.025
84.49	866.81	-5.654	83.347	-27.305	4.025
84.56	867.58	-5.686	83.346	-27.463	4.025
84.64	868.34	-5.721	83.344	-27.631	4.025
84.72	869.11	-5.755	83.343	-27.792	4.025
84.79	869.87	-5.785	83.342	-27.937	4.025
84.87	870.64	-5.816	83.341	-28.090	4.025
84.95	871.40	-5.850	83.340	-28.252	4.025
85.02	872.16	-5.883	83.338	-28.413	4.025
85.10	872.93	-5.914	83.337	-28.564	4.025
85.18	873.69	-5.953	83.336	-28.748	4.025
85.25	874.46	-5.984	83.335	-28.902	4.025
85.33	875.22	-6.014	83.334	-29.045	4.025
85.41	875.99	-6.050	83.333	-29.218	4.025
85.48	876.75	-6.083	83.331	-29.376	4.025
85.56	877.52	-6.119	83.330	-29.553	4.025
85.64	878.28	-6.150	83.329	-29.701	4.024
85.71	879.05	-6.182	83.328	-29.855	4.024
85.79	879.82	-6.215	83.327	-30.018	4.024
85.87	880.58	-6.246	83.325	-30.168	4.024
85.94	881.34	-6.285	83.324	-30.353	4.024
86.02	882.11	-6.321	83.323	-30.528	4.024
86.10	882.87	-6.357	83.322	-30.703	4.024
86.17	883.63	-6.391	83.320	-30.865	4.024
86.25	884.40	-6.424	83.319	-31.024	4.024
86.33	885.16	-6.458	83.318	-31.188	4.024
86.40	885.93	-6.491	83.317	-31.347	4.024
86.48	886.69	-6.524	83.316	-31.509	4.024
86.56	887.45	-6.561	83.314	-31.687	4.024
86.63	888.22	-6.597	83.313	-31.860	4.024
86.71	888.98	-6.631	83.312	-32.023	4.024
86.79	889.75	-6.660	83.311	-32.163	4.024
86.86	890.51	-6.691	83.310	-32.317	4.024
86.94	891.27	-6.728	83.309	-32.494	4.024
87.02	892.04	-6.757	83.307	-32.633	4.023
87.09	892.80	-6.784	83.304	-32.766	4.023
87.17	893.57	-6.819	83.301	-32.935	4.023
87.25	894.33	-6.855	83.299	-33.105	4.023
87.32	895.10	-6.890	83.297	-33.276	4.023
87.40	895.86	-6.921	83.295	-33.424	4.023
87.48	896.63	-6.951	83.294	-33.570	4.023
87.55	897.40	-6.980	83.290	-33.713	4.023
87.63	898.16	-7.017	83.286	-33.887	4.022
87.71	898.93	-7.051	83.283	-34.052	4.022
87.78	899.69	-7.086	83.281	-34.223	4.022
87.86	900.46	-7.121	83.280	-34.392	4.022
87.94	901.22	-7.152	83.282	-34.543	4.022
88.01	901.99	-7.187	83.284	-34.708	4.022
88.09	902.75	-7.224	83.285	-34.890	4.022
88.17	903.52	-7.260	83.286	-35.061	4.022
88.24	904.28	-7.294	83.286	-35.229	4.022
88.32	905.04	-7.326	83.285	-35.384	4.022
88.40	905.81	-7.365	83.284	-35.571	4.022
88.47	906.57	-7.400	83.283	-35.738	4.022
88.55	907.33	-7.436	83.282	-35.913	4.022
88.63	908.10	-7.470	83.281	-36.075	4.022
88.70	908.86	-7.503	83.280	-36.235	4.022
88.78	909.63	-7.538	83.279	-36.404	4.022
88.86	910.39	-7.576	83.278	-36.588	4.022
88.93	911.15	-7.608	83.276	-36.746	4.022
89.01	911.92	-7.638	83.275	-36.889	4.022
89.09	912.68	-7.672	83.274	-37.053	4.022
89.16	913.45	-7.706	83.272	-37.218	4.022
89.24	914.22	-7.735	83.271	-37.357	4.022
89.32	914.98	-7.770	83.269	-37.525	4.022
89.39	915.75	-7.803	83.267	-37.685	4.021
89.47	916.51	-7.837	83.266	-37.849	4.021
89.55	917.28	-7.871	83.264	-38.016	4.021
89.62	918.05	-7.905	83.263	-38.179	4.021
89.70	918.81	-7.942	83.262	-38.359	4.021
89.78	919.58	-7.976	83.260	-38.522	4.021
89.85	920.34	-8.014	83.259	-38.704	4.021
89.93	921.10	-8.048	83.258	-38.867	4.021
90.01	921.87	-8.079	83.256	-39.020	4.021
90.08	922.63	-8.114	83.255	-39.185	4.021
90.16	923.40	-8.151	83.253	-39.366	4.021
90.24	924.16	-8.185	83.252	-39.531	4.021
90.31	924.93	-8.220	83.251	-39.701	4.021
90.39	925.69	-8.255	83.249	-39.867	4.021
90.47	926.46	-8.291	83.248	-40.042	4.021
90.54	927.22	-8.323	83.246	-40.199	4.020
90.62	927.98	-8.358	83.245	-40.366	4.020
90.70	928.75	-8.391	83.243	-40.526	4.020
90.77	929.51	-8.423	83.242	-40.681	4.020
90.85	930.28	-8.458	83.240	-40.850	4.020
90.93	931.04	-8.493	83.239	-41.017	4.020
91.00	931.81	-8.529	83.237	-41.192	4.020
91.08	932.57	-8.561	83.236	-41.348	4.020
91.16	933.34	-8.595	83.235	-41.512	4.020
91.23	934.11	-8.624	83.234	-41.652	4.020
91.31	934.87	-8.660	83.232	-41.826	4.020
91.39	935.63	-8.698	83.231	-42.010	4.020
91.46	936.40	-8.729	83.230	-42.157	4.020
91.54	937.17	-8.766	83.228	-42.339	4.020
91.62	937.93	-8.799	83.227	-42.495	4.020
91.69	938.69	-8.836	83.225	-42.672	4.019
91.77	939.46	-8.873	83.224	-42.852	4.019
91.85	940.22	-8.908	83.223	-43.022	4.019
91.92	940.99	-8.944	83.221	-43.198	4.019
92.00	941.75	-8.979	83.220	-43.365	4.019
92.08	942.52	-9.014	83.218	-43.532	4.019
92.15	943.28	-9.051	83.217	-43.712	4.019
92.23	944.05	-9.086	83.215	-43.880	4.019
92.31	944.81	-9.124	83.214	-44.065	4.019
92.38	945.57	-9.156	83.213	-44.220	4.019
92.46	946.34	-9.191	83.211	-44.388	4.019
92.54	947.10	-9.226	83.210	-44.557	4.019
92.61	947.87	-9.260	83.209	-44.722	4.019
92.69	948.63	-9.296	83.207	-44.897	4.019
92.77	949.40	-9.331	83.206	-45.065	4.019
92.84	950.16	-9.367	83.204	-45.239	4.018
92.92	950.93	-9.404	83.203	-45.416	4.018
93.00	951.69	-9.441	83.202	-45.596	4.018
93.07	952.46	-9.475	83.201	-45.761	4.018
93.15	953.22	-9.509	83.199	-45.923	4.018
93.23	953.99	-9.547	83.198	-46.108	4.018
93.30	954.75	-9.583	83.197	-46.282	4.018
93.38	955.52	-9.621	83.196	-46.468	4.018
93.46	956.28	-9.660	83.195	-46.655	4.018
93.53	957.05	-9.699	83.193	-46.843	4.018
93.61	957.81	-9.734	83.192	-47.013	4.018
93.69	958.58	-9.774	83.191	-47.203	4.018
93.76	959.34	-9.812	83.189	-47.389	4.018
93.84	960.10	-9.851	83.188	-47.579	4.018
93.92	960.87	-9.889	83.187	-47.761	4.018
93.99	961.63	-9.927	83.186	-47.943	4.018
94.07	962.40	-9.967	83.185	-48.138	4.018
94.15	963.16	-10.003	83.183	-48.309	4.017
94.22	963.92	-10.040	83.182	-48.488	4.017
94.30	964.69	-10.077	83.181	-48.669	4.017
94.38	965.45	-10.112	83.179	-48.835	4.017
94.45	966.22	-10.150	83.178	-49.022	4.017
94.53	966.98	-10.184	83.177	-49.184	4.017
94.61	967.75	-10.223	83.176	-49.372	4.017
94.68	968.51	-10.259	83.175	-49.549	4.017
94.76	969.28	-10.297	83.173	-49.729	4.017
94.84	970.04	-10.336	83.172	-49.920	4.017
94.91	970.81	-10.370	83.171	-50.085	4.017
94.99	971.57	-10.408	83.169	-50.265	4.017
95.07	972.34	-10.443	83.168	-50.438	4.017
95.14	973.10	-10.482	83.167	-50.625	4.017
95.22	973.87	-10.521	83.166	-50.812	4.017
95.30	974.63	-10.561	83.164	-51.005	4.017
95.37	975.40	-10.599	83.163	-51.189	4.016
95.45	976.16	-10.637	83.162	-51.375	4.016
95.53	976.93	-10.679	83.161	-51.574	4.016
95.60	977.69	-10.716	83.160	-51.752	4.016
95.68	978.46	-10.755	83.159	-51.944	4.016
95.76	979.22	-10.794	83.159	-52.132	4.016
95.83	979.99	-10.832	83.159	-52.316	4.016
95.91	980.75	-10.869	83.158	-52.493	4.016
95.99	981.51	-10.911	83.158	-52.695	4.016
96.06	982.28	-10.949	83.157	-52.879	4.016
96.14	983.04	-10.990	83.156	-53.077	4.016
96.22	983.81	-11.028	83.155	-53.260	4.016
96.29	984.57	-11.064	83.154	-53.436	4.016
96.37	985.34	-11.105	83.152	-53.634	4.016
96.45	986.10	-11.146	83.151	-53.832	4.016
96.52	986.87	-11.187	83.149	-54.028	4.016
96.60	987.63	-11.225	83.147	-54.211	4.016
96.68	988.40	-11.263	83.146	-54.397	4.016
96.75	989.16	-11.302	83.145	-54.586	4.016
96.83	989.93	-11.344	83.143	-54.790	4.016
96.91	990.69	-11.386	83.142	-54.989	4.015
96.98			83.141		4.015
97.00			83.140		4.015