File: Data/KMK316/MvsH/KMK316_MvsH_300K.dat
[Header]
; MPMS3 Data File (default extension .dat)
; Copyright (c) 2007, Quantum Design, Inc. All rights reserved.
TITLE,
FILEOPENTIME,3885184764.09569,02/10/2023,10:00 am
BYAPP,MPMS3 w/ AC,1.0,1.1
INFO,MPMS3 Measurement Release 1.1.16 Build 424, MultiVu Release 2.3.4.19,APPNAME
INFO,Linear Motor Servo Controller,MOTOR_MODULE_NAME
INFO,3101-100 J0,MOTOR_HW_VERSION
INFO,MMC721,MOTOR_SERIAL_NUMBER
INFO,01.04.28,MOTOR_SOFTWARE_VERSION
INFO,Quantum Design Squid Module,SQUID_MODULE_NAME
INFO,3101-501 B0,SQUID_HW_VERSION
INFO,SQM195,SQUID_SERIAL_NUMBER
INFO,01.03.04,SQUID_SOFTWARE_VERSION
INFO,SQUID AC,AC_MODULE_NAME
INFO,3101-401 f1,AC_HW_VERSION
INFO,SAC107,AC_SERIAL_NUMBER
INFO,SQUID AC 00.95.07,AC_SOFTWARE_VERSION
INFO,TCI166,COIL_SERIAL_NUMBER
INFO,0,MOMENT_UNITS
INFO,KMK316,SAMPLE_MATERIAL
INFO,0.7 mg KMK273S + 0.8 mg KMK245S,SAMPLE_COMMENT
INFO,1.5,SAMPLE_MASS
INFO,,SAMPLE_VOLUME
INFO,,SAMPLE_MOLECULAR_WEIGHT
INFO,,SAMPLE_SIZE
INFO,,SAMPLE_SHAPE
INFO,Straw,SAMPLE_HOLDER
INFO,Standard,SAMPLE_HOLDER_DETAIL
INFO,67.04,SAMPLE_OFFSET
DATATYPE,COMMENT,1
DATATYPE,TIME,2
STARTUPAXIS,X,2
STARTUPAXIS,Y1,5
FIELDGROUP, VSM,2,3,4,5,6,8,9,10,11,14,15
FIELDGROUP, DC, 2,3,4,14,56,57,58,59,60,61,62,63,64,65,66,67,68,69
FIELDGROUP, AC, 2,3,4,11,16,17,18,19,20,21,22,23,24,25,26,27,28,29,30
STARTUPGROUP, All
[Data]
Comment,Time Stamp (sec),Temperature (K),Magnetic Field (Oe),Moment (emu),M. Std. Err. (emu),Transport Action,Averaging Time (sec),Frequency (Hz),Peak Amplitude (mm),Center Position (mm),Lockin Signal' (V),Lockin Signal (V),Range,M. Quad. Signal (emu),AC Moment (emu),AC M. Std Err. (emu),AC Phase (deg),AC Phase Std. Err. (deg),AC Susceptibility (emu/Oe),AC Suscept. Std Err. (emu/Oe),AC X' (emu/Oe),AC X' Std Err. (emu/Oe),AC X'' (emu/Oe),AC X'' Std Err. (emu/Oe),AC Drive (Oe),AC Frequency (Hz),AC Averaging Time (sec),AC Cycles,AC Range,AC Measure Type,AC Signal' (V),AC Signal'' (V),AC Trim Coil Ratio,AC Trim Coil Phase,Min. Temperature (K),Max. Temperature (K),Min. Field (Oe),Max. Field (Oe),Mass (grams),Motor Lag (deg),Pressure (Torr),Measure Count,Measurement Number,SQUID Status (code),Motor Status (code),Measure Status (code),Motor Current (amps),Motor Temp. (C),Temp. Status (code),Field Status (code),Chamber Status (code),Chamber Temp (K),Redirection State,Evercool Status,Average Temp (K),Rotation Angle (deg),Rotator state,DC Moment Fixed Ctr (emu),DC Moment Err Fixed Ctr (emu),DC Moment Free Ctr (emu),DC Moment Err Free Ctr (emu),DC Fixed Fit,DC Free Fit,DC Calculated Center (mm),DC Calculated Center Err (mm),DC Scan Length (mm),DC Scan Time (s),DC Number of Points,DC Squid Drift,DC Min V (V),DC Max V (V),DC Scans per Measure,Map 01,Map 02,Map 03,Map 04,Map 05,Map 06,Map 07,Map 08,Map 09,Map 10,Map 11,Map 12,Map 13,Map 14,Map 15,Map 16
,3885184905.7903,300.071807861328,-70000.484375,,,6,,,,32.2820510864258,,,10,,,,,,,,,,,,,,,,,,,,,,300.071472167969,300.084777832031,-70000.484375,-70000.484375,,,7.6686372756958,,1,0,0,0,0.0138092041015625,32.2580642700195,1,1,1,300.072082519531,0,4232058720,300.077542114258,,,-0.00672520877941339,0.000338234992744837,-0.00673020762359352,0.00033824068098002,0.871320009231567,0.876999378204346,32.4240226745605,0,35,4,200,-0.0310618467628956,-1.33110356330872,2.43659639358521,1,,,,,,,,,,,,,,,,
,3885185063.876,300.168441772461,-45000.328125,,,6,,,,32.2820510864258,,,10,,,,,,,,,,,,,,,,,,,,,,300.167816162109,300.186584472656,-45000.328125,-45000.328125,,,7.74544858932495,,1,0,0,0,0,32.7468223571777,1,1,1,300.169067382812,0,4232058656,300.177276611328,,,-0.00681630164153594,0.000341367285650547,-0.00681868328644538,0.000341368807172151,0.909491837024689,0.913354933261871,32.3806190490723,0,35,4,200,0.0286169182509184,-0.916907668113709,2.66609907150269,1,,,,,,,,,,,,,,,,
,3885185222.57598,300.057464599609,-20000.33984375,,,6,,,,32.2820510864258,,,10,,,,,,,,,,,,,,,,,,,,,,300.056213378906,300.07373046875,-20000.33984375,-20000.33984375,,,7.78413581848145,,1,0,0,0,0,32.7468223571777,1,1,1,300.058715820313,0,4232058432,300.065570068359,,,-0.00681373617716951,0.000340309944484295,-0.00681462869628408,0.000340310684130284,0.947372674942017,0.949873089790344,32.3426971435547,0,35,4,200,0.0292407609522343,-0.780177414417267,2.66141295433044,1,,,,,,,,,,,,,,,,
,3885185372.53629,300.171020507812,-8500.41796875,,,6,,,,32.2820510864258,,,10,,,,,,,,,,,,,,,,,,,,,,300.155487060547,300.187072753906,-8500.41796875,-8500.41796875,,,7.82290410995483,,1,0,0,0,0.013885498046875,32.2580642700195,1,1,1,300.154968261719,0,4232058592,300.175607299805,,,-0.00659964204121721,0.000329385419031157,-0.00660013132410924,0.000329385937341998,0.963031888008118,0.965047061443329,32.327709197998,0,35,4,200,0.0345264188945293,-0.652899742126465,2.65672206878662,1,,,,,,,,,,,,,,,,
,3885185498.78654,300.090591430664,-6000.33740234375,,,6,,,,32.2820510864258,,,10,,,,,,,,,,,,,,,,,,,,,,300.090209960937,300.107879638672,-6000.33740234375,-6000.33740234375,,,7.84277296066284,,1,0,0,0,0.013885498046875,32.2580642700195,1,1,1,300.090118408203,0,4232058624,300.098733520508,,,-0.00641813216927939,0.000320295994832173,-0.00641857073434843,0.000320296520111008,0.965684711933136,0.967684268951416,32.3258514404297,0,35,4,200,0.028121517971158,-0.669971764087677,2.56863188743591,1,,,,,,,,,,,,,,,,
,3885185618.18319,300.077285766602,-3500.2939453125,,,6,,,,32.2820510864258,,,10,,,,,,,,,,,,,,,,,,,,,,300.073394775391,300.091125488281,-3500.2939453125,-3500.2939453125,,,7.85766458511353,,1,0,0,0,0.0006103515625,32.7468223571777,1,1,1,300.081176757812,0,4232058592,300.083374023438,,,-0.00598584248649958,0.000298689226340554,-0.00598616509957738,0.000298689366510839,0.969101786613464,0.970880508422852,32.3212814331055,0,35,4,200,0.0221572984009981,-0.605908095836639,2.44292950630188,1,,,,,,,,,,,,,,,,
,3885185740.29564,300.187652587891,-1000.34753417969,,,6,,,,32.2820510864258,,,10,,,,,,,,,,,,,,,,,,,,,,300.178131103516,300.206665039063,-1000.34753417969,-1000.34753417969,,,7.87029123306274,,1,0,0,0,0.013885498046875,31.7693061828613,1,1,1,300.197174072266,0,4232058656,300.197320556641,,,-0.00404722636843604,0.000201932109184048,-0.00404733493150663,0.000201932188693578,0.972794830799103,0.973783612251282,32.3096694946289,0,35,4,200,0.014891441911459,-0.351224631071091,1.66791152954102,1,,,,,,,,,,,,,,,,
,3885185869.94782,300.15739440918,-760.444519042969,,,6,,,,32.2820510864258,,,10,,,,,,,,,,,,,,,,,,,,,,300.140899658203,300.174835205078,-760.444519042969,-760.444519042969,,,7.8789758682251,,1,0,0,0,0.013885498046875,32.2580642700195,1,1,1,300.140838623047,0,4232058816,300.163394165039,,,-0.00357749888502869,0.000178498862591612,-0.00357755033244828,0.000178498991263938,0.972108662128449,0.972602367401123,32.3019027709961,0,35,4,200,-0.0173641815781593,-0.429692059755325,1.36556339263916,1,,,,,,,,,,,,,,,,
,3885185989.82243,300.219009399414,-710.408203125,,,6,,,,32.2820510864258,,,10,,,,,,,,,,,,,,,,,,,,,,300.209655761719,300.240264892578,-710.408203125,-710.408203125,,,7.89002323150635,,1,0,0,0,0.0148773193359375,31.7693061828613,1,1,1,300.228363037109,0,4232058688,300.229470825195,,,-0.00346932119540931,0.00017309683848922,-0.00346938192570846,0.000173096894546225,0.973055601119995,0.973700523376465,32.3043174743652,5.68368864059448,35,4,200,-0.014207829721272,-0.412839978933334,1.3331743478775,1,,,,,,,,,,,,,,,,
,3885186110.5089,300.233322143555,-660.384094238281,,,6,,,,32.2820510864258,,,10,,,,,,,,,,,,,,,,,,,,,,300.232269287109,300.251434326172,-660.384094238281,-660.384094238281,,,7.89815855026245,,1,0,0,0,0.015869140625,32.2580642700195,1,1,1,300.232269287109,0,4232058688,300.242050170898,,,-0.00335170457953534,0.000167226355876646,-0.00335175768303375,0.000167226463836463,0.973541855812073,0.974122285842895,32.3030014038086,5.68357276916504,35,4,200,-0.0146087277680635,-0.362718671560287,1.32452988624573,1,,,,,,,,,,,,,,,,
,3885186228.96316,300.231506347656,-610.323364257812,,,6,,,,32.2820510864258,,,10,,,,,,,,,,,,,,,,,,,,,,300.225341796875,300.25146484375,-610.323364257812,-610.323364257812,,,7.90299129486084,,1,0,0,0,0.013885498046875,32.2580642700195,1,1,1,300.237670898438,0,4232058624,300.241464233398,,,-0.00322759730280227,0.000161034535642056,-0.00322764707698931,0.000161034734372571,0.973494708538055,0.974035084247589,32.3022880554199,0.173088759183884,35,4,200,-0.0149035220965743,-0.386008530855179,1.26250600814819,1,,,,,,,,,,,,,,,,
,3885186343.98186,300.223541259766,-560.274841308594,,,6,,,,32.2820510864258,,,10,,,,,,,,,,,,,,,,,,,,,,300.215209960937,300.239654541016,-560.274841308594,-560.274841308594,,,7.90983819961548,,1,0,0,0,0.013885498046875,32.2580642700195,1,1,1,300.215240478516,0,4232058592,300.230578613281,,,-0.00309831212578155,0.000154585676649083,-0.00309834983553926,0.000154585748142644,0.973109126091003,0.97354781627655,32.3004341125488,0,35,4,200,-0.0161550436168909,-0.385623097419739,1.20841717720032,1,,,,,,,,,,,,,,,,
,3885186458.59813,300.168075561523,-510.250732421875,,,6,,,,32.2820510864258,,,10,,,,,,,,,,,,,,,,,,,,,,300.152374267578,300.184295654297,-510.250732421875,-510.250732421875,,,7.91542482376099,,1,0,0,0,0.013885498046875,32.2580642700195,1,1,1,300.15185546875,0,4232058688,300.172915649414,,,-0.00296288651380822,0.000147828238179713,-0.00296291802817794,0.000147828284175598,0.973253607749939,0.973642230033875,32.29931640625,0,35,4,200,-0.0169039648026228,-0.38114333152771,1.10958099365234,1,,,,,,,,,,,,,,,,
,3885186576.21996,300.112274169922,-460.397705078125,,,6,,,,32.2820510864258,,,10,,,,,,,,,,,,,,,,,,,,,,300.099334716797,300.127319335937,-460.397705078125,-460.397705078125,,,7.9216570854187,,1,0,0,0,0.013885498046875,31.7693061828613,1,1,1,300.099029541016,0,4232058624,300.117947387695,,,-0.0028176160747291,0.000140578745937113,-0.00281764991475845,0.000140578785350312,0.973633587360382,0.974081933498383,32.3004570007324,5.37163987246458E-6,35,4,200,-0.0174750201404095,-0.353835701942444,1.06257796287537,1,,,,,,,,,,,,,,,,
,3885186693.2887,300.272872924805,-410.361389160156,,,6,,,,32.2820510864258,,,10,,,,,,,,,,,,,,,,,,,,,,300.271453857422,300.293395996094,-410.361389160156,-410.361389160156,,,7.92896318435669,,1,0,0,0,0.0147247314453125,28.3479976654053,1,1,1,300.271667480469,0,4232058752,300.282867431641,,,-0.00265926890371245,0.000132678755860582,-0.0026593022443768,0.000132678806882462,0.97353208065033,0.973994970321655,32.3007850646973,5.22905254364014,35,4,200,-0.015301370061934,-0.314893752336502,1.03373301029205,1,,,,,,,,,,,,,,,,
,3885186809.98103,300.204742431641,-360.312866210937,,,6,,,,32.2820510864258,,,10,,,,,,,,,,,,,,,,,,,,,,300.186614990234,300.223052978516,-360.312866210937,-360.312866210937,,,7.93533897399902,,1,0,0,0,0.013885498046875,31.7693061828613,1,1,1,300.186431884766,0,4232058624,300.210232543945,,,-0.0024843641214545,0.000123965594704288,-0.00248439689818248,0.000123965679317472,0.969737648963928,0.970153510570526,32.3010406494141,0,35,4,200,-0.0188033618032932,-0.325197696685791,0.930854439735413,1,,,,,,,,,,,,,,,,
,3885186929.34639,300.185256958008,-310.288757324219,,,6,,,,32.2820510864258,,,10,,,,,,,,,,,,,,,,,,,,,,300.183197021484,300.202514648438,-310.288757324219,-310.288757324219,,,7.94029378890991,,1,0,0,0,0.013885498046875,32.2580642700195,1,1,1,300.183074951172,0,4232058624,300.19436340332,,,-0.002300434370925,0.000114774298077506,-0.00230045333766331,0.000114774322852715,0.97390627861023,0.974215567111969,32.2972793579102,0.146155789494514,35,4,200,-0.0165016520768404,-0.255751460790634,0.912066876888275,1,,,,,,,,,,,,,,,,
,3885187043.31738,299.989471435547,-260.215759277344,,,6,,,,32.2820510864258,,,10,,,,,,,,,,,,,,,,,,,,,,299.965209960937,300.013763427734,-260.215759277344,-260.215759277344,,,7.94414901733398,,1,0,0,0,0.013885498046875,31.7693061828613,1,1,1,299.965179443359,0,4232058720,299.990197753906,,,-0.00208340267791421,0.000103949507337181,-0.00208341005985249,0.000103949493625045,0.97266811132431,0.972802817821503,32.292350769043,4.14658416048042E-6,35,4,200,-0.019025195389986,-0.279730588197708,0.778474271297455,1,,,,,,,,,,,,,,,,
,3885187157.42308,300.087173461914,-210.203887939453,,,6,,,,32.2820510864258,,,10,,,,,,,,,,,,,,,,,,,,,,300.081451416016,300.099060058594,-210.203887939453,-210.203887939453,,,7.94638013839722,,1,0,0,0,0.013885498046875,31.7693061828613,1,1,1,300.081207275391,0,4232058624,300.092028808594,,,-0.00183077556678909,9.1346396018402E-5,-0.00183078260720297,9.13464166262241E-5,0.972091555595398,0.972221434116364,32.2922744750977,0.162095114588737,35,4,200,-0.0185582637786865,-0.239581540226936,0.697857022285461,1,,,,,,,,,,,,,,,,
,3885187270.69232,300.07373046875,-160.167572021484,,,6,,,,32.2820510864258,,,10,,,,,,,,,,,,,,,,,,,,,,300.054840087891,300.093963623047,-160.167572021484,-160.167572021484,,,7.94700479507446,,1,0,0,0,0.013885498046875,31.7693061828613,1,1,1,300.092620849609,0,4232058688,300.081485324436,,,-0.00150932155657504,7.53068766738834E-5,-0.00150933071852487,7.53069098324449E-5,0.972365796566009,0.9725701212883,32.2948036193848,,35,4,200,-0.0160989034920931,-0.238878905773163,0.549118757247925,1,,,,,,,,,,,,,,,,
,3885187390.52483,300.344848632812,-110.094581604004,,,6,,,,32.2820510864258,,,10,,,,,,,,,,,,,,,,,,,,,,300.338623046875,300.366943359375,-110.094581604004,-110.094581604004,,,7.94822216033935,,1,0,0,0,0,31.7693061828613,1,1,1,300.35107421875,0,4232058688,300.356762695313,,,-0.00106012838280835,5.28965092100639E-5,-0.00106013191738133,5.28965233035939E-5,0.971083104610443,0.971189320087433,32.2914619445801,0,35,4,200,-0.0148481456562877,-0.173240885138512,0.40162718296051,1,,,,,,,,,,,,,,,,
,3885187509.36395,300.248504638672,-60.0949211120605,,,6,,,,32.2820510864258,,,10,,,,,,,,,,,,,,,,,,,,,,300.243255615234,300.267120361328,-60.0949211120605,-60.0949211120605,,,7.9480504989624,,1,0,0,0,0.013885498046875,31.7693061828613,1,1,1,300.253753662109,0,4232058656,300.258251953125,,,-0.000399125368731018,1.99400235611953E-5,-0.000399125960442777,1.99400238035925E-5,0.942092478275299,0.942117810249329,32.2755508422852,0.000200481794308871,35,4,200,-0.0155593110248446,-0.133446961641312,0.144896760582924,1,,,,,,,,,,,,,,,,
,3885187632.37429,300.140274047852,-9.97304344177246,,,6,,,,32.2820510864258,,,1,,,,,,,,,,,,,,,,,,,,,,300.122619628906,300.158843994141,-9.97304344177246,-9.97304344177246,,,7.9461259841919,,1,0,0,0,0.015869140625,31.7693061828613,1,1,1,300.157928466797,0,4232058624,300.149157714844,,,0.00041046366491364,2.04867083255485E-5,0.000410469782927623,2.04867325111412E-5,0.962203145027161,0.962567508220673,32.3020286560059,3.85524010658264,35,4,200,-0.166457697749138,-2.490389585495,0.00469260197132826,1,,,,,,,,,,,,,,,,
,3885187748.35294,300.175430297852,40.0388374328613,,,6,,,,32.2820510864258,,,1,,,,,,,,,,,,,,,,,,,,,,300.163726806641,300.194366455078,40.0388374328613,40.0388374328613,,,7.94297647476196,,1,0,0,0,0.013885498046875,32.2580642700195,1,1,1,300.187133789063,0,4232058624,300.18420715332,,,0.00106879542522585,5.33265975895591E-5,0.00106882558293443,5.33266619613328E-5,0.972656965255737,0.973662495613098,32.3100357055664,0,35,4,200,-0.172334060072899,-4.80715322494507,0.860435247421265,1,,,,,,,,,,,,,,,,
,3885187873.01975,300.155044555664,90.1851501464844,,,6,,,,32.2820510864258,,,10,,,,,,,,,,,,,,,,,,,,,,300.133514404297,300.176849365234,90.1851501464844,90.1851501464844,,,7.94592475891113,,1,0,0,0,0,31.7693061828613,1,1,1,300.133239746094,0,4232058624,300.157748413086,,,0.00151660053641114,7.56670143892761E-5,0.00151662229566664,7.56670979452997E-5,0.973858118057251,0.974369406700134,32.301628112793,0,35,4,200,-0.0166713036596775,-0.65727710723877,0.126499816775322,1,,,,,,,,,,,,,,,,
,3885187989.10209,300.141799926758,140.233703613281,,,6,,,,32.2820510864258,,,10,,,,,,,,,,,,,,,,,,,,,,300.130218505859,300.156799316406,140.233703613281,140.233703613281,,,7.94942617416382,,1,0,0,0,0.013885498046875,31.7693061828613,1,1,1,300.129150390625,0,4232058592,300.148434448242,,,0.00183730253934059,9.16626724371651E-5,0.00183732857579685,9.16627165235939E-5,0.976023018360138,0.976600646972656,32.3019561767578,5.22958374023438,35,4,200,-0.016285652294755,-0.80676007270813,0.134388327598572,1,,,,,,,,,,,,,,,,
,3885188106.56228,300.031768798828,190.257797241211,,,6,,,,32.2820510864258,,,10,,,,,,,,,,,,,,,,,,,,,,300.021118164063,300.044189453125,190.257797241211,190.257797241211,,,7.95238542556763,,1,0,0,0,0.0006866455078125,31.7693061828613,1,1,1,300.020111083984,0,4232058592,300.036828613281,,,0.00209280752185461,0.00010441755580862,0.00209285802409087,0.000104417670391142,0.973088443279266,0.973957777023315,32.3078651428223,0,35,4,200,-0.0188400875777006,-0.899795174598694,0.152709558606148,1,,,,,,,,,,,,,,,,
,3885188221.74878,300.114303588867,240.220794677734,,,6,,,,32.2820510864258,,,10,,,,,,,,,,,,,,,,,,,,,,300.099548339844,300.134399414063,240.220794677734,240.220794677734,,,7.95217609405518,,1,0,0,0,0,31.7693061828613,1,1,1,300.129058837891,0,4232058816,300.123699951172,,,0.00230391768605989,0.00011494370333682,0.00230395288320729,0.000114943794363831,0.975420415401459,0.976016581058502,32.3025131225586,0.0762511640787125,35,4,200,-0.0187730100005865,-0.924891173839569,0.237788468599319,1,,,,,,,,,,,,,,,,
,3885188336.80324,300.043563842773,290.269317626953,,,6,,,,32.2820510864258,,,10,,,,,,,,,,,,,,,,,,,,,,300.028839111328,300.058807373047,290.269317626953,290.269317626953,,,7.95265197753906,,1,0,0,0,0.013885498046875,32.2580642700195,1,1,1,300.058288574219,0,4232058624,300.04992980957,,,0.00249687882275487,0.000124574504138791,0.00249694817495619,0.000124574691937084,0.974190175533295,0.975228130817413,32.3096199035645,3.77239848603494E-5,35,4,200,-0.0187366120517254,-1.09674334526062,0.153274804353714,1,,,,,,,,,,,,,,,,
,3885188450.43444,299.941314697266,340.110107421875,,,6,,,,32.2820510864258,,,10,,,,,,,,,,,,,,,,,,,,,,299.927612304687,299.954864501953,340.110107421875,340.110107421875,,,7.95359325408936,,1,0,0,0,0,32.2580642700195,1,1,1,299.927764892578,0,4232058624,299.944979858398,,,0.00266789535876399,0.00013310521103427,0.00266794967626373,0.000133105342322746,0.974679172039032,0.975455701351166,32.3057250976562,0,35,4,200,-0.0184296108782291,-1.06452977657318,0.27196478843689,1,,,,,,,,,,,,,,,,
,3885188564.33283,299.93424987793,390.109771728516,,,6,,,,32.2820510864258,,,10,,,,,,,,,,,,,,,,,,,,,,299.917785644531,299.949615478516,390.109771728516,390.109771728516,,,7.95225763320923,,1,0,0,0,0,31.7693061828613,1,1,1,299.950714111328,0,4232058752,299.939981079102,,,0.00282325173866957,0.000140857391758304,0.00282332321170022,0.00014085746373231,0.974340081214905,0.975324988365173,32.3088302612305,5.22971200942993,35,4,200,-0.0164697039872408,-1.19628250598907,0.273280680179596,1,,,,,,,,,,,,,,,,
,3885188681.98273,300.107177734375,440.133850097656,,,6,,,,32.2820510864258,,,10,,,,,,,,,,,,,,,,,,,,,,300.086029052734,300.129852294922,440.133850097656,440.133850097656,,,7.95274353027344,,1,0,0,0,0.000457763671875,32.7468223571777,1,1,1,300.084503173828,0,4232058816,300.111901855469,,,0.00296878552257712,0.000148118448519325,0.00296887165131198,0.000148118595099989,0.974311530590057,0.975425779819489,32.3105125427246,,35,4,200,-0.0165383648127317,-1.24949824810028,0.241056993603706,1,,,,,,,,,,,,,,,,
,3885188800.72716,300.170028686523,490.145721435547,,,6,,,,32.2820510864258,,,10,,,,,,,,,,,,,,,,,,,,,,300.163238525391,300.186309814453,490.145721435547,490.145721435547,,,7.95452213287353,,1,0,0,0,0.017242431640625,31.7693061828613,1,1,1,300.176818847656,0,4232058560,300.177838134766,,,0.00310334898411579,0.000154835803450845,0.00310343729277787,0.000154835955612887,0.973394691944122,0.974447429180145,32.310230255127,0,35,4,200,-0.0177811197936535,-1.24504542350769,0.30817973613739,1,,,,,,,,,,,,,,,,
,3885188920.90069,300.206207275391,540.194274902344,,,6,,,,32.2820510864258,,,10,,,,,,,,,,,,,,,,,,,,,,300.201354980469,300.226715087891,540.194274902344,540.194274902344,,,7.95589923858643,,1,0,0,0,0,31.2805480957031,1,1,1,300.211059570313,0,4232058752,300.216387939453,,,0.00323469528033437,0.000161388615507122,0.00323481374973222,0.000161388701554874,0.973500370979309,0.974898219108582,32.3143539428711,0,35,4,200,-0.0167685952037573,-1.34443557262421,0.272807359695435,1,,,,,,,,,,,,,,,,
,3885189035.97039,299.970581054687,590.291687011719,,,6,,,,32.2820510864258,,,10,,,,,,,,,,,,,,,,,,,,,,299.954956054687,299.986450195313,590.291687011719,590.291687011719,,,7.95451354980469,,1,0,0,0,0.013885498046875,30.7917900085449,1,1,1,299.954711914063,0,4232058944,299.974267578125,,,0.00336308996094701,0.000167796742992353,0.00336321317741077,0.000167797008596677,0.973028659820557,0.974360287189484,32.313892364502,6.69306317035989E-8,35,4,200,-0.0226888433098793,-1.36760795116425,0.297019183635712,1,,,,,,,,,,,,,,,,
,3885189152.34155,300.080657958984,640.413635253906,,,6,,,,32.2820510864258,,,10,,,,,,,,,,,,,,,,,,,,,,300.062072753906,300.098724365234,640.413635253906,640.413635253906,,,7.95553207397461,,1,0,0,0,0,31.7693061828613,1,1,1,300.099243164063,0,4232058656,300.088726806641,,,0.0034803500131092,0.000173645625410016,0.00348048018701375,0.000173645929358495,0.973381757736206,0.974755644798279,32.3141593933105,INF,35,4,200,-0.0238387621939182,-1.49554538726807,0.325625032186508,1,,,,,,,,,,,,,,,,
,3885189269.67512,300.144714355469,690.2421875,,,6,,,,32.2820510864258,,,10,,,,,,,,,,,,,,,,,,,,,,300.136108398438,300.167358398438,690.2421875,690.2421875,,,7.95614433288574,,1,0,0,0,0.013885498046875,31.2805480957031,1,1,1,300.160919189453,0,4232058720,300.157691107856,,,0.00358188793264294,0.000178717119940623,0.00358203932129459,0.000178717346413455,0.972256779670715,0.973774969577789,32.316463470459,,35,4,200,-0.016432860866189,-1.44819533824921,0.341355204582214,1,,,,,,,,,,,,,,,,
,3885189386.83323,300.209014892578,740.290710449219,,,6,,,,32.2820510864258,,,10,,,,,,,,,,,,,,,,,,,,,,300.198791503906,300.226196289063,740.290710449219,740.290710449219,,,7.95667362213135,,1,0,0,0,0,31.7693061828613,1,1,1,300.21923828125,0,4232058752,300.217077636719,,,0.00369486010465889,0.000184349868557117,0.00369503109329613,0.000184350051896127,0.973041892051697,0.974776268005371,32.3182411193848,,35,4,200,-0.0288212690502405,-1.55973827838898,0.348231822252274,1,,,,,,,,,,,,,,,,
,3885189505.73732,300.221603393555,790.388122558594,,,6,,,,32.2820510864258,,,10,,,,,,,,,,,,,,,,,,,,,,300.212768554687,300.241333007812,790.388122558594,790.388122558594,,,7.95607185363769,,1,0,0,0,0.013885498046875,31.7693061828613,1,1,1,300.230438232422,0,4232058624,300.231866455078,,,0.00378485787379259,0.000188843415871941,0.00378501810781091,0.00018884373403427,0.97242134809494,0.973935842514038,32.3163185119629,0,35,4,200,-0.0233557466417551,-1.52435803413391,0.343930691480637,1,,,,,,,,,,,,,,,,
,3885189646.65799,300.109619140625,2500.20288085938,,,6,,,,32.2820510864258,,,10,,,,,,,,,,,,,,,,,,,,,,300.093872070313,300.131164550781,2500.20288085938,2500.20288085938,,,7.95425415039063,,1,0,0,0,0.0005340576171875,31.7693061828613,1,1,1,300.125366210937,0,4232058528,300.120333862305,,,0.00560896762567107,0.000279879916323766,0.00560936275677149,0.000279880674622112,0.96951699256897,0.971824467182159,32.326244354248,0,35,4,200,0.00539307156577706,-2.2405698299408,0.515334725379944,1,,,,,,,,,,,,,,,,
,3885189785.42935,300.033447265625,5000.25927734375,,,6,,,,32.2820510864258,,,10,,,,,,,,,,,,,,,,,,,,,,300.030212402344,300.042938232422,5000.25927734375,5000.25927734375,,,7.94654130935669,,1,0,0,0,0,32.2580642700195,1,1,1,300.030914306641,0,4232058528,300.037127685547,,,0.00630535069229054,0.000314655559884862,0.00630582426075409,0.000314655988109351,0.966821908950806,0.969121992588043,32.3281288146973,,35,4,200,0.0139877088367939,-2.44003582000732,0.704425156116486,1,,,,,,,,,,,,,,,,
,3885189929.83397,300.122711181641,7500.388671875,,,6,,,,32.2820510864258,,,10,,,,,,,,,,,,,,,,,,,,,,300.108703613281,300.145385742188,7500.388671875,7500.388671875,,,7.9482102394104,,1,0,0,0,0,31.2805480957031,1,1,1,300.13671875,0,4232058624,300.134222412109,,,0.00654344399791352,0.000326572107582381,0.00654406003742088,0.000326572893222159,0.963737785816193,0.966359198093414,32.3334121704102,0,35,4,200,0.0168807879090309,-2.54422497749329,0.692959070205688,1,,,,,,,,,,,,,,,,
,3885190080.88256,300.260818481445,10000.3955078125,,,6,,,,32.2820510864258,,,10,,,,,,,,,,,,,,,,,,,,,,300.250701904297,300.281494140625,10000.3955078125,10000.3955078125,,,7.94850397109985,,1,0,0,0,0.013885498046875,32.2580642700195,1,1,1,300.270935058594,0,4232058496,300.271148681641,,,0.00665816370387597,0.00033233922803912,0.00665888974311283,0.000332339648606503,0.96043986082077,0.963260769844055,32.3376846313477,5.22669887542725,35,4,200,0.00934992078691721,-2.59080767631531,0.707047462463379,1,,,,,,,,,,,,,,,,
,3885190229.16941,299.934234619141,35000.2265625,,,6,,,,32.2820510864258,,,10,,,,,,,,,,,,,,,,,,,,,,299.926147460937,299.946624755859,35000.2265625,35000.2265625,,,7.94399213790894,,1,0,0,0,0,31.7693061828613,1,1,1,299.926177978516,0,4232058432,299.939007568359,,,0.00683079457382314,0.000341630267963772,0.00683267921998511,0.000341631024156992,0.925819516181946,0.929584741592407,32.3701019287109,5.21591663360596,35,4,200,0.0145802637562156,-2.60390591621399,0.95330286026001,1,,,,,,,,,,,,,,,,
,3885190385.2608,300.229782104492,60000.2109375,,,6,,,,32.2820510864258,,,10,,,,,,,,,,,,,,,,,,,,,,300.228179931641,300.248870849609,60000.2109375,60000.2109375,,,7.94366216659546,,1,0,0,0,0,31.2805480957031,1,1,1,300.231384277344,0,4232058496,300.239849853516,,,0.00676323296724562,0.000339493770237843,0.00676748829931125,0.000339497916767855,0.887001395225525,0.892528474330902,32.4133071899414,5.69326877593994,35,4,200,0.0176832992583513,-2.55134010314941,1.14294385910034,1,,,,,,,,,,,,,,,,
,3885190545.34406,300.202392578125,55000.34765625,,,6,,,,32.2820510864258,,,10,,,,,,,,,,,,,,,,,,,,,,300.204895019531,300.220733642578,55000.34765625,55000.34765625,,,7.94391441345215,,1,0,0,0,0.013885498046875,31.7693061828613,1,1,1,300.202575683594,0,4232058496,300.213572184245,,,0.00678644267418241,0.000340411666028049,0.00679008887898928,0.000340414540715901,0.893535375595093,0.898566424846649,32.4037857055664,0,35,4,200,-0.0233434997498989,-2.67897725105286,1.03088557720184,1,,,,,,,,,,,,,,,,
,3885190703.95167,300.089157104492,30000.150390625,,,6,,,,32.2820510864258,,,10,,,,,,,,,,,,,,,,,,,,,,300.071624755859,300.112335205078,30000.150390625,30000.150390625,,,7.93984746932983,,1,0,0,0,0.013885498046875,32.2580642700195,1,1,1,300.106689453125,0,4232058400,300.100225830078,,,0.00683742931239506,0.000341806625565534,0.00683914782534689,0.00034180884895863,0.932190477848053,0.935885548591614,32.3654632568359,0.000326776440488175,35,4,200,-0.0307938065379858,-2.76908755302429,0.800372660160065,1,,,,,,,,,,,,,,,,
,3885190861.90003,300.023056030273,9500.240234375,,,6,,,,32.2820510864258,,,10,,,,,,,,,,,,,,,,,,,,,,300.020477294922,300.041320800781,9500.240234375,9500.240234375,,,7.94112730026245,,1,0,0,0,0.0159454345703125,33.2355842590332,1,1,1,300.025634765625,0,4232058752,300.031774902344,,,0.00664253030936972,0.000331549306906042,0.00664324732797873,0.000331550440503478,0.961172342300415,0.963960528373718,32.3368492126465,9.46578657021746E-5,35,4,200,-0.0487516447901726,-2.71429634094238,0.593942284584045,1,,,,,,,,,,,,,,,,
,3885191004.87001,300.038162231445,7000.40380859375,,,6,,,,32.2820510864258,,,10,,,,,,,,,,,,,,,,,,,,,,300.027618408203,300.054107666016,7000.40380859375,7000.40380859375,,,7.94120931625366,,1,0,0,0,0.013885498046875,32.2580642700195,1,1,1,300.02734375,0,4232058624,300.044808959961,,,0.00651017950285435,0.000324904818317488,0.00651077639764098,0.000324905206105858,0.964345514774323,0.966977596282959,32.3330764770508,0,35,4,200,-0.0287045799195766,-2.61441087722778,0.669665694236755,1,,,,,,,,,,,,,,,,
,3885191149.74751,300.093490600586,4500.44580078125,,,6,,,,32.2820510864258,,,10,,,,,,,,,,,,,,,,,,,,,,300.081207275391,300.11376953125,4500.44580078125,4500.44580078125,,,7.9395809173584,,1,0,0,0,0.013885498046875,31.7693061828613,1,1,1,300.105773925781,0,4232058592,300.103253173828,,,0.00621913689595883,0.000310348281758022,0.00621964171115177,0.000310348939815767,0.967304110527039,0.969815850257874,32.329776763916,0,35,4,200,-0.0275906790047884,-2.49291491508484,0.586450755596161,1,,,,,,,,,,,,,,,,
,3885191293.61373,300.139099121094,2000.45068359375,,,6,,,,32.2820510864258,,,10,,,,,,,,,,,,,,,,,,,,,,300.129486083984,300.158264160156,2000.45068359375,2000.45068359375,,,7.93797588348389,,1,0,0,0,0.013885498046875,31.7693061828613,1,1,1,300.148712158203,0,4232058560,300.148907470703,,,0.00524604534437407,0.000261763351591573,0.00524636797592178,0.000261763832882487,0.970432281494141,0.9725221991539,32.3235397338867,,35,4,200,-0.0263867918401957,-2.14173293113709,0.455030292272568,1,,,,,,,,,,,,,,,,
,3885191432.12279,300.112380981445,780.036193847656,,,6,,,,32.2820510864258,,,10,,,,,,,,,,,,,,,,,,,,,,300.108734130859,300.128753662109,780.036193847656,780.036193847656,,,7.93784141540527,,1,0,0,0,0.013885498046875,32.2580642700195,1,1,1,300.116027832031,0,4232058720,300.120816040039,,,0.00362570910089296,0.00018089759322908,0.00362582285563622,0.000180897812250814,0.973477005958557,0.974638938903809,32.3115692138672,0,35,4,200,0.00327392551116645,-1.46646547317505,0.391865938901901,1,,,,,,,,,,,,,,,,
,3885191546.81144,300.100509643555,729.963256835938,,,6,,,,32.2820510864258,,,10,,,,,,,,,,,,,,,,,,,,,,300.078704833984,300.122741699219,729.963256835938,729.963256835938,,,7.93769884109497,,1,0,0,0,0.013885498046875,31.7693061828613,1,1,1,300.078277587891,0,4232058624,300.103964233398,,,0.00351506756576878,0.000175379472336939,0.00351516456832459,0.000175379761392846,0.973013341426849,0.973991930484772,32.3094291687012,0,35,4,200,0.0177399255335331,-1.34180617332458,0.415454149246216,1,,,,,,,,,,,,,,,,
,3885191657.60171,300.162872314453,679.939086914062,,,6,,,,32.2820510864258,,,10,,,,,,,,,,,,,,,,,,,,,,300.151428222656,300.180755615234,679.939086914062,679.939086914062,,,7.93878793716431,,1,0,0,0,0.013885498046875,32.2580642700195,1,1,1,300.17431640625,0,4232058624,300.171029663086,,,0.00339950594275855,0.000169614748085923,0.00339959679849197,0.000169614895669339,0.972785830497742,0.973752379417419,32.3093757629395,0,35,4,200,0.0172361638396978,-1.28916251659393,0.412704885005951,1,,,,,,,,,,,,,,,,
,3885191768.0503,300.066040039063,630.037231445313,,,6,,,,32.2820510864258,,,10,,,,,,,,,,,,,,,,,,,,,,300.056427001953,300.077941894531,630.037231445313,630.037231445313,,,7.93900203704834,,1,0,0,0,0,31.7693061828613,1,1,1,300.075653076172,0,4232058752,300.070706176758,,,0.00328110754002561,0.000163707022666244,0.00328118039322079,0.000163707330296393,0.972865700721741,0.9736248254776,32.3062744140625,,35,4,200,0.0175109524279833,-1.27545964717865,0.370570927858353,1,,,,,,,,,,,,,,,,
,3885191880.24176,300.117401123047,580.196472167969,,,6,,,,32.2820510864258,,,10,,,,,,,,,,,,,,,,,,,,,,300.108917236328,300.135711669922,580.196472167969,580.196472167969,,,7.93915462493896,,1,0,0,0,0.0147247314453125,32.7468223571777,1,1,1,300.125885009766,0,4232058624,300.126647949219,,,0.00315674026287465,0.00015749886066435,0.00315679828548575,0.000157498899954087,0.973580598831177,0.974275588989258,32.3049354553223,0,35,4,200,0.0157888643443584,-1.20649182796478,0.380813241004944,1,,,,,,,,,,,,,,,,
,3885191997.94556,300.252822875977,530.14794921875,,,6,,,,32.2820510864258,,,10,,,,,,,,,,,,,,,,,,,,,,300.252166748047,300.272094726562,530.14794921875,530.14794921875,,,7.94124984741211,,1,0,0,0,0.013885498046875,32.2580642700195,1,1,1,300.251770019531,0,4232058624,300.262344360352,,,0.00302163741153679,0.00015075849199983,0.00302170692326092,0.000150758617840704,0.973513126373291,0.974363207817078,32.3073539733887,,35,4,200,0.0157029964029789,-1.2085188627243,0.345824718475342,1,,,,,,,,,,,,,,,,
,3885192116.60707,300.136810302734,480.148284912109,,,6,,,,32.2820510864258,,,10,,,,,,,,,,,,,,,,,,,,,,300.125671386719,300.158538818359,480.148284912109,480.148284912109,,,7.93979167938232,,1,0,0,0,0,32.2580642700195,1,1,1,300.14794921875,0,4232058752,300.146780395508,,,0.00287936288408528,0.000143660323370012,0.00287942009328653,0.000143660517878979,0.973408877849579,0.974114000797272,32.30517578125,5.68376398086548,35,4,200,0.0166864339262247,-1.11890077590942,0.3305544257164,1,,,,,,,,,,,,,,,,
,3885192230.30251,300.153579711914,430.063018798828,,,6,,,,32.2820510864258,,,10,,,,,,,,,,,,,,,,,,,,,,300.130615234375,300.175415039063,430.063018798828,430.063018798828,,,7.93966817855835,,1,0,0,0,0.013885498046875,32.2580642700195,1,1,1,300.176544189453,0,4232058656,300.162075805664,,,0.00272597968685141,0.000136009069811425,0.00272602666873173,0.000136009166030156,0.97301185131073,0.973630905151367,32.303897857666,5.22878503799438,35,4,200,0.0175360068678856,-1.07413995265961,0.30008652806282,1,,,,,,,,,,,,,,,,
,3885192340.88142,300.093811035156,380.051177978516,,,6,,,,32.2820510864258,,,10,,,,,,,,,,,,,,,,,,,,,,300.063720703125,300.1240234375,380.051177978516,380.051177978516,,,7.94001150131226,,1,0,0,0,0.013885498046875,32.2580642700195,1,1,1,300.063598632812,0,4232058592,300.094241333008,,,0.00256553406982745,0.000127999380648913,0.00256557387977162,0.000127999501851967,0.974336326122284,0.974910140037537,32.3025703430176,5.68353509902954,35,4,200,0.0194549616426229,-0.943700313568115,0.341857969760895,1,,,,,,,,,,,,,,,,
,3885192455.40862,300.220031738281,330.039306640625,,,6,,,,32.2820510864258,,,10,,,,,,,,,,,,,,,,,,,,,,300.211547851562,300.242004394531,330.039306640625,330.039306640625,,,7.94062948226929,,1,0,0,0,0,32.2580642700195,1,1,1,300.228515625,0,4232058592,300.231103515625,,,0.00238471051101042,0.000118976169537116,0.00238474922968494,0.000118976329667067,0.974860429763794,0.975459456443787,32.3027992248535,,35,4,200,0.0158695951104164,-0.940309882164001,0.268933981657028,1,,,,,,,,,,,,,,,,
,3885192570.0033,300.190795898438,279.941864013672,,,6,,,,32.2820510864258,,,10,,,,,,,,,,,,,,,,,,,,,,300.173614501953,300.207977294922,279.941864013672,279.941864013672,,,7.94102668762207,,1,0,0,0,0.013885498046875,32.2580642700195,1,1,1,300.173614501953,0,4232058784,300.195559692383,,,0.00217698808635268,0.000108617773184926,0.00217701271355821,0.000108617856198944,0.97304630279541,0.973440229892731,32.299503326416,5.683265209198,35,4,200,0.01805111579597,-0.812102556228638,0.292670130729675,1,,,,,,,,,,,,,,,,
,3885192685.88318,300.045379638672,229.893310546875,,,6,,,,32.2820510864258,,,10,,,,,,,,,,,,,,,,,,,,,,300.027984619141,300.059539794922,229.893310546875,229.893310546875,,,7.94092273712158,,1,0,0,0,0.013885498046875,32.2580642700195,1,1,1,300.027679443359,0,4232058624,300.046410454644,,,0.00194604158818398,9.70899676315034E-5,0.00194606251896969,9.70900380440687E-5,0.975036799907684,0.975441634654999,32.2990798950195,0,35,4,200,0.0171648878604174,-0.72726309299469,0.265288859605789,1,,,,,,,,,,,,,,,,
,3885192801.93286,300.011627197266,180.015869140625,,,6,,,,32.2820510864258,,,10,,,,,,,,,,,,,,,,,,,,,,300.005310058594,300.027069091797,180.015869140625,180.015869140625,,,7.94114112854004,,1,0,0,0,0,32.2580642700195,1,1,1,300.017944335937,0,4232058688,300.018460083008,,,0.00165582204292715,8.26122831057502E-5,0.00165584726611692,8.26124018194425E-5,0.974256753921509,0.974798023700714,32.3020133972168,0,35,4,200,0.0161489173769951,-0.670115470886231,0.226509988307953,1,,,,,,,,,,,,,,,,
,3885192915.84688,300.200866699219,129.955108642578,,,6,,,,32.2820510864258,,,10,,,,,,,,,,,,,,,,,,,,,,300.183319091797,300.222412109375,129.955108642578,129.955108642578,,,7.94232654571533,,1,0,0,0,0.013885498046875,31.7693061828613,1,1,1,300.218414306641,0,4232058784,300.210903930664,,,0.00126704553193456,6.32177448130486E-5,0.00126706437697736,6.32178428134972E-5,0.972873687744141,0.973369002342224,32.3016700744629,0.191233932971954,35,4,200,0.0168139152228832,-0.496202111244202,0.174417957663536,1,,,,,,,,,,,,,,,,
,3885193028.7009,300.104827880859,79.9065628051758,,,6,,,,32.2820510864258,,,10,,,,,,,,,,,,,,,,,,,,,,300.089874267578,300.119567871094,79.9065628051758,79.9065628051758,,,7.9432110786438,,1,0,0,0,0.013885498046875,31.7693061828613,1,1,1,300.090087890625,0,4232058592,300.108975219727,,,0.000699523399461778,3.4909750112085E-5,0.000699523581799377,3.49097525058485E-5,0.965582191944122,0.965587794780731,32.2844085693359,0,35,4,200,0.0177181493490934,-0.302009373903275,0.0882560238242149,1,,,,,,,,,,,,,,,,
,3885193155.35211,300.11311340332,30.029125213623,,,6,,,,32.2820510864258,,,1,,,,,,,,,,,,,,,,,,,,,,300.089874267578,300.137481689453,30.029125213623,30.029125213623,,,7.94457101821899,,1,0,0,0,0,31.7693061828613,1,1,1,300.088745117188,0,4232058720,300.115469360352,,,-8.10539885160905E-5,4.1133827485016E-6,-8.10771167949444E-5,4.11341540194918E-6,0.815292477607727,0.816749036312103,32.3735122680664,3.85527968406677,35,4,200,0.173307538032532,-0.353884875774384,0.613308787345886,1,,,,,,,,,,,,,,,,
,3885193270.63666,300.206558227539,-20.0071964263916,,,6,,,,32.2820510864258,,,1,,,,,,,,,,,,,,,,,,,,,,300.190368652344,300.228240966797,-20.0071964263916,-20.0071964263916,,,7.94624948501587,,1,0,0,0,0.012969970703125,31.7693061828613,1,1,1,300.222747802734,0,4232058624,300.216870117188,,,-0.00082140824247742,4.09890577459582E-5,-0.000821445672832571,4.0989132391249E-5,0.968038618564606,0.969436585903168,32.3176574707031,0,35,4,200,0.1592036485672,-0.48614826798439,4.01819896697998,1,,,,,,,,,,,,,,,,
,3885193398.31363,300.227111816406,-70.1168518066406,,,6,,,,32.2820510864258,,,10,,,,,,,,,,,,,,,,,,,,,,300.219604492188,300.247344970703,-70.1168518066406,-70.1168518066406,,,7.94674682617187,,1,0,0,0,0,31.7693061828613,1,1,1,300.234619140625,0,4232058688,300.235003662109,,,-0.00134843413964246,6.72734840723764E-5,-0.00134846341525056,6.72735588981979E-5,0.975807011127472,0.976673483848572,32.306468963623,0,35,4,200,0.0133461533114314,-0.161933675408363,0.575358152389526,1,,,,,,,,,,,,,,,,
,3885193515.08106,300.106979370117,-120.104286193848,,,6,,,,32.2820510864258,,,10,,,,,,,,,,,,,,,,,,,,,,300.089996337891,300.126953125,-120.104286193848,-120.104286193848,,,7.94673776626587,,1,0,0,0,0.013885498046875,31.7693061828613,1,1,1,300.123962402344,0,4232058848,300.116027832031,,,-0.00171646872677538,8.56367727578155E-5,-0.00171651438542777,8.56368989628313E-5,0.974843740463257,0.975862562656403,32.3090209960937,0.191253483295441,35,4,200,0.0157674867659807,-0.129070535302162,0.753891706466675,1,,,,,,,,,,,,,,,,
,3885193633.50384,300.254409790039,-170.128387451172,,,6,,,,32.2820510864258,,,10,,,,,,,,,,,,,,,,,,,,,,300.252624511719,300.268768310547,-170.128387451172,-170.128387451172,,,7.94744062423706,,1,0,0,0,0.013885498046875,31.7693061828613,1,1,1,300.252197265625,0,4232058976,300.261056518555,,,-0.00199617482238529,9.95932795640817E-5,-0.00199622761546727,9.95933991104395E-5,0.974208414554596,0.975205957889557,32.3090896606445,0,35,4,200,0.0179127398878336,-0.207053244113922,0.802844226360321,1,,,,,,,,,,,,,,,,
,3885193749.71304,300.173873901367,-219.969146728516,,,6,,,,32.2820510864258,,,10,,,,,,,,,,,,,,,,,,,,,,300.164245605469,300.194396972656,-219.969146728516,-219.969146728516,,,7.9481086730957,,1,0,0,0,0,32.2580642700195,1,1,1,300.183502197266,0,4232058688,300.183743286133,,,-0.00221963911815401,0.000110740678457046,-0.00221969809695586,0.000110740885444451,0.97480833530426,0.975808143615723,32.3087844848633,0,35,4,200,0.0174899380654097,-0.231674879789352,0.950183093547821,1,,,,,,,,,,,,,,,,
,3885193866.33481,300.092193603516,-269.968811035156,,,6,,,,32.2820510864258,,,10,,,,,,,,,,,,,,,,,,,,,,300.081237792969,300.110198974609,-269.968811035156,-269.968811035156,,,7.94909906387329,,1,0,0,0,0.013885498046875,31.7693061828613,1,1,1,300.103149414063,0,4232058688,300.101168823242,,,-0.00242103782772543,0.000120788026219564,-0.00242110709492011,0.000120788113907418,0.975038111209869,0.976180672645569,32.3104667663574,0,35,4,200,0.017618652433157,-0.216839075088501,1.00166666507721,1,,,,,,,,,,,,,,,,
,3885193980.29058,299.975128173828,-320.054016113281,,,6,,,,32.2820510864258,,,10,,,,,,,,,,,,,,,,,,,,,,299.973510742188,299.986389160156,-320.054016113281,-320.054016113281,,,7.94847774505615,,1,0,0,0,0.013885498046875,32.2580642700195,1,1,1,299.97412109375,0,4232058816,299.979620361328,,,-0.00259588910511276,0.000129515752049749,-0.00259597071338543,0.000129515902358135,0.973765432834625,0.974945247173309,32.311637878418,0,35,4,200,0.0176034457981586,-0.279833644628525,1.02228736877441,1,,,,,,,,,,,,,,,,
,3885194096.85061,300.184814453125,-370.017028808594,,,6,,,,32.2820510864258,,,10,,,,,,,,,,,,,,,,,,,,,,300.171203613281,300.207092285156,-370.017028808594,-370.017028808594,,,7.95046710968018,,1,0,0,0,0.013885498046875,31.7693061828613,1,1,1,300.198425292969,0,4232058816,300.195611572266,,,-0.00275678582630223,0.000137543086582584,-0.002756880172812,0.000137543254435335,0.973820865154266,0.975112557411194,32.3129501342773,0,35,4,200,0.0167710836976767,-0.242052987217903,1.14285695552826,1,,,,,,,,,,,,,,,,
,3885194211.79196,300.134033203125,-420.053314208984,,,6,,,,32.2820510864258,,,10,,,,,,,,,,,,,,,,,,,,,,300.120056152344,300.154418945313,-420.053314208984,-420.053314208984,,,7.95306873321533,,1,0,0,0,0.013885498046875,31.2805480957031,1,1,1,300.148010253906,0,4232058656,300.143197631836,,,-0.00290880131104951,0.000145125834695523,-0.00290890599138488,0.00014512606985787,0.974285662174225,0.975657880306244,32.3135757446289,INF,35,4,200,0.0149041153490543,-0.285224348306656,1.17683219909668,1,,,,,,,,,,,,,,,,
,3885194330.0739,300.155181884766,-470.028533935547,,,6,,,,32.2820510864258,,,10,,,,,,,,,,,,,,,,,,,,,,300.147979736328,300.174682617188,-470.028533935547,-470.028533935547,,,7.9543285369873,,1,0,0,0,0.01495361328125,31.7693061828613,1,1,1,300.162384033203,0,4232058624,300.164886474609,,,-0.00304882187458084,0.000152115494447296,-0.00304896630600272,0.000152116133670799,0.973329126834869,0.974998950958252,32.3173828125,0,35,4,200,0.01498484890908,-0.250559687614441,1.28128445148468,1,,,,,,,,,,,,,,,,
,3885194449.4598,300.220993041992,-520.11376953125,,,6,,,,32.2820510864258,,,10,,,,,,,,,,,,,,,,,,,,,,300.217102050781,300.236083984375,-520.11376953125,-520.11376953125,,,7.95529556274414,,1,0,0,0,0.013885498046875,31.7693061828613,1,1,1,300.224884033203,0,4232058624,300.228234863281,,,-0.00318346884801458,0.000158837641926473,-0.00318362495630241,0.000158837922969028,0.972367167472839,0.974132895469666,32.319019317627,3.85527968406677,35,4,200,0.0175001062452793,-0.285573840141296,1.3053811788559,1,,,,,,,,,,,,,,,,
,3885194564.25409,299.945983886719,-570.150085449219,,,6,,,,32.2820510864258,,,10,,,,,,,,,,,,,,,,,,,,,,299.938385009766,299.955627441406,-570.150085449219,-570.150085449219,,,7.95664262771606,,1,0,0,0,0.0139617919921875,31.7693061828613,1,1,1,299.939819335937,0,4232058688,299.948880004883,,,-0.00330945381884153,0.000165124623149102,-0.00330959238879846,0.000165124756887468,0.972142398357391,0.973656356334686,32.3165092468262,0,35,4,200,0.020832683891058,-0.245610520243645,1.38996362686157,1,,,,,,,,,,,,,,,,
,3885194685.38136,300.199661254883,-620.149780273437,,,6,,,,32.2820510864258,,,10,,,,,,,,,,,,,,,,,,,,,,300.19091796875,300.217681884766,-620.149780273437,-620.149780273437,,,7.95746755599976,,1,0,0,0,0.013885498046875,31.7693061828613,1,1,1,300.208404541016,0,4232058624,300.208828735352,,,-0.00342513233828974,0.000170898066463541,-0.00342533024124239,0.000170898515991585,0.971793293952942,0.97381979227066,32.3219795227051,0,35,4,200,0.0188543107360601,-0.27748441696167,1.42411255836487,1,,,,,,,,,,,,,,,,
,3885194802.11347,300.13053894043,-670.186096191406,,,6,,,,32.2820510864258,,,10,,,,,,,,,,,,,,,,,,,,,,300.122894287109,300.148834228516,-670.186096191406,-670.186096191406,,,7.95775318145752,,1,0,0,0,0.013885498046875,31.7693061828613,1,1,1,300.13818359375,0,4232058752,300.139312744141,,,-0.0035401246239551,0.000176632554869576,-0.00354030870526045,0.000176632890429614,0.972425818443298,0.974305391311646,32.3201141357422,0,35,4,200,0.0217879991978407,-0.342915564775467,1.40678596496582,1,,,,,,,,,,,,,,,,
,3885194917.35595,300.064208984375,-720.02685546875,,,6,,,,32.2820510864258,,,10,,,,,,,,,,,,,,,,,,,,,,300.056976318359,300.07763671875,-720.02685546875,-720.02685546875,,,7.95798969268799,,1,0,0,0,0.013885498046875,31.7693061828613,1,1,1,300.057037353516,0,4232058592,300.070538330078,,,-0.00365214551371661,0.000182228267264523,-0.00365234844907759,0.000182228396978264,0.971157550811768,0.973124980926514,32.3218803405762,0,35,4,200,0.0242264103144407,-0.297827690839767,1.51044797897339,1,,,,,,,,,,,,,,,,
,3885195030.2688,300.068115234375,-770.087585449219,,,6,,,,32.2820510864258,,,10,,,,,,,,,,,,,,,,,,,,,,300.061737060547,300.080505371094,-770.087585449219,-770.087585449219,,,7.96036434173584,,1,0,0,0,0,31.7693061828613,1,1,1,300.061828613281,0,4232058592,300.073379516602,,,-0.00375391476734098,0.000187303998579161,-0.00375409133069252,0.000187304489722829,0.971570372581482,0.973176717758179,32.3178863525391,0,35,4,200,0.0271565522998571,-0.362326472997665,1.57079017162323,1,,,,,,,,,,,,,,,,
,3885195151.13597,300.144439697266,-1499.84301757813,,,6,,,,32.2820510864258,,,10,,,,,,,,,,,,,,,,,,,,,,300.119079589844,300.170623779297,-1499.84301757813,-1499.84301757813,,,7.95823001861572,,1,0,0,0,0.013885498046875,31.7693061828613,1,1,1,300.118255615234,0,4232058560,300.147274780273,,,-0.00484134087408693,0.000241560779469675,-0.00484162245328335,0.000241561553996429,0.971717596054077,0.973730862140655,32.3218879699707,0,35,4,200,9.82152705546468E-5,-0.477668702602386,1.87557566165924,1,,,,,,,,,,,,,,,,
,3885195268.06304,300.097702026367,-4000.37573242188,,,6,,,,32.2820510864258,,,10,,,,,,,,,,,,,,,,,,,,,,300.092163085937,300.114715576172,-4000.37573242188,-4000.37573242188,,,7.96046590805054,,1,0,0,0,0.013885498046875,31.2805480957031,1,1,1,300.103240966797,0,4232058560,300.106173706055,,,-0.00612742755778353,0.000305768601980494,-0.00612797140636842,0.000305769932194311,0.96762490272522,0.97034353017807,32.3313636779785,0,35,4,200,-0.0044669141061604,-0.567950665950775,2.43449473381042,1,,,,,,,,,,,,,,,,
,3885195386.50242,300.14372253418,-6500.3095703125,,,6,,,,32.2820510864258,,,10,,,,,,,,,,,,,,,,,,,,,,300.121215820313,300.166625976562,-6500.3095703125,-6500.3095703125,,,7.96008682250977,,1,0,0,0,0.013885498046875,31.7693061828613,1,1,1,300.120819091797,0,4232058528,300.148065185547,,,-0.00647091895091849,0.00032294187128084,-0.00647157253733209,0.000322943574787187,0.964653789997101,0.967471122741699,32.3345336914063,0,35,4,200,-0.00963223818689585,-0.73198676109314,2.46969413757324,1,,,,,,,,,,,,,,,,
,3885195506.25262,300.113464355469,-9000.21875,,,6,,,,32.2820510864258,,,10,,,,,,,,,,,,,,,,,,,,,,300.103057861328,300.132293701172,-9000.21875,-9000.21875,,,7.96063184738159,,1,0,0,0,0.013885498046875,31.7693061828613,1,1,1,300.123870849609,0,4232058592,300.122842407227,,,-0.0066208685524311,0.000330462873155518,-0.00662162978902489,0.000330464387809557,0.96157717704773,0.964562118053436,32.3383674621582,0,35,4,200,-0.0105567779392004,-0.708250105381012,2.57512307167053,1,,,,,,,,,,,,,,,,
,3885195654.09705,300.156509399414,-25000.365234375,,,6,,,,32.2820510864258,,,10,,,,,,,,,,,,,,,,,,,,,,300.153686523438,300.174438476562,-25000.365234375,-25000.365234375,,,7.96750688552856,,1,0,0,0,0.01495361328125,32.2580642700195,1,1,1,300.159332275391,0,4232058368,300.166024780273,,,-0.00683044749109299,0.000341287514963706,-0.00683199950950184,0.000341290371845609,0.939958691596985,0.943707942962647,32.3610000610352,0,35,4,200,-0.0156439989805222,-0.896887540817261,2.65420627593994,1,,,,,,,,,,,,,,,,
,3885195806.27663,300.198455810547,-50000.36328125,,,6,,,,32.2820510864258,,,10,,,,,,,,,,,,,,,,,,,,,,300.194458007812,300.217559814453,-50000.36328125,-50000.36328125,,,7.96869611740112,,1,0,0,0,0.013885498046875,31.7693061828613,1,1,1,300.202453613281,0,4232058752,300.208703613281,,,-0.00677825305255444,0.000339807656535147,-0.00678213591118634,0.000339812347944209,0.898958325386047,0.904593110084534,32.4073371887207,0.000164894547197036,35,4,200,-0.0125490808859467,-1.0687016248703,2.59077930450439,1,,,,,,,,,,,,,,,,
,3885195927.21153,300.125106811523,-70000.265625,,,6,,,,32.2820510864258,,,10,,,,,,,,,,,,,,,,,,,,,,300.119750976562,300.139953613281,-70000.265625,-70000.265625,,,7.97212505340576,,1,0,0,0,0.013885498046875,31.7693061828613,1,1,1,300.130462646484,0,4232058656,300.132037353516,,,-0.00672264436686939,0.000338111721939145,-0.0067284167934478,0.000338120872057043,0.871191322803497,0.877707540988922,32.4339561462402,0,35,4,200,-0.0301843229681253,-1.3134822845459,2.44001436233521,1,,,,,,,,,,,,,,,,