File: Data/KMK242S/MvsH/KMK242S_MvsH_300K.dat
[Header]
; MPMS3 Data File (default extension .dat)
; Copyright (c) 2007, Quantum Design, Inc. All rights reserved.
TITLE,
FILEOPENTIME,3870522287.53796,08/24/2022,5:04 pm
BYAPP,MPMS3 w/ AC,1.0,1.1
INFO,MPMS3 Measurement Release 1.1.16 Build 424, MultiVu Release 2.3.4.19,APPNAME
INFO,Linear Motor Servo Controller,MOTOR_MODULE_NAME
INFO,3101-100 J0,MOTOR_HW_VERSION
INFO,MMC721,MOTOR_SERIAL_NUMBER
INFO,01.04.28,MOTOR_SOFTWARE_VERSION
INFO,Quantum Design Squid Module,SQUID_MODULE_NAME
INFO,3101-501 B0,SQUID_HW_VERSION
INFO,SQM195,SQUID_SERIAL_NUMBER
INFO,01.03.04,SQUID_SOFTWARE_VERSION
INFO,SQUID AC,AC_MODULE_NAME
INFO,3101-401 f1,AC_HW_VERSION
INFO,SAC107,AC_SERIAL_NUMBER
INFO,SQUID AC 00.95.07,AC_SOFTWARE_VERSION
INFO,TCI166,COIL_SERIAL_NUMBER
INFO,0,MOMENT_UNITS
INFO,KMK242S,SAMPLE_MATERIAL
INFO,,SAMPLE_COMMENT
INFO,1.9,SAMPLE_MASS
INFO,,SAMPLE_VOLUME
INFO,,SAMPLE_MOLECULAR_WEIGHT
INFO,,SAMPLE_SIZE
INFO,,SAMPLE_SHAPE
INFO,Straw,SAMPLE_HOLDER
INFO,Standard,SAMPLE_HOLDER_DETAIL
INFO,66.09,SAMPLE_OFFSET
DATATYPE,COMMENT,1
DATATYPE,TIME,2
STARTUPAXIS,X,2
STARTUPAXIS,Y1,5
FIELDGROUP, VSM,2,3,4,5,6,8,9,10,11,14,15
FIELDGROUP, DC, 2,3,4,14,56,57,58,59,60,61,62,63,64,65,66,67,68,69
FIELDGROUP, AC, 2,3,4,11,16,17,18,19,20,21,22,23,24,25,26,27,28,29,30
STARTUPGROUP, All
[Data]
Comment,Time Stamp (sec),Temperature (K),Magnetic Field (Oe),Moment (emu),M. Std. Err. (emu),Transport Action,Averaging Time (sec),Frequency (Hz),Peak Amplitude (mm),Center Position (mm),Lockin Signal' (V),Lockin Signal (V),Range,M. Quad. Signal (emu),AC Moment (emu),AC M. Std Err. (emu),AC Phase (deg),AC Phase Std. Err. (deg),AC Susceptibility (emu/Oe),AC Suscept. Std Err. (emu/Oe),AC X' (emu/Oe),AC X' Std Err. (emu/Oe),AC X'' (emu/Oe),AC X'' Std Err. (emu/Oe),AC Drive (Oe),AC Frequency (Hz),AC Averaging Time (sec),AC Cycles,AC Range,AC Measure Type,AC Signal' (V),AC Signal'' (V),AC Trim Coil Ratio,AC Trim Coil Phase,Min. Temperature (K),Max. Temperature (K),Min. Field (Oe),Max. Field (Oe),Mass (grams),Motor Lag (deg),Pressure (Torr),Measure Count,Measurement Number,SQUID Status (code),Motor Status (code),Measure Status (code),Motor Current (amps),Motor Temp. (C),Temp. Status (code),Field Status (code),Chamber Status (code),Chamber Temp (K),Redirection State,Evercool Status,Average Temp (K),Rotation Angle (deg),Rotator state,DC Moment Fixed Ctr (emu),DC Moment Err Fixed Ctr (emu),DC Moment Free Ctr (emu),DC Moment Err Free Ctr (emu),DC Fixed Fit,DC Free Fit,DC Calculated Center (mm),DC Calculated Center Err (mm),DC Scan Length (mm),DC Scan Time (s),DC Number of Points,DC Squid Drift,DC Min V (V),DC Max V (V),DC Scans per Measure,Map 01,Map 02,Map 03,Map 04,Map 05,Map 06,Map 07,Map 08,Map 09,Map 10,Map 11,Map 12,Map 13,Map 14,Map 15,Map 16
,3870522426.62238,299.971466064453,-70000.3515625,,,6,,,,33.6600112915039,,,10,,,,,,,,,,,,,,,,,,,,,,299.965698242188,299.980773925781,-70000.3515625,-70000.3515625,,,7.55376291275024,,1,0,0,0,0.0138092041015625,31.2805480957031,1,1,1,299.966461181641,0,4232058656,299.975323486328,,,-0.00196387117812177,0.000103901167938356,-0.0019709830116122,0.000103908701822828,0.647351264953613,0.656291425228119,33.9615631103516,0,35,4,200,-0.0299140997231007,-0.818298578262329,0.527120888233185,1,,,,,,,,,,,,,,,,
,3870522582.19044,300.124816894531,-45000.25390625,,,6,,,,33.6600112915039,,,10,,,,,,,,,,,,,,,,,,,,,,300.123138427734,300.137298583984,-45000.25390625,-45000.25390625,,,7.63703536987305,,1,0,0,0,0.0138092041015625,31.2805480957031,1,1,1,300.123077392578,0,4232058464,300.130758666992,,,-0.00213037101704766,0.000108306485852435,-0.00213327152237097,0.000108309857410641,0.772602260112762,0.778223097324371,33.8495597839355,0.142923250794411,35,4,200,0.0299014858901501,-0.459538638591766,0.830631017684937,1,,,,,,,,,,,,,,,,
,3870522741.29089,300.142013549805,-20000.44921875,,,6,,,,33.6600112915039,,,10,,,,,,,,,,,,,,,,,,,,,,300.135894775391,300.159881591797,-20000.44921875,-20000.44921875,,,7.70751285552979,,1,0,0,0,0.0145721435546875,31.2805480957031,1,1,1,300.148132324219,0,4232058656,300.150698852539,,,-0.00227795004741401,0.00011336120971787,-0.00227854958465528,0.000113362038958493,0.898464858531952,0.900990724563599,33.7449760437012,0.000101332952908706,35,4,200,0.0293960068374872,-0.309596031904221,0.918342888355255,1,,,,,,,,,,,,,,,,
,3870522890.6851,300.042953491211,-8500.2109375,,,6,,,,33.6600112915039,,,10,,,,,,,,,,,,,,,,,,,,,,300.039215087891,300.057647705078,-8500.2109375,-8500.2109375,,,7.70042133331299,,1,0,0,0,0.0138092041015625,31.2805480957031,1,1,1,300.046691894531,0,4232058720,300.049728393555,,,-0.00232571581681375,0.000115270137105022,-0.0023258515874658,0.000115270500322108,0.95250928401947,0.953684151172638,33.6998443603516,5.80515670776367,35,4,200,0.0350195541977882,-0.2560995221138,0.979748845100403,1,,,,,,,,,,,,,,,,
,3870523012.42773,300.123764038086,-6000.32568359375,,,6,,,,33.6600112915039,,,10,,,,,,,,,,,,,,,,,,,,,,300.122283935547,300.138122558594,-6000.32568359375,-6000.32568359375,,,7.72852897644043,,1,0,0,0,0.013885498046875,31.2805480957031,1,1,1,300.125244140625,0,4232058624,300.130706787109,,,-0.00232569035761259,0.000115215274458185,-0.00232577414154782,0.000115215492612187,0.963578224182129,0.964526474475861,33.6913871765137,0,35,4,200,0.0276847779750824,-0.242209926247597,0.944087207317352,1,,,,,,,,,,,,,,,,
,3870523136.56021,300.102233886719,-3500.4404296875,,,6,,,,33.6600112915039,,,10,,,,,,,,,,,,,,,,,,,,,,300.092742919922,300.113830566406,-3500.4404296875,-3500.4404296875,,,7.77997446060181,,1,0,0,0,0.0138092041015625,31.2805480957031,1,1,1,300.111724853516,0,4232058688,300.1076171875,,,-0.00230493602918652,0.000114150008688498,-0.00230497841219394,0.000114150063508243,0.973966777324676,0.974663496017456,33.6827850341797,3.48156095242302E-6,35,4,200,0.0222158748656511,-0.199976548552513,0.944670677185059,1,,,,,,,,,,,,,,,,
,3870523258.2467,300.116333007812,-1000.27423095703,,,6,,,,33.6600112915039,,,10,,,,,,,,,,,,,,,,,,,,,,300.111877441406,300.132965087891,-1000.27423095703,-1000.27423095703,,,7.81396341323853,,1,0,0,0,0.0138092041015625,31.7693061828613,1,1,1,300.120788574219,0,4232058816,300.124249267578,,,-0.0020647023959376,0.000102230982656052,-0.00206471354242743,0.000102231023385964,0.984058499336243,0.984375238418579,33.6720695495605,0,35,4,200,0.0145988101139665,-0.186949983239174,0.866970717906952,1,,,,,,,,,,,,,,,,
,3870523385.24746,300.010559082031,-760.248962402344,,,6,,,,33.6600112915039,,,10,,,,,,,,,,,,,,,,,,,,,,300.004547119141,300.01953125,-760.248962402344,-760.248962402344,,,7.78381490707398,,1,0,0,0,0.0138092041015625,31.7693061828613,1,1,1,300.005401611328,0,4232058688,300.014175415039,,,-0.00195413950136434,9.67628997820376E-5,-0.0019541403765206,9.67629100579816E-5,0.980412304401398,0.980429708957672,33.6631622314453,0,35,4,200,-0.017529858276248,-0.289684176445007,0.755278527736664,1,,,,,,,,,,,,,,,,
,3870523500.64985,300.061416625977,-710.481506347656,,,6,,,,33.6600112915039,,,10,,,,,,,,,,,,,,,,,,,,,,300.053436279297,300.074035644531,-710.481506347656,-710.481506347656,,,7.77439832687378,,1,0,0,0,0.0138092041015625,31.2805480957031,1,1,1,300.053466796875,0,4232058656,300.066702270508,,,-0.00192703378821817,9.54176481799564E-5,-0.00192703436710015,9.54176592575795E-5,0.982106029987335,0.982116341590881,33.6623268127441,,35,4,200,-0.015715304762125,-0.297508120536804,0.690302789211273,1,,,,,,,,,,,,,,,,
,3870523619.06414,300.197891235352,-660.469665527344,,,6,,,,33.6600112915039,,,10,,,,,,,,,,,,,,,,,,,,,,300.190185546875,300.212677001953,-660.469665527344,-660.469665527344,,,7.76314496994019,,1,0,0,0,0.0146484375,31.7693061828613,1,1,1,300.189056396484,0,4232058656,300.204791259766,,,-0.0018936619831614,9.37686729149994E-5,-0.00189366359758437,9.37686842276403E-5,0.980166792869568,0.980203688144684,33.664623260498,0,35,4,200,-0.0170507598668337,-0.271799445152283,0.699288010597229,1,,,,,,,,,,,,,,,,
,3870523730.95382,300.141250610352,-610.421142578125,,,6,,,,33.6600112915039,,,10,,,,,,,,,,,,,,,,,,,,,,300.125518798828,300.160491943359,-610.421142578125,-610.421142578125,,,7.74919843673706,,1,0,0,0,0.0138092041015625,31.2805480957031,1,1,1,300.159088134766,0,4232058848,300.150555419922,,,-0.00185556360139481,9.18784160352569E-5,-0.00185556798575012,9.18784503862039E-5,0.982334434986115,0.982447326183319,33.6676139831543,0,35,4,200,-0.0176033601164818,-0.244062229990959,0.70430189371109,1,,,,,,,,,,,,,,,,
,3870523843.49284,300.222412109375,-560.34814453125,,,6,,,,33.6600112915039,,,10,,,,,,,,,,,,,,,,,,,,,,300.221984863281,300.238128662109,-560.34814453125,-560.34814453125,,,7.74056148529053,,1,0,0,0,0.0138092041015625,31.2805480957031,1,1,1,300.222839355469,0,4232058816,300.23039855957,,,-0.0018134947616835,8.97954683981867E-5,-0.00181349963594982,8.97954900154002E-5,0.982279360294342,0.982417941093445,33.6684455871582,0,35,4,200,-0.0166419204324484,-0.247327253222466,0.679963886737823,1,,,,,,,,,,,,,,,,
,3870523958.29512,300.063171386719,-510.336273193359,,,6,,,,33.6600112915039,,,10,,,,,,,,,,,,,,,,,,,,,,300.040283203125,300.084747314453,-510.336273193359,-510.336273193359,,,7.75985431671143,,1,0,0,0,0.0138092041015625,30.7917900085449,1,1,1,300.086059570313,0,4232058688,300.070883178711,,,-0.00176424646307152,8.73590255147698E-5,-0.0017642499421915,8.73590484902788E-5,0.980964362621307,0.981054365634918,33.6670570373535,0.189786940813065,35,4,200,-0.0179788563400507,-0.202580392360687,0.698435425758362,1,,,,,,,,,,,,,,,,
,3870524070.30365,300.199630737305,-460.287719726562,,,6,,,,33.6600112915039,,,10,,,,,,,,,,,,,,,,,,,,,,300.183746337891,300.21728515625,-460.287719726562,-460.287719726562,,,7.77893304824829,,1,0,0,0,0.0138092041015625,31.2805480957031,1,1,1,300.215515136719,0,4232058592,300.207043457031,,,-0.00170712452001665,8.45289941122261E-5,-0.00170712868622612,8.4529017577413E-5,0.981978893280029,0.982099294662476,33.6679382324219,5.80240821838379,35,4,200,-0.0180685613304377,-0.20726503431797,0.66520768404007,1,,,,,,,,,,,,,,,,
,3870524184.28414,300.182952880859,-410.275848388672,,,6,,,,33.6600112915039,,,10,,,,,,,,,,,,,,,,,,,,,,300.176452636719,300.194213867188,-410.275848388672,-410.275848388672,,,7.74848747253418,,1,0,0,0,0.0145721435546875,31.2805480957031,1,1,1,300.176513671875,0,4232058816,300.187979125977,,,-0.00164114396460189,8.12593931488468E-5,-0.00164114936847781,8.12594323883993E-5,0.983789265155792,0.983963489532471,33.6690521240234,0,35,4,200,-0.0180672630667686,-0.259963482618332,0.637064039707184,1,,,,,,,,,,,,,,,,
,3870524294.92785,300.13948059082,-360.239501953125,,,6,,,,33.6600112915039,,,10,,,,,,,,,,,,,,,,,,,,,,300.119201660156,300.158630371094,-360.239501953125,-360.239501953125,,,7.74562311172485,,1,0,0,0,0.0138092041015625,31.2805480957031,1,1,1,300.159759521484,0,4232058624,300.147555541992,,,-0.00155855876671591,7.71712075630765E-5,-0.00155856029257646,7.71712188545262E-5,0.983070015907288,0.983119308948517,33.6649322509766,0,35,4,200,-0.0186864528805017,-0.223327144980431,0.577105343341827,1,,,,,,,,,,,,,,,,
,3870524407.51484,300.20849609375,-310.374298095703,,,6,,,,33.6600112915039,,,10,,,,,,,,,,,,,,,,,,,,,,300.204986572266,300.224456787109,-310.374298095703,-310.374298095703,,,7.7411847114563,,1,0,0,0,0.0138092041015625,30.7917900085449,1,1,1,300.212005615234,0,4232058656,300.216674804687,,,-0.00145670257958267,7.21293239210078E-5,-0.00145670376195658,7.2129332432135E-5,0.981923282146454,0.981961667537689,33.6645011901855,0.18977464735508,35,4,200,-0.0161626469343901,-0.218949764966965,0.540315866470337,1,,,,,,,,,,,,,,,,
,3870524518.39822,300.186431884766,-260.313537597656,,,6,,,,33.6600112915039,,,10,,,,,,,,,,,,,,,,,,,,,,300.166046142578,300.205261230469,-260.313537597656,-260.313537597656,,,7.74360036849976,,1,0,0,0,0.0138092041015625,30.7917900085449,1,1,1,300.206817626953,0,4232058784,300.193048095703,,,-0.00132835186919583,6.57752873101176E-5,-0.00132835321919305,6.5775303727181E-5,0.980845332145691,0.98088538646698,33.6647338867188,0,35,4,200,-0.0192553512752056,-0.239398300647736,0.445884704589844,1,,,,,,,,,,,,,,,,
,3870524631.49768,300.193496704102,-210.350555419922,,,6,,,,33.6600112915039,,,10,,,,,,,,,,,,,,,,,,,,,,300.177642822266,300.209930419922,-210.350555419922,-210.350555419922,,,7.74355936050415,,1,0,0,0,0.0138092041015625,30.7917900085449,1,1,1,300.177062988281,0,4232058656,300.19931640625,,,-0.00115628152482467,5.72569222192567E-5,-0.00115628159956972,5.72569225064388E-5,0.97913783788681,0.979140698909759,33.6586952209473,0,35,4,200,-0.0178365223109722,-0.226697564125061,0.378395706415176,1,,,,,,,,,,,,,,,,
,3870524750.52072,300.220504760742,-160.253128051758,,,6,,,,33.6600112915039,,,10,,,,,,,,,,,,,,,,,,,,,,300.209930419922,300.233245849609,-160.253128051758,-160.253128051758,,,7.75715446472168,,1,0,0,0,0.0138092041015625,31.2805480957031,1,1,1,300.208923339844,0,4232058848,300.225692749023,,,-0.000922714312100624,4.56967400812295E-5,-0.000922714539816294,4.56967353149576E-5,0.973881363868713,0.973894834518433,33.6568183898926,0,35,4,200,-0.0172507986426353,-0.206907078623772,0.289872497320175,1,,,,,,,,,,,,,,,,
,3870524861.14105,300.08268737793,-110.216796875,,,6,,,,33.6600112915039,,,10,,,,,,,,,,,,,,,,,,,,,,300.076416015625,300.092407226562,-110.216796875,-110.216796875,,,7.76232957839966,,1,0,0,0,0.0138092041015625,31.2805480957031,1,1,1,300.075317382812,0,4232058592,300.086782836914,,,-0.000612952473583948,3.03612872533201E-5,-0.000612953686093353,3.03612855047867E-5,0.967933535575867,0.967997014522552,33.6523284912109,5.80106258392334,35,4,200,-0.0181226339191198,-0.118865720927715,0.227448239922523,1,,,,,,,,,,,,,,,,
,3870524988.53971,300.134124755859,-60.2049140930176,,,6,,,,33.6600112915039,,,1,,,,,,,,,,,,,,,,,,,,,,300.130035400391,300.149261474609,-60.2049140930176,-60.2049140930176,,,7.77315330505371,,1,0,0,0,0.0138092041015625,31.2805480957031,1,1,1,300.130004882812,0,4232058592,300.141159057617,,,-0.000212236311057576,1.05322722919921E-5,-0.000212236852820548,1.0532271340305E-5,0.931126594543457,0.931164801120758,33.651294708252,0.190182372927666,35,4,200,-0.145379945635796,-0.944029152393341,0.903293490409851,1,,,,,,,,,,,,,,,,
,3870525099.73314,300.114196777344,-10.1563711166382,,,6,,,,33.6600112915039,,,1,,,,,,,,,,,,,,,,,,,,,,300.098266601562,300.12939453125,-10.1563711166382,-10.1563711166382,,,7.75885915756226,,1,0,0,0,0.0138092041015625,30.7917900085449,1,1,1,300.098999023438,0,4232058688,300.116876220703,,,0.000224833051917622,1.11874402315046E-5,0.000224861685123551,1.11874814058817E-5,0.899584531784058,0.900811314582825,33.7202529907227,0,35,4,200,-0.173760309815407,-1.68780469894409,0.447169005870819,1,,,,,,,,,,,,,,,,
,3870525212.53492,300.193313598633,40.0143928527832,,,6,,,,33.6600112915039,,,1,,,,,,,,,,,,,,,,,,,,,,300.185363769531,300.212066650391,40.0143928527832,40.0143928527832,,,7.74861526489258,,1,0,0,0,0.0146484375,30.7917900085449,1,1,1,300.201263427734,0,4232058624,300.203369140625,,,0.000623775822665551,3.089909578631E-5,0.000623788566621368,3.0899149188827E-5,0.966261923313141,0.966820240020752,33.6833953857422,0,35,4,200,-0.156803831458092,-3.19277286529541,0.324623912572861,1,,,,,,,,,,,,,,,,
,3870525328.37768,300.059463500977,90.0873794555664,,,6,,,,33.6600112915039,,,1,,,,,,,,,,,,,,,,,,,,,,300.056701660156,300.070129394531,90.0873794555664,90.0873794555664,,,7.73292589187622,,1,0,0,0,0.0138092041015625,30.7917900085449,1,1,1,300.062225341797,0,4232058624,300.064218139648,,,0.000934334483165098,4.62655638524823E-5,0.000934341214833289,4.62655941880806E-5,0.980151355266571,0.980484008789063,33.6738357543945,4.76836112284218E-6,35,4,200,-0.178601622581482,-3.88202905654907,1.03437936306,1,,,,,,,,,,,,,,,,
,3870525445.64049,300.116180419922,140.209243774414,,,6,,,,33.6600112915039,,,1,,,,,,,,,,,,,,,,,,,,,,300.097534179687,300.136016845703,140.209243774414,140.209243774414,,,7.72964906692505,,1,0,0,0,0.0138092041015625,30.7917900085449,1,1,1,300.096343994141,0,4232058784,300.119058227539,,,0.00116388012429182,5.76272579464325E-5,0.00116388987827635,5.76272799898265E-5,0.984857797622681,0.985395431518555,33.6752777099609,7.06224363966612E-6,35,4,200,-0.181302607059479,-4.85800790786743,1.23230457305908,1,,,,,,,,,,,,,,,,
,3870525569.04527,300.104156494141,190.257797241211,,,6,,,,33.6600112915039,,,10,,,,,,,,,,,,,,,,,,,,,,300.0908203125,300.117004394531,190.257797241211,190.257797241211,,,7.74422645568848,,1,0,0,0,0.0138092041015625,31.2805480957031,1,1,1,300.117492675781,0,4232058688,300.109344482422,,,0.00133597365421091,6.61543835531923E-5,0.00133598750219928,6.61544337949832E-5,0.979547500610352,0.980022490024567,33.6767463684082,0.111326895654202,35,4,200,-0.0184960663318634,-0.604362070560455,0.0841696560382843,1,,,,,,,,,,,,,,,,
,3870525688.45135,300.179901123047,240.171905517578,,,6,,,,33.6600112915039,,,10,,,,,,,,,,,,,,,,,,,,,,300.170867919922,300.197387695313,240.171905517578,240.171905517578,,,7.78870534896851,,1,0,0,0,0.0145721435546875,32.7468223571777,1,1,1,300.188934326172,0,4232058592,300.188571166992,,,0.00146177346300984,7.23740246499202E-5,0.00146177640015965,7.23740477700936E-5,0.987710058689117,0.987848341464996,33.6670303344727,5.80233001708984,35,4,200,-0.0157739389687777,-0.663559257984161,0.0935152173042297,1,,,,,,,,,,,,,,,,
,3870525806.14449,300.150054931641,290.220458984375,,,6,,,,33.6600112915039,,,10,,,,,,,,,,,,,,,,,,,,,,300.147003173828,300.163482666016,290.220458984375,290.220458984375,,,7.78316640853882,,1,0,0,0,0.0138092041015625,30.7917900085449,1,1,1,300.153106689453,0,4232058592,300.156518554688,,,0.001565729979408,7.75279733836271E-5,0.00156574251735638,7.75280161521664E-5,0.981818556785583,0.982233226299286,33.6747550964355,0,35,4,200,-0.0187210589647293,-0.68941056728363,0.107790447771549,1,,,,,,,,,,,,,,,,
,3870525920.02967,300.136291503906,340.171203613281,,,6,,,,33.6600112915039,,,10,,,,,,,,,,,,,,,,,,,,,,300.115386962891,300.156036376953,340.171203613281,340.171203613281,,,7.75675535202026,,1,0,0,0,0.0146484375,31.2805480957031,1,1,1,300.157196044922,0,4232058720,300.143365478516,,,0.00164739648769343,8.15734560038818E-5,0.00164741816678564,8.15735189692682E-5,0.980702459812164,0.9813551902771,33.679012298584,0,35,4,200,-0.0191853418946266,-0.741002976894379,0.0914694964885712,1,,,,,,,,,,,,,,,,
,3870526033.87277,300.078567504883,390.1953125,,,6,,,,33.6600112915039,,,10,,,,,,,,,,,,,,,,,,,,,,300.06591796875,300.092864990234,390.1953125,390.1953125,,,7.75698041915894,,1,0,0,0,0.0145721435546875,31.2805480957031,1,1,1,300.065826416016,0,4232058816,300.083374023438,,,0.00171506775227133,8.4922812388314E-5,0.00171508030578981,8.49228689324658E-5,0.981648445129395,0.982014536857605,33.6739349365234,0,35,4,200,-0.0181336887180805,-0.771711528301239,0.0993010401725769,1,,,,,,,,,,,,,,,,
,3870526150.9394,300.193984985352,440.170562744141,,,6,,,,33.6600112915039,,,10,,,,,,,,,,,,,,,,,,,,,,300.179779052734,300.209777832031,440.170562744141,440.170562744141,,,7.76948165893555,,1,0,0,0,0.0138092041015625,31.2805480957031,1,1,1,300.179412841797,0,4232058656,300.199673461914,,,0.00176960082411401,8.76220480619314E-5,0.00176961249119335,8.76220961848127E-5,0.982269823551178,0.982613921165466,33.6732788085937,5.26944494247437,35,4,200,-0.017130721360445,-0.760090410709381,0.142769500613213,1,,,,,,,,,,,,,,,,
,3870526273.3337,300.3095703125,490.072418212891,,,6,,,,33.6600112915039,,,10,,,,,,,,,,,,,,,,,,,,,,300.303588867188,300.329467773438,490.072418212891,490.072418212891,,,7.79946422576904,,1,0,0,0,0.0145721435546875,31.2805480957031,1,1,1,300.315551757812,0,4232058784,300.320028686523,,,0.00181786400384553,9.00105912251756E-5,0.00181787779988765,9.00106411146011E-5,0.983070611953735,0.983491241931915,33.6743240356445,5.8029580116272,35,4,200,-0.0163035932928324,-0.792953550815582,0.18265737593174,1,,,,,,,,,,,,,,,,
,3870526387.82352,300.070388793945,540.157592773438,,,6,,,,33.6600112915039,,,10,,,,,,,,,,,,,,,,,,,,,,300.054168701172,300.085205078125,540.157592773438,540.157592773438,,,7.77723979949951,,1,0,0,0,0.0145721435546875,30.3030319213867,1,1,1,300.086608886719,0,4232058720,300.075219726562,,,0.00186293544536264,9.22484525481681E-5,0.00186294954950056,9.22484986653605E-5,0.979491591453552,0.979839205741882,33.6743621826172,0.131424501538277,35,4,200,-0.0193141587078571,-0.824984848499298,0.110994063317776,1,,,,,,,,,,,,,,,,
,3870526504.02965,300.142669677734,590.230590820312,,,6,,,,33.6600112915039,,,10,,,,,,,,,,,,,,,,,,,,,,300.140563964844,300.154541015625,590.230590820312,590.230590820312,,,7.76481199264526,,1,0,0,0,0.013885498046875,30.7917900085449,1,1,1,300.144775390625,0,4232058880,300.148159790039,,,0.00190052490296765,9.4121536265285E-5,0.00190055279737753,9.41216228176911E-5,0.974113047122955,0.974649727344513,33.6800308227539,0.303281158208847,35,4,200,-0.0234030969440937,-0.826293706893921,0.125503480434418,1,,,,,,,,,,,,,,,,
,3870526619.14095,300.135803222656,640.266906738281,,,6,,,,33.6600112915039,,,10,,,,,,,,,,,,,,,,,,,,,,300.115509033203,300.1552734375,640.266906738281,640.266906738281,,,7.77149152755737,,1,0,0,0,0.0138092041015625,30.7917900085449,1,1,1,300.156097412109,0,4232058816,300.144427490234,,,0.00193570660777812,9.58605243712332E-5,0.00193573426806871,9.58606064686446E-5,0.975514471530914,0.976069033145905,33.6797904968262,9.28720601223176E-6,35,4,200,-0.0241985656321049,-0.816859364509582,0.160626351833344,1,,,,,,,,,,,,,,,,
,3870526734.52391,300.105224609375,690.193298339844,,,6,,,,33.6600112915039,,,10,,,,,,,,,,,,,,,,,,,,,,300.083587646484,300.12841796875,690.193298339844,690.193298339844,,,7.79140329360962,,1,0,0,0,0.0138092041015625,30.7917900085449,1,1,1,300.08203125,0,4232058624,300.108340454102,,,0.00196876116248253,9.74853213636902E-5,0.00196878334126972,9.74853714309793E-5,0.98125821352005,0.98184072971344,33.6777153015137,3.77404358005151E-5,35,4,200,-0.0250036139041185,-0.856507956981659,0.136613264679909,1,,,,,,,,,,,,,,,,
,3870526849.28152,300.062530517578,740.15625,,,6,,,,33.6600112915039,,,10,,,,,,,,,,,,,,,,,,,,,,300.035675048828,300.087738037109,740.15625,740.15625,,,7.82813358306885,,1,0,0,0,0.0138092041015625,31.2805480957031,1,1,1,300.089385986328,0,4232058688,300.069598388672,,,0.00199309389070462,9.87106088413278E-5,0.00199313079345949,9.8710661101856E-5,0.972324132919311,0.972981333732605,33.6828994750977,,35,4,200,-0.0222802683711052,-0.820385456085205,0.178494960069656,1,,,,,,,,,,,,,,,,
,3870526966.36835,300.154571533203,790.314819335938,,,6,,,,33.6600112915039,,,10,,,,,,,,,,,,,,,,,,,,,,300.141662597656,300.173461914063,790.314819335938,790.314819335938,,,7.86888074874878,,1,0,0,0,0.0138092041015625,30.7917900085449,1,1,1,300.16748046875,0,4232058592,300.163342285156,,,0.0020145094269689,9.97516220116985E-5,0.00201454886170454,9.97517073168248E-5,0.980720281600952,0.981716632843018,33.6833648681641,0,35,4,200,-0.021578112617135,-0.857164680957794,0.144567281007767,1,,,,,,,,,,,,,,,,
,3870527105.09132,300.127182006836,2500.23950195313,,,6,,,,33.6600112915039,,,10,,,,,,,,,,,,,,,,,,,,,,300.108276367188,300.146575927734,2500.23950195313,2500.23950195313,,,7.88322257995606,,1,0,0,0,0.0138092041015625,31.2805480957031,1,1,1,300.146087646484,0,4232058464,300.135366821289,,,0.00227609472645098,0.000112710168101165,0.00227612907093535,0.000112710253013933,0.978235483169556,0.978904128074646,33.6804046630859,0,35,4,200,0.00570415845140815,-0.934944450855255,0.202208429574966,1,,,,,,,,,,,,,,,,
,3870527245.89148,300.092590332031,5000.4423828125,,,6,,,,33.6600112915039,,,10,,,,,,,,,,,,,,,,,,,,,,300.076904296875,300.108703613281,5000.4423828125,5000.4423828125,,,7.87976121902466,,1,0,0,0,0.0138092041015625,31.2805480957031,1,1,1,300.076477050781,0,4232058592,300.097885131836,,,0.00232189483270696,0.000115007819741446,0.00232194936298433,0.000115007957543437,0.968543946743011,0.969259917736054,33.6853828430176,0,35,4,200,0.0138668995350599,-0.88274884223938,0.326784819364548,1,,,,,,,,,,,,,,,,
,3870527388.40893,300.20539855957,7500.4736328125,,,6,,,,33.6600112915039,,,10,,,,,,,,,,,,,,,,,,,,,,300.19189453125,300.227020263672,7500.4736328125,7500.4736328125,,,7.91059589385986,,1,0,0,0,0.0138092041015625,30.7917900085449,1,1,1,300.218902587891,0,4232058752,300.215121459961,,,0.0023269071075902,0.000115303142012213,0.00232701888775143,0.000115303387685315,0.957518875598908,0.95861166715622,33.6963539123535,0.147189572453499,35,4,200,0.0162942241877317,-0.897235989570618,0.333150714635849,1,,,,,,,,,,,,,,,,
,3870527539.32388,300.222076416016,10000.4326171875,,,6,,,,33.6600112915039,,,10,,,,,,,,,,,,,,,,,,,,,,300.211181640625,300.237121582031,10000.4326171875,10000.4326171875,,,7.8637809753418,,1,0,0,0,0.0138092041015625,31.2805480957031,1,1,1,300.209991455078,0,4232058688,300.228442382812,,,0.0023227932616555,0.000115166139406017,0.0023229768280868,0.000115166465288342,0.945564031600952,0.946978032588959,33.7067451477051,5.80575084686279,35,4,200,0.00883454643189907,-0.941257059574127,0.358218044042587,1,,,,,,,,,,,,,,,,
,3870527690.77314,299.999923706055,35000.296875,,,6,,,,33.6600112915039,,,10,,,,,,,,,,,,,,,,,,,,,,299.986267089844,300.016967773438,35000.296875,35000.296875,,,7.92133188247681,,1,0,0,0,0.0138092041015625,32.7468223571777,1,1,1,300.013580322266,0,4232058560,300.008200073242,,,0.00219080480580663,0.000110090027340018,0.00219249287043346,0.00011009192197131,0.828607022762299,0.832929134368897,33.8038368225098,,35,4,200,0.0128306951373816,-0.799980461597443,0.49752539396286,1,,,,,,,,,,,,,,,,
,3870527843.63201,300.104263305664,60000.48046875,,,6,,,,33.6600112915039,,,10,,,,,,,,,,,,,,,,,,,,,,300.098022460937,300.1220703125,60000.48046875,60000.48046875,,,7.84731769561768,,1,0,0,0,0.0138092041015625,30.7917900085449,1,1,1,300.110504150391,0,4232058720,300.113809204102,,,0.00203151906346748,0.000105434790959973,0.00203663195842327,0.000105440167104932,0.699903845787048,0.707485139369965,33.9140396118164,5.8235764503479,35,4,200,0.0167898368090391,-0.654023110866547,0.738759160041809,1,,,,,,,,,,,,,,,,
,3870528004.65349,300.165435791016,55000.28515625,,,6,,,,33.6600112915039,,,10,,,,,,,,,,,,,,,,,,,,,,300.163909912109,300.182891845703,55000.28515625,55000.28515625,,,7.88840198516846,,1,0,0,0,0.013885498046875,31.2805480957031,1,1,1,300.166961669922,0,4232058496,300.174264526367,,,0.00206962048642623,0.000106724769536743,0.00207409307778413,0.000106728999208262,0.720183670520782,0.72726845741272,33.8970565795898,0,35,4,200,-0.0238044764846563,-0.820547938346863,0.582307636737823,1,,,,,,,,,,,,,,,,
,3870528164.76109,300.083480834961,30000.150390625,,,6,,,,33.6600112915039,,,10,,,,,,,,,,,,,,,,,,,,,,300.070770263672,300.097900390625,30000.150390625,30000.150390625,,,7.87285470962524,,1,0,0,0,0.0138092041015625,31.2805480957031,1,1,1,300.069946289063,0,4232058464,300.088787841797,,,0.00222403581407896,0.000111380967313849,0.00222531583577184,0.00011138231635808,0.849137544631958,0.85283350944519,33.7850303649902,4.02926969528198,35,4,200,-0.0317152477800846,-0.92861533164978,0.383992344141006,1,,,,,,,,,,,,,,,,
,3870528324.98018,299.916015625,9500.2158203125,,,6,,,,33.6600112915039,,,10,,,,,,,,,,,,,,,,,,,,,,299.907531738281,299.927856445313,9500.2158203125,9500.2158203125,,,7.9305944442749,,1,0,0,0,0.0138092041015625,31.7693061828613,1,1,1,299.907836914063,0,4232058656,299.920428466797,,,0.0023262040625444,0.000115326269251116,0.00232636323530288,0.000115326597751487,0.947009325027466,0.9482581615448,33.7033882141113,0,35,4,200,-0.0485946387052536,-0.975690364837646,0.232883393764496,1,,,,,,,,,,,,,,,,
,3870528469.20461,300.105834960937,7000.28173828125,,,6,,,,33.6600112915039,,,10,,,,,,,,,,,,,,,,,,,,,,300.095001220703,300.125671386719,7000.28173828125,7000.28173828125,,,7.88876295089722,,1,0,0,0,0.0144195556640625,31.7693061828613,1,1,1,300.116668701172,0,4232058784,300.115417480469,,,0.00232860563836913,0.00011538016388521,0.00232871289560311,0.000115380403515932,0.959006905555725,0.960092484951019,33.6956024169922,0,35,4,200,-0.0282631367444992,-0.998546063899994,0.249382451176643,1,,,,,,,,,,,,,,,,
,3870528611.3499,300.014434814453,4500.54345703125,,,6,,,,33.6600112915039,,,10,,,,,,,,,,,,,,,,,,,,,,300.007690429687,300.027130126953,4500.54345703125,4500.54345703125,,,7.94448280334473,,1,0,0,0,0.0138092041015625,31.2805480957031,1,1,1,300.007873535156,0,4232058496,300.019281005859,,,0.00232093223211614,0.000114959134771434,0.00232098602510773,0.000114959283868154,0.968839645385742,0.969549238681793,33.6851692199707,2.45823885052232E-5,35,4,200,-0.0290273893624544,-1.02794206142426,0.210886552929878,1,,,,,,,,,,,,,,,,
,3870528748.58966,300.066390991211,2000.23071289062,,,6,,,,33.6600112915039,,,10,,,,,,,,,,,,,,,,,,,,,,300.038604736328,300.09326171875,2000.23071289062,2000.23071289062,,,7.90871143341064,,1,0,0,0,0.0138092041015625,31.7693061828613,1,1,1,300.094177246094,0,4232058752,300.075619506836,,,0.00224194303183256,0.000111018689760685,0.00224196856777656,0.000111018752731882,0.978379368782044,0.978885650634766,33.6777381896973,0,35,4,200,-0.0281971972435713,-0.939145863056183,0.205290198326111,1,,,,,,,,,,,,,,,,
,3870528882.01192,300.210159301758,780.109497070312,,,6,,,,33.6600112915039,,,10,,,,,,,,,,,,,,,,,,,,,,300.200958251953,300.229919433594,780.109497070312,780.109497070312,,,7.88129901885986,,1,0,0,0,0.0138092041015625,31.7693061828613,1,1,1,300.219360351562,0,4232058688,300.220663452148,,,0.00196981556064645,9.75331953071145E-5,0.00196982286949948,9.75332391142902E-5,0.98380047082901,0.984003007411957,33.6697463989258,1.10405187569995E-6,35,4,200,0.00236169202253222,-0.74241441488266,0.223137632012367,1,,,,,,,,,,,,,,,,
,3870528998.0464,300.22900390625,730.10986328125,,,6,,,,33.6600112915039,,,10,,,,,,,,,,,,,,,,,,,,,,300.210021972656,300.250152587891,730.10986328125,730.10986328125,,,7.89606094360352,,1,0,0,0,0.0138092041015625,31.2805480957031,1,1,1,300.207855224609,0,4232058656,300.234912109375,,,0.00193872593785665,9.59981631858847E-5,0.00193872773051955,9.59981800162212E-5,0.981223583221436,0.981263518333435,33.6646766662598,0,35,4,200,0.0172080080956221,-0.725748300552368,0.262232035398483,1,,,,,,,,,,,,,,,,
,3870529106.0181,300.019134521484,680.097961425781,,,6,,,,33.6600112915039,,,10,,,,,,,,,,,,,,,,,,,,,,300.016052246094,300.029571533203,680.097961425781,680.097961425781,,,7.90476608276367,,1,0,0,0,0.0138092041015625,31.2805480957031,1,1,1,300.022216796875,0,4232058656,300.023849487305,,,0.00190698795716203,9.44265319944905E-5,0.00190699047478014,9.44265589343409E-5,0.981267988681793,0.981323301792145,33.6654930114746,4.02928495407105,35,4,200,0.0181412007659674,-0.740799367427826,0.22534516453743,1,,,,,,,,,,,,,,,,
,3870529214.04191,300.057006835937,630.208312988281,,,6,,,,33.6600112915039,,,10,,,,,,,,,,,,,,,,,,,,,,300.030639648438,300.079681396484,630.208312988281,630.208312988281,,,7.89546155929565,,1,0,0,0,0.0138092041015625,31.2805480957031,1,1,1,300.083374023438,0,4232058656,300.063342285156,,,0.00187303225415063,9.27435808289462E-5,0.00187303622577726,9.27436003355817E-5,0.98222678899765,0.982334554195404,33.6674613952637,0,35,4,200,0.0182140320539474,-0.691784679889679,0.254715383052826,1,,,,,,,,,,,,,,,,
,3870529332.36307,300.162200927734,580.196472167969,,,6,,,,33.6600112915039,,,10,,,,,,,,,,,,,,,,,,,,,,300.148529052734,300.178314208984,580.196472167969,580.196472167969,,,7.92423868179321,,1,0,0,0,0.0138092041015625,30.7917900085449,1,1,1,300.146759033203,0,4232058592,300.168539428711,,,0.00183478938667883,9.08512618507523E-5,0.00183479093110945,9.08512766973646E-5,0.981439650058746,0.981476187705994,33.6644515991211,0,35,4,200,0.0170353669673204,-0.678463339805603,0.259779781103134,1,,,,,,,,,,,,,,,,
,3870529442.94149,300.137634277344,530.123474121094,,,6,,,,33.6600112915039,,,10,,,,,,,,,,,,,,,,,,,,,,300.116394042969,300.159301757812,530.123474121094,530.123474121094,,,7.92679643630982,,1,0,0,0,0.0138092041015625,31.2805480957031,1,1,1,300.115966796875,0,4232058720,300.140548706055,,,0.00178666812232786,8.84738335489612E-5,0.00178666812869633,8.84738289484637E-5,0.978445053100586,0.978447616100311,33.6587409973145,4.02933883666992,35,4,200,0.0193310137838125,-0.722538232803345,0.18653616309166,1,,,,,,,,,,,,,,,,
,3870529550.81584,300.075378417969,480.099334716797,,,6,,,,33.6600112915039,,,10,,,,,,,,,,,,,,,,,,,,,,300.056579589844,300.093841552734,480.099334716797,480.099334716797,,,7.88981771469116,,1,0,0,0,0.0138092041015625,31.2805480957031,1,1,1,300.056915283203,0,4232058688,300.077432250977,,,0.00173499497364764,8.59088431236442E-5,0.00173499547959644,8.59088510457844E-5,0.982092082500458,0.982103228569031,33.6624183654785,2.5991694201366E-5,35,4,200,0.0188847128301859,-0.622090399265289,0.259576618671417,1,,,,,,,,,,,,,,,,
,3870529663.91141,300.235275268555,430.221923828125,,,6,,,,33.6600112915039,,,10,,,,,,,,,,,,,,,,,,,,,,300.216888427734,300.255126953125,430.221923828125,430.221923828125,,,7.84305381774902,,1,0,0,0,0.0138092041015625,31.2805480957031,1,1,1,300.215423583984,0,4232058688,300.241018676758,,,0.0016708361746424,8.27319793453089E-5,0.00167083956401472,8.27319980510986E-5,0.982085943222046,0.982186853885651,33.6672477722168,9.32670354814036E-6,35,4,200,0.0182819496840239,-0.674087524414062,0.177919387817383,1,,,,,,,,,,,,,,,,
,3870529781.0836,300.189270019531,380.100067138672,,,6,,,,33.6600112915039,,,10,,,,,,,,,,,,,,,,,,,,,,300.179565429687,300.206481933594,380.100067138672,380.100067138672,,,7.79414844512939,,1,0,0,0,0.0138092041015625,31.2805480957031,1,1,1,300.198974609375,0,4232058688,300.197650146484,,,0.00159669418765761,7.90589512084294E-5,0.00159669640112955,7.90589663795593E-5,0.983461737632751,0.983534097671509,33.6659049987793,7.34884167741257E-7,35,4,200,0.0163382962346077,-0.598250865936279,0.225103989243507,1,,,,,,,,,,,,,,,,
,3870529892.3848,300.108551025391,330.088165283203,,,6,,,,33.6600112915039,,,10,,,,,,,,,,,,,,,,,,,,,,300.090087890625,300.125762939453,330.088165283203,330.088165283203,,,7.77292490005493,,1,0,0,0,0.0138092041015625,31.2805480957031,1,1,1,300.127014160156,0,4232058656,300.114260864258,,,0.00150373672075703,7.44596836990886E-5,0.00150373865139948,7.44597106555656E-5,0.980872571468353,0.980920791625977,33.6651878356934,0,35,4,200,0.0186514258384705,-0.59903222322464,0.234424889087677,1,,,,,,,,,,,,,,,,
,3870530004.27372,300.072601318359,280.039642333984,,,6,,,,33.6600112915039,,,10,,,,,,,,,,,,,,,,,,,,,,300.049011230469,300.09521484375,280.039642333984,280.039642333984,,,7.75465869903564,,1,0,0,0,0.0145721435546875,31.2805480957031,1,1,1,300.09619140625,0,4232058688,300.079110717773,,,0.00138557719207202,6.86082363055029E-5,0.00138557825364049,6.86082467655046E-5,0.981329500675201,0.981362402439117,33.664234161377,0,35,4,200,0.0192944034934044,-0.476386874914169,0.235934123396873,1,,,,,,,,,,,,,,,,
,3870530123.83465,300.229293823242,230.186630249023,,,6,,,,33.6600112915039,,,10,,,,,,,,,,,,,,,,,,,,,,300.229156494141,300.246215820313,230.186630249023,230.186630249023,,,7.74948501586914,,1,0,0,0,0.0138092041015625,30.7917900085449,1,1,1,300.228912353516,0,4232058688,300.237347412109,,,0.00123478397210836,6.11419272855563E-5,0.00123478702839466,6.11419378473994E-5,0.981031060218811,0.981152772903442,33.6681938171387,,35,4,200,0.0162743143737316,-0.488893449306488,0.163875162601471,1,,,,,,,,,,,,,,,,
,3870530236.04752,300.128311157227,180.296981811523,,,6,,,,33.6600112915039,,,10,,,,,,,,,,,,,,,,,,,,,,300.116180419922,300.141967773438,180.296981811523,180.296981811523,,,7.78102159500122,,1,0,0,0,0.0138092041015625,31.2805480957031,1,1,1,300.140441894531,0,4232058688,300.133847045898,,,0.00103109409105309,5.10623536898055E-5,0.00103109414639087,5.10623554406575E-5,0.97529411315918,0.975294947624207,33.6607627868652,0,35,4,200,0.0185255762189627,-0.352585017681122,0.188751831650734,1,,,,,,,,,,,,,,,,
,3870530352.11385,300.161285400391,130.223983764648,,,6,,,,33.6600112915039,,,10,,,,,,,,,,,,,,,,,,,,,,300.146514892578,300.176361083984,130.223983764648,130.223983764648,,,7.8093523979187,,1,0,0,0,0.0138092041015625,31.7693061828613,1,1,1,300.146209716797,0,4232058624,300.165737915039,,,0.000755055813756722,3.73938328879453E-5,0.000755055810238552,3.73938325699261E-5,0.973634898662567,0.973635017871857,33.6596755981445,2.04382722586161E-5,35,4,200,0.0184730105102062,-0.305462747812271,0.164053022861481,1,,,,,,,,,,,,,,,,
,3870530463.50337,300.103210449219,80.1754455566406,,,6,,,,33.6600112915039,,,10,,,,,,,,,,,,,,,,,,,,,,300.090148925781,300.117614746094,80.1754455566406,80.1754455566406,,,7.80528211593628,,1,0,0,0,0.013885498046875,30.7917900085449,1,1,1,300.116271972656,0,4232058688,300.1095703125,,,0.000391292912963177,1.94094811158102E-5,0.000391307226594359,1.94094702148174E-5,0.937791705131531,0.938389360904694,33.6272468566895,INF,35,4,200,0.0186308417469263,-0.158407211303711,0.0774258449673653,1,,,,,,,,,,,,,,,,
,3870530586.59077,300.108871459961,30.151346206665,,,6,,,,33.6600112915039,,,1,,,,,,,,,,,,,,,,,,,,,,300.093597412109,300.124206542969,30.151346206665,30.151346206665,,,7.77595376968384,,1,0,0,0,0.0145721435546875,30.7917900085449,1,1,1,300.093536376953,0,4232058656,300.112313842773,,,-4.1799911168569E-5,2.26463893686691E-6,-4.17999154795328E-5,2.26463904321608E-6,0.593812465667725,0.593812584877014,33.6613273620605,8.33669691928662E-5,35,4,200,0.177827790379524,0.349706500768662,1.31240475177765,1,,,,,,,,,,,,,,,,
,3870530698.61727,300.228164672852,-19.9216423034668,,,6,,,,33.6600112915039,,,1,,,,,,,,,,,,,,,,,,,,,,300.212951660156,300.249755859375,-19.9216423034668,-19.9216423034668,,,7.76137018203735,,1,0,0,0,0.0145721435546875,31.2805480957031,1,1,1,300.243377685547,0,4232058688,300.238723754883,,,-0.000456480116697183,2.26459558287494E-5,-0.000456500537112946,2.26459880020862E-5,0.935727059841156,0.936401784420013,33.6955680847168,0,35,4,200,0.188320383429527,-0.70139753818512,1.85491502285004,1,,,,,,,,,,,,,,,,
,3870530813.98417,300.151428222656,-69.99462890625,,,6,,,,33.6600112915039,,,1,,,,,,,,,,,,,,,,,,,,,,300.138610839844,300.165130615234,-69.99462890625,-69.99462890625,,,7.75803709030151,,1,0,0,0,0.0138092041015625,31.2805480957031,1,1,1,300.138488769531,0,4232058656,300.156002807617,,,-0.000814350967999226,4.03265059391406E-5,-0.000814362620290896,4.03265326314759E-5,0.977574467658997,0.978191137313843,33.6799659729004,0,35,4,200,0.173772186040878,-1.04395091533661,3.92179179191589,1,,,,,,,,,,,,,,,,
,3870530932.46852,300.114166259766,-120.018730163574,,,6,,,,33.6600112915039,,,10,,,,,,,,,,,,,,,,,,,,,,300.099761962891,300.132354736328,-120.018730163574,-120.018730163574,,,7.78035926818848,,1,0,0,0,0.0146484375,30.7917900085449,1,1,1,300.098815917969,0,4232058848,300.117916709498,,,-0.00107204838264998,5.30808167998848E-5,-0.00107205229587782,5.30808308420097E-5,0.98433244228363,0.984549999237061,33.6699447631836,0,35,4,200,0.0115618482232094,-4.90466070175171,4.90990495681763,1,,,,,,,,,,,,,,,,
,3870531050.91845,300.087707519531,-170.01838684082,,,6,,,,33.6600112915039,,,10,,,,,,,,,,,,,,,,,,,,,,300.083892822266,300.101654052734,-170.01838684082,-170.01838684082,,,7.81468820571899,,1,0,0,0,0.0138092041015625,31.2805480957031,1,1,1,300.091522216797,0,4232058656,300.093649291992,,,-0.00126902824824252,6.28356099653507E-5,-0.00126903316786925,6.2835632390453E-5,0.982748210430145,0.982953369617462,33.6701393127441,INF,35,4,200,0.0170344337821007,-0.150146201252937,0.562505602836609,1,,,,,,,,,,,,,,,,
,3870531164.67198,300.105117797852,-220.091384887695,,,6,,,,33.6600112915039,,,10,,,,,,,,,,,,,,,,,,,,,,300.101013183594,300.116363525391,-220.091384887695,-220.091384887695,,,7.82231998443603,,1,0,0,0,0.0138092041015625,30.7917900085449,1,1,1,300.101135253906,0,4232058816,300.110345458984,,,-0.00141285795288033,6.99624039273724E-5,-0.00141286875381734,6.99624485336355E-5,0.97893887758255,0.979274094104767,33.6743011474609,,35,4,200,0.0191601123660803,-0.103221662342548,0.619270622730255,1,,,,,,,,,,,,,,,,
,3870531278.04765,300.111328125,-269.871032714844,,,6,,,,33.6600112915039,,,10,,,,,,,,,,,,,,,,,,,,,,300.102355957031,300.124084472656,-269.871032714844,-269.871032714844,,,7.79597282409668,,1,0,0,0,0.0138092041015625,30.3030319213867,1,1,1,300.102172851562,0,4232058656,300.116268920898,,,-0.0015239896192996,7.54723367843236E-5,-0.00152400983332494,7.54723730818755E-5,0.974992692470551,0.975508868694305,33.6793060302734,0,35,4,200,0.0200922042131424,-0.169262126088142,0.598298311233521,1,,,,,,,,,,,,,,,,
,3870531391.81097,300.10546875,-319.79736328125,,,6,,,,33.6600112915039,,,10,,,,,,,,,,,,,,,,,,,,,,300.092712402344,300.118469238281,-319.79736328125,-319.79736328125,,,7.75274610519409,,1,0,0,0,0.0138092041015625,31.2805480957031,1,1,1,300.092468261719,0,4232058656,300.109219360352,,,-0.00161307199716905,7.98728627975933E-5,-0.00161309253621025,7.98729012579284E-5,0.981335341930389,0.982003450393677,33.6789054870605,0,35,4,200,0.0188503824174404,-0.189693719148636,0.626959204673767,1,,,,,,,,,,,,,,,,
,3870531505.37353,300.070831298828,-369.760345458984,,,6,,,,33.6600112915039,,,10,,,,,,,,,,,,,,,,,,,,,,300.0615234375,300.083587646484,-369.760345458984,-369.760345458984,,,7.72984790802002,,1,0,0,0,0.0145721435546875,30.7917900085449,1,1,1,300.080139160156,0,4232058720,300.076483154297,,,-0.0016868136338097,8.35237226630319E-5,-0.00168682844272116,8.35237685532241E-5,0.981696844100952,0.982151985168457,33.6754951477051,5.80305910110474,35,4,200,0.0185409337282181,-0.161918371915817,0.692523777484894,1,,,,,,,,,,,,,,,,
,3870531621.79897,300.184783935547,-419.833312988281,,,6,,,,33.6600112915039,,,10,,,,,,,,,,,,,,,,,,,,,,300.163848876953,300.206237792969,-419.833312988281,-419.833312988281,,,7.70528507232666,,1,0,0,0,0.0145721435546875,30.7917900085449,1,1,1,300.163330078125,0,4232058656,300.187890625,,,-0.00174874689448073,8.65903884145965E-5,-0.00174875798900496,8.65904241566359E-5,0.981682896614075,0.982009530067444,33.673152923584,0,35,4,200,0.0176706928759813,-0.129383832216263,0.759533941745758,1,,,,,,,,,,,,,,,,
,3870531737.78342,300.062591552734,-469.771881103516,,,6,,,,33.6600112915039,,,10,,,,,,,,,,,,,,,,,,,,,,300.044586181641,300.081115722656,-469.771881103516,-469.771881103516,,,7.69464826583862,,1,0,0,0,0.0145721435546875,32.2580642700195,1,1,1,300.044067382812,0,4232058688,300.067013549805,,,-0.0017984648493184,8.90495507879619E-5,-0.00179847626708077,8.90496049889328E-5,0.983401536941528,0.983750939369202,33.6729393005371,0,35,4,200,0.0186094660311937,-0.189253598451614,0.719361186027527,1,,,,,,,,,,,,,,,,
,3870531854.57858,300.225433349609,-519.771545410156,,,6,,,,33.6600112915039,,,10,,,,,,,,,,,,,,,,,,,,,,300.220367431641,300.244720458984,-519.771545410156,-519.771545410156,,,7.70951461791992,,1,0,0,0,0.0146484375,31.2805480957031,1,1,1,300.236724853516,0,4232058720,300.236914740668,,,-0.0018426254860385,9.1234424418142E-5,-0.00184263554502048,9.1234469138671E-5,0.984556019306183,0.984881103038788,33.6720352172852,0,35,4,200,0.00649590417742729,-0.195844769477844,0.732938706874847,1,,,,,,,,,,,,,,,,
,3870531971.50838,300.154327392578,-569.771179199219,,,6,,,,33.6600112915039,,,10,,,,,,,,,,,,,,,,,,,,,,300.137817382812,300.171142578125,-569.771179199219,-569.771179199219,,,7.74676704406738,,1,0,0,0,0.0145721435546875,30.7917900085449,1,1,1,300.137512207031,0,4232058688,300.159002685547,,,-0.00188788308905191,9.34839022568165E-5,-0.00188790488342436,9.34839629994311E-5,0.979442894458771,0.979979634284973,33.6778297424316,5.26918411254883,35,4,200,0.0201125796884298,-0.200477123260498,0.748766243457794,1,,,,,,,,,,,,,,,,
,3870532084.57449,300.052551269531,-619.770874023437,,,6,,,,33.6600112915039,,,10,,,,,,,,,,,,,,,,,,,,,,300.041687011719,300.064971923828,-619.770874023437,-619.770874023437,,,7.75988721847534,,1,0,0,0,0.0138092041015625,30.7917900085449,1,1,1,300.041564941406,0,4232058656,300.056890869141,,,-0.00192006860439115,9.50751245432496E-5,-0.00192008477293273,9.50751902210541E-5,0.980774402618408,0.981180608272552,33.6750183105469,0,35,4,200,0.0235301274806261,-0.206481590867043,0.754117608070374,1,,,,,,,,,,,,,,,,
,3870532199.73352,300.155685424805,-669.843811035156,,,6,,,,33.6600112915039,,,10,,,,,,,,,,,,,,,,,,,,,,300.136901855469,300.175964355469,-669.843811035156,-669.843811035156,,,7.74926710128784,,1,0,0,0,0.0138092041015625,31.7693061828613,1,1,1,300.174468994141,0,4232058720,300.164379882812,,,-0.00195717830731031,9.69154270688331E-5,-0.00195719931657965,9.69154851034254E-5,0.979341328144073,0.979837715625763,33.6772041320801,6.22715833742404E-6,35,4,200,0.0247479695826769,-0.146018713712692,0.833271205425262,1,,,,,,,,,,,,,,,,
,3870532316.59728,300.206069946289,-719.843505859375,,,6,,,,33.6600112915039,,,10,,,,,,,,,,,,,,,,,,,,,,300.192413330078,300.225402832031,-719.843505859375,-719.843505859375,,,7.73755788803101,,1,0,0,0,0.0145721435546875,30.7917900085449,1,1,1,300.2197265625,0,4232058848,300.215811157227,,,-0.00198298312740962,9.82024714891334E-5,-0.00198301123816593,9.82025950129031E-5,0.975197911262512,0.975724041461945,33.6794166564941,4.39664800069295E-5,35,4,200,0.0233890749514103,-0.186707898974419,0.804251134395599,1,,,,,,,,,,,,,,,,
,3870532431.6446,300.216217041016,-769.867614746094,,,6,,,,33.6600112915039,,,10,,,,,,,,,,,,,,,,,,,,,,300.208374023438,300.232421875,-769.867614746094,-769.867614746094,,,7.73152732849121,,1,0,0,0,0.0138092041015625,30.7917900085449,1,1,1,300.224060058594,0,4232058752,300.224133300781,,,-0.00200763785807303,9.94315895275606E-5,-0.00200766837958097,9.94316534415483E-5,0.972097516059875,0.972623884677887,33.680606842041,0,35,4,200,0.0270997565239668,-0.187148362398148,0.896670997142792,1,,,,,,,,,,,,,,,,
,3870532557.63108,300.221069335937,-1499.76977539062,,,6,,,,33.6600112915039,,,10,,,,,,,,,,,,,,,,,,,,,,300.218200683594,300.232482910156,-1499.76977539062,-1499.76977539062,,,7.70961570739746,,1,0,0,0,0.0138092041015625,30.7917900085449,1,1,1,300.218048095703,0,4232058624,300.226345825195,,,-0.00219515997369295,0.000108698413258328,-0.00219518868411883,0.000108698474495087,0.979960143566132,0.980594515800476,33.679084777832,0,35,4,200,0.00163398031145334,-0.237169533967972,0.835220634937286,1,,,,,,,,,,,,,,,,
,3870532670.33097,300.106323242188,-4000.32690429687,,,6,,,,33.6600112915039,,,10,,,,,,,,,,,,,,,,,,,,,,300.10595703125,300.119506835937,-4000.32690429687,-4000.32690429687,,,7.70245122909546,,1,0,0,0,0.0138092041015625,30.7917900085449,1,1,1,300.106689453125,0,4232058752,300.112551879883,,,-0.00231462763566975,0.000114636779117708,-0.00231467951431264,0.000114636916344641,0.971777260303497,0.972538709640503,33.6847877502441,3.59324876626488E-5,35,4,200,-0.00423553632572293,-0.230728939175606,0.918583810329437,1,,,,,,,,,,,,,,,,
,3870532785.87143,300.044021606445,-6500.33447265625,,,6,,,,33.6600112915039,,,10,,,,,,,,,,,,,,,,,,,,,,300.032409667969,300.061096191406,-6500.33447265625,-6500.33447265625,,,7.72050714492798,,1,0,0,0,0.0145721435546875,30.7917900085449,1,1,1,300.055633544922,0,4232058688,300.05188293457,,,-0.00232940385227644,0.000115408727938552,-0.00232950263224264,0.000115408889693822,0.961390256881714,0.962465703487396,33.6943855285645,5.0252227083547E-5,35,4,200,-0.00943989213556051,-0.340964645147324,0.848474144935608,1,,,,,,,,,,,,,,,,
,3870532905.60501,300.188201904297,-9000.451171875,,,6,,,,33.6600112915039,,,10,,,,,,,,,,,,,,,,,,,,,,300.161895751953,300.214508056641,-9000.451171875,-9000.451171875,,,7.74893140792847,,1,0,0,0,0.0138092041015625,30.7917900085449,1,1,1,300.161895751953,0,4232058624,300.191647338867,,,-0.0023253903349183,0.000115262668730483,-0.00232553999759719,0.000115262936222729,0.950952768325806,0.952231287956238,33.7022094726562,0,35,4,200,-0.0110072558745742,-0.353462934494019,0.846746683120728,1,,,,,,,,,,,,,,,,
,3870533057.65411,300.278121948242,-25000.365234375,,,6,,,,33.6600112915039,,,10,,,,,,,,,,,,,,,,,,,,,,300.274719238281,300.299011230469,-25000.365234375,-25000.365234375,,,7.69323110580444,,1,0,0,0,0.0138092041015625,30.7917900085449,1,1,1,300.281524658203,0,4232058592,300.288940429687,,,-0.00224960323413891,0.000112218863017146,-0.00225053724857486,0.000112219893508266,0.877373933792114,0.880680322647095,33.7665481567383,0,35,4,200,-0.0156173696741462,-0.48759189248085,0.836893498897553,1,,,,,,,,,,,,,,,,
,3870533210.64947,300.243179321289,-50000.2421875,,,6,,,,33.6600112915039,,,10,,,,,,,,,,,,,,,,,,,,,,300.234161376953,300.261291503906,-50000.2421875,-50000.2421875,,,7.71419906616211,,1,0,0,0,0.0138092041015625,31.2805480957031,1,1,1,300.252197265625,0,4232058400,300.252178955078,,,-0.00209776294743436,0.000107199642899328,-0.00210131018694717,0.000107203522222497,0.752146005630493,0.758498609066009,33.8702354431152,0,35,4,200,-0.0124179311096668,-0.658796370029449,0.723991990089416,1,,,,,,,,,,,,,,,,
,3870533333.07001,300.104049682617,-70000.5234375,,,6,,,,33.6600112915039,,,10,,,,,,,,,,,,,,,,,,,,,,300.094024658203,300.116790771484,-70000.5234375,-70000.5234375,,,7.69238996505737,,1,0,0,0,0.0138092041015625,30.7917900085449,1,1,1,300.095001220703,0,4232058656,300.108795166016,,,-0.00196652649342927,0.000104001440687932,-0.00197361968092824,0.000104008515538054,0.648311793804169,0.657258749008179,33.9611053466797,0,35,4,200,-0.0234133061021566,-0.854515552520752,0.560125946998596,1,,,,,,,,,,,,,,,,