File: Data/KMK273S/ZFCFC/KMK273S_ZFCFC.dat
[Header]
; MPMS3 Data File (default extension .dat)
; Copyright (c) 2007, Quantum Design, Inc. All rights reserved.
TITLE,
FILEOPENTIME,3870376376.35216,08/23/2022,12:32 am
BYAPP,MPMS3 w/ AC,1.0,1.1
INFO,MPMS3 Measurement Release 1.1.16 Build 424, MultiVu Release 2.3.4.19,APPNAME
INFO,Linear Motor Servo Controller,MOTOR_MODULE_NAME
INFO,3101-100 J0,MOTOR_HW_VERSION
INFO,MMC721,MOTOR_SERIAL_NUMBER
INFO,01.04.28,MOTOR_SOFTWARE_VERSION
INFO,Quantum Design Squid Module,SQUID_MODULE_NAME
INFO,3101-501 B0,SQUID_HW_VERSION
INFO,SQM195,SQUID_SERIAL_NUMBER
INFO,01.03.04,SQUID_SOFTWARE_VERSION
INFO,SQUID AC,AC_MODULE_NAME
INFO,3101-401 f1,AC_HW_VERSION
INFO,SAC107,AC_SERIAL_NUMBER
INFO,SQUID AC 00.95.07,AC_SOFTWARE_VERSION
INFO,TCI166,COIL_SERIAL_NUMBER
INFO,0,MOMENT_UNITS
INFO,KMK273S,SAMPLE_MATERIAL
INFO,,SAMPLE_COMMENT
INFO,1.9,SAMPLE_MASS
INFO,,SAMPLE_VOLUME
INFO,,SAMPLE_MOLECULAR_WEIGHT
INFO,,SAMPLE_SIZE
INFO,,SAMPLE_SHAPE
INFO,Straw,SAMPLE_HOLDER
INFO,Standard,SAMPLE_HOLDER_DETAIL
INFO,66.22,SAMPLE_OFFSET
DATATYPE,COMMENT,1
DATATYPE,TIME,2
STARTUPAXIS,X,2
STARTUPAXIS,Y1,5
FIELDGROUP, VSM,2,3,4,5,6,8,9,10,11,14,15
FIELDGROUP, DC, 2,3,4,14,56,57,58,59,60,61,62,63,64,65,66,67,68,69
FIELDGROUP, AC, 2,3,4,11,16,17,18,19,20,21,22,23,24,25,26,27,28,29,30
STARTUPGROUP, All
[Data]
Comment,Time Stamp (sec),Temperature (K),Magnetic Field (Oe),Moment (emu),M. Std. Err. (emu),Transport Action,Averaging Time (sec),Frequency (Hz),Peak Amplitude (mm),Center Position (mm),Lockin Signal' (V),Lockin Signal (V),Range,M. Quad. Signal (emu),AC Moment (emu),AC M. Std Err. (emu),AC Phase (deg),AC Phase Std. Err. (deg),AC Susceptibility (emu/Oe),AC Suscept. Std Err. (emu/Oe),AC X' (emu/Oe),AC X' Std Err. (emu/Oe),AC X'' (emu/Oe),AC X'' Std Err. (emu/Oe),AC Drive (Oe),AC Frequency (Hz),AC Averaging Time (sec),AC Cycles,AC Range,AC Measure Type,AC Signal' (V),AC Signal'' (V),AC Trim Coil Ratio,AC Trim Coil Phase,Min. Temperature (K),Max. Temperature (K),Min. Field (Oe),Max. Field (Oe),Mass (grams),Motor Lag (deg),Pressure (Torr),Measure Count,Measurement Number,SQUID Status (code),Motor Status (code),Measure Status (code),Motor Current (amps),Motor Temp. (C),Temp. Status (code),Field Status (code),Chamber Status (code),Chamber Temp (K),Redirection State,Evercool Status,Average Temp (K),Rotation Angle (deg),Rotator state,DC Moment Fixed Ctr (emu),DC Moment Err Fixed Ctr (emu),DC Moment Free Ctr (emu),DC Moment Err Free Ctr (emu),DC Fixed Fit,DC Free Fit,DC Calculated Center (mm),DC Calculated Center Err (mm),DC Scan Length (mm),DC Scan Time (s),DC Number of Points,DC Squid Drift,DC Min V (V),DC Max V (V),DC Scans per Measure,Map 01,Map 02,Map 03,Map 04,Map 05,Map 06,Map 07,Map 08,Map 09,Map 10,Map 11,Map 12,Map 13,Map 14,Map 15,Map 16
,3870377601.81113,5.00217175483704,100.121528625488,,,6,,,,32.2533668535579,,,10,,,,,,,,,,,,,,,,,,,,,,4.9980001449585,5.00223588943481,100.121528625488,100.121528625488,,,3.80353331565857,,1,0,0,0,0,30.7917900085449,1,1,1,5.00210237503052,0,4232058592,5.00018601417542,,,0.0022202243123769,0.000110250647898902,0.00222656833737267,0.000110255527515032,0.922314763069153,0.979141116142273,31.9682655334473,0,35,4,200,0.000186505392775871,-0.842552125453949,0.237548962235451,1,,,,,,,,,,,,,,,,
,3870377667.31438,9.37284374237061,100.121528625488,,,6,,,,32.2533668535579,,,10,,,,,,,,,,,,,,,,,,,,,,8.99337768554687,9.70100784301758,100.121528625488,100.121528625488,,,4.6411714553833,,1,0,0,0,0.0138092041015625,31.2805480957031,6,1,1,9.75230979919434,0,4232058752,9.35487260818482,,,0.00332152872615514,0.000164957175828207,0.00333093041948332,0.000164964322164349,0.920889794826508,0.973327577114105,31.9695053100586,5.25315761566162,35,4,200,0.00183513422962278,-1.35520160198212,0.288745433092117,1,,,,,,,,,,,,,,,,
,3870377734.27551,14.642972946167,100.121528625488,,,6,,,,32.2584099292056,,,10,,,,,,,,,,,,,,,,,,,,,,14.2603626251221,14.9974784851074,100.121528625488,100.121528625488,,,6.11354970932007,,1,0,0,0,0.0138092041015625,30.7917900085449,6,1,1,15.0255832672119,0,4232058752,14.625232219696,,,0.00441335758193926,0.000219160481808169,0.00442603010401851,0.0002191709354559,0.922058582305908,0.978690147399902,31.9727268218994,0,35,4,200,0.000867594557348639,-1.72692048549652,0.429608255624771,1,,,,,,,,,,,,,,,,
,3870377792.98171,19.3922157287598,100.121528625488,,,6,,,,32.2584099292056,,,10,,,,,,,,,,,,,,,,,,,,,,19.0703811645508,19.715295791626,100.121528625488,100.121528625488,,,6.40744495391846,,1,0,0,0,0,31.2805480957031,2,1,1,19.7634429931641,0,4232058656,19.3927853902181,,,0.00468363375609118,0.000232559936011758,0.00469666519665352,0.00023256910629651,0.923275113105774,0.979361832141876,31.9768314361572,5.25466251373291,35,4,200,0.00023699075973127,-1.81505560874939,0.460992157459259,1,,,,,,,,,,,,,,,,
,3870377860.21704,24.7586574554443,100.121528625488,,,6,,,,32.2638458847539,,,10,,,,,,,,,,,,,,,,,,,,,,24.3830451965332,25.0957984924316,100.121528625488,100.121528625488,,,6.5899658203125,,1,0,0,0,0.0138092041015625,30.7917900085449,2,1,1,25.1342697143555,0,4232058688,24.7359704971313,,,0.00459132340004452,0.000227976141367686,0.00460409347892677,0.000227985573820262,0.923289656639099,0.979274809360504,31.9824161529541,5.25451850891113,35,4,200,-8.12459184089676E-5,-1.78587591648102,0.448460102081299,1,,,,,,,,,,,,,,,,
,3870377918.93795,29.4359817504883,100.121528625488,,,6,,,,32.2638458847539,,,10,,,,,,,,,,,,,,,,,,,,,,29.0534057617188,29.7678985595703,100.121528625488,100.121528625488,,,6.76283645629883,,1,0,0,0,0.0138092041015625,30.7917900085449,2,1,1,29.8185577392578,0,4232058688,29.4039707183838,,,0.00439036941867519,0.000217972917881405,0.00440205075113598,0.000217981430266405,0.924798011779785,0.979140400886536,31.9885387420654,0.201506823301315,35,4,200,-0.000153967295773327,-1.71714615821838,0.420633941888809,1,,,,,,,,,,,,,,,,
,3870377986.0426,34.8112258911133,100.121528625488,,,6,,,,32.2692553143689,,,10,,,,,,,,,,,,,,,,,,,,,,34.4190979003906,35.1439170837402,100.121528625488,100.121528625488,,,6.85657691955566,,1,0,0,0,0.0138092041015625,30.7917900085449,2,1,1,35.2033538818359,0,4232058688,34.7836654663086,,,0.00412127838066656,0.000204600607137574,0.00413199785721465,0.00020460920631313,0.925609171390534,0.979069948196411,31.9972362518311,5.25477313995361,35,4,200,-0.000280954671325162,-1.62377560138702,0.383519321680069,1,,,,,,,,,,,,,,,,
,3870378053.25829,40.185079574585,100.121528625488,,,6,,,,32.2744119532188,,,10,,,,,,,,,,,,,,,,,,,,,,39.810474395752,40.5432167053223,100.121528625488,100.121528625488,,,6.93173456192017,,1,0,0,0,0.0138092041015625,31.2805480957031,2,1,1,40.559684753418,0,4232058592,40.1802658081055,,,0.00384749713455987,0.00019099165658894,0.00385714533479538,0.000190999251190194,0.926811754703522,0.978992521762848,32.0072860717773,5.25548267364502,35,4,200,-0.000190125196240842,-1.52822816371918,0.345751821994782,1,,,,,,,,,,,,,,,,
,3870378120.50446,45.5999889373779,100.121528625488,,,6,,,,32.2796411913613,,,10,,,,,,,,,,,,,,,,,,,,,,45.2129821777344,45.9604148864746,100.121528625488,100.121528625488,,,7.03937435150146,,1,0,0,0,0,30.7917900085449,2,1,1,45.9869956970215,0,4232058656,45.5829437255859,,,0.00358349790554218,0.000177867350995521,0.00359207476262211,0.000177873742501532,0.928302884101868,0.978920102119446,32.0185432434082,1.73803127836436E-5,35,4,200,-0.00026053941110149,-1.43582797050476,0.309572547674179,1,,,,,,,,,,,,,,,,
,3870378187.50543,51.0203666687012,100.121528625488,,,6,,,,32.2847933413251,,,10,,,,,,,,,,,,,,,,,,,,,,50.6360359191895,51.3662719726562,100.121528625488,100.121528625488,,,7.07717323303223,,1,0,0,0,0.0138092041015625,31.2805480957031,2,1,1,51.4046974182129,0,4232058720,50.9987319946289,,,0.00333645900443056,0.000165585003667149,0.00334401467913534,0.000165590476589172,0.93004435300827,0.97883927822113,32.0307807922363,3.54655664175793E-36,35,4,200,-0.000155914283823222,-1.34921383857727,0.275741100311279,1,,,,,,,,,,,,,,,,
,3870378254.86852,56.4588565826416,100.121528625488,,,6,,,,32.2904625600577,,,10,,,,,,,,,,,,,,,,,,,,,,56.0483627319336,56.8157768249512,100.121528625488,100.121528625488,,,7.12405014038086,,1,0,0,0,0.0138092041015625,30.7917900085449,2,1,1,56.8693504333496,0,4232058720,56.4325637817383,,,0.00310683709295412,0.000154169422717795,0.00311344339600578,0.000154173139690727,0.931883573532104,0.97877436876297,32.0439147949219,5.25783634185791,35,4,200,-0.000236146777751856,-1.26871538162231,0.244378328323364,1,,,,,,,,,,,,,,,,
,3870378322.19861,61.9196510314941,100.121528625488,,,6,,,,32.2957329631249,,,10,,,,,,,,,,,,,,,,,,,,,,61.5376586914062,62.2684097290039,100.121528625488,100.121528625488,,,7.19580888748169,,1,0,0,0,0.0138092041015625,30.7917900085449,2,1,1,62.301643371582,0,4232058752,61.9024810791016,,,0.00289767746350789,0.000143769574824491,0.00290344361132821,0.000143774466997659,0.93403023481369,0.978702783584595,32.057933807373,0,35,4,200,-0.000122144178021699,-1.19520771503448,0.215798452496529,1,,,,,,,,,,,,,,,,
,3870378389.60423,67.4271965026855,100.121528625488,,,6,,,,32.301396842403,,,10,,,,,,,,,,,,,,,,,,,,,,67.0034713745117,67.8385009765625,100.121528625488,100.121528625488,,,7.21742820739746,,1,0,0,0,0.0138092041015625,30.7917900085449,2,1,1,67.8509216308594,0,4232058656,67.4169776916504,,,0.00270706571225469,0.000134292786604844,0.00271203089606856,0.000134296170202549,0.936260342597961,0.9786376953125,32.0726661682129,,35,4,200,-0.00018850780907087,-1.12827432155609,0.295759230852127,1,,,,,,,,,,,,,,,,
,3870378465.88732,73.6062965393066,100.121528625488,,,6,,,,32.3116754545102,,,10,,,,,,,,,,,,,,,,,,,,,,73.2136154174805,73.9826889038086,100.121528625488,100.121528625488,,,7.24089336395264,,1,0,0,0,0.0176239013671875,30.7917900085449,2,1,1,73.9989776611328,0,4232058688,73.5998847961426,,,0.00251229132372536,0.000124616609067177,0.00251664133977088,0.000124620969553608,0.938008844852447,0.978547990322113,32.0901565551758,5.25933885574341,35,4,200,-0.000114086731628049,-0.951211333274841,0.271859973669052,1,,,,,,,,,,,,,,,,
,3870378533.69649,79.1586570739746,100.121528625488,,,6,,,,32.3171957536184,,,10,,,,,,,,,,,,,,,,,,,,,,78.7832946777344,79.4963073730469,100.121528625488,100.121528625488,,,7.30393838882446,,1,0,0,0,0.0150299072265625,30.7917900085449,2,1,1,79.5340194702148,0,4232058816,79.1356430053711,,,0.00235660964797085,0.000116876243403352,0.00236029758108778,0.00011687921515689,0.940555870532989,0.978478193283081,32.1061782836914,0.190095946192741,35,4,200,-9.1740170319099E-5,-0.896499872207642,0.250544041395187,1,,,,,,,,,,,,,,,,
,3870378609.54247,85.3363914489746,100.121528625488,,,6,,,,32.3291060244399,,,10,,,,,,,,,,,,,,,,,,,,,,84.9169540405273,85.6613922119141,100.121528625488,100.121528625488,,,7.33052968978882,,1,0,0,0,0,30.7917900085449,2,1,1,85.7558288574219,0,4232058656,85.2951210021973,,,0.00219950664705391,0.000109074241383354,0.0022027406898176,0.000109077414887226,0.942191958427429,0.978391885757446,32.124942779541,0,35,4,200,-0.00014836253831163,-0.841451585292816,0.229074418544769,1,,,,,,,,,,,,,,,,
,3870378686.06073,91.6512336730957,100.121528625488,,,6,,,,32.3393260853791,,,10,,,,,,,,,,,,,,,,,,,,,,91.2160491943359,92.0332412719727,100.121528625488,100.121528625488,,,7.32744789123535,,1,0,0,0,0,30.7917900085449,2,1,1,92.0864181518555,0,4232058592,91.6241539001465,,,0.00205764547221458,0.000102026351119716,0.00206039188799496,0.00010202859564859,0.94441545009613,0.978306233882904,32.1444664001465,0,35,4,200,-0.00013464453513734,-0.791679382324219,0.209633141756058,1,,,,,,,,,,,,,,,,
,3870378762.03621,97.9757385253906,100.121528625488,,,6,,,,32.350270710504,,,10,,,,,,,,,,,,,,,,,,,,,,97.5941009521484,98.3242111206055,100.121528625488,100.121528625488,,,7.33841133117676,,1,0,0,0,0.0152587890625,30.7917900085449,2,1,1,98.3573760986328,0,4232058592,97.9574890136719,,,0.00193086417007593,9.57289866030955E-5,0.00193321923439684,9.57313774567001E-5,0.946529865264893,0.978203535079956,32.1643943786621,5.26293659210205,35,4,200,-0.000119374926725868,-0.747231423854828,0.192236050963402,1,,,,,,,,,,,,,,,,
,3870378838.07706,104.268058776855,100.121528625488,,,6,,,,32.3618188194012,,,10,,,,,,,,,,,,,,,,,,,,,,103.863845825195,104.623069763184,100.121528625488,100.121528625488,,,7.38408088684082,,1,0,0,0,0.0182342529296875,30.7917900085449,2,1,1,104.672271728516,0,4232058688,104.246959686279,,,0.0018161630204963,9.00322788042702E-5,0.00181816346600054,9.00340871098485E-5,0.948638021945953,0.978094100952148,32.1849594116211,0.127327561378479,35,4,200,-5.76756101509091E-5,-0.707053184509277,0.176506727933884,1,,,,,,,,,,,,,,,,
,3870378913.77091,110.54683303833,100.121528625488,,,6,,,,32.3738351557097,,,10,,,,,,,,,,,,,,,,,,,,,,110.158355712891,110.917335510254,100.121528625488,100.121528625488,,,7.42695140838623,,1,0,0,0,0.0205230712890625,30.3030319213867,2,1,1,110.93531036377,0,4232058880,110.542250061035,,,0.00171240630897367,8.487923740261E-5,0.00171409121699381,8.48807489261717E-5,0.950869560241699,0.977970480918884,32.2066764831543,3.86631941795349,35,4,200,-4.97924847877584E-5,-0.670677185058594,0.16226914525032,1,,,,,,,,,,,,,,,,
,3870378999.29908,117.608131408691,100.121528625488,,,6,,,,32.3906550971301,,,10,,,,,,,,,,,,,,,,,,,,,,117.213569641113,117.963584899902,100.121528625488,100.121528625488,,,7.47297668457031,,1,0,0,0,0.0186920166015625,30.7917900085449,2,1,1,118.00269317627,0,4232058688,117.601750183105,,,0.00160662472413499,7.96288717298231E-5,0.0016080490823683,7.96298811523891E-5,0.95270824432373,0.977820515632629,32.231689453125,0,35,4,200,-9.24042251426727E-5,-0.633656203746796,0.147748291492462,1,,,,,,,,,,,,,,,,
,3870379085.08852,124.728031158447,100.121528625488,,,6,,,,32.4084625710965,,,10,,,,,,,,,,,,,,,,,,,,,,124.316368103027,125.096061706543,100.121528625488,100.121528625488,,,7.49944353103638,,1,0,0,0,0.0138092041015625,30.7917900085449,2,1,1,125.139694213867,0,4232058656,124.717882537842,,,0.00151077304471244,7.48721710784477E-5,0.00151198317838428,7.48730116926644E-5,0.95443594455719,0.977657079696655,32.2573432922363,1.20898366731126E-5,35,4,200,-3.47306668118108E-5,-0.600148856639862,0.134590357542038,1,,,,,,,,,,,,,,,,
,3870379170.93795,131.910285949707,100.121528625488,,,6,,,,32.427456086238,,,10,,,,,,,,,,,,,,,,,,,,,,131.529006958008,132.258377075195,100.121528625488,100.121528625488,,,7.49338483810425,,1,0,0,0,0.0211334228515625,30.7917900085449,2,1,1,132.291564941406,0,4232058720,131.892431640625,,,0.00142359747083025,7.05468094998723E-5,0.00142463120375486,7.0547599489662E-5,0.956032395362854,0.977515876293182,32.2836723327637,5.26535367965698,35,4,200,-3.01099953503581E-5,-0.569624125957489,0.122633866965771,1,,,,,,,,,,,,,,,,
,3870379256.1936,138.934631347656,100.121528625488,,,6,,,,32.4474135074883,,,10,,,,,,,,,,,,,,,,,,,,,,138.528289794922,139.301239013672,100.121528625488,100.121528625488,,,7.49464464187622,,1,0,0,0,0.0189208984375,30.7917900085449,2,1,1,139.340972900391,0,4232058560,138.910917663574,,,0.00134465875652687,6.6630761217731E-5,0.00134554261800847,6.66313383130597E-5,0.9574875831604,0.977373957633972,32.3104515075684,5.68422842025757,35,4,200,-2.79137148027075E-5,-0.54201751947403,0.111829735338688,1,,,,,,,,,,,,,,,,
,3870379341.79434,146.039276123047,100.121528625488,,,6,,,,32.468451503828,,,10,,,,,,,,,,,,,,,,,,,,,,145.645034790039,146.399856567383,100.121528625488,100.121528625488,,,7.51394844055176,,1,0,0,0,0.0138092041015625,30.7917900085449,2,1,1,146.433517456055,0,4232058656,146.029499816895,,,0.00127212354034258,6.30329521521828E-5,0.00127288769490985,6.3033645636396E-5,0.958829402923584,0.977255761623383,32.3378868103027,0,35,4,200,-2.79471314570401E-5,-0.516601800918579,0.101925514638424,1,,,,,,,,,,,,,,,,
,3870379426.54285,153.096527099609,100.121528625488,,,6,,,,32.4905253545805,,,10,,,,,,,,,,,,,,,,,,,,,,152.701110839844,153.461273193359,100.121528625488,100.121528625488,,,7.55459642410278,,1,0,0,0,0.02044677734375,30.7917900085449,2,1,1,153.491943359375,0,4232058752,153.069741821289,,,0.00120606269717561,5.97568277565645E-5,0.00120672265394224,5.97572866030671E-5,0.959994673728943,0.977134525775909,32.3656196594238,0,35,4,200,-6.30139838904142E-5,-0.49347135424614,0.0929146409034729,1,,,,,,,,,,,,,,,,
,3870379539.03946,162.418151855469,100.121528625488,,,6,,,,32.5239514744577,,,10,,,,,,,,,,,,,,,,,,,,,,162.007202148438,162.762512207031,100.121528625488,100.121528625488,,,7.57656383514404,,1,0,0,0,0.018310546875,30.7917900085449,2,1,1,162.8291015625,0,4232058624,162.385795593262,,,0.00112620386433098,5.57980531298306E-5,0.00112677508613871,5.57984637496941E-5,0.960902571678162,0.976974070072174,32.4037170410156,0,35,4,200,-2.2266745872912E-5,-0.465484231710434,0.0820787027478218,1,,,,,,,,,,,,,,,,
,3870379651.66641,171.79044342041,100.121528625488,,,6,,,,32.5566450656949,,,10,,,,,,,,,,,,,,,,,,,,,,171.384704589844,172.144622802734,100.121528625488,100.121528625488,,,7.59883403778076,,1,0,0,0,0.0215911865234375,30.7917900085449,2,1,1,172.196182250977,0,4232058656,171.762963867187,,,0.00105405238614345,5.22210050546454E-5,0.00105453601574695,5.22213661112485E-5,0.962042272090912,0.976803779602051,32.4423408508301,,35,4,200,-1.68244641827187E-5,-0.440142154693604,0.0723339095711708,1,,,,,,,,,,,,,,,,
,3870379764.38847,181.148620605469,100.121528625488,,,6,,,,32.5911854882188,,,10,,,,,,,,,,,,,,,,,,,,,,180.71826171875,181.516784667969,100.121528625488,100.121528625488,,,7.6233868598938,,1,0,0,0,0.0199127197265625,30.7917900085449,2,1,1,181.578979492187,0,4232058624,181.11750793457,,,0.000988357757940163,4.89645182694154E-5,0.000988773050143126,4.89649132927828E-5,0.963005781173706,0.976648271083832,32.4820251464844,0.189890876412392,35,4,200,-4.79360205645207E-5,-0.41707906126976,0.0634653121232986,1,,,,,,,,,,,,,,,,
,3870379875.98749,190.402931213379,100.121528625488,,,6,,,,32.6274426477126,,,10,,,,,,,,,,,,,,,,,,,,,,190.009963989258,190.766082763672,100.121528625488,100.121528625488,,,7.65005350112915,,1,0,0,0,0.0138092041015625,30.3030319213867,2,1,1,190.7958984375,0,4232058720,190.390420532227,,,0.000929088251502909,4.60271043452408E-5,0.000929451441364049,4.60274359394073E-5,0.963667094707489,0.976472616195679,32.5221099853516,0,35,4,200,-1.26115974126151E-5,-0.396228641271591,0.0555085353553295,1,,,,,,,,,,,,,,,,
,3870379986.49484,199.580940246582,100.121528625488,,,6,,,,32.6649441614694,,,10,,,,,,,,,,,,,,,,,,,,,,199.186599731445,199.954437255859,100.121528625488,100.121528625488,,,7.68539571762085,,1,0,0,0,0.0157928466796875,30.7917900085449,2,1,1,199.975280761719,0,4232058624,199.568173217773,,,0.000875136405107884,4.33534777283041E-5,0.000875456524231124,4.33537295528883E-5,0.964214384555817,0.976305305957794,32.562931060791,5.26655769348145,35,4,200,-1.427417191735E-5,-0.377225339412689,0.0482984483242035,1,,,,,,,,,,,,,,,,
,3870380097.31663,208.79753112793,100.121528625488,,,6,,,,32.7042294514021,,,10,,,,,,,,,,,,,,,,,,,,,,208.403259277344,209.167205810547,100.121528625488,100.121528625488,,,7.73318481445313,,1,0,0,0,0.0138092041015625,31.2805480957031,2,1,1,209.191802978516,0,4232058752,208.784240722656,,,0.000825347618987079,4.08863800882721E-5,0.000825633278800044,4.08866040556396E-5,0.964628577232361,0.976112425327301,32.6050148010254,,35,4,200,-9.99277472146787E-6,-0.359673738479614,0.0416828766465187,1,,,,,,,,,,,,,,,,
,3870380208.2754,218.021133422852,100.121528625488,,,6,,,,32.7455478199806,,,10,,,,,,,,,,,,,,,,,,,,,,217.611694335938,218.347106933594,100.121528625488,100.121528625488,,,7.78100633621216,,1,0,0,0,0.0164794921875,30.7917900085449,2,1,1,218.430572509766,0,4232058656,217.979042053223,,,0.000779276647714362,3.86037843775778E-5,0.000779535194262745,3.86039302118205E-5,0.964855074882507,0.975919425487518,32.6481971740723,5.26733064651489,35,4,200,-1.46408392538433E-5,-0.343409508466721,0.0355523675680161,1,,,,,,,,,,,,,,,,
,3870380319.0046,227.209838867187,100.121528625488,,,6,,,,32.7884568894476,,,10,,,,,,,,,,,,,,,,,,,,,,226.790115356445,227.549270629883,100.121528625488,100.121528625488,,,7.82722330093384,,1,0,0,0,0.0145721435546875,30.7917900085449,2,1,1,227.62956237793,0,4232058624,227.170938110352,,,0.000736895538408166,3.65041164419844E-5,0.000737131515245644,3.65042273542091E-5,0.965018391609192,0.975709974765778,32.6927337646484,5.26769971847534,35,4,200,-2.02726187126245E-6,-0.328417629003525,0.0299587287008762,1,,,,,,,,,,,,,,,,
,3870380430.98052,236.53540802002,100.121528625488,,,6,,,,32.833992399765,,,10,,,,,,,,,,,,,,,,,,,,,,236.155746459961,236.881774902344,100.121528625488,100.121528625488,,,7.87155961990356,,1,0,0,0,0.01708984375,30.7917900085449,2,1,1,236.915069580078,0,4232058656,236.51014251709,,,0.000697167082074453,3.45360214639183E-5,0.000697386728582767,3.45361457212749E-5,0.965046286582947,0.975515067577362,32.7391090393066,0.0802652612328529,35,4,200,-6.04556498728925E-6,-0.314294189214706,0.0247999280691147,1,,,,,,,,,,,,,,,,
,3870380541.78537,245.719017028809,100.121528625488,,,6,,,,32.8803902163161,,,10,,,,,,,,,,,,,,,,,,,,,,245.327514648438,246.11051940918,100.121528625488,100.121528625488,,,7.95878601074219,,1,0,0,0,0.0167083740234375,30.7917900085449,2,1,1,246.11051940918,0,4232058688,245.713388061523,,,0.000660528026482447,3.27209363280018E-5,0.000660729634395508,3.27209745559009E-5,0.9651118516922,0.975307404994965,32.7866592407227,5.26634311676025,35,4,200,-2.49138465733267E-5,-0.301191210746765,0.0201368518173695,1,,,,,,,,,,,,,,,,
,3870380652.75934,254.9697265625,100.121528625488,,,6,,,,32.9285524770744,,,10,,,,,,,,,,,,,,,,,,,,,,254.549072265625,255.325149536133,100.121528625488,100.121528625488,,,8.11203002929688,,1,0,0,0,0,30.7917900085449,2,1,1,255.390380859375,0,4232058688,254.938079833984,,,0.000626378879144275,3.10290201654938E-5,0.000626561576536701,3.10290347444128E-5,0.965334534645081,0.975102126598358,32.8368225097656,5.26604175567627,35,4,200,-2.06555773729633E-6,-0.28898623585701,0.0157491490244865,1,,,,,,,,,,,,,,,,
,3870380764.12079,264.272216796875,100.121528625488,,,6,,,,32.9787251677541,,,10,,,,,,,,,,,,,,,,,,,,,,263.882690429687,264.600738525391,100.121528625488,100.121528625488,,,8.27066898345947,,1,0,0,0,0.0138092041015625,30.3030319213867,2,1,1,264.661743164062,0,4232058624,264.238134765625,,,0.000594178456746082,2.94333947302815E-5,0.000594339491130932,2.94334908347371E-5,0.965839266777039,0.974860429763794,32.8907852172852,5.26696014404297,35,4,200,-2.14533829421271E-5,-0.277419447898865,0.0116964755579829,1,,,,,,,,,,,,,,,,
,3870380874.97584,273.465682983398,100.121528625488,,,6,,,,33.0306083741736,,,10,,,,,,,,,,,,,,,,,,,,,,273.078002929687,273.799713134766,100.121528625488,100.121528625488,,,8.16284465789795,,1,0,0,0,0.0138092041015625,31.2805480957031,2,1,1,273.853363037109,0,4232058720,273.440798950195,,,0.000564296701015012,2.79520323791066E-5,0.000564422221499723,2.79520596168963E-5,0.967043995857239,0.974630653858185,32.9506378173828,5.26731395721436,35,4,200,-1.35985319502652E-5,-0.266694158315659,0.00790892448276281,1,,,,,,,,,,,,,,,,
,3870380986.30939,282.669311523438,100.121528625488,,,6,,,,33.0845264881163,,,10,,,,,,,,,,,,,,,,,,,,,,282.272583007813,283.049407958984,100.121528625488,100.121528625488,,,8.14025688171387,,1,0,0,0,0.0138092041015625,30.7917900085449,2,1,1,283.066040039062,0,4232058688,282.66428527832,,,0.000536231877061366,2.6559751993257E-5,0.000536305733346471,2.65597778125176E-5,0.969548881053925,0.974426865577698,33.0216827392578,0.179445937275887,35,4,200,-8.66376694830251E-7,-0.256582409143448,0.00440258672460914,1,,,,,,,,,,,,,,,,
,3870381096.80119,291.849502563477,100.121528625488,,,6,,,,33.1398940952388,,,10,,,,,,,,,,,,,,,,,,,,,,291.453277587891,292.225128173828,100.121528625488,100.121528625488,,,8.1998929977417,,1,0,0,0,0.0138092041015625,30.7917900085449,2,1,1,292.245727539063,0,4232058240,291.835653686523,,,0.00051018495167926,2.52674506353872E-5,0.000510208648302528,2.52674648981567E-5,0.972537100315094,0.974260687828064,33.1034927368164,0,35,4,200,-9.50146659306483E-6,-0.247184813022614,0.00114447739906609,1,,,,,,,,,,,,,,,,
,3870381198.35356,299.377807617188,100.121528625488,,,6,,,,33.1867083667666,,,10,,,,,,,,,,,,,,,,,,,,,,299.274261474609,299.481353759766,100.121528625488,100.121528625488,,,8.38368129730225,,1,0,0,0,0.0138092041015625,30.7917900085449,6,1,1,299.486083984375,0,4232058688,299.387194824219,,,0.000489501809560224,2.42421365677096E-5,0.000489505917388918,2.42421314260977E-5,0.974011778831482,0.974344789981842,33.1709442138672,,35,4,200,8.26784889795817E-6,-0.240080669522285,-0.00200283550657332,1,,,,,,,,,,,,,,,,
,3870381257.1861,299.895904541016,100.121528625488,,,6,,,,33.1867083667666,,,10,,,,,,,,,,,,,,,,,,,,,,299.884429931641,299.906951904297,100.121528625488,100.121528625488,,,8.5750093460083,,1,0,0,0,0.0138092041015625,30.7917900085449,5,1,1,299.907379150391,0,4232058656,299.898416137695,,,0.000487398774974594,2.41378286214538E-5,0.000487400228127659,2.41378172098648E-5,0.974273324012756,0.974407851696014,33.1767196655273,5.26849126815796,35,4,200,1.34526662805001E-5,-0.239187002182007,-0.00222199317067862,1,,,,,,,,,,,,,,,,
,3870381350.71297,298.664901733398,100.121528625488,,,6,,,,33.1811067274533,,,10,,,,,,,,,,,,,,,,,,,,,,298.381072998047,298.966064453125,100.121528625488,100.121528625488,,,8.88079261779785,,1,0,0,0,0.01434326171875,30.3030319213867,2,1,1,298.363739013672,0,4232058080,298.687307739258,,,0.00048946402077412,2.42400919019493E-5,0.000489467413718008,2.4240090126749E-5,0.97428435087204,0.974558055400848,33.1668815612793,5.26815700531006,35,4,200,9.57885640673339E-5,-0.241605028510094,-0.00331086781807244,1,,,,,,,,,,,,,,,,
,3870381460.54184,289.109786987305,100.121528625488,,,6,,,,33.1274925586561,,,10,,,,,,,,,,,,,,,,,,,,,,288.725402832031,289.528228759766,100.121528625488,100.121528625488,,,9.36159992218018,,1,0,0,0,0.0145721435546875,30.7917900085449,2,1,1,288.691345214844,0,4232058592,289.135946655273,,,0.000520179091197499,2.57610483152632E-5,0.000520179209303931,2.57610461982981E-5,0.97454434633255,0.974556446075439,33.1245040893555,0,35,4,200,6.09063026786316E-5,-0.249873384833336,0.00302493595518172,1,,,,,,,,,,,,,,,,
,3870381571.55628,280.383712768555,100.121528625488,,,6,,,,33.0820298409529,,,10,,,,,,,,,,,,,,,,,,,,,,280.021453857422,280.787567138672,100.121528625488,100.121528625488,,,9.51456069946289,,1,0,0,0,0.013885498046875,30.3030319213867,2,1,1,279.979858398438,0,4232058688,280.41608581543,,,0.000547537234651458,2.71162119328477E-5,0.000547553557859343,2.71162129617457E-5,0.97412896156311,0.9753058552742,33.0526962280273,5.26800775527954,35,4,200,4.30710715590976E-5,-0.261176466941834,0.00510379299521446,1,,,,,,,,,,,,,,,,
,3870381682.33979,271.152740478516,100.121528625488,,,6,,,,33.0356390091563,,,10,,,,,,,,,,,,,,,,,,,,,,270.775756835938,271.561157226562,100.121528625488,100.121528625488,,,9.2502498626709,,1,0,0,0,0.0138092041015625,30.7917900085449,2,1,1,270.744323730469,0,4232058752,271.172232055664,,,0.000576303793944838,2.85431270355853E-5,0.000576370504155181,2.85431513431142E-5,0.97120201587677,0.975511312484741,32.9780120849609,5.26747846603394,35,4,200,4.67985300929286E-5,-0.271384507417679,0.00885898806154728,1,,,,,,,,,,,,,,,,
,3870381792.89093,261.966720581055,100.121528625488,,,6,,,,32.9921244287603,,,10,,,,,,,,,,,,,,,,,,,,,,261.588775634766,262.370422363281,100.121528625488,100.121528625488,,,9.08010482788086,,1,0,0,0,0.0138092041015625,30.3030319213867,2,1,1,261.563018798828,0,4232058688,261.982412719727,,,0.00060713036242455,3.00721514118711E-5,0.000607250233971177,3.00722494891374E-5,0.96871554851532,0.975695610046387,32.9172134399414,0,35,4,200,4.88911355205346E-5,-0.282121747732162,0.0130525156855583,1,,,,,,,,,,,,,,,,
,3870381904.17768,252.663558959961,100.121528625488,,,6,,,,32.9500200477648,,,10,,,,,,,,,,,,,,,,,,,,,,252.244934082031,253.119384765625,100.121528625488,100.121528625488,,,8.96357917785645,,1,0,0,0,0.014801025390625,30.7917900085449,2,1,1,252.207733154297,0,4232058208,252.684614562988,,,0.00064087660404541,3.17455554682348E-5,0.000641047381986653,3.17456359151985E-5,0.966856837272644,0.976102352142334,32.8626708984375,0,35,4,200,5.22879054187797E-5,-0.294463813304901,0.0172614380717278,1,,,,,,,,,,,,,,,,
,3870382016.18671,243.106971740723,100.121528625488,,,6,,,,32.9091000072471,,,10,,,,,,,,,,,,,,,,,,,,,,242.738891601562,243.517211914062,100.121528625488,100.121528625488,,,8.86800861358643,,1,0,0,0,0.0138092041015625,30.7917900085449,2,1,1,242.696731567383,0,4232058720,243.13358001709,,,0.000678439895341158,3.36074093186455E-5,0.000678644109613174,3.36075492955479E-5,0.965821802616119,0.976019203662872,32.8164520263672,,35,4,200,3.1804676837055E-5,-0.306273311376572,0.0234230943024158,1,,,,,,,,,,,,,,,,
,3870382126.31459,233.931732177734,100.121528625488,,,6,,,,32.8716026300932,,,10,,,,,,,,,,,,,,,,,,,,,,233.543075561523,234.357925415039,100.121528625488,100.121528625488,,,8.79810333251953,,1,0,0,0,0.0160980224609375,30.7917900085449,2,1,1,233.50553894043,0,4232058560,233.959591674805,,,0.000717240987895589,3.55309621834543E-5,0.000717492221692652,3.55312217021459E-5,0.964617371559143,0.976193964481354,32.7720413208008,,35,4,200,6.85960112605244E-5,-0.32009756565094,0.0284738410264254,1,,,,,,,,,,,,,,,,
,3870382236.4481,224.674087524414,100.121528625488,,,6,,,,32.8352808745231,,,10,,,,,,,,,,,,,,,,,,,,,,224.298690795898,225.085144042969,100.121528625488,100.121528625488,,,8.73772048950195,,1,0,0,0,0.0171661376953125,30.7917900085449,2,1,1,224.263031005859,0,4232058592,224.703578186035,,,0.000758107945667405,3.75573095013062E-5,0.000758414418355224,3.75575501989751E-5,0.963254332542419,0.976431727409363,32.7280235290527,0,35,4,200,4.96927204949316E-5,-0.334473490715027,0.0339238680899143,1,,,,,,,,,,,,,,,,
,3870382347.63072,215.466232299805,100.121528625488,,,6,,,,32.8004125348693,,,10,,,,,,,,,,,,,,,,,,,,,,215.102554321289,215.905212402344,100.121528625488,100.121528625488,,,8.67520523071289,,1,0,0,0,0.0138092041015625,30.7917900085449,2,1,1,215.027252197266,0,4232058624,215.513214111328,,,0.000803179706483896,3.97930625440733E-5,0.000803566202012937,3.97935363358461E-5,0.961345314979553,0.976403832435608,32.6839485168457,1.16588098535431E-5,35,4,200,5.25137365912087E-5,-0.350455939769745,0.0399473756551743,1,,,,,,,,,,,,,,,,
,3870382459.56528,206.114883422852,100.121528625488,,,6,,,,32.7652624835798,,,10,,,,,,,,,,,,,,,,,,,,,,205.724792480469,206.579971313477,100.121528625488,100.121528625488,,,8.61595821380615,,1,0,0,0,0.0147247314453125,30.3030319213867,2,1,1,205.649795532227,0,4232058624,206.152600097656,,,0.000851995341626396,4.22144238122436E-5,0.00085245983762252,4.22147576280072E-5,0.959653437137604,0.976446747779846,32.6406669616699,5.26665878295898,35,4,200,7.60127586545423E-5,-0.367768406867981,0.0464120283722878,1,,,,,,,,,,,,,,,,
,3870382572.06338,196.735748291016,100.121528625488,,,6,,,,32.7306611193265,,,10,,,,,,,,,,,,,,,,,,,,,,196.363479614258,197.148086547852,100.121528625488,100.121528625488,,,8.56036281585693,,1,0,0,0,0.0168609619140625,30.7917900085449,2,1,1,196.32341003418,0,4232058656,196.767231750488,,,0.00090515311438081,4.48519407612726E-5,0.000905724794521863,4.48524443027036E-5,0.957683444023132,0.976508975028992,32.5967559814453,5.26529455184937,35,4,200,6.1571117839776E-5,-0.386531174182892,0.0534210242331028,1,,,,,,,,,,,,,,,,
,3870382684.55068,187.314224243164,100.121528625488,,,6,,,,32.696563913896,,,10,,,,,,,,,,,,,,,,,,,,,,186.942489624023,187.734069824219,100.121528625488,100.121528625488,,,8.48345565795898,,1,0,0,0,0.0138092041015625,30.7917900085449,2,1,1,186.894378662109,0,4232058688,187.329223632813,,,0.000962424507228758,4.76934188690929E-5,0.000963109466498664,4.76941151184484E-5,0.955945670604706,0.97657310962677,32.554615020752,5.26473188400269,35,4,200,8.86709822225384E-5,-0.406775206327438,0.0609898418188095,1,,,,,,,,,,,,,,,,
,3870382796.89918,177.92414855957,100.121528625488,,,6,,,,32.6635564314475,,,10,,,,,,,,,,,,,,,,,,,,,,177.549850463867,178.348663330078,100.121528625488,100.121528625488,,,8.4126033782959,,1,0,0,0,0.000152587890625,30.3030319213867,2,1,1,177.499633789062,0,4232058720,177.96434173584,,,0.00102605505071905,5.08512298796515E-5,0.00102687290257782,5.08515922284883E-5,0.95395165681839,0.976691842079163,32.5124626159668,3.90360546112061,35,4,200,9.65014478424564E-5,-0.429411947727203,0.0693527162075043,1,,,,,,,,,,,,,,,,
,3870382909.42104,168.517890930176,100.121528625488,,,6,,,,32.6307613377968,,,10,,,,,,,,,,,,,,,,,,,,,,168.157989501953,168.942321777344,100.121528625488,100.121528625488,,,8.35949897766113,,1,0,0,0,0.0002288818359375,30.3030319213867,2,1,1,168.093460083008,0,4232058752,168.557006835938,,,0.00109538868226302,5.42918850681984E-5,0.00109636290631789,5.42926248795317E-5,0.952198266983032,0.976832211017609,32.4716644287109,0,35,4,200,7.42531483410858E-5,-0.453960746526718,0.0785081014037132,1,,,,,,,,,,,,,,,,
,3870383022.10205,159.146186828613,100.121528625488,,,6,,,,32.5990396617835,,,10,,,,,,,,,,,,,,,,,,,,,,158.787780761719,159.570220947266,100.121528625488,100.121528625488,,,8.30379486083984,,1,0,0,0,0.01983642578125,30.7917900085449,2,1,1,158.722152709961,0,4232058592,159.193551635742,,,0.00117149818338973,5.80695242330809E-5,0.00117264758366677,5.80700855081673E-5,0.950312852859497,0.976983785629272,32.4314613342285,7.45560464565642E-5,35,4,200,8.63582754391246E-5,-0.480924665927887,0.0885588005185127,1,,,,,,,,,,,,,,,,
,3870383134.89764,149.77067565918,100.121528625488,,,6,,,,32.5681917846564,,,10,,,,,,,,,,,,,,,,,,,,,,149.38688659668,150.216064453125,100.121528625488,100.121528625488,,,8.26253318786621,,1,0,0,0,0.016937255859375,30.7917900085449,2,1,1,149.325286865234,0,4232058656,149.809971618652,,,0.00125626438372392,6.22774878454643E-5,0.00125763458216139,6.22784368017081E-5,0.9483482837677,0.977161347866058,32.3918800354004,1.44893419928849E-5,35,4,200,0.000128476181998849,-0.510965883731842,0.0996790528297424,1,,,,,,,,,,,,,,,,
,3870383220.73558,142.660438537598,100.121528625488,,,6,,,,32.5480453037031,,,10,,,,,,,,,,,,,,,,,,,,,,142.315567016602,143.05046081543,100.121528625488,100.121528625488,,,8.23609733581543,,1,0,0,0,0.02105712890625,30.3030319213867,2,1,1,142.270416259766,0,4232058592,142.69465637207,,,0.00132443372449883,6.56632057991161E-5,0.00132600527734719,6.56638227829881E-5,0.946517825126648,0.977387130260468,32.3635711669922,0.190029010176659,35,4,200,0.000122697820188478,-0.534870743751526,0.108739234507084,1,,,,,,,,,,,,,,,,
,3870383305.49783,135.594268798828,100.121528625488,,,6,,,,32.5260230291639,,,10,,,,,,,,,,,,,,,,,,,,,,135.232025146484,135.994674682617,100.121528625488,100.121528625488,,,8.22131061553955,,1,0,0,0,0.018768310546875,30.7917900085449,2,1,1,135.193862915039,0,4232058496,135.61882019043,,,0.00140065924667618,6.94478139157124E-5,0.00140244252281866,6.94486556382208E-5,0.945068418979645,0.977607309818268,32.3350791931152,0,35,4,200,0.000109156033431645,-0.561809360980988,0.118825070559978,1,,,,,,,,,,,,,,,,
,3870383392.15132,128.389675140381,100.121528625488,,,6,,,,32.5040925595685,,,10,,,,,,,,,,,,,,,,,,,,,,128.036346435547,128.785430908203,100.121528625488,100.121528625488,,,8.20804595947266,,1,0,0,0,0.0176239013671875,30.7917900085449,2,1,1,127.993919372559,0,4232058592,128.423097229004,,,0.00148645420042436,7.37084117044208E-5,0.00148851016181449,7.37104893421592E-5,0.943445086479187,0.977740466594696,32.306224822998,0.190010443329811,35,4,200,0.000157203627168201,-0.592177867889404,0.130242228507996,1,,,,,,,,,,,,,,,,
,3870383477.5747,121.247020721436,100.121528625488,,,6,,,,32.4828989833354,,,10,,,,,,,,,,,,,,,,,,,,,,120.889709472656,121.638442993164,100.121528625488,100.121528625488,,,8.1755838394165,,1,0,0,0,0.0170135498046875,30.3030319213867,2,1,1,120.855598449707,0,4232058464,121.266956329346,,,0.00157859275365715,7.82836611227489E-5,0.00158090790994836,7.82856687948794E-5,0.942024230957031,0.977932333946228,32.2787895202637,INF,35,4,200,0.000160640556714498,-0.624517977237701,0.14262492954731,1,,,,,,,,,,,,,,,,
,3870383563.02891,114.087230682373,100.121528625488,,,6,,,,32.4626931941293,,,10,,,,,,,,,,,,,,,,,,,,,,113.699829101562,114.51921081543,100.121528625488,100.121528625488,,,8.11492538452148,,1,0,0,0,0.020599365234375,30.3030319213867,2,1,1,113.655250549316,0,4232058656,114.115367889404,,,0.00168130038767758,8.33852071124498E-5,0.00168393461647548,8.33872762303149E-5,0.940361738204956,0.978057622909546,32.2515678405762,5.26093053817749,35,4,200,0.000183682845090516,-0.660724341869354,0.156323373317718,1,,,,,,,,,,,,,,,,
,3870383648.46098,107.000576019287,100.121528625488,,,6,,,,32.4427840036803,,,10,,,,,,,,,,,,,,,,,,,,,,106.60472869873,107.41641998291,100.121528625488,100.121528625488,,,8.05751323699951,,1,0,0,0,0.016326904296875,30.7917900085449,2,1,1,106.584732055664,0,4232058816,107.010012817383,,,0.00179505503217468,8.90350675707691E-5,0.00179806002501249,8.90383944003524E-5,0.938854515552521,0.978202879428863,32.225284576416,,35,4,200,0.000218713539652526,-0.700816333293915,0.17158468067646,1,,,,,,,,,,,,,,,,
,3870383735.11816,99.6638259887695,100.121528625488,,,6,,,,32.4235494944157,,,10,,,,,,,,,,,,,,,,,,,,,,99.3208999633789,100.053901672363,100.121528625488,100.121528625488,,,8.02864170074463,,1,0,0,0,0.0180816650390625,30.3030319213867,2,1,1,99.2737503051758,0,4232058560,99.6933006286621,,,0.00192762233752948,9.5620842424111E-5,0.00193103744829164,9.56230979137059E-5,0.937103748321533,0.978305637836456,32.1988296508789,5.26169443130493,35,4,200,0.000198795387404971,-0.7472163438797,0.18946199119091,1,,,,,,,,,,,,,,,,
,3870383820.2814,92.6060905456543,100.121528625488,,,6,,,,32.4048232493232,,,10,,,,,,,,,,,,,,,,,,,,,,92.2534027099609,92.9359817504883,100.121528625488,100.121528625488,,,8.00543785095215,,1,0,0,0,0.019683837890625,30.7917900085449,2,1,1,92.2045669555664,0,4232058624,92.594735039605,,,0.00206898744238424,0.000102643667983195,0.00207289671922047,0.000102647467456585,0.935534477233887,0.978482007980347,32.1733551025391,5.67215633392334,35,4,200,0.000231381098274142,-0.796771109104157,0.208543181419373,1,,,,,,,,,,,,,,,,
,3870383905.83362,85.4215126037598,100.121528625488,,,6,,,,32.3869925224506,,,10,,,,,,,,,,,,,,,,,,,,,,85.0678405761719,85.8068161010742,100.121528625488,100.121528625488,,,7.9853515625,,1,0,0,0,0.0194549560546875,30.3030319213867,2,1,1,85.0362091064453,0,4232058720,85.4416526794434,,,0.0022302178679545,0.000110655293361076,0.00223466412101411,0.000110657683434803,0.933758616447449,0.978613972663879,32.1482696533203,0,35,4,200,0.000255573017057031,-0.853343069553375,0.23032408952713,1,,,,,,,,,,,,,,,,
,3870383991.43615,78.245792388916,100.121528625488,,,6,,,,32.369972229817,,,10,,,,,,,,,,,,,,,,,,,,,,77.8769912719727,78.6494827270508,100.121528625488,100.121528625488,,,7.96027851104736,,1,0,0,0,0.0203704833984375,30.7917900085449,2,1,1,77.8421020507812,0,4232058656,78.2676315307617,,,0.00241237775712484,0.000119707819680007,0.00241751960194683,0.000119712224441083,0.931972086429596,0.978700339794159,32.1239471435547,8.88481881702319E-5,35,4,200,0.000201112095965073,-0.917195796966553,0.254911959171295,1,,,,,,,,,,,,,,,,
,3870384076.22404,71.0740928649902,100.121528625488,,,6,,,,32.3539196420198,,,10,,,,,,,,,,,,,,,,,,,,,,70.7158584594727,71.483772277832,100.121528625488,100.121528625488,,,7.88878536224365,,1,0,0,0,0.0138092041015625,30.7917900085449,2,1,1,70.6644134521484,0,4232058560,71.0965843200684,,,0.00261678202266556,0.000129867263735674,0.0026227168724835,0.00012987313600124,0.930147528648376,0.978768289089203,32.1004867553711,9.11820025066845E-5,35,4,200,0.000316638237563893,-1.09738302230835,0.282603561878204,1,,,,,,,,,,,,,,,,
,3870384160.94108,63.911434173584,100.121528625488,,,6,,,,32.3371588874736,,,10,,,,,,,,,,,,,,,,,,,,,,63.544189453125,64.3261184692383,100.121528625488,100.121528625488,,,7.812903881073,,1,0,0,0,0.0146484375,30.3030319213867,2,1,1,63.4967498779297,0,4232058752,63.9431652069092,,,0.00285300792751084,0.000141606907274987,0.00285979577124482,0.000141612725376673,0.928548038005829,0.978838562965393,32.0771865844727,0,35,4,200,0.000295354169793427,-1.18005907535553,0.314310818910599,1,,,,,,,,,,,,,,,,
,3870384237.03725,57.4711761474609,100.121528625488,,,6,,,,32.3244368293648,,,10,,,,,,,,,,,,,,,,,,,,,,57.1111717224121,57.8731536865234,100.121528625488,100.121528625488,,,7.75299787521362,,1,0,0,0,0.0138092041015625,30.7917900085449,2,1,1,57.0691986083984,0,4232058528,57.4915657043457,,,0.00308635034537302,0.00015320664118945,0.00309404021820706,0.000153212094151462,0.926934599876404,0.978857934474945,32.0579872131348,,35,4,200,0.000307477894239128,-1.26367890834808,0.237193137407303,1,,,,,,,,,,,,,,,,
,3870384312.67878,51.0883827209473,100.121528625488,,,6,,,,32.3126113818807,,,10,,,,,,,,,,,,,,,,,,,,,,50.7031784057617,51.4903526306152,100.121528625488,100.121528625488,,,7.70421981811523,,1,0,0,0,0,30.3030319213867,2,1,1,50.6864128112793,0,4232058592,51.1064239501953,,,0.00334723052657579,0.000166176083712683,0.00335596993570142,0.000166182499766008,0.925366103649139,0.978837728500366,32.0399475097656,0,35,4,200,0.000355520052835345,-1.35602462291718,0.272595047950745,1,,,,,,,,,,,,,,,,
,3870384388.29912,44.6896514892578,100.121528625488,,,6,,,,32.3015858231341,,,10,,,,,,,,,,,,,,,,,,,,,,44.3179321289063,45.0946044921875,100.121528625488,100.121528625488,,,7.62134647369385,,1,0,0,0,0.0138092041015625,30.7917900085449,2,1,1,44.2846984863281,0,4232058752,44.7018718719482,,,0.00363496314309892,0.000180480407967055,0.00364488194648301,0.000180488960728132,0.923927962779999,0.978823959827423,32.0232162475586,5.65890598297119,35,4,200,0.000409100030083209,-1.45794272422791,0.311604201793671,1,,,,,,,,,,,,,,,,
,3870384455.38205,39.042537689209,100.121528625488,,,6,,,,32.2963449929232,,,10,,,,,,,,,,,,,,,,,,,,,,38.6735343933105,39.4538116455078,100.121528625488,100.121528625488,,,7.47611284255981,,1,0,0,0,0.0138092041015625,30.7917900085449,2,1,1,38.6312637329102,0,4232058688,39.0615345001221,,,0.00390945864541744,0.00019413988246373,0.00392074143215612,0.000194149261270637,0.921907424926758,0.97878897190094,32.0099868774414,0,35,4,200,0.000447502039605752,-1.5551997423172,0.348978787660599,1,,,,,,,,,,,,,,,,
,3870384531.20825,32.6319408416748,100.121528625488,,,6,,,,32.2841054183234,,,10,,,,,,,,,,,,,,,,,,,,,,32.282585144043,33.0490989685059,100.121528625488,100.121528625488,,,7.34688234329224,,1,0,0,0,0.0138092041015625,30.7917900085449,2,1,1,32.2147827148438,0,4232058592,32.6593162536621,,,0.00423925749221162,0.000210525689440368,0.00425166417988295,0.000210536146699479,0.921410083770752,0.97878485918045,31.9957695007324,5.65648031234741,35,4,200,0.000472948770038784,-1.67146182060242,0.393533736467361,1,,,,,,,,,,,,,,,,
,3870384598.5053,26.9669771194458,100.121528625488,,,6,,,,32.2785068950644,,,10,,,,,,,,,,,,,,,,,,,,,,26.5817489624023,27.3686504364014,100.121528625488,100.121528625488,,,7.2240571975708,,1,0,0,0,0.0138092041015625,30.7917900085449,2,1,1,26.5653038024902,0,4232058656,26.9674440383911,,,0.00453474981314651,0.000225223175855092,0.00454846083118896,0.000225232925317343,0.920122444629669,0.978801608085632,31.9850578308105,5.25309181213379,35,4,200,0.000482982315588742,-1.77554261684418,0.433440983295441,1,,,,,,,,,,,,,,,,
,3870384673.98474,20.6417465209961,100.121528625488,,,6,,,,32.2672159179847,,,10,,,,,,,,,,,,,,,,,,,,,,20.2929458618164,21.029203414917,100.121528625488,100.121528625488,,,6.89046144485474,,1,0,0,0,0,30.3030319213867,2,1,1,20.2542896270752,0,4232058592,20.6642087936401,,,0.00484824595589453,0.000240787961011908,0.00486283787616972,0.000240800275052717,0.920401453971863,0.978837728500366,31.9748401641846,5.25332927703857,35,4,200,0.000456438137916848,-1.88534438610077,0.475594609975815,1,,,,,,,,,,,,,,,,
,3870384741.05563,15.1001081466675,100.121528625488,,,6,,,,32.2615193388539,,,10,,,,,,,,,,,,,,,,,,,,,,14.7230653762817,15.5014123916626,100.121528625488,100.121528625488,,,6.41098833084106,,1,0,0,0,0,31.7693061828613,2,1,1,14.6988039016724,0,4232058688,15.105144405365,,,0.0050769204143428,0.000252154251483407,0.00509240333682736,0.000252167923065616,0.919949591159821,0.978858411312103,31.9673442840576,0,35,4,200,0.000379699660697952,-2.06893038749695,0.506338179111481,1,,,,,,,,,,,,,,,,
,3870384808.27862,9.80413055419922,100.121528625488,,,6,,,,32.2564933470275,,,10,,,,,,,,,,,,,,,,,,,,,,9.57232189178467,10.052583694458,100.121528625488,100.121528625488,,,4.44204330444336,,1,0,0,0,0.0138092041015625,30.7917900085449,6,1,1,9.55567741394043,0,4232059200,9.83820314407349,,,0.00522164000482574,0.000259344655257635,0.0052376085224436,0.000259357977690852,0.919818818569183,0.978893935680389,31.9617252349854,0.190382570028305,35,4,200,0.000231074343901128,-2.1211998462677,0.524941563606262,1,,,,,,,,,,,,,,,,
,3870384875.48063,5.00583553314209,100.121528625488,,,6,,,,32.2513670123387,,,10,,,,,,,,,,,,,,,,,,,,,,4.9957537651062,5.00917482376099,100.121528625488,100.121528625488,,,3.73028421401978,,1,0,0,0,0.0138092041015625,30.7917900085449,6,1,1,5.00249624252319,0,4232058752,5.00021071434021,,,0.00528531124423128,0.00026248082153387,0.00530095163193106,0.000262494610147392,0.921065270900726,0.978894233703613,31.9615459442139,5.65345430374146,35,4,200,4.60725241282489E-5,-2.14477705955505,0.532735884189606,1,,,,,,,,,,,,,,,,
,3870384933.96283,5.00300312042236,100.121528625488,,,6,,,,32.2513670123387,,,10,,,,,,,,,,,,,,,,,,,,,,4.99830722808838,5.00454616546631,100.121528625488,100.121528625488,,,3.66403150558472,,1,0,0,0,0.0138092041015625,30.7917900085449,1,1,1,5.00146007537842,0,4232058752,5.00023250579834,,,0.0052860587195115,0.000262515315672391,0.00530158994779641,0.000262526272377654,0.921193778514862,0.978893756866455,31.9620571136475,5.25338888168335,35,4,200,4.34173671237659E-5,-2.14504885673523,0.532788276672363,1,,,,,,,,,,,,,,,,
,3870384943.69365,5.00179076194763,100.121528625488,,,6,,,,32.2513670123387,,,10,,,,,,,,,,,,,,,,,,,,,,4.99686574935913,5.00211668014526,100.121528625488,100.121528625488,,,3.66547417640686,,1,0,0,0,0,30.3030319213867,1,1,1,5.00230073928833,0,4232058688,4.9992404460907,,,0.00528615834510378,0.000262519640962549,0.00530170791926278,0.000262532064995762,0.921223282814026,0.978900969028473,31.9621658325195,5.25340509414673,35,4,200,5.14643688802607E-5,-2.14506602287292,0.532791495323181,1,,,,,,,,,,,,,,,,