File: Data/KMK254/MvsH/KMK254_MvsH_300K.dat
[Header]
; MPMS3 Data File (default extension .dat)
; Copyright (c) 2007, Quantum Design, Inc. All rights reserved.
TITLE,
FILEOPENTIME,3844657213.68655,10/29/2021,8:20 am
BYAPP,MPMS3 w/ AC,1.0,1.1
INFO,MPMS3 Measurement Release 1.1.16 Build 424, MultiVu Release 2.3.4.19,APPNAME
INFO,Linear Motor Servo Controller,MOTOR_MODULE_NAME
INFO,3101-100 J0,MOTOR_HW_VERSION
INFO,MMC721,MOTOR_SERIAL_NUMBER
INFO,01.04.28,MOTOR_SOFTWARE_VERSION
INFO,Quantum Design Squid Module,SQUID_MODULE_NAME
INFO,3101-501 B0,SQUID_HW_VERSION
INFO,SQM195,SQUID_SERIAL_NUMBER
INFO,01.03.04,SQUID_SOFTWARE_VERSION
INFO,SQUID AC,AC_MODULE_NAME
INFO,3101-401 f1,AC_HW_VERSION
INFO,SAC107,AC_SERIAL_NUMBER
INFO,SQUID AC 00.95.07,AC_SOFTWARE_VERSION
INFO,TCI166,COIL_SERIAL_NUMBER
INFO,0,MOMENT_UNITS
INFO,KMK254,SAMPLE_MATERIAL
INFO,,SAMPLE_COMMENT
INFO,2.4,SAMPLE_MASS
INFO,,SAMPLE_VOLUME
INFO,,SAMPLE_MOLECULAR_WEIGHT
INFO,,SAMPLE_SIZE
INFO,,SAMPLE_SHAPE
INFO,Straw,SAMPLE_HOLDER
INFO,Standard,SAMPLE_HOLDER_DETAIL
INFO,65.58,SAMPLE_OFFSET
DATATYPE,COMMENT,1
DATATYPE,TIME,2
STARTUPAXIS,X,2
STARTUPAXIS,Y1,5
FIELDGROUP, VSM,2,3,4,5,6,8,9,10,11,14,15
FIELDGROUP, DC, 2,3,4,14,56,57,58,59,60,61,62,63,64,65,66,67,68,69
FIELDGROUP, AC, 2,3,4,11,16,17,18,19,20,21,22,23,24,25,26,27,28,29,30
STARTUPGROUP, All
[Data]
Comment,Time Stamp (sec),Temperature (K),Magnetic Field (Oe),Moment (emu),M. Std. Err. (emu),Transport Action,Averaging Time (sec),Frequency (Hz),Peak Amplitude (mm),Center Position (mm),Lockin Signal' (V),Lockin Signal (V),Range,M. Quad. Signal (emu),AC Moment (emu),AC M. Std Err. (emu),AC Phase (deg),AC Phase Std. Err. (deg),AC Susceptibility (emu/Oe),AC Suscept. Std Err. (emu/Oe),AC X' (emu/Oe),AC X' Std Err. (emu/Oe),AC X'' (emu/Oe),AC X'' Std Err. (emu/Oe),AC Drive (Oe),AC Frequency (Hz),AC Averaging Time (sec),AC Cycles,AC Range,AC Measure Type,AC Signal' (V),AC Signal'' (V),AC Trim Coil Ratio,AC Trim Coil Phase,Min. Temperature (K),Max. Temperature (K),Min. Field (Oe),Max. Field (Oe),Mass (grams),Motor Lag (deg),Pressure (Torr),Measure Count,Measurement Number,SQUID Status (code),Motor Status (code),Measure Status (code),Motor Current (amps),Motor Temp. (C),Temp. Status (code),Field Status (code),Chamber Status (code),Chamber Temp (K),Redirection State,Evercool Status,Average Temp (K),Rotation Angle (deg),Rotator state,DC Moment Fixed Ctr (emu),DC Moment Err Fixed Ctr (emu),DC Moment Free Ctr (emu),DC Moment Err Free Ctr (emu),DC Fixed Fit,DC Free Fit,DC Calculated Center (mm),DC Calculated Center Err (mm),DC Scan Length (mm),DC Scan Time (s),DC Number of Points,DC Squid Drift,DC Min V (V),DC Max V (V),DC Scans per Measure,Map 01,Map 02,Map 03,Map 04,Map 05,Map 06,Map 07,Map 08,Map 09,Map 10,Map 11,Map 12,Map 13,Map 14,Map 15,Map 16
,3844672397.65863,299.986450195313,-70000.078125,,,6,,,,34.7763789877002,,,1000,,,,,,,,,,,,,,,,,,,,,,299.983917236328,299.988159179687,-70000.078125,-70000.078125,,,7.6847767829895,,1,0,0,0,0.013885498046875,32.2580642700195,1,1,1,299.987915039063,0,4232057856,299.985687255859,,,-0.178671944226622,0.00892672024192985,-0.178712430315167,0.00892671039953764,0.941336214542389,0.945341467857361,34.6960716247559,0,35,4,200,-0.000116374816570897,-0.179583504796028,0.706334114074707,1,,,,,,,,,,,,,,,,
,3844672548.4309,299.938323974609,-45000.3046875,,,6,,,,34.7763789877002,,,1000,,,,,,,,,,,,,,,,,,,,,,299.938018798828,299.939086914063,-45000.3046875,-45000.3046875,,,7.57619619369507,,1,0,0,0,0,31.7693061828613,1,1,1,299.938507080078,0,4232057856,299.938516235352,,,-0.177649359632917,0.00887514127153098,-0.177690930025621,0.0088751281587606,0.942280352115631,0.946501314640045,34.6946754455566,0,35,4,200,0.000202935800189152,-0.176362469792366,0.703417301177978,1,,,,,,,,,,,,,,,,
,3844672699.58231,299.982833862305,-20000.36328125,,,6,,,,34.7763789877002,,,1000,,,,,,,,,,,,,,,,,,,,,,299.981842041016,299.986236572266,-20000.36328125,-20000.36328125,,,7.60739707946777,,1,0,0,0,0.0147247314453125,32.7468223571777,1,1,1,299.982757568359,0,4232057568,299.983947753906,,,-0.175569475849335,0.00877029441066931,-0.175602431933649,0.00877031575609694,0.944163382053375,0.947575807571411,34.7038764953613,0.0652528926730156,35,4,200,0.000191358180018142,-0.17179711163044,0.695136189460754,1,,,,,,,,,,,,,,,,
,3844672841.71151,300.004745483398,-8500.455078125,,,6,,,,34.7763789877002,,,1000,,,,,,,,,,,,,,,,,,,,,,300.002258300781,300.010131835937,-8500.455078125,-8500.455078125,,,7.56902122497559,,1,0,0,0,0.013885498046875,32.7468223571777,1,1,1,300.002380371094,0,4232058336,300.006973266602,,,-0.172593233618698,0.0086210311749395,-0.17261732766333,0.00862101972429344,0.945397436618805,0.948034644126892,34.7131195068359,0.104104161262512,35,4,200,0.000294067460345104,-0.168208822607994,0.683662354946136,1,,,,,,,,,,,,,,,,
,3844672956.45808,300.003952026367,-6000.28857421875,,,6,,,,34.7763789877002,,,1000,,,,,,,,,,,,,,,,,,,,,,300.001220703125,300.008453369141,-6000.28857421875,-6000.28857421875,,,7.6900315284729,,1,0,0,0,0.013885498046875,32.7468223571777,1,1,1,300.001617431641,0,4232057856,300.005648803711,,,-0.170619677897836,0.00852217366551962,-0.170639313134742,0.00852218432399577,0.945993423461914,0.948137700557709,34.7195281982422,,35,4,200,0.00020972041238565,-0.165260002017021,0.674908697605133,1,,,,,,,,,,,,,,,,
,3844673072.33738,300.001937866211,-3500.4404296875,,,6,,,,34.7763789877002,,,1000,,,,,,,,,,,,,,,,,,,,,,299.998962402344,300.006469726562,-3500.4404296875,-3500.4404296875,,,7.88485050201416,,1,0,0,0,0.013885498046875,32.7468223571777,1,1,1,299.999237060547,0,4232058016,300.003659057617,,,-0.165219512627316,0.00825210878592364,-0.165232631780191,0.00825211974596994,0.946751296520233,0.948234140872955,34.7292976379395,,35,4,200,0.000175954948645085,-0.160595595836639,0.654147505760193,1,,,,,,,,,,,,,,,,
,3844673186.44027,300.001510620117,-1000.26202392578,,,6,,,,34.7763789877002,,,1000,,,,,,,,,,,,,,,,,,,,,,299.999176025391,300.006103515625,-1000.26202392578,-1000.26202392578,,,8.23569297790527,,1,0,0,0,0.013885498046875,33.2355842590332,1,1,1,299.999359130859,0,4232057984,300.003500366211,,,-0.112061878376174,0.00559688879555923,-0.112064989638972,0.00559688147702649,0.947384357452393,0.94793826341629,34.7476501464844,0,35,4,200,9.72530906437896E-5,-0.108887322247028,0.442977637052536,1,,,,,,,,,,,,,,,,
,3844673308.03193,300.002090454102,-760.2734375,,,6,,,,34.7763789877002,,,1000,,,,,,,,,,,,,,,,,,,,,,300.000183105469,300.005432128906,-760.2734375,-760.2734375,,,8.7025842666626,,1,0,0,0,0.0147247314453125,32.7468223571777,1,1,1,300.000183105469,0,4232058016,300.003607177734,,,-0.0928216739259929,0.00463595317968454,-0.0928237053112817,0.00463594848094451,0.947352886199951,0.947788417339325,34.7508888244629,3.86303872801363E-5,35,4,200,-0.000170833794982173,-0.0903540402650833,0.366383075714111,1,,,,,,,,,,,,,,,,
,3844673418.28457,299.998077392578,-710.188232421875,,,6,,,,34.7763789877002,,,1000,,,,,,,,,,,,,,,,,,,,,,299.995483398438,300.003540039063,-710.188232421875,-710.188232421875,,,8.74668979644775,,1,0,0,0,0.013885498046875,32.7468223571777,1,1,1,299.995513916016,0,4232057856,300.000430297852,,,-0.0881972433695624,0.00440497450051618,-0.0881989113837722,0.00440497034010757,0.94740754365921,0.947785437107086,34.7526397705078,0.000194775784621015,35,4,200,-0.000157710164785385,-0.0859218388795853,0.348068118095398,1,,,,,,,,,,,,,,,,
,3844673528.53317,299.99641418457,-660.139709472656,,,6,,,,34.7763789877002,,,1000,,,,,,,,,,,,,,,,,,,,,,299.993408203125,300.001983642578,-660.139709472656,-660.139709472656,,,8.62595176696777,,1,0,0,0,0.013885498046875,32.7468223571777,1,1,1,299.993682861328,0,4232057952,299.998681640625,,,-0.0833399436675314,0.0041623710056829,-0.0833413534254834,0.00416237048598055,0.947441518306732,0.947765827178955,34.7543907165527,0,35,4,200,-0.000181644762051292,-0.0815942883491516,0.328627079725265,1,,,,,,,,,,,,,,,,
,3844673636.78281,299.997695922852,-610.091186523437,,,6,,,,34.7763789877002,,,1000,,,,,,,,,,,,,,,,,,,,,,299.994781494141,300.00390625,-610.091186523437,-610.091186523437,,,8.54736042022705,,1,0,0,0,0.013885498046875,32.7468223571777,1,1,1,299.995025634766,0,4232058176,300.000173950195,,,-0.078268065281252,0.00390906087793663,-0.0782691690949525,0.00390905924736917,0.94744211435318,0.947718322277069,34.7560806274414,0,35,4,200,-0.000185138589586131,-0.0765775814652443,0.308793246746063,1,,,,,,,,,,,,,,,,
,3844673745.91855,299.998733520508,-560.030334472656,,,6,,,,34.7763789877002,,,1000,,,,,,,,,,,,,,,,,,,,,,299.996032714844,300.005310058594,-560.030334472656,-560.030334472656,,,8.49855709075928,,1,0,0,0,0.013885498046875,32.7468223571777,1,1,1,299.996307373047,0,4232057952,300.001425170898,,,-0.0729576360099678,0.00364382937143859,-0.0729585196124166,0.00364382753063262,0.947456836700439,0.947696805000305,34.7574615478516,5.22360706329346,35,4,200,-0.000176766887307167,-0.0716237276792526,0.287609040737152,1,,,,,,,,,,,,,,,,
,3844673857.68714,299.99919128418,-509.932952880859,,,6,,,,34.7763789877002,,,1000,,,,,,,,,,,,,,,,,,,,,,299.996704101562,300.006011962891,-509.932952880859,-509.932952880859,,,8.46876430511475,,1,0,0,0,0.013885498046875,32.2580642700195,1,1,1,299.996856689453,0,4232058080,300.002005004883,,,-0.0674217297835229,0.00336734436222699,-0.0674224515967846,0.00336734180705987,0.947439432144165,0.947657406330109,34.7583427429199,0,35,4,200,-0.000202032606466673,-0.0665334910154343,0.265641629695892,1,,,,,,,,,,,,,,,,
,3844673968.06154,299.998229980469,-459.933288574219,,,6,,,,34.7763789877002,,,1000,,,,,,,,,,,,,,,,,,,,,,299.995239257812,300.004943847656,-459.933288574219,-459.933288574219,,,8.43451881408691,,1,0,0,0,0.013885498046875,32.7468223571777,1,1,1,299.995574951172,0,4232058016,300.001019287109,,,-0.0616353206419627,0.0030783463955711,-0.0616359841527518,0.00307834583097555,0.947434842586517,0.947642982006073,34.7587509155273,0.000168980623129755,35,4,200,-0.000185163560672663,-0.0605461001396179,0.242722541093826,1,,,,,,,,,,,,,,,,
,3844674080.30794,299.997985839844,-410.006927490234,,,6,,,,34.7763789877002,,,1000,,,,,,,,,,,,,,,,,,,,,,299.995086669922,300.004150390625,-410.006927490234,-410.006927490234,,,8.4011116027832,,1,0,0,0,0.0147247314453125,32.2580642700195,1,1,1,299.995269775391,0,4232057952,300.000482177734,,,-0.0556122627902046,0.00277753507400106,-0.0556128388391087,0.00277753375815236,0.947377800941467,0.947583496570587,34.7588500976562,3.23314307024702E-5,35,4,200,-0.000191273968084715,-0.0549994111061096,0.218691304326057,1,,,,,,,,,,,,,,,,
,3844674190.42872,299.996963500977,-359.970642089844,,,6,,,,34.7763789877002,,,1000,,,,,,,,,,,,,,,,,,,,,,299.994476318359,300.004669189453,-359.970642089844,-359.970642089844,,,8.376296043396,,1,0,0,0,0.013885498046875,32.7468223571777,1,1,1,299.994506835937,0,4232057856,300.000405883789,,,-0.0493137384944557,0.00246296225538744,-0.0493142348544365,0.00246295933309422,0.947346329689026,0.947559893131256,34.7585105895996,0.0674590021371841,35,4,200,-0.000178445392521098,-0.049206655472517,0.193938970565796,1,,,,,,,,,,,,,,,,
,3844674303.05213,299.997131347656,-309.909881591797,,,6,,,,34.7763789877002,,,1000,,,,,,,,,,,,,,,,,,,,,,299.994689941406,300.005218505859,-309.909881591797,-309.909881591797,,,8.35229969024658,,1,0,0,0,0.013885498046875,32.2580642700195,1,1,1,299.994873046875,0,4232057984,300.000817871094,,,-0.0427228875402667,0.00213379590485082,-0.042723422923444,0.00213379532311502,0.947239577770233,0.947482168674469,34.7573204040527,4.16602611541748,35,4,200,-0.000200168098672293,-0.0428515523672104,0.167966321110725,1,,,,,,,,,,,,,,,,
,3844674411.24449,299.997497558594,-259.910217285156,,,6,,,,34.7763789877002,,,1000,,,,,,,,,,,,,,,,,,,,,,299.994598388672,300.004608154297,-259.910217285156,-259.910217285156,,,8.33335304260254,,1,0,0,0,0.013885498046875,32.7468223571777,1,1,1,299.995025634766,0,4232058016,300.000198364258,,,-0.0358369861283239,0.00178988621729255,-0.0358374870313915,0.00178988411300439,0.947167158126831,0.947453916072845,34.7556419372559,0,35,4,200,-0.000201238508452661,-0.0358957797288895,0.140688449144363,1,,,,,,,,,,,,,,,,
,3844674520.41265,299.9970703125,-209.910552978516,,,6,,,,34.7763789877002,,,1000,,,,,,,,,,,,,,,,,,,,,,299.993988037109,300.003570556641,-209.910552978516,-209.910552978516,,,8.32498550415039,,1,0,0,0,0.013885498046875,32.7468223571777,1,1,1,299.994049072266,0,4232057920,299.999880981445,,,-0.028617568204327,0.0014293209979418,-0.0286181081317649,0.00142932070662216,0.947030544281006,0.947390794754028,34.753116607666,3.76347561541479E-5,35,4,200,-0.000199698988581076,-0.0293215867131948,0.112228527665138,1,,,,,,,,,,,,,,,,
,3844674640.55175,299.99690246582,-159.800903320313,,,6,,,,34.7763789877002,,,100,,,,,,,,,,,,,,,,,,,,,,299.994293212891,300.0048828125,-159.800903320313,-159.800903320313,,,8.30033493041992,,1,0,0,0,0.013885498046875,32.7468223571777,1,1,1,299.994598388672,0,4232058176,300.000201416016,,,-0.0209964562189298,0.00104869814957801,-0.0209969903838358,0.00104869790122912,0.946707963943481,0.947190642356873,34.7493934631348,,35,4,200,-0.00202610506676137,-0.211210042238235,0.825787127017975,1,,,,,,,,,,,,,,,,
,3844674748.93769,299.996658325195,-109.801254272461,,,6,,,,34.7763789877002,,,100,,,,,,,,,,,,,,,,,,,,,,299.993225097656,300.004119873047,-109.801254272461,-109.801254272461,,,8.29574203491211,,1,0,0,0,0.013885498046875,32.7468223571777,1,1,1,299.993438720703,0,4232058048,299.999810791016,,,-0.0129779741018146,0.000648221431691256,-0.0129784381492967,0.000648220604428827,0.946195065975189,0.946885764598846,34.743968963623,0,35,4,200,-0.00196543103083968,-0.132919073104858,0.510560274124146,1,,,,,,,,,,,,,,,,
,3844674857.02095,299.996200561523,-59.7893753051758,,,6,,,,34.7763789877002,,,100,,,,,,,,,,,,,,,,,,,,,,299.9931640625,300.002960205078,-59.7893753051758,-59.7893753051758,,,8.25579166412354,,1,0,0,0,0.013885498046875,32.7468223571777,1,1,1,299.993682861328,0,4232058048,299.999075317383,,,-0.00442390819599504,0.000221010761020772,-0.0044241641431238,0.000221010918458449,0.942455589771271,0.943454027175903,34.736156463623,0,35,4,200,-0.0019407543586567,-0.0496395453810692,0.174081355333328,1,,,,,,,,,,,,,,,,
,3844674977.5457,299.996826171875,-9.716383934021,,,6,,,,34.7763789877002,,,10,,,,,,,,,,,,,,,,,,,,,,299.993682861328,300.003875732422,-9.716383934021,-9.716383934021,,,8.26812934875488,,1,0,0,0,0.013885498046875,32.7468223571777,1,1,1,299.994506835937,0,4232058112,299.999771118164,,,0.0045706141608726,0.000228258796863371,0.00457084943258145,0.000228258995046865,0.9489825963974,0.94998174905777,34.7384376525879,0,35,4,200,-0.0192941874265671,-1.89573454856873,0.399287760257721,1,,,,,,,,,,,,,,,,
,3844675093.49253,299.997406005859,40.0632820129395,,,6,,,,34.7763789877002,,,100,,,,,,,,,,,,,,,,,,,,,,299.993408203125,300.004852294922,40.0632820129395,40.0632820129395,,,8.25171089172363,,1,0,0,0,0.013885498046875,32.7468223571777,1,1,1,299.9951171875,0,4232057984,299.99926275956,,,0.0129381389966053,0.000646163755438671,0.0129385696433726,0.000646163627488202,0.948186278343201,0.948834836483002,34.7455406188965,0.136368051171303,35,4,200,-0.00123385316692293,-4.88978290557861,4.83666181564331,1,,,,,,,,,,,,,,,,
,3844675211.74724,299.99626159668,90.0996017456055,,,6,,,,34.7763789877002,,,100,,,,,,,,,,,,,,,,,,,,,,299.9931640625,300.003295898438,90.0996017456055,90.0996017456055,,,8.23966312408447,,1,0,0,0,0.013885498046875,32.2580642700195,1,1,1,299.993743896484,0,4232058016,299.999020385742,,,0.0210942290463927,0.00105350743712267,0.0210946562844117,0.00105350668151499,0.948044955730438,0.948449075222015,34.7519760131836,INF,35,4,200,-0.00176882604137063,-0.841690957546234,0.199905663728714,1,,,,,,,,,,,,,,,,
,3844675325.40562,299.996887207031,140.197036743164,,,6,,,,34.7763789877002,,,100,,,,,,,,,,,,,,,,,,,,,,299.993804931641,300.005065917969,140.197036743164,140.197036743164,,,8.24367141723633,,1,0,0,0,0.013885498046875,32.7468223571777,1,1,1,299.994049072266,0,4232058080,300.000180053711,,,0.0286906552465105,0.00143290110389933,0.0286910690392813,0.0014329009850651,0.947969615459442,0.948248386383057,34.7560882568359,0,35,4,200,-0.00194947957061231,-1.13850152492523,0.276596277952194,1,,,,,,,,,,,,,,,,
,3844675438.89204,299.995758056641,190.221130371094,,,6,,,,34.7763789877002,,,100,,,,,,,,,,,,,,,,,,,,,,299.992797851562,300.002166748047,190.221130371094,190.221130371094,,,8.25224208831787,,1,0,0,0,0.013885498046875,32.2580642700195,1,1,1,299.993255615234,0,4232058080,299.998260498047,,,0.0359073108492953,0.00179331991502688,0.035907663809412,0.00179331958719612,0.948004901409149,0.948197305202484,34.759521484375,0,35,4,200,-0.00195538741536438,-1.42701971530914,0.342738568782806,1,,,,,,,,,,,,,,,,
,3844675552.87483,299.995483398438,240.159698486328,,,6,,,,34.7763789877002,,,100,,,,,,,,,,,,,,,,,,,,,,299.992492675781,300.003051757812,240.159698486328,240.159698486328,,,8.24556255340576,,1,0,0,0,0.013885498046875,32.2580642700195,1,1,1,299.993011474609,0,4232057888,299.998614501953,,,0.042770908683291,0.00213611142334806,0.042771165715655,0.00213610935332412,0.947979331016541,0.948113262653351,34.7623062133789,2.81771735899383E-5,35,4,200,-0.00200435752049088,-1.69914376735687,0.40812024474144,1,,,,,,,,,,,,,,,,
,3844675665.76708,299.996490478516,290.208221435547,,,6,,,,34.7763789877002,,,100,,,,,,,,,,,,,,,,,,,,,,299.993896484375,300.004669189453,290.208221435547,290.208221435547,,,8.24041557312012,,1,0,0,0,0.013885498046875,32.2580642700195,1,1,1,299.993988037109,0,4232058112,300.000061035156,,,0.0493439473888129,0.00246438904674204,0.0493441993356936,0.00246438800254714,0.947982132434845,0.948088228702545,34.7638511657715,0,35,4,200,-0.00215751281939447,-1.95634806156158,0.473813503980637,1,,,,,,,,,,,,,,,,
,3844675779.05966,299.998062133789,340.256774902344,,,6,,,,34.7763789877002,,,100,,,,,,,,,,,,,,,,,,,,,,299.994354248047,300.005981445313,340.256774902344,340.256774902344,,,8.25014209747314,,1,0,0,0,0.013885498046875,32.2580642700195,1,1,1,299.994750976562,0,4232058048,300.001220703125,,,0.0556410130153156,0.00277888185172245,0.0556412234807397,0.00277888023405236,0.947999536991119,0.948083281517029,34.7652473449707,0,35,4,200,-0.00207194639369845,-2.20656085014343,0.533261120319366,1,,,,,,,,,,,,,,,,
,3844675892.43732,299.997741699219,390.341979980469,,,6,,,,34.7763789877002,,,100,,,,,,,,,,,,,,,,,,,,,,299.994720458984,300.005645751953,390.341979980469,390.341979980469,,,8.25638198852539,,1,0,0,0,0.013885498046875,32.7468223571777,1,1,1,299.995025634766,0,4232056832,300.00107421875,,,0.0616666330714323,0.00307981352122448,0.0616668329548273,0.00307981196643909,0.948038756847382,0.948110699653625,34.7660675048828,0,35,4,200,-0.00190683000255376,-2.44572973251343,0.59002298116684,1,,,,,,,,,,,,,,,,
,3844676005.77359,299.994171142578,440.256072998047,,,6,,,,34.7763789877002,,,100,,,,,,,,,,,,,,,,,,,,,,299.990264892578,300.001831054687,440.256072998047,440.256072998047,,,8.25507068634033,,1,0,0,0,0.013885498046875,32.2580642700195,1,1,1,299.990600585937,0,4232057984,299.997225952148,,,0.0674344545898489,0.00336786698821419,0.0674346769916041,0.00336786750496497,0.948081254959106,0.948141694068909,34.7669296264648,2.3085887733032E-5,35,4,200,-0.00205145287327468,-2.67531061172485,0.643816947937012,1,,,,,,,,,,,,,,,,
,3844676119.29144,299.997604370117,490.170196533203,,,6,,,,34.7763789877002,,,100,,,,,,,,,,,,,,,,,,,,,,299.994140625,300.005218505859,490.170196533203,490.170196533203,,,8.24925804138184,,1,0,0,0,0.013885498046875,32.2580642700195,1,1,1,299.994750976562,0,4232057856,300.00080871582,,,0.0729446999049759,0.00364305064358085,0.0729448658415408,0.00364304948889365,0.948156654834747,0.948206543922424,34.7678031921387,2.18966360989725E-5,35,4,200,-0.0020979130640626,-2.89551949501038,0.700816571712494,1,,,,,,,,,,,,,,,,
,3844676233.33797,299.997650146484,540.23095703125,,,6,,,,34.7763789877002,,,100,,,,,,,,,,,,,,,,,,,,,,299.994079589844,300.004333496094,540.23095703125,540.23095703125,,,8.28036212921143,,1,0,0,0,0.0139617919921875,32.2580642700195,1,1,1,299.994934082031,0,4232057984,300.000119018555,,,0.0768735982106697,0.00383935374899101,0.0768738188968752,0.0038393531208306,0.947730422019959,0.947788298130035,34.7671012878418,5.89636325836182,35,4,200,0.0039252950809896,-3.03189587593079,0.754693627357483,1,,,,,,,,,,,,,,,,
,3844676347.13469,299.995223999023,590.291687011719,,,6,,,,34.7763789877002,,,100,,,,,,,,,,,,,,,,,,,,,,299.992401123047,300.003021240234,590.291687011719,590.291687011719,,,8.29341411590576,,1,0,0,0,0.0139617919921875,32.7468223571777,1,1,1,299.992401123047,0,4232057952,299.998635864258,,,0.0832588939640458,0.00415815616810052,0.0832590391081004,0.00415815414464818,0.948212742805481,0.948255717754364,34.7684211730957,2.10525777220028E-5,35,4,200,-0.00266890320926905,-3.30611610412598,0.793668746948242,1,,,,,,,,,,,,,,,,
,3844676461.01746,299.996978759766,640.242492675781,,,6,,,,34.7763789877002,,,100,,,,,,,,,,,,,,,,,,,,,,299.993988037109,300.005065917969,640.242492675781,640.242492675781,,,8.31106948852539,,1,0,0,0,0.0139617919921875,32.7468223571777,1,1,1,299.994476318359,0,4232057952,300.000384521484,,,0.0880901941886393,0.00439942700208394,0.0880903778356704,0.00439942678274089,0.948282659053802,0.948323845863342,34.7685928344727,0,35,4,200,-0.00283889845013618,-3.49131727218628,0.845005989074707,1,,,,,,,,,,,,,,,,
,3844676575.23916,299.994918823242,690.168823242188,,,6,,,,34.7763789877002,,,100,,,,,,,,,,,,,,,,,,,,,,299.992523193359,300.001586914063,690.168823242188,690.168823242188,,,8.31431484222412,,1,0,0,0,0.013885498046875,31.7693061828613,1,1,1,299.992736816406,0,4232057984,299.997573852539,,,0.0927028566108368,0.00462978471434514,0.0927029962248521,0.00462978200281364,0.948324203491211,0.948364615440369,34.7686729431152,5.89649677276611,35,4,200,-0.00303155090659857,-3.68242311477661,0.890156447887421,1,,,,,,,,,,,,,,,,
,3844676689.14044,299.994445800781,740.205139160156,,,6,,,,34.7763789877002,,,100,,,,,,,,,,,,,,,,,,,,,,299.991912841797,300.002716064453,740.205139160156,740.205139160156,,,8.32273960113525,,1,0,0,0,0.013885498046875,32.7468223571777,1,1,1,299.992431640625,0,4232057952,299.997891235352,,,0.0971089734448598,0.00484983158593277,0.0971091259268434,0.00484983177641958,0.948341429233551,0.94837099313736,34.7697868347168,1.90424489119323E-5,35,4,200,-0.00325068598613143,-3.85535836219788,0.93267160654068,1,,,,,,,,,,,,,,,,
,3844676803.12,299.999206542969,790.314819335938,,,6,,,,34.7763789877002,,,100,,,,,,,,,,,,,,,,,,,,,,299.995941162109,300.006988525391,790.314819335938,790.314819335938,,,8.31011009216309,,1,0,0,0,0.013885498046875,32.2580642700195,1,1,1,299.996398925781,0,4232057888,300.002304077148,,,0.101296754573227,0.00505898058824258,0.101296927362602,0.00505898036767232,0.948327660560608,0.948361456394196,34.7693328857422,0,35,4,200,-0.00292748212814331,-4.01479005813599,0.970175206661224,1,,,,,,,,,,,,,,,,
,3844676950.59221,299.997161865234,2500.4716796875,,,6,,,,34.7763789877002,,,1000,,,,,,,,,,,,,,,,,,,,,,299.9931640625,300.006164550781,2500.4716796875,2500.4716796875,,,8.2267255783081,,1,0,0,0,0.013885498046875,32.7468223571777,1,1,1,299.993835449219,0,4232058144,300.001031494141,,,0.159266129015985,0.00795413923535412,0.159268105453249,0.00795413924977404,0.948231160640717,0.948470711708069,34.7576103210449,0,35,4,200,0.000154775101691484,-0.629965543746948,0.153655424714088,1,,,,,,,,,,,,,,,,
,3844677088.18131,299.995864868164,5000.466796875,,,6,,,,34.7763789877002,,,1000,,,,,,,,,,,,,,,,,,,,,,299.991790771484,300.003967285156,5000.466796875,5000.466796875,,,8.27800750732422,,1,0,0,0,0.013885498046875,32.7468223571777,1,1,1,299.992340087891,0,4232057856,299.999261474609,,,0.169323799383867,0.00845655517311295,0.169328222560314,0.00845656326282205,0.947979152202606,0.94846385717392,34.7496490478516,0,35,4,200,0.000175191860762425,-0.669599950313568,0.163570895791054,1,,,,,,,,,,,,,,,,
,3844677227.34861,299.998306274414,7500.41259765625,,,6,,,,34.7763789877002,,,1000,,,,,,,,,,,,,,,,,,,,,,299.994293212891,300.007019042969,7500.41259765625,7500.41259765625,,,8.31701183319092,,1,0,0,0,0.013885498046875,32.2580642700195,1,1,1,299.994934082031,0,4232058144,300.001629638672,,,0.172013663519996,0.00859096410453353,0.172018534777209,0.00859095174058933,0.94781756401062,0.948389410972595,34.747314453125,0,35,4,200,0.000253602425800636,-0.679817140102386,0.165851429104805,1,,,,,,,,,,,,,,,,
,3844677373.9278,300.011611938477,10000.3955078125,,,6,,,,34.7763789877002,,,1000,,,,,,,,,,,,,,,,,,,,,,300.009613037109,300.021118164063,10000.3955078125,10000.3955078125,,,8.32612705230713,,1,0,0,0,0.0139617919921875,32.7468223571777,1,1,1,300.010131835937,0,4232057920,300.015924072266,,,0.173331178493132,0.00865681440676236,0.173336735510974,0.00865681817906813,0.947711408138275,0.948318064212799,34.7464179992676,0,35,4,200,0.000211154649150558,-0.685448825359345,0.167579889297485,1,,,,,,,,,,,,,,,,
,3844677522.13859,300.055557250977,35000.48046875,,,6,,,,34.7763789877002,,,1000,,,,,,,,,,,,,,,,,,,,,,300.050933837891,300.065307617188,35000.48046875,35000.48046875,,,8.29602432250977,,1,0,0,0,0.013885498046875,32.2580642700195,1,1,1,300.060180664063,0,4232057600,300.060260009766,,,0.177054528507986,0.00884298176586027,0.177058450520627,0.00884298552242261,0.947263896465302,0.947676360607147,34.7515563964844,0,35,4,200,0.000294477969873697,-0.700231075286865,0.172975078225136,1,,,,,,,,,,,,,,,,
,3844677669.32176,300.007049560547,60000.44140625,,,6,,,,34.7763789877002,,,1000,,,,,,,,,,,,,,,,,,,,,,300.00244140625,300.016021728516,60000.44140625,60000.44140625,,,8.34231281280518,,1,0,0,0,0.0147247314453125,32.2580642700195,1,1,1,300.002655029297,0,4232057568,300.010751342773,,,0.178463918718341,0.00891373857902055,0.17846473430999,0.00891373282404147,0.946496665477753,0.946593999862671,34.764217376709,2.81550819636323E-5,35,4,200,0.000303333159536123,-0.704526662826538,0.17590905725956,1,,,,,,,,,,,,,,,,
,3844677819.95465,300.064849853516,55000.34765625,,,6,,,,34.7763789877002,,,1000,,,,,,,,,,,,,,,,,,,,,,300.052551269531,300.077117919922,55000.34765625,55000.34765625,,,8.33160209655762,,1,0,0,0,0.013885498046875,32.7468223571777,1,1,1,300.0771484375,0,4232057856,300.070306396484,,,0.178262567308256,0.00890362256561784,0.17826410557421,0.00890362135624432,0.946623921394348,0.946787893772125,34.760612487793,0,35,4,200,-8.57886043377221E-5,-0.705012679100037,0.174437209963799,1,,,,,,,,,,,,,,,,
,3844677972.99412,300.037414550781,30000.208984375,,,6,,,,34.7763789877002,,,1000,,,,,,,,,,,,,,,,,,,,,,300.031494140625,300.047668457031,30000.208984375,30000.208984375,,,8.32304763793945,,1,0,0,0,0.013885498046875,33.2355842590332,1,1,1,300.031646728516,0,4232057824,300.041390991211,,,0.176727513423822,0.00882668660062928,0.176732467626701,0.00882667930281963,0.947183728218079,0.947731494903564,34.7477645874023,0.000214371117181145,35,4,200,-0.000143870405736379,-0.699830293655395,0.171519950032234,1,,,,,,,,,,,,,,,,
,3844678129.83981,300.016815185547,9500.484375,,,6,,,,34.7763789877002,,,1000,,,,,,,,,,,,,,,,,,,,,,300.011779785156,300.026275634766,9500.484375,9500.484375,,,8.37056255340576,,1,0,0,0,0.0147247314453125,32.7468223571777,1,1,1,300.011749267578,0,4232058144,300.020767211914,,,0.173122180356133,0.00864635852737216,0.173128115128424,0.00864636016105898,0.947754800319672,0.948409676551819,34.7452697753906,0,35,4,200,-0.000354006013367325,-0.686532139778137,0.166275635361671,1,,,,,,,,,,,,,,,,
,3844678268.01912,300.016555786133,7000.3427734375,,,6,,,,34.7763789877002,,,1000,,,,,,,,,,,,,,,,,,,,,,300.011108398438,300.025726318359,7000.3427734375,7000.3427734375,,,8.37226009368897,,1,0,0,0,0.013885498046875,32.7468223571777,1,1,1,300.011260986328,0,4232058112,300.020251464844,,,0.171622715205983,0.00857141319972206,0.171627938004672,0.00857140760467193,0.947878479957581,0.948476731777191,34.7466735839844,,35,4,200,-0.000149660059832968,-0.679583549499512,0.164349243044853,1,,,,,,,,,,,,,,,,
,3844678406.50416,300.005462646484,4500.29931640625,,,6,,,,34.7763789877002,,,1000,,,,,,,,,,,,,,,,,,,,,,300.001556396484,300.013458251953,4500.29931640625,4500.29931640625,,,8.34559154510498,,1,0,0,0,0.013885498046875,32.7468223571777,1,1,1,300.001892089844,0,4232058080,300.008755493164,,,0.168297297954871,0.00840523676264591,0.168301383906273,0.00840524160410482,0.948089957237244,0.94854736328125,34.7504348754883,0,35,4,200,-0.000138724499265663,-0.667098939418793,0.161564081907272,1,,,,,,,,,,,,,,,,
,3844678543.71546,299.999267578125,2000.36511230469,,,6,,,,34.7763789877002,,,1000,,,,,,,,,,,,,,,,,,,,,,299.995391845703,300.008148193359,2000.36511230469,2000.36511230469,,,8.34568214416504,,1,0,0,0,0.013885498046875,33.2355842590332,1,1,1,299.995697021484,0,4232058048,300.003155517578,,,0.15171687730223,0.00757705691119552,0.151717960966011,0.00757704996092305,0.948364973068237,0.948520839214325,34.7612533569336,0,35,4,200,-0.000122318393550813,-0.600688099861145,0.145463839173317,1,,,,,,,,,,,,,,,,
,3844678674.96079,299.997299194336,780.072875976563,,,6,,,,34.7763789877002,,,1000,,,,,,,,,,,,,,,,,,,,,,299.994018554687,300.004974365234,780.072875976563,780.072875976563,,,8.36824798583984,,1,0,0,0,0.013885498046875,34.2131004333496,1,1,1,299.994293212891,0,4232058048,300.000396728516,,,0.0946325319879335,0.00472622192768993,0.0946327341892058,0.00472622068964472,0.948060393333435,0.948106467723846,34.7681274414063,0.0935364961624146,35,4,200,-1.44408377309446E-5,-0.375123500823975,0.0904786661267281,1,,,,,,,,,,,,,,,,
,3844678782.89652,299.994552612305,730.195434570312,,,6,,,,34.7763789877002,,,1000,,,,,,,,,,,,,,,,,,,,,,299.991638183594,300.002471923828,730.195434570312,730.195434570312,,,8.36465263366699,,1,0,0,0,0.0147247314453125,32.7468223571777,1,1,1,299.991973876953,0,4232057984,299.997808837891,,,0.0901366090369399,0.00450169218345932,0.0901368060196889,0.00450169151009972,0.948017001152039,0.94806182384491,34.768238067627,0.191452369093895,35,4,200,0.000189825645065866,-0.357205510139465,0.0864032506942749,1,,,,,,,,,,,,,,,,
,3844678891.01251,299.995819091797,680.159118652344,,,6,,,,34.7763789877002,,,1000,,,,,,,,,,,,,,,,,,,,,,299.992797851562,300.003173828125,680.159118652344,680.159118652344,,,8.35374546051025,,1,0,0,0,0.013885498046875,32.2580642700195,1,1,1,299.993225097656,0,4232057888,299.998782348633,,,0.0853834203400982,0.00426431309821277,0.0853835829505939,0.00426431126885957,0.947970986366272,0.948015749454498,34.7682418823242,4.16607856750488,35,4,200,0.000180001923581585,-0.337867945432663,0.0823087841272354,1,,,,,,,,,,,,,,,,
,3844678999.31346,299.996353149414,630.257202148438,,,6,,,,34.7763789877002,,,1000,,,,,,,,,,,,,,,,,,,,,,299.993713378906,300.00439453125,630.257202148438,630.257202148438,,,8.33905696868897,,1,0,0,0,0.013885498046875,32.7468223571777,1,1,1,299.994049072266,0,4232058048,299.999755859375,,,0.0804138383693311,0.00401612697588144,0.0804139841616502,0.00401612437642563,0.947923183441162,0.947970330715179,34.7680206298828,0,35,4,200,0.000194961088709533,-0.31824854016304,0.0771605297923088,1,,,,,,,,,,,,,,,,
,3844679110.23501,299.996505737305,580.392028808594,,,6,,,,34.7763789877002,,,1000,,,,,,,,,,,,,,,,,,,,,,299.994293212891,300.003112792969,580.392028808594,580.392028808594,,,8.32727813720703,,1,0,0,0,0.013885498046875,32.2580642700195,1,1,1,299.994598388672,0,4232058336,299.999127197266,,,0.0752221620901781,0.00375682582087507,0.0752223311521477,0.00375682516566341,0.94798481464386,0.94803124666214,34.7680892944336,0,35,4,200,0.000178723159478977,-0.297553718090057,0.0728085041046143,1,,,,,,,,,,,,,,,,
,3844679222.87441,299.996536254883,530.245666503906,,,6,,,,34.7763789877002,,,1000,,,,,,,,,,,,,,,,,,,,,,299.993041992188,300.004852294922,530.245666503906,530.245666503906,,,8.31029510498047,,1,0,0,0,0.013885498046875,32.7468223571777,1,1,1,299.993530273438,0,4232057984,299.999850463867,,,0.0697726341542934,0.00348469537226758,0.0697727939797855,0.00348469412775295,0.947791159152985,0.947841763496399,34.7677116394043,0.000117275907541625,35,4,200,0.000191933329915628,-0.276255965232849,0.0669303685426712,1,,,,,,,,,,,,,,,,
,3844679330.8285,299.997665405273,480.246032714844,,,6,,,,34.7763789877002,,,1000,,,,,,,,,,,,,,,,,,,,,,299.994293212891,300.005157470703,480.246032714844,480.246032714844,,,8.30560493469238,,1,0,0,0,0.013885498046875,32.2580642700195,1,1,1,299.994964599609,0,4232057984,300.0005859375,,,0.0640956630329738,0.00320117221158138,0.0640958069696669,0.00320117022808516,0.947762966156006,0.94781768321991,34.7673606872559,5.22268056869507,35,4,200,0.0001969113945961,-0.254145979881287,0.0616345852613449,1,,,,,,,,,,,,,,,,
,3844679438.78607,299.997940063477,430.307495117188,,,6,,,,34.7763789877002,,,1000,,,,,,,,,,,,,,,,,,,,,,299.995300292969,300.005218505859,430.307495117188,430.307495117188,,,8.30905055999756,,1,0,0,0,0.0146484375,32.7468223571777,1,1,1,299.995758056641,0,4232058240,300.000854492188,,,0.0581806605238286,0.00290576525867502,0.0581808245070594,0.00290576382831006,0.947693943977356,0.947757124900818,34.7666854858398,5.22329330444336,35,4,200,0.000200988521100953,-0.230259999632835,0.0559928417205811,1,,,,,,,,,,,,,,,,
,3844679547.822,299.996612548828,380.283386230469,,,6,,,,34.7763789877002,,,1000,,,,,,,,,,,,,,,,,,,,,,299.992553710937,300.004516601562,380.283386230469,380.283386230469,,,8.32197666168213,,1,0,0,0,0.013885498046875,32.2580642700195,1,1,1,299.993011474609,0,4232058368,299.999722290039,,,0.0519794994527668,0.0025960727994983,0.0519796924259061,0.00259607138892255,0.947563290596008,0.947644293308258,34.7653884887695,5.89621829986572,35,4,200,0.000205993099370971,-0.205812305212021,0.0499896071851254,1,,,,,,,,,,,,,,,,
,3844679658.44582,299.9951171875,330.283721923828,,,6,,,,34.7763789877002,,,1000,,,,,,,,,,,,,,,,,,,,,,299.992279052734,300.002838134766,330.283721923828,330.283721923828,,,8.33294296264648,,1,0,0,0,0.013885498046875,32.2580642700195,1,1,1,299.992431640625,0,4232058016,299.998297119141,,,0.0455199626430794,0.00227345995344259,0.0455201874858244,0.00227345871783563,0.947533071041107,0.947637379169464,34.7639083862305,4.16604232788086,35,4,200,0.000200610651518218,-0.180287092924118,0.0442846305668354,1,,,,,,,,,,,,,,,,
,3844679767.9182,299.997650146484,280.284057617187,,,6,,,,34.7763789877002,,,1000,,,,,,,,,,,,,,,,,,,,,,299.994262695313,300.005798339844,280.284057617187,280.284057617187,,,8.35128307342529,,1,0,0,0,0.013885498046875,33.2355842590332,1,1,1,299.994598388672,0,4232058112,300.000915527344,,,0.038758444679591,0.00193577041670558,0.0387587227520942,0.00193576934363901,0.947446465492249,0.947593331336975,34.7615737915039,0,35,4,200,0.00019823299953714,-0.153770312666893,0.0375682152807713,1,,,,,,,,,,,,,,,,
,3844679876.27696,299.995651245117,230.333312988281,,,6,,,,34.7763789877002,,,1000,,,,,,,,,,,,,,,,,,,,,,299.992767333984,300.003784179687,230.333312988281,230.333312988281,,,8.3560037612915,,1,0,0,0,0.013885498046875,32.7468223571777,1,1,1,299.993408203125,0,4232058176,299.999124145508,,,0.0316860473295359,0.00158255324189592,0.0316863650719413,0.0015825523384301,0.947331011295319,0.947532057762146,34.7590370178223,0.0540786720812321,35,4,200,0.000199628004338592,-0.125847369432449,0.030707286670804,1,,,,,,,,,,,,,,,,
,3844679991.09465,299.997634887695,180.431411743164,,,6,,,,34.7763789877002,,,100,,,,,,,,,,,,,,,,,,,,,,299.993286132812,300.004852294922,180.431411743164,180.431411743164,,,8.35002040863037,,1,0,0,0,0.013885498046875,31.2805480957031,1,1,1,299.995422363281,0,4232058048,299.999466745477,,,0.0243692215052949,0.00121712888341712,0.0243695529813067,0.00121712720263201,0.947128593921661,0.947411954402924,34.7557601928711,0.187140896916389,35,4,200,0.00136981846299022,-0.965225756168365,0.242975443601608,1,,,,,,,,,,,,,,,,
,3844680104.49014,299.996368408203,130.370651245117,,,6,,,,34.7763789877002,,,100,,,,,,,,,,,,,,,,,,,,,,299.993103027344,300.003936767578,130.370651245117,130.370651245117,,,8.34404563903809,,1,0,0,0,0.013885498046875,32.2580642700195,1,1,1,299.993530273438,0,4232058048,299.999536132813,,,0.0164157075538264,0.000819905727357763,0.0164161021867334,0.000819905780706045,0.946717023849487,0.947167634963989,34.750301361084,0.122985295951366,35,4,200,0.00192910898476839,-0.650726735591888,0.165067061781883,1,,,,,,,,,,,,,,,,
,3844680215.07775,299.995834350586,80.2854461669922,,,6,,,,34.7763789877002,,,100,,,,,,,,,,,,,,,,,,,,,,299.992004394531,300.004974365234,80.2854461669922,80.2854461669922,,,8.36656284332275,,1,0,0,0,0.013885498046875,32.7468223571777,1,1,1,299.992218017578,0,4232058144,299.999841308594,,,0.0080778262504467,0.000403493279864513,0.00807814900533789,0.000403493095791201,0.945126175880432,0.945865392684937,34.7425346374512,4.81970237160567E-5,35,4,200,0.00179121678229421,-0.320539593696594,0.0847688987851143,1,,,,,,,,,,,,,,,,
,3844680335.46356,299.996917724609,30.2980060577393,,,6,,,,34.7763789877002,,,10,,,,,,,,,,,,,,,,,,,,,,299.993988037109,300.003997802734,30.2980060577393,30.2980060577393,,,8.35665035247803,,1,0,0,0,0.013885498046875,32.7468223571777,1,1,1,299.994232177734,0,4232058080,299.99983215332,,,-0.00086097521012511,4.30494702871331E-5,-0.000861007408412011,4.30493952814237E-5,0.929230153560638,0.929782629013062,34.7428398132324,0.191677689552307,35,4,200,0.0168167054653168,-0.0423521213233471,0.434244364500046,1,,,,,,,,,,,,,,,,
,3844680445.83797,299.997253417969,-19.9827518463135,,,6,,,,34.7763789877002,,,10,,,,,,,,,,,,,,,,,,,,,,299.994018554687,300.004058837891,-19.9827518463135,-19.9827518463135,,,8.36241245269775,,1,0,0,0,0.013885498046875,32.7468223571777,1,1,1,299.994354248047,0,4232058016,300.00007019043,,,-0.00964661997746683,0.00048176927828684,-0.00964695675988945,0.000481769285359197,0.948485732078552,0.949165821075439,34.7448959350586,3.94575727113988E-5,35,4,200,0.0186414122581482,-0.915427029132843,3.87294149398804,1,,,,,,,,,,,,,,,,
,3844680568.37016,299.996398925781,-70.0312957763672,,,6,,,,34.7763789877002,,,100,,,,,,,,,,,,,,,,,,,,,,299.9931640625,300.004364013672,-70.0312957763672,-70.0312957763672,,,8.36462116241455,,1,0,0,0,0.013885498046875,32.7468223571777,1,1,1,299.99365234375,0,4232058144,299.999722290039,,,-0.0178977863476984,0.000893861014656146,-0.0178981657799029,0.000893860401974231,0.948186576366425,0.948609530925751,34.7514495849609,4.1660590171814,35,4,200,0.00182908168062568,-0.172248244285583,0.711986064910889,1,,,,,,,,,,,,,,,,
,3844680681.32546,299.995849609375,-120.006507873535,,,6,,,,34.7763789877002,,,100,,,,,,,,,,,,,,,,,,,,,,299.992797851562,300.003784179687,-120.006507873535,-120.006507873535,,,8.36634922027588,,1,0,0,0,0.013885498046875,30.3030319213867,1,1,1,299.993072509766,0,4232058016,299.999264526367,,,-0.0256493435327754,0.00128100008029855,-0.0256496680162452,0.00128099941068827,0.948085010051727,0.948338687419891,34.7570419311523,0,35,4,200,0.00196166848763824,-0.243209719657898,1.02250802516937,1,,,,,,,,,,,,,,,,
,3844680794.65139,299.996109008789,-170.01838684082,,,6,,,,34.7763789877002,,,100,,,,,,,,,,,,,,,,,,,,,,299.993133544922,300.002899169922,-170.01838684082,-170.01838684082,,,8.36825847625732,,1,0,0,0,0.0146484375,32.7468223571777,1,1,1,299.993499755859,0,4232058080,299.998950195313,,,-0.0330114426034512,0.00164868906854355,-0.0330117494398381,0.00164868870064197,0.948029100894928,0.948212087154388,34.7599449157715,0.000158244874910451,35,4,200,0.00183879304677248,-0.321980714797974,1.31432390213013,1,,,,,,,,,,,,,,,,
,3844680908.12636,299.995468139648,-220.04248046875,,,6,,,,34.7763789877002,,,100,,,,,,,,,,,,,,,,,,,,,,299.992614746094,300.003204345703,-220.04248046875,-220.04248046875,,,8.37478256225586,,1,0,0,0,0.013885498046875,32.7468223571777,1,1,1,299.992736816406,0,4232057984,299.998797607422,,,-0.0400251096080008,0.00199897720043352,-0.0400253610510653,0.00199897634140611,0.947984933853149,0.948113739490509,34.7625770568848,0.192264765501022,35,4,200,0.00201762700453401,-0.386064887046814,1.58618915081024,1,,,,,,,,,,,,,,,,
,3844681021.80451,299.996429443359,-270.029937744141,,,6,,,,34.7763789877002,,,100,,,,,,,,,,,,,,,,,,,,,,299.992980957031,300.004425048828,-270.029937744141,-270.029937744141,,,8.38306331634521,,1,0,0,0,0.013885498046875,32.2580642700195,1,1,1,299.993835449219,0,4232057984,299.999475097656,,,-0.0467207000093116,0.00233337837876848,-0.0467209147171569,0.00233337800495052,0.947961926460266,0.948053121566772,34.764762878418,0,35,4,200,0.00199767178855836,-0.452249735593796,1.84914016723633,1,,,,,,,,,,,,,,,,
,3844681135.19385,299.997100830078,-319.858459472656,,,6,,,,34.7763789877002,,,100,,,,,,,,,,,,,,,,,,,,,,299.994018554687,300.004974365234,-319.858459472656,-319.858459472656,,,8.34342384338379,,1,0,0,0,0.013885498046875,32.2580642700195,1,1,1,299.994567871094,0,4232058464,300.000408935547,,,-0.0531052289947843,0.0026522348024072,-0.0531054121199826,0.00265223466353908,0.948010444641113,0.948077619075775,34.7664108276367,0,35,4,200,0.00196130201220512,-0.512983858585358,2.10205388069153,1,,,,,,,,,,,,,,,,
,3844681247.80863,299.997329711914,-369.968109130859,,,6,,,,34.7763789877002,,,100,,,,,,,,,,,,,,,,,,,,,,299.994720458984,300.004211425781,-369.968109130859,-369.968109130859,,,8.38029193878174,,1,0,0,0,0.013885498046875,32.2580642700195,1,1,1,299.995269775391,0,4232057952,300.000198364258,,,-0.0592395630008125,0.00295859664812572,-0.0592397124416444,0.00295859554567741,0.948050975799561,0.948106586933136,34.7673149108887,2.26372649194673E-5,35,4,200,0.00192740524653345,-0.574660301208496,2.3493971824646,1,,,,,,,,,,,,,,,,
,3844681361.09699,299.995727539063,-419.857818603516,,,6,,,,34.7763789877002,,,100,,,,,,,,,,,,,,,,,,,,,,299.993438720703,300.003326416016,-419.857818603516,-419.857818603516,,,8.38122177124023,,1,0,0,0,0.0147247314453125,32.7468223571777,1,1,1,299.993682861328,0,4232057920,299.998944091797,,,-0.0651098352496021,0.00325177037983212,-0.065109978680356,0.00325176956952274,0.948074877262115,0.948122024536133,34.7680358886719,2.16933476622216E-5,35,4,200,0.00194220885168761,-0.629010379314423,2.58298754692078,1,,,,,,,,,,,,,,,,
,3844681474.16786,299.997222900391,-469.918579101562,,,6,,,,34.7763789877002,,,100,,,,,,,,,,,,,,,,,,,,,,299.994262695313,300.005737304687,-469.918579101562,-469.918579101562,,,8.36662578582764,,1,0,0,0,0.013885498046875,32.2580642700195,1,1,1,299.994598388672,0,4232058112,300.000833129883,,,-0.0707361827821292,0.00353275581487723,-0.0707363073348143,0.00353275472679724,0.948128163814545,0.948167979717255,34.7687149047852,INF,35,4,200,0.00205603195354342,-0.685163974761963,2.802814245224,1,,,,,,,,,,,,,,,,
,3844681587.49522,299.995910644531,-519.930419921875,,,6,,,,34.7763789877002,,,100,,,,,,,,,,,,,,,,,,,,,,299.992523193359,300.004119873047,-519.930419921875,-519.930419921875,,,8.3722620010376,,1,0,0,0,0.013885498046875,32.7468223571777,1,1,1,299.992828369141,0,4232057984,299.999282836914,,,-0.0761253587398092,0.00380190417113096,-0.0761254890402992,0.00380190299700715,0.948136389255524,0.948175251483917,34.7688064575195,0.150242418050766,35,4,200,0.00215632002800703,-0.735120892524719,3.011385679245,1,,,,,,,,,,,,,,,,
,3844681701.07949,299.995803833008,-569.9912109375,,,6,,,,34.7763789877002,,,100,,,,,,,,,,,,,,,,,,,,,,299.992584228516,300.005645751953,-569.9912109375,-569.9912109375,,,8.37465572357178,,1,0,0,0,0.0147247314453125,32.7468223571777,1,1,1,299.992858886719,0,4232057984,300.000161743164,,,-0.0812783732853052,0.00405925122097795,-0.0812784967440262,0.00405924989671863,0.948179244995117,0.948214769363403,34.7691421508789,2.01137245312566E-5,35,4,200,0.00243946746923029,-0.785524845123291,3.21835446357727,1,,,,,,,,,,,,,,,,
,3844681814.63064,299.996673583984,-619.954223632813,,,6,,,,34.7763789877002,,,100,,,,,,,,,,,,,,,,,,,,,,299.993316650391,300.004730224609,-619.954223632813,-619.954223632813,,,8.37431144714355,,1,0,0,0,0.0139617919921875,32.2580642700195,1,1,1,299.993743896484,0,4232058208,299.999658203125,,,-0.0855424646888161,0.00427248262311952,-0.0855425669258435,0.00427248343053112,0.946968495845795,0.946987450122833,34.7710342407227,5.89669704437256,35,4,200,-0.000764243537560105,-0.851617634296417,3.41876769065857,1,,,,,,,,,,,,,,,,
,3844681927.51903,299.996475219727,-670.039367675781,,,6,,,,34.7763789877002,,,100,,,,,,,,,,,,,,,,,,,,,,299.993469238281,300.004333496094,-670.039367675781,-670.039367675781,,,8.37597179412842,,1,0,0,0,0.013885498046875,32.2580642700195,1,1,1,299.993896484375,0,4232058208,299.999935913086,,,-0.0908790917008258,0.00453871231629501,-0.0908792052127792,0.00453871096054575,0.94827938079834,0.948309242725372,34.7697486877441,1.91584513231646E-5,35,4,200,0.0031643440015614,-0.878547370433807,3.60457444190979,1,,,,,,,,,,,,,,,,
,3844682040.90362,299.997283935547,-719.990173339844,,,6,,,,34.7763789877002,,,100,,,,,,,,,,,,,,,,,,,,,,299.994293212891,300.005035400391,-719.990173339844,-719.990173339844,,,8.37506294250488,,1,0,0,0,0.013885498046875,32.2580642700195,1,1,1,299.994384765625,0,4232058048,300.000552368164,,,-0.0953669156753736,0.00476283106827289,-0.0953670317973976,0.00476282923898889,0.94833105802536,0.948361992835999,34.7696380615234,0.191434741020203,35,4,200,0.00347229652106762,-0.914364159107208,3.7796893119812,1,,,,,,,,,,,,,,,,
,3844682154.38861,299.995941162109,-770.026489257812,,,6,,,,34.7763789877002,,,100,,,,,,,,,,,,,,,,,,,,,,299.992950439453,300.004455566406,-770.026489257812,-770.026489257812,,,8.38309001922607,,1,0,0,0,0.013885498046875,32.2580642700195,1,1,1,299.993377685547,0,4232058016,299.999456787109,,,-0.0996419258796064,0.00497633384390712,-0.0996420833469865,0.00497633352494373,0.948334455490112,0.948366224765778,34.7695465087891,0,35,4,200,0.00346394744701684,-0.95665693283081,3.9472553730011,1,,,,,,,,,,,,,,,,
,3844682278.02061,299.998031616211,-1499.65966796875,,,6,,,,34.7763789877002,,,1000,,,,,,,,,,,,,,,,,,,,,,299.993713378906,300.003997802734,-1499.65966796875,-1499.65966796875,,,8.3774881362915,,1,0,0,0,0.013885498046875,32.2580642700195,1,1,1,299.996246337891,0,4232057888,299.999628970498,,,-0.140580011607867,0.00702087801608959,-0.140580512345627,0.00702087357353155,0.948315739631653,0.948396742343903,34.7654685974121,0,35,4,200,-0.000135821712319739,-4.83287191390991,4.80799198150635,1,,,,,,,,,,,,,,,,
,3844682393.68217,299.996505737305,-4000.21704101562,,,6,,,,34.7763789877002,,,1000,,,,,,,,,,,,,,,,,,,,,,299.993713378906,300.003326416016,-4000.21704101562,-4000.21704101562,,,8.38773345947266,,1,0,0,0,0.013885498046875,32.2580642700195,1,1,1,299.993927001953,0,4232058016,299.999557495117,,,-0.167190705158948,0.00834995919289386,-0.167194086035068,0.00834995994551129,0.948118925094605,0.94850742816925,34.7524719238281,0,35,4,200,-0.000114075053716078,-0.162171870470047,0.660178005695343,1,,,,,,,,,,,,,,,,
,3844682507.24089,300.001220703125,-6500.3583984375,,,6,,,,34.7763789877002,,,1000,,,,,,,,,,,,,,,,,,,,,,299.998413085937,300.008209228516,-6500.3583984375,-6500.3583984375,,,8.40097522735596,,1,0,0,0,0.013885498046875,32.7468223571777,1,1,1,299.998565673828,0,4232057888,300.00436706543,,,-0.171255383378661,0.00855304857905757,-0.171260161035128,0.00855305062308109,0.94791978597641,0.948452174663544,34.7483596801758,0,35,4,200,-0.000136288494104519,-0.166819885373116,0.67675769329071,1,,,,,,,,,,,,,,,,
,3844682620.88307,299.996963500977,-9000.3662109375,,,6,,,,34.7763789877002,,,1000,,,,,,,,,,,,,,,,,,,,,,299.993255615234,300.005340576172,-9000.3662109375,-9000.3662109375,,,8.4306755065918,,1,0,0,0,0.013885498046875,32.7468223571777,1,1,1,299.993713378906,0,4232057952,300.000546264648,,,-0.172936925413742,0.00863710937894382,-0.172942267964046,0.00863710873810516,0.947749733924866,0.948344171047211,34.7467346191406,,35,4,200,-0.000223552429815754,-0.168627932667732,0.682523250579834,1,,,,,,,,,,,,,,,,
,3844682766.25757,300.00309753418,-25000.255859375,,,6,,,,34.7763789877002,,,1000,,,,,,,,,,,,,,,,,,,,,,299.998474121094,300.011047363281,-25000.255859375,-25000.255859375,,,8.41271781921387,,1,0,0,0,0.013885498046875,32.2580642700195,1,1,1,299.998870849609,0,4232057376,300.006430053711,,,-0.176281219056818,0.00880433804815966,-0.176285870884343,0.00880432427231386,0.947310268878937,0.947842001914978,34.748218536377,0,35,4,200,-0.000335929304128513,-0.173429355025291,0.695955753326416,1,,,,,,,,,,,,,,,,
,3844682914.25475,300.048675537109,-50000.29296875,,,6,,,,34.7763789877002,,,1000,,,,,,,,,,,,,,,,,,,,,,300.031005859375,300.065948486328,-50000.29296875,-50000.29296875,,,8.40086936950684,,1,0,0,0,0.013885498046875,32.2580642700195,1,1,1,300.066345214844,0,4232057952,300.055303955078,,,-0.178052475025253,0.00889304593707096,-0.17805412153279,0.00889304189118427,0.946793913841248,0.946976065635681,34.7597923278809,0,35,4,200,-0.000284135370748118,-0.17664647102356,0.702608823776245,1,,,,,,,,,,,,,,,,
,3844683032.64317,300.014556884766,-70000.4765625,,,6,,,,34.7763789877002,,,1000,,,,,,,,,,,,,,,,,,,,,,300.009613037109,300.023559570313,-70000.4765625,-70000.4765625,,,8.421630859375,,1,0,0,0,0.0147247314453125,31.7693061828613,1,1,1,300.009613037109,0,4232057760,300.017932128906,,,-0.178901056529233,0.00893573037077846,-0.178901051774674,0.00893572947566214,0.946161925792694,0.946163296699524,34.7749328613281,5.89702749252319,35,4,200,-0.000313023891067132,-0.179303258657455,0.70451545715332,1,,,,,,,,,,,,,,,,