File: Data/KMK249S/ZFCFC/KMK249S_ZFCFC.dat
[Header]
; MPMS3 Data File (default extension .dat)
; Copyright (c) 2007, Quantum Design, Inc. All rights reserved.
TITLE,
FILEOPENTIME,3870409570.65778,08/23/2022,9:46 am
BYAPP,MPMS3 w/ AC,1.0,1.1
INFO,MPMS3 Measurement Release 1.1.16 Build 424, MultiVu Release 2.3.4.19,APPNAME
INFO,Linear Motor Servo Controller,MOTOR_MODULE_NAME
INFO,3101-100 J0,MOTOR_HW_VERSION
INFO,MMC721,MOTOR_SERIAL_NUMBER
INFO,01.04.28,MOTOR_SOFTWARE_VERSION
INFO,Quantum Design Squid Module,SQUID_MODULE_NAME
INFO,3101-501 B0,SQUID_HW_VERSION
INFO,SQM195,SQUID_SERIAL_NUMBER
INFO,01.03.04,SQUID_SOFTWARE_VERSION
INFO,SQUID AC,AC_MODULE_NAME
INFO,3101-401 f1,AC_HW_VERSION
INFO,SAC107,AC_SERIAL_NUMBER
INFO,SQUID AC 00.95.07,AC_SOFTWARE_VERSION
INFO,TCI166,COIL_SERIAL_NUMBER
INFO,0,MOMENT_UNITS
INFO,KMK249S,SAMPLE_MATERIAL
INFO,,SAMPLE_COMMENT
INFO,2.2,SAMPLE_MASS
INFO,,SAMPLE_VOLUME
INFO,,SAMPLE_MOLECULAR_WEIGHT
INFO,,SAMPLE_SIZE
INFO,,SAMPLE_SHAPE
INFO,Straw,SAMPLE_HOLDER
INFO,Standard,SAMPLE_HOLDER_DETAIL
INFO,66.99,SAMPLE_OFFSET
DATATYPE,COMMENT,1
DATATYPE,TIME,2
STARTUPAXIS,X,2
STARTUPAXIS,Y1,5
FIELDGROUP, VSM,2,3,4,5,6,8,9,10,11,14,15
FIELDGROUP, DC, 2,3,4,14,56,57,58,59,60,61,62,63,64,65,66,67,68,69
FIELDGROUP, AC, 2,3,4,11,16,17,18,19,20,21,22,23,24,25,26,27,28,29,30
STARTUPGROUP, All
[Data]
Comment,Time Stamp (sec),Temperature (K),Magnetic Field (Oe),Moment (emu),M. Std. Err. (emu),Transport Action,Averaging Time (sec),Frequency (Hz),Peak Amplitude (mm),Center Position (mm),Lockin Signal' (V),Lockin Signal (V),Range,M. Quad. Signal (emu),AC Moment (emu),AC M. Std Err. (emu),AC Phase (deg),AC Phase Std. Err. (deg),AC Susceptibility (emu/Oe),AC Suscept. Std Err. (emu/Oe),AC X' (emu/Oe),AC X' Std Err. (emu/Oe),AC X'' (emu/Oe),AC X'' Std Err. (emu/Oe),AC Drive (Oe),AC Frequency (Hz),AC Averaging Time (sec),AC Cycles,AC Range,AC Measure Type,AC Signal' (V),AC Signal'' (V),AC Trim Coil Ratio,AC Trim Coil Phase,Min. Temperature (K),Max. Temperature (K),Min. Field (Oe),Max. Field (Oe),Mass (grams),Motor Lag (deg),Pressure (Torr),Measure Count,Measurement Number,SQUID Status (code),Motor Status (code),Measure Status (code),Motor Current (amps),Motor Temp. (C),Temp. Status (code),Field Status (code),Chamber Status (code),Chamber Temp (K),Redirection State,Evercool Status,Average Temp (K),Rotation Angle (deg),Rotator state,DC Moment Fixed Ctr (emu),DC Moment Err Fixed Ctr (emu),DC Moment Free Ctr (emu),DC Moment Err Free Ctr (emu),DC Fixed Fit,DC Free Fit,DC Calculated Center (mm),DC Calculated Center Err (mm),DC Scan Length (mm),DC Scan Time (s),DC Number of Points,DC Squid Drift,DC Min V (V),DC Max V (V),DC Scans per Measure,Map 01,Map 02,Map 03,Map 04,Map 05,Map 06,Map 07,Map 08,Map 09,Map 10,Map 11,Map 12,Map 13,Map 14,Map 15,Map 16
,3870410798.03103,5.00303506851196,99.9748687744141,,,6,,,,30.8535521203546,,,10,,,,,,,,,,,,,,,,,,,,,,4.99835777282715,5.00309991836548,99.9748687744141,99.9748687744141,,,3.38834977149963,,1,0,0,0,0.0002288818359375,30.7917900085449,1,1,1,5.0031909942627,0,4232058688,5.00073027610779,,,0.00038845521798389,1.92434768099065E-5,0.000388468348028757,1.9243455035128E-5,0.964576840400696,0.965575873851776,30.821891784668,0,35,4,200,6.55982075841166E-5,-0.202858373522758,-0.0133062265813351,1,,,,,,,,,,,,,,,,
,3870410866.46133,9.4725079536438,99.9748687744141,,,6,,,,30.8535521203546,,,10,,,,,,,,,,,,,,,,,,,,,,9.10426044464111,9.82377624511719,99.9748687744141,99.9748687744141,,,4.16071510314941,,1,0,0,0,0.000152587890625,30.7917900085449,6,1,1,9.84075546264648,0,4232058784,9.45543670654297,,,0.000467808281608939,2.3175786760925E-5,0.000467825262158889,2.31757854251035E-5,0.96305513381958,0.964051306247711,30.8212451934814,,35,4,200,0.000220917427213863,-0.22902338206768,0.0016196456272155,1,,,,,,,,,,,,,,,,
,3870410935.96442,14.9733672142029,99.9748687744141,,,6,,,,30.8586706579034,,,10,,,,,,,,,,,,,,,,,,,,,,14.5729761123657,15.3136577606201,99.9748687744141,99.9748687744141,,,4.61995697021484,,1,0,0,0,0.000152587890625,30.7917900085449,6,1,1,15.37375831604,0,4232058912,14.936682510376,,,0.00061859600699676,3.06456032085984E-5,0.000618623433308859,3.06455731930639E-5,0.96339601278305,0.964653968811035,30.8225917816162,0.185042262077332,35,4,200,0.000229994024266489,-0.280544757843018,0.0240939352661371,1,,,,,,,,,,,,,,,,
,3870410997.65531,19.9545097351074,99.9748687744141,,,6,,,,30.8586706579034,,,10,,,,,,,,,,,,,,,,,,,,,,19.5695381164551,20.2895202636719,99.9748687744141,99.9748687744141,,,4.84298610687256,,1,0,0,0,0.000152587890625,30.3030319213867,2,1,1,20.3394813537598,0,4232058688,19.9331382751465,,,0.000766215213485643,3.79577397020444E-5,0.000766243226532781,3.79576967989085E-5,0.964120924472809,0.965185880661011,30.8257732391357,0,35,4,200,0.000170669969520532,-0.333510905504227,0.0429832637310028,1,,,,,,,,,,,,,,,,
,3870411067.73139,25.5368518829346,99.9748687744141,,,6,,,,30.8640814637865,,,10,,,,,,,,,,,,,,,,,,,,,,25.1609916687012,25.8677921295166,99.9748687744141,99.9748687744141,,,6.64421701431274,,1,0,0,0,0.000152587890625,30.7917900085449,2,1,1,25.912712097168,0,4232058592,25.5150005340576,,,0.000922918637396676,4.57198360543922E-5,0.000922952415852572,4.57198303494182E-5,0.964662969112396,0.965716660022736,30.8316059112549,5.55262136459351,35,4,200,0.000175495937583037,-0.390363812446594,0.0620910152792931,1,,,,,,,,,,,,,,,,
,3870411129.12277,30.437255859375,99.9748687744141,,,6,,,,30.8640814637865,,,10,,,,,,,,,,,,,,,,,,,,,,30.0500354766846,30.7721939086914,99.9748687744141,99.9748687744141,,,6.74199104309082,,1,0,0,0,0.000152587890625,30.7917900085449,2,1,1,30.8244762420654,0,4232058848,30.4025007247925,,,0.00104194681876798,5.16150734816237E-5,0.00104196979382391,5.16150303770847E-5,0.965334951877594,0.966000735759735,30.8384475708008,,35,4,200,0.000149940431583673,-0.433667659759521,0.0762996077537537,1,,,,,,,,,,,,,,,,
,3870411197.16425,35.8595809936523,99.9748687744141,,,6,,,,30.8694270313367,,,10,,,,,,,,,,,,,,,,,,,,,,35.4720191955566,36.225513458252,99.9748687744141,99.9748687744141,,,6.87792253494263,,1,0,0,0,0.016021728515625,30.7917900085449,2,1,1,36.247142791748,0,4232058624,35.8549644470215,,,0.00114881099837897,5.69081278381039E-5,0.00114882899827764,5.69080778651621E-5,0.965688467025757,0.966173529624939,30.8476276397705,0.189857423305511,35,4,200,8.98846701602451E-5,-0.472492545843124,0.0889768674969673,1,,,,,,,,,,,,,,,,
,3870411264.67142,41.3050518035889,99.9748687744141,,,6,,,,30.8748521218175,,,10,,,,,,,,,,,,,,,,,,,,,,40.9141082763672,41.6775436401367,99.9748687744141,99.9748687744141,,,6.96544122695923,,1,0,0,0,0.0194549560546875,31.2805480957031,2,1,1,41.6959953308105,0,4232058656,41.2745063781738,,,0.00122646609316692,6.07542991644843E-5,0.0012264778693225,6.07542875870195E-5,0.965977668762207,0.966266334056854,30.858081817627,0,35,4,200,9.47763182921335E-5,-0.500857353210449,0.0979029387235641,1,,,,,,,,,,,,,,,,
,3870411332.1509,46.7350997924805,99.9748687744141,,,6,,,,30.8802782395003,,,10,,,,,,,,,,,,,,,,,,,,,,46.4092025756836,47.0605278015137,99.9748687744141,99.9748687744141,,,7.0073676109314,,1,0,0,0,0.0191497802734375,30.7917900085449,2,1,1,47.1152610778809,0,4232058688,46.7389255099826,,,0.00127791760644524,6.3302519363737E-5,0.00127792197054057,6.33024888034774E-5,0.966199517250061,0.966314911842346,30.8696975708008,4.27925697294995E-5,35,4,200,3.75973322661594E-5,-0.519702792167664,0.103658191859722,1,,,,,,,,,,,,,,,,
,3870411400.23146,52.2336254119873,99.9748687744141,,,6,,,,30.8855751458198,,,10,,,,,,,,,,,,,,,,,,,,,,51.8414726257324,52.6080627441406,99.9748687744141,99.9748687744141,,,7.10303211212158,,1,0,0,0,0.013885498046875,30.7917900085449,2,1,1,52.6257781982422,0,4232058720,52.240064239502,,,0.00130728126825843,6.47568050184221E-5,0.00130728162986149,6.47568016189726E-5,0.966320931911469,0.966330647468567,30.8824996948242,0,35,4,200,6.03937041887548E-5,-0.530602514743805,0.106633007526398,1,,,,,,,,,,,,,,,,
,3870411468.3309,57.7346878051758,99.9748687744141,,,6,,,,30.8906178656699,,,10,,,,,,,,,,,,,,,,,,,,,,57.341480255127,58.0778121948242,99.9748687744141,99.9748687744141,,,7.1443042755127,,1,0,0,0,0.014801025390625,30.7917900085449,2,1,1,58.1278953552246,0,4232058656,57.7116596221924,,,0.00131872923775342,6.53239849009924E-5,0.00131873119321512,6.53240075278479E-5,0.96628749370575,0.966321170330048,30.8963317871094,0,35,4,200,4.83465919387527E-6,-0.535126686096191,0.107418738305569,1,,,,,,,,,,,,,,,,
,3870411536.4684,63.2434120178223,99.9748687744141,,,6,,,,30.8959820488831,,,10,,,,,,,,,,,,,,,,,,,,,,62.8539505004883,63.6010055541992,99.9748687744141,99.9748687744141,,,7.15528249740601,,1,0,0,0,0.0202178955078125,30.7917900085449,2,1,1,63.6328735351562,0,4232058656,63.2360691070557,,,0.00131687851892485,6.52327189163619E-5,0.00131688881500556,6.52327279015642E-5,0.966090619564056,0.966317653656006,30.9108333587646,,35,4,200,3.11695293930825E-5,-0.535127341747284,0.106648959219456,1,,,,,,,,,,,,,,,,
,3870411612.6449,69.4441909790039,99.9748687744141,,,6,,,,30.9068454371779,,,10,,,,,,,,,,,,,,,,,,,,,,69.0607452392578,69.7816543579102,99.9748687744141,99.9748687744141,,,7.20481634140015,,1,0,0,0,0.01617431640625,31.2805480957031,2,1,1,69.82763671875,0,4232058656,69.5404678344727,,,0.00130367907219157,6.45794744383951E-5,0.0013036999681319,6.45795220986317E-5,0.96581357717514,0.966263294219971,30.9277992248535,0.189855813980103,35,4,200,1.46808470162796E-5,-0.531187176704407,0.10435176640749,1,,,,,,,,,,,,,,,,
,3870411680.25789,74.9464683532715,99.9748687744141,,,6,,,,30.9121106934467,,,10,,,,,,,,,,,,,,,,,,,,,,74.5534286499023,75.3045806884766,99.9748687744141,99.9748687744141,,,7.26159000396729,,1,0,0,0,0.013885498046875,30.7917900085449,2,1,1,75.3395080566406,0,4232058592,74.9304893493652,,,0.00128520328173566,6.3665528606551E-5,0.00128524994031175,6.36656476756281E-5,0.965234160423279,0.966237962245941,30.9435653686523,6.25537395477295,35,4,200,8.84937617229298E-6,-0.525196492671967,0.101428158581257,1,,,,,,,,,,,,,,,,
,3870411755.90354,81.1027221679688,99.9748687744141,,,6,,,,30.923408238617,,,10,,,,,,,,,,,,,,,,,,,,,,80.7188568115234,81.4375839233398,99.9748687744141,99.9748687744141,,,7.25130176544189,,1,0,0,0,0.018463134765625,29.3255138397217,2,1,1,81.4865875244141,0,4232058624,81.0800399780273,,,0.00125954136677781,6.23954418887839E-5,0.0012596104228315,6.23956264032826E-5,0.964710891246796,0.966210782527924,30.9620056152344,0,35,4,200,7.8792745625833E-6,-0.51668781042099,0.097510926425457,1,,,,,,,,,,,,,,,,
,3870411832.66659,87.4509086608887,99.9748687744141,,,6,,,,30.9345479106313,,,10,,,,,,,,,,,,,,,,,,,,,,87.0134429931641,87.7900161743164,99.9748687744141,99.9748687744141,,,7.26711845397949,,1,0,0,0,0.0202178955078125,30.3030319213867,2,1,1,87.8883743286133,0,4232058624,87.4102668762207,,,0.00122989970403385,6.09286031737842E-5,0.00122999845505532,6.09288153956729E-5,0.963997423648834,0.966195285320282,30.9815254211426,0,35,4,200,8.58156738559046E-7,-0.506722152233124,0.0930796042084694,1,,,,,,,,,,,,,,,,
,3870411909.10333,93.7521133422852,99.9748687744141,,,6,,,,30.9451342839888,,,10,,,,,,,,,,,,,,,,,,,,,,93.3277969360352,94.1130523681641,99.9748687744141,99.9748687744141,,,7.29891157150269,,1,0,0,0,0.0209808349609375,30.7917900085449,2,1,1,94.1764297485352,0,4232058688,93.7350471496582,,,0.00119812433215478,5.93564309919122E-5,0.00119826308927219,5.93567215485421E-5,0.963091433048248,0.966225802898407,31.0015850067139,0,35,4,200,-7.29659313947195E-6,-0.495955049991608,0.0883763208985329,1,,,,,,,,,,,,,,,,
,3870411985.51483,100.082324981689,99.9748687744141,,,6,,,,30.9564860937561,,,10,,,,,,,,,,,,,,,,,,,,,,99.6549682617187,100.46076965332,99.9748687744141,99.9748687744141,,,7.33591079711914,,1,0,0,0,0.000152587890625,30.3030319213867,2,1,1,100.50968170166,0,4232058816,100.070635223389,,,0.00116510050969645,5.77225797484818E-5,0.00116528356728299,5.7722968071264E-5,0.962083697319031,0.966276407241821,31.0222110748291,INF,35,4,200,-3.93997765968379E-7,-0.484691619873047,0.0835229381918907,1,,,,,,,,,,,,,,,,
,3870412061.82464,106.373767852783,99.9748687744141,,,6,,,,30.9683655737636,,,10,,,,,,,,,,,,,,,,,,,,,,105.970016479492,106.720191955566,99.9748687744141,99.9748687744141,,,7.33270454406738,,1,0,0,0,0.0159454345703125,30.3030319213867,2,1,1,106.777519226074,0,4232058656,106.348484039307,,,0.00113149505882765,5.60601083783402E-5,0.00113172485484052,5.60605090917206E-5,0.960949838161469,0.966331124305725,31.0433788299561,0,35,4,200,2.39397877521697E-7,-0.473209977149963,0.0786318182945251,1,,,,,,,,,,,,,,,,
,3870412138.5555,112.794799804688,99.9748687744141,,,6,,,,30.98121838899,,,10,,,,,,,,,,,,,,,,,,,,,,112.39820098877,113.114204406738,99.9748687744141,99.9748687744141,,,7.3263373374939,,1,0,0,0,0.020904541015625,31.7693061828613,2,1,1,113.191398620605,0,4232058816,112.75474395752,,,0.00109748594553281,5.43777392093858E-5,0.00109776275677359,5.43780611013528E-5,0.95974063873291,0.966400146484375,31.0653228759766,0,35,4,200,-3.91784378734883E-5,-0.461576461791992,0.0737292394042015,1,,,,,,,,,,,,,,,,
,3870412223.91548,119.801368713379,99.9748687744141,,,6,,,,30.998417085066,,,10,,,,,,,,,,,,,,,,,,,,,,119.413291931152,120.160926818848,99.9748687744141,99.9748687744141,,,7.35016012191772,,1,0,0,0,0.0191497802734375,30.3030319213867,2,1,1,120.189445495605,0,4232058720,119.78493347168,,,0.00105983580952556,5.25147180499683E-5,0.00106016129687833,5.25151900413158E-5,0.958593845367432,0.96654611825943,31.090950012207,2.43906415562378E-5,35,4,200,-7.47425337976892E-6,-0.448638826608658,0.0683120489120483,1,,,,,,,,,,,,,,,,
,3870412309.45103,126.903823852539,99.9748687744141,,,6,,,,31.0166616436259,,,10,,,,,,,,,,,,,,,,,,,,,,126.485282897949,127.255790710449,99.9748687744141,99.9748687744141,,,7.38313436508179,,1,0,0,0,0.0202178955078125,30.7917900085449,2,1,1,127.322364807129,0,4232058592,126.866425323486,,,0.00102248605146938,5.06665857786048E-5,0.00102285424875389,5.06670209381473E-5,0.957405865192413,0.966647386550903,31.1171398162842,0.0981907993555069,35,4,200,-7.94904462964041E-6,-0.43577241897583,0.0629830583930016,1,,,,,,,,,,,,,,,,
,3870412392.62567,133.806274414062,99.9748687744141,,,6,,,,31.0358482530725,,,10,,,,,,,,,,,,,,,,,,,,,,133.392395019531,134.135787963867,99.9748687744141,99.9748687744141,,,7.41762399673462,,1,0,0,0,0.020751953125,30.3030319213867,2,1,1,134.220153808594,0,4232058656,133.770021057129,,,0.000986956382118044,4.8908273560805E-5,0.000987364474891204,4.89088782513181E-5,0.956332087516785,0.966743111610413,31.1431922912598,0.000137784561957233,35,4,200,-3.06861124954594E-6,-0.423510819673538,0.0579468719661236,1,,,,,,,,,,,,,,,,
,3870412477.13688,140.79549407959,99.9748687744141,,,6,,,,31.0557499950028,,,10,,,,,,,,,,,,,,,,,,,,,,140.381622314453,141.158920288086,99.9748687744141,99.9748687744141,,,7.42832136154175,,1,0,0,0,0.0138092041015625,30.7917900085449,2,1,1,141.209365844727,0,4232058656,140.771696472168,,,0.000951712789237669,4.71643062672447E-5,0.000952157176429961,4.71648256323623E-5,0.95514190196991,0.966803014278412,31.1701774597168,2.70329583145212E-5,35,4,200,-1.00122733783792E-5,-0.411297738552094,0.0529945939779282,1,,,,,,,,,,,,,,,,
,3870412563.03971,147.933898925781,99.9748687744141,,,6,,,,31.0772877858183,,,10,,,,,,,,,,,,,,,,,,,,,,147.521133422852,148.297088623047,99.9748687744141,99.9748687744141,,,7.4299259185791,,1,0,0,0,0,30.7917900085449,2,1,1,148.346664428711,0,4232058624,147.90245513916,,,0.000916908699299434,4.54418286524828E-5,0.000917388214896149,4.54424217989557E-5,0.954010188579559,0.966876864433289,31.1983070373535,0,35,4,200,-9.1592328317347E-6,-0.399199366569519,0.0481113381683826,1,,,,,,,,,,,,,,,,
,3870412648.21349,155.011825561523,99.9748687744141,,,6,,,,31.0995584664123,,,10,,,,,,,,,,,,,,,,,,,,,,154.596221923828,155.358749389648,99.9748687744141,99.9748687744141,,,7.4346866607666,,1,0,0,0,0.01922607421875,30.7917900085449,2,1,1,155.427429199219,0,4232058688,154.977186584473,,,0.00088336590858938,4.37816858114035E-5,0.00088387583786517,4.37822780404203E-5,0.95291393995285,0.966957032680511,31.2268028259277,0,35,4,200,-3.64974839612842E-5,-0.387526601552963,0.0434314385056496,1,,,,,,,,,,,,,,,,
,3870412760.65439,164.323356628418,99.9748687744141,,,6,,,,31.1308428185496,,,10,,,,,,,,,,,,,,,,,,,,,,163.913604736328,164.665954589844,99.9748687744141,99.9748687744141,,,7.46526288986206,,1,0,0,0,0.018768310546875,30.7917900085449,2,1,1,164.733108520508,0,4232058624,164.290995788574,,,0.000840829739010536,4.1676023168168E-5,0.00084137191468796,4.16766946522624E-5,0.951648414134979,0.967090368270874,31.2652320861816,0,35,4,200,-3.68900327885058E-5,-0.372656792402267,0.0375830307602882,1,,,,,,,,,,,,,,,,
,3870412871.78447,173.579162597656,99.9748687744141,,,6,,,,31.1635510976183,,,10,,,,,,,,,,,,,,,,,,,,,,173.172714233398,173.902938842773,99.9748687744141,99.9748687744141,,,7.48899173736572,,1,0,0,0,0.0138092041015625,30.7917900085449,2,1,1,173.985610961914,0,4232058656,173.540489196777,,,0.000800747006994268,3.96914632815857E-5,0.00080131032661472,3.96921594198999E-5,0.950543344020844,0.967182874679565,31.3039093017578,INF,35,4,200,-8.41765995573951E-6,-0.358559966087341,0.0321162641048431,1,,,,,,,,,,,,,,,,
,3870412982.93388,182.797721862793,99.9748687744141,,,6,,,,31.1980191623429,,,10,,,,,,,,,,,,,,,,,,,,,,182.39436340332,183.149719238281,99.9748687744141,99.9748687744141,,,7.53452682495117,,1,0,0,0,0.0138092041015625,30.3030319213867,2,1,1,183.201080322266,0,4232058656,182.767741394043,,,0.000762337800720153,3.7789541722101E-5,0.000762917672361534,3.77902937506116E-5,0.949510931968689,0.967275261878967,31.3438854217529,0,35,4,200,-5.85430097999051E-6,-0.345068395137787,0.0268896855413914,1,,,,,,,,,,,,,,,,
,3870413094.23892,192.077209472656,99.9748687744141,,,6,,,,31.2345095430443,,,10,,,,,,,,,,,,,,,,,,,,,,191.653915405273,192.477294921875,99.9748687744141,99.9748687744141,,,7.54080390930176,,1,0,0,0,0.015716552734375,30.7917900085449,2,1,1,192.500503540039,0,4232058784,192.041625976562,,,0.000725811415431428,3.59803932358783E-5,0.000726395335652555,3.59811125071081E-5,0.948702096939087,0.967350542545319,31.3846244812012,0,35,4,200,-4.74899525215733E-6,-0.332139521837234,0.0219833347946405,1,,,,,,,,,,,,,,,,
,3870413205.71422,201.325965881348,99.9748687744141,,,6,,,,31.2726373125915,,,10,,,,,,,,,,,,,,,,,,,,,,200.912322998047,201.664840698242,99.9748687744141,99.9748687744141,,,7.5530366897583,,1,0,0,0,0.0145721435546875,31.2805480957031,2,1,1,201.739608764648,0,4232058656,201.292900085449,,,0.000691000577516717,3.42559896188197E-5,0.000691584512736487,3.42567152430257E-5,0.947990477085113,0.967426180839539,31.4264793395996,0,35,4,200,-7.72016119299224E-6,-0.319807976484299,0.0173391457647085,1,,,,,,,,,,,,,,,,
,3870413312.43179,210.135459899902,99.9748687744141,,,6,,,,31.3105704769507,,,10,,,,,,,,,,,,,,,,,,,,,,209.71516418457,210.520095825195,99.9748687744141,99.9748687744141,,,7.56839609146118,,1,0,0,0,0.0145721435546875,30.7917900085449,2,1,1,210.555755615234,0,4232058656,210.135595703125,,,0.000659241181400291,3.2682576260235E-5,0.00065982341194246,3.26833820678439E-5,0.94738095998764,0.967507421970367,31.4676208496094,,35,4,200,-2.16512707993388E-5,-0.308521419763565,0.0131456004455686,1,,,,,,,,,,,,,,,,
,3870413423.43908,219.356056213379,99.9748687744141,,,6,,,,31.3522775872988,,,10,,,,,,,,,,,,,,,,,,,,,,218.949813842773,219.726425170898,99.9748687744141,99.9748687744141,,,7.57987070083618,,1,0,0,0,0.0147247314453125,30.7917900085449,2,1,1,219.762298583984,0,4232058592,219.339817810059,,,0.000628002426465995,3.11345594519525E-5,0.000628568469193112,3.1135166391415E-5,0.946968495845795,0.967552006244659,31.5114822387695,0.190081939101219,35,4,200,-5.96599147684174E-6,-0.297420412302017,0.00898053031414747,1,,,,,,,,,,,,,,,,
,3870413534.00173,228.512405395508,99.9748687744141,,,6,,,,31.39552238308,,,10,,,,,,,,,,,,,,,,,,,,,,228.097518920898,228.852020263672,99.9748687744141,99.9748687744141,,,7.60248470306397,,1,0,0,0,0.0165557861328125,30.7917900085449,2,1,1,228.927291870117,0,4232058848,228.478680419922,,,0.000598572567095076,2.96761280504431E-5,0.000599127136560823,2.96767905071641E-5,0.946583867073059,0.967606425285339,31.5566883087158,0,35,4,200,-7.22812046660692E-6,-0.286907166242599,0.00512490980327129,1,,,,,,,,,,,,,,,,
,3870413645.45586,237.745185852051,99.9748687744141,,,6,,,,31.4402433795383,,,10,,,,,,,,,,,,,,,,,,,,,,237.350006103516,238.095977783203,99.9748687744141,99.9748687744141,,,7.63348817825317,,1,0,0,0,0,30.7917900085449,2,1,1,238.140365600586,0,4232058688,237.734817504883,,,0.000570318080706049,2.827596596972E-5,0.000570856649812797,2.82764386273871E-5,0.9461629986763,0.967631161212921,31.6034488677978,3.17559133691248E-5,35,4,200,-1.85550579772098E-5,-0.27676323056221,0.00151135248597711,1,,,,,,,,,,,,,,,,
,3870413750.21237,246.43913269043,99.9748687744141,,,6,,,,31.4846844139387,,,10,,,,,,,,,,,,,,,,,,,,,,246.045776367187,246.796829223633,99.9748687744141,99.9748687744141,,,7.71674919128418,,1,0,0,0,0.0147247314453125,30.7917900085449,2,1,1,246.832489013672,0,4232058656,246.424063110352,,,0.000545158627869713,2.70289734068239E-5,0.000545688668788019,2.70297466306836E-5,0.945889234542847,0.967668175697327,31.6492919921875,0,35,4,200,1.79758683316322E-6,-0.267687976360321,-0.00170733267441392,1,,,,,,,,,,,,,,,,
,3870413855.55175,255.199966430664,99.9748687744141,,,6,,,,31.5306546650362,,,10,,,,,,,,,,,,,,,,,,,,,,254.812240600586,255.553939819336,99.9748687744141,99.9748687744141,,,7.88638782501221,,1,0,0,0,0.0138092041015625,30.7917900085449,2,1,1,255.587692260742,0,4232058656,255.184063720703,,,0.000521181155874553,2.5840824593248E-5,0.000521697532168967,2.58413870409687E-5,0.945427656173706,0.967673718929291,31.6974563598633,0,35,4,200,-1.48474418892874E-5,-0.259034097194672,-0.00476110028102994,1,,,,,,,,,,,,,,,,
,3870413960.66598,263.901657104492,99.9748687744141,,,6,,,,31.5780626457444,,,10,,,,,,,,,,,,,,,,,,,,,,263.484497070313,264.245635986328,99.9748687744141,99.9748687744141,,,7.88079977035522,,1,0,0,0,0.0164794921875,30.7917900085449,2,1,1,264.318817138672,0,4232058656,263.872735595703,,,0.000498232751034796,2.47042293200809E-5,0.000498750685892526,2.47047592487138E-5,0.944527983665466,0.967654466629028,31.749059677124,3.27612178807612E-5,35,4,200,2.43915792452754E-6,-0.250746220350266,-0.00764974625781178,1,,,,,,,,,,,,,,,,
,3870414070.9798,273.037612915039,99.9748687744141,,,6,,,,31.6290834099609,,,10,,,,,,,,,,,,,,,,,,,,,,272.625640869141,273.367248535156,99.9748687744141,99.9748687744141,,,7.880286693573,,1,0,0,0,0.0167083740234375,30.7917900085449,2,1,1,273.449584960938,0,4232058656,273.003698730469,,,0.000475561089389474,2.35826852624145E-5,0.000476109113345078,2.35832709459943E-5,0.942585587501526,0.967633903026581,31.8090305328369,0,35,4,200,-1.1232786164328E-5,-0.242519617080688,-0.0104507217183709,1,,,,,,,,,,,,,,,,
,3870414180.42985,282.080459594727,99.9748687744141,,,6,,,,31.682439199301,,,10,,,,,,,,,,,,,,,,,,,,,,281.687072753906,282.437957763672,99.9748687744141,99.9748687744141,,,7.90140581130982,,1,0,0,0,0.0168609619140625,30.7917900085449,2,1,1,282.473846435547,0,4232058624,282.067074584961,,,0.000454240206776522,2.25301989119951E-5,0.000454863073588257,2.2530903230302E-5,0.939001798629761,0.967610001564026,31.8785820007324,5.26049518585205,35,4,200,4.73885819474162E-7,-0.234786167740822,-0.0130779407918453,1,,,,,,,,,,,,,,,,
,3870414289.74479,291.151214599609,99.9748687744141,,,6,,,,31.7360290091851,,,10,,,,,,,,,,,,,,,,,,,,,,290.753021240234,291.506439208984,99.9748687744141,99.9748687744141,,,7.96218156814575,,1,0,0,0,0.0138092041015625,30.3030319213867,2,1,1,291.549407958984,0,4232058688,291.123049926758,,,0.0004338818509393,2.15286485075384E-5,0.000434647808851867,2.15295364012116E-5,0.933054327964783,0.967656195163727,31.9585075378418,0,35,4,200,3.01420209325443E-6,-0.227371886372566,-0.0155653972178698,1,,,,,,,,,,,,,,,,
,3870414391.62111,299.131439208984,99.9748687744141,,,6,,,,31.7838195235076,,,10,,,,,,,,,,,,,,,,,,,,,,298.967987060547,299.283233642578,99.9748687744141,99.9748687744141,,,8.1295804977417,,1,0,0,0,0.0138092041015625,31.2805480957031,6,1,1,299.294891357422,0,4232058656,299.139834594727,,,0.000416626488375809,2.06806249480897E-5,0.000417525645123535,2.06815122390443E-5,0.927423000335693,0.967521131038666,32.030200958252,0,35,4,200,4.18604258811683E-6,-0.221658065915108,-0.0182611960917711,1,,,,,,,,,,,,,,,,
,3870414459.27385,299.891662597656,99.9748687744141,,,6,,,,31.7889399836965,,,10,,,,,,,,,,,,,,,,,,,,,,299.879852294922,299.902282714844,99.9748687744141,99.9748687744141,,,8.29618072509766,,1,0,0,0,0.0138092041015625,31.2805480957031,5,1,1,299.903472900391,0,4232058656,299.894906616211,,,0.000414428251769341,2.05724714566445E-5,0.000415344797515162,2.05733475788589E-5,0.926784157752991,0.967730700969696,32.0384330749512,,35,4,200,-1.59658043230593E-6,-0.220706567168236,-0.0184425134211779,1,,,,,,,,,,,,,,,,
,3870414550.84421,298.563537597656,99.9748687744141,,,6,,,,31.7806660546995,,,10,,,,,,,,,,,,,,,,,,,,,,298.241851806641,298.917938232422,99.9748687744141,99.9748687744141,,,8.59357929229736,,1,0,0,0,0.0138092041015625,30.3030319213867,2,1,1,298.209136962891,0,4232058048,298.587789916992,,,0.000416338350246142,2.06678731321676E-5,0.000417272118836414,2.0668855381958E-5,0.926401436328888,0.967667758464813,32.0316390991211,0,35,4,200,4.27824597863946E-5,-0.221982672810554,-0.0186861082911491,1,,,,,,,,,,,,,,,,
,3870414661.59057,288.803497314453,99.9748687744141,,,6,,,,31.7265581571716,,,10,,,,,,,,,,,,,,,,,,,,,,288.439666748047,289.230316162109,99.9748687744141,99.9748687744141,,,9.19511699676514,,1,0,0,0,0.016021728515625,30.3030319213867,2,1,1,288.376678466797,0,4232058688,288.844027709961,,,0.000440874370718663,2.18899736588051E-5,0.000441952856441911,2.18910465057097E-5,0.923921287059784,0.968128681182861,31.988826751709,0,35,4,200,4.65802804683335E-5,-0.228821560740471,-0.0136122889816761,1,,,,,,,,,,,,,,,,
,3870414772.17746,279.8720703125,99.9748687744141,,,6,,,,31.6798241812469,,,10,,,,,,,,,,,,,,,,,,,,,,279.487091064453,280.273284912109,99.9748687744141,99.9748687744141,,,8.99578094482422,,1,0,0,0,0.0138092041015625,30.7917900085449,2,1,1,279.470855712891,0,4232058656,279.893328857422,,,0.000462974895154586,2.29761130790751E-5,0.000463880650710222,2.29770096526974E-5,0.930571734905243,0.968368709087372,31.914457321167,0,35,4,200,7.33545584807871E-6,-0.238267838954926,-0.0122695313766599,1,,,,,,,,,,,,,,,,
,3870414883.49755,270.638168334961,99.9748687744141,,,6,,,,31.6339387620656,,,10,,,,,,,,,,,,,,,,,,,,,,270.233093261719,271.043243408203,99.9748687744141,99.9748687744141,,,8.77204132080078,,1,0,0,0,0.01678466796875,30.3030319213867,2,1,1,270.233093261719,0,4232058688,270.649597167969,,,0.000485502546858515,2.40837518417747E-5,0.000486236334263412,2.40844052638895E-5,0.937032699584961,0.968282401561737,31.8404178619385,5.25953006744385,35,4,200,2.50680495810229E-5,-0.246159493923187,-0.00924003217369318,1,,,,,,,,,,,,,,,,
,3870414993.72144,261.465637207031,99.9748687744141,,,6,,,,31.5903028743586,,,10,,,,,,,,,,,,,,,,,,,,,,261.080047607422,261.894256591797,99.9748687744141,99.9748687744141,,,8.61545753479004,,1,0,0,0,0.0173187255859375,30.7917900085449,2,1,1,261.037017822266,0,4232058592,261.50625,,,0.000509199682201843,2.52529083658773E-5,0.000509844768682247,2.52537689615022E-5,0.941153883934021,0.968307673931122,31.7784805297852,0.189969137310982,35,4,200,3.48135217791423E-5,-0.254609912633896,-0.00615293672308326,1,,,,,,,,,,,,,,,,
,3870415104.34092,252.183860778809,99.9748687744141,,,6,,,,31.5487975752449,,,10,,,,,,,,,,,,,,,,,,,,,,251.748229980469,252.649780273438,99.9748687744141,99.9748687744141,,,8.48192882537842,,1,0,0,0,0.018463134765625,30.3030319213867,2,1,1,251.71794128418,0,4232058688,252.228881835938,,,0.000534046005167979,2.64810581996107E-5,0.000534636023413243,2.64817047068678E-5,0.943808019161224,0.968338251113892,31.725004196167,0,35,4,200,1.71250430867076E-5,-0.263329237699509,-0.00282655470073223,1,,,,,,,,,,,,,,,,
,3870415215.45022,242.936401367187,99.9748687744141,,,6,,,,31.5092992678936,,,10,,,,,,,,,,,,,,,,,,,,,,242.542236328125,243.370422363281,99.9748687744141,99.9748687744141,,,8.38506698608398,,1,0,0,0,0.0151824951171875,30.3030319213867,2,1,1,242.502380371094,0,4232058528,242.975614929199,,,0.00056074731074259,2.78014057711959E-5,0.000561290469867152,2.7801987290982E-5,0.946195065975189,0.968311429023743,31.6743221282959,0,35,4,200,4.41917109128553E-5,-0.27284249663353,0.000705361424479634,1,,,,,,,,,,,,,,,,
,3870415327.08157,233.454795837402,99.9748687744141,,,6,,,,31.4703254802433,,,10,,,,,,,,,,,,,,,,,,,,,,233.084808349609,233.861526489258,99.9748687744141,99.9748687744141,,,8.30994606018066,,1,0,0,0,0.0165557861328125,30.7917900085449,2,1,1,233.048065185547,0,4232058688,233.482289123535,,,0.000589588726091166,2.92289991906611E-5,0.000590116414339849,2.92297895351147E-5,0.947700262069702,0.96832412481308,31.6282691955566,0.190023094415665,35,4,200,1.87329278560355E-5,-0.282212913036346,0.00525963352993131,1,,,,,,,,,,,,,,,,
,3870415438.40504,224.155921936035,99.9748687744141,,,6,,,,31.4344154055583,,,10,,,,,,,,,,,,,,,,,,,,,,223.774551391602,224.599746704102,99.9748687744141,99.9748687744141,,,8.26654243469238,,1,0,0,0,0,30.7917900085449,2,1,1,223.712097167969,0,4232058592,224.196934509277,,,0.000619378336897845,3.07027941504839E-5,0.000619870282077434,3.07035549149605E-5,0.949614226818085,0.968327879905701,31.5831241607666,0,35,4,200,4.7423363866983E-5,-0.292748212814331,0.0092505905777216,1,,,,,,,,,,,,,,,,
,3870415549.57039,214.874824523926,99.9748687744141,,,6,,,,31.3984917292308,,,10,,,,,,,,,,,,,,,,,,,,,,214.531707763672,215.306610107422,99.9748687744141,99.9748687744141,,,8.20322036743164,,1,0,0,0,0.016021728515625,30.7917900085449,2,1,1,214.44303894043,0,4232058688,214.933068847656,,,0.000650641384153872,3.22496558119342E-5,0.000651099191064206,3.22503806539067E-5,0.951399743556976,0.968338072299957,31.5383796691895,0,35,4,200,5.79513944103383E-5,-0.303756237030029,0.0134588498622179,1,,,,,,,,,,,,,,,,
,3870415660.9004,205.576232910156,99.9748687744141,,,6,,,,31.3636544985994,,,10,,,,,,,,,,,,,,,,,,,,,,205.175384521484,205.991928100586,99.9748687744141,99.9748687744141,,,8.16140079498291,,1,0,0,0,0.0164794921875,31.2805480957031,2,1,1,205.160537719727,0,4232058688,205.590475463867,,,0.000683200659218177,3.3860861573877E-5,0.000683625349955518,3.38614509809211E-5,0.9530228972435,0.968365371227264,31.4954376220703,2.6186202376266E-5,35,4,200,4.7195117076626E-5,-0.315251618623734,0.0178144164383411,1,,,,,,,,,,,,,,,,
,3870415772.30016,196.306541442871,99.9748687744141,,,6,,,,31.329822803332,,,10,,,,,,,,,,,,,,,,,,,,,,195.955413818359,196.728591918945,99.9748687744141,99.9748687744141,,,8.12470436096191,,1,0,0,0,0.016021728515625,30.3030319213867,2,1,1,195.884490966797,0,4232058624,196.356938171387,,,0.000717973613993509,3.5581317919593E-5,0.000718358605364019,3.5581883471521E-5,0.954826533794403,0.968347787857056,31.4521255493164,5.60821962356567,35,4,200,4.231962520862E-5,-0.327609360218048,0.0223886650055647,1,,,,,,,,,,,,,,,,
,3870415883.731,187.104766845703,99.9748687744141,,,6,,,,31.2966231059172,,,10,,,,,,,,,,,,,,,,,,,,,,186.770843505859,187.526031494141,99.9748687744141,99.9748687744141,,,8.07833862304687,,1,0,0,0,0.0138092041015625,30.7917900085449,2,1,1,186.683502197266,0,4232058560,187.142309570313,,,0.000753995480856199,3.73638072933144E-5,0.000754343268482734,3.73643587120046E-5,0.956438362598419,0.968280553817749,31.4099216461182,0.0844230949878693,35,4,200,6.92815374350175E-5,-0.340390771627426,0.0271341148763895,1,,,,,,,,,,,,,,,,
,3870415994.72946,177.896186828613,99.9748687744141,,,6,,,,31.2639169983172,,,10,,,,,,,,,,,,,,,,,,,,,,177.519836425781,178.318435668945,99.9748687744141,99.9748687744141,,,8.03695678710937,,1,0,0,0,0.0138092041015625,30.7917900085449,2,1,1,177.473937988281,0,4232058528,177.929277038574,,,0.000791215781032021,3.92058306775344E-5,0.000791530235825493,3.92063124954413E-5,0.957873165607452,0.968288600444794,31.3691730499268,0,35,4,200,6.50632500764914E-5,-0.353539168834686,0.0320813022553921,1,,,,,,,,,,,,,,,,
,3870416105.91769,168.542068481445,99.9748687744141,,,6,,,,31.2316156666929,,,10,,,,,,,,,,,,,,,,,,,,,,168.182952880859,168.982223510742,99.9748687744141,99.9748687744141,,,7.99274063110352,,1,0,0,0,0.0180816650390625,30.7917900085449,2,1,1,168.101913452148,0,4232058624,168.601654052734,,,0.000831825732543386,4.1215686790968E-5,0.000832105248012679,4.12162221529074E-5,0.959289610385895,0.968184351921082,31.3279857635498,0,35,4,200,8.29167111078277E-5,-0.367930293083191,0.0374579131603241,1,,,,,,,,,,,,,,,,
,3870416207.75583,160.086822509766,99.9748687744141,,,6,,,,31.2032283230525,,,10,,,,,,,,,,,,,,,,,,,,,,159.699829101562,160.52278137207,99.9748687744141,99.9748687744141,,,7.94901418685913,,1,0,0,0,0.0173187255859375,30.7917900085449,2,1,1,159.650863647461,0,4232058560,160.117309570313,,,0.000869615900495843,4.30860921897094E-5,0.000869860387954514,4.30864719424572E-5,0.960454046726227,0.968062520027161,31.291711807251,2.12090344575699E-5,35,4,200,8.23145674075931E-5,-0.381315797567368,0.0424503646790981,1,,,,,,,,,,,,,,,,
,3870416300.9996,152.334564208984,99.9748687744141,,,6,,,,31.1776121733214,,,10,,,,,,,,,,,,,,,,,,,,,,151.939147949219,152.72998046875,99.9748687744141,99.9748687744141,,,7.92927169799805,,1,0,0,0,0.013885498046875,30.7917900085449,2,1,1,151.939147949219,0,4232058656,152.351252746582,,,0.000905374015887748,4.48560823196156E-5,0.000905596528360239,4.48566747088214E-5,0.961421728134155,0.96800309419632,31.2593784332275,2.03952040465083E-5,35,4,200,7.59587928769179E-5,-0.394019961357117,0.0471957623958588,1,,,,,,,,,,,,,,,,
,3870416387.12552,145.200355529785,99.9748687744141,,,6,,,,31.1573044996943,,,10,,,,,,,,,,,,,,,,,,,,,,144.850067138672,145.59716796875,99.9748687744141,99.9748687744141,,,7.90107011795044,,1,0,0,0,0.017547607421875,31.2805480957031,2,1,1,144.80354309082,0,4232058624,145.233990478516,,,0.00093951898318143,4.65455002212667E-5,0.000939698113941538,4.65458403767986E-5,0.962703347206116,0.967987358570099,31.2298965454102,0,35,4,200,6.51183217996731E-5,-0.406147122383118,0.0516163483262062,1,,,,,,,,,,,,,,,,
,3870416471.43192,138.219047546387,99.9748687744141,,,6,,,,31.1352945694663,,,10,,,,,,,,,,,,,,,,,,,,,,137.873931884766,138.611541748047,99.9748687744141,99.9748687744141,,,7.81866836547852,,1,0,0,0,0.016021728515625,30.7917900085449,2,1,1,137.826553344727,0,4232058624,138.245104980469,,,0.000973952435440251,4.82502706049857E-5,0.000974108196421432,4.82505548890613E-5,0.963339030742645,0.967807650566101,31.2018299102783,,35,4,200,6.02619766141288E-5,-0.418357253074646,0.0562159568071365,1,,,,,,,,,,,,,,,,
,3870416555.5722,131.268280029297,99.9748687744141,,,6,,,,31.1139019701694,,,10,,,,,,,,,,,,,,,,,,,,,,130.914016723633,131.652755737305,99.9748687744141,99.9748687744141,,,7.78344058990478,,1,0,0,0,0.016021728515625,30.7917900085449,2,1,1,130.883804321289,0,4232058592,131.291918945312,,,0.00100982986755194,5.00265004301714E-5,0.00100995961671068,5.00267187946971E-5,0.963978826999664,0.967602610588074,31.173620223999,5.58333444595337,35,4,200,7.67852034186944E-5,-0.430743157863617,0.0613012500107288,1,,,,,,,,,,,,,,,,
,3870416640.62431,124.206039428711,99.9748687744141,,,6,,,,31.0928774045555,,,10,,,,,,,,,,,,,,,,,,,,,,123.858543395996,124.606803894043,99.9748687744141,99.9748687744141,,,7.75759601593018,,1,0,0,0,0.0196075439453125,30.7917900085449,2,1,1,123.805274963379,0,4232058560,124.224660491943,,,0.00104678702590251,5.18558350011093E-5,0.00104688903599415,5.18558483176916E-5,0.964784502983093,0.967658460140228,31.1457176208496,5.58083486557007,35,4,200,7.69499238231219E-5,-0.443906635046005,0.0660677328705788,1,,,,,,,,,,,,,,,,
,3870416727.20815,116.981491088867,99.9748687744141,,,6,,,,31.0719949431732,,,10,,,,,,,,,,,,,,,,,,,,,,116.639961242676,117.373146057129,99.9748687744141,99.9748687744141,,,7.74652910232544,,1,0,0,0,0.000152587890625,30.7917900085449,2,1,1,116.589836120605,0,4232058688,117.013648223877,,,0.00108605713642005,5.38003446003021E-5,0.0010861339043323,5.38002314447106E-5,0.965242385864258,0.967401146888733,31.1177234649658,0,35,4,200,7.47437152313069E-5,-0.457550168037415,0.0716815292835236,1,,,,,,,,,,,,,,,,
,3870416812.9956,109.83345413208,99.9748687744141,,,6,,,,31.0515385646814,,,10,,,,,,,,,,,,,,,,,,,,,,109.486396789551,110.213745117187,99.9748687744141,99.9748687744141,,,7.73401117324829,,1,0,0,0,0.0189208984375,30.7917900085449,2,1,1,109.453163146973,0,4232058656,109.862022399902,,,0.0011244451990658,5.57010505295594E-5,0.00112450602179366,5.5701107800924E-5,0.965725183486938,0.967308104038238,31.0905876159668,,35,4,200,7.86171513027512E-5,-0.471041709184647,0.0768792256712914,1,,,,,,,,,,,,,,,,
,3870416898.55907,102.727519989014,99.9748687744141,,,6,,,,31.0317636547472,,,10,,,,,,,,,,,,,,,,,,,,,,102.391754150391,103.11270904541,99.9748687744141,99.9748687744141,,,7.69248104095459,,1,0,0,0,0.0201416015625,30.7917900085449,2,1,1,102.342330932617,0,4232058656,102.755184936523,,,0.00116362901606631,5.76414881590598E-5,0.00116367107591184,5.76415242922044E-5,0.9660364985466,0.967097699642181,31.0637092590332,0,35,4,200,8.54234822327271E-5,-0.484750211238861,0.0823089778423309,1,,,,,,,,,,,,,,,,
,3870416984.07475,95.6444053649902,99.9748687744141,,,6,,,,31.0127467804267,,,10,,,,,,,,,,,,,,,,,,,,,,95.2862548828125,96.0471343994141,99.9748687744141,99.9748687744141,,,7.6526050567627,,1,0,0,0,0.01739501953125,30.7917900085449,2,1,1,95.2416763305664,0,4232058624,95.6725959777832,,,0.00120295191709024,5.95888514478748E-5,0.00120297799884297,5.95888574649944E-5,0.966291308403015,0.966937005519867,31.0376472473145,1,35,4,200,8.92410389496945E-5,-0.498573362827301,0.0877275392413139,1,,,,,,,,,,,,,,,,
,3870417069.06715,88.6029853820801,99.9748687744141,,,6,,,,30.9945695951045,,,10,,,,,,,,,,,,,,,,,,,,,,88.2381973266602,89.0092163085938,99.9748687744141,99.9748687744141,,,7.5920934677124,,1,0,0,0,0.0189208984375,30.7917900085449,2,1,1,88.1967544555664,0,4232058656,88.6231620788574,,,0.00124189286376948,6.15174437665807E-5,0.00124190809368727,6.15175148817798E-5,0.966470658779144,0.966803193092346,31.0124320983887,0,35,4,200,0.000101316174550448,-0.512124300003052,0.09318907558918,1,,,,,,,,,,,,,,,,
,3870417154.70084,81.4150619506836,99.9748687744141,,,6,,,,30.9771420697289,,,10,,,,,,,,,,,,,,,,,,,,,,81.0291442871094,81.8322601318359,99.9748687744141,99.9748687744141,,,7.55225706100464,,1,0,0,0,0.000152587890625,30.7917900085449,2,1,1,80.9978637695313,0,4232058752,81.4415565490723,,,0.00128096918483275,6.34529546265078E-5,0.00128097442479105,6.34529879904422E-5,0.96654599905014,0.966652572154999,30.9872608184814,,35,4,200,0.000110324610432144,-0.52574610710144,0.0986543819308281,1,,,,,,,,,,,,,,,,
,3870417240.55235,74.17138671875,99.9748687744141,,,6,,,,30.9605005037923,,,10,,,,,,,,,,,,,,,,,,,,,,73.811149597168,74.5912933349609,99.9748687744141,99.9748687744141,,,7.51260995864868,,1,0,0,0,0.0002288818359375,31.7693061828613,2,1,1,73.7514801025391,0,4232058656,74.1872131347656,,,0.00131898096240946,6.53358421597952E-5,0.00131898179773547,6.53358590684346E-5,0.966560125350952,0.96657133102417,30.9637794494629,0,35,4,200,7.36599031370133E-5,-0.538886785507202,0.104039557278156,1,,,,,,,,,,,,,,,,
,3870417326.60098,66.7888832092285,99.9748687744141,,,6,,,,30.9441809754789,,,10,,,,,,,,,,,,,,,,,,,,,,66.4372406005859,67.1893310546875,99.9748687744141,99.9748687744141,,,7.46347951889038,,1,0,0,0,0.0168609619140625,30.7917900085449,2,1,1,66.3884353637695,0,4232058400,66.821711730957,,,0.00135593576446317,6.71665929104023E-5,0.00135593616936116,6.71665796989982E-5,0.966479361057282,0.966494143009186,30.940408706665,0,35,4,200,0.0001189202448586,-0.551751017570496,0.109215699136257,1,,,,,,,,,,,,,,,,
,3870417412.84535,59.4940738677978,99.9748687744141,,,6,,,,30.9281443685728,,,10,,,,,,,,,,,,,,,,,,,,,,59.1263618469238,59.8939094543457,99.9748687744141,99.9748687744141,,,7.44100141525269,,1,0,0,0,0.0002288818359375,30.7917900085449,2,1,1,59.09423828125,0,4232058656,59.5185691833496,,,0.00139002991922275,6.88559792776838E-5,0.00139003464594783,6.88559562944156E-5,0.966241240501404,0.966351926326752,30.9177913665771,1.00000047683716,35,4,200,9.11392271518707E-5,-0.563509941101074,0.11392867565155,1,,,,,,,,,,,,,,,,
,3870417489.69926,53.0014038085937,99.9748687744141,,,6,,,,30.9163560917428,,,10,,,,,,,,,,,,,,,,,,,,,,52.6417198181152,53.4100494384766,99.9748687744141,99.9748687744141,,,7.35575819015503,,1,0,0,0,0.01800537109375,30.7917900085449,2,1,1,52.5927581787109,0,4232058560,53.009220123291,,,0.00141768446156533,7.02264937351256E-5,0.00141769896728085,7.02264447790539E-5,0.965978503227234,0.966300904750824,30.8986434936523,5.55865478515625,35,4,200,8.17180698504671E-5,-0.572965681552887,0.117929048836231,1,,,,,,,,,,,,,,,,
,3870417565.81672,46.6091079711914,99.9748687744141,,,6,,,,30.9036841310905,,,10,,,,,,,,,,,,,,,,,,,,,,46.2216415405273,47.0249938964844,99.9748687744141,99.9748687744141,,,7.24642276763916,,1,0,0,0,0.0186920166015625,30.7917900085449,2,1,1,46.1932220458984,0,4232058496,46.6050247192383,,,0.00144221451401324,7.14421689606685E-5,0.00144224102171281,7.14421959887789E-5,0.965743660926819,0.966272592544556,30.8809413909912,0,35,4,200,5.70280426472891E-5,-0.581410944461822,0.121493227779865,1,,,,,,,,,,,,,,,,
,3870417642.44939,40.1494235992432,99.9748687744141,,,6,,,,30.8920186425188,,,10,,,,,,,,,,,,,,,,,,,,,,39.7803916931152,40.4834671020508,99.9748687744141,99.9748687744141,,,7.14784526824951,,1,0,0,0,0.0138092041015625,30.7917900085449,2,1,1,39.7377166748047,0,4232058752,40.1148779127333,,,0.00146331795560152,7.24882688914702E-5,0.0014633572304511,7.24882912676899E-5,0.965465366840362,0.966241419315338,30.8644123077393,0,35,4,200,6.28874404355884E-5,-0.588470995426178,0.124747112393379,1,,,,,,,,,,,,,,,,
,3870417718.34662,33.7761402130127,99.9748687744141,,,6,,,,30.88133494544,,,10,,,,,,,,,,,,,,,,,,,,,,33.3819236755371,34.1831588745117,99.9748687744141,99.9748687744141,,,7.04680156707764,,1,0,0,0,0.0138092041015625,30.7917900085449,2,1,1,33.3382606506348,0,4232058496,33.7783477783203,,,0.00148023454106746,7.33269329788133E-5,0.00148028525354045,7.33269376852662E-5,0.965203821659088,0.966199696063995,30.8499965667725,1.41766777232988E-5,35,4,200,1.350007369183E-5,-0.593943417072296,0.127535104751587,1,,,,,,,,,,,,,,,,
,3870417794.59638,27.3460092544556,99.9748687744141,,,6,,,,30.8702419031834,,,10,,,,,,,,,,,,,,,,,,,,,,27.0172080993652,27.7244777679443,99.9748687744141,99.9748687744141,,,6.85821771621704,,1,0,0,0,0.01495361328125,30.7917900085449,2,1,1,26.9675407409668,0,4232058528,27.3808340072632,,,0.00149314782468967,7.39671022688049E-5,0.00149320541168716,7.39670597178563E-5,0.965025901794434,0.966162204742432,30.8367118835449,0,35,4,200,1.71688825503225E-5,-0.59791111946106,0.129822626709938,1,,,,,,,,,,,,,,,,
,3870417862.20513,21.7386627197266,99.9748687744141,,,6,,,,30.8644446744339,,,10,,,,,,,,,,,,,,,,,,,,,,21.3744106292725,22.1223678588867,99.9748687744141,99.9748687744141,,,4.84971952438354,,1,0,0,0,0.0153350830078125,30.7917900085449,2,1,1,21.3549575805664,0,4232058624,21.7586086273193,,,0.0015013265104386,7.43731729198302E-5,0.00150140201501815,7.43731968709825E-5,0.964674890041351,0.966117203235626,30.8265647888184,1.57068534463178E-5,35,4,200,6.65750703774393E-5,-0.600165486335754,0.13153849542141,1,,,,,,,,,,,,,,,,
,3870417938.73571,15.4787402153015,99.9748687744141,,,6,,,,30.8530482407242,,,10,,,,,,,,,,,,,,,,,,,,,,15.1095790863037,15.8683404922485,99.9748687744141,99.9748687744141,,,4.41283893585205,,1,0,0,0,0.017242431640625,30.7917900085449,2,1,1,15.0891399383545,0,4232058752,15.4824966430664,,,0.00150740635765023,7.46740255847461E-5,0.00150747310417443,7.46739793331599E-5,0.964794218540192,0.966091930866241,30.8171424865723,0.31454873085022,35,4,200,7.0172107371036E-5,-0.60149747133255,0.13315661251545,1,,,,,,,,,,,,,,,,
,3870417996.98449,10.7650108337402,99.9748687744141,,,6,,,,30.8530482407242,,,10,,,,,,,,,,,,,,,,,,,,,,10.4178190231323,11.140456199646,99.9748687744141,99.9748687744141,,,3.90765595436096,,1,0,0,0,0.0212860107421875,30.7917900085449,2,1,1,10.3895654678345,0,4232058496,10.7790758132935,,,0.0015103226591293,7.48195421434809E-5,0.00151040984553482,7.48195086561738E-5,0.964398622512817,0.966069877147675,30.8121757507324,0.147548258304596,35,4,200,6.68236971250735E-5,-0.601927399635315,0.134116798639297,1,,,,,,,,,,,,,,,,
,3870418055.44888,6.4482696056366,99.9748687744141,,,6,,,,30.8530482407242,,,10,,,,,,,,,,,,,,,,,,,,,,6.0840106010437,6.84953355789185,99.9748687744141,99.9748687744141,,,3.45996928215027,,1,0,0,0,0.0168609619140625,30.7917900085449,6,1,1,6.04700565338135,0,4232058880,6.45910406112671,,,0.00151225210443055,7.49151167048733E-5,0.0015123422262382,7.49151558982995E-5,0.96440577507019,0.966103792190552,30.8118648529053,INF,35,4,200,7.23132761777379E-5,-0.60333114862442,0.133645907044411,1,,,,,,,,,,,,,,,,
,3870418114.07593,5.00165557861328,99.9748687744141,,,6,,,,30.8530482407242,,,10,,,,,,,,,,,,,,,,,,,,,,4.99788856506348,5.00220680236816,99.9748687744141,99.9748687744141,,,3.146728515625,,1,0,0,0,0.01861572265625,30.3030319213867,5,1,1,5.00164413452148,0,4232058816,5.00003066062927,,,0.00151290708518498,7.4947277670482E-5,0.00151298920330867,7.49472144872602E-5,0.96451461315155,0.96610152721405,30.8132667541504,1,35,4,200,4.81063252664171E-5,-0.603313505649567,0.133946299552917,1,,,,,,,,,,,,,,,,
,3870418143.24979,5.00238132476807,99.9748687744141,,,6,,,,30.8530482407242,,,10,,,,,,,,,,,,,,,,,,,,,,4.99811935424805,5.00247049331665,99.9748687744141,99.9748687744141,,,3.13388919830322,,1,0,0,0,0.01983642578125,30.7917900085449,1,1,1,5.00268697738647,0,4232058784,5.00007367134094,,,0.00151293893446691,7.49486629132368E-5,0.00151301974399563,7.49486622193963E-5,0.964580833911896,0.966120719909668,30.8138809204102,0,35,4,200,4.53057145932689E-5,-0.603357970714569,0.133921548724174,1,,,,,,,,,,,,,,,,