File: Data/KMK273S/MvsH/KMK273S_MvsH_300K.dat
[Header]
; MPMS3 Data File (default extension .dat)
; Copyright (c) 2007, Quantum Design, Inc. All rights reserved.
TITLE,
FILEOPENTIME,3889699640.4701,04/03/2023,5:08 pm
BYAPP,MPMS3 w/ AC,1.0,1.1
INFO,MPMS3 Measurement Release 1.1.16 Build 424, MultiVu Release 2.3.4.19,APPNAME
INFO,Linear Motor Servo Controller,MOTOR_MODULE_NAME
INFO,3101-100 J0,MOTOR_HW_VERSION
INFO,MMC721,MOTOR_SERIAL_NUMBER
INFO,01.04.28,MOTOR_SOFTWARE_VERSION
INFO,Quantum Design Squid Module,SQUID_MODULE_NAME
INFO,3101-501 B0,SQUID_HW_VERSION
INFO,SQM195,SQUID_SERIAL_NUMBER
INFO,01.03.04,SQUID_SOFTWARE_VERSION
INFO,SQUID AC,AC_MODULE_NAME
INFO,3101-401 f1,AC_HW_VERSION
INFO,SAC107,AC_SERIAL_NUMBER
INFO,SQUID AC 00.95.07,AC_SOFTWARE_VERSION
INFO,TCI166,COIL_SERIAL_NUMBER
INFO,0,MOMENT_UNITS
INFO,KMK273S,SAMPLE_MATERIAL
INFO,,SAMPLE_COMMENT
INFO,1.9,SAMPLE_MASS
INFO,,SAMPLE_VOLUME
INFO,,SAMPLE_MOLECULAR_WEIGHT
INFO,,SAMPLE_SIZE
INFO,,SAMPLE_SHAPE
INFO,Standard,SAMPLE_HOLDER
INFO,Standard,SAMPLE_HOLDER_DETAIL
INFO,64.75,SAMPLE_OFFSET
DATATYPE,COMMENT,1
DATATYPE,TIME,2
STARTUPAXIS,X,2
STARTUPAXIS,Y1,5
FIELDGROUP, VSM,2,3,4,5,6,8,9,10,11,14,15
FIELDGROUP, DC, 2,3,4,14,56,57,58,59,60,61,62,63,64,65,66,67,68,69
FIELDGROUP, AC, 2,3,4,11,16,17,18,19,20,21,22,23,24,25,26,27,28,29,30
STARTUPGROUP, All
[Data]
Comment,Time Stamp (sec),Temperature (K),Magnetic Field (Oe),Moment (emu),M. Std. Err. (emu),Transport Action,Averaging Time (sec),Frequency (Hz),Peak Amplitude (mm),Center Position (mm),Lockin Signal' (V),Lockin Signal (V),Range,M. Quad. Signal (emu),AC Moment (emu),AC M. Std Err. (emu),AC Phase (deg),AC Phase Std. Err. (deg),AC Susceptibility (emu/Oe),AC Suscept. Std Err. (emu/Oe),AC X' (emu/Oe),AC X' Std Err. (emu/Oe),AC X'' (emu/Oe),AC X'' Std Err. (emu/Oe),AC Drive (Oe),AC Frequency (Hz),AC Averaging Time (sec),AC Cycles,AC Range,AC Measure Type,AC Signal' (V),AC Signal'' (V),AC Trim Coil Ratio,AC Trim Coil Phase,Min. Temperature (K),Max. Temperature (K),Min. Field (Oe),Max. Field (Oe),Mass (grams),Motor Lag (deg),Pressure (Torr),Measure Count,Measurement Number,SQUID Status (code),Motor Status (code),Measure Status (code),Motor Current (amps),Motor Temp. (C),Temp. Status (code),Field Status (code),Chamber Status (code),Chamber Temp (K),Redirection State,Evercool Status,Average Temp (K),Rotation Angle (deg),Rotator state,DC Moment Fixed Ctr (emu),DC Moment Err Fixed Ctr (emu),DC Moment Free Ctr (emu),DC Moment Err Free Ctr (emu),DC Fixed Fit,DC Free Fit,DC Calculated Center (mm),DC Calculated Center Err (mm),DC Scan Length (mm),DC Scan Time (s),DC Number of Points,DC Squid Drift,DC Min V (V),DC Max V (V),DC Scans per Measure,Map 01,Map 02,Map 03,Map 04,Map 05,Map 06,Map 07,Map 08,Map 09,Map 10,Map 11,Map 12,Map 13,Map 14,Map 15,Map 16
,3889699779.0234,300.087783813477,-70000.2578125,,,6,,,,34.3862152099609,,,10,,,,,,,,,,,,,,,,,,,,,,300.074279785156,300.106201171875,-70000.2578125,-70000.2578125,,,8.03248119354248,,1,0,0,0,0.013885498046875,32.7468223571777,1,1,1,300.101287841797,0,2084575072,300.095304790296,,,-0.0103197224869719,0.0005180587459252,-0.0103292515583162,0.000518067563336218,0.886329293251038,0.894496738910675,34.544563293457,0.313857227563858,35,4,200,-0.0225375182926655,-4.70618963241577,4.68538808822632,1,,,,,,,,,,,,,,,,
,3889699939.23131,300.170288085937,-45000.25390625,,,6,,,,34.3862152099609,,,10,,,,,,,,,,,,,,,,,,,,,,300.155670166016,300.184722900391,-45000.25390625,-45000.25390625,,,8.09785079956055,,1,0,0,0,0.013885498046875,32.7468223571777,1,1,1,300.184906005859,0,2084574688,300.177337646484,,,-0.0103542603604593,0.000518453691755849,-0.0103587287705452,0.00051845617806325,0.911588966846466,0.916516482830048,34.4954223632812,0,35,4,200,0.032267726957798,-1.27957630157471,4.08231782913208,1,,,,,,,,,,,,,,,,
,3889700093.28627,300.120986938477,-20000.3515625,,,6,,,,34.3862152099609,,,10,,,,,,,,,,,,,,,,,,,,,,300.105651855469,300.141998291016,-20000.3515625,-20000.3515625,,,8.16023540496826,,1,0,0,0,0.013885498046875,32.2580642700195,1,1,1,300.136322021484,0,2084574944,300.132015991211,,,-0.0102091977734899,0.00051028707335294,-0.0102108339181079,0.00051028838321588,0.93441116809845,0.936850666999817,34.4529113769531,0.307465344667435,35,4,200,0.0300708841532469,-1.08061337471008,4.06845808029175,1,,,,,,,,,,,,,,,,
,3889700240.04863,300.299285888672,-8500.4306640625,,,6,,,,34.3862152099609,,,10,,,,,,,,,,,,,,,,,,,,,,300.292236328125,300.315704345703,-8500.4306640625,-8500.4306640625,,,8.21060752868652,,1,0,0,0,0,32.7468223571777,1,1,1,300.29150390625,0,2084574976,300.306640625,,,-0.00966906723451926,0.000483028019514774,-0.0096700008829051,0.000483028369353278,0.943236529827118,0.944945275783539,34.4383163452148,0,35,4,200,0.0349050052464008,-1.0107456445694,3.83907604217529,1,,,,,,,,,,,,,,,,
,3889700362.8333,300.105682373047,-6000.32568359375,,,6,,,,34.3862152099609,,,10,,,,,,,,,,,,,,,,,,,,,,300.092224121094,300.119354248047,-6000.32568359375,-6000.32568359375,,,8.23846626281738,,1,0,0,0,0.001983642578125,32.7468223571777,1,1,1,300.092010498047,0,2084575072,300.110162353516,,,-0.00926724504246575,0.000462909029265892,-0.00926804594662249,0.00046290991249448,0.944996953010559,0.946550905704498,34.4351615905762,0,35,4,200,0.0261825285851955,-0.90545266866684,3.69474744796753,1,,,,,,,,,,,,,,,,
,3889700484.39418,299.955657958984,-3500.46459960937,,,6,,,,34.3862152099609,,,10,,,,,,,,,,,,,,,,,,,,,,299.943359375,299.966949462891,-3500.46459960937,-3500.46459960937,,,8.26354026794434,,1,0,0,0,0.013885498046875,33.2355842590332,1,1,1,299.944366455078,0,2084575072,299.956726074219,,,-0.00827489786444624,0.000413303555311564,-0.00827547060481143,0.000413304679982791,0.946620941162109,0.947877883911133,34.4296455383301,0,35,4,200,0.0205105356872082,-0.834356129169464,3.26666188240051,1,,,,,,,,,,,,,,,,
,3889700608.97274,300.010955810547,-1000.28643798828,,,6,,,,34.3862152099609,,,10,,,,,,,,,,,,,,,,,,,,,,300.010650634766,300.024078369141,-1000.28643798828,-1000.28643798828,,,8.31317520141602,,1,0,0,0,0.013885498046875,33.2355842590332,1,1,1,300.011260986328,0,2084574848,300.017288208008,,,-0.00413628286911452,0.000206581576546021,-0.0041365534945986,0.000206582097171425,0.947721362113953,0.948935508728027,34.4284782409668,0,35,4,200,0.0117002390325069,-0.424427837133408,1.67632246017456,1,,,,,,,,,,,,,,,,
,3889700730.10179,300.110778808594,-760.383422851562,,,6,,,,34.3862152099609,,,10,,,,,,,,,,,,,,,,,,,,,,300.088317871094,300.132751464844,-760.383422851562,-760.383422851562,,,8.34389114379883,,1,0,0,0,0.013885498046875,32.2580642700195,1,1,1,300.088806152344,0,2084575040,300.112542724609,,,-0.00325435031209043,0.000162542857421822,-0.00325453398306438,0.000162543011121509,0.946748435497284,0.947797954082489,34.4258995056152,0,35,4,200,-0.0177536308765411,-0.382611244916916,1.264981508255,1,,,,,,,,,,,,,,,,
,3889700844.99475,300.181304931641,-710.237121582031,,,6,,,,34.3862152099609,,,10,,,,,,,,,,,,,,,,,,,,,,300.175506591797,300.192932128906,-710.237121582031,-710.237121582031,,,8.3660249710083,,1,0,0,0,0.013885498046875,33.2355842590332,1,1,1,300.187103271484,0,2084575136,300.186669921875,,,-0.00305541937955326,0.00015259924637072,-0.0030556029708174,0.000152599270885624,0.947710454463959,0.948866188526154,34.4274635314941,,35,4,200,-0.0167202912271023,-0.353194653987885,1.19675731658936,1,,,,,,,,,,,,,,,,
,3889700960.17287,300.141876220703,-660.469665527344,,,6,,,,34.3862152099609,,,10,,,,,,,,,,,,,,,,,,,,,,300.135589599609,300.153564453125,-660.469665527344,-660.469665527344,,,8.3877534866333,,1,0,0,0,0.013885498046875,32.2580642700195,1,1,1,300.135314941406,0,2084575008,300.146832275391,,,-0.00284890099969536,0.000142294822581783,-0.00284903407024787,0.000142294729660446,0.946396887302399,0.947285294532776,34.4228744506836,0.163018435239792,35,4,200,-0.0158494152128696,-0.36602309346199,1.11915183067322,1,,,,,,,,,,,,,,,,
,3889701070.13517,300.109970092773,-610.445556640625,,,6,,,,34.3862152099609,,,10,,,,,,,,,,,,,,,,,,,,,,300.09619140625,300.123565673828,-610.445556640625,-610.445556640625,,,8.40910720825195,,1,0,0,0,0.013885498046875,32.2580642700195,1,1,1,300.096374511719,0,2084574976,300.113272094727,,,-0.00264225028843632,0.000131972889602087,-0.00264237792078108,0.000131972946628005,0.946446359157562,0.94734525680542,34.4230728149414,5.8671178817749,35,4,200,-0.0181373078376055,-0.355672299861908,1.03972673416138,1,,,,,,,,,,,,,,,,
,3889701183.15502,300.183380126953,-560.3603515625,,,6,,,,34.3862152099609,,,10,,,,,,,,,,,,,,,,,,,,,,300.176849365234,300.192352294922,-560.3603515625,-560.3603515625,,,8.41975975036621,,1,0,0,0,0.013885498046875,32.7468223571777,1,1,1,300.177154541016,0,2084574944,300.187020874023,,,-0.00242628421827416,0.00012118540736941,-0.00242642576903816,0.000121185494426177,0.946529924869537,0.947615504264831,34.4266471862793,0,35,4,200,-0.0174062941223383,-0.336126416921616,0.955109059810638,1,,,,,,,,,,,,,,,,
,3889701293.77208,300.109268188477,-510.275177001953,,,6,,,,34.3862152099609,,,10,,,,,,,,,,,,,,,,,,,,,,300.090484619141,300.126922607422,-510.275177001953,-510.275177001953,,,8.43692111968994,,1,0,0,0,0.0017547607421875,32.2580642700195,1,1,1,300.128051757812,0,2084574912,300.114376831055,,,-0.00221538375234422,0.000110649937387396,-0.00221549093097586,0.000110649952485208,0.946806073188782,0.947718262672424,34.4232139587402,0,35,4,200,-0.0171031095087528,-0.261369645595551,0.876980602741241,1,,,,,,,,,,,,,,,,
,3889701409.36196,300.091064453125,-460.275512695313,,,6,,,,34.3862152099609,,,10,,,,,,,,,,,,,,,,,,,,,,300.069366455078,300.11328125,-460.275512695313,-460.275512695313,,,8.44740867614746,,1,0,0,0,0.013885498046875,32.7468223571777,1,1,1,300.06884765625,0,2084574944,300.093734741211,,,-0.00199254490204514,9.9525978869196E-5,-0.00199263037293978,9.95260235515143E-5,0.945696651935577,0.946481704711914,34.4209060668945,0,35,4,200,-0.018711406737566,-0.25665494799614,0.770659267902374,1,,,,,,,,,,,,,,,,
,3889701519.7662,300.126281738281,-410.190277099609,,,6,,,,34.3862152099609,,,10,,,,,,,,,,,,,,,,,,,,,,300.098114013672,300.152740478516,-410.190277099609,-410.190277099609,,,8.45791625976563,,1,0,0,0,0.013885498046875,32.7468223571777,1,1,1,300.154449462891,0,2084574944,300.132669067383,,,-0.0017663054802755,8.82307276726641E-5,-0.00176639167363991,8.8230793622062E-5,0.944622218608856,0.945494174957275,34.4231185913086,0,35,4,200,-0.0192037168890238,-0.230070218443871,0.68055534362793,1,,,,,,,,,,,,,,,,
,3889701635.29972,300.008026123047,-360.178405761719,,,6,,,,34.3862152099609,,,10,,,,,,,,,,,,,,,,,,,,,,299.986663818359,300.029388427734,-360.178405761719,-360.178405761719,,,8.48153781890869,,1,0,0,0,0.013885498046875,32.7468223571777,1,1,1,299.986663818359,0,2084574912,300.009213256836,,,-0.00153849588785791,7.68519555059438E-5,-0.00153854698483505,7.68520290074065E-5,0.944428384304047,0.94501006603241,34.4164543151855,0,35,4,200,-0.0194829497486353,-0.256606191396713,0.545090913772583,1,,,,,,,,,,,,,,,,
,3889701746.22086,299.945373535156,-310.154327392578,,,6,,,,34.3862152099609,,,10,,,,,,,,,,,,,,,,,,,,,,299.940765380859,299.954345703125,-310.154327392578,-310.154327392578,,,8.4986743927002,,1,0,0,0,0.013885498046875,32.7468223571777,1,1,1,299.941467285156,0,2084574944,299.948583984375,,,-0.00130669082162441,6.52764300547313E-5,-0.00130673874262121,6.52764710750562E-5,0.943409264087677,0.944047808647156,34.4181671142578,5.86669969558716,35,4,200,-0.0190380159765482,-0.170862659811974,0.517824947834015,1,,,,,,,,,,,,,,,,
,3889701854.17772,300.075149536133,-260.093536376953,,,6,,,,34.3862152099609,,,10,,,,,,,,,,,,,,,,,,,,,,300.062683105469,300.087799072266,-260.093536376953,-260.093536376953,,,8.50868892669678,,1,0,0,0,0.013885498046875,32.2580642700195,1,1,1,300.063018798828,0,2084575072,300.078921508789,,,-0.00107257256707114,5.35925999121769E-5,-0.0010726048168531,5.35926478402016E-5,0.939695298671722,0.940179288387299,34.4149551391602,0,35,4,200,-0.0188491437584162,-0.210474893450737,0.359679877758026,1,,,,,,,,,,,,,,,,
,3889701962.13293,299.952713012695,-210.13053894043,,,6,,,,34.3862152099609,,,10,,,,,,,,,,,,,,,,,,,,,,299.945831298828,299.960052490234,-210.13053894043,-210.13053894043,,,8.52496814727783,,1,0,0,0,0.013885498046875,32.2580642700195,1,1,1,299.946075439453,0,2084574912,299.954650878906,,,-0.000837564063282342,4.18446108508893E-5,-0.000837594330818848,4.18446407365286E-5,0.941884994506836,0.942495703697205,34.417896270752,0,35,4,200,-0.018518814817071,-0.188646927475929,0.271831870079041,1,,,,,,,,,,,,,,,,
,3889702072.52599,300.094192504883,-160.179779052734,,,6,,,,34.3862152099609,,,10,,,,,,,,,,,,,,,,,,,,,,300.069763183594,300.116882324219,-160.179779052734,-160.179779052734,,,8.53513717651367,,1,0,0,0,0.013885498046875,32.7468223571777,1,1,1,300.118621826172,0,2084574880,300.101058959961,,,-0.000597494541703181,2.98620793021561E-5,-0.000597507997501661,2.98620736598971E-5,0.935718297958374,0.9360710978508,34.4115676879883,0.0745688006281853,35,4,200,-0.0190202239900827,-0.124586597084999,0.217700645327568,1,,,,,,,,,,,,,,,,
,3889702183.23744,300.102874755859,-110.106796264648,,,6,,,,34.3862152099609,,,10,,,,,,,,,,,,,,,,,,,,,,300.093322753906,300.114410400391,-110.106796264648,-110.106796264648,,,8.54214572906494,,1,0,0,0,0.013885498046875,32.2580642700195,1,1,1,300.093536376953,0,2084574880,300.107061767578,,,-0.000358415167270169,1.79249803481637E-5,-0.000358418732779033,1.79249861256158E-5,0.926221787929535,0.9263516664505,34.4027061462402,5.86538219451904,35,4,200,-0.0170988030731678,-0.115790791809559,0.109586395323277,1,,,,,,,,,,,,,,,,
,3889702301.51853,300.076049804687,-60.1438102722168,,,6,,,,34.3862152099609,,,1,,,,,,,,,,,,,,,,,,,,,,300.074096679687,300.085388183594,-60.1438102722168,-60.1438102722168,,,8.55561256408691,,1,0,0,0,0.013885498046875,32.7468223571777,1,1,1,300.074645996094,0,2084574944,300.079739379883,,,-0.000115589511807178,5.86761255195545E-6,-0.000115611821214528,5.86763143925993E-6,0.813873648643494,0.814860701560974,34.3134078979492,,35,4,200,-0.187237560749054,-0.680198788642883,0.417460918426514,1,,,,,,,,,,,,,,,,
,3889702411.7842,299.997039794922,-10.0463743209839,,,6,,,,34.3862152099609,,,1,,,,,,,,,,,,,,,,,,,,,,299.992279052734,300.007873535156,-10.0463743209839,-10.0463743209839,,,8.54958534240723,,1,0,0,0,0.013885498046875,32.7468223571777,1,1,1,300.001800537109,0,2084574880,300.001986694336,,,0.000124663016021678,6.28951422178361E-6,0.000124689493589801,6.28954229462868E-6,0.849238872528076,0.850592970848083,34.4634971618652,5.1710147857666,35,4,200,-0.183167353272438,-0.924353361129761,0.114356778562069,1,,,,,,,,,,,,,,,,
,3889702522.4859,300.124526977539,40.0510597229004,,,6,,,,34.3862152099609,,,1,,,,,,,,,,,,,,,,,,,,,,300.117584228516,300.136535644531,40.0510597229004,40.0510597229004,,,8.55583763122559,,1,0,0,0,0.013885498046875,32.7468223571777,1,1,1,300.117431640625,0,2084574880,300.12917175293,,,0.000365232228859262,1.82604037234815E-5,0.000365279919656682,1.82604395627317E-5,0.930405616760254,0.932269752025604,34.4466552734375,INF,35,4,200,-0.173119679093361,-2.10821461677551,0.14858666062355,1,,,,,,,,,,,,,,,,
,3889702641.55364,300.197143554687,90.0996017456055,,,6,,,,34.3862152099609,,,1,,,,,,,,,,,,,,,,,,,,,,300.177185058594,300.215637207031,90.0996017456055,90.0996017456055,,,8.5546350479126,,1,0,0,0,0.00152587890625,32.7468223571777,1,1,1,300.217102050781,0,2084574976,300.204296875,,,0.000607551238995845,3.03450785964134E-5,0.000607611771329639,3.03451232567532E-5,0.946675539016724,0.948543965816498,34.4390830993652,0.000217693799640983,35,4,200,-0.1692855656147,-3.01472783088684,0.452355891466141,1,,,,,,,,,,,,,,,,
,3889702758.41879,300.121124267578,140.148147583008,,,6,,,,34.3862152099609,,,1,,,,,,,,,,,,,,,,,,,,,,300.104827880859,300.137847900391,140.148147583008,140.148147583008,,,8.55698394775391,,1,0,0,0,0.013885498046875,32.7468223571777,1,1,1,300.104400634766,0,2084574976,300.124496459961,,,0.000847200840467673,4.23175321520755E-5,0.00084727031619616,4.23176023227928E-5,0.94546115398407,0.946950376033783,34.4340286254883,5.22326326370239,35,4,200,-0.176566243171692,-3.84956908226013,0.789802968502045,1,,,,,,,,,,,,,,,,
,3889702872.53922,299.992706298828,190.184478759766,,,6,,,,34.3862152099609,,,1,,,,,,,,,,,,,,,,,,,,,,299.977508544922,300.007751464844,190.184478759766,190.184478759766,,,8.55651950836182,,1,0,0,0,0.013885498046875,32.7468223571777,1,1,1,299.977661132812,0,2084574944,299.994671630859,,,0.00108565340285497,5.42204576530861E-5,0.00108572645599181,5.42204794603177E-5,0.948133587837219,0.949436128139496,34.4298400878906,,35,4,200,-0.184734731912613,-4.4988865852356,1.23540318012238,1,,,,,,,,,,,,,,,,
,3889702995.92316,300.093719482422,239.976364135742,,,6,,,,34.3862152099609,,,10,,,,,,,,,,,,,,,,,,,,,,300.089263916016,300.105133056641,239.976364135742,239.976364135742,,,8.5799503326416,,1,0,0,0,0.013885498046875,32.7468223571777,1,1,1,300.089202880859,0,2084574912,300.098880004883,,,0.00131837250192194,6.5840673227048E-5,0.00131849297000552,6.58407675990683E-5,0.948842525482178,0.950627326965332,34.4368133544922,0,35,4,200,-0.0187434293329716,-0.572727978229523,0.115687623620033,1,,,,,,,,,,,,,,,,
,3889703109.39218,300.087524414063,289.963806152344,,,6,,,,34.3862152099609,,,10,,,,,,,,,,,,,,,,,,,,,,300.075653076172,300.100006103516,289.963806152344,289.963806152344,,,8.58365631103516,,1,0,0,0,0.013885498046875,32.2580642700195,1,1,1,300.076171875,0,2084574880,300.091546630859,,,0.0015500281085963,7.74165327642288E-5,0.0015501715249566,7.74166431493895E-5,0.947157680988312,0.948905825614929,34.4371185302734,0,35,4,200,-0.020256320014596,-0.721566140651703,0.0701879262924194,1,,,,,,,,,,,,,,,,
,3889703223.3609,300.027816772461,340.061218261719,,,6,,,,34.3862152099609,,,10,,,,,,,,,,,,,,,,,,,,,,300.021850585937,300.037506103516,340.061218261719,340.061218261719,,,8.58539295196533,,1,0,0,0,0,31.7693061828613,1,1,1,300.022277832031,0,2084574912,300.031549072266,,,0.00177990785382414,8.88883503290593E-5,0.00178003854145711,8.88883364204415E-5,0.949232697486877,0.9506995677948,34.4319610595703,0,35,4,200,-0.0192824080586433,-0.771494507789612,0.141916170716286,1,,,,,,,,,,,,,,,,
,3889703337.28212,300.091613769531,390.121978759766,,,6,,,,34.3862152099609,,,10,,,,,,,,,,,,,,,,,,,,,,300.066497802734,300.114379882812,390.121978759766,390.121978759766,,,8.59126853942871,,1,0,0,0,0.013885498046875,32.7468223571777,1,1,1,300.116729736328,0,2084575040,300.098645019531,,,0.00200320918306259,0.000100049763733166,0.00200338322128759,0.000100049936968126,0.94735062122345,0.948988974094391,34.4354133605957,,35,4,200,-0.0167938265949488,-0.836031079292297,0.193693608045578,1,,,,,,,,,,,,,,,,
,3889703453.08767,300.059204101562,440.133850097656,,,6,,,,34.3862152099609,,,10,,,,,,,,,,,,,,,,,,,,,,300.046966552734,300.072387695313,440.133850097656,440.133850097656,,,8.58005523681641,,1,0,0,0,0.013885498046875,32.7468223571777,1,1,1,300.046966552734,0,2084575136,300.062622070313,,,0.00222522158058768,0.000111131913914733,0.00222540096751026,0.000111132147746585,0.94841605424881,0.949957072734833,34.4334526062012,5.86800241470337,35,4,200,-0.0175292491912842,-0.973074734210968,0.16474737226963,1,,,,,,,,,,,,,,,,
,3889703566.72581,300.032623291016,490.145721435547,,,6,,,,34.3862152099609,,,10,,,,,,,,,,,,,,,,,,,,,,300.014068603516,300.048980712891,490.145721435547,490.145721435547,,,8.57351398468018,,1,0,0,0,0.0138092041015625,32.2580642700195,1,1,1,300.051177978516,0,2084574880,300.038845825195,,,0.00244324226691666,0.000122019617711852,0.00244344123158639,0.000122019506053243,0.948526740074158,0.950147926807404,34.4346008300781,5.22388887405396,35,4,200,-0.0173562671989202,-1.01460635662079,0.227654024958611,1,,,,,,,,,,,,,,,,
,3889703680.22302,300.154922485352,540.2431640625,,,6,,,,34.3862152099609,,,10,,,,,,,,,,,,,,,,,,,,,,300.147216796875,300.16845703125,540.2431640625,540.2431640625,,,8.5824728012085,,1,0,0,0,0.013885498046875,32.7468223571777,1,1,1,300.162628173828,0,2084574976,300.161166381836,,,0.00265347844153303,0.000132526097411334,0.00265372168290814,0.000132526195625582,0.947521865367889,0.949279248714447,34.4370574951172,5.22292423248291,35,4,200,-0.0182153265923262,-1.11752963066101,0.226791456341743,1,,,,,,,,,,,,,,,,
,3889703797.19438,300.197265625,590.340576171875,,,6,,,,34.3862152099609,,,10,,,,,,,,,,,,,,,,,,,,,,300.181335449219,300.213592529297,590.340576171875,590.340576171875,,,8.57748413085938,,1,0,0,0,0.013885498046875,32.7468223571777,1,1,1,300.180969238281,0,2085107424,300.202407836914,,,0.00286103406139638,0.000142889700876205,0.00286126170811727,0.000142889871792094,0.947871088981628,0.949392735958099,34.4334106445313,0,35,4,200,-0.0227854158729315,-1.17859053611755,0.255525767803192,1,,,,,,,,,,,,,,,,
,3889703911.43687,300.081634521484,640.328002929688,,,6,,,,34.3862152099609,,,10,,,,,,,,,,,,,,,,,,,,,,300.064422607422,300.099334716797,640.328002929688,640.328002929688,,,8.58714389801025,,1,0,0,0,0.013885498046875,32.2580642700195,1,1,1,300.063934326172,0,2084575008,300.084170532227,,,0.00306503554662918,0.000153072613718784,0.00306524612169259,0.000153072862746021,0.948575437068939,0.949893295764923,34.4298782348633,,35,4,200,-0.0246789697557688,-1.25528359413147,0.283623158931732,1,,,,,,,,,,,,,,,,
,3889704026.20778,300.150543212891,690.364318847656,,,6,,,,34.3862152099609,,,10,,,,,,,,,,,,,,,,,,,,,,300.136932373047,300.164398193359,690.364318847656,690.364318847656,,,8.59982299804687,,1,0,0,0,0,32.2580642700195,1,1,1,300.164154052734,0,2084574912,300.156680297852,,,0.00326252902740034,0.000162942751211303,0.00326279915789608,0.000162942718490385,0.947746634483337,0.949355483055115,34.4347953796387,,35,4,200,-0.0260288342833519,-1.34225726127625,0.304884970188141,1,,,,,,,,,,,,,,,,
,3889704145.03857,300.188812255859,740.229614257812,,,6,,,,34.3862152099609,,,10,,,,,,,,,,,,,,,,,,,,,,300.159332275391,300.218963623047,740.229614257812,740.229614257812,,,8.60330963134766,,1,0,0,0,0.013885498046875,32.2580642700195,1,1,1,300.158660888672,0,2084574944,300.189791870117,,,0.003451397542005,0.000172379058334434,0.00345164871810071,0.00017237908587587,0.947356462478638,0.948750495910644,34.4316291809082,0.179551869630814,35,4,200,-0.0262475162744522,-1.40323603153229,0.336157739162445,1,,,,,,,,,,,,,,,,
,3889704259.21732,299.975646972656,790.363647460937,,,6,,,,34.3862152099609,,,10,,,,,,,,,,,,,,,,,,,,,,299.970703125,299.986633300781,790.363647460937,790.363647460937,,,8.61565494537353,,1,0,0,0,0.013885498046875,32.7468223571777,1,1,1,299.970733642578,0,2084575104,299.979782104492,,,0.00364184425422912,0.00018188583607868,0.00364212304080233,0.000181886238724551,0.947890698909759,0.949333429336548,34.4321708679199,5.86789321899414,35,4,200,-0.0198484230786562,-1.4418671131134,0.380926370620728,1,,,,,,,,,,,,,,,,
,3889704398.09743,300.094619750977,2500.19067382813,,,6,,,,34.3862152099609,,,10,,,,,,,,,,,,,,,,,,,,,,300.077239990234,300.109985351562,2500.19067382813,2500.19067382813,,,8.59854888916016,,1,0,0,0,0.013885498046875,32.2580642700195,1,1,1,300.111999511719,0,2084574880,300.100695800781,,,0.00743453766077911,0.000371326423043473,0.00743515942859503,0.000371326500871759,0.946820378303528,0.948408424854279,34.4348678588867,0,35,4,200,0.000408431573305279,-2.92641615867615,0.726827561855316,1,,,,,,,,,,,,,,,,
,3889704536.67129,300.026275634766,5000.47900390625,,,6,,,,34.3862152099609,,,10,,,,,,,,,,,,,,,,,,,,,,300.00732421875,300.044281005859,5000.47900390625,5000.47900390625,,,8.59957599639893,,1,0,0,0,0.013885498046875,32.2580642700195,1,1,1,300.045227050781,0,2084575072,300.033355712891,,,0.00900404824291215,0.000449754504777836,0.00900483443085561,0.000449755473212941,0.945297122001648,0.946871995925903,34.4353561401367,,35,4,200,0.0141182094812393,-3.55257987976074,0.948043704032898,1,,,,,,,,,,,,,,,,
,3889704678.85617,300.192169189453,7500.42529296875,,,6,,,,34.3862152099609,,,10,,,,,,,,,,,,,,,,,,,,,,300.176147460937,300.213806152344,7500.42529296875,7500.42529296875,,,8.61822414398193,,1,0,0,0,0.0139617919921875,32.2580642700195,1,1,1,300.208190917969,0,2084575040,300.20256652832,,,0.00954736762359052,0.000476940231754508,0.00954834641332154,0.000476941196210656,0.943535268306732,0.945338308811188,34.4395713806152,0,35,4,200,0.0188777316361666,-3.75056910514832,1.04655253887177,1,,,,,,,,,,,,,,,,
,3889704831.20533,300.203796386719,10000.3349609375,,,6,,,,34.3862152099609,,,10,,,,,,,,,,,,,,,,,,,,,,300.203704833984,300.221557617188,10000.3349609375,10000.3349609375,,,8.61149978637695,,1,0,0,0,0.013885498046875,32.2580642700195,1,1,1,300.203887939453,0,2084574976,300.212152099609,,,0.009819432104272,0.000490580896620898,0.00982059057910864,0.00049058141747653,0.941778600215912,0.9438157081604,34.4437370300293,0,35,4,200,0.0110074942931533,-3.80824732780457,1.08100700378418,1,,,,,,,,,,,,,,,,
,3889704984.33469,300.124206542969,35000.3359375,,,6,,,,34.3862152099609,,,10,,,,,,,,,,,,,,,,,,,,,,300.117828369141,300.140167236328,35000.3359375,35000.3359375,,,8.64315319061279,,1,0,0,0,0.013885498046875,32.2580642700195,1,1,1,300.130584716797,0,2084574944,300.132135009766,,,0.0103366581073195,0.000517176867665758,0.0103402817811688,0.000517180138313388,0.920640170574188,0.925075232982636,34.4844589233398,0,35,4,200,0.0122425397858024,-3.95804572105408,1.32989585399628,1,,,,,,,,,,,,,,,,
,3889705137.2864,300.127075195313,60000.22265625,,,6,,,,34.3862152099609,,,10,,,,,,,,,,,,,,,,,,,,,,300.112213134766,300.143096923828,60000.22265625,60000.22265625,,,8.62615203857422,,1,0,0,0,0.013885498046875,32.2580642700195,1,1,1,300.141937255859,0,2084574976,300.134661865234,,,0.0103419305779814,0.000518604150268012,0.0103497802307183,0.000518610623046778,0.896307170391083,0.903694927692413,34.5301818847656,0,35,4,200,0.0185501836240292,-3.90828680992126,1.45361840724945,1,,,,,,,,,,,,,,,,
,3889705292.06879,300.157012939453,55000.3515625,,,6,,,,34.3862152099609,,,10,,,,,,,,,,,,,,,,,,,,,,300.136840820313,300.180297851562,55000.3515625,55000.3515625,,,8.65313529968262,,1,0,0,0,0,32.7468223571777,1,1,1,300.177185058594,0,2084574976,300.16882019043,,,0.0103557693332849,0.000519048892022993,0.010362688205886,0.000519055912453409,0.90099424123764,0.907775342464447,34.521183013916,,35,4,200,-0.0255466662347317,-4.05259943008423,1.34863543510437,1,,,,,,,,,,,,,,,,
,3889705455.01495,300.15315246582,30000.29296875,,,6,,,,34.3862152099609,,,10,,,,,,,,,,,,,,,,,,,,,,300.140991210937,300.167327880859,30000.29296875,30000.29296875,,,8.63312149047852,,1,0,0,0,0.013885498046875,32.2580642700195,1,1,1,300.139862060547,0,2084574720,300.158480834961,,,0.0103168805804061,0.000515997666184847,0.0103196824043919,0.000515999655660873,0.925382852554321,0.929040968418121,34.4729499816895,0,35,4,200,-0.0329713746905327,-4.15352487564087,1.16312086582184,1,,,,,,,,,,,,,,,,
,3889705613.59471,300.162094116211,9500.1669921875,,,6,,,,34.3862152099609,,,10,,,,,,,,,,,,,,,,,,,,,,300.157623291016,300.180328369141,9500.1669921875,9500.1669921875,,,8.64783668518066,,1,0,0,0,0.013885498046875,32.2580642700195,1,1,1,300.166564941406,0,2084575008,300.171441650391,,,0.0097772188732114,0.000488456360486086,0.00977832197149206,0.000488456842664759,0.942328691482544,0.944295048713684,34.4424896240234,0.191496998071671,35,4,200,-0.0528577342629433,-3.96252536773682,0.984837055206299,1,,,,,,,,,,,,,,,,
,3889705752.6662,300.177581787109,7000.31884765625,,,6,,,,34.3862152099609,,,10,,,,,,,,,,,,,,,,,,,,,,300.163482666016,300.193420410156,7000.31884765625,7000.31884765625,,,8.62242412567139,,1,0,0,0,0.000457763671875,32.7468223571777,1,1,1,300.162292480469,0,2084575072,300.182870483398,,,0.00946450674012376,0.00047278318950504,0.00946539265307175,0.00047278466512871,0.944203853607178,0.945844709873199,34.4368591308594,5.88712427997962E-5,35,4,200,-0.0308778174221516,-3.7936384677887,0.968593537807465,1,,,,,,,,,,,,,,,,
,3889705896.97919,300.229080200195,4500.3232421875,,,6,,,,34.3862152099609,,,10,,,,,,,,,,,,,,,,,,,,,,300.216522216797,300.248931884766,4500.3232421875,4500.3232421875,,,8.65045261383057,,1,0,0,0,0.0003814697265625,32.7468223571777,1,1,1,300.241638183594,0,2084574848,300.239218139648,,,0.00880020782606092,0.000439560293060672,0.00880098207435606,0.000439561004303088,0.945810198783875,0.947423338890076,34.4357032775879,0,35,4,200,-0.0287768747657537,-3.53745079040527,0.84833288192749,1,,,,,,,,,,,,,,,,
,3889706036.47098,300.001541137695,2000.08410644531,,,6,,,,34.3862152099609,,,10,,,,,,,,,,,,,,,,,,,,,,299.992706298828,300.014770507812,2000.08410644531,2000.08410644531,,,8.64305686950684,,1,0,0,0,0.000762939453125,32.2580642700195,1,1,1,299.993469238281,0,2084575008,300.00637512207,,,0.00663474507329075,0.000331367488481276,0.00663522235176721,0.000331368190154914,0.947529077529907,0.948873281478882,34.4307403564453,0,35,4,200,-0.0257159266620874,-2.727210521698,0.65569281578064,1,,,,,,,,,,,,,,,,
,3889706172.07028,300.059585571289,779.9873046875,,,6,,,,34.3862152099609,,,10,,,,,,,,,,,,,,,,,,,,,,300.045654296875,300.073516845703,779.9873046875,779.9873046875,,,8.6287088394165,,1,0,0,0,0,32.2580642700195,1,1,1,300.073516845703,0,2084574976,300.065090942383,,,0.00333463170639796,0.000166544676928816,0.0033348429802802,0.00016654481282162,0.947644054889679,0.948849201202393,34.4283561706543,0,35,4,200,-0.00314521905966103,-1.36744630336761,0.288123697042465,1,,,,,,,,,,,,,,,,
,3889706285.27662,300.243591308594,729.914306640625,,,6,,,,34.3862152099609,,,10,,,,,,,,,,,,,,,,,,,,,,300.238616943359,300.261840820313,729.914306640625,729.914306640625,,,8.63812446594238,,1,0,0,0,0.013885498046875,32.7468223571777,1,1,1,300.248565673828,0,2084574976,300.25237121582,,,0.00313355597431906,0.000156512116278991,0.00313378065044141,0.000156512439153686,0.946452677249908,0.947765588760376,34.4306678771973,5.86776542663574,35,4,200,0.0170647911727428,-1.24454176425934,0.386767953634262,1,,,,,,,,,,,,,,,,
,3889706395.11944,300.140884399414,679.865783691406,,,6,,,,34.3862152099609,,,10,,,,,,,,,,,,,,,,,,,,,,300.137573242188,300.150970458984,679.865783691406,679.865783691406,,,8.65742683410644,,1,0,0,0,0.013885498046875,32.2580642700195,1,1,1,300.138244628906,0,2084575104,300.145416259766,,,0.00293644506922413,0.000146662056050384,0.00293659464073801,0.000146662109473914,0.94708651304245,0.94804835319519,34.4241027832031,4.53625398222357E-5,35,4,200,0.0190629195421934,-1.13839256763458,0.348468959331512,1,,,,,,,,,,,,,,,,
,3889706508.66232,300.271942138672,629.976135253906,,,6,,,,34.3862152099609,,,10,,,,,,,,,,,,,,,,,,,,,,300.263488769531,300.288940429687,629.976135253906,629.976135253906,,,8.65874862670898,,1,0,0,0,0.013885498046875,33.2355842590332,1,1,1,300.280395507812,0,2084574944,300.280413818359,,,0.00272830350388794,0.000136269917536317,0.00272848391394631,0.000136270007408412,0.946581959724426,0.947818338871002,34.4293174743652,0,35,4,200,0.0160428192466497,-1.03259897232056,0.361478745937347,1,,,,,,,,,,,,,,,,
,3889706625.11798,300.184112548828,580.000915527344,,,6,,,,34.3862152099609,,,10,,,,,,,,,,,,,,,,,,,,,,300.169586181641,300.199005126953,580.000915527344,580.000915527344,,,8.66925144195557,,1,0,0,0,0.013885498046875,32.2580642700195,1,1,1,300.198638916016,0,2084575040,300.190203857422,,,0.00251736689919409,0.000125741096779978,0.0025174960104299,0.000125741259942507,0.94558984041214,0.946513712406158,34.4238700866699,0.190173715353012,35,4,200,0.0187059305608273,-0.986385107040405,0.297743111848831,1,,,,,,,,,,,,,,,,
,3889706739.47345,300.194137573242,529.940185546875,,,6,,,,34.3862152099609,,,10,,,,,,,,,,,,,,,,,,,,,,300.193023681641,300.205627441406,529.940185546875,529.940185546875,,,8.66735553741455,,1,0,0,0,0.0005340576171875,32.7468223571777,1,1,1,300.193481445313,0,2084574944,300.199334716797,,,0.00230582141331142,0.000115161620392294,0.00230597829522224,0.000115161867240062,0.947689175605774,0.948960900306702,34.4294815063477,,35,4,200,0.0180191807448864,-0.852007925510407,0.332488566637039,1,,,,,,,,,,,,,,,,
,3889706854.62104,300.1552734375,479.916076660156,,,6,,,,34.3862152099609,,,10,,,,,,,,,,,,,,,,,,,,,,300.131683349609,300.180572509766,479.916076660156,479.916076660156,,,8.65077400207519,,1,0,0,0,0.013885498046875,32.7468223571777,1,1,1,300.129974365234,0,2084575040,300.158895874023,,,0.00208547400010495,0.000104162818063507,0.00208557877855575,0.000104162937885304,0.946564972400665,0.947489082813263,34.4235382080078,,35,4,200,0.0187861174345016,-0.832320094108582,0.296723395586014,1,,,,,,,,,,,,,,,,
,3889706967.5091,300.18098449707,430.124176025391,,,6,,,,34.3862152099609,,,10,,,,,,,,,,,,,,,,,,,,,,300.164733886719,300.197570800781,430.124176025391,430.124176025391,,,8.65622711181641,,1,0,0,0,0,32.2580642700195,1,1,1,300.164398193359,0,2084574912,300.185797119141,,,0.00186208544107396,9.30070172448104E-5,0.00186218230705743,9.30070544129475E-5,0.946212589740753,0.947178244590759,34.4244842529297,0,35,4,200,0.018169853836298,-0.738039612770081,0.276495099067688,1,,,,,,,,,,,,,,,,
,3889707077.98309,299.943084716797,380.087829589844,,,6,,,,34.3862152099609,,,10,,,,,,,,,,,,,,,,,,,,,,299.929840087891,299.956237792969,380.087829589844,380.087829589844,,,8.65128135681152,,1,0,0,0,0.013885498046875,32.2580642700195,1,1,1,299.929931640625,0,2084575040,299.944577026367,,,0.00163570724479138,8.17003013769682E-5,0.00163578995522406,8.17003698293747E-5,0.946125268936157,0.947053611278534,34.4237747192383,0,35,4,200,0.0184557344764471,-0.605381965637207,0.244762673974037,1,,,,,,,,,,,,,,,,
,3889707189.58606,300.081359863281,330.075958251953,,,6,,,,34.3862152099609,,,10,,,,,,,,,,,,,,,,,,,,,,300.070983886719,300.092712402344,330.075958251953,330.075958251953,,,8.65275001525879,,1,0,0,0,0.013885498046875,32.7468223571777,1,1,1,300.091735839844,0,2084575072,300.085687255859,,,0.00140589663354227,7.02232310935633E-5,0.00140598423356153,7.0223350450158E-5,0.945731103420258,0.946856379508972,34.4276809692383,5.86751079559326,35,4,200,0.0180528853088617,-0.527811765670776,0.212587893009186,1,,,,,,,,,,,,,,,,
,3889707301.67461,300.237640380859,279.990753173828,,,6,,,,34.3862152099609,,,10,,,,,,,,,,,,,,,,,,,,,,300.218780517578,300.260986328125,279.990753173828,279.990753173828,,,8.65603351593018,,1,0,0,0,0.013885498046875,32.2580642700195,1,1,1,300.256500244141,0,2084574912,300.248678588867,,,0.00117177913703222,5.85296406288654E-5,0.00117183642448446,5.85296364208348E-5,0.945620894432068,0.946526169776916,34.4234886169434,,35,4,200,0.0168626457452774,-0.451216518878937,0.177303224802017,1,,,,,,,,,,,,,,,,
,3889707413.96099,300.117431640625,229.929992675781,,,6,,,,34.3862152099609,,,10,,,,,,,,,,,,,,,,,,,,,,300.106658935547,300.130249023438,229.929992675781,229.929992675781,,,8.66152858734131,,1,0,0,0,0.0139617919921875,32.2580642700195,1,1,1,300.128204345703,0,2084574400,300.122927856445,,,0.000932398082848495,4.65998635949259E-5,0.000932433077842703,4.65998765962839E-5,0.935822308063507,0.936403036117554,34.4186820983887,0,35,4,200,0.0201093032956123,-0.291956841945648,0.213137239217758,1,,,,,,,,,,,,,,,,
,3889707524.51079,300.143707275391,179.991439819336,,,6,,,,34.3862152099609,,,10,,,,,,,,,,,,,,,,,,,,,,300.126159667969,300.160827636719,179.991439819336,179.991439819336,,,8.66048908233643,,1,0,0,0,0.013885498046875,32.7468223571777,1,1,1,300.126586914063,0,2084575104,300.147192382812,,,0.000697131372019207,3.48344130197596E-5,0.000697146999865986,3.48344207663471E-5,0.939098477363586,0.939462661743164,34.4112815856934,0,35,4,200,0.0194888450205326,-0.214258268475533,0.169342413544655,1,,,,,,,,,,,,,,,,
,3889707632.43103,300.012115478516,130.040664672852,,,6,,,,34.3862152099609,,,10,,,,,,,,,,,,,,,,,,,,,,299.995941162109,300.026184082031,130.040664672852,130.040664672852,,,8.65944004058838,,1,0,0,0,0.013885498046875,32.2580642700195,1,1,1,300.028289794922,0,2084574944,300.017172241211,,,0.000458196846488429,2.29104097827581E-5,0.000458205367962729,2.29104087196795E-5,0.929113864898682,0.929376065731049,34.4091911315918,0,35,4,200,0.0183931477367878,-0.189143761992455,0.135370522737503,1,,,,,,,,,,,,,,,,
,3889707750.54724,300.056579589844,79.9310073852539,,,6,,,,34.3862152099609,,,1,,,,,,,,,,,,,,,,,,,,,,300.0517578125,300.065887451172,79.9310073852539,79.9310073852539,,,8.66819381713867,,1,0,0,0,0.013885498046875,32.2580642700195,1,1,1,300.051940917969,0,2084574944,300.060256958008,,,0.000216630455775047,1.08541816378141E-5,0.000216631360084849,1.08541818230344E-5,0.904474139213562,0.904517292976379,34.397029876709,,35,4,200,0.159536302089691,-0.49251988530159,1.13686943054199,1,,,,,,,,,,,,,,,,
,3889707866.07298,300.219161987305,30.0535697937012,,,6,,,,34.3862152099609,,,1,,,,,,,,,,,,,,,,,,,,,,300.207855224609,300.231201171875,30.0535697937012,30.0535697937012,,,8.67312526702881,,1,0,0,0,0,32.2580642700195,1,1,1,300.206848144531,0,2084574976,300.223049926758,,,-2.54831684827059E-5,1.5726396877587E-6,-2.58356855088633E-5,1.57302891995809E-6,0.411072075366974,0.42643877863884,35.023323059082,0,35,4,200,0.171769350767136,0.246566593647003,1.20638608932495,1,,,,,,,,,,,,,,,,
,3889707981.539,300.127502441406,-19.8360900878906,,,6,,,,34.3862152099609,,,1,,,,,,,,,,,,,,,,,,,,,,300.107482910156,300.146514892578,-19.8360900878906,-19.8360900878906,,,8.67265701293945,,1,0,0,0,0.013885498046875,32.2580642700195,1,1,1,300.147521972656,0,2084574944,300.135131835937,,,-0.000267048671358894,1.33485653181197E-5,-0.00026710612801517,1.33485750221858E-5,0.933681428432465,0.936983048915863,34.4646263122559,0,35,4,200,0.168420448899269,0.166089400649071,1.91614866256714,1,,,,,,,,,,,,,,,,
,3889708097.98942,300.220199584961,-69.99462890625,,,6,,,,34.3862152099609,,,1,,,,,,,,,,,,,,,,,,,,,,300.216857910156,300.232574462891,-69.99462890625,-69.99462890625,,,8.66781711578369,,1,0,0,0,0.013885498046875,32.2580642700195,1,1,1,300.215301513672,0,2084574944,300.226351928711,,,-0.00050733028415675,2.53512147170136E-5,-0.000507405481952988,2.53512983431465E-5,0.938566863536835,0.940963923931122,34.4505271911621,0,35,4,200,0.177423298358917,-0.444661498069763,2.49610471725464,1,,,,,,,,,,,,,,,,
,3889708213.08848,300.056716918945,-120.006507873535,,,6,,,,34.3862152099609,,,1,,,,,,,,,,,,,,,,,,,,,,300.044097900391,300.069610595703,-120.006507873535,-120.006507873535,,,8.66326999664307,,1,0,0,0,0,32.7468223571777,1,1,1,300.044097900391,0,2084574944,300.060375976562,,,-0.000749101181266666,3.74123110813894E-5,-0.000749190828717154,3.74123956179961E-5,0.948039531707764,0.950344383716583,34.4440269470215,0,35,4,200,0.179293841123581,-0.46027410030365,3.6445255279541,1,,,,,,,,,,,,,,,,
,3889708329.79644,300.138412475586,-170.055053710938,,,6,,,,34.3862152099609,,,1,,,,,,,,,,,,,,,,,,,,,,300.113220214844,300.163818359375,-170.055053710938,-170.055053710938,,,8.64249420166016,,1,0,0,0,0.013885498046875,31.7693061828613,1,1,1,300.113006591797,0,2084575040,300.139526367188,,,-0.000985087779963671,4.92036719449883E-5,-0.000985195150908719,4.92037427116792E-5,0.945940494537353,0.947962164878845,34.441535949707,0,35,4,200,0.180418446660042,-0.423398852348328,4.82964563369751,1,,,,,,,,,,,,,,,,
,3889708452.86156,300.091369628906,-220.128036499023,,,6,,,,34.3862152099609,,,10,,,,,,,,,,,,,,,,,,,,,,300.071533203125,300.117858886719,-220.128036499023,-220.128036499023,,,8.64572715759277,,1,0,0,0,0.013885498046875,32.7468223571777,1,1,1,300.119598388672,0,2084575008,300.101233588325,,,-0.00122360296549576,6.1111540992058E-5,-0.00122371472773474,6.11115504511897E-5,0.947659254074097,0.949426531791687,34.4371490478516,0,35,4,200,0.0199258551001549,-0.145621061325073,0.490470200777054,1,,,,,,,,,,,,,,,,
,3889708565.98413,300.136352539063,-270.091033935547,,,6,,,,34.3862152099609,,,10,,,,,,,,,,,,,,,,,,,,,,300.114074707031,300.157531738281,-270.091033935547,-270.091033935547,,,8.63136100769043,,1,0,0,0,0.013885498046875,32.2580642700195,1,1,1,300.158630371094,0,2084575136,300.144232177734,,,-0.00145425185102105,7.26312683902585E-5,-0.0014543921416073,7.26313153461659E-5,0.947599649429321,0.94945627450943,34.438419342041,0,35,4,200,0.0204409025609493,-0.142287150025368,0.603316605091095,1,,,,,,,,,,,,,,,,
,3889708679.56015,300.194854736328,-320.164001464844,,,6,,,,34.3862152099609,,,10,,,,,,,,,,,,,,,,,,,,,,300.179626464844,300.210693359375,-320.164001464844,-320.164001464844,,,8.6419095993042,,1,0,0,0,0.0139617919921875,32.2580642700195,1,1,1,300.179016113281,0,2084574944,300.199530029297,,,-0.00168410750277205,8.41093532319224E-5,-0.00168427255579665,8.41094060102718E-5,0.948020935058594,0.949924230575561,34.4388465881348,5.86846208572388,35,4,200,0.0197314638644457,-0.143607020378113,0.720156192779541,1,,,,,,,,,,,,,,,,
,3889708793.02964,300.004745483398,-370.139251708984,,,6,,,,34.3862152099609,,,10,,,,,,,,,,,,,,,,,,,,,,299.975494384766,300.031768798828,-370.139251708984,-370.139251708984,,,8.65233421325684,,1,0,0,0,0.0139617919921875,32.2580642700195,1,1,1,300.033996582031,0,2084574944,300.010678100586,,,-0.00190941049876188,9.53606385190699E-5,-0.00190956464027632,9.53608512406542E-5,0.948223292827606,0.949758112430573,34.4334487915039,0,35,4,200,0.0178520083427429,-0.190949335694313,0.787122488021851,1,,,,,,,,,,,,,,,,
,3889708912.55529,300.28581237793,-419.992218017578,,,6,,,,34.3862152099609,,,10,,,,,,,,,,,,,,,,,,,,,,300.271057128906,300.307647705078,-419.992218017578,-419.992218017578,,,8.65703964233398,,1,0,0,0,0.013885498046875,33.7243423461914,1,1,1,300.300567626953,0,2084574912,300.297424316406,,,-0.00213032646876096,0.00010639101242039,-0.00213050966689181,0.000106391111500738,0.948722898960114,0.950405120849609,34.4353904724121,0,35,4,200,0.0150709990411997,-0.198763728141785,0.901362299919128,1,,,,,,,,,,,,,,,,
,3889709027.60356,300.159286499023,-469.942993164063,,,6,,,,34.3862152099609,,,10,,,,,,,,,,,,,,,,,,,,,,300.145965576172,300.17333984375,-469.942993164063,-469.942993164063,,,8.64768505096436,,1,0,0,0,0.013885498046875,32.2580642700195,1,1,1,300.145812988281,0,2084575008,300.164263916016,,,-0.00235044544993282,0.000117390975920508,-0.00235068240856812,0.000117391235161783,0.947576761245727,0.949487447738647,34.439151763916,0.191438838839531,35,4,200,0.0170453693717718,-0.218171432614326,0.982827186584473,1,,,,,,,,,,,,,,,,
,3889709140.77282,300.123641967773,-519.979309082031,,,6,,,,34.3862152099609,,,10,,,,,,,,,,,,,,,,,,,,,,300.122528076172,300.136169433594,-519.979309082031,-519.979309082031,,,8.63788986206055,,1,0,0,0,0.013885498046875,31.7693061828613,1,1,1,300.123352050781,0,2084575008,300.128698730469,,,-0.00256430362340146,0.000128073299245199,-0.00256456552252657,0.000128073408562935,0.947375297546387,0.949330985546112,34.4398651123047,,35,4,200,0.0180820673704147,-0.232745811343193,1.07161629199982,1,,,,,,,,,,,,,,,,
,3889709255.51305,300.147308349609,-570.040100097656,,,6,,,,34.3862152099609,,,10,,,,,,,,,,,,,,,,,,,,,,300.122833251953,300.171936035156,-570.040100097656,-570.040100097656,,,8.63228607177734,,1,0,0,0,0.013885498046875,32.2580642700195,1,1,1,300.122680664063,0,2084574944,300.149221801758,,,-0.00277648511476237,0.00013866712008988,-0.00277672788314624,0.000138667334614325,0.947855174541473,0.949524641036987,34.4356346130371,,35,4,200,0.0194201227277517,-0.210759714245796,1.18983149528503,1,,,,,,,,,,,,,,,,
,3889709373.77324,299.985794067383,-620.039733886719,,,6,,,,34.3862152099609,,,10,,,,,,,,,,,,,,,,,,,,,,299.965545654297,300.005981445313,-620.039733886719,-620.039733886719,,,8.63265800476074,,1,0,0,0,0.0139617919921875,32.2580642700195,1,1,1,299.965606689453,0,2084574944,299.982049239309,,,-0.00292323913269426,0.000145998742648892,-0.00292344736084035,0.000145998936624914,0.947565972805023,0.948912799358368,34.4307632446289,,35,4,200,-0.0160065591335297,-0.941443145275116,1.09077537059784,1,,,,,,,,,,,,,,,,
,3889709491.85396,300.155288696289,-670.100463867187,,,6,,,,34.3862152099609,,,10,,,,,,,,,,,,,,,,,,,,,,300.129119873047,300.179748535156,-670.100463867187,-670.100463867187,,,8.63584327697754,,1,0,0,0,0.0006866455078125,32.2580642700195,1,1,1,300.181457519531,0,2084574976,300.163781738281,,,-0.0031801539976622,0.000158834299885423,-0.00318049865678413,0.000158834518797946,0.947079181671143,0.949135482311249,34.4413642883301,0.171612933278084,35,4,200,0.0232026856392622,-0.299972385168076,1.29426383972168,1,,,,,,,,,,,,,,,,
,3889709605.13342,300.157516479492,-720.100158691406,,,6,,,,34.3862152099609,,,10,,,,,,,,,,,,,,,,,,,,,,300.137512207031,300.175689697266,-720.100158691406,-720.100158691406,,,8.6399621963501,,1,0,0,0,0.013885498046875,32.2580642700195,1,1,1,300.177520751953,0,2084575072,300.163656616211,,,-0.00337569621212929,0.000168603482371368,-0.00337606253620041,0.000168604023838871,0.946766257286072,0.94877690076828,34.4409294128418,0.177757039666176,35,4,200,0.0265213195234537,-0.326678842306137,1.44977700710297,1,,,,,,,,,,,,,,,,
,3889709720.80085,300.105682373047,-770.111999511719,,,6,,,,34.3862152099609,,,10,,,,,,,,,,,,,,,,,,,,,,300.087585449219,300.123779296875,-770.111999511719,-770.111999511719,,,8.64749622344971,,1,0,0,0,0.013885498046875,32.2580642700195,1,1,1,300.123779296875,0,2084575168,300.113824462891,,,-0.00356372211832393,0.000177972820949445,-0.00356401183883987,0.000177973290836124,0.94911527633667,0.950681209564209,34.4335021972656,0.191405177116394,35,4,200,0.0253355912864208,-0.335181295871735,1.45715665817261,1,,,,,,,,,,,,,,,,
,3889709845.11065,300.097793579102,-1499.69641113281,,,6,,,,34.3862152099609,,,10,,,,,,,,,,,,,,,,,,,,,,300.084167480469,300.112030029297,-1499.69641113281,-1499.69641113281,,,8.65529632568359,,1,0,0,0,0.013885498046875,32.2580642700195,1,1,1,300.083557128906,0,2084574912,300.102767944336,,,-0.00575843964962712,0.000287599809258157,-0.00575892111360705,0.000287600585335074,0.947616875171661,0.949180662631988,34.4341430664063,0,35,4,200,0.00964322406798601,-0.563816606998444,2.34051489830017,1,,,,,,,,,,,,,,,,
,3889709960.31914,300.203491210937,-4000.43676757812,,,6,,,,34.3862152099609,,,10,,,,,,,,,,,,,,,,,,,,,,300.200378417969,300.21630859375,-4000.43676757812,-4000.43676757812,,,8.63933086395264,,1,0,0,0,0.013885498046875,32.2580642700195,1,1,1,300.206604003906,0,2084574912,300.209625244141,,,-0.00859604052238781,0.00042935908458784,-0.00859680765835619,0.000429359845615181,0.945958018302918,0.947596788406372,34.4360237121582,0,35,4,200,-0.0017080798279494,-0.84079509973526,3.38784050941467,1,,,,,,,,,,,,,,,,
,3889710077.23434,300.050277709961,-6500.2607421875,,,6,,,,34.3862152099609,,,10,,,,,,,,,,,,,,,,,,,,,,300.033660888672,300.067169189453,-6500.2607421875,-6500.2607421875,,,8.63624477386475,,1,0,0,0,0.013885498046875,32.7468223571777,1,1,1,300.033386230469,0,2084575040,300.051965332031,,,-0.00938487362590852,0.000468801578451816,-0.00938578111140754,0.000468801960554484,0.944344341754913,0.946089208126068,34.4383430480957,0,35,4,200,-0.00887314602732658,-1.00434112548828,3.65575623512268,1,,,,,,,,,,,,,,,,
,3889710193.91244,300.137969970703,-9000.3662109375,,,6,,,,34.3862152099609,,,10,,,,,,,,,,,,,,,,,,,,,,300.122741699219,300.153717041016,-9000.3662109375,-9000.3662109375,,,8.62161159515381,,1,0,0,0,0.0139617919921875,32.2580642700195,1,1,1,300.153198242188,0,2084575008,300.145169067383,,,-0.00973212018565287,0.000486201888397936,-0.00973326609268131,0.000486202467031588,0.942377984523773,0.944430649280548,34.443660736084,0.191391661763191,35,4,200,-0.0120373871177435,-1.00285530090332,3.84690523147583,1,,,,,,,,,,,,,,,,
,3889710343.94861,300.123199462891,-25000.35546875,,,6,,,,34.3862152099609,,,10,,,,,,,,,,,,,,,,,,,,,,300.106689453125,300.142364501953,-25000.35546875,-25000.35546875,,,8.63045120239258,,1,0,0,0,0.013885498046875,32.7468223571777,1,1,1,300.139709472656,0,2084574656,300.132080078125,,,-0.010275980643479,0.000513795891295831,-0.0102784754013565,0.00051379935327132,0.929552018642426,0.932969212532044,34.4677200317383,5.21816301345825,35,4,200,-0.0176229272037745,-1.28979122638702,3.9876070022583,1,,,,,,,,,,,,,,,,
,3889710495.88302,300.005187988281,-50000.37890625,,,6,,,,34.3862152099609,,,10,,,,,,,,,,,,,,,,,,,,,,299.998046875,300.014892578125,-50000.37890625,-50000.37890625,,,8.61501121520996,,1,0,0,0,0.013885498046875,32.7468223571777,1,1,1,299.999053955078,0,2084574848,300.008361816406,,,-0.0103548993533967,0.000518736581596479,-0.0103607049573232,0.00051874002812075,0.906322658061981,0.912382483482361,34.5104827880859,5.71575110370759E-5,35,4,200,-0.0122846532613039,-1.38907694816589,3.92670750617981,1,,,,,,,,,,,,,,,,
,3889710615.21241,299.999420166016,-70000.453125,,,6,,,,34.3862152099609,,,10,,,,,,,,,,,,,,,,,,,,,,299.994323730469,300.009338378906,-70000.453125,-70000.453125,,,8.60271739959717,,1,0,0,0,0.013885498046875,32.7468223571777,1,1,1,300.004516601562,0,2084574816,300.004040527344,,,-0.0103220065443612,0.000518189618692266,-0.010332190186251,0.000518197384319419,0.886058151721954,0.894815146923065,34.5501136779785,0,35,4,200,-0.0316783636808395,-1.58124923706055,3.85548496246338,1,,,,,,,,,,,,,,,,