File: Data/KMK254/ZFCFC/KMK254_ZFCFC.dat
[Header]
; MPMS3 Data File (default extension .dat)
; Copyright (c) 2007, Quantum Design, Inc. All rights reserved.
TITLE,
FILEOPENTIME,3844657476.06856,10/29/2021,8:24 am
BYAPP,MPMS3 w/ AC,1.0,1.1
INFO,MPMS3 Measurement Release 1.1.16 Build 424, MultiVu Release 2.3.4.19,APPNAME
INFO,Linear Motor Servo Controller,MOTOR_MODULE_NAME
INFO,3101-100 J0,MOTOR_HW_VERSION
INFO,MMC721,MOTOR_SERIAL_NUMBER
INFO,01.04.28,MOTOR_SOFTWARE_VERSION
INFO,Quantum Design Squid Module,SQUID_MODULE_NAME
INFO,3101-501 B0,SQUID_HW_VERSION
INFO,SQM195,SQUID_SERIAL_NUMBER
INFO,01.03.04,SQUID_SOFTWARE_VERSION
INFO,SQUID AC,AC_MODULE_NAME
INFO,3101-401 f1,AC_HW_VERSION
INFO,SAC107,AC_SERIAL_NUMBER
INFO,SQUID AC 00.95.07,AC_SOFTWARE_VERSION
INFO,TCI166,COIL_SERIAL_NUMBER
INFO,0,MOMENT_UNITS
INFO,KMK254,SAMPLE_MATERIAL
INFO,,SAMPLE_COMMENT
INFO,1,SAMPLE_MASS
INFO,,SAMPLE_VOLUME
INFO,,SAMPLE_MOLECULAR_WEIGHT
INFO,,SAMPLE_SIZE
INFO,,SAMPLE_SHAPE
INFO,Straw,SAMPLE_HOLDER
INFO,Standard,SAMPLE_HOLDER_DETAIL
INFO,64.48,SAMPLE_OFFSET
DATATYPE,COMMENT,1
DATATYPE,TIME,2
STARTUPAXIS,X,2
STARTUPAXIS,Y1,5
FIELDGROUP, VSM,2,3,4,5,6,8,9,10,11,14,15
FIELDGROUP, DC, 2,3,4,14,56,57,58,59,60,61,62,63,64,65,66,67,68,69
FIELDGROUP, AC, 2,3,4,11,16,17,18,19,20,21,22,23,24,25,26,27,28,29,30
STARTUPGROUP, All
[Data]
Comment,Time Stamp (sec),Temperature (K),Magnetic Field (Oe),Moment (emu),M. Std. Err. (emu),Transport Action,Averaging Time (sec),Frequency (Hz),Peak Amplitude (mm),Center Position (mm),Lockin Signal' (V),Lockin Signal (V),Range,M. Quad. Signal (emu),AC Moment (emu),AC M. Std Err. (emu),AC Phase (deg),AC Phase Std. Err. (deg),AC Susceptibility (emu/Oe),AC Suscept. Std Err. (emu/Oe),AC X' (emu/Oe),AC X' Std Err. (emu/Oe),AC X'' (emu/Oe),AC X'' Std Err. (emu/Oe),AC Drive (Oe),AC Frequency (Hz),AC Averaging Time (sec),AC Cycles,AC Range,AC Measure Type,AC Signal' (V),AC Signal'' (V),AC Trim Coil Ratio,AC Trim Coil Phase,Min. Temperature (K),Max. Temperature (K),Min. Field (Oe),Max. Field (Oe),Mass (grams),Motor Lag (deg),Pressure (Torr),Measure Count,Measurement Number,SQUID Status (code),Motor Status (code),Measure Status (code),Motor Current (amps),Motor Temp. (C),Temp. Status (code),Field Status (code),Chamber Status (code),Chamber Temp (K),Redirection State,Evercool Status,Average Temp (K),Rotation Angle (deg),Rotator state,DC Moment Fixed Ctr (emu),DC Moment Err Fixed Ctr (emu),DC Moment Free Ctr (emu),DC Moment Err Free Ctr (emu),DC Fixed Fit,DC Free Fit,DC Calculated Center (mm),DC Calculated Center Err (mm),DC Scan Length (mm),DC Scan Time (s),DC Number of Points,DC Squid Drift,DC Min V (V),DC Max V (V),DC Scans per Measure,Map 01,Map 02,Map 03,Map 04,Map 05,Map 06,Map 07,Map 08,Map 09,Map 10,Map 11,Map 12,Map 13,Map 14,Map 15,Map 16
,3844658433.87617,5.00318789482117,100.084869384766,,,6,,,,33.8420636829573,,,100,,,,,,,,,,,,,,,,,,,,,,4.99773359298706,5.00311708450317,100.084869384766,100.084869384766,,,3.95632839202881,,1,0,0,0,0.020904541015625,32.2580642700195,1,1,1,5.00325870513916,0,4232056832,5.00030565261841,,,0.00595481924292533,0.00029989877340949,0.00600621318606411,0.000299936157602002,0.861285150051117,0.95011705160141,33.3521728515625,,35,4,200,8.13561709946953E-5,-0.242331206798553,0.0635669305920601,1,,,,,,,,,,,,,,,,
,3844658501.34891,9.38858795166016,100.084869384766,,,6,,,,33.8420636829573,,,100,,,,,,,,,,,,,,,,,,,,,,9.00469207763672,9.74041366577148,100.084869384766,100.084869384766,,,4.81901502609253,,1,0,0,0,0.000152587890625,30.3030319213867,6,1,1,9.77248382568359,0,4232056832,9.37749099731445,,,0.00621770921355129,0.000313127109241402,0.00627126731214986,0.000313173248085482,0.861542284488678,0.95005589723587,33.3532676696777,0,35,4,200,0.000111029366962612,-0.251873224973679,0.0570162758231163,1,,,,,,,,,,,,,,,,
,3844658570.84356,14.8652091026306,100.084869384766,,,6,,,,33.847355880022,,,100,,,,,,,,,,,,,,,,,,,,,,14.4683141708374,15.2052621841431,100.084869384766,100.084869384766,,,5.7397780418396,,1,0,0,0,0.000152587890625,32.2580642700195,6,1,1,15.2621040344238,0,4232056832,14.8329973220825,,,0.00692908226685105,0.000348980173007961,0.00698902680673842,0.000349020604088921,0.860974907875061,0.949822008609772,33.3565483093262,INF,35,4,200,0.000170570740010589,-0.277926921844482,0.0672745183110237,1,,,,,,,,,,,,,,,,
,3844658631.9011,19.7937631607056,100.084869384766,,,6,,,,33.847355880022,,,100,,,,,,,,,,,,,,,,,,,,,,19.4113540649414,20.1449413299561,100.084869384766,100.084869384766,,,6.04298543930054,,1,0,0,0,0.000152587890625,32.2580642700195,2,1,1,20.1761722564697,0,4232056832,19.7885940551758,,,0.0079006948622395,0.00039783927395488,0.00796778796243369,0.000397897639750406,0.862326443195343,0.949862480163574,33.3619995117188,0.0376686044037342,35,4,200,0.000177059089764953,-0.321322560310364,0.0803686901926994,1,,,,,,,,,,,,,,,,
,3844658701.45793,25.3234634399414,100.084869384766,,,6,,,,33.852388230416,,,100,,,,,,,,,,,,,,,,,,,,,,24.9402809143066,25.6740665435791,100.084869384766,100.084869384766,,,6.23842477798462,,1,0,0,0,0.000152587890625,32.2580642700195,2,1,1,25.7066459655762,0,4232056832,25.3111148834229,,,0.00872341185142457,0.000439237473408392,0.00879711671570968,0.000439311204248219,0.862808048725128,0.949936270713806,33.3688545227051,5.30038487340789E-5,35,4,200,0.000152673150296323,-0.351332038640976,0.0912309885025024,1,,,,,,,,,,,,,,,,
,3844658768.83136,30.7322559356689,100.084869384766,,,6,,,,33.85760532024,,,100,,,,,,,,,,,,,,,,,,,,,,30.3449363708496,31.0587329864502,100.084869384766,100.084869384766,,,6.42373037338257,,1,0,0,0,0.020751953125,32.2580642700195,2,1,1,31.1195755004883,0,4232056832,30.6972675323486,,,0.0094057770097462,0.000473554081334599,0.00948423063630869,0.000473624687023192,0.86343640089035,0.949920833110809,33.3767547607422,,35,4,200,0.000157722955918871,-0.377637952566147,0.0894627124071121,1,,,,,,,,,,,,,,,,
,3844658827.51476,35.4214515686035,100.084869384766,,,6,,,,33.85760532024,,,100,,,,,,,,,,,,,,,,,,,,,,35.0432662963867,35.7593154907227,100.084869384766,100.084869384766,,,6.4821252822876,,1,0,0,0,0.016937255859375,32.2580642700195,2,1,1,35.7996368408203,0,4232056832,35.4036449432373,,,0.0100110036376006,0.000503886002561545,0.0100913092624439,0.000503942196203414,0.865442156791687,0.949878811836243,33.3850250244141,5.18288278579712,35,4,200,0.000166460187756456,-0.408559709787369,0.0975774675607681,1,,,,,,,,,,,,,,,,
,3844658894.65116,40.8117618560791,100.084869384766,,,6,,,,33.8629422325937,,,100,,,,,,,,,,,,,,,,,,,,,,40.4105987548828,41.1895637512207,100.084869384766,100.084869384766,,,6.6081223487854,,1,0,0,0,0.013885498046875,32.2580642700195,2,1,1,41.2129249572754,0,4232056832,40.810595703125,,,0.0107596747870358,0.000541476047767919,0.0108442612800986,0.000541544376799385,0.866700887680054,0.949838221073151,33.3955688476562,0.000260731991147622,35,4,200,0.000178292932105251,-0.435409486293793,0.107678540050983,1,,,,,,,,,,,,,,,,
,3844658962.30156,46.2437133789063,100.084869384766,,,6,,,,33.8682930122232,,,100,,,,,,,,,,,,,,,,,,,,,,45.8492546081543,46.5693550109863,100.084869384766,100.084869384766,,,6.64672708511353,,1,0,0,0,0,32.2580642700195,2,1,1,46.6381721496582,0,4232057664,46.2183029174805,,,0.0115671442879251,0.000581981377858862,0.0116554427922874,0.000582054487935052,0.868360042572022,0.949801564216614,33.4078102111816,0,35,4,200,0.000191626560990699,-0.464349716901779,0.118566416203976,1,,,,,,,,,,,,,,,,
,3844659030.12834,51.7507076263428,100.084869384766,,,6,,,,33.8735550662126,,,100,,,,,,,,,,,,,,,,,,,,,,51.3534545898438,52.0880508422852,100.084869384766,100.084869384766,,,6.72598838806152,,1,0,0,0,0.019073486328125,32.2580642700195,2,1,1,52.1479606628418,0,4232058016,51.7082004547119,,,0.012394693377373,0.000623448492460618,0.0124857657476063,0.000623520623448932,0.870405852794647,0.949762463569641,33.4215507507324,0,35,4,200,0.000199772301129997,-0.495939761400223,0.118830487132072,1,,,,,,,,,,,,,,,,
,3844659097.51531,57.1866092681885,100.084869384766,,,6,,,,33.8792535792982,,,100,,,,,,,,,,,,,,,,,,,,,,56.8109397888184,57.5129013061523,100.084869384766,100.084869384766,,,6.75414085388184,,1,0,0,0,0.0205230712890625,31.7693061828613,2,1,1,57.5622787475586,0,4232057824,57.1635673522949,,,0.0131932134199414,0.000663420374114137,0.0132861931471723,0.000663495416187494,0.872638404369354,0.949687659740448,33.4367179870605,,35,4,200,0.000174495828105137,-0.533538162708282,0.129553839564323,1,,,,,,,,,,,,,,,,
,3844659165.1919,62.6727752685547,100.084869384766,,,6,,,,33.8846337635766,,,100,,,,,,,,,,,,,,,,,,,,,,62.2923965454102,63.0199661254883,100.084869384766,100.084869384766,,,6.81089735031128,,1,0,0,0,0.0194549560546875,32.2580642700195,2,1,1,63.0531539916992,0,4232057952,62.6489162445068,,,0.0139373174766089,0.000700593981708012,0.0140307387212418,0.000700678339243699,0.875356793403625,0.949658334255219,33.4533233642578,,35,4,200,0.000208564539207146,-0.560195505619049,0.139539897441864,1,,,,,,,,,,,,,,,,
,3844659242.36374,68.944580078125,100.084869384766,,,6,,,,33.8953358997656,,,100,,,,,,,,,,,,,,,,,,,,,,68.5586547851562,69.2974624633789,100.084869384766,100.084869384766,,,6.87204837799072,,1,0,0,0,0.0212860107421875,32.2580642700195,2,1,1,69.3305053710937,0,4232057824,68.9305679321289,,,0.0146863415674559,0.000738036930794732,0.0147799790498353,0.000738098377538418,0.877604961395264,0.949542284011841,33.4736137390137,0,35,4,200,0.000196654844330624,-0.587086260318756,0.149583697319031,1,,,,,,,,,,,,,,,,
,3844659310.09394,74.475887298584,100.084869384766,,,6,,,,33.9006495583482,,,100,,,,,,,,,,,,,,,,,,,,,,74.0654067993164,74.8561935424805,100.084869384766,100.084869384766,,,6.8663387298584,,1,0,0,0,0.0168609619140625,32.2580642700195,2,1,1,74.8863677978516,0,4232057824,74.4514862060547,,,0.0152495626434718,0.000766040879857718,0.0153409612091279,0.000766117934198157,0.880798578262329,0.949428081512451,33.4924507141113,5.19256162643433,35,4,200,0.000159876144607551,-0.60823655128479,0.146224290132523,1,,,,,,,,,,,,,,,,
,3844659386.83039,80.705078125,100.084869384766,,,6,,,,33.9121177072587,,,100,,,,,,,,,,,,,,,,,,,,,,80.3167724609375,81.0542449951172,100.084869384766,100.084869384766,,,6.92902278900146,,1,0,0,0,0.0159454345703125,32.2580642700195,2,1,1,81.0933837890625,0,4232057984,80.6829971313477,,,0.0157782223351637,0.000792363900546904,0.0158675772511821,0.000792422132832462,0.883256673812866,0.949285209178925,33.5145454406738,0,35,4,200,0.000189843281987123,-0.637018084526062,0.153270334005356,1,,,,,,,,,,,,,,,,
,3844659463.42262,86.9856262207031,100.084869384766,,,6,,,,33.9232938389548,,,100,,,,,,,,,,,,,,,,,,,,,,86.5824432373047,87.3384704589844,100.084869384766,100.084869384766,,,6.93810606002808,,1,0,0,0,0.017242431640625,31.7693061828613,2,1,1,87.3888092041016,0,4232057888,86.9577476501465,,,0.0162045385027978,0.000813516729303889,0.0162913776485513,0.000813591494121293,0.885954916477203,0.949178814888001,33.5373497009277,,35,4,200,0.000185325639904477,-0.652244389057159,0.158955186605454,1,,,,,,,,,,,,,,,,
,3844659540.37455,93.3456115722656,100.084869384766,,,6,,,,33.9339188674695,,,100,,,,,,,,,,,,,,,,,,,,,,92.9197845458984,93.6938247680664,100.084869384766,100.084869384766,,,6.94873285293579,,1,0,0,0,0.0186920166015625,31.7693061828613,2,1,1,93.7714385986328,0,4232057984,93.3147827148438,,,0.0165467868890266,0.000830420204477605,0.0166296922084425,0.000830492923836099,0.888894736766815,0.949036598205566,33.5608177185059,0,35,4,200,0.000180289702257141,-0.664399445056915,0.163493096828461,1,,,,,,,,,,,,,,,,
,3844659617.12141,99.7137260437012,100.084869384766,,,6,,,,33.9451443389699,,,100,,,,,,,,,,,,,,,,,,,,,,99.2985916137695,100.06812286377,100.084869384766,100.084869384766,,,7.00529623031616,,1,0,0,0,0.0002288818359375,31.7693061828613,2,1,1,100.128860473633,0,4232057920,99.6821044921875,,,0.0168193035496749,0.000843828737651797,0.0168978130319532,0.000843889012342363,0.891755282878876,0.948895990848541,33.5846366882324,0,35,4,200,0.000174628963577561,-0.674010574817657,0.167092174291611,1,,,,,,,,,,,,,,,,
,3844659694.12178,106.086479187012,100.084869384766,,,6,,,,33.9571554879377,,,100,,,,,,,,,,,,,,,,,,,,,,105.675392150879,106.455284118652,100.084869384766,100.084869384766,,,6.97732067108154,,1,0,0,0,0.000152587890625,32.2580642700195,2,1,1,106.497566223145,0,4232058016,106.069336700439,,,0.0170384475617427,0.000854564312314996,0.017112489219168,0.000854614665870761,0.894559562206268,0.948794066905975,33.6089286804199,0,35,4,200,0.000167424615938216,-0.681687355041504,0.169979184865952,1,,,,,,,,,,,,,,,,
,3844659770.98493,112.461963653564,100.084869384766,,,6,,,,33.969816170219,,,100,,,,,,,,,,,,,,,,,,,,,,112.052017211914,112.795967102051,100.084869384766,100.084869384766,,,7.00042057037353,,1,0,0,0,0.020599365234375,31.7693061828613,2,1,1,112.871910095215,0,4232057952,112.422470855713,,,0.0172175852548369,0.000863301466598997,0.0172873077616536,0.000863350770617627,0.897281527519226,0.948665380477905,33.633731842041,0,35,4,200,0.000128042403957807,-0.687990784645081,0.172330409288406,1,,,,,,,,,,,,,,,,
,3844659848.40319,118.867816925049,100.084869384766,,,6,,,,33.9825071807184,,,100,,,,,,,,,,,,,,,,,,,,,,118.464431762695,119.237762451172,100.084869384766,100.084869384766,,,7.06503438949585,,1,0,0,0,0.000152587890625,31.7693061828613,2,1,1,119.271202087402,0,4232058016,118.861190795898,,,0.0173698825630467,0.000870679624604445,0.0174346559491457,0.000870718823206929,0.900177955627441,0.94845712184906,33.659610748291,0,35,4,200,0.000164214681717567,-0.693379402160644,0.17429618537426,1,,,,,,,,,,,,,,,,
,3844659935.41066,126.101097106934,100.084869384766,,,6,,,,34.0008560640613,,,100,,,,,,,,,,,,,,,,,,,,,,125.700080871582,126.458930969238,100.084869384766,100.084869384766,,,7.05449056625366,,1,0,0,0,0.0002288818359375,32.2580642700195,2,1,1,126.502113342285,0,4232057920,126.074917602539,,,0.0175132022206556,0.000877647649856477,0.0175740041259861,0.000877689272424418,0.902652621269226,0.948217630386353,33.6895332336426,0,35,4,200,0.000134032321511768,-0.698462784290314,0.176189556717873,1,,,,,,,,,,,,,,,,
,3844660022.09292,133.278915405273,100.084869384766,,,6,,,,34.0202967401385,,,100,,,,,,,,,,,,,,,,,,,,,,132.88134765625,133.631134033203,100.084869384766,100.084869384766,,,7.07044363021851,,1,0,0,0,0.000152587890625,32.2580642700195,2,1,1,133.676483154297,0,4232058144,133.262802124023,,,0.0176331629524912,0.000883458116752723,0.0176902350599756,0.00088350251338254,0.904995679855347,0.948030412197113,33.7200164794922,5.20755577087402,35,4,200,0.00012933393009007,-0.702762007713318,0.177751243114471,1,,,,,,,,,,,,,,,,
,3844660108.82712,140.546020507812,100.084869384766,,,6,,,,34.040802079164,,,100,,,,,,,,,,,,,,,,,,,,,,140.204391479492,140.935241699219,100.084869384766,100.084869384766,,,7.093017578125,,1,0,0,0,0.0002288818359375,31.7693061828613,2,1,1,140.935241699219,0,4232058240,140.574913024902,,,0.0177293840131138,0.000888073941759824,0.0177827455480614,0.000888117340622268,0.90743750333786,0.948150932788849,33.7512245178223,0,35,4,200,0.00012859124399256,-0.706468760967255,0.17892099916935,1,,,,,,,,,,,,,,,,
,3844660195.40312,147.67960357666,100.084869384766,,,6,,,,34.0623668740868,,,100,,,,,,,,,,,,,,,,,,,,,,147.287261962891,148.054153442383,100.084869384766,100.084869384766,,,7.13527488708496,,1,0,0,0,0.000152587890625,32.2580642700195,2,1,1,148.07194519043,0,4232057952,147.670693969727,,,0.0178309203668581,0.000892998749907692,0.0178811513519461,0.000893051088619012,0.909391224384308,0.947740137577057,33.7828063964844,3.02246971841669E-5,35,4,200,0.000168472048244439,-0.709702551364899,0.180350795388222,1,,,,,,,,,,,,,,,,
,3844660300.10315,156.34447479248,100.084869384766,,,6,,,,34.0925668108526,,,100,,,,,,,,,,,,,,,,,,,,,,155.938110351562,156.700775146484,100.084869384766,100.084869384766,,,7.14847612380982,,1,0,0,0,0.000152587890625,32.2580642700195,2,1,1,156.750839233398,0,4232057984,156.317839050293,,,0.0179218943013105,0.000897377014947141,0.017968547878499,0.000897405801519328,0.911586463451385,0.947955846786499,33.8226776123047,0.191969335079193,35,4,200,0.000153244283865206,-0.712986052036285,0.181442096829414,1,,,,,,,,,,,,,,,,
,3844660413.5978,165.758354187012,100.084869384766,,,6,,,,34.1244044080527,,,100,,,,,,,,,,,,,,,,,,,,,,165.344955444336,166.121307373047,100.084869384766,100.084869384766,,,7.16062545776367,,1,0,0,0,0.000152587890625,32.2580642700195,2,1,1,166.171752929687,0,4232058048,165.734158325195,,,0.0180190057362902,0.000902047921057357,0.0180621039944673,0.000902084617041965,0.914005935192108,0.94782555103302,33.8663749694824,0.125895217061043,35,4,200,0.000161368458066136,-0.716393053531647,0.172000542283058,1,,,,,,,,,,,,,,,,
,3844660527.14217,175.18879699707,100.084869384766,,,6,,,,34.1579773574419,,,100,,,,,,,,,,,,,,,,,,,,,,174.782333374023,175.536285400391,100.084869384766,100.084869384766,,,7.18699216842651,,1,0,0,0,0.0002288818359375,32.2580642700195,2,1,1,175.595260620117,0,4232058016,175.158447265625,,,0.0181094691447291,0.000906402438961145,0.0181487995408804,0.000906425197494357,0.916249930858612,0.947594821453095,33.911376953125,0,35,4,200,0.000146501261042431,-0.719358801841736,0.173151731491089,1,,,,,,,,,,,,,,,,
,3844660640.27177,184.623115539551,100.084869384766,,,6,,,,34.1933751001914,,,100,,,,,,,,,,,,,,,,,,,,,,184.21875,184.970993041992,100.084869384766,100.084869384766,,,7.19186878204346,,1,0,0,0,0.000152587890625,31.7693061828613,2,1,1,185.027481079102,0,4232057856,184.591784667969,,,0.0181898026651619,0.000910277764769587,0.0182259335299853,0.00091029506650989,0.918171525001526,0.947237908840179,33.9573097229004,0.191851958632469,35,4,200,0.000148654391523451,-0.722253799438477,0.174326658248901,1,,,,,,,,,,,,,,,,
,3844660753.95103,194.045616149902,100.084869384766,,,6,,,,34.2307943360252,,,100,,,,,,,,,,,,,,,,,,,,,,193.632781982422,194.394836425781,100.084869384766,100.084869384766,,,7.19885492324829,,1,0,0,0,0.000152587890625,32.7468223571777,2,1,1,194.458450317383,0,4232058208,194.018145751953,,,0.0182453525657308,0.00091291454239393,0.0182785735975758,0.000912932708339017,0.920092523097992,0.947054147720337,34.0049514770508,0,35,4,200,0.000109218715806492,-0.724134206771851,0.175045773386955,1,,,,,,,,,,,,,,,,
,3844660867.33089,203.42333984375,100.084869384766,,,6,,,,34.2701247638778,,,100,,,,,,,,,,,,,,,,,,,,,,203.016296386719,203.791366577148,100.084869384766,100.084869384766,,,7.21095848083496,,1,0,0,0,0.013885498046875,31.7693061828613,2,1,1,203.830383300781,0,4232058080,203.405917358398,,,0.0182780681342516,0.00091442289392507,0.0183085029203282,0.000914438824097231,0.921863794326782,0.946826756000519,34.0540618896484,0.191819787025452,35,4,200,0.000117519732157234,-0.725287854671478,0.175513297319412,1,,,,,,,,,,,,,,,,
,3844660979.4897,212.75666809082,100.084869384766,,,6,,,,34.3107351105957,,,100,,,,,,,,,,,,,,,,,,,,,,212.355926513672,213.133056640625,100.084869384766,100.084869384766,,,7.23011922836304,,1,0,0,0,0.0165557861328125,32.2580642700195,2,1,1,213.157409667969,0,4232058080,212.746772766113,,,0.0182731998611245,0.000914061040761309,0.0183010562897545,0.000914074893782817,0.923528492450714,0.946663796901703,34.1040229797363,2.4906099497457E-5,35,4,200,0.000121684213809203,-0.724968135356903,0.175371006131172,1,,,,,,,,,,,,,,,,
,3844661091.2634,222.034294128418,100.084869384766,,,6,,,,34.3529753293946,,,100,,,,,,,,,,,,,,,,,,,,,,221.623352050781,222.39111328125,100.084869384766,100.084869384766,,,7.24343252182007,,1,0,0,0,0.0196075439453125,32.2580642700195,2,1,1,222.445236206055,0,4232058176,222.000997924805,,,0.0182310187478685,0.000911839354321895,0.0182564694975627,0.000911853494748373,0.925137877464294,0.946549594402313,34.1552238464355,0,35,4,200,0.000139188457978889,-0.723313271999359,0.174724251031876,1,,,,,,,,,,,,,,,,
,3844661203.54291,231.352767944336,100.084869384766,,,6,,,,34.3971940265043,,,100,,,,,,,,,,,,,,,,,,,,,,230.939651489258,231.730575561523,100.084869384766,100.084869384766,,,7.28006458282471,,1,0,0,0,0.02044677734375,32.2580642700195,2,1,1,231.765884399414,0,4232057888,231.339265441895,,,0.0181500712275087,0.000907690404532853,0.018173315336683,0.000907708146707994,0.926622569561005,0.946389734745026,34.2082214355469,0.0401510521769524,35,4,200,0.000143651501275599,-0.720478355884552,0.173656582832336,1,,,,,,,,,,,,,,,,
,3844661316.52421,240.728446960449,100.084869384766,,,6,,,,34.4436183954422,,,100,,,,,,,,,,,,,,,,,,,,,,240.333053588867,241.107330322266,100.084869384766,100.084869384766,,,7.30596351623535,,1,0,0,0,0.013885498046875,32.2580642700195,2,1,1,241.123840332031,0,4232058112,240.709394836426,,,0.0180381579213128,0.000902002150521117,0.0180591667199074,0.000902017413130227,0.928006649017334,0.946165680885315,34.2633056640625,0,35,4,200,0.000132762434077449,-0.71643054485321,0.172163367271423,1,,,,,,,,,,,,,,,,
,3844661426.51222,249.831031799316,100.084869384766,,,6,,,,34.4904518551773,,,100,,,,,,,,,,,,,,,,,,,,,,249.443252563477,250.200561523438,100.084869384766,100.084869384766,,,7.36713695526123,,1,0,0,0,0.018463134765625,35.190616607666,2,1,1,250.218811035156,0,4232058144,249.821562194824,,,0.0178954892289332,0.000894772520573397,0.0179142846065992,0.000894784049813689,0.929496765136719,0.946100354194641,34.3190498352051,0,35,4,200,8.97770223673433E-5,-0.711276113986969,0.170253530144691,1,,,,,,,,,,,,,,,,
,3844661537.86887,259.082870483398,100.084869384766,,,6,,,,34.5398782155778,,,100,,,,,,,,,,,,,,,,,,,,,,258.685028076172,259.434387207031,100.084869384766,100.084869384766,,,7.34858655929565,,1,0,0,0,0.0147247314453125,32.7468223571777,2,1,1,259.480712890625,0,4232058304,259.067166137695,,,0.0177282781276676,0.00088631690170979,0.0177447888959222,0.000886325072613607,0.931025624275208,0.945951879024506,34.3782844543457,0,35,4,200,9.74138747551478E-5,-0.705349922180176,0.167986556887627,1,,,,,,,,,,,,,,,,
,3844661649.1808,268.322372436523,100.084869384766,,,6,,,,34.5907441379383,,,100,,,,,,,,,,,,,,,,,,,,,,267.931274414062,268.671142578125,100.084869384766,100.084869384766,,,7.34643936157227,,1,0,0,0,0.013885498046875,31.7693061828613,2,1,1,268.713470458984,0,4232058112,268.295452880859,,,0.017540841357197,0.000876825753603924,0.0175546183605232,0.000876830230533318,0.933033049106598,0.945867419242859,34.4420356750488,,35,4,200,8.6991349235177E-5,-0.698735296726227,0.17603000998497,1,,,,,,,,,,,,,,,,
,3844661759.8991,277.497924804687,100.084869384766,,,6,,,,34.6432571412754,,,100,,,,,,,,,,,,,,,,,,,,,,277.099060058594,277.853271484375,100.084869384766,100.084869384766,,,7.34118461608887,,1,0,0,0,0.013885498046875,32.2580642700195,2,1,1,277.896789550781,0,4232058240,277.473638916016,,,0.0173383289895599,0.000866532941485523,0.0173484412028698,0.000866535365857582,0.93601655960083,0.945801854133606,34.5150489807129,0.12507638335228,35,4,200,0.000126854705740698,-0.691452920436859,0.173240959644318,1,,,,,,,,,,,,,,,,
,3844661871.042,286.700881958008,100.084869384766,,,6,,,,34.6975968287102,,,100,,,,,,,,,,,,,,,,,,,,,,286.275054931641,287.0771484375,100.084869384766,100.084869384766,,,7.40406799316406,,1,0,0,0,0.013885498046875,31.7693061828613,2,1,1,287.126708984375,0,4232058144,286.688488769531,,,0.0171174429714928,0.000855270584414718,0.0171231194395836,0.000855269563677119,0.94021087884903,0.946042776107788,34.6004905700684,0,35,4,200,0.00012591783888638,-0.683441579341888,0.170208767056465,1,,,,,,,,,,,,,,,,
,3844661981.81142,295.892730712891,100.084869384766,,,6,,,,34.753775912043,,,100,,,,,,,,,,,,,,,,,,,,,,295.493438720703,296.257537841797,100.084869384766,100.084869384766,,,7.52123117446899,,1,0,0,0,0.013885498046875,32.7468223571777,2,1,1,296.292022705078,0,4232057888,295.875827026367,,,0.0168771772906688,0.00084305485257812,0.0168791294191378,0.000843052125526666,0.944535851478577,0.946716010570526,34.6957130432129,0,35,4,200,0.000122725788969547,-0.674473404884338,0.166852056980133,1,,,,,,,,,,,,,,,,
,3844662057.72871,299.721710205078,100.084869384766,,,6,,,,34.7728183067983,,,100,,,,,,,,,,,,,,,,,,,,,,299.682525634766,299.757873535156,100.084869384766,100.084869384766,,,7.63780355453491,,1,0,0,0,0.013885498046875,32.2580642700195,5,1,1,299.760894775391,0,4232058016,299.724420166016,,,0.0167655934731548,0.000837418009051251,0.0167667194327146,0.000837417538978148,0.945903539657593,0.947166502475738,34.7289924621582,0,35,4,200,0.000127322957268916,-0.670218288898468,0.165324747562408,1,,,,,,,,,,,,,,,,
,3844663019.77069,5.00287365913391,100.084869384766,,,6,,,,33.8418099216239,,,100,,,,,,,,,,,,,,,,,,,,,,4.99796104431152,5.002760887146,100.084869384766,100.084869384766,,,3.94587230682373,,1,0,0,0,0.0177001953125,32.2580642700195,1,1,1,5.0030312538147,0,4232056832,5.00025587081909,,,0.0170719078032899,0.000860096433092135,0.0172272400526723,0.000860229424445096,0.85871833562851,0.951484680175781,33.3391914367676,5.2608382247854E-5,35,4,200,0.000151002022903413,-0.684647142887116,0.171280756592751,1,,,,,,,,,,,,,,,,
,3844663085.90055,9.28491973876953,100.084869384766,,,6,,,,33.8418099216239,,,100,,,,,,,,,,,,,,,,,,,,,,8.92364406585693,9.61172389984131,100.084869384766,100.084869384766,,,4.79256820678711,,1,0,0,0,0.0147247314453125,31.7693061828613,6,1,1,9.64619541168213,0,4232056832,9.2743236541748,,,0.0170752730057902,0.000860238971726507,0.0172305844910274,0.000860402656389771,0.858937680721283,0.95134025812149,33.3404273986816,INF,35,4,200,0.000163550401339307,-0.68491268157959,0.171293184161186,1,,,,,,,,,,,,,,,,
,3844663153.28647,14.566107749939,100.084869384766,,,6,,,,33.8468141051428,,,100,,,,,,,,,,,,,,,,,,,,,,14.1642017364502,14.9150485992432,100.084869384766,100.084869384766,,,5.70066022872925,,1,0,0,0,0.02105712890625,31.7693061828613,6,1,1,14.9680137634277,0,4232056832,14.5420166015625,,,0.0170775520113187,0.000860418854402518,0.0172340010050147,0.000860574381825761,0.858412861824036,0.951312303543091,33.3433570861816,,35,4,200,0.000158677663421258,-0.685059905052185,0.171369880437851,1,,,,,,,,,,,,,,,,
,3844663213.23615,19.4098777770996,100.084869384766,,,6,,,,33.8468141051428,,,100,,,,,,,,,,,,,,,,,,,,,,19.0260944366455,19.7586345672607,100.084869384766,100.084869384766,,,5.96137523651123,,1,0,0,0,0.000152587890625,32.2580642700195,2,1,1,19.7936611175537,0,4232056832,19.3951349258423,,,0.0170855434109565,0.000860678968412453,0.0172388341671297,0.000860816629681393,0.859564602375031,0.951293528079987,33.3479347229004,0,35,4,200,0.000159920236910693,-0.685302197933197,0.171388193964958,1,,,,,,,,,,,,,,,,
,3844663281.82848,24.8735828399658,100.084869384766,,,6,,,,33.8519904234154,,,100,,,,,,,,,,,,,,,,,,,,,,24.4930629730225,25.2255096435547,100.084869384766,100.084869384766,,,6.1943507194519,,1,0,0,0,0.0002288818359375,32.2580642700195,2,1,1,25.2541027069092,0,4232056832,24.8466274261475,,,0.0170955848444279,0.00086114118851556,0.0172481490764963,0.000861284973489162,0.859917521476746,0.951214075088501,33.3549003601074,0,35,4,200,0.000174807253642939,-0.685771346092224,0.171401247382164,1,,,,,,,,,,,,,,,,
,3844663340.83256,29.5912170410156,100.084869384766,,,6,,,,33.8519904234154,,,100,,,,,,,,,,,,,,,,,,,,,,29.1933422088623,29.9537982940674,100.084869384766,100.084869384766,,,6.3002610206604,,1,0,0,0,0.019989013671875,32.2580642700195,2,1,1,29.9890918731689,0,4232056832,29.5788951873779,,,0.0171121179186157,0.000861738341259172,0.0172598712641639,0.000861872249034673,0.861844956874847,0.951168656349182,33.3626098632812,0.19305619597435,35,4,200,0.000156319452798925,-0.686357080936432,0.171438634395599,1,,,,,,,,,,,,,,,,
,3844663408.71876,35.0427360534668,100.084869384766,,,6,,,,33.8574593997646,,,100,,,,,,,,,,,,,,,,,,,,,,34.673469543457,35.3598403930664,100.084869384766,100.084869384766,,,6.44269466400146,,1,0,0,0,0.013885498046875,31.7693061828613,2,1,1,35.4120025634766,0,4232056832,35.0034069061279,,,0.0171298143262018,0.00086248410629568,0.017274537150075,0.000862608253219509,0.863048017024994,0.951084196567535,33.3731689453125,0.120054751634598,35,4,200,0.000159242961672135,-0.687041521072388,0.171561196446419,1,,,,,,,,,,,,,,,,
,3844663476.13297,40.4438190460205,100.084869384766,,,6,,,,33.8626962751184,,,100,,,,,,,,,,,,,,,,,,,,,,40.0660057067871,40.771728515625,100.084869384766,100.084869384766,,,6.51303052902222,,1,0,0,0,0.013885498046875,32.2580642700195,2,1,1,40.8216323852539,0,4232056832,40.4114093780518,,,0.0171501590241377,0.000863315039230389,0.0172909799247759,0.000863432089869067,0.864661633968353,0.951015293598175,33.3850593566895,0,35,4,200,0.000160015624715015,-0.687725245952606,0.17170438170433,1,,,,,,,,,,,,,,,,
,3844663543.47745,45.8431701660156,100.084869384766,,,6,,,,33.8679964161796,,,100,,,,,,,,,,,,,,,,,,,,,,45.449291229248,46.1873054504395,100.084869384766,100.084869384766,,,6.59353351593018,,1,0,0,0,0.013885498046875,32.2580642700195,2,1,1,46.2370491027832,0,4232056832,45.8217273712158,,,0.0171720913258855,0.00086419022200041,0.0173083266080479,0.000864302124698426,0.866596937179565,0.950926065444946,33.3984375,5.18367004394531,35,4,200,0.000159547373186797,-0.688485085964203,0.171899631619453,1,,,,,,,,,,,,,,,,
,3844663610.70094,51.2777366638184,100.084869384766,,,6,,,,33.8731770990865,,,100,,,,,,,,,,,,,,,,,,,,,,50.8855857849121,51.6352996826172,100.084869384766,100.084869384766,,,6.67110586166382,,1,0,0,0,0.013885498046875,31.7693061828613,2,1,1,51.6698875427246,0,4232057504,51.262419128418,,,0.0171958996151385,0.000865129325352221,0.0173269601354805,0.00086523652930526,0.868822574615479,0.950839579105377,33.412914276123,,35,4,200,0.000158566486788914,-0.689239799976349,0.17213249206543,1,,,,,,,,,,,,,,,,
,3844663678.26752,56.7648754119873,100.084869384766,,,6,,,,33.8788561629119,,,100,,,,,,,,,,,,,,,,,,,,,,56.4096221923828,57.0387153625488,100.084869384766,100.084869384766,,,6.71236610412598,,1,0,0,0,0.018463134765625,31.7693061828613,2,1,1,57.1362915039063,0,4232057728,56.7375636630588,,,0.0172218360876641,0.000866164441291599,0.0173472759512302,0.000866254180280037,0.871176302433014,0.950762689113617,33.4283447265625,,35,4,200,0.000119095064292196,-0.690046429634094,0.172403812408447,1,,,,,,,,,,,,,,,,
,3844663745.92958,62.2387008666992,100.084869384766,,,6,,,,33.8841263436835,,,100,,,,,,,,,,,,,,,,,,,,,,61.8625373840332,62.5818595886231,100.084869384766,100.084869384766,,,6.78237962722778,,1,0,0,0,0.0193023681640625,32.7468223571777,2,1,1,62.6148643493652,0,4232057632,62.2152481079102,,,0.0172484378807504,0.000867203002040035,0.0173686310650999,0.000867323253108414,0.873840630054474,0.950703084468842,33.4447402954102,0,35,4,200,0.000160733427037485,-0.690842747688294,0.172690823674202,1,,,,,,,,,,,,,,,,
,3844663813.62273,67.7336349487305,100.084869384766,,,6,,,,33.8899194361713,,,100,,,,,,,,,,,,,,,,,,,,,,67.3595886230469,68.0963973999023,100.084869384766,100.084869384766,,,6.79070234298706,,1,0,0,0,0.0164794921875,32.2580642700195,2,1,1,68.1076812744141,0,4232057856,67.7327751159668,,,0.0172789171573601,0.000868429815011723,0.0173931676097024,0.000868552067772903,0.87661612033844,0.950619220733643,33.4620704650879,0,35,4,200,0.000120591474114917,-0.691712439060211,0.173056975007057,1,,,,,,,,,,,,,,,,
,3844663890.50261,73.9752807617187,100.084869384766,,,6,,,,33.901404815198,,,100,,,,,,,,,,,,,,,,,,,,,,73.5636825561523,74.3462829589844,100.084869384766,100.084869384766,,,6.85042381286621,,1,0,0,0,0.0139617919921875,32.2580642700195,2,1,1,74.3868789672852,0,4232057824,73.950008392334,,,0.0173139803162211,0.000869962163009021,0.0174237119404258,0.000870080976032035,0.878741323947906,0.950528144836426,33.4826011657715,4.14116439060308E-5,35,4,200,0.000127053310279734,-0.692816913127899,0.17352893948555,1,,,,,,,,,,,,,,,,
,3844663958.002,79.4772834777832,100.084869384766,,,6,,,,33.9070730166805,,,100,,,,,,,,,,,,,,,,,,,,,,79.0804595947266,79.8271942138672,100.084869384766,100.084869384766,,,6.87555122375488,,1,0,0,0,0.017242431640625,32.2580642700195,2,1,1,79.8741073608398,0,4232057760,79.4662178039551,,,0.0173506749884224,0.000871481708561574,0.0174534837015733,0.00087157268846273,0.881806612014771,0.950419664382935,33.5012855529785,0,35,4,200,0.00016468258399982,-0.693875014781952,0.1739781498909,1,,,,,,,,,,,,,,,,
,3844664034.48316,85.7255210876465,100.084869384766,,,6,,,,33.9190291337326,,,100,,,,,,,,,,,,,,,,,,,,,,85.3117828369141,86.0827102661133,100.084869384766,100.084869384766,,,6.8907299041748,,1,0,0,0,0.0002288818359375,31.7693061828613,2,1,1,86.1392593383789,0,4232057856,85.6970436096191,,,0.0173920297570466,0.000873314928448476,0.0174902889270168,0.000873414032053414,0.884158909320831,0.9503373503685,33.523265838623,0.192477822303772,35,4,200,0.00012036429689033,-0.695208609104157,0.174524858593941,1,,,,,,,,,,,,,,,,
,3844664111.9045,92.1260414123535,100.084869384766,,,6,,,,33.9295317086871,,,100,,,,,,,,,,,,,,,,,,,,,,91.7127685546875,92.5393142700195,100.084869384766,100.084869384766,,,6.94085645675659,,1,0,0,0,0.000152587890625,32.2580642700195,2,1,1,92.5393142700195,0,4232058208,92.1298356489702,,,0.0174396451765348,0.00087540938333341,0.0175318410869692,0.000875493822275105,0.887080132961273,0.950226306915283,33.5462188720703,0,35,4,200,0.000120063836220652,-0.696652472019196,0.175144240260124,1,,,,,,,,,,,,,,,,
,3844664189.22441,98.5408020019531,100.084869384766,,,6,,,,33.9407562793938,,,100,,,,,,,,,,,,,,,,,,,,,,98.1406021118164,98.8908996582031,100.084869384766,100.084869384766,,,6.92021131515503,,1,0,0,0,0.000152587890625,32.2580642700195,2,1,1,98.9410018920898,0,4232057888,98.5114799499512,,,0.0174899652675396,0.000877652610754377,0.017576723152316,0.000877740142629421,0.889935910701752,0.950119256973267,33.5698432922363,0.000186793826287612,35,4,200,0.00012547148799058,-0.69821572303772,0.175782352685928,1,,,,,,,,,,,,,,,,
,3844664265.96688,104.886837005615,100.084869384766,,,6,,,,33.9525070919182,,,100,,,,,,,,,,,,,,,,,,,,,,104.464324951172,105.254554748535,100.084869384766,100.084869384766,,,6.95973348617554,,1,0,0,0,0.000152587890625,32.2580642700195,2,1,1,105.309349060059,0,4232058048,104.874043273926,,,0.0175436269586228,0.000880070935669203,0.017624767888012,0.000880143979714164,0.89276796579361,0.950006723403931,33.593921661377,,35,4,200,0.000152898719534278,-0.699970722198486,0.176470309495926,1,,,,,,,,,,,,,,,,
,3844664343.82067,111.385250091553,100.084869384766,,,6,,,,33.9644766372165,,,100,,,,,,,,,,,,,,,,,,,,,,111.010681152344,111.727561950684,100.084869384766,100.084869384766,,,7.01199960708618,,1,0,0,0,0.000152587890625,31.2805480957031,2,1,1,111.759819030762,0,4232057824,111.368243408203,,,0.0176034020992899,0.000882776856619567,0.01767886715337,0.00088285433972827,0.895871639251709,0.949813425540924,33.6196174621582,3.34994292643387E-5,35,4,200,0.000145822632475756,-0.701831817626953,0.177248775959015,1,,,,,,,,,,,,,,,,
,3844664429.69575,118.449542999268,100.084869384766,,,6,,,,33.9815219628229,,,100,,,,,,,,,,,,,,,,,,,,,,118.059936523437,118.79451751709,100.084869384766,100.084869384766,,,7.02303838729858,,1,0,0,0,0.013885498046875,32.2580642700195,2,1,1,118.839149475098,0,4232057952,118.426741790771,,,0.0176695884356445,0.000885857321314254,0.0177402428036878,0.000885926965751077,0.898465871810913,0.949647605419159,33.6483459472656,,35,4,200,0.000154918976477347,-0.70408296585083,0.178108021616936,1,,,,,,,,,,,,,,,,
,3844664515.98644,125.625556945801,100.084869384766,,,6,,,,33.9996162083122,,,100,,,,,,,,,,,,,,,,,,,,,,125.227890014648,125.991195678711,100.084869384766,100.084869384766,,,7.02476692199707,,1,0,0,0,0.0002288818359375,31.7693061828613,2,1,1,126.023223876953,0,4232058144,125.63364944458,,,0.0177301316405369,0.000888648643779138,0.0177958250645635,0.000888697957282674,0.90117621421814,0.949748039245606,33.678108215332,0,35,4,200,0.000119134769192897,-0.706467986106873,0.17882464826107,1,,,,,,,,,,,,,,,,
,3844664602.46469,132.745292663574,100.084869384766,,,6,,,,34.0188986325602,,,100,,,,,,,,,,,,,,,,,,,,,,132.335922241211,133.104995727539,100.084869384766,100.084869384766,,,7.04801797866821,,1,0,0,0,0.0002288818359375,32.2580642700195,2,1,1,133.154663085938,0,4232058016,132.722766113281,,,0.0177977499472939,0.000891815132750696,0.0178593609976593,0.000891874868778181,0.903709650039673,0.949658036231995,33.7087478637695,3.00602114293724E-5,35,4,200,0.000115234775876161,-0.708896696567535,0.179611131548882,1,,,,,,,,,,,,,,,,
,3844664689.54249,139.988594055176,100.084869384766,,,6,,,,34.0392873193981,,,100,,,,,,,,,,,,,,,,,,,,,,139.586120605469,140.340911865234,100.084869384766,100.084869384766,,,7.08139038085938,,1,0,0,0,0.0002288818359375,32.2580642700195,2,1,1,140.391067504883,0,4232057984,139.960870361328,,,0.0178793800171871,0.000895723875693491,0.0179370385305249,0.000895779751961267,0.905817449092865,0.949088573455811,33.7399597167969,0,35,4,200,0.000124267098726705,-0.711330056190491,0.180800184607506,1,,,,,,,,,,,,,,,,
,3844664776.02989,147.142974853516,100.084869384766,,,6,,,,34.0608090566424,,,100,,,,,,,,,,,,,,,,,,,,,,146.750701904297,147.501693725586,100.084869384766,100.084869384766,,,7.09039688110352,,1,0,0,0,0.0148773193359375,32.2580642700195,2,1,1,147.535247802734,0,4232058016,147.129167175293,,,0.0179472331883579,0.000898934957993484,0.0180010132788051,0.000898981019041906,0.90805196762085,0.948957979679108,33.7719039916992,0,35,4,200,0.00011741831258405,-0.713685095310211,0.181689992547035,1,,,,,,,,,,,,,,,,
,3844664871.17857,155.027168273926,100.084869384766,,,6,,,,34.0883254404445,,,100,,,,,,,,,,,,,,,,,,,,,,154.619674682617,155.350860595703,100.084869384766,100.084869384766,,,7.09359979629517,,1,0,0,0,0.0002288818359375,32.7468223571777,2,1,1,155.434661865234,0,4232058112,154.9896484375,,,0.0180137975404901,0.000902113420800243,0.018064758974182,0.000902159539799454,0.909925520420074,0.949055731296539,33.8077926635742,0,35,4,200,0.00014373441808857,-0.716060996055603,0.171832680702209,1,,,,,,,,,,,,,,,,
,3844664984.70436,164.460548400879,100.084869384766,,,6,,,,34.1197109252302,,,100,,,,,,,,,,,,,,,,,,,,,,164.019409179687,164.856582641602,100.084869384766,100.084869384766,,,7.11618757247925,,1,0,0,0,0.000152587890625,32.2580642700195,2,1,1,164.90168762207,0,4232057888,164.428594970703,,,0.0180988558260283,0.000906164218466957,0.0181456676274602,0.000906211070027506,0.912503242492676,0.948825001716614,33.851734161377,0,35,4,200,0.00011749095574487,-0.718883216381073,0.172880902886391,1,,,,,,,,,,,,,,,,
,3844665098.0967,173.876243591309,100.084869384766,,,6,,,,34.1530754986335,,,100,,,,,,,,,,,,,,,,,,,,,,173.457046508789,174.241012573242,100.084869384766,100.084869384766,,,7.13501453399658,,1,0,0,0,0.0002288818359375,32.2580642700195,2,1,1,174.295440673828,0,4232056864,173.842420959473,,,0.0181750515882152,0.000909795865858235,0.0182179120383186,0.000909826073975198,0.914819240570068,0.94867467880249,33.896354675293,0,35,4,200,0.000146035439684056,-0.721423447132111,0.173901453614235,1,,,,,,,,,,,,,,,,
,3844665211.48254,183.267639160156,100.084869384766,,,6,,,,34.1883100149098,,,100,,,,,,,,,,,,,,,,,,,,,,182.849731445313,183.64241027832,100.084869384766,100.084869384766,,,7.15004587173462,,1,0,0,0,0.0159454345703125,32.2580642700195,2,1,1,183.685546875,0,4232058112,183.24041595459,,,0.0182407889036374,0.000912921755060606,0.0182803555281445,0.000912952877611959,0.916949093341827,0.948498070240021,33.942325592041,0,35,4,200,0.000145389116369188,-0.723718523979187,0.174843668937683,1,,,,,,,,,,,,,,,,
,3844665325.02345,192.667854309082,100.084869384766,,,6,,,,34.2252720804303,,,100,,,,,,,,,,,,,,,,,,,,,,192.239074707031,193.096633911133,100.084869384766,100.084869384766,,,7.16551876068115,,1,0,0,0,0.0189971923828125,31.7693061828613,2,1,1,193.096633911133,0,4232058016,192.671310424805,,,0.0182939459753634,0.000915427271347658,0.0183304196325047,0.000915463462235825,0.918997943401337,0.94828063249588,33.9899482727051,0,35,4,200,0.000152611683006398,-0.725550055503845,0.175514489412308,1,,,,,,,,,,,,,,,,
,3844665438.32995,202.074394226074,100.084869384766,,,6,,,,34.2642424952991,,,100,,,,,,,,,,,,,,,,,,,,,,201.653564453125,202.428161621094,100.084869384766,100.084869384766,,,7.18094158172607,,1,0,0,0,0.0147247314453125,32.7468223571777,2,1,1,202.495223999023,0,4232058176,202.046600341797,,,0.018321074822925,0.000916643600704644,0.018354542748419,0.000916675112745428,0.920906841754913,0.948131442070007,34.0388069152832,2.46044091909425E-5,35,4,200,0.000147145736264065,-0.726414859294891,0.175826817750931,1,,,,,,,,,,,,,,,,
,3844665547.79967,211.176856994629,100.084869384766,,,6,,,,34.3040752168755,,,100,,,,,,,,,,,,,,,,,,,,,,210.767639160156,211.522521972656,100.084869384766,100.084869384766,,,7.20185852050781,,1,0,0,0,0.01495361328125,32.2580642700195,2,1,1,211.586074829102,0,4232058016,211.144253540039,,,0.0183161028499225,0.000916285297617974,0.0183471314095996,0.000916312576249204,0.922427177429199,0.947977483272552,34.0869026184082,0,35,4,200,0.000150312742334791,-0.726179957389832,0.1757732629776,1,,,,,,,,,,,,,,,,
,3844665658.54951,220.381744384766,100.084869384766,,,6,,,,34.345309865799,,,100,,,,,,,,,,,,,,,,,,,,,,219.987747192383,220.734268188477,100.084869384766,100.084869384766,,,7.22125434875488,,1,0,0,0,0,32.2580642700195,2,1,1,220.775741577148,0,4232058048,220.361868286133,,,0.0182825185239076,0.000914492817424491,0.0183107308991655,0.00091451089716487,0.92401796579361,0.947637021541596,34.1375122070313,0,35,4,200,0.000146334306919016,-0.725119590759277,0.17536161839962,1,,,,,,,,,,,,,,,,
,3844665767.8312,229.471496582031,100.084869384766,,,6,,,,34.3885490173308,,,100,,,,,,,,,,,,,,,,,,,,,,229.062789916992,229.843643188477,100.084869384766,100.084869384766,,,7.24733591079712,,1,0,0,0,0.016326904296875,32.7468223571777,2,1,1,229.88020324707,0,4232058304,229.46219329834,,,0.0182037210104668,0.000910445347438452,0.0182296705770769,0.000910459561621975,0.925550818443298,0.947687685489655,34.188663482666,0,35,4,200,0.000147673432365991,-0.722175300121307,0.174271777272224,1,,,,,,,,,,,,,,,,
,3844665879.16033,238.696174621582,100.084869384766,,,6,,,,34.4336126550961,,,100,,,,,,,,,,,,,,,,,,,,,,238.290252685547,239.085418701172,100.084869384766,100.084869384766,,,7.27893018722534,,1,0,0,0,0.0154876708984375,33.2355842590332,2,1,1,239.102096557617,0,4232058048,238.686065673828,,,0.0180954957155982,0.000904926813113526,0.0181189913430466,0.000904941471297595,0.927132785320282,0.947490930557251,34.2429885864258,,35,4,200,0.000145408281241544,-0.718278288841248,0.172832697629929,1,,,,,,,,,,,,,,,,
,3844665990.33132,247.974884033203,100.084869384766,,,6,,,,34.4806719690024,,,100,,,,,,,,,,,,,,,,,,,,,,247.584320068359,248.313064575195,100.084869384766,100.084869384766,,,7.33973693847656,,1,0,0,0,0.013885498046875,32.7468223571777,2,1,1,248.365447998047,0,4232058048,247.949298095703,,,0.0179565343069545,0.000897880487557753,0.0179776747082479,0.000897893565372177,0.928621590137482,0.947275042533875,34.299144744873,0,35,4,200,9.86914164968766E-5,-0.713221371173859,0.170995488762856,1,,,,,,,,,,,,,,,,
,3844666101.53278,257.213241577148,100.084869384766,,,6,,,,34.5296180588609,,,100,,,,,,,,,,,,,,,,,,,,,,256.826904296875,257.599578857422,100.084869384766,100.084869384766,,,7.35766839981079,,1,0,0,0,0.013885498046875,32.2580642700195,2,1,1,257.599578857422,0,4232058048,257.216482543945,,,0.0177937229592656,0.000889639470139067,0.0178123633960282,0.000889643981928761,0.930208206176758,0.947132706642151,34.357723236084,0,35,4,200,9.4437382358592E-5,-0.707341969013214,0.168795183300972,1,,,,,,,,,,,,,,,,
,3844666209.71253,266.223480224609,100.084869384766,,,6,,,,34.5794736278427,,,100,,,,,,,,,,,,,,,,,,,,,,265.813232421875,266.615203857422,100.084869384766,100.084869384766,,,7.35364151000977,,1,0,0,0,0.013885498046875,32.2580642700195,2,1,1,266.633728027344,0,4232058048,266.214416503906,,,0.0176196542093532,0.000880830295147903,0.0176359238235477,0.000880839063779906,0.931949555873871,0.946974873542786,34.4185638427734,0.000106981242424808,35,4,200,8.98064827197231E-5,-0.701159477233887,0.166443973779678,1,,,,,,,,,,,,,,,,
,3844666320.67948,275.429580688477,100.084869384766,,,6,,,,34.6312507707002,,,100,,,,,,,,,,,,,,,,,,,,,,275.040466308594,275.795715332031,100.084869384766,100.084869384766,,,7.34491539001465,,1,0,0,0,0.0147247314453125,32.2580642700195,2,1,1,275.818695068359,0,4232058048,275.421493530273,,,0.0174130848718291,0.00087033023582657,0.0174255069902897,0.000870336581992417,0.934925019741058,0.946820378303528,34.4897880554199,0,35,4,200,9.13101321202703E-5,-0.693801820278168,0.174221441149712,1,,,,,,,,,,,,,,,,
,3844666430.97226,284.586486816406,100.084869384766,,,6,,,,34.6849054046016,,,100,,,,,,,,,,,,,,,,,,,,,,284.201995849609,284.937866210938,100.084869384766,100.084869384766,,,7.36527299880982,,1,0,0,0,0.013885498046875,32.2580642700195,2,1,1,284.970977783203,0,4232058144,284.564370727539,,,0.0171920003223841,0.000859054673955027,0.0171997576827011,0.000859058140282216,0.939079463481903,0.946895658969879,34.5723152160645,0,35,4,200,0.000123153717140667,-0.685785531997681,0.17117415368557,1,,,,,,,,,,,,,,,,
,3844666541.15838,293.725982666016,100.084869384766,,,6,,,,34.7405471215041,,,100,,,,,,,,,,,,,,,,,,,,,,293.332397460937,294.105194091797,100.084869384766,100.084869384766,,,7.45050859451294,,1,0,0,0,0.0139617919921875,33.7243423461914,2,1,1,294.119567871094,0,4232058112,293.717971801758,,,0.0169564147610989,0.000847054458568177,0.0169597330984586,0.000847052577053844,0.943662703037262,0.947281241416931,34.6656150817871,0,35,4,200,8.53729798109271E-5,-0.677142918109894,0.167931988835335,1,,,,,,,,,,,,,,,,
,3844666634.20711,299.634216308594,100.084869384766,,,6,,,,34.7763789877002,,,100,,,,,,,,,,,,,,,,,,,,,,299.575592041016,299.6884765625,100.084869384766,100.084869384766,,,7.6088695526123,,1,0,0,0,0.013885498046875,32.7468223571777,5,1,1,299.692840576172,0,4232057952,299.635821533203,,,0.0167916631028078,0.000838727759508575,0.016793418191881,0.000838727853112286,0.945739388465881,0.947693228721619,34.7219505310059,0,35,4,200,0.000126957573229447,-0.670944511890411,0.165716379880905,1,,,,,,,,,,,,,,,,
,3844666693.14093,299.93359375,100.084869384766,,,6,,,,34.7763789877002,,,100,,,,,,,,,,,,,,,,,,,,,,299.924896240234,299.941131591797,100.084869384766,100.084869384766,,,7.78540945053101,,1,0,0,0,0.0139617919921875,32.2580642700195,1,1,1,299.942291259766,0,4232058176,299.935073852539,,,0.0167799128276906,0.000838121389871534,0.0167813537088522,0.000838121669198736,0.946164727210999,0.947773039340973,34.727108001709,0,35,4,200,0.000134095040266402,-0.670446932315826,0.165563568472862,1,,,,,,,,,,,,,,,,