File: Data/KMK254/TGA/KMK254_1000C_Air.txt
Filename	KMK254_1000C_Air
Instrument name	0650-0588 (172.23.191.35)
Operator	Kyle Kirkpatrick
rundate	1/18/2023
Sample name	KMK254_1000C_Air
proceduresegments	Blend Channel B (Air) at 100% with Channel A (N2); Equilibrate 30.00 °C; Ramp 10.00 °C/min to 1000.00 °C
[File Parameters]
Run date	1/18/2023 6:22:45 PM
Trios version	5.5.1.5
Original File Name
Current File Name	C:\Users\ucsdi\OneDrive\Desktop\Data\Rinehart\Kyle\Jan 18 2023\KMK254_1000C_Air.tri
User at run start	DESKTOP-JSQIMO4\ucsdi
[Procedure]
Procedure Name
Sample Name	KMK254_1000C_Air
Sample Mass	10.24861 mg
Pan Number	7
Reference Pan Number	30
Pan Type	Alumina 90 ul
Comments
Project Name
Operator	Kyle Kirkpatrick
Skip Weight Stabilization	False
Enable Air Cool	True
Air Cool Until Temperature Is Below	50
End of Test Delay	0
Stop on Gas Flow Error	No
Sample mass pre-weigh	Not Available
[Signal List]
Signal #1	Time (min)
Signal #2	Temperature (°C)
Signal #3	Sample Flow (mL/min)
Signal #4	Balance Flow (mL/min)
Signal #5	Set Point (°C)
Signal #6	Power Requested (W)
Signal #7	Power Delivered (W)
Signal #8	Temperature Rate (°C/min)
Signal #9	Weight (mg)
Signal #10	Heat Flow (mW)
Signal #11	Weight Corrected Heat Flow (W/g)
Signal #12	Weight Change (%)
Signal #13	Temperature Difference (°C)
Signal #14	Channel A Flow (mL/min)
Signal #15	Channel A Flow (%)
Signal #16	Channel B Flow (mL/min)
Signal #17	Channel B Flow (%)
[Configuration]
Company Name
Instrument Name	0650-0588
Instrument Type	SDT650
Serial Number	0650-0588
IP	172.23.191.35
Location of Instrument	MFG
DisplayType	TianmaV2andV3
Sample Interval 	0.1 s/pt
Gas 1	Nitrogen
Gas 2	Air
Gas 3	Oxygen
Gas 4	Nitrogen
Total Sample Flow	100
Channel B	0%
Channel A Gas Selected	1
Channel B Gas Selected	4
Thermocouple Type	Type R
Exotherm Direction	Up
Sampling Mode	Single Sample Mode
[Versions]
Common IDD Version	1
Cortex Version	VER 1.3.3.11
Driver	5.0.0.7
GDM Version	1.2.1.2
Blending GDM Version	1.2.1.2
Blending GDM Bootloader	2.0.0.5
TouchscreenVersion	1.0.3.1817
Transducer Version	1.1.0.32
Transducer Bootloader	2.0.0.5
PCU Version	1.2.0.15
PCU Bootloader	2.0.0.5
AutoSampler Version	2.0.4.19
Auto Sampler Bootloader	2.0.0.5
[Experiment Logs]
Experiment Log Entry # 1	Blending segment primary gas 4, percent 0, secondary gas 2
Experiment Log Entry # 3	Equilibrate Segment 30 (C) Started
Experiment Log Entry # 5	Ramp Segment 10 C/min to 1000 C Started
[Method Log]
Method Log Entry # 1	Blend Channel B at 100% with Channel A
Method Log Entry # 2	Equilibrate 30 °C
Method Log Entry # 3	(Ramp 659365) Ramp 10 °C/minute to 1000 °C
[Room Temperature Calibration]
Date Applied	2/24/2021 3:27:30 AM
Measured	22.351
Correct	22.200
[Furnace Room Temperature Calibration]
Date Applied	2/24/2021 3:27:30 AM
Measured	24.159
Correct	22.200
[DTA Signal Setup]
Date Applied	1/11/2023 5:48:48 PM
Description	From 200.000 °C to 1,450.000 °C at 20.000°C/min
Source Files 1	C:\Users\ucsdi\OneDrive\Desktop\Data\Sailor\Ricardo\Calibrations\1-11-23\Weight Calibration.tri
[Weight Calibration]
Date Applied	1/11/2023 5:48:48 PM
Reference Beam Weight	4892.573
Reference Beam Weight at 200 °C	435.1747
Reference Beam Gain	0.09938934
Sample Beam Weight	5794.918
Sample Beam Weight at 200 °C	439.0667
Sample Beam Gain	0.09625536
Weight Ratio	0.9274598
Reference Weight	341.1444
Sample Weight	336.5152
[Heat Flow Calibration]
Date Applied	1/12/2023 4:18:26 AM
Description	From 100.000 °C to 1,450.000 °C at 20.000°C/min
Source Files 1	C:\Users\ucsdi\OneDrive\Desktop\Data\Sailor\Ricardo\Calibrations\1-11-23\Heat Flow Sapphire Calibration(1).tri
Source Files 2	C:\Users\ucsdi\OneDrive\Desktop\Data\Sailor\Ricardo\Calibrations\1-11-23\Heat Flow Sapphire Calibration.tri
[Temperature Calibration]
Date Applied	1/11/2023 9:24:14 PM
Description	From 107.000 °C to 227.000 °C at 10.000°C/min
Gas Type	Nitrogen
Pan Type	Alumina 90 ul
Source Files 1	C:\Users\ucsdi\OneDrive\Desktop\Data\Sailor\Ricardo\Calibrations\1-11-23\Indium.tri
Source Files 2	C:\Users\ucsdi\OneDrive\Desktop\Data\Sailor\Ricardo\Calibrations\1-11-23\Zinc.tri
Source Files 3	C:\Users\ucsdi\OneDrive\Desktop\Data\Sailor\Ricardo\Calibrations\1-11-23\Tin.tri
Measured 1	155.275
Known 1	156.6
Measured 2	230.5534
Known 2	231.93
Measured 3	418.0948
Known 3	419.53
[Dual Weight]
Date Applied	1/12/2023 4:18:26 AM
[Dual DeltaT]
Date Applied	1/12/2023 4:18:26 AM
[Cell Constant Calibration]
Date Applied	4/21/2022 4:38:29 AM
Description	From 370.000 °C to 480.000 °C at 10.000°C/min
Gas Type	Nitrogen
Pan Type	Alumina 90 ul
Source Files 1	C:\Users\ucsdi\OneDrive\Desktop\Sailor\Ricardo\Calibrations\Zinc(2).tri
Cell Constant	1.029587
Temperature	419.53
[Rev Cp Calibration]
Date Applied	1/12/2023 5:11:31 PM
Description	From 210.000 °C to 1,500.000 °C at 2.000°C/min
Gas Type	Nitrogen
Pan Type	Alumina 90 ul
Source Files 1	C:\Users\ucsdi\OneDrive\Desktop\Data\Sailor\Ricardo\Calibrations\1-11-23\Sappphire calibration.tri
[step]
Ramp 10.00 °C/min to 1000.00 °C
Time	Temperature	Heat Flow (Normalized)	Weight	Heat Flow	Weight
min	°C	W/g	%	mW	mg
0.00			99.363		10.183
0.08	31.06	0.596	99.363	6.108	10.183
0.16	31.05	0.596	99.363	6.107	10.183
0.24	31.05	0.596	99.364	6.104	10.183
0.31	31.06	0.595	99.365	6.096	10.184
0.39	31.11	0.590	99.368	6.049	10.184
0.47	31.23	0.579	99.371	5.938	10.184
0.55	31.43	0.563	99.376	5.773	10.185
0.63	31.70	0.544	99.381	5.573	10.185
0.70	32.07	0.521	99.386	5.339	10.186
0.78	32.52	0.495	99.391	5.074	10.186
0.86	33.05	0.467	99.395	4.784	10.187
0.94	33.66	0.438	99.398	4.490	10.187
1.02	34.33	0.411	99.401	4.210	10.187
1.10	35.06	0.383	99.403	3.929	10.187
1.18	35.83	0.358	99.405	3.669	10.188
1.25	36.65	0.335	99.406	3.433	10.188
1.33	37.50	0.314	99.407	3.222	10.188
1.41	38.38	0.296	99.408	3.038	10.188
1.49	39.27	0.281	99.409	2.882	10.188
1.57	40.17	0.269	99.409	2.752	10.188
1.64	41.07	0.257	99.409	2.637	10.188
1.72	41.97	0.249	99.409	2.556	10.188
1.80	42.86	0.243	99.409	2.489	10.188
1.88	43.73	0.239	99.408	2.447	10.188
1.96	44.60	0.237	99.407	2.425	10.188
2.04	45.45	0.235	99.407	2.413	10.188
2.12	46.29	0.235	99.406	2.406	10.188
2.19	47.11	0.235	99.405	2.407	10.188
2.27	47.92	0.236	99.404	2.423	10.188
2.35	48.72	0.240	99.403	2.455	10.187
2.43	49.50	0.244	99.402	2.505	10.187
2.51	50.27	0.251	99.401	2.567	10.187
2.59	51.03	0.256	99.400	2.626	10.187
2.66	51.78	0.264	99.399	2.702	10.187
2.74	52.53	0.270	99.398	2.770	10.187
2.82	53.28	0.277	99.396	2.842	10.187
2.90	54.01	0.285	99.395	2.918	10.187
2.98	54.75	0.292	99.394	2.989	10.186
3.06	55.50	0.299	99.392	3.068	10.186
3.13	56.23	0.306	99.390	3.139	10.186
3.21	56.98	0.314	99.389	3.214	10.186
3.29	57.72	0.321	99.387	3.292	10.186
3.37	58.47	0.329	99.386	3.370	10.186
3.45	59.22	0.336	99.384	3.441	10.185
3.53	59.97	0.342	99.382	3.510	10.185
3.60	60.73	0.349	99.380	3.575	10.185
3.68	61.49	0.357	99.378	3.654	10.185
3.76	62.26	0.363	99.375	3.722	10.185
3.84	63.03	0.370	99.373	3.788	10.184
3.92	63.80	0.376	99.371	3.851	10.184
3.99	64.58	0.382	99.369	3.915	10.184
4.07	65.36	0.388	99.366	3.974	10.184
4.15	66.14	0.394	99.363	4.042	10.183
4.23	66.92	0.401	99.360	4.112	10.183
4.31	67.70	0.407	99.357	4.175	10.183
4.39	68.49	0.414	99.354	4.241	10.182
4.46	69.27	0.419	99.351	4.299	10.182
4.54	70.06	0.426	99.347	4.366	10.182
4.62	70.85	0.432	99.344	4.430	10.181
4.70	71.64	0.438	99.340	4.492	10.181
4.78	72.42	0.444	99.336	4.550	10.181
4.86	73.21	0.451	99.332	4.621	10.180
4.94	74.00	0.457	99.328	4.688	10.180
5.01	74.78	0.463	99.324	4.746	10.179
5.09	75.57	0.470	99.319	4.816	10.179
5.17	76.35	0.477	99.315	4.884	10.178
5.25	77.14	0.483	99.310	4.946	10.178
5.33	77.92	0.490	99.306	5.019	10.177
5.40	78.70	0.497	99.301	5.091	10.177
5.48	79.48	0.504	99.296	5.161	10.176
5.56	80.27	0.510	99.291	5.231	10.176
5.64	81.05	0.517	99.286	5.303	10.175
5.72	81.83	0.525	99.280	5.383	10.175
5.80	82.61	0.532	99.275	5.455	10.174
5.88	83.39	0.540	99.269	5.531	10.174
5.95	84.17	0.547	99.264	5.610	10.173
6.03	84.95	0.554	99.259	5.681	10.173
6.11	85.73	0.561	99.253	5.750	10.172
6.19	86.51	0.568	99.247	5.822	10.171
6.27	87.30	0.575	99.242	5.892	10.171
6.35	88.08	0.583	99.236	5.972	10.170
6.42	88.86	0.590	99.231	6.050	10.170
6.50	89.64	0.598	99.225	6.128	10.169
6.58	90.43	0.605	99.220	6.201	10.169
6.66	91.21	0.613	99.214	6.279	10.168
6.74	91.99	0.620	99.208	6.354	10.167
6.81	92.77	0.628	99.203	6.431	10.167
6.89	93.56	0.635	99.197	6.511	10.166
6.97	94.34	0.643	99.192	6.593	10.166
7.05	95.13	0.652	99.186	6.678	10.165
7.13	95.91	0.660	99.181	6.765	10.165
7.21	96.70	0.668	99.175	6.844	10.164
7.29	97.48	0.676	99.170	6.925	10.164
7.36	98.27	0.684	99.164	7.007	10.163
7.44	99.05	0.692	99.159	7.097	10.162
7.52	99.84	0.701	99.153	7.181	10.162
7.60	100.62	0.708	99.148	7.260	10.161
7.68	101.41	0.717	99.142	7.349	10.161
7.75	102.20	0.725	99.137	7.433	10.160
7.83	102.98	0.734	99.132	7.525	10.160
7.91	103.77	0.742	99.127	7.609	10.159
7.99	104.55	0.751	99.122	7.701	10.159
8.07	105.34	0.761	99.117	7.795	10.158
8.15	106.13	0.769	99.111	7.881	10.158
8.23	106.91	0.778	99.106	7.969	10.157
8.30	107.70	0.787	99.101	8.066	10.157
8.38	108.48	0.795	99.096	8.152	10.156
8.46	109.27	0.805	99.092	8.250	10.156
8.54	110.06	0.814	99.087	8.344	10.155
8.62	110.84	0.824	99.082	8.441	10.155
8.70	111.63	0.833	99.078	8.533	10.154
8.77	112.42	0.842	99.073	8.628	10.154
8.85	113.20	0.851	99.069	8.725	10.153
8.93	113.99	0.861	99.064	8.822	10.153
9.01	114.77	0.870	99.060	8.919	10.152
9.09	115.56	0.880	99.055	9.018	10.152
9.17	116.35	0.890	99.051	9.118	10.151
9.24	117.13	0.899	99.047	9.217	10.151
9.32	117.92	0.909	99.042	9.311	10.150
9.40	118.71	0.919	99.038	9.417	10.150
9.48	119.49	0.929	99.034	9.518	10.150
9.56	120.28	0.938	99.030	9.618	10.149
9.63	121.07	0.948	99.026	9.711	10.149
9.71	121.85	0.958	99.022	9.818	10.148
9.79	122.64	0.969	99.018	9.928	10.148
9.87	123.43	0.978	99.014	10.027	10.148
9.95	124.21	0.988	99.010	10.124	10.147
10.03	125.00	0.998	99.006	10.229	10.147
10.10	125.79	1.008	99.002	10.331	10.146
10.18	126.57	1.018	98.999	10.435	10.146
10.26	127.36	1.029	98.995	10.545	10.146
10.34	128.15	1.039	98.991	10.650	10.145
10.42	128.93	1.049	98.988	10.752	10.145
10.50	129.72	1.060	98.984	10.866	10.145
10.58	130.51	1.070	98.980	10.971	10.144
10.65	131.29	1.082	98.977	11.085	10.144
10.73	132.08	1.092	98.973	11.189	10.143
10.81	132.87	1.103	98.970	11.300	10.143
10.89	133.65	1.113	98.967	11.409	10.143
10.97	134.44	1.124	98.963	11.519	10.142
11.05	135.23	1.134	98.960	11.626	10.142
11.12	136.02	1.146	98.957	11.746	10.142
11.20	136.80	1.158	98.954	11.865	10.141
11.28	137.59	1.168	98.950	11.969	10.141
11.36	138.38	1.179	98.947	12.083	10.141
11.44	139.16	1.191	98.944	12.203	10.140
11.52	139.95	1.202	98.941	12.316	10.140
11.59	140.74	1.213	98.938	12.434	10.140
11.67	141.52	1.225	98.935	12.553	10.139
11.75	142.31	1.236	98.932	12.665	10.139
11.83	143.10	1.248	98.929	12.790	10.139
11.91	143.89	1.259	98.926	12.905	10.139
11.98	144.67	1.271	98.923	13.030	10.138
12.06	145.46	1.283	98.920	13.145	10.138
12.14	146.25	1.295	98.918	13.272	10.138
12.22	147.03	1.306	98.915	13.388	10.137
12.30	147.82	1.318	98.912	13.511	10.137
12.38	148.61	1.331	98.909	13.638	10.137
12.45	149.40	1.343	98.907	13.761	10.137
12.53	150.18	1.356	98.904	13.894	10.136
12.61	150.97	1.369	98.901	14.028	10.136
12.69	151.76	1.381	98.899	14.152	10.136
12.77	152.55	1.394	98.896	14.284	10.136
12.85	153.34	1.407	98.894	14.420	10.135
12.93	154.12	1.419	98.891	14.548	10.135
13.00	154.91	1.433	98.889	14.687	10.135
13.08	155.70	1.447	98.886	14.827	10.134
13.16	156.49	1.460	98.884	14.958	10.134
13.24	157.28	1.473	98.881	15.096	10.134
13.32	158.06	1.486	98.879	15.232	10.134
13.40	158.85	1.500	98.876	15.374	10.133
13.47	159.64	1.514	98.874	15.520	10.133
13.55	160.43	1.529	98.872	15.667	10.133
13.63	161.22	1.542	98.870	15.807	10.133
13.71	162.01	1.557	98.867	15.960	10.133
13.79	162.79	1.571	98.865	16.104	10.132
13.87	163.58	1.586	98.863	16.257	10.132
13.94	164.37	1.600	98.861	16.403	10.132
14.02	165.16	1.616	98.859	16.561	10.132
14.10	165.95	1.631	98.857	16.712	10.131
14.18	166.74	1.646	98.854	16.867	10.131
14.26	167.53	1.661	98.852	17.025	10.131
14.33	168.32	1.677	98.850	17.187	10.131
14.41	169.11	1.693	98.848	17.350	10.131
14.49	169.89	1.709	98.846	17.510	10.130
14.57	170.68	1.725	98.844	17.675	10.130
14.65	171.47	1.740	98.842	17.835	10.130
14.73	172.26	1.757	98.840	18.009	10.130
14.80	173.05	1.774	98.838	18.181	10.130
14.88	173.84	1.791	98.836	18.354	10.129
14.96	174.63	1.808	98.834	18.528	10.129
15.04	175.42	1.825	98.832	18.706	10.129
15.12	176.21	1.843	98.831	18.886	10.129
15.20	177.01	1.861	98.829	19.070	10.129
15.28	177.80	1.879	98.827	19.253	10.128
15.35	178.59	1.897	98.825	19.444	10.128
15.43	179.38	1.915	98.823	19.630	10.128
15.51	180.17	1.934	98.821	19.823	10.128
15.59	180.96	1.953	98.819	20.014	10.128
15.67	181.75	1.972	98.817	20.206	10.127
15.75	182.54	1.991	98.815	20.404	10.127
15.82	183.34	2.010	98.813	20.605	10.127
15.90	184.13	2.030	98.811	20.803	10.127
15.98	184.92	2.049	98.809	21.004	10.127
16.06	185.71	2.070	98.808	21.211	10.126
16.14	186.50	2.090	98.806	21.421	10.126
16.22	187.30	2.111	98.804	21.634	10.126
16.29	188.09	2.132	98.802	21.848	10.126
16.37	188.88	2.153	98.800	22.064	10.126
16.45	189.68	2.174	98.798	22.278	10.125
16.53	190.47	2.196	98.796	22.503	10.125
16.61	191.26	2.217	98.794	22.726	10.125
16.68	192.06	2.240	98.791	22.953	10.125
16.76	192.85	2.263	98.789	23.189	10.124
16.84	193.64	2.285	98.786	23.422	10.124
16.92	194.44	2.308	98.783	23.658	10.124
17.00	195.23	2.332	98.780	23.897	10.124
17.08	196.03	2.356	98.777	24.146	10.123
17.16	196.82	2.380	98.774	24.390	10.123
17.23	197.62	2.404	98.770	24.633	10.123
17.31	198.41	2.428	98.767	24.881	10.122
17.39	199.21	2.453	98.763	25.135	10.122
17.47	200.00	2.478	98.759	25.391	10.121
17.55	200.80	2.503	98.756	25.652	10.121
17.63	201.60	2.529	98.752	25.919	10.121
17.70	202.39	2.555	98.748	26.183	10.120
17.78	203.19	2.581	98.743	26.454	10.120
17.86	203.99	2.608	98.739	26.725	10.119
17.94	204.79	2.635	98.734	27.003	10.119
18.02	205.58	2.662	98.729	27.281	10.118
18.09	206.38	2.690	98.724	27.567	10.118
18.17	207.18	2.718	98.718	27.854	10.117
18.25	207.98	2.746	98.712	28.144	10.117
18.33	208.78	2.775	98.706	28.439	10.116
18.41	209.58	2.804	98.700	28.741	10.115
18.49	210.38	2.835	98.693	29.051	10.115
18.57	211.18	2.865	98.686	29.364	10.114
18.64	211.98	2.896	98.679	29.676	10.113
18.72	212.78	2.927	98.671	29.997	10.112
18.80	213.59	2.959	98.663	30.324	10.112
18.88	214.39	2.991	98.654	30.650	10.111
18.96	215.19	3.024	98.646	30.987	10.110
19.03	215.99	3.057	98.636	31.329	10.109
19.11	216.79	3.091	98.627	31.676	10.108
19.19	217.59	3.125	98.617	32.030	10.107
19.27	218.40	3.160	98.607	32.389	10.106
19.35	219.20	3.196	98.596	32.757	10.105
19.43	220.00	3.233	98.585	33.133	10.104
19.51	220.81	3.270	98.574	33.513	10.102
19.58	221.61	3.307	98.562	33.896	10.101
19.66	222.42	3.346	98.550	34.289	10.100
19.74	223.22	3.384	98.537	34.686	10.099
19.82	224.03	3.424	98.523	35.091	10.097
19.90	224.84	3.464	98.510	35.506	10.096
19.98	225.64	3.505	98.496	35.926	10.094
20.05	226.45	3.548	98.481	36.358	10.093
20.13	227.26	3.591	98.465	36.803	10.091
20.21	228.07	3.635	98.450	37.251	10.090
20.29	228.88	3.679	98.433	37.706	10.088
20.37	229.69	3.725	98.416	38.175	10.086
20.44	230.50	3.771	98.399	38.649	10.085
20.52	231.31	3.819	98.380	39.135	10.083
20.60	232.12	3.867	98.362	39.629	10.081
20.68	232.94	3.916	98.342	40.134	10.079
20.76	233.75	3.966	98.322	40.648	10.077
20.84	234.56	4.017	98.301	41.166	10.074
20.92	235.38	4.069	98.279	41.701	10.072
20.99	236.19	4.122	98.257	42.243	10.070
21.07	237.01	4.175	98.234	42.790	10.068
21.15	237.82	4.230	98.210	43.354	10.065
21.23	238.64	4.286	98.186	43.922	10.063
21.31	239.46	4.342	98.161	44.499	10.060
21.38	240.27	4.399	98.135	45.087	10.057
21.46	241.09	4.457	98.108	45.680	10.055
21.54	241.91	4.516	98.081	46.282	10.052
21.62	242.73	4.575	98.053	46.892	10.049
21.70	243.55	4.636	98.024	47.512	10.046
21.78	244.37	4.697	97.994	48.134	10.043
21.86	245.19	4.758	97.963	48.764	10.040
21.93	246.01	4.821	97.931	49.405	10.037
22.01	246.83	4.882	97.899	50.038	10.033
22.09	247.65	4.945	97.865	50.681	10.030
22.17	248.47	5.008	97.831	51.329	10.026
22.25	249.29	5.071	97.795	51.973	10.023
22.33	250.11	5.134	97.759	52.619	10.019
22.40	250.93	5.198	97.721	53.268	10.015
22.48	251.75	5.260	97.683	53.907	10.011
22.56	252.57	5.322	97.644	54.539	10.007
22.64	253.39	5.383	97.603	55.169	10.003
22.72	254.21	5.444	97.562	55.791	9.999
22.79	255.03	5.503	97.520	56.402	9.994
22.87	255.84	5.562	97.476	57.000	9.990
22.95	256.65	5.618	97.432	57.581	9.985
23.03	257.47	5.674	97.387	58.155	9.981
23.11	258.28	5.728	97.341	58.701	9.976
23.19	259.09	5.780	97.294	59.234	9.971
23.27	259.90	5.830	97.246	59.746	9.966
23.34	260.71	5.877	97.196	60.231	9.961
23.42	261.51	5.922	97.146	60.690	9.956
23.50	262.32	5.964	97.095	61.124	9.951
23.58	263.12	6.004	97.043	61.529	9.946
23.66	263.92	6.040	96.991	61.901	9.940
23.73	264.71	6.073	96.937	62.239	9.935
23.81	265.51	6.102	96.883	62.540	9.929
23.89	266.30	6.129	96.828	62.814	9.924
23.97	267.09	6.152	96.772	63.046	9.918
24.05	267.87	6.171	96.716	63.248	9.912
24.13	268.65	6.187	96.659	63.407	9.906
24.21	269.43	6.200	96.601	63.538	9.900
24.28	270.21	6.208	96.542	63.626	9.894
24.36	270.99	6.215	96.483	63.694	9.888
24.44	271.76	6.219	96.423	63.740	9.882
24.52	272.53	6.220	96.363	63.751	9.876
24.60	273.30	6.216	96.303	63.707	9.870
24.68	274.07	6.209	96.241	63.636	9.863
24.75	274.84	6.199	96.180	63.534	9.857
24.83	275.60	6.188	96.118	63.418	9.851
24.91	276.36	6.174	96.055	63.279	9.844
24.99	277.13	6.158	95.993	63.111	9.838
25.07	277.89	6.141	95.929	62.938	9.831
25.14	278.65	6.122	95.866	62.739	9.825
25.22	279.41	6.101	95.802	62.528	9.818
25.30	280.16	6.079	95.737	62.299	9.812
25.38	280.92	6.055	95.673	62.059	9.805
25.46	281.68	6.031	95.608	61.805	9.798
25.54	282.43	6.005	95.543	61.547	9.792
25.62	283.19	5.980	95.477	61.288	9.785
25.69	283.94	5.954	95.412	61.015	9.778
25.77	284.70	5.927	95.346	60.746	9.772
25.85	285.46	5.900	95.279	60.464	9.765
25.93	286.21	5.872	95.213	60.182	9.758
26.01	286.97	5.845	95.146	59.900	9.751
26.08	287.72	5.817	95.079	59.620	9.744
26.16	288.48	5.790	95.012	59.337	9.737
26.24	289.23	5.762	94.945	59.057	9.730
26.32	289.99	5.735	94.877	58.778	9.724
26.40	290.74	5.708	94.809	58.500	9.717
26.48	291.50	5.681	94.741	58.221	9.710
26.56	292.26	5.653	94.673	57.935	9.703
26.63	293.01	5.625	94.605	57.652	9.696
26.71	293.77	5.598	94.537	57.373	9.689
26.79	294.52	5.570	94.469	57.089	9.682
26.87	295.28	5.543	94.401	56.813	9.675
26.95	296.04	5.516	94.332	56.528	9.668
27.03	296.79	5.487	94.264	56.236	9.661
27.10	297.55	5.458	94.196	55.937	9.654
27.18	298.31	5.429	94.127	55.639	9.647
27.26	299.06	5.400	94.059	55.339	9.640
27.34	299.82	5.370	93.991	55.031	9.633
27.42	300.57	5.339	93.923	54.720	9.626
27.49	301.33	5.309	93.855	54.408	9.619
27.57	302.08	5.278	93.787	54.091	9.612
27.65	302.84	5.246	93.719	53.765	9.605
27.73	303.59	5.214	93.652	53.439	9.598
27.81	304.35	5.183	93.585	53.118	9.591
27.89	305.11	5.152	93.518	52.797	9.584
27.97	305.86	5.120	93.451	52.475	9.577
28.04	306.62	5.090	93.384	52.163	9.571
28.12	307.37	5.058	93.318	51.841	9.564
28.20	308.13	5.028	93.252	51.526	9.557
28.28	308.89	4.997	93.186	51.214	9.550
28.36	309.64	4.967	93.121	50.910	9.544
28.43	310.40	4.937	93.056	50.602	9.537
28.51	311.16	4.909	92.991	50.307	9.530
28.59	311.91	4.880	92.927	50.017	9.524
28.67	312.67	4.851	92.863	49.720	9.517
28.75	313.43	4.823	92.799	49.427	9.511
28.83	314.19	4.795	92.736	49.138	9.504
28.91	314.95	4.767	92.673	48.852	9.498
28.98	315.71	4.738	92.610	48.562	9.491
29.06	316.46	4.710	92.548	48.273	9.485
29.14	317.22	4.682	92.486	47.984	9.479
29.22	317.98	4.654	92.425	47.696	9.472
29.30	318.74	4.625	92.364	47.398	9.466
29.38	319.50	4.596	92.303	47.100	9.460
29.45	320.26	4.567	92.243	46.802	9.454
29.53	321.02	4.537	92.184	46.495	9.448
29.61	321.77	4.506	92.125	46.182	9.442
29.69	322.53	4.476	92.067	45.869	9.436
29.77	323.29	4.444	92.010	45.542	9.430
29.84	324.04	4.411	91.953	45.205	9.424
29.92	324.80	4.378	91.897	44.867	9.418
30.00	325.56	4.342	91.841	44.502	9.412
30.08	326.31	4.301	91.793	44.082	9.407
30.16	327.06	4.264	91.760	43.699	9.404
30.24	327.81	4.226	91.724	43.313	9.400
30.32	328.57	4.188	91.683	42.925	9.396
30.39	329.32	4.149	91.639	42.525	9.392
30.47	330.07	4.110	91.594	42.121	9.387
30.55	330.82	4.070	91.548	41.707	9.382
30.63	331.57	4.028	91.501	41.283	9.378
30.71	332.32	3.986	91.455	40.849	9.373
30.78	333.07	3.942	91.410	40.404	9.368
30.86	333.82	3.899	91.365	39.962	9.364
30.94	334.57	3.855	91.321	39.505	9.359
31.02	335.32	3.810	91.278	39.047	9.355
31.10	336.07	3.764	91.236	38.573	9.350
31.18	336.82	3.718	91.195	38.102	9.346
31.26	337.56	3.672	91.156	37.628	9.342
31.33	338.31	3.625	91.117	37.147	9.338
31.41	339.06	3.578	91.079	36.671	9.334
31.49	339.81	3.530	91.043	36.181	9.331
31.57	340.56	3.482	91.008	35.689	9.327
31.65	341.31	3.434	90.974	35.197	9.324
31.73	342.06	3.387	90.941	34.708	9.320
31.80	342.80	3.340	90.909	34.226	9.317
31.88	343.55	3.293	90.878	33.747	9.314
31.96	344.30	3.245	90.848	33.257	9.311
32.04	345.05	3.199	90.819	32.788	9.308
32.12	345.80	3.153	90.792	32.319	9.305
32.19	346.55	3.108	90.765	31.857	9.302
32.27	347.30	3.064	90.739	31.397	9.300
32.35	348.05	3.019	90.715	30.939	9.297
32.43	348.80	2.976	90.691	30.502	9.295
32.51	349.56	2.934	90.668	30.068	9.292
32.59	350.31	2.892	90.645	29.643	9.290
32.67	351.06	2.852	90.624	29.227	9.288
32.74	351.82	2.812	90.604	28.822	9.286
32.82	352.57	2.774	90.584	28.430	9.284
32.90	353.33	2.737	90.565	28.046	9.282
32.98	354.09	2.700	90.546	27.671	9.280
33.06	354.84	2.665	90.529	27.308	9.278
33.13	355.60	2.630	90.512	26.949	9.276
33.21	356.36	2.596	90.495	26.602	9.275
33.29	357.12	2.563	90.480	26.270	9.273
33.37	357.88	2.532	90.464	25.947	9.271
33.45	358.64	2.500	90.450	25.625	9.270
33.53	359.40	2.471	90.435	25.320	9.268
33.61	360.16	2.441	90.422	25.020	9.267
33.68	360.93	2.414	90.409	24.738	9.266
33.76	361.69	2.387	90.396	24.459	9.264
33.84	362.45	2.360	90.384	24.188	9.263
33.92	363.22	2.335	90.372	23.933	9.262
34.00	363.98	2.310	90.361	23.678	9.261
34.08	364.75	2.287	90.350	23.434	9.260
34.15	365.51	2.263	90.339	23.195	9.258
34.23	366.28	2.242	90.329	22.974	9.257
34.31	367.05	2.220	90.319	22.750	9.256
34.39	367.81	2.199	90.309	22.534	9.255
34.47	368.58	2.179	90.299	22.332	9.254
34.54	369.35	2.160	90.291	22.136	9.254
34.62	370.12	2.141	90.282	21.942	9.253
34.70	370.89	2.123	90.274	21.761	9.252
34.78	371.66	2.105	90.266	21.576	9.251
34.86	372.43	2.089	90.258	21.412	9.250
34.94	373.20	2.072	90.251	21.239	9.249
35.01	373.97	2.057	90.243	21.083	9.249
35.09	374.74	2.042	90.236	20.925	9.248
35.17	375.51	2.027	90.230	20.769	9.247
35.25	376.28	2.013	90.223	20.629	9.247
35.33	377.05	1.999	90.217	20.487	9.246
35.41	377.82	1.985	90.211	20.346	9.245
35.49	378.59	1.972	90.205	20.213	9.245
35.56	379.37	1.960	90.199	20.087	9.244
35.64	380.14	1.949	90.193	19.973	9.244
35.72	380.91	1.937	90.188	19.853	9.243
35.80	381.69	1.926	90.183	19.737	9.242
35.88	382.46	1.915	90.178	19.622	9.242
35.96	383.23	1.904	90.173	19.513	9.241
36.03	384.01	1.893	90.168	19.405	9.241
36.11	384.78	1.883	90.164	19.302	9.241
36.19	385.56	1.874	90.159	19.201	9.240
36.27	386.33	1.865	90.155	19.111	9.240
36.35	387.11	1.855	90.151	19.007	9.239
36.43	387.88	1.846	90.147	18.915	9.239
36.50	388.66	1.837	90.143	18.824	9.238
36.58	389.43	1.828	90.139	18.737	9.238
36.66	390.21	1.820	90.135	18.650	9.238
36.74	390.98	1.812	90.132	18.570	9.237
36.82	391.76	1.804	90.128	18.485	9.237
36.89	392.53	1.796	90.125	18.404	9.237
36.97	393.31	1.789	90.121	18.332	9.236
37.05	394.08	1.781	90.118	18.252	9.236
37.13	394.86	1.774	90.115	18.183	9.236
37.21	395.64	1.767	90.112	18.108	9.235
37.29	396.41	1.760	90.109	18.040	9.235
37.36	397.19	1.754	90.106	17.974	9.235
37.44	397.97	1.747	90.103	17.906	9.234
37.52	398.74	1.742	90.100	17.849	9.234
37.60	399.52	1.735	90.097	17.782	9.234
37.68	400.30	1.728	90.095	17.712	9.233
37.76	401.08	1.722	90.092	17.651	9.233
37.84	401.85	1.716	90.090	17.589	9.233
37.91	402.63	1.710	90.087	17.525	9.233
37.99	403.41	1.704	90.085	17.463	9.232
38.07	404.19	1.699	90.082	17.408	9.232
38.15	404.97	1.693	90.080	17.354	9.232
38.23	405.75	1.688	90.077	17.302	9.232
38.31	406.52	1.682	90.075	17.241	9.231
38.38	407.30	1.677	90.073	17.182	9.231
38.46	408.08	1.671	90.071	17.126	9.231
38.54	408.86	1.666	90.068	17.074	9.231
38.62	409.64	1.661	90.066	17.021	9.231
38.70	410.41	1.656	90.064	16.968	9.230
38.78	411.19	1.651	90.062	16.920	9.230
38.85	411.97	1.646	90.060	16.865	9.230
38.93	412.75	1.640	90.058	16.809	9.230
39.01	413.53	1.635	90.056	16.756	9.230
39.09	414.31	1.630	90.054	16.707	9.229
39.17	415.09	1.626	90.052	16.659	9.229
39.24	415.86	1.621	90.050	16.611	9.229
39.32	416.64	1.615	90.048	16.556	9.229
39.40	417.42	1.610	90.046	16.503	9.229
39.48	418.20	1.606	90.045	16.458	9.228
39.56	418.98	1.601	90.043	16.408	9.228
39.64	419.76	1.596	90.041	16.354	9.228
39.71	420.53	1.591	90.040	16.308	9.228
39.79	421.31	1.587	90.038	16.260	9.228
39.87	422.09	1.582	90.036	16.213	9.227
39.95	422.87	1.577	90.035	16.161	9.227
40.03	423.65	1.571	90.033	16.101	9.227
40.11	424.43	1.567	90.031	16.059	9.227
40.19	425.20	1.562	90.030	16.011	9.227
40.26	425.98	1.557	90.028	15.960	9.227
40.34	426.76	1.552	90.027	15.907	9.226
40.42	427.54	1.547	90.025	15.855	9.226
40.50	428.32	1.542	90.023	15.802	9.226
40.58	429.10	1.537	90.022	15.750	9.226
40.66	429.88	1.533	90.021	15.710	9.226
40.73	430.66	1.528	90.019	15.657	9.226
40.81	431.43	1.523	90.017	15.604	9.226
40.89	432.21	1.518	90.016	15.554	9.225
40.97	432.99	1.512	90.014	15.498	9.225
41.05	433.77	1.507	90.013	15.447	9.225
41.13	434.55	1.503	90.012	15.400	9.225
41.20	435.33	1.497	90.010	15.338	9.225
41.28	436.11	1.492	90.009	15.294	9.225
41.36	436.89	1.487	90.007	15.243	9.225
41.44	437.66	1.482	90.006	15.193	9.224
41.52	438.44	1.478	90.005	15.144	9.224
41.59	439.22	1.473	90.003	15.092	9.224
41.67	440.00	1.467	90.002	15.038	9.224
41.75	440.78	1.463	90.001	14.993	9.224
41.83	441.56	1.458	90.000	14.938	9.224
41.91	442.33	1.452	89.999	14.879	9.224
41.99	443.11	1.447	89.997	14.830	9.223
42.06	443.89	1.442	89.996	14.774	9.223
42.14	444.67	1.438	89.995	14.735	9.223
42.22	445.45	1.434	89.994	14.693	9.223
42.30	446.23	1.428	89.993	14.634	9.223
42.38	447.01	1.423	89.992	14.581	9.223
42.46	447.79	1.418	89.991	14.529	9.223
42.54	448.57	1.413	89.989	14.483	9.223
42.61	449.35	1.409	89.988	14.437	9.223
42.69	450.13	1.403	89.987	14.380	9.222
42.77	450.90	1.398	89.986	14.328	9.222
42.85	451.68	1.394	89.985	14.282	9.222
42.93	452.46	1.388	89.984	14.228	9.222
43.01	453.24	1.383	89.983	14.178	9.222
43.08	454.02	1.378	89.981	14.124	9.222
43.16	454.80	1.374	89.980	14.086	9.222
43.24	455.58	1.370	89.979	14.041	9.222
43.32	456.35	1.365	89.978	13.988	9.222
43.40	457.13	1.361	89.977	13.944	9.221
43.48	457.91	1.355	89.976	13.891	9.221
43.55	458.69	1.350	89.975	13.840	9.221
43.63	459.47	1.346	89.974	13.794	9.221
43.71	460.25	1.340	89.973	13.728	9.221
43.79	461.03	1.336	89.972	13.691	9.221
43.87	461.81	1.331	89.971	13.639	9.221
43.94	462.59	1.325	89.970	13.579	9.221
44.02	463.37	1.320	89.969	13.527	9.221
44.10	464.15	1.316	89.968	13.485	9.220
44.18	464.93	1.310	89.967	13.428	9.220
44.26	465.71	1.306	89.966	13.385	9.220
44.34	466.49	1.301	89.965	13.330	9.220
44.41	467.26	1.295	89.964	13.275	9.220
44.49	468.04	1.290	89.963	13.219	9.220
44.57	468.82	1.285	89.962	13.171	9.220
44.65	469.60	1.280	89.961	13.114	9.220
44.73	470.38	1.274	89.960	13.059	9.220
44.81	471.16	1.269	89.959	13.010	9.220
44.89	471.93	1.265	89.958	12.962	9.219
44.96	472.71	1.259	89.957	12.906	9.219
45.04	473.49	1.254	89.956	12.849	9.219
45.12	474.27	1.249	89.955	12.802	9.219
45.20	475.05	1.244	89.954	12.750	9.219
45.28	475.83	1.239	89.953	12.700	9.219
45.36	476.61	1.234	89.952	12.646	9.219
45.43	477.39	1.229	89.951	12.597	9.219
45.51	478.17	1.225	89.950	12.550	9.219
45.59	478.95	1.219	89.949	12.497	9.219
45.67	479.73	1.214	89.948	12.442	9.218
45.75	480.51	1.208	89.947	12.381	9.218
45.83	481.29	1.203	89.946	12.325	9.218
45.90	482.07	1.198	89.945	12.278	9.218
45.98	482.84	1.193	89.944	12.225	9.218
46.06	483.62	1.187	89.943	12.165	9.218
46.14	484.40	1.181	89.942	12.106	9.218
46.22	485.18	1.174	89.941	12.036	9.218
46.29	485.96	1.169	89.941	11.985	9.218
46.37	486.74	1.165	89.940	11.936	9.218
46.45	487.52	1.159	89.939	11.880	9.217
46.53	488.30	1.154	89.938	11.825	9.217
46.61	489.07	1.148	89.937	11.763	9.217
46.69	489.85	1.142	89.936	11.709	9.217
46.76	490.63	1.137	89.935	11.653	9.217
46.84	491.41	1.132	89.934	11.600	9.217
46.92	492.19	1.126	89.933	11.541	9.217
47.00	492.97	1.120	89.932	11.483	9.217
47.08	493.75	1.114	89.931	11.413	9.217
47.16	494.53	1.108	89.931	11.360	9.217
47.24	495.31	1.102	89.930	11.298	9.217
47.31	496.09	1.096	89.929	11.234	9.216
47.39	496.87	1.090	89.928	11.172	9.216
47.47	497.65	1.084	89.927	11.112	9.216
47.55	498.43	1.079	89.926	11.053	9.216
47.63	499.21	1.072	89.926	10.989	9.216
47.71	499.99	1.067	89.925	10.937	9.216
47.78	500.77	1.061	89.924	10.873	9.216
47.86	501.55	1.055	89.923	10.809	9.216
47.94	502.33	1.048	89.922	10.742	9.216
48.02	503.10	1.041	89.921	10.668	9.216
48.10	503.88	1.035	89.920	10.605	9.216
48.18	504.66	1.028	89.919	10.540	9.215
48.25	505.44	1.023	89.919	10.489	9.215
48.33	506.22	1.017	89.918	10.423	9.215
48.41	507.00	1.011	89.917	10.359	9.215
48.49	507.78	1.004	89.916	10.291	9.215
48.57	508.56	0.997	89.915	10.222	9.215
48.64	509.34	0.992	89.915	10.167	9.215
48.72	510.12	0.986	89.914	10.100	9.215
48.80	510.90	0.980	89.913	10.039	9.215
48.88	511.68	0.974	89.912	9.981	9.215
48.96	512.46	0.968	89.911	9.916	9.215
49.04	513.24	0.960	89.910	9.836	9.215
49.11	514.02	0.953	89.909	9.769	9.214
49.19	514.80	0.947	89.909	9.706	9.214
49.27	515.58	0.940	89.908	9.635	9.214
49.35	516.35	0.934	89.907	9.568	9.214
49.43	517.13	0.927	89.906	9.497	9.214
49.51	517.91	0.920	89.905	9.426	9.214
49.59	518.69	0.913	89.905	9.359	9.214
49.66	519.47	0.906	89.904	9.290	9.214
49.74	520.25	0.899	89.903	9.217	9.214
49.82	521.03	0.893	89.903	9.151	9.214
49.90	521.81	0.886	89.902	9.084	9.214
49.98	522.58	0.878	89.901	9.003	9.214
50.06	523.36	0.872	89.900	8.938	9.214
50.13	524.14	0.864	89.900	8.856	9.213
50.21	524.92	0.859	89.899	8.804	9.213
50.29	525.70	0.853	89.898	8.741	9.213
50.37	526.48	0.845	89.898	8.663	9.213
50.45	527.26	0.839	89.897	8.597	9.213
50.53	528.04	0.831	89.896	8.517	9.213
50.60	528.83	0.825	89.896	8.453	9.213
50.68	529.61	0.818	89.895	8.385	9.213
50.76	530.38	0.809	89.894	8.296	9.213
50.84	531.16	0.803	89.893	8.232	9.213
50.92	531.94	0.797	89.892	8.164	9.213
50.99	532.72	0.789	89.892	8.086	9.213
51.07	533.50	0.781	89.891	8.006	9.213
51.15	534.28	0.774	89.890	7.933	9.212
51.23	535.06	0.766	89.889	7.851	9.212
51.31	535.83	0.759	89.888	7.778	9.212
51.39	536.61	0.749	89.888	7.681	9.212
51.46	537.39	0.743	89.887	7.617	9.212
51.54	538.17	0.735	89.886	7.537	9.212
51.62	538.95	0.728	89.886	7.462	9.212
51.70	539.73	0.721	89.885	7.387	9.212
51.78	540.51	0.713	89.884	7.310	9.212
51.86	541.29	0.707	89.883	7.244	9.212
51.94	542.07	0.700	89.882	7.178	9.212
52.01	542.85	0.694	89.881	7.111	9.212
52.09	543.63	0.687	89.881	7.046	9.212
52.17	544.41	0.681	89.880	6.980	9.211
52.25	545.19	0.674	89.879	6.907	9.211
52.33	545.97	0.667	89.879	6.841	9.211
52.41	546.75	0.662	89.878	6.787	9.211
52.48	547.53	0.656	89.877	6.724	9.211
52.56	548.31	0.650	89.876	6.667	9.211
52.64	549.09	0.647	89.876	6.626	9.211
52.72	549.87	0.643	89.875	6.588	9.211
52.80	550.65	0.640	89.874	6.554	9.211
52.88	551.43	0.637	89.873	6.529	9.211
52.95	552.22	0.636	89.872	6.516	9.211
53.03	553.00	0.636	89.872	6.516	9.211
53.11	553.78	0.637	89.871	6.533	9.211
53.19	554.57	0.643	89.870	6.593	9.210
53.27	555.36	0.655	89.869	6.714	9.210
53.34	556.15	0.673	89.868	6.899	9.210
53.42	556.94	0.697	89.868	7.147	9.210
53.50	557.74	0.730	89.867	7.477	9.210
53.58	558.54	0.772	89.866	7.917	9.210
53.66	559.35	0.829	89.865	8.492	9.210
53.74	560.17	0.903	89.864	9.250	9.210
53.81	560.99	0.998	89.863	10.228	9.210
53.89	561.83	1.120	89.862	11.480	9.210
53.97	562.68	1.269	89.861	13.010	9.209
54.05	563.54	1.436	89.860	14.720	9.209
54.13	564.40	1.604	89.859	16.436	9.209
54.21	565.25	1.747	89.858	17.903	9.209
54.29	566.08	1.850	89.856	18.961	9.209
54.36	566.88	1.903	89.855	19.506	9.209
54.44	567.67	1.911	89.854	19.580	9.209
54.52	568.43	1.878	89.852	19.252	9.209
54.60	569.18	1.814	89.851	18.594	9.208
54.68	569.92	1.727	89.849	17.702	9.208
54.76	570.66	1.627	89.848	16.675	9.208
54.83	571.39	1.519	89.847	15.566	9.208
54.91	572.12	1.406	89.846	14.412	9.208
54.99	572.85	1.297	89.844	13.293	9.208
55.07	573.58	1.194	89.843	12.232	9.208
55.15	574.32	1.097	89.842	11.244	9.208
55.23	575.06	1.008	89.840	10.328	9.207
55.30	575.81	0.928	89.839	9.512	9.207
55.38	576.56	0.856	89.838	8.777	9.207
55.46	577.32	0.792	89.837	8.120	9.207
55.54	578.08	0.735	89.836	7.530	9.207
55.62	578.84	0.684	89.835	7.013	9.207
55.69	579.60	0.641	89.834	6.565	9.207
55.77	580.37	0.601	89.833	6.161	9.207
55.85	581.14	0.566	89.832	5.801	9.207
55.93	581.91	0.536	89.831	5.492	9.206
56.01	582.68	0.508	89.830	5.204	9.206
56.09	583.46	0.484	89.830	4.961	9.206
56.16	584.23	0.462	89.829	4.734	9.206
56.24	585.01	0.442	89.828	4.529	9.206
56.32	585.78	0.424	89.827	4.345	9.206
56.40	586.56	0.407	89.827	4.176	9.206
56.48	587.33	0.391	89.826	4.011	9.206
56.56	588.11	0.378	89.825	3.869	9.206
56.64	588.89	0.365	89.825	3.739	9.206
56.71	589.67	0.353	89.824	3.618	9.206
56.79	590.45	0.342	89.824	3.504	9.206
56.87	591.23	0.332	89.823	3.402	9.206
56.95	592.01	0.321	89.823	3.289	9.206
57.03	592.79	0.310	89.822	3.181	9.206
57.11	593.57	0.301	89.822	3.084	9.205
57.18	594.35	0.290	89.821	2.976	9.205
57.26	595.13	0.282	89.821	2.890	9.205
57.34	595.90	0.274	89.820	2.806	9.205
57.42	596.68	0.265	89.820	2.712	9.205
57.50	597.46	0.257	89.819	2.633	9.205
57.58	598.24	0.248	89.818	2.539	9.205
57.65	599.02	0.239	89.818	2.453	9.205
57.73	599.80	0.230	89.817	2.362	9.205
57.81	600.58	0.223	89.817	2.285	9.205
57.89	601.36	0.216	89.816	2.213	9.205
57.97	602.14	0.207	89.816	2.122	9.205
58.04	602.92	0.199	89.816	2.042	9.205
58.12	603.70	0.192	89.815	1.966	9.205
58.20	604.48	0.184	89.815	1.890	9.205
58.28	605.26	0.177	89.814	1.810	9.205
58.36	606.04	0.168	89.814	1.724	9.205
58.44	606.83	0.161	89.813	1.647	9.205
58.51	607.61	0.152	89.813	1.560	9.205
58.59	608.39	0.145	89.813	1.488	9.205
58.67	609.17	0.136	89.812	1.395	9.204
58.75	609.95	0.127	89.812	1.305	9.204
58.83	610.73	0.119	89.811	1.216	9.204
58.91	611.51	0.111	89.811	1.140	9.204
58.99	612.29	0.103	89.811	1.058	9.204
59.06	613.07	0.095	89.810	0.975	9.204
59.14	613.85	0.088	89.810	0.903	9.204
59.22	614.63	0.080	89.810	0.819	9.204
59.30	615.41	0.073	89.809	0.744	9.204
59.38	616.19	0.065	89.809	0.662	9.204
59.46	616.97	0.057	89.808	0.581	9.204
59.53	617.74	0.049	89.808	0.498	9.204
59.61	618.52	0.039	89.808	0.399	9.204
59.69	619.30	0.032	89.807	0.329	9.204
59.77	620.08	0.025	89.807	0.252	9.204
59.85	620.87	0.016	89.806	0.163	9.204
59.93	621.65	0.009	89.806	0.089	9.204
60.00	622.43	-0.001	89.806	-0.010	9.204
60.08	623.21	-0.008	89.805	-0.085	9.204
60.16	623.99	-0.017	89.805	-0.173	9.204
60.24	624.77	-0.026	89.805	-0.263	9.204
60.32	625.55	-0.034	89.804	-0.346	9.204
60.39	626.33	-0.042	89.804	-0.433	9.204
60.47	627.11	-0.050	89.803	-0.511	9.204
60.55	627.89	-0.059	89.803	-0.602	9.204
60.63	628.67	-0.068	89.803	-0.692	9.204
60.71	629.45	-0.077	89.802	-0.791	9.204
60.79	630.23	-0.085	89.802	-0.870	9.203
60.86	631.01	-0.093	89.802	-0.949	9.203
60.94	631.79	-0.103	89.801	-1.051	9.203
61.02	632.57	-0.111	89.801	-1.137	9.203
61.10	633.35	-0.119	89.800	-1.220	9.203
61.18	634.13	-0.128	89.800	-1.316	9.203
61.26	634.91	-0.137	89.800	-1.405	9.203
61.34	635.69	-0.145	89.799	-1.490	9.203
61.41	636.47	-0.155	89.799	-1.590	9.203
61.49	637.25	-0.164	89.799	-1.679	9.203
61.57	638.03	-0.173	89.798	-1.770	9.203
61.65	638.81	-0.182	89.798	-1.864	9.203
61.73	639.59	-0.192	89.797	-1.966	9.203
61.81	640.37	-0.200	89.797	-2.054	9.203
61.88	641.15	-0.210	89.797	-2.148	9.203
61.96	641.94	-0.220	89.797	-2.252	9.203
62.04	642.72	-0.229	89.796	-2.348	9.203
62.12	643.50	-0.237	89.796	-2.430	9.203
62.20	644.28	-0.234	89.796	-2.396	9.203
62.28	645.06	-0.237	89.796	-2.431	9.203
62.35	645.84	-0.247	89.797	-2.532	9.203
62.43	646.62	-0.256	89.797	-2.620	9.203
62.51	647.40	-0.267	89.797	-2.733	9.203
62.59	648.18	-0.277	89.797	-2.837	9.203
62.67	648.96	-0.287	89.797	-2.939	9.203
62.74	649.74	-0.296	89.797	-3.033	9.203
62.82	650.52	-0.307	89.796	-3.144	9.203
62.90	651.30	-0.317	89.796	-3.251	9.203
62.98	652.08	-0.327	89.796	-3.350	9.203
63.06	652.86	-0.336	89.795	-3.447	9.203
63.14	653.64	-0.347	89.795	-3.552	9.203
63.21	654.42	-0.356	89.795	-3.644	9.203
63.29	655.20	-0.367	89.794	-3.761	9.203
63.37	655.98	-0.377	89.794	-3.859	9.203
63.45	656.76	-0.387	89.794	-3.967	9.203
63.53	657.54	-0.397	89.793	-4.064	9.203
63.61	658.32	-0.409	89.793	-4.194	9.203
63.69	659.10	-0.420	89.793	-4.305	9.202
63.76	659.88	-0.430	89.792	-4.409	9.202
63.84	660.66	-0.440	89.792	-4.507	9.202
63.92	661.44	-0.452	89.792	-4.632	9.202
64.00	662.22	-0.462	89.791	-4.740	9.202
64.08	663.00	-0.473	89.791	-4.843	9.202
64.16	663.78	-0.486	89.790	-4.977	9.202
64.23	664.55	-0.497	89.790	-5.094	9.202
64.31	665.33	-0.508	89.790	-5.206	9.202
64.39	666.11	-0.518	89.789	-5.305	9.202
64.47	666.89	-0.527	89.789	-5.403	9.202
64.55	667.67	-0.538	89.788	-5.511	9.202
64.63	668.45	-0.549	89.788	-5.625	9.202
64.70	669.23	-0.559	89.788	-5.729	9.202
64.78	670.01	-0.570	89.787	-5.840	9.202
64.86	670.80	-0.581	89.787	-5.954	9.202
64.94	671.58	-0.592	89.786	-6.069	9.202
65.02	672.36	-0.602	89.786	-6.172	9.202
65.09	673.14	-0.614	89.786	-6.288	9.202
65.17	673.92	-0.625	89.785	-6.401	9.202
65.25	674.70	-0.636	89.785	-6.517	9.202
65.33	675.48	-0.647	89.784	-6.632	9.202
65.41	676.26	-0.658	89.784	-6.743	9.202
65.49	677.04	-0.669	89.784	-6.856	9.202
65.56	677.82	-0.681	89.783	-6.981	9.202
65.64	678.60	-0.692	89.783	-7.094	9.202
65.72	679.38	-0.703	89.783	-7.203	9.201
65.80	680.16	-0.713	89.782	-7.308	9.201
65.88	680.93	-0.723	89.782	-7.414	9.201
65.96	681.71	-0.734	89.781	-7.521	9.201
66.04	682.49	-0.745	89.781	-7.638	9.201
66.11	683.27	-0.756	89.781	-7.745	9.201
66.19	684.05	-0.766	89.780	-7.852	9.201
66.27	684.83	-0.776	89.780	-7.951	9.201
66.35	685.61	-0.786	89.780	-8.058	9.201
66.43	686.40	-0.797	89.779	-8.167	9.201
66.51	687.18	-0.808	89.779	-8.282	9.201
66.58	687.96	-0.819	89.778	-8.395	9.201
66.66	688.74	-0.830	89.778	-8.508	9.201
66.74	689.52	-0.841	89.777	-8.622	9.201
66.82	690.31	-0.853	89.777	-8.742	9.201
66.90	691.08	-0.865	89.777	-8.865	9.201
66.98	691.86	-0.877	89.776	-8.986	9.201
67.05	692.64	-0.889	89.776	-9.109	9.201
67.13	693.42	-0.901	89.775	-9.232	9.201
67.21	694.20	-0.913	89.775	-9.359	9.201
67.29	694.98	-0.925	89.775	-9.478	9.201
67.37	695.76	-0.936	89.774	-9.589	9.201
67.44	696.54	-0.947	89.774	-9.710	9.201
67.52	697.32	-0.960	89.773	-9.839	9.201
67.60	698.10	-0.970	89.773	-9.944	9.201
67.68	698.88	-0.982	89.773	-10.061	9.200
67.76	699.66	-0.994	89.772	-10.191	9.200
67.84	700.44	-1.005	89.772	-10.303	9.200
67.91	701.22	-1.018	89.772	-10.430	9.200
67.99	702.00	-1.030	89.771	-10.552	9.200
68.07	702.79	-1.042	89.771	-10.675	9.200
68.15	703.57	-1.053	89.770	-10.792	9.200
68.23	704.35	-1.064	89.770	-10.903	9.200
68.31	705.13	-1.077	89.769	-11.042	9.200
68.39	705.91	-1.091	89.769	-11.183	9.200
68.46	706.69	-1.104	89.768	-11.312	9.200
68.54	707.48	-1.115	89.768	-11.428	9.200
68.62	708.26	-1.127	89.768	-11.555	9.200
68.70	709.03	-1.143	89.767	-11.713	9.200
68.78	709.81	-1.154	89.767	-11.831	9.200
68.85	710.59	-1.167	89.766	-11.959	9.200
68.93	711.37	-1.180	89.766	-12.091	9.200
69.01	712.15	-1.193	89.766	-12.229	9.200
69.09	712.93	-1.207	89.765	-12.371	9.200
69.17	713.71	-1.218	89.765	-12.482	9.200
69.25	714.49	-1.233	89.765	-12.632	9.200
69.33	715.27	-1.245	89.764	-12.756	9.200
69.40	716.05	-1.257	89.764	-12.880	9.200
69.48	716.83	-1.269	89.763	-13.004	9.200
69.56	717.61	-1.282	89.763	-13.142	9.199
69.64	718.39	-1.296	89.763	-13.281	9.199
69.72	719.17	-1.309	89.762	-13.416	9.199
69.80	719.96	-1.321	89.762	-13.534	9.199
69.87	720.74	-1.333	89.761	-13.665	9.199
69.95	721.52	-1.348	89.761	-13.816	9.199
70.03	722.30	-1.362	89.760	-13.956	9.199
70.11	723.08	-1.376	89.760	-14.105	9.199
70.19	723.86	-1.390	89.759	-14.244	9.199
70.26	724.64	-1.403	89.759	-14.382	9.199
70.34	725.42	-1.417	89.758	-14.519	9.199
70.42	726.20	-1.430	89.758	-14.658	9.199
70.50	726.97	-1.444	89.757	-14.803	9.199
70.58	727.75	-1.459	89.757	-14.948	9.199
70.66	728.53	-1.471	89.756	-15.077	9.199
70.74	729.31	-1.485	89.756	-15.224	9.199
70.81	730.09	-1.499	89.755	-15.362	9.199
70.89	730.87	-1.512	89.755	-15.500	9.199
70.97	731.65	-1.526	89.755	-15.641	9.199
71.05	732.43	-1.540	89.754	-15.784	9.199
71.13	733.21	-1.553	89.754	-15.916	9.199
71.20	733.99	-1.566	89.754	-16.054	9.199
71.28	734.77	-1.580	89.753	-16.194	9.198
71.36	735.56	-1.593	89.753	-16.328	9.198
71.44	736.34	-1.608	89.753	-16.477	9.198
71.52	737.12	-1.620	89.752	-16.604	9.198
71.60	737.90	-1.635	89.752	-16.755	9.198
71.68	738.68	-1.649	89.752	-16.899	9.198
71.75	739.46	-1.664	89.751	-17.052	9.198
71.83	740.24	-1.678	89.751	-17.200	9.198
71.91	741.02	-1.692	89.751	-17.346	9.198
71.99	741.80	-1.708	89.750	-17.502	9.198
72.07	742.58	-1.722	89.750	-17.649	9.198
72.15	743.36	-1.737	89.749	-17.800	9.198
72.22	744.14	-1.751	89.749	-17.949	9.198
72.30	744.92	-1.767	89.749	-18.106	9.198
72.38	745.70	-1.780	89.748	-18.242	9.198
72.46	746.48	-1.794	89.748	-18.390	9.198
72.54	747.25	-1.809	89.747	-18.541	9.198
72.61	748.03	-1.822	89.747	-18.677	9.198
72.69	748.81	-1.836	89.746	-18.812	9.198
72.77	749.60	-1.851	89.746	-18.968	9.198
72.85	750.38	-1.864	89.745	-19.104	9.198
72.93	751.16	-1.879	89.745	-19.255	9.198
73.01	751.94	-1.893	89.744	-19.404	9.198
73.09	752.72	-1.907	89.744	-19.549	9.197
73.16	753.50	-1.924	89.743	-19.716	9.197
73.24	754.28	-1.939	89.742	-19.875	9.197
73.32	755.06	-1.954	89.742	-20.027	9.197
73.40	755.84	-1.969	89.741	-20.183	9.197
73.48	756.62	-1.986	89.741	-20.351	9.197
73.55	757.40	-2.001	89.740	-20.504	9.197
73.63	758.18	-2.015	89.740	-20.650	9.197
73.71	758.96	-2.031	89.739	-20.815	9.197
73.79	759.74	-2.047	89.738	-20.977	9.197
73.87	760.52	-2.061	89.738	-21.124	9.197
73.95	761.30	-2.078	89.737	-21.294	9.197
74.03	762.08	-2.092	89.737	-21.441	9.197
74.10	762.86	-2.107	89.736	-21.598	9.197
74.18	763.64	-2.122	89.735	-21.750	9.197
74.26	764.42	-2.137	89.735	-21.905	9.197
74.34	765.20	-2.152	89.734	-22.050	9.197
74.42	765.98	-2.168	89.734	-22.215	9.196
74.50	766.76	-2.182	89.733	-22.360	9.196
74.57	767.54	-2.198	89.733	-22.523	9.196
74.65	768.32	-2.213	89.732	-22.684	9.196
74.73	769.10	-2.230	89.732	-22.851	9.196
74.81	769.88	-2.247	89.731	-23.027	9.196
74.89	770.66	-2.263	89.731	-23.190	9.196
74.96	771.44	-2.279	89.730	-23.356	9.196
75.04	772.22	-2.294	89.730	-23.515	9.196
75.12	773.00	-2.311	89.729	-23.683	9.196
75.20	773.78	-2.328	89.728	-23.857	9.196
75.28	774.56	-2.343	89.728	-24.016	9.196
75.36	775.34	-2.359	89.727	-24.181	9.196
75.44	776.12	-2.374	89.726	-24.327	9.196
75.51	776.90	-2.391	89.726	-24.505	9.196
75.59	777.68	-2.406	89.725	-24.657	9.196
75.67	778.46	-2.422	89.724	-24.825	9.195
75.75	779.24	-2.439	89.724	-24.995	9.195
75.83	780.02	-2.456	89.723	-25.166	9.195
75.90	780.80	-2.470	89.722	-25.319	9.195
75.98	781.58	-2.487	89.722	-25.483	9.195
76.06	782.36	-2.503	89.721	-25.648	9.195
76.14	783.14	-2.517	89.720	-25.797	9.195
76.22	783.93	-2.534	89.720	-25.973	9.195
76.30	784.71	-2.550	89.719	-26.137	9.195
76.38	785.49	-2.568	89.718	-26.320	9.195
76.45	786.27	-2.585	89.718	-26.494	9.195
76.53	787.05	-2.602	89.717	-26.671	9.195
76.61	787.83	-2.620	89.716	-26.856	9.195
76.69	788.60	-2.637	89.715	-27.029	9.195
76.77	789.38	-2.655	89.715	-27.209	9.195
76.85	790.16	-2.671	89.714	-27.374	9.194
76.92	790.94	-2.689	89.713	-27.558	9.194
77.00	791.72	-2.708	89.712	-27.752	9.194
77.08	792.50	-2.724	89.712	-27.919	9.194
77.16	793.28	-2.740	89.711	-28.082	9.194
77.24	794.06	-2.757	89.710	-28.257	9.194
77.31	794.84	-2.773	89.709	-28.422	9.194
77.39	795.62	-2.791	89.709	-28.608	9.194
77.47	796.40	-2.809	89.708	-28.791	9.194
77.55	797.18	-2.826	89.707	-28.967	9.194
77.63	797.97	-2.841	89.706	-29.119	9.194
77.71	798.75	-2.858	89.705	-29.293	9.194
77.79	799.53	-2.874	89.704	-29.459	9.193
77.86	800.31	-2.892	89.704	-29.641	9.193
77.94	801.09	-2.909	89.703	-29.815	9.193
78.02	801.87	-2.928	89.702	-30.005	9.193
78.10	802.66	-2.946	89.701	-30.195	9.193
78.18	803.44	-2.966	89.700	-30.393	9.193
78.25	804.22	-2.984	89.699	-30.580	9.193
78.33	805.00	-3.004	89.698	-30.783	9.193
78.41	805.78	-3.022	89.697	-30.967	9.193
78.49	806.55	-3.039	89.696	-31.143	9.193
78.57	807.33	-3.058	89.695	-31.338	9.192
78.65	808.11	-3.078	89.694	-31.540	9.192
78.73	808.89	-3.096	89.693	-31.730	9.192
78.80	809.67	-3.116	89.692	-31.932	9.192
78.88	810.45	-3.134	89.691	-32.120	9.192
78.96	811.23	-3.152	89.690	-32.302	9.192
79.04	812.01	-3.171	89.689	-32.501	9.192
79.12	812.79	-3.190	89.689	-32.696	9.192
79.20	813.57	-3.209	89.688	-32.884	9.192
79.27	814.35	-3.228	89.687	-33.083	9.192
79.35	815.14	-3.246	89.686	-33.265	9.192
79.43	815.92	-3.264	89.685	-33.456	9.191
79.51	816.70	-3.285	89.684	-33.667	9.191
79.59	817.48	-3.305	89.683	-33.870	9.191
79.66	818.26	-3.324	89.682	-34.070	9.191
79.74	819.04	-3.345	89.681	-34.283	9.191
79.82	819.82	-3.366	89.680	-34.494	9.191
79.90	820.60	-3.385	89.679	-34.692	9.191
79.98	821.38	-3.404	89.678	-34.886	9.191
80.06	822.16	-3.425	89.678	-35.103	9.191
80.14	822.94	-3.446	89.677	-35.312	9.191
80.21	823.72	-3.465	89.676	-35.510	9.191
80.29	824.50	-3.484	89.675	-35.702	9.190
80.37	825.28	-3.503	89.674	-35.906	9.190
80.45	826.06	-3.523	89.673	-36.102	9.190
80.53	826.84	-3.543	89.672	-36.309	9.190
80.60	827.62	-3.563	89.674	-36.517	9.190
80.68	828.40	-3.582	89.682	-36.709	9.191
80.76	829.18	-3.602	89.687	-36.913	9.192
80.84	829.96	-3.624	89.690	-37.136	9.192
80.92	830.74	-3.643	89.692	-37.336	9.192
81.00	831.52	-3.663	89.693	-37.545	9.192
81.08	832.30	-3.682	89.693	-37.739	9.192
81.15	833.08	-3.703	89.693	-37.947	9.192
81.23	833.86	-3.723	89.692	-38.160	9.192
81.31	834.64	-3.745	89.692	-38.379	9.192
81.39	835.42	-3.768	89.691	-38.613	9.192
81.47	836.20	-3.788	89.690	-38.817	9.192
81.55	836.98	-3.809	89.689	-39.038	9.192
81.62	837.76	-3.833	89.687	-39.284	9.192
81.70	838.54	-3.855	89.686	-39.504	9.192
81.78	839.32	-3.876	89.685	-39.720	9.191
81.86	840.10	-3.897	89.684	-39.936	9.191
81.94	840.88	-3.917	89.683	-40.140	9.191
82.01	841.66	-3.938	89.681	-40.359	9.191
82.09	842.44	-3.958	89.680	-40.568	9.191
82.17	843.22	-3.978	89.679	-40.771	9.191
82.25	844.00	-4.000	89.677	-40.995	9.191
82.33	844.78	-4.020	89.676	-41.197	9.191
82.41	845.56	-4.042	89.675	-41.421	9.190
82.49	846.34	-4.061	89.674	-41.622	9.190
82.56	847.12	-4.082	89.673	-41.830	9.190
82.64	847.90	-4.104	89.671	-42.057	9.190
82.72	848.68	-4.124	89.670	-42.270	9.190
82.80	849.46	-4.144	89.669	-42.472	9.190
82.88	850.24	-4.167	89.668	-42.708	9.190
82.95	851.02	-4.189	89.666	-42.934	9.190
83.03	851.80	-4.211	89.665	-43.157	9.189
83.11	852.58	-4.234	89.664	-43.390	9.189
83.19	853.36	-4.253	89.662	-43.590	9.189
83.27	854.14	-4.276	89.661	-43.825	9.189
83.35	854.92	-4.297	89.660	-44.041	9.189
83.43	855.70	-4.319	89.659	-44.266	9.189
83.50	856.48	-4.340	89.657	-44.482	9.189
83.58	857.26	-4.362	89.656	-44.708	9.189
83.66	858.04	-4.383	89.655	-44.924	9.188
83.74	858.82	-4.406	89.654	-45.160	9.188
83.82	859.60	-4.427	89.653	-45.374	9.188
83.90	860.38	-4.450	89.651	-45.602	9.188
83.97	861.16	-4.470	89.650	-45.816	9.188
84.05	861.94	-4.491	89.649	-46.031	9.188
84.13	862.72	-4.514	89.648	-46.258	9.188
84.21	863.50	-4.535	89.647	-46.479	9.188
84.29	864.28	-4.557	89.646	-46.700	9.187
84.36	865.06	-4.579	89.644	-46.928	9.187
84.44	865.84	-4.601	89.643	-47.157	9.187
84.52	866.62	-4.623	89.642	-47.382	9.187
84.60	867.40	-4.646	89.641	-47.610	9.187
84.68	868.18	-4.669	89.640	-47.851	9.187
84.76	868.96	-4.691	89.639	-48.076	9.187
84.84	869.74	-4.712	89.637	-48.296	9.187
84.91	870.52	-4.737	89.636	-48.547	9.186
84.99	871.30	-4.758	89.635	-48.766	9.186
85.07	872.08	-4.781	89.634	-49.000	9.186
85.15	872.86	-4.803	89.633	-49.223	9.186
85.23	873.64	-4.826	89.632	-49.457	9.186
85.30	874.42	-4.848	89.630	-49.689	9.186
85.38	875.20	-4.871	89.629	-49.921	9.186
85.46	875.97	-4.894	89.628	-50.156	9.186
85.54	876.75	-4.916	89.627	-50.381	9.185
85.62	877.53	-4.939	89.626	-50.617	9.185
85.70	878.31	-4.961	89.625	-50.843	9.185
85.78	879.09	-4.984	89.624	-51.082	9.185
85.85	879.88	-5.006	89.623	-51.303	9.185
85.93	880.66	-5.029	89.623	-51.536	9.185
86.01	881.44	-5.052	89.623	-51.774	9.185
86.09	882.22	-5.074	89.622	-51.999	9.185
86.17	883.00	-5.099	89.622	-52.254	9.185
86.25	883.78	-5.120	89.622	-52.478	9.185
86.32	884.56	-5.144	89.621	-52.719	9.185
86.40	885.34	-5.168	89.620	-52.968	9.185
86.48	886.11	-5.191	89.620	-53.200	9.185
86.56	886.89	-5.214	89.621	-53.433	9.185
86.64	887.67	-5.237	89.621	-53.668	9.185
86.71	888.45	-5.259	89.621	-53.898	9.185
86.79	889.23	-5.282	89.621	-54.133	9.185
86.87	890.01	-5.303	89.621	-54.353	9.185
86.95	890.79	-5.327	89.620	-54.589	9.185
87.03	891.57	-5.350	89.619	-54.825	9.185
87.11	892.35	-5.371	89.619	-55.048	9.185
87.19	893.13	-5.393	89.618	-55.272	9.185
87.26	893.91	-5.415	89.617	-55.491	9.185
87.34	894.69	-5.438	89.616	-55.727	9.184
87.42	895.47	-5.459	89.615	-55.952	9.184
87.50	896.25	-5.482	89.614	-56.182	9.184
87.58	897.04	-5.504	89.613	-56.405	9.184
87.65	897.82	-5.526	89.612	-56.638	9.184
87.73	898.60	-5.550	89.611	-56.882	9.184
87.81	899.38	-5.573	89.610	-57.112	9.184
87.89	900.16	-5.595	89.609	-57.341	9.184
87.97	900.94	-5.618	89.608	-57.581	9.184
88.05	901.72	-5.642	89.607	-57.821	9.183
88.13	902.50	-5.664	89.606	-58.048	9.183
88.20	903.28	-5.688	89.605	-58.298	9.183
88.28	904.06	-5.710	89.604	-58.522	9.183
88.36	904.84	-5.733	89.603	-58.760	9.183
88.44	905.62	-5.757	89.602	-59.005	9.183
88.52	906.40	-5.780	89.601	-59.233	9.183
88.60	907.18	-5.800	89.600	-59.446	9.183
88.67	907.96	-5.823	89.600	-59.679	9.183
88.75	908.74	-5.845	89.599	-59.900	9.183
88.83	909.52	-5.868	89.598	-60.137	9.183
88.91	910.30	-5.891	89.597	-60.370	9.182
88.99	911.08	-5.911	89.596	-60.583	9.182
89.06	911.86	-5.934	89.595	-60.814	9.182
89.14	912.64	-5.955	89.595	-61.032	9.182
89.22	913.42	-5.979	89.594	-61.272	9.182
89.30	914.21	-6.002	89.593	-61.515	9.182
89.38	914.99	-6.024	89.592	-61.739	9.182
89.46	915.77	-6.048	89.591	-61.981	9.182
89.54	916.54	-6.072	89.591	-62.231	9.182
89.61	917.32	-6.094	89.590	-62.457	9.182
89.69	918.10	-6.117	89.589	-62.690	9.182
89.77	918.88	-6.141	89.588	-62.933	9.182
89.85	919.66	-6.163	89.587	-63.158	9.181
89.93	920.44	-6.185	89.586	-63.388	9.181
90.00	921.22	-6.207	89.586	-63.610	9.181
90.08	922.00	-6.228	89.585	-63.831	9.181
90.16	922.79	-6.249	89.584	-64.048	9.181
90.24	923.57	-6.272	89.584	-64.283	9.181
90.32	924.35	-6.295	89.583	-64.518	9.181
90.40	925.13	-6.317	89.582	-64.743	9.181
90.48	925.91	-6.340	89.581	-64.972	9.181
90.55	926.69	-6.362	89.580	-65.202	9.181
90.63	927.47	-6.384	89.580	-65.430	9.181
90.71	928.25	-6.406	89.579	-65.653	9.181
90.79	929.03	-6.428	89.578	-65.882	9.181
90.87	929.81	-6.451	89.577	-66.115	9.180
90.95	930.59	-6.473	89.577	-66.344	9.180
91.02	931.38	-6.498	89.576	-66.591	9.180
91.10	932.15	-6.522	89.575	-66.837	9.180
91.18	932.94	-6.544	89.574	-67.066	9.180
91.26	933.71	-6.566	89.574	-67.295	9.180
91.34	934.49	-6.589	89.573	-67.533	9.180
91.41	935.27	-6.613	89.572	-67.772	9.180
91.49	936.05	-6.634	89.572	-67.994	9.180
91.57	936.83	-6.657	89.571	-68.225	9.180
91.65	937.61	-6.680	89.570	-68.464	9.180
91.73	938.39	-6.702	89.570	-68.691	9.180
91.81	939.17	-6.726	89.570	-68.934	9.180
91.89	939.95	-6.748	89.569	-69.153	9.180
91.96	940.74	-6.770	89.569	-69.383	9.180
92.04	941.51	-6.792	89.569	-69.608	9.180
92.12	942.30	-6.813	89.568	-69.828	9.179
92.20	943.08	-6.837	89.567	-70.065	9.179
92.28	943.86	-6.857	89.567	-70.276	9.179
92.35	944.64	-6.879	89.566	-70.503	9.179
92.43	945.42	-6.903	89.565	-70.741	9.179
92.51	946.20	-6.925	89.564	-70.967	9.179
92.59	946.98	-6.948	89.563	-71.206	9.179
92.67	947.76	-6.970	89.562	-71.432	9.179
92.75	948.55	-6.993	89.561	-71.670	9.179
92.83	949.33	-7.016	89.561	-71.901	9.179
92.90	950.11	-7.039	89.560	-72.136	9.179
92.98	950.88	-7.064	89.559	-72.392	9.179
93.06	951.67	-7.087	89.558	-72.630	9.178
93.14	952.44	-7.110	89.557	-72.864	9.178
93.22	953.22	-7.133	89.557	-73.104	9.178
93.30	954.00	-7.156	89.556	-73.341	9.178
93.37	954.78	-7.178	89.555	-73.566	9.178
93.45	955.56	-7.203	89.554	-73.820	9.178
93.53	956.34	-7.224	89.553	-74.033	9.178
93.61	957.13	-7.246	89.553	-74.260	9.178
93.69	957.91	-7.268	89.552	-74.488	9.178
93.76	958.69	-7.291	89.551	-74.719	9.178
93.84	959.47	-7.314	89.550	-74.962	9.178
93.92	960.25	-7.337	89.550	-75.196	9.178
94.00	961.03	-7.361	89.549	-75.436	9.178
94.08	961.81	-7.384	89.548	-75.680	9.177
94.16	962.59	-7.407	89.547	-75.907	9.177
94.24	963.37	-7.433	89.546	-76.173	9.177
94.31	964.16	-7.456	89.546	-76.412	9.177
94.39	964.93	-7.481	89.545	-76.665	9.177
94.47	965.71	-7.504	89.544	-76.901	9.177
94.55	966.49	-7.528	89.543	-77.149	9.177
94.63	967.27	-7.552	89.542	-77.395	9.177
94.70	968.05	-7.576	89.541	-77.647	9.177
94.78	968.83	-7.600	89.541	-77.892	9.177
94.86	969.61	-7.624	89.540	-78.136	9.177
94.94	970.39	-7.648	89.539	-78.378	9.176
95.02	971.17	-7.671	89.538	-78.620	9.176
95.10	971.96	-7.695	89.537	-78.860	9.176
95.18	972.74	-7.719	89.537	-79.110	9.176
95.25	973.52	-7.743	89.536	-79.360	9.176
95.33	974.30	-7.766	89.535	-79.590	9.176
95.41	975.08	-7.791	89.534	-79.851	9.176
95.49	975.86	-7.813	89.534	-80.075	9.176
95.57	976.64	-7.837	89.533	-80.317	9.176
95.65	977.42	-7.861	89.532	-80.568	9.176
95.72	978.20	-7.885	89.531	-80.810	9.176
95.80	978.99	-7.910	89.530	-81.065	9.176
95.88	979.77	-7.934	89.529	-81.309	9.176
95.96	980.54	-7.960	89.529	-81.577	9.175
96.04	981.33	-7.984	89.528	-81.830	9.175
96.11	982.11	-8.008	89.527	-82.072	9.175
96.19	982.89	-8.032	89.526	-82.314	9.175
96.27	983.66	-8.057	89.525	-82.578	9.175
96.35	984.45	-8.082	89.524	-82.826	9.175
96.43	985.23	-8.105	89.524	-83.066	9.175
96.51	986.01	-8.129	89.523	-83.314	9.175
96.59	986.79	-8.155	89.522	-83.573	9.175
96.66	987.57	-8.179	89.521	-83.819	9.175
96.74	988.35	-8.202	89.521	-84.060	9.175
96.82	989.13	-8.227	89.520	-84.319	9.175
96.90	989.91	-8.250	89.519	-84.555	9.174
96.98			89.518		9.174
97.00			89.518		9.174