File: Data/KMK242/TGA/KMK242_1000C_Air.txt
Filename	kmk242_1000c_air_01172023
Instrument name	0650-0588 (172.23.191.35)
Operator	Kyle Kirkpatrick
rundate	1/17/2023
Sample name	KMK242_1000C_Air_01172023
proceduresegments	Blend Channel B (Air) at 100% with Channel A (N2); Equilibrate 30.00 °C; Ramp 10.00 °C/min to 1000.00 °C
[File Parameters]
Run date	1/17/2023 3:34:19 PM
Trios version	5.5.1.5
Original File Name	C:\Users\ucsdi\OneDrive\Desktop\Data\Rinehart\Kyle\Jan 17 2023\KMK242_1000C_Air_01172023.tri
Current File Name	c:\users\ucsdi\onedrive\desktop\data\rinehart\kyle\jan 17 2023\kmk242_1000c_air_01172023.tri
User at run start	DESKTOP-JSQIMO4\ucsdi
[Procedure]
Procedure Name
Sample Name	KMK242_1000C_Air_01172023
Sample Mass	3.892818 mg
Pan Number	4
Reference Pan Number	30
Pan Type	Alumina 90 ul
Comments
Project Name
Operator	Kyle Kirkpatrick
Skip Weight Stabilization	False
Enable Air Cool	True
Air Cool Until Temperature Is Below	50
End of Test Delay	0
Stop on Gas Flow Error	No
Sample mass pre-weigh	Not Available
[Signal List]
Signal #1	Time (min)
Signal #2	Temperature (°C)
Signal #3	Sample Flow (mL/min)
Signal #4	Balance Flow (mL/min)
Signal #5	Set Point (°C)
Signal #6	Power Requested (W)
Signal #7	Power Delivered (W)
Signal #8	Temperature Rate (°C/min)
Signal #9	Weight (mg)
Signal #10	Heat Flow (mW)
Signal #11	Weight Corrected Heat Flow (W/g)
Signal #12	Weight Change (%)
Signal #13	Temperature Difference (°C)
Signal #14	Channel A Flow (mL/min)
Signal #15	Channel A Flow (%)
Signal #16	Channel B Flow (mL/min)
Signal #17	Channel B Flow (%)
[Configuration]
Company Name
Instrument Name	0650-0588
Instrument Type	SDT650
Serial Number	0650-0588
IP	172.23.191.35
Location of Instrument	MFG
DisplayType	TianmaV2andV3
Sample Interval 	0.1 s/pt
Gas 1	Nitrogen
Gas 2	Air
Gas 3	Oxygen
Gas 4	Nitrogen
Total Sample Flow	100
Channel B	0%
Channel A Gas Selected	1
Channel B Gas Selected	4
Thermocouple Type	Type R
Exotherm Direction	Up
Sampling Mode	Single Sample Mode
[Versions]
Common IDD Version	1
Cortex Version	VER 1.3.3.11
Driver	5.0.0.7
GDM Version	1.2.1.2
Blending GDM Version	1.2.1.2
Blending GDM Bootloader	2.0.0.5
TouchscreenVersion	1.0.3.1817
Transducer Version	1.1.0.32
Transducer Bootloader	2.0.0.5
PCU Version	1.2.0.15
PCU Bootloader	2.0.0.5
AutoSampler Version	2.0.4.19
Auto Sampler Bootloader	2.0.0.5
[Experiment Logs]
Experiment Log Entry # 1	Blending segment primary gas 4, percent 0, secondary gas 2
Experiment Log Entry # 3	Equilibrate Segment 30 (C) Started
Experiment Log Entry # 5	Ramp Segment 10 C/min to 1000 C Started
[Method Log]
Method Log Entry # 1	Blend Channel B at 100% with Channel A
Method Log Entry # 2	Equilibrate 30 °C
Method Log Entry # 3	(Ramp 568747) Ramp 10 °C/minute to 1000 °C
[Room Temperature Calibration]
Date Applied	2/24/2021 3:27:30 AM
Measured	22.351
Correct	22.200
[Furnace Room Temperature Calibration]
Date Applied	2/24/2021 3:27:30 AM
Measured	24.159
Correct	22.200
[DTA Signal Setup]
Date Applied	1/11/2023 5:48:48 PM
Description	From 200.000 °C to 1,450.000 °C at 20.000°C/min
Source Files 1	C:\Users\ucsdi\OneDrive\Desktop\Data\Sailor\Ricardo\Calibrations\1-11-23\Weight Calibration.tri
[Weight Calibration]
Date Applied	1/11/2023 5:48:48 PM
Reference Beam Weight	4892.573
Reference Beam Weight at 200 °C	435.1747
Reference Beam Gain	0.09938934
Sample Beam Weight	5794.918
Sample Beam Weight at 200 °C	439.0667
Sample Beam Gain	0.09625536
Weight Ratio	0.9274598
Reference Weight	341.1444
Sample Weight	336.5152
[Heat Flow Calibration]
Date Applied	1/12/2023 4:18:26 AM
Description	From 100.000 °C to 1,450.000 °C at 20.000°C/min
Source Files 1	C:\Users\ucsdi\OneDrive\Desktop\Data\Sailor\Ricardo\Calibrations\1-11-23\Heat Flow Sapphire Calibration(1).tri
Source Files 2	C:\Users\ucsdi\OneDrive\Desktop\Data\Sailor\Ricardo\Calibrations\1-11-23\Heat Flow Sapphire Calibration.tri
[Temperature Calibration]
Date Applied	1/11/2023 9:24:14 PM
Description	From 107.000 °C to 227.000 °C at 10.000°C/min
Gas Type	Nitrogen
Pan Type	Alumina 90 ul
Source Files 1	C:\Users\ucsdi\OneDrive\Desktop\Data\Sailor\Ricardo\Calibrations\1-11-23\Indium.tri
Source Files 2	C:\Users\ucsdi\OneDrive\Desktop\Data\Sailor\Ricardo\Calibrations\1-11-23\Zinc.tri
Source Files 3	C:\Users\ucsdi\OneDrive\Desktop\Data\Sailor\Ricardo\Calibrations\1-11-23\Tin.tri
Measured 1	155.275
Known 1	156.6
Measured 2	230.5534
Known 2	231.93
Measured 3	418.0948
Known 3	419.53
[Dual Weight]
Date Applied	1/12/2023 4:18:26 AM
[Dual DeltaT]
Date Applied	1/12/2023 4:18:26 AM
[Cell Constant Calibration]
Date Applied	4/21/2022 4:38:29 AM
Description	From 370.000 °C to 480.000 °C at 10.000°C/min
Gas Type	Nitrogen
Pan Type	Alumina 90 ul
Source Files 1	C:\Users\ucsdi\OneDrive\Desktop\Sailor\Ricardo\Calibrations\Zinc(2).tri
Cell Constant	1.029587
Temperature	419.53
[Rev Cp Calibration]
Date Applied	1/12/2023 5:11:31 PM
Description	From 210.000 °C to 1,500.000 °C at 2.000°C/min
Gas Type	Nitrogen
Pan Type	Alumina 90 ul
Source Files 1	C:\Users\ucsdi\OneDrive\Desktop\Data\Sailor\Ricardo\Calibrations\1-11-23\Sappphire calibration.tri
[step]
Ramp 10.00 °C/min to 1000.00 °C
Time	Temperature	Heat Flow (Normalized)	Weight	Heat Flow	Weight
min	°C	W/g	%	mW	mg
0.00			99.489		3.873
0.08	31.10	1.594	99.489	6.206	3.873
0.15	31.09	1.594	99.489	6.206	3.873
0.23	31.09	1.594	99.491	6.206	3.873
0.31	31.10	1.593	99.494	6.201	3.873
0.38	31.15	1.586	99.500	6.175	3.873
0.46	31.26	1.567	99.509	6.098	3.874
0.54	31.45	1.537	99.522	5.984	3.874
0.61	31.71	1.502	99.537	5.846	3.875
0.69	32.06	1.461	99.551	5.688	3.875
0.77	32.49	1.417	99.565	5.515	3.876
0.84	33.00	1.371	99.577	5.338	3.876
0.92	33.58	1.326	99.587	5.162	3.877
1.00	34.23	1.282	99.596	4.989	3.877
1.07	34.94	1.242	99.603	4.833	3.877
1.15	35.69	1.206	99.610	4.694	3.878
1.23	36.50	1.178	99.615	4.586	3.878
1.30	37.33	1.156	99.618	4.499	3.878
1.38	38.19	1.139	99.622	4.435	3.878
1.46	39.06	1.127	99.624	4.388	3.878
1.53	39.95	1.122	99.625	4.368	3.878
1.61	40.84	1.118	99.627	4.352	3.878
1.69	41.73	1.117	99.628	4.347	3.878
1.76	42.61	1.117	99.629	4.350	3.878
1.84	43.49	1.122	99.630	4.368	3.878
1.92	44.35	1.131	99.630	4.402	3.878
1.99	45.20	1.143	99.630	4.450	3.878
2.07	46.03	1.160	99.630	4.516	3.878
2.15	46.85	1.178	99.629	4.586	3.878
2.22	47.65	1.196	99.629	4.657	3.878
2.30	48.44	1.214	99.628	4.727	3.878
2.38	49.22	1.236	99.627	4.810	3.878
2.45	49.98	1.254	99.626	4.880	3.878
2.53	50.74	1.277	99.624	4.971	3.878
2.61	51.48	1.297	99.622	5.050	3.878
2.68	52.22	1.320	99.620	5.138	3.878
2.76	52.95	1.343	99.618	5.228	3.878
2.84	53.68	1.362	99.617	5.302	3.878
2.91	54.41	1.385	99.614	5.390	3.878
2.99	55.13	1.408	99.612	5.480	3.878
3.07	55.86	1.430	99.610	5.565	3.878
3.14	56.59	1.451	99.608	5.650	3.878
3.22	57.31	1.473	99.606	5.734	3.877
3.30	58.04	1.495	99.605	5.819	3.877
3.37	58.78	1.518	99.603	5.909	3.877
3.45	59.51	1.539	99.601	5.991	3.877
3.53	60.25	1.560	99.600	6.074	3.877
3.60	60.99	1.580	99.598	6.153	3.877
3.68	61.74	1.603	99.595	6.240	3.877
3.76	62.49	1.625	99.593	6.324	3.877
3.83	63.25	1.643	99.590	6.397	3.877
3.91	64.00	1.665	99.587	6.481	3.877
3.99	64.76	1.684	99.584	6.556	3.877
4.06	65.53	1.705	99.581	6.638	3.877
4.14	66.29	1.728	99.578	6.726	3.876
4.22	67.06	1.748	99.575	6.806	3.876
4.29	67.83	1.767	99.571	6.878	3.876
4.37	68.60	1.787	99.567	6.956	3.876
4.45	69.37	1.807	99.564	7.035	3.876
4.52	70.14	1.825	99.560	7.105	3.876
4.60	70.91	1.847	99.555	7.192	3.876
4.68	71.68	1.866	99.551	7.266	3.875
4.75	72.46	1.888	99.547	7.348	3.875
4.83	73.23	1.907	99.542	7.424	3.875
4.91	74.00	1.927	99.537	7.502	3.875
4.98	74.77	1.946	99.532	7.576	3.875
5.06	75.53	1.967	99.527	7.655	3.874
5.14	76.30	1.985	99.522	7.728	3.874
5.21	77.07	2.006	99.517	7.808	3.874
5.29	77.84	2.026	99.513	7.888	3.874
5.37	78.60	2.044	99.508	7.957	3.874
5.44	79.37	2.064	99.503	8.035	3.873
5.52	80.14	2.084	99.498	8.112	3.873
5.60	80.90	2.103	99.493	8.187	3.873
5.67	81.66	2.122	99.488	8.260	3.873
5.75	82.43	2.140	99.483	8.331	3.873
5.83	83.19	2.160	99.478	8.408	3.872
5.90	83.96	2.178	99.473	8.477	3.872
5.98	84.72	2.198	99.467	8.556	3.872
6.06	85.49	2.218	99.463	8.636	3.872
6.13	86.25	2.236	99.458	8.704	3.872
6.21	87.02	2.257	99.453	8.785	3.872
6.29	87.78	2.275	99.448	8.858	3.871
6.36	88.55	2.294	99.443	8.932	3.871
6.44	89.31	2.314	99.438	9.008	3.871
6.52	90.08	2.335	99.432	9.091	3.871
6.59	90.84	2.355	99.427	9.169	3.871
6.67	91.61	2.374	99.422	9.243	3.870
6.75	92.38	2.393	99.417	9.316	3.870
6.82	93.14	2.414	99.412	9.397	3.870
6.90	93.91	2.432	99.407	9.468	3.870
6.98	94.68	2.452	99.403	9.547	3.870
7.05	95.44	2.472	99.398	9.624	3.869
7.13	96.21	2.492	99.393	9.702	3.869
7.21	96.98	2.513	99.388	9.781	3.869
7.28	97.75	2.534	99.384	9.864	3.869
7.36	98.52	2.554	99.379	9.941	3.869
7.44	99.28	2.573	99.374	10.016	3.868
7.51	100.05	2.592	99.369	10.091	3.868
7.59	100.82	2.612	99.365	10.170	3.868
7.67	101.59	2.632	99.360	10.246	3.868
7.74	102.36	2.653	99.355	10.327	3.868
7.82	103.13	2.674	99.350	10.411	3.868
7.90	103.89	2.693	99.345	10.485	3.867
7.97	104.66	2.714	99.340	10.565	3.867
8.05	105.43	2.735	99.336	10.648	3.867
8.13	106.20	2.755	99.331	10.724	3.867
8.20	106.97	2.777	99.327	10.810	3.867
8.28	107.74	2.797	99.322	10.889	3.866
8.36	108.50	2.817	99.318	10.967	3.866
8.43	109.27	2.838	99.313	11.049	3.866
8.51	110.04	2.858	99.309	11.126	3.866
8.59	110.81	2.879	99.305	11.209	3.866
8.66	111.58	2.902	99.301	11.296	3.866
8.74	112.35	2.922	99.297	11.376	3.865
8.82	113.11	2.943	99.293	11.456	3.865
8.89	113.88	2.962	99.289	11.532	3.865
8.97	114.65	2.984	99.286	11.615	3.865
9.05	115.42	3.004	99.282	11.694	3.865
9.12	116.19	3.026	99.279	11.779	3.865
9.20	116.96	3.048	99.275	11.865	3.865
9.28	117.72	3.069	99.271	11.947	3.864
9.35	118.49	3.090	99.267	12.027	3.864
9.43	119.26	3.111	99.263	12.110	3.864
9.51	120.03	3.130	99.259	12.186	3.864
9.58	120.80	3.153	99.255	12.272	3.864
9.66	121.56	3.175	99.251	12.360	3.864
9.74	122.33	3.195	99.248	12.438	3.864
9.81	123.10	3.217	99.244	12.522	3.863
9.89	123.87	3.239	99.240	12.609	3.863
9.97	124.64	3.260	99.237	12.692	3.863
10.04	125.41	3.280	99.234	12.767	3.863
10.12	126.17	3.301	99.231	12.850	3.863
10.20	126.94	3.325	99.228	12.942	3.863
10.27	127.71	3.346	99.225	13.024	3.863
10.35	128.48	3.368	99.221	13.111	3.863
10.43	129.25	3.390	99.218	13.196	3.862
10.50	130.01	3.412	99.215	13.283	3.862
10.58	130.78	3.434	99.212	13.370	3.862
10.66	131.55	3.456	99.208	13.453	3.862
10.73	132.32	3.477	99.205	13.534	3.862
10.81	133.09	3.499	99.202	13.620	3.862
10.89	133.85	3.522	99.199	13.712	3.862
10.96	134.62	3.544	99.196	13.795	3.862
11.04	135.39	3.565	99.193	13.878	3.861
11.12	136.16	3.587	99.190	13.965	3.861
11.19	136.92	3.609	99.188	14.048	3.861
11.27	137.69	3.632	99.185	14.138	3.861
11.35	138.46	3.653	99.182	14.220	3.861
11.42	139.23	3.676	99.179	14.311	3.861
11.50	140.00	3.699	99.176	14.401	3.861
11.58	140.77	3.722	99.174	14.488	3.861
11.65	141.53	3.744	99.171	14.576	3.861
11.73	142.30	3.767	99.169	14.662	3.860
11.81	143.07	3.790	99.166	14.753	3.860
11.88	143.84	3.812	99.164	14.840	3.860
11.96	144.61	3.834	99.162	14.926	3.860
12.04	145.37	3.858	99.159	15.019	3.860
12.11	146.14	3.881	99.157	15.108	3.860
12.19	146.91	3.902	99.155	15.189	3.860
12.27	147.67	3.926	99.153	15.283	3.860
12.34	148.44	3.950	99.151	15.376	3.860
12.42	149.21	3.974	99.148	15.469	3.860
12.50	149.98	3.997	99.146	15.559	3.860
12.57	150.75	4.020	99.143	15.650	3.859
12.65	151.51	4.044	99.141	15.742	3.859
12.73	152.28	4.066	99.139	15.830	3.859
12.80	153.05	4.091	99.137	15.926	3.859
12.88	153.82	4.116	99.135	16.021	3.859
12.96	154.59	4.139	99.134	16.113	3.859
13.03	155.35	4.162	99.131	16.202	3.859
13.11	156.12	4.186	99.129	16.296	3.859
13.19	156.89	4.211	99.128	16.393	3.859
13.26	157.66	4.235	99.126	16.486	3.859
13.34	158.42	4.260	99.124	16.582	3.859
13.42	159.19	4.283	99.122	16.672	3.859
13.49	159.96	4.308	99.120	16.772	3.859
13.57	160.73	4.333	99.118	16.866	3.858
13.65	161.49	4.357	99.116	16.959	3.858
13.72	162.26	4.382	99.114	17.060	3.858
13.80	163.03	4.407	99.112	17.157	3.858
13.88	163.80	4.433	99.111	17.255	3.858
13.95	164.56	4.457	99.109	17.350	3.858
14.03	165.33	4.482	99.107	17.449	3.858
14.11	166.10	4.509	99.106	17.551	3.858
14.18	166.87	4.533	99.104	17.645	3.858
14.26	167.63	4.559	99.102	17.748	3.858
14.34	168.40	4.585	99.101	17.847	3.858
14.41	169.17	4.612	99.099	17.953	3.858
14.49	169.94	4.637	99.097	18.050	3.858
14.57	170.71	4.663	99.095	18.152	3.858
14.64	171.47	4.690	99.094	18.256	3.858
14.72	172.24	4.717	99.092	18.362	3.857
14.80	173.01	4.744	99.090	18.466	3.857
14.87	173.78	4.771	99.089	18.573	3.857
14.95	174.55	4.796	99.087	18.671	3.857
15.03	175.31	4.826	99.085	18.785	3.857
15.10	176.08	4.853	99.084	18.893	3.857
15.18	176.85	4.881	99.082	19.001	3.857
15.26	177.62	4.909	99.081	19.109	3.857
15.33	178.39	4.937	99.079	19.220	3.857
15.41	179.15	4.966	99.078	19.332	3.857
15.49	179.92	4.995	99.077	19.443	3.857
15.56	180.69	5.023	99.075	19.552	3.857
15.64	181.46	5.052	99.074	19.666	3.857
15.72	182.23	5.082	99.073	19.783	3.857
15.79	183.00	5.112	99.071	19.900	3.857
15.87	183.77	5.141	99.070	20.014	3.857
15.95	184.53	5.170	99.068	20.127	3.857
16.02	185.30	5.201	99.067	20.246	3.856
16.10	186.07	5.231	99.065	20.362	3.856
16.18	186.84	5.262	99.064	20.483	3.856
16.25	187.61	5.292	99.062	20.599	3.856
16.33	188.38	5.321	99.061	20.715	3.856
16.41	189.15	5.351	99.060	20.830	3.856
16.48	189.91	5.382	99.058	20.952	3.856
16.56	190.68	5.415	99.057	21.078	3.856
16.64	191.45	5.444	99.055	21.194	3.856
16.71	192.22	5.476	99.053	21.318	3.856
16.79	192.99	5.507	99.051	21.438	3.856
16.87	193.76	5.540	99.049	21.567	3.856
16.94	194.53	5.573	99.047	21.694	3.856
17.02	195.30	5.604	99.044	21.815	3.856
17.10	196.07	5.637	99.042	21.943	3.856
17.17	196.83	5.670	99.040	22.072	3.855
17.25	197.60	5.702	99.037	22.196	3.855
17.33	198.37	5.734	99.034	22.321	3.855
17.40	199.14	5.767	99.031	22.450	3.855
17.48	199.91	5.800	99.028	22.580	3.855
17.56	200.68	5.833	99.024	22.708	3.855
17.63	201.45	5.867	99.020	22.840	3.855
17.71	202.22	5.902	99.017	22.974	3.855
17.79	202.99	5.935	99.013	23.105	3.854
17.86	203.76	5.970	99.009	23.242	3.854
17.94	204.53	6.004	99.005	23.372	3.854
18.02	205.30	6.039	99.000	23.507	3.854
18.09	206.07	6.074	98.996	23.645	3.854
18.17	206.85	6.108	98.991	23.776	3.854
18.25	207.62	6.142	98.987	23.908	3.853
18.32	208.39	6.177	98.982	24.045	3.853
18.40	209.16	6.213	98.976	24.186	3.853
18.48	209.93	6.248	98.971	24.322	3.853
18.55	210.70	6.284	98.965	24.464	3.853
18.63	211.47	6.320	98.960	24.604	3.852
18.71	212.24	6.358	98.954	24.750	3.852
18.78	213.01	6.393	98.947	24.886	3.852
18.86	213.78	6.430	98.941	25.031	3.852
18.94	214.56	6.468	98.933	25.179	3.851
19.01	215.33	6.505	98.926	25.321	3.851
19.09	216.10	6.541	98.919	25.463	3.851
19.17	216.87	6.577	98.911	25.603	3.850
19.24	217.64	6.616	98.902	25.755	3.850
19.32	218.41	6.656	98.894	25.910	3.850
19.40	219.18	6.695	98.886	26.061	3.849
19.47	219.95	6.733	98.877	26.211	3.849
19.55	220.73	6.772	98.867	26.364	3.849
19.63	221.50	6.811	98.857	26.516	3.848
19.70	222.27	6.853	98.847	26.677	3.848
19.78	223.04	6.893	98.836	26.834	3.848
19.86	223.81	6.934	98.825	26.994	3.847
19.93	224.58	6.975	98.813	27.153	3.847
20.01	225.36	7.018	98.802	27.318	3.846
20.09	226.13	7.060	98.789	27.483	3.846
20.16	226.90	7.103	98.776	27.651	3.845
20.24	227.67	7.147	98.763	27.821	3.845
20.32	228.44	7.189	98.749	27.987	3.844
20.39	229.22	7.235	98.735	28.163	3.844
20.47	229.99	7.279	98.720	28.335	3.843
20.55	230.76	7.326	98.705	28.520	3.842
20.62	231.53	7.372	98.689	28.696	3.842
20.70	232.31	7.419	98.673	28.881	3.841
20.78	233.08	7.466	98.657	29.063	3.841
20.85	233.85	7.515	98.639	29.254	3.840
20.93	234.63	7.562	98.621	29.438	3.839
21.01	235.40	7.612	98.603	29.632	3.838
21.08	236.17	7.663	98.584	29.832	3.838
21.16	236.95	7.714	98.564	30.031	3.837
21.24	237.72	7.766	98.544	30.232	3.836
21.31	238.50	7.819	98.523	30.438	3.835
21.39	239.27	7.871	98.501	30.640	3.834
21.47	240.05	7.924	98.479	30.846	3.834
21.54	240.82	7.980	98.456	31.064	3.833
21.62	241.60	8.035	98.432	31.280	3.832
21.70	242.37	8.090	98.408	31.493	3.831
21.77	243.15	8.146	98.383	31.711	3.830
21.85	243.92	8.203	98.357	31.932	3.829
21.93	244.70	8.260	98.331	32.154	3.828
22.00	245.47	8.317	98.304	32.377	3.827
22.08	246.25	8.375	98.277	32.603	3.826
22.16	247.03	8.433	98.249	32.829	3.825
22.23	247.80	8.492	98.220	33.057	3.824
22.31	248.58	8.551	98.190	33.288	3.822
22.39	249.35	8.610	98.160	33.517	3.821
22.46	250.13	8.669	98.128	33.745	3.820
22.54	250.90	8.728	98.096	33.975	3.819
22.62	251.68	8.786	98.063	34.203	3.817
22.69	252.45	8.846	98.030	34.438	3.816
22.77	253.23	8.905	97.995	34.664	3.815
22.85	254.01	8.962	97.960	34.886	3.813
22.92	254.78	9.018	97.923	35.107	3.812
23.00	255.56	9.077	97.886	35.333	3.811
23.08	256.33	9.131	97.848	35.547	3.809
23.15	257.10	9.183	97.810	35.746	3.808
23.23	257.88	9.236	97.770	35.953	3.806
23.31	258.65	9.287	97.730	36.152	3.804
23.38	259.42	9.336	97.688	36.345	3.803
23.46	260.20	9.383	97.646	36.527	3.801
23.54	260.97	9.428	97.603	36.702	3.800
23.61	261.74	9.471	97.559	36.869	3.798
23.69	262.51	9.512	97.514	37.029	3.796
23.77	263.28	9.549	97.468	37.172	3.794
23.84	264.05	9.585	97.422	37.315	3.792
23.92	264.82	9.620	97.375	37.450	3.791
24.00	265.58	9.650	97.327	37.565	3.789
24.07	266.35	9.678	97.278	37.675	3.787
24.15	267.11	9.702	97.229	37.768	3.785
24.23	267.88	9.722	97.178	37.847	3.783
24.30	268.64	9.742	97.127	37.923	3.781
24.38	269.41	9.756	97.076	37.979	3.779
24.46	270.17	9.770	97.024	38.032	3.777
24.53	270.93	9.782	96.971	38.078	3.775
24.61	271.69	9.791	96.917	38.115	3.773
24.69	272.45	9.799	96.863	38.147	3.771
24.76	273.21	9.806	96.808	38.171	3.769
24.84	273.97	9.805	96.753	38.171	3.766
24.92	274.73	9.805	96.697	38.170	3.764
24.99	275.49	9.802	96.641	38.156	3.762
25.07	276.24	9.789	96.584	38.109	3.760
25.15	277.00	9.780	96.527	38.073	3.758
25.22	277.76	9.765	96.470	38.015	3.755
25.30	278.51	9.748	96.414	37.946	3.753
25.38	279.27	9.732	96.358	37.885	3.751
25.45	280.02	9.715	96.301	37.819	3.749
25.53	280.78	9.698	96.243	37.751	3.747
25.61	281.53	9.676	96.184	37.667	3.744
25.68	282.28	9.657	96.125	37.592	3.742
25.76	283.04	9.635	96.065	37.506	3.740
25.84	283.79	9.612	96.005	37.416	3.737
25.91	284.54	9.586	95.944	37.315	3.735
25.99	285.30	9.563	95.884	37.225	3.733
26.07	286.05	9.536	95.822	37.124	3.730
26.14	286.80	9.511	95.761	37.025	3.728
26.22	287.56	9.484	95.699	36.919	3.725
26.30	288.31	9.458	95.638	36.818	3.723
26.37	289.06	9.430	95.576	36.711	3.721
26.45	289.82	9.403	95.513	36.603	3.718
26.53	290.57	9.374	95.451	36.490	3.716
26.60	291.32	9.344	95.388	36.373	3.713
26.68	292.07	9.313	95.326	36.254	3.711
26.76	292.83	9.283	95.263	36.137	3.708
26.83	293.58	9.252	95.200	36.016	3.706
26.91	294.33	9.220	95.137	35.891	3.704
26.99	295.08	9.186	95.075	35.758	3.701
27.06	295.83	9.150	95.012	35.620	3.699
27.14	296.58	9.116	94.949	35.488	3.696
27.22	297.34	9.080	94.887	35.348	3.694
27.29	298.09	9.044	94.824	35.208	3.691
27.37	298.84	9.008	94.762	35.066	3.689
27.45	299.59	8.970	94.701	34.918	3.687
27.52	300.34	8.932	94.639	34.769	3.684
27.60	301.09	8.893	94.578	34.617	3.682
27.68	301.85	8.853	94.517	34.462	3.679
27.75	302.60	8.814	94.456	34.310	3.677
27.83	303.35	8.775	94.396	34.160	3.675
27.91	304.10	8.734	94.336	34.001	3.672
27.98	304.85	8.696	94.276	33.853	3.670
28.06	305.60	8.657	94.216	33.698	3.668
28.14	306.35	8.618	94.157	33.547	3.665
28.21	307.11	8.579	94.099	33.397	3.663
28.29	307.86	8.539	94.041	33.242	3.661
28.37	308.61	8.502	93.983	33.098	3.659
28.44	309.36	8.463	93.926	32.946	3.656
28.52	310.11	8.426	93.868	32.800	3.654
28.60	310.86	8.388	93.812	32.651	3.652
28.67	311.62	8.349	93.755	32.501	3.650
28.75	312.37	8.311	93.700	32.352	3.648
28.83	313.12	8.273	93.645	32.203	3.645
28.90	313.87	8.234	93.590	32.052	3.643
28.98	314.63	8.198	93.536	31.913	3.641
29.06	315.38	8.157	93.482	31.755	3.639
29.13	316.13	8.119	93.429	31.604	3.637
29.21	316.88	8.081	93.376	31.459	3.635
29.29	317.63	8.043	93.324	31.308	3.633
29.36	318.39	8.004	93.273	31.160	3.631
29.44	319.14	7.965	93.222	31.008	3.629
29.52	319.89	7.925	93.172	30.851	3.627
29.59	320.64	7.886	93.122	30.700	3.625
29.67	321.39	7.847	93.073	30.547	3.623
29.75	322.15	7.806	93.025	30.389	3.621
29.82	322.90	7.765	92.977	30.227	3.619
29.90	323.65	7.722	92.930	30.061	3.618
29.98	324.40	7.680	92.884	29.896	3.616
30.05	325.15	7.637	92.839	29.728	3.614
30.13	325.90	7.594	92.795	29.563	3.612
30.21	326.66	7.550	92.751	29.392	3.611
30.28	327.41	7.507	92.708	29.222	3.609
30.36	328.16	7.463	92.667	29.051	3.607
30.44	328.91	7.416	92.626	28.870	3.606
30.51	329.66	7.371	92.586	28.694	3.604
30.59	330.41	7.324	92.547	28.512	3.603
30.67	331.16	7.277	92.509	28.330	3.601
30.74	331.91	7.231	92.472	28.148	3.600
30.82	332.66	7.182	92.436	27.960	3.598
30.90	333.41	7.136	92.401	27.778	3.597
30.97	334.16	7.088	92.366	27.594	3.596
31.05	334.91	7.041	92.333	27.409	3.594
31.13	335.66	6.991	92.301	27.217	3.593
31.20	336.42	6.943	92.270	27.028	3.592
31.28	337.17	6.895	92.240	26.840	3.591
31.36	337.92	6.846	92.211	26.649	3.590
31.43	338.67	6.798	92.182	26.464	3.588
31.51	339.42	6.749	92.155	26.272	3.587
31.59	340.17	6.703	92.128	26.093	3.586
31.66	340.92	6.656	92.102	25.911	3.585
31.74	341.67	6.608	92.077	25.725	3.584
31.82	342.42	6.562	92.054	25.547	3.583
31.89	343.17	6.517	92.031	25.369	3.583
31.97	343.93	6.471	92.008	25.189	3.582
32.05	344.68	6.424	91.987	25.006	3.581
32.12	345.43	6.378	91.967	24.828	3.580
32.20	346.18	6.334	91.948	24.658	3.579
32.28	346.93	6.291	91.929	24.491	3.579
32.35	347.69	6.249	91.911	24.324	3.578
32.43	348.44	6.207	91.894	24.161	3.577
32.51	349.19	6.165	91.877	23.998	3.577
32.58	349.94	6.124	91.862	23.839	3.576
32.66	350.70	6.085	91.847	23.689	3.575
32.74	351.45	6.045	91.832	23.534	3.575
32.81	352.20	6.008	91.818	23.388	3.574
32.89	352.96	5.971	91.804	23.245	3.574
32.97	353.71	5.935	91.791	23.106	3.573
33.04	354.47	5.900	91.779	22.968	3.573
33.12	355.22	5.865	91.767	22.831	3.572
33.20	355.98	5.833	91.756	22.706	3.572
33.27	356.73	5.800	91.745	22.577	3.571
33.35	357.49	5.768	91.734	22.456	3.571
33.43	358.24	5.740	91.724	22.343	3.571
33.50	359.00	5.709	91.714	22.224	3.570
33.58	359.76	5.679	91.704	22.105	3.570
33.66	360.51	5.650	91.696	21.996	3.570
33.73	361.27	5.623	91.687	21.891	3.569
33.81	362.03	5.597	91.679	21.788	3.569
33.89	362.78	5.570	91.671	21.682	3.569
33.96	363.54	5.545	91.663	21.587	3.568
34.04	364.30	5.520	91.655	21.489	3.568
34.12	365.06	5.497	91.648	21.399	3.568
34.19	365.82	5.474	91.641	21.310	3.567
34.27	366.57	5.453	91.634	21.228	3.567
34.35	367.33	5.430	91.628	21.136	3.567
34.42	368.09	5.409	91.621	21.058	3.567
34.50	368.85	5.387	91.615	20.972	3.566
34.58	369.61	5.369	91.610	20.899	3.566
34.65	370.37	5.350	91.604	20.827	3.566
34.73	371.12	5.329	91.599	20.743	3.566
34.81	371.88	5.310	91.594	20.670	3.566
34.88	372.64	5.293	91.589	20.604	3.565
34.96	373.40	5.276	91.584	20.538	3.565
35.04	374.16	5.260	91.580	20.475	3.565
35.11	374.92	5.242	91.575	20.405	3.565
35.19	375.68	5.226	91.571	20.344	3.565
35.27	376.44	5.210	91.567	20.283	3.565
35.34	377.20	5.193	91.563	20.217	3.564
35.42	377.96	5.177	91.559	20.154	3.564
35.50	378.72	5.165	91.555	20.105	3.564
35.57	379.48	5.151	91.552	20.051	3.564
35.65	380.24	5.134	91.548	19.986	3.564
35.73	381.00	5.122	91.545	19.939	3.564
35.80	381.76	5.108	91.542	19.883	3.564
35.88	382.52	5.093	91.539	19.825	3.563
35.96	383.28	5.080	91.536	19.775	3.563
36.03	384.04	5.071	91.533	19.739	3.563
36.11	384.80	5.057	91.530	19.684	3.563
36.19	385.56	5.043	91.528	19.631	3.563
36.26	386.32	5.030	91.525	19.581	3.563
36.34	387.08	5.019	91.523	19.537	3.563
36.42	387.84	5.005	91.520	19.485	3.563
36.49	388.60	4.996	91.518	19.449	3.563
36.57	389.36	4.983	91.516	19.397	3.563
36.65	390.13	4.973	91.513	19.359	3.562
36.72	390.89	4.963	91.511	19.319	3.562
36.80	391.65	4.949	91.509	19.266	3.562
36.88	392.41	4.938	91.506	19.222	3.562
36.95	393.17	4.927	91.504	19.178	3.562
37.03	393.93	4.916	91.502	19.139	3.562
37.11	394.69	4.907	91.500	19.103	3.562
37.18	395.45	4.898	91.498	19.065	3.562
37.26	396.21	4.884	91.496	19.013	3.562
37.34	396.98	4.874	91.494	18.973	3.562
37.41	397.74	4.864	91.493	18.936	3.562
37.49	398.50	4.854	91.491	18.895	3.562
37.57	399.26	4.843	91.489	18.852	3.562
37.64	400.02	4.833	91.488	18.816	3.561
37.72	400.79	4.822	91.486	18.772	3.561
37.80	401.55	4.812	91.485	18.733	3.561
37.87	402.31	4.802	91.483	18.695	3.561
37.95	403.07	4.791	91.481	18.649	3.561
38.03	403.84	4.782	91.480	18.615	3.561
38.10	404.60	4.771	91.478	18.574	3.561
38.18	405.36	4.763	91.477	18.540	3.561
38.26	406.12	4.752	91.475	18.497	3.561
38.33	406.88	4.740	91.474	18.454	3.561
38.41	407.65	4.731	91.472	18.418	3.561
38.49	408.41	4.721	91.471	18.379	3.561
38.56	409.17	4.712	91.469	18.341	3.561
38.64	409.93	4.699	91.468	18.293	3.561
38.72	410.70	4.688	91.467	18.250	3.561
38.79	411.46	4.679	91.465	18.213	3.561
38.87	412.22	4.668	91.464	18.174	3.561
38.95	412.98	4.658	91.462	18.133	3.560
39.02	413.75	4.648	91.461	18.095	3.560
39.10	414.51	4.637	91.459	18.050	3.560
39.18	415.27	4.626	91.458	18.007	3.560
39.25	416.03	4.615	91.456	17.966	3.560
39.33	416.80	4.607	91.455	17.936	3.560
39.41	417.56	4.597	91.453	17.896	3.560
39.48	418.32	4.586	91.451	17.852	3.560
39.56	419.08	4.578	91.450	17.821	3.560
39.64	419.84	4.566	91.448	17.776	3.560
39.71	420.61	4.556	91.447	17.735	3.560
39.79	421.37	4.545	91.446	17.692	3.560
39.87	422.13	4.533	91.445	17.648	3.560
39.94	422.89	4.523	91.444	17.609	3.560
40.02	423.66	4.513	91.443	17.570	3.560
40.10	424.42	4.505	91.441	17.538	3.560
40.17	425.18	4.493	91.440	17.491	3.560
40.25	425.94	4.483	91.439	17.453	3.560
40.33	426.71	4.475	91.437	17.420	3.559
40.40	427.47	4.464	91.436	17.379	3.559
40.48	428.23	4.454	91.434	17.339	3.559
40.56	428.99	4.441	91.433	17.289	3.559
40.63	429.76	4.432	91.432	17.251	3.559
40.71	430.52	4.419	91.430	17.204	3.559
40.79	431.28	4.410	91.429	17.168	3.559
40.86	432.04	4.401	91.428	17.134	3.559
40.94	432.81	4.390	91.427	17.088	3.559
41.02	433.57	4.381	91.426	17.055	3.559
41.09	434.33	4.372	91.425	17.019	3.559
41.17	435.09	4.361	91.424	16.977	3.559
41.25	435.85	4.351	91.423	16.936	3.559
41.32	436.62	4.341	91.421	16.897	3.559
41.40	437.38	4.331	91.419	16.860	3.559
41.48	438.14	4.319	91.418	16.813	3.559
41.55	438.91	4.310	91.417	16.776	3.559
41.63	439.67	4.299	91.416	16.736	3.559
41.71	440.43	4.290	91.414	16.700	3.559
41.78	441.19	4.278	91.413	16.654	3.559
41.86	441.96	4.268	91.411	16.615	3.558
41.94	442.72	4.259	91.410	16.580	3.558
42.01	443.48	4.248	91.409	16.536	3.558
42.09	444.24	4.238	91.408	16.499	3.558
42.17	445.01	4.227	91.406	16.454	3.558
42.24	445.77	4.216	91.406	16.413	3.558
42.32	446.53	4.205	91.405	16.370	3.558
42.40	447.29	4.196	91.404	16.335	3.558
42.47	448.06	4.185	91.403	16.292	3.558
42.55	448.82	4.175	91.402	16.252	3.558
42.63	449.58	4.165	91.401	16.214	3.558
42.70	450.35	4.154	91.400	16.171	3.558
42.78	451.11	4.146	91.398	16.138	3.558
42.86	451.87	4.136	91.397	16.100	3.558
42.93	452.63	4.127	91.395	16.065	3.558
43.01	453.40	4.115	91.394	16.018	3.558
43.09	454.16	4.104	91.393	15.978	3.558
43.16	454.92	4.095	91.392	15.940	3.558
43.24	455.69	4.082	91.390	15.889	3.558
43.32	456.45	4.070	91.389	15.845	3.558
43.39	457.21	4.062	91.388	15.813	3.558
43.47	457.97	4.051	91.387	15.770	3.558
43.55	458.74	4.040	91.386	15.729	3.557
43.62	459.50	4.028	91.384	15.679	3.557
43.70	460.26	4.017	91.383	15.639	3.557
43.78	461.03	4.007	91.382	15.599	3.557
43.85	461.79	3.996	91.381	15.557	3.557
43.93	462.55	3.985	91.380	15.513	3.557
44.01	463.31	3.973	91.378	15.467	3.557
44.08	464.08	3.962	91.377	15.422	3.557
44.16	464.84	3.954	91.376	15.393	3.557
44.24	465.60	3.943	91.375	15.348	3.557
44.31	466.37	3.931	91.373	15.303	3.557
44.39	467.13	3.921	91.372	15.265	3.557
44.47	467.89	3.910	91.371	15.223	3.557
44.54	468.65	3.898	91.370	15.174	3.557
44.62	469.42	3.885	91.369	15.125	3.557
44.70	470.18	3.877	91.367	15.093	3.557
44.77	470.94	3.865	91.366	15.046	3.557
44.85	471.70	3.853	91.365	15.001	3.557
44.93	472.47	3.844	91.363	14.964	3.557
45.00	473.23	3.835	91.362	14.927	3.557
45.08	473.99	3.825	91.361	14.890	3.557
45.16	474.75	3.813	91.359	14.842	3.556
45.23	475.52	3.801	91.358	14.798	3.556
45.31	476.28	3.790	91.357	14.755	3.556
45.39	477.04	3.779	91.355	14.712	3.556
45.46	477.80	3.768	91.354	14.668	3.556
45.54	478.57	3.756	91.353	14.622	3.556
45.62	479.33	3.746	91.351	14.583	3.556
45.69	480.09	3.735	91.350	14.539	3.556
45.77	480.86	3.726	91.349	14.506	3.556
45.85	481.62	3.716	91.347	14.464	3.556
45.92	482.38	3.705	91.346	14.422	3.556
46.00	483.15	3.693	91.345	14.377	3.556
46.08	483.91	3.684	91.344	14.340	3.556
46.15	484.67	3.672	91.342	14.295	3.556
46.23	485.44	3.661	91.341	14.253	3.556
46.31	486.20	3.650	91.339	14.211	3.556
46.38	486.96	3.640	91.338	14.171	3.556
46.46	487.72	3.627	91.337	14.119	3.556
46.54	488.49	3.617	91.335	14.080	3.556
46.61	489.25	3.605	91.334	14.032	3.555
46.69	490.01	3.595	91.333	13.993	3.555
46.77	490.78	3.585	91.332	13.955	3.555
46.84	491.54	3.571	91.330	13.903	3.555
46.92	492.30	3.560	91.329	13.858	3.555
47.00	493.07	3.550	91.327	13.819	3.555
47.07	493.83	3.536	91.326	13.763	3.555
47.15	494.59	3.523	91.325	13.713	3.555
47.23	495.36	3.511	91.323	13.667	3.555
47.30	496.12	3.499	91.322	13.620	3.555
47.38	496.88	3.488	91.321	13.576	3.555
47.46	497.65	3.475	91.320	13.528	3.555
47.53	498.41	3.464	91.319	13.484	3.555
47.61	499.17	3.452	91.317	13.437	3.555
47.69	499.93	3.441	91.316	13.396	3.555
47.76	500.70	3.425	91.315	13.333	3.555
47.84	501.46	3.415	91.313	13.295	3.555
47.92	502.22	3.401	91.312	13.241	3.555
47.99	502.99	3.389	91.311	13.194	3.555
48.07	503.75	3.378	91.310	13.149	3.555
48.15	504.51	3.365	91.309	13.099	3.554
48.22	505.28	3.352	91.308	13.048	3.554
48.30	506.04	3.338	91.306	12.994	3.554
48.38	506.81	3.326	91.305	12.946	3.554
48.45	507.57	3.313	91.304	12.896	3.554
48.53	508.33	3.299	91.303	12.842	3.554
48.61	509.10	3.285	91.302	12.789	3.554
48.68	509.86	3.275	91.301	12.749	3.554
48.76	510.62	3.263	91.300	12.702	3.554
48.84	511.38	3.247	91.299	12.642	3.554
48.91	512.15	3.236	91.298	12.598	3.554
48.99	512.91	3.223	91.296	12.545	3.554
49.07	513.67	3.210	91.295	12.496	3.554
49.14	514.44	3.197	91.294	12.446	3.554
49.22	515.20	3.184	91.293	12.396	3.554
49.30	515.96	3.168	91.291	12.333	3.554
49.37	516.73	3.157	91.289	12.291	3.554
49.45	517.49	3.144	91.288	12.240	3.554
49.53	518.25	3.132	91.287	12.193	3.554
49.60	519.02	3.116	91.285	12.130	3.554
49.68	519.78	3.102	91.284	12.074	3.554
49.76	520.54	3.089	91.283	12.025	3.553
49.83	521.31	3.079	91.282	11.984	3.553
49.91	522.07	3.065	91.281	11.930	3.553
49.99	522.83	3.050	91.280	11.872	3.553
50.06	523.60	3.035	91.279	11.813	3.553
50.14	524.36	3.021	91.278	11.762	3.553
50.22	525.12	3.008	91.276	11.709	3.553
50.29	525.89	2.993	91.276	11.650	3.553
50.37	526.65	2.978	91.275	11.593	3.553
50.45	527.41	2.962	91.274	11.530	3.553
50.52	528.18	2.947	91.272	11.474	3.553
50.60	528.94	2.934	91.271	11.421	3.553
50.68	529.70	2.921	91.270	11.369	3.553
50.75	530.46	2.905	91.270	11.309	3.553
50.83	531.23	2.892	91.269	11.256	3.553
50.91	531.99	2.873	91.268	11.186	3.553
50.98	532.75	2.860	91.266	11.135	3.553
51.06	533.52	2.844	91.265	11.072	3.553
51.14	534.28	2.829	91.264	11.012	3.553
51.21	535.04	2.815	91.262	10.959	3.553
51.29	535.80	2.800	91.261	10.900	3.553
51.37	536.57	2.786	91.259	10.846	3.553
51.44	537.33	2.770	91.257	10.782	3.552
51.52	538.10	2.755	91.256	10.724	3.552
51.60	538.86	2.738	91.255	10.658	3.552
51.67	539.62	2.723	91.253	10.599	3.552
51.75	540.39	2.709	91.252	10.545	3.552
51.83	541.15	2.697	91.251	10.498	3.552
51.90	541.92	2.682	91.249	10.440	3.552
51.98	542.68	2.666	91.248	10.378	3.552
52.06	543.44	2.647	91.247	10.305	3.552
52.13	544.20	2.631	91.245	10.244	3.552
52.21	544.96	2.615	91.244	10.181	3.552
52.29	545.73	2.600	91.243	10.121	3.552
52.36	546.49	2.588	91.242	10.077	3.552
52.44	547.26	2.575	91.240	10.025	3.552
52.52	548.02	2.560	91.239	9.967	3.552
52.59	548.78	2.548	91.237	9.918	3.552
52.67	549.55	2.537	91.236	9.878	3.552
52.75	550.31	2.521	91.235	9.815	3.552
52.82	551.08	2.510	91.234	9.772	3.552
52.90	551.84	2.498	91.233	9.726	3.552
52.98	552.60	2.489	91.232	9.690	3.551
53.05	553.37	2.481	91.230	9.659	3.551
53.13	554.13	2.475	91.229	9.634	3.551
53.21	554.90	2.471	91.227	9.619	3.551
53.28	555.66	2.468	91.225	9.606	3.551
53.36	556.43	2.467	91.224	9.603	3.551
53.44	557.19	2.469	91.222	9.611	3.551
53.51	557.96	2.473	91.220	9.629	3.551
53.59	558.73	2.486	91.218	9.679	3.551
53.67	559.50	2.516	91.217	9.794	3.551
53.74	560.28	2.552	91.215	9.934	3.551
53.82	561.05	2.602	91.214	10.128	3.551
53.90	561.83	2.662	91.212	10.363	3.551
53.97	562.61	2.742	91.211	10.675	3.551
54.05	563.39	2.834	91.209	11.031	3.551
54.13	564.17	2.941	91.207	11.447	3.551
54.20	564.96	3.060	91.205	11.911	3.550
54.28	565.74	3.180	91.203	12.380	3.550
54.36	566.53	3.290	91.201	12.808	3.550
54.43	567.31	3.375	91.199	13.138	3.550
54.51	568.08	3.420	91.197	13.315	3.550
54.59	568.85	3.434	91.195	13.369	3.550
54.66	569.61	3.422	91.193	13.323	3.550
54.74	570.37	3.372	91.191	13.126	3.550
54.82	571.12	3.300	91.190	12.845	3.550
54.89	571.88	3.218	91.188	12.527	3.550
54.97	572.63	3.126	91.186	12.168	3.550
55.05	573.37	3.029	91.184	11.792	3.550
55.12	574.12	2.933	91.183	11.416	3.550
55.20	574.87	2.838	91.181	11.046	3.550
55.28	575.62	2.746	91.179	10.691	3.549
55.35	576.37	2.659	91.178	10.351	3.549
55.43	577.12	2.574	91.177	10.021	3.549
55.51	577.88	2.496	91.175	9.717	3.549
55.58	578.63	2.420	91.174	9.422	3.549
55.66	579.38	2.349	91.173	9.145	3.549
55.74	580.14	2.284	91.172	8.890	3.549
55.81	580.90	2.222	91.171	8.650	3.549
55.89	581.65	2.167	91.169	8.436	3.549
55.97	582.41	2.116	91.168	8.235	3.549
56.04	583.17	2.067	91.167	8.045	3.549
56.12	583.93	2.022	91.166	7.871	3.549
56.20	584.69	1.979	91.165	7.706	3.549
56.27	585.45	1.940	91.165	7.552	3.549
56.35	586.21	1.903	91.164	7.409	3.549
56.43	586.97	1.871	91.163	7.283	3.549
56.50	587.73	1.838	91.163	7.154	3.549
56.58	588.49	1.807	91.162	7.033	3.549
56.66	589.26	1.778	91.161	6.921	3.549
56.73	590.02	1.752	91.161	6.821	3.549
56.81	590.78	1.724	91.160	6.712	3.549
56.89	591.54	1.699	91.159	6.614	3.549
56.96	592.30	1.674	91.158	6.517	3.549
57.04	593.07	1.650	91.157	6.422	3.549
57.12	593.83	1.630	91.156	6.344	3.549
57.19	594.59	1.607	91.156	6.256	3.549
57.27	595.35	1.583	91.155	6.161	3.548
57.35	596.12	1.564	91.154	6.089	3.548
57.42	596.88	1.546	91.153	6.020	3.548
57.50	597.64	1.525	91.153	5.936	3.548
57.58	598.41	1.506	91.152	5.862	3.548
57.65	599.17	1.486	91.152	5.784	3.548
57.73	599.94	1.467	91.151	5.712	3.548
57.81	600.70	1.451	91.150	5.648	3.548
57.88	601.46	1.430	91.150	5.566	3.548
57.96	602.22	1.407	91.149	5.479	3.548
58.04	602.99	1.392	91.148	5.420	3.548
58.11	603.75	1.374	91.147	5.348	3.548
58.19	604.52	1.352	91.146	5.263	3.548
58.27	605.28	1.336	91.145	5.199	3.548
58.34	606.05	1.318	91.145	5.130	3.548
58.42	606.81	1.297	91.144	5.048	3.548
58.50	607.57	1.279	91.143	4.980	3.548
58.57	608.34	1.263	91.143	4.915	3.548
58.65	609.10	1.245	91.142	4.848	3.548
58.73	609.86	1.226	91.141	4.773	3.548
58.80	610.63	1.209	91.141	4.706	3.548
58.88	611.39	1.193	91.140	4.644	3.548
58.96	612.16	1.173	91.140	4.568	3.548
59.03	612.92	1.156	91.139	4.502	3.548
59.11	613.69	1.141	91.139	4.441	3.548
59.19	614.44	1.116	91.138	4.343	3.548
59.26	615.21	1.099	91.137	4.279	3.548
59.34	615.97	1.086	91.137	4.226	3.548
59.42	616.74	1.063	91.136	4.139	3.548
59.49	617.50	1.047	91.135	4.077	3.548
59.57	618.26	1.030	91.134	4.009	3.548
59.65	619.03	1.014	91.133	3.948	3.548
59.72	619.79	0.998	91.132	3.886	3.548
59.80	620.56	0.979	91.132	3.810	3.548
59.88	621.32	0.964	91.131	3.751	3.548
59.95	622.09	0.943	91.130	3.672	3.548
60.03	622.85	0.927	91.130	3.608	3.548
60.11	623.62	0.910	91.129	3.541	3.547
60.18	624.38	0.891	91.128	3.470	3.547
60.26	625.15	0.873	91.127	3.399	3.547
60.34	625.91	0.860	91.126	3.347	3.547
60.41	626.67	0.843	91.125	3.282	3.547
60.49	627.44	0.822	91.124	3.201	3.547
60.57	628.20	0.805	91.123	3.135	3.547
60.64	628.96	0.789	91.123	3.073	3.547
60.72	629.73	0.773	91.122	3.009	3.547
60.80	630.49	0.757	91.121	2.947	3.547
60.87	631.26	0.738	91.120	2.873	3.547
60.95	632.02	0.718	91.119	2.797	3.547
61.03	632.79	0.704	91.118	2.740	3.547
61.10	633.55	0.688	91.117	2.678	3.547
61.18	634.31	0.669	91.117	2.604	3.547
61.26	635.08	0.652	91.117	2.537	3.547
61.33	635.84	0.634	91.116	2.467	3.547
61.41	636.61	0.617	91.115	2.403	3.547
61.49	637.37	0.601	91.115	2.340	3.547
61.56	638.13	0.581	91.114	2.262	3.547
61.64	638.90	0.567	91.113	2.207	3.547
61.72	639.66	0.549	91.113	2.137	3.547
61.79	640.43	0.533	91.112	2.075	3.547
61.87	641.19	0.518	91.111	2.017	3.547
61.95	641.96	0.498	91.110	1.940	3.547
62.02	642.72	0.482	91.109	1.875	3.547
62.10	643.48	0.465	91.109	1.809	3.547
62.18	644.25	0.450	91.107	1.752	3.547
62.25	645.01	0.433	91.107	1.685	3.547
62.33	645.78	0.411	91.106	1.601	3.547
62.41	646.54	0.397	91.105	1.545	3.547
62.48	647.31	0.383	91.104	1.492	3.546
62.56	648.07	0.365	91.103	1.422	3.546
62.64	648.83	0.348	91.102	1.356	3.546
62.71	649.60	0.330	91.101	1.287	3.546
62.79	650.36	0.313	91.100	1.218	3.546
62.87	651.13	0.299	91.099	1.166	3.546
62.94	651.89	0.285	91.098	1.110	3.546
63.02	652.66	0.270	91.098	1.049	3.546
63.10	653.42	0.254	91.097	0.988	3.546
63.17	654.19	0.239	91.096	0.930	3.546
63.25	654.95	0.218	91.095	0.848	3.546
63.33	655.72	0.202	91.094	0.787	3.546
63.40	656.48	0.186	91.093	0.723	3.546
63.48	657.25	0.171	91.093	0.665	3.546
63.56	658.01	0.154	91.092	0.600	3.546
63.63	658.78	0.139	91.091	0.542	3.546
63.71	659.54	0.121	91.090	0.469	3.546
63.79	660.30	0.105	91.089	0.409	3.546
63.86	661.07	0.092	91.088	0.357	3.546
63.94	661.83	0.076	91.088	0.297	3.546
64.02	662.60	0.059	91.087	0.231	3.546
64.09	663.36	0.039	91.086	0.152	3.546
64.17	664.13	0.024	91.085	0.093	3.546
64.25	664.89	0.010	91.084	0.038	3.546
64.32	665.65	-0.007	91.083	-0.026	3.546
64.40	666.42	-0.023	91.082	-0.088	3.546
64.48	667.18	-0.039	91.081	-0.153	3.546
64.55	667.95	-0.051	91.080	-0.200	3.546
64.63	668.71	-0.066	91.079	-0.257	3.546
64.71	669.48	-0.084	91.078	-0.328	3.545
64.78	670.25	-0.099	91.077	-0.387	3.545
64.86	671.01	-0.111	91.075	-0.433	3.545
64.94	671.77	-0.128	91.074	-0.499	3.545
65.01	672.54	-0.146	91.073	-0.567	3.545
65.09	673.30	-0.160	91.073	-0.622	3.545
65.17	674.07	-0.175	91.072	-0.681	3.545
65.24	674.83	-0.187	91.071	-0.729	3.545
65.32	675.60	-0.201	91.070	-0.784	3.545
65.40	676.37	-0.216	91.069	-0.840	3.545
65.47	677.13	-0.229	91.068	-0.893	3.545
65.55	677.89	-0.247	91.067	-0.962	3.545
65.63	678.66	-0.257	91.067	-1.001	3.545
65.70	679.42	-0.270	91.066	-1.053	3.545
65.78	680.19	-0.283	91.065	-1.102	3.545
65.86	680.96	-0.296	91.064	-1.152	3.545
65.93	681.72	-0.307	91.062	-1.195	3.545
66.01	682.49	-0.319	91.062	-1.240	3.545
66.09	683.25	-0.331	91.061	-1.287	3.545
66.16	684.02	-0.341	91.060	-1.329	3.545
66.24	684.78	-0.354	91.059	-1.378	3.545
66.32	685.55	-0.367	91.058	-1.427	3.545
66.39	686.31	-0.378	91.056	-1.473	3.545
66.47	687.08	-0.392	91.055	-1.526	3.545
66.55	687.85	-0.403	91.055	-1.569	3.545
66.62	688.61	-0.412	91.054	-1.605	3.545
66.70	689.38	-0.425	91.052	-1.653	3.544
66.78	690.14	-0.440	91.051	-1.711	3.544
66.85	690.91	-0.449	91.050	-1.749	3.544
66.93	691.67	-0.461	91.049	-1.793	3.544
67.01	692.44	-0.474	91.048	-1.844	3.544
67.08	693.20	-0.485	91.047	-1.888	3.544
67.16	693.97	-0.495	91.046	-1.928	3.544
67.24	694.73	-0.507	91.045	-1.975	3.544
67.31	695.50	-0.521	91.044	-2.026	3.544
67.39	696.27	-0.534	91.043	-2.078	3.544
67.47	697.03	-0.546	91.042	-2.127	3.544
67.54	697.80	-0.557	91.041	-2.167	3.544
67.62	698.57	-0.570	91.039	-2.217	3.544
67.70	699.33	-0.581	91.038	-2.263	3.544
67.77	700.10	-0.592	91.037	-2.305	3.544
67.85	700.86	-0.604	91.036	-2.350	3.544
67.93	701.63	-0.618	91.035	-2.406	3.544
68.00	702.40	-0.632	91.034	-2.459	3.544
68.08	703.16	-0.646	91.033	-2.513	3.544
68.16	703.93	-0.655	91.032	-2.551	3.544
68.23	704.70	-0.666	91.030	-2.594	3.544
68.31	705.46	-0.677	91.029	-2.637	3.544
68.39	706.23	-0.691	91.028	-2.689	3.544
68.46	706.99	-0.702	91.027	-2.734	3.544
68.54	707.76	-0.716	91.026	-2.785	3.543
68.62	708.53	-0.727	91.025	-2.832	3.543
68.69	709.29	-0.739	91.024	-2.876	3.543
68.77	710.06	-0.754	91.023	-2.934	3.543
68.85	710.82	-0.764	91.022	-2.975	3.543
68.92	711.59	-0.776	91.020	-3.021	3.543
69.00	712.35	-0.790	91.020	-3.075	3.543
69.08	713.12	-0.803	91.018	-3.128	3.543
69.15	713.89	-0.814	91.017	-3.169	3.543
69.23	714.65	-0.826	91.016	-3.216	3.543
69.31	715.42	-0.839	91.015	-3.267	3.543
69.38	716.19	-0.852	91.013	-3.318	3.543
69.46	716.95	-0.865	91.012	-3.365	3.543
69.54	717.72	-0.877	91.010	-3.415	3.543
69.61	718.48	-0.888	91.009	-3.456	3.543
69.69	719.25	-0.899	91.008	-3.501	3.543
69.77	720.02	-0.918	91.006	-3.572	3.543
69.84	720.78	-0.931	91.005	-3.624	3.543
69.92	721.55	-0.943	91.004	-3.671	3.543
70.00	722.31	-0.961	91.003	-3.739	3.543
70.07	723.08	-0.976	91.001	-3.800	3.543
70.15	723.85	-0.992	91.000	-3.860	3.542
70.23	724.61	-1.004	90.999	-3.908	3.542
70.30	725.38	-1.020	90.997	-3.971	3.542
70.38	726.14	-1.038	90.996	-4.040	3.542
70.46	726.91	-1.050	90.994	-4.087	3.542
70.53	727.67	-1.063	90.993	-4.137	3.542
70.61	728.44	-1.075	90.991	-4.186	3.542
70.69	729.20	-1.091	90.990	-4.246	3.542
70.76	729.97	-1.108	90.989	-4.311	3.542
70.84	730.73	-1.125	90.987	-4.378	3.542
70.92	731.50	-1.141	90.986	-4.443	3.542
70.99	732.27	-1.156	90.985	-4.499	3.542
71.07	733.03	-1.172	90.983	-4.562	3.542
71.15	733.80	-1.191	90.982	-4.635	3.542
71.22	734.56	-1.209	90.980	-4.706	3.542
71.30	735.33	-1.226	90.979	-4.774	3.542
71.38	736.09	-1.243	90.977	-4.840	3.542
71.45	736.86	-1.261	90.975	-4.909	3.542
71.53	737.63	-1.279	90.973	-4.980	3.541
71.61	738.39	-1.297	90.971	-5.049	3.541
71.68	739.16	-1.315	90.970	-5.120	3.541
71.76	739.92	-1.333	90.968	-5.190	3.541
71.84	740.68	-1.353	90.966	-5.267	3.541
71.91	741.45	-1.371	90.964	-5.337	3.541
71.99	742.22	-1.394	90.963	-5.425	3.541
72.07	742.98	-1.415	90.961	-5.508	3.541
72.14	743.75	-1.434	90.959	-5.582	3.541
72.22	744.51	-1.454	90.958	-5.660	3.541
72.30	745.28	-1.474	90.956	-5.738	3.541
72.37	746.04	-1.498	90.954	-5.830	3.541
72.45	746.81	-1.519	90.952	-5.914	3.541
72.53	747.57	-1.543	90.951	-6.007	3.541
72.60	748.34	-1.566	90.949	-6.097	3.540
72.68	749.10	-1.589	90.947	-6.184	3.540
72.76	749.87	-1.610	90.945	-6.268	3.540
72.83	750.63	-1.633	90.943	-6.358	3.540
72.91	751.40	-1.658	90.941	-6.454	3.540
72.99	752.16	-1.679	90.939	-6.538	3.540
73.06	752.93	-1.704	90.937	-6.634	3.540
73.14	753.69	-1.731	90.935	-6.740	3.540
73.22	754.45	-1.758	90.933	-6.844	3.540
73.29	755.22	-1.781	90.931	-6.931	3.540
73.37	755.98	-1.805	90.929	-7.027	3.540
73.45	756.75	-1.836	90.927	-7.147	3.540
73.52	757.51	-1.861	90.925	-7.245	3.540
73.60	758.28	-1.881	90.924	-7.322	3.539
73.68	759.04	-1.908	90.921	-7.429	3.539
73.75	759.81	-1.939	90.920	-7.550	3.539
73.83	760.57	-1.966	90.917	-7.652	3.539
73.91	761.34	-1.992	90.915	-7.756	3.539
73.98	762.10	-2.022	90.913	-7.870	3.539
74.06	762.87	-2.050	90.911	-7.981	3.539
74.14	763.63	-2.080	90.909	-8.096	3.539
74.21	764.39	-2.111	90.907	-8.219	3.539
74.29	765.16	-2.142	90.905	-8.338	3.539
74.37	765.92	-2.172	90.903	-8.454	3.539
74.44	766.69	-2.203	90.901	-8.577	3.539
74.52	767.45	-2.235	90.899	-8.701	3.539
74.60	768.22	-2.267	90.897	-8.827	3.538
74.67	768.98	-2.299	90.895	-8.950	3.538
74.75	769.74	-2.333	90.893	-9.082	3.538
74.83	770.51	-2.360	90.890	-9.187	3.538
74.90	771.27	-2.398	90.888	-9.334	3.538
74.98	772.03	-2.433	90.886	-9.471	3.538
75.06	772.80	-2.466	90.884	-9.600	3.538
75.13	773.56	-2.501	90.882	-9.734	3.538
75.21	774.32	-2.536	90.880	-9.871	3.538
75.29	775.09	-2.572	90.878	-10.012	3.538
75.36	775.85	-2.607	90.876	-10.148	3.538
75.44	776.61	-2.644	90.874	-10.291	3.538
75.52	777.38	-2.680	90.872	-10.434	3.537
75.59	778.14	-2.719	90.870	-10.583	3.537
75.67	778.90	-2.754	90.867	-10.719	3.537
75.75	779.67	-2.787	90.865	-10.850	3.537
75.82	780.43	-2.824	90.863	-10.992	3.537
75.90	781.20	-2.864	90.861	-11.149	3.537
75.98	781.96	-2.904	90.859	-11.305	3.537
76.05	782.72	-2.940	90.856	-11.443	3.537
76.13	783.49	-2.976	90.854	-11.584	3.537
76.21	784.25	-3.018	90.852	-11.749	3.537
76.28	785.01	-3.057	90.850	-11.899	3.537
76.36	785.78	-3.097	90.847	-12.054	3.537
76.44	786.54	-3.136	90.845	-12.209	3.536
76.51	787.30	-3.177	90.843	-12.366	3.536
76.59	788.07	-3.214	90.841	-12.511	3.536
76.67	788.83	-3.256	90.838	-12.675	3.536
76.74	789.59	-3.299	90.836	-12.842	3.536
76.82	790.36	-3.342	90.834	-13.009	3.536
76.90	791.12	-3.382	90.832	-13.166	3.536
76.97	791.88	-3.424	90.829	-13.329	3.536
77.05	792.65	-3.463	90.827	-13.483	3.536
77.13	793.41	-3.505	90.825	-13.645	3.536
77.20	794.17	-3.551	90.823	-13.824	3.536
77.28	794.94	-3.592	90.821	-13.985	3.535
77.36	795.70	-3.640	90.819	-14.169	3.535
77.43	796.46	-3.681	90.817	-14.331	3.535
77.51	797.23	-3.728	90.815	-14.511	3.535
77.59	797.99	-3.766	90.813	-14.660	3.535
77.66	798.75	-3.813	90.811	-14.841	3.535
77.74	799.52	-3.856	90.809	-15.009	3.535
77.82	800.28	-3.899	90.807	-15.178	3.535
77.89	801.05	-3.945	90.805	-15.356	3.535
77.97	801.81	-3.994	90.802	-15.549	3.535
78.05	802.57	-4.038	90.800	-15.720	3.535
78.12	803.34	-4.085	90.798	-15.901	3.535
78.20	804.10	-4.133	90.796	-16.089	3.535
78.28	804.86	-4.175	90.795	-16.251	3.534
78.35	805.63	-4.223	90.793	-16.438	3.534
78.43	806.39	-4.269	90.791	-16.620	3.534
78.51	807.15	-4.317	90.789	-16.804	3.534
78.58	807.92	-4.361	90.787	-16.977	3.534
78.66	808.68	-4.408	90.785	-17.161	3.534
78.74	809.45	-4.453	90.783	-17.336	3.534
78.81	810.21	-4.504	90.781	-17.532	3.534
78.89	810.97	-4.553	90.779	-17.725	3.534
78.97	811.74	-4.599	90.777	-17.902	3.534
79.04	812.50	-4.647	90.775	-18.091	3.534
79.12	813.26	-4.696	90.773	-18.282	3.534
79.20	814.02	-4.746	90.771	-18.475	3.534
79.27	814.79	-4.796	90.769	-18.671	3.533
79.35	815.55	-4.844	90.767	-18.856	3.533
79.43	816.31	-4.891	90.765	-19.038	3.533
79.50	817.08	-4.940	90.763	-19.231	3.533
79.58	817.84	-4.990	90.761	-19.426	3.533
79.66	818.60	-5.036	90.759	-19.606	3.533
79.73	819.37	-5.088	90.757	-19.808	3.533
79.81	820.13	-5.137	90.755	-19.996	3.533
79.89	820.89	-5.187	90.753	-20.194	3.533
79.96	821.66	-5.240	90.751	-20.399	3.533
80.04	822.42	-5.289	90.749	-20.589	3.533
80.12	823.18	-5.342	90.747	-20.794	3.533
80.19	823.95	-5.396	90.745	-21.006	3.533
80.27	824.71	-5.445	90.743	-21.195	3.532
80.35	825.47	-5.492	90.741	-21.380	3.532
80.42	826.24	-5.548	90.739	-21.597	3.532
80.50	827.00	-5.603	90.738	-21.812	3.532
80.58	827.76	-5.656	90.736	-22.019	3.532
80.65	828.53	-5.706	90.734	-22.214	3.532
80.73	829.29	-5.757	90.732	-22.409	3.532
80.81	830.05	-5.810	90.730	-22.617	3.532
80.88	830.81	-5.865	90.728	-22.831	3.532
80.96	831.58	-5.917	90.725	-23.033	3.532
81.04	832.34	-5.970	90.723	-23.239	3.532
81.11	833.10	-6.020	90.721	-23.434	3.532
81.19	833.87	-6.072	90.719	-23.637	3.532
81.27	834.63	-6.124	90.717	-23.839	3.531
81.34	835.39	-6.176	90.715	-24.043	3.531
81.42	836.16	-6.227	90.714	-24.241	3.531
81.50	836.92	-6.282	90.712	-24.455	3.531
81.57	837.68	-6.336	90.711	-24.666	3.531
81.65	838.45	-6.389	90.709	-24.873	3.531
81.73	839.21	-6.442	90.707	-25.076	3.531
81.80	839.97	-6.494	90.705	-25.281	3.531
81.88	840.74	-6.548	90.703	-25.491	3.531
81.96	841.50	-6.600	90.701	-25.694	3.531
82.03	842.26	-6.655	90.699	-25.905	3.531
82.11	843.02	-6.706	90.698	-26.104	3.531
82.19	843.79	-6.761	90.696	-26.318	3.531
82.26	844.55	-6.814	90.694	-26.527	3.531
82.34	845.31	-6.867	90.691	-26.733	3.530
82.42	846.08	-6.920	90.690	-26.938	3.530
82.49	846.84	-6.973	90.688	-27.146	3.530
82.57	847.60	-7.024	90.686	-27.345	3.530
82.65	848.37	-7.078	90.684	-27.553	3.530
82.72	849.13	-7.133	90.682	-27.767	3.530
82.80	849.89	-7.189	90.681	-27.986	3.530
82.88	850.65	-7.242	90.679	-28.193	3.530
82.95	851.42	-7.298	90.677	-28.408	3.530
83.03	852.18	-7.350	90.676	-28.610	3.530
83.11	852.94	-7.399	90.674	-28.804	3.530
83.18	853.71	-7.451	90.672	-29.006	3.530
83.26	854.47	-7.511	90.670	-29.239	3.530
83.34	855.23	-7.562	90.669	-29.436	3.530
83.41	855.99	-7.620	90.667	-29.664	3.529
83.49	856.76	-7.670	90.665	-29.859	3.529
83.57	857.52	-7.727	90.663	-30.078	3.529
83.64	858.29	-7.781	90.662	-30.292	3.529
83.72	859.05	-7.836	90.660	-30.503	3.529
83.80	859.81	-7.890	90.659	-30.714	3.529
83.87	860.58	-7.947	90.657	-30.938	3.529
83.95	861.34	-8.004	90.655	-31.158	3.529
84.03	862.10	-8.058	90.653	-31.370	3.529
84.10	862.86	-8.114	90.651	-31.588	3.529
84.18	863.62	-8.169	90.650	-31.802	3.529
84.26	864.39	-8.224	90.648	-32.013	3.529
84.33	865.15	-8.277	90.647	-32.219	3.529
84.41	865.92	-8.330	90.646	-32.426	3.529
84.49	866.68	-8.389	90.644	-32.657	3.529
84.56	867.44	-8.440	90.642	-32.855	3.529
84.64	868.21	-8.496	90.641	-33.072	3.528
84.72	868.97	-8.550	90.639	-33.283	3.528
84.79	869.73	-8.604	90.637	-33.495	3.528
84.87	870.50	-8.662	90.636	-33.720	3.528
84.95	871.26	-8.717	90.634	-33.934	3.528
85.02	872.02	-8.772	90.633	-34.147	3.528
85.10	872.78	-8.828	90.631	-34.364	3.528
85.18	873.55	-8.880	90.629	-34.567	3.528
85.25	874.31	-8.937	90.627	-34.791	3.528
85.33	875.07	-8.994	90.626	-35.012	3.528
85.41	875.84	-9.050	90.624	-35.229	3.528
85.48	876.60	-9.105	90.622	-35.443	3.528
85.56	877.36	-9.158	90.621	-35.649	3.528
85.64	878.13	-9.213	90.619	-35.864	3.528
85.71	878.89	-9.270	90.618	-36.088	3.528
85.79	879.65	-9.324	90.616	-36.298	3.528
85.87	880.42	-9.380	90.614	-36.516	3.527
85.94	881.18	-9.437	90.612	-36.735	3.527
86.02	881.94	-9.493	90.610	-36.955	3.527
86.10	882.70	-9.549	90.608	-37.172	3.527
86.17	883.47	-9.606	90.607	-37.396	3.527
86.25	884.23	-9.662	90.605	-37.611	3.527
86.33	884.99	-9.718	90.603	-37.829	3.527
86.40	885.76	-9.775	90.602	-38.052	3.527
86.48	886.52	-9.829	90.600	-38.264	3.527
86.56	887.28	-9.889	90.598	-38.496	3.527
86.63	888.05	-9.944	90.596	-38.709	3.527
86.71	888.81	-9.999	90.594	-38.923	3.527
86.79	889.57	-10.056	90.592	-39.148	3.527
86.86	890.34	-10.112	90.590	-39.363	3.527
86.94	891.10	-10.167	90.589	-39.578	3.526
87.02	891.86	-10.222	90.587	-39.794	3.526
87.09	892.63	-10.281	90.585	-40.023	3.526
87.17	893.39	-10.336	90.583	-40.236	3.526
87.25	894.15	-10.392	90.581	-40.453	3.526
87.32	894.92	-10.445	90.580	-40.662	3.526
87.40	895.68	-10.505	90.578	-40.893	3.526
87.48	896.44	-10.559	90.576	-41.106	3.526
87.55	897.21	-10.614	90.575	-41.319	3.526
87.63	897.97	-10.673	90.573	-41.546	3.526
87.71	898.73	-10.730	90.571	-41.772	3.526
87.78	899.50	-10.786	90.569	-41.988	3.526
87.86	900.26	-10.846	90.567	-42.222	3.526
87.94	901.03	-10.902	90.565	-42.438	3.526
88.01	901.79	-10.956	90.564	-42.649	3.525
88.09	902.55	-11.014	90.562	-42.876	3.525
88.17	903.32	-11.069	90.561	-43.091	3.525
88.24	904.08	-11.130	90.559	-43.328	3.525
88.32	904.84	-11.187	90.557	-43.549	3.525
88.40	905.61	-11.240	90.555	-43.757	3.525
88.47	906.37	-11.301	90.553	-43.993	3.525
88.55	907.13	-11.357	90.551	-44.210	3.525
88.63	907.90	-11.414	90.549	-44.434	3.525
88.70	908.66	-11.471	90.547	-44.656	3.525
88.78	909.42	-11.529	90.545	-44.881	3.525
88.86	910.19	-11.584	90.543	-45.094	3.525
88.93	910.95	-11.636	90.541	-45.296	3.525
89.01	911.72	-11.694	90.539	-45.524	3.525
89.09	912.48	-11.755	90.538	-45.758	3.524
89.16	913.24	-11.810	90.536	-45.973	3.524
89.24	914.00	-11.868	90.534	-46.200	3.524
89.32	914.77	-11.922	90.532	-46.411	3.524
89.39	915.53	-11.979	90.530	-46.633	3.524
89.47	916.30	-12.033	90.529	-46.842	3.524
89.55	917.06	-12.086	90.527	-47.050	3.524
89.62	917.82	-12.147	90.525	-47.286	3.524
89.70	918.59	-12.203	90.523	-47.504	3.524
89.78	919.35	-12.261	90.521	-47.728	3.524
89.85	920.11	-12.313	90.520	-47.934	3.524
89.93	920.88	-12.369	90.518	-48.152	3.524
90.01	921.64	-12.423	90.516	-48.362	3.524
90.08	922.41	-12.479	90.514	-48.577	3.524
90.16	923.17	-12.536	90.512	-48.798	3.523
90.24	923.93	-12.594	90.510	-49.028	3.523
90.31	924.70	-12.651	90.509	-49.247	3.523
90.39	925.46	-12.708	90.507	-49.471	3.523
90.47	926.22	-12.763	90.505	-49.684	3.523
90.54	926.99	-12.821	90.503	-49.909	3.523
90.62	927.75	-12.879	90.501	-50.137	3.523
90.70	928.52	-12.933	90.499	-50.344	3.523
90.77	929.28	-12.990	90.497	-50.569	3.523
90.85	930.04	-13.047	90.495	-50.789	3.523
90.93	930.81	-13.104	90.493	-51.011	3.523
91.00	931.57	-13.160	90.491	-51.230	3.523
91.08	932.33	-13.216	90.489	-51.447	3.523
91.16	933.10	-13.278	90.487	-51.687	3.522
91.23	933.86	-13.333	90.485	-51.904	3.522
91.31	934.62	-13.387	90.483	-52.112	3.522
91.39	935.39	-13.443	90.481	-52.332	3.522
91.46	936.15	-13.502	90.479	-52.559	3.522
91.54	936.92	-13.555	90.477	-52.768	3.522
91.62	937.68	-13.613	90.475	-52.992	3.522
91.69	938.44	-13.674	90.473	-53.231	3.522
91.77	939.21	-13.729	90.471	-53.444	3.522
91.85	939.97	-13.782	90.469	-53.651	3.522
91.92	940.73	-13.839	90.467	-53.871	3.522
92.00	941.50	-13.894	90.465	-54.089	3.522
92.08	942.26	-13.952	90.462	-54.311	3.522
92.15	943.02	-14.011	90.460	-54.543	3.521
92.23	943.79	-14.066	90.458	-54.757	3.521
92.31	944.55	-14.126	90.456	-54.992	3.521
92.38	945.31	-14.180	90.454	-55.200	3.521
92.46	946.08	-14.238	90.452	-55.426	3.521
92.54	946.84	-14.293	90.450	-55.642	3.521
92.61	947.61	-14.351	90.448	-55.865	3.521
92.69	948.37	-14.406	90.445	-56.079	3.521
92.77	949.13	-14.460	90.444	-56.291	3.521
92.84	949.90	-14.513	90.442	-56.498	3.521
92.92	950.66	-14.570	90.439	-56.719	3.521
93.00	951.43	-14.627	90.437	-56.941	3.521
93.07	952.19	-14.683	90.435	-57.160	3.520
93.15	952.95	-14.738	90.432	-57.371	3.520
93.23	953.72	-14.793	90.430	-57.588	3.520
93.30	954.48	-14.849	90.428	-57.806	3.520
93.38	955.25	-14.906	90.426	-58.028	3.520
93.46	956.01	-14.964	90.423	-58.253	3.520
93.53	956.77	-15.023	90.421	-58.482	3.520
93.61	957.54	-15.080	90.419	-58.702	3.520
93.69	958.30	-15.133	90.416	-58.910	3.520
93.76	959.07	-15.190	90.414	-59.134	3.520
93.84	959.83	-15.247	90.412	-59.353	3.520
93.92	960.59	-15.306	90.410	-59.584	3.519
93.99	961.36	-15.367	90.407	-59.819	3.519
94.07	962.12	-15.425	90.405	-60.045	3.519
94.15	962.88	-15.481	90.403	-60.264	3.519
94.22	963.65	-15.541	90.401	-60.499	3.519
94.30	964.41	-15.598	90.398	-60.719	3.519
94.38	965.17	-15.658	90.396	-60.953	3.519
94.45	965.94	-15.715	90.394	-61.177	3.519
94.53	966.70	-15.772	90.391	-61.399	3.519
94.61	967.47	-15.830	90.389	-61.625	3.519
94.68	968.23	-15.891	90.387	-61.862	3.519
94.76	968.99	-15.947	90.384	-62.079	3.518
94.84	969.76	-16.006	90.382	-62.308	3.518
94.91	970.52	-16.063	90.379	-62.532	3.518
94.99	971.29	-16.121	90.377	-62.755	3.518
95.07	972.05	-16.180	90.374	-62.987	3.518
95.14	972.81	-16.240	90.372	-63.220	3.518
95.22	973.58	-16.299	90.369	-63.450	3.518
95.30	974.34	-16.359	90.367	-63.683	3.518
95.37	975.11	-16.416	90.365	-63.903	3.518
95.45	975.87	-16.481	90.362	-64.158	3.518
95.53	976.63	-16.540	90.359	-64.388	3.518
95.60	977.40	-16.599	90.356	-64.618	3.517
95.68	978.16	-16.657	90.354	-64.842	3.517
95.76	978.93	-16.712	90.351	-65.057	3.517
95.83	979.69	-16.777	90.348	-65.310	3.517
95.91	980.45	-16.837	90.345	-65.542	3.517
95.99	981.22	-16.894	90.343	-65.765	3.517
96.06	981.98	-16.955	90.340	-66.004	3.517
96.14	982.74	-17.012	90.338	-66.223	3.517
96.22	983.51	-17.070	90.335	-66.451	3.517
96.29	984.27	-17.133	90.333	-66.696	3.516
96.37	985.03	-17.192	90.330	-66.925	3.516
96.45	985.80	-17.251	90.328	-67.155	3.516
96.52	986.56	-17.312	90.325	-67.391	3.516
96.60	987.33	-17.369	90.322	-67.614	3.516
96.68	988.09	-17.428	90.320	-67.844	3.516
96.75	988.86	-17.487	90.317	-68.074	3.516
96.83	989.62	-17.547	90.314	-68.307	3.516
96.91	990.38	-17.609	90.312	-68.550	3.516
96.98			90.309		3.516
97.00			90.309		3.516