File: Data/KMK249S/MvsH/KMK249S_MvsH_300K.dat
[Header]
; MPMS3 Data File (default extension .dat)
; Copyright (c) 2007, Quantum Design, Inc. All rights reserved.
TITLE,
FILEOPENTIME,3870398384.88299,08/23/2022,6:39 am
BYAPP,MPMS3 w/ AC,1.0,1.1
INFO,MPMS3 Measurement Release 1.1.16 Build 424, MultiVu Release 2.3.4.19,APPNAME
INFO,Linear Motor Servo Controller,MOTOR_MODULE_NAME
INFO,3101-100 J0,MOTOR_HW_VERSION
INFO,MMC721,MOTOR_SERIAL_NUMBER
INFO,01.04.28,MOTOR_SOFTWARE_VERSION
INFO,Quantum Design Squid Module,SQUID_MODULE_NAME
INFO,3101-501 B0,SQUID_HW_VERSION
INFO,SQM195,SQUID_SERIAL_NUMBER
INFO,01.03.04,SQUID_SOFTWARE_VERSION
INFO,SQUID AC,AC_MODULE_NAME
INFO,3101-401 f1,AC_HW_VERSION
INFO,SAC107,AC_SERIAL_NUMBER
INFO,SQUID AC 00.95.07,AC_SOFTWARE_VERSION
INFO,TCI166,COIL_SERIAL_NUMBER
INFO,0,MOMENT_UNITS
INFO,KMK249S,SAMPLE_MATERIAL
INFO,,SAMPLE_COMMENT
INFO,2.2,SAMPLE_MASS
INFO,,SAMPLE_VOLUME
INFO,,SAMPLE_MOLECULAR_WEIGHT
INFO,,SAMPLE_SIZE
INFO,,SAMPLE_SHAPE
INFO,Straw,SAMPLE_HOLDER
INFO,Standard,SAMPLE_HOLDER_DETAIL
INFO,66.99,SAMPLE_OFFSET
DATATYPE,COMMENT,1
DATATYPE,TIME,2
STARTUPAXIS,X,2
STARTUPAXIS,Y1,5
FIELDGROUP, VSM,2,3,4,5,6,8,9,10,11,14,15
FIELDGROUP, DC, 2,3,4,14,56,57,58,59,60,61,62,63,64,65,66,67,68,69
FIELDGROUP, AC, 2,3,4,11,16,17,18,19,20,21,22,23,24,25,26,27,28,29,30
STARTUPGROUP, All
[Data]
Comment,Time Stamp (sec),Temperature (K),Magnetic Field (Oe),Moment (emu),M. Std. Err. (emu),Transport Action,Averaging Time (sec),Frequency (Hz),Peak Amplitude (mm),Center Position (mm),Lockin Signal' (V),Lockin Signal (V),Range,M. Quad. Signal (emu),AC Moment (emu),AC M. Std Err. (emu),AC Phase (deg),AC Phase Std. Err. (deg),AC Susceptibility (emu/Oe),AC Suscept. Std Err. (emu/Oe),AC X' (emu/Oe),AC X' Std Err. (emu/Oe),AC X'' (emu/Oe),AC X'' Std Err. (emu/Oe),AC Drive (Oe),AC Frequency (Hz),AC Averaging Time (sec),AC Cycles,AC Range,AC Measure Type,AC Signal' (V),AC Signal'' (V),AC Trim Coil Ratio,AC Trim Coil Phase,Min. Temperature (K),Max. Temperature (K),Min. Field (Oe),Max. Field (Oe),Mass (grams),Motor Lag (deg),Pressure (Torr),Measure Count,Measurement Number,SQUID Status (code),Motor Status (code),Measure Status (code),Motor Current (amps),Motor Temp. (C),Temp. Status (code),Field Status (code),Chamber Status (code),Chamber Temp (K),Redirection State,Evercool Status,Average Temp (K),Rotation Angle (deg),Rotator state,DC Moment Fixed Ctr (emu),DC Moment Err Fixed Ctr (emu),DC Moment Free Ctr (emu),DC Moment Err Free Ctr (emu),DC Fixed Fit,DC Free Fit,DC Calculated Center (mm),DC Calculated Center Err (mm),DC Scan Length (mm),DC Scan Time (s),DC Number of Points,DC Squid Drift,DC Min V (V),DC Max V (V),DC Scans per Measure,Map 01,Map 02,Map 03,Map 04,Map 05,Map 06,Map 07,Map 08,Map 09,Map 10,Map 11,Map 12,Map 13,Map 14,Map 15,Map 16
,3870398525.30937,300.042129516602,-70000.484375,,,6,,,,31.7899998559058,,,10,,,,,,,,,,,,,,,,,,,,,,300.033905029297,300.05322265625,-70000.484375,-70000.484375,,,7.8955774307251,,1,0,0,0,0.0138092041015625,30.7917900085449,1,1,1,300.037750244141,0,4232058656,300.043858337402,,,-0.00207689388003798,0.000111363138767286,-0.00211902274931556,0.000111402552326377,0.615919828414917,0.663532793521881,32.4917945861816,4.86546802520752,35,4,200,-0.015672231093049,-4.91629838943481,4.80868053436279,1,,,,,,,,,,,,,,,,
,3870398689.08886,300.187210083008,-45000.3984375,,,6,,,,31.7899998559058,,,10,,,,,,,,,,,,,,,,,,,,,,300.178283691406,300.209838867188,-45000.3984375,-45000.3984375,,,8.09921455383301,,1,0,0,0,0.0144195556640625,30.7917900085449,1,1,1,300.196136474609,0,4232058464,300.198428344727,,,-0.00227095178684844,0.000116397871787187,-0.00229560641720738,0.000116423394605908,0.741089820861816,0.783009350299835,32.3189277648926,INF,35,4,200,0.0278965663164854,-0.498116135597229,0.903868675231934,1,,,,,,,,,,,,,,,,
,3870398845.25662,300.212783813477,-20000.400390625,,,6,,,,31.7899998559058,,,10,,,,,,,,,,,,,,,,,,,,,,300.194244384766,300.233581542969,-20000.400390625,-20000.400390625,,,8.18732738494873,,1,0,0,0,0.0138092041015625,31.2805480957031,1,1,1,300.231323242188,0,4232058592,300.221795654297,,,-0.00244547460537679,0.000122361752439835,-0.00245806584549458,0.000122375000476815,0.855027079582214,0.894528806209564,32.1637191772461,0,35,4,200,0.0303641129285097,-0.378067255020142,0.952267587184906,1,,,,,,,,,,,,,,,,
,3870398996.86881,300.108383178711,-8500.1376953125,,,6,,,,31.7899998559058,,,10,,,,,,,,,,,,,,,,,,,,,,300.094329833984,300.126129150391,-8500.1376953125,-8500.1376953125,,,8.28009700775146,,1,0,0,0,0.0167083740234375,31.2805480957031,1,1,1,300.093383789063,0,4232058624,300.114794921875,,,-0.00248806731056969,0.000123794563621311,-0.00249638128071225,0.000123804872742933,0.900293529033661,0.941011309623718,32.0936241149902,INF,35,4,200,0.0352542549371719,-0.280958324670792,1.04396545886993,1,,,,,,,,,,,,,,,,
,3870399117.38001,300.08137512207,-6000.4111328125,,,6,,,,31.7899998559058,,,10,,,,,,,,,,,,,,,,,,,,,,300.077606201172,300.096649169922,-6000.4111328125,-6000.4111328125,,,8.33245086669922,,1,0,0,0,0.0138092041015625,31.2805480957031,1,1,1,300.077819824219,0,4232058688,300.088067626953,,,-0.0024763203955304,0.000123113840476143,-0.00248384095912353,0.000123122931439245,0.908387303352356,0.949919581413269,32.0802383422852,0,35,4,200,0.0279028285294771,-0.26230263710022,1.07292354106903,1,,,,,,,,,,,,,,,,
,3870399238.10858,300.096435546875,-3500.42822265625,,,6,,,,31.7899998559058,,,10,,,,,,,,,,,,,,,,,,,,,,300.073516845703,300.120361328125,-3500.42822265625,-3500.42822265625,,,8.31900501251221,,1,0,0,0,0.0138092041015625,30.7917900085449,1,1,1,300.072509765625,0,4232058784,300.100598144531,,,-0.00241742959819425,0.000120100825356406,-0.00242396969089544,0.000120108349763214,0.916419446468353,0.958400189876556,32.0646362304687,0,35,4,200,0.0222552102059126,-0.242132186889648,0.970219612121582,1,,,,,,,,,,,,,,,,
,3870399363.93974,300.123626708984,-1000.37194824219,,,6,,,,31.7899998559058,,,10,,,,,,,,,,,,,,,,,,,,,,300.104156494141,300.143981933594,-1000.37194824219,-1000.37194824219,,,8.33444786071777,,1,0,0,0,0.0160980224609375,31.2805480957031,1,1,1,300.103271484375,0,4232058816,300.129733276367,,,-0.00196822029252608,9.77249788596231E-5,-0.0019728993749524,9.77305502242216E-5,0.923875629901886,0.965705454349518,32.0478706359863,0,35,4,200,0.0143261067569256,-0.228140115737915,0.81675386428833,1,,,,,,,,,,,,,,,,
,3870399496.48951,300.073135375977,-760.420104980469,,,6,,,,31.7899998559058,,,10,,,,,,,,,,,,,,,,,,,,,,300.057464599609,300.088531494141,-760.420104980469,-760.420104980469,,,8.37235260009766,,1,0,0,0,0.0179290771484375,31.2805480957031,1,1,1,300.057739257812,0,4232058656,300.076705932617,,,-0.00177402804381295,8.80880624330928E-5,-0.00177815137550056,8.80925393360789E-5,0.923139750957489,0.962817490100861,32.0451240539551,INF,35,4,200,-0.0181623343378305,-0.237574011087418,0.678285121917725,1,,,,,,,,,,,,,,,,
,3870399608.4135,300.100051879883,-710.359313964844,,,6,,,,31.7899998559058,,,10,,,,,,,,,,,,,,,,,,,,,,300.089752197266,300.115753173828,-710.359313964844,-710.359313964844,,,8.41880035400391,,1,0,0,0,0.017242431640625,30.7917900085449,1,1,1,300.1103515625,0,4232058656,300.106658935547,,,-0.00172361968056322,8.55783962244873E-5,-0.00172760983843774,8.55829460537077E-5,0.924156188964844,0.964647233486175,32.044563293457,,35,4,200,-0.016093397513032,-0.219144463539124,0.673658192157745,1,,,,,,,,,,,,,,,,
,3870399728.8903,300.036911010742,-660.213012695313,,,6,,,,31.7899998559058,,,10,,,,,,,,,,,,,,,,,,,,,,300.029998779297,300.05517578125,-660.213012695313,-660.213012695313,,,8.47271251678467,,1,0,0,0,0.016632080078125,30.7917900085449,1,1,1,300.043823242188,0,4232058688,300.045169067383,,,-0.00166190725743759,8.25178061851935E-5,-0.00166571107651142,8.25211854300527E-5,0.923604309558868,0.963095426559448,32.0436820983887,9.32406874198932E-6,35,4,200,-0.0144965695217252,-0.263032823801041,0.610785961151123,1,,,,,,,,,,,,,,,,
,3870399848.5319,300.085556030273,-610.164489746094,,,6,,,,31.7899998559058,,,10,,,,,,,,,,,,,,,,,,,,,,300.077545166016,300.100372314453,-610.164489746094,-610.164489746094,,,8.46916961669922,,1,0,0,0,0.0138092041015625,31.2805480957031,1,1,1,300.093566894531,0,4232058752,300.091885375977,,,-0.00159877188404815,7.93794916372484E-5,-0.00160244820864365,7.93833080046989E-5,0.924176096916199,0.964397430419922,32.0439796447754,3.78928899765015,35,4,200,-0.0159714575856924,-0.242545813322067,0.592961549758911,1,,,,,,,,,,,,,,,,
,3870399966.71906,300.206069946289,-560.445922851562,,,6,,,,31.7899998559058,,,10,,,,,,,,,,,,,,,,,,,,,,300.199676513672,300.228057861328,-560.445922851562,-560.445922851562,,,8.45963859558105,,1,0,0,0,0.0138092041015625,31.2805480957031,1,1,1,300.212463378906,0,4232058656,300.217370605469,,,-0.00152156264015627,7.55446712703533E-5,-0.0015250140319617,7.55481729568712E-5,0.924414157867432,0.964083909988403,32.0423736572266,0,35,4,200,-0.0164383444935083,-0.270935207605362,0.527387499809265,1,,,,,,,,,,,,,,,,
,3870400083.66064,300.16650390625,-510.482940673828,,,6,,,,31.7899998559058,,,10,,,,,,,,,,,,,,,,,,,,,,300.152648925781,300.184020996094,-510.482940673828,-510.482940673828,,,8.46068382263184,,1,0,0,0,0.015106201171875,30.7917900085449,1,1,1,300.180358886719,0,4232058656,300.174212646484,,,-0.00143789289653933,7.13957478289271E-5,-0.00144119882212092,7.13992651053879E-5,0.923460483551025,0.962850451469421,32.0438537597656,0,35,4,200,-0.0166128370910883,-0.250173479318619,0.503953278064728,1,,,,,,,,,,,,,,,,
,3870400199.48423,300.082183837891,-460.263305664063,,,6,,,,31.7899998559058,,,10,,,,,,,,,,,,,,,,,,,,,,300.062744140625,300.101806640625,-460.263305664063,-460.263305664063,,,8.47693920135498,,1,0,0,0,0.0148773193359375,31.2805480957031,1,1,1,300.062561035156,0,4232058592,300.087734985352,,,-0.00134342092371635,6.66993683011714E-5,-0.00134644434964185,6.6702540491525E-5,0.924550771713257,0.963846385478973,32.0413017272949,0,35,4,200,-0.017125004902482,-0.209410637617111,0.495113521814346,1,,,,,,,,,,,,,,,,
,3870400316.25703,300.168502807617,-410.459197998047,,,6,,,,31.7899998559058,,,10,,,,,,,,,,,,,,,,,,,,,,300.163177490234,300.181182861328,-410.459197998047,-410.459197998047,,,8.49386310577393,,1,0,0,0,0.0138092041015625,31.2805480957031,1,1,1,300.162963867188,0,4232058432,300.173422241211,,,-0.00123631357525413,6.13835475658568E-5,-0.00123911621852146,6.1387020374839E-5,0.924134194850922,0.963179647922516,32.041633605957,0,35,4,200,-0.017174793407321,-0.180348172783852,0.474858850240707,1,,,,,,,,,,,,,,,,
,3870400433.70847,300.119506835937,-360.398406982422,,,6,,,,31.7899998559058,,,10,,,,,,,,,,,,,,,,,,,,,,300.099090576172,300.140167236328,-360.398406982422,-360.398406982422,,,8.53623580932617,,1,0,0,0,0.0160980224609375,31.2805480957031,1,1,1,300.098846435547,0,4232058720,300.124237060547,,,-0.0011149977112055,5.53608772265467E-5,-0.00111753889778441,5.53636454302374E-5,0.923963069915772,0.963332831859589,32.0427703857422,0.228111505508423,35,4,200,-0.0187720935791731,-0.232264414429665,0.361262857913971,1,,,,,,,,,,,,,,,,
,3870400548.91876,300.162155151367,-310.362091064453,,,6,,,,31.7899998559058,,,10,,,,,,,,,,,,,,,,,,,,,,300.149108886719,300.184967041016,-310.362091064453,-310.362091064453,,,8.53211975097656,,1,0,0,0,0,30.7917900085449,1,1,1,300.175201416016,0,4232058656,300.173355102539,,,-0.000979390610673866,4.86314690875237E-5,-0.000981647134052771,4.86338965521806E-5,0.922988474369049,0.961993455886841,32.0439872741699,0,35,4,200,-0.0161240492016077,-0.137584149837494,0.393324375152588,1,,,,,,,,,,,,,,,,
,3870400662.79215,299.984436035156,-260.423522949219,,,6,,,,31.7899998559058,,,10,,,,,,,,,,,,,,,,,,,,,,299.977966308594,300.000061035156,-260.423522949219,-260.423522949219,,,8.51700305938721,,1,0,0,0,0.013885498046875,30.7917900085449,1,1,1,299.978698730469,0,4232058752,299.991366577148,,,-0.000829804855832735,4.12073977034651E-5,-0.000831546010911209,4.12091642604647E-5,0.921876549720764,0.955127537250519,32.0325012207031,0.190367758274078,35,4,200,-0.0166540592908859,-0.177657350897789,0.323876708745956,1,,,,,,,,,,,,,,,,
,3870400778.45728,300.066528320313,-210.411651611328,,,6,,,,31.7899998559058,,,10,,,,,,,,,,,,,,,,,,,,,,300.046539306641,300.087066650391,-210.411651611328,-210.411651611328,,,8.50546550750732,,1,0,0,0,0.0167083740234375,31.2805480957031,1,1,1,300.045989990234,0,4232058592,300.069888305664,,,-0.000665869906585249,3.30645573371406E-5,-0.000667373891486587,3.30662077841788E-5,0.922643840312958,0.960147082805634,32.0415344238281,0,35,4,200,-0.017533278092742,-0.149446576833725,0.224582105875015,1,,,,,,,,,,,,,,,,
,3870400891.19421,300.212738037109,-160.228668212891,,,6,,,,31.7899998559058,,,10,,,,,,,,,,,,,,,,,,,,,,300.202331542969,300.236389160156,-160.228668212891,-160.228668212891,,,8.50713443756104,,1,0,0,0,0.0138092041015625,30.7917900085449,1,1,1,300.22314453125,0,4232058624,300.225103759766,,,-0.000488376592611598,2.42556500276411E-5,-0.000489527388412449,2.425687931176E-5,0.920174241065979,0.957749426364899,32.0468940734863,9.8255568445893E-6,35,4,200,-0.015807693824172,-0.163284078240395,0.131067618727684,1,,,,,,,,,,,,,,,,
,3870401010.28178,300.025039672852,-110.216796875,,,6,,,,31.7899998559058,,,1,,,,,,,,,,,,,,,,,,,,,,299.998901367188,300.050750732422,-110.216796875,-110.216796875,,,8.52474880218506,,1,0,0,0,0.016937255859375,30.7917900085449,1,1,1,299.999328613281,0,4232058656,300.021985505757,,,-0.000298379272450468,1.48186652285757E-5,-0.000299012901624292,1.48193397598095E-5,0.920681834220886,0.953553140163422,32.0334625244141,0,35,4,200,-0.113389767706394,-1.03311479091644,1.2363258600235,1,,,,,,,,,,,,,,,,
,3870401134.73068,300.069290161133,-60.4860191345215,,,6,,,,31.7899998559058,,,1,,,,,,,,,,,,,,,,,,,,,,300.060272216797,300.083374023438,-60.4860191345215,-60.4860191345215,,,8.55571460723877,,1,0,0,0,0.0174713134765625,30.7917900085449,1,1,1,300.060852050781,0,4232058720,300.075143432617,,,-9.87204434689985E-5,4.94420130849638E-6,-9.89121972736403E-5,4.94439119990679E-6,0.848840951919556,0.861707925796509,32.0218467712402,1.00000047683716,35,4,200,-0.161986619234085,-1.08072078227997,-0.0149033768102527,1,,,,,,,,,,,,,,,,
,3870401254.623,300.252258300781,-10.4374742507935,,,6,,,,31.7899998559058,,,1,,,,,,,,,,,,,,,,,,,,,,300.249206542969,300.269378662109,-10.4374742507935,-10.4374742507935,,,8.58902454376221,,1,0,0,0,0.0138092041015625,30.7917900085449,1,1,1,300.249298095703,0,4232058656,300.260269165039,,,0.000102537818126324,5.14728593129324E-6,0.000102957110911664,5.14769912299487E-6,0.834586262702942,0.860184669494629,32.132022857666,0,35,4,200,-0.146599441766739,-0.610209584236145,0.464951932430267,1,,,,,,,,,,,,,,,,
,3870401368.56534,300.114440917969,39.8799514770508,,,6,,,,31.7899998559058,,,1,,,,,,,,,,,,,,,,,,,,,,300.106567382812,300.129119873047,39.8799514770508,39.8799514770508,,,8.56549263000488,,1,0,0,0,0.0138092041015625,31.2805480957031,1,1,1,300.122314453125,0,4232058688,300.121008300781,,,0.000303898619702803,1.51005728830621E-5,0.000304755450446928,1.51016471485378E-5,0.914457023143768,0.9569411277771,32.0719184875488,0,35,4,200,-0.181821420788765,-1.99612379074097,0.548253059387207,1,,,,,,,,,,,,,,,,
,3870401488.9952,300.199752807617,89.9773788452148,,,6,,,,31.7899998559058,,,1,,,,,,,,,,,,,,,,,,,,,,300.186401367188,300.2216796875,89.9773788452148,89.9773788452148,,,8.53261280059814,,1,0,0,0,0.0138092041015625,30.7917900085449,1,1,1,300.213104248047,0,4232058784,300.210870361328,,,0.000492000173670263,2.44344454574612E-5,0.000493281930478518,2.44358253549694E-5,0.920772314071655,0.965281009674072,32.0607833862305,5.66222429275513,35,4,200,-0.156914666295052,-2.6219220161438,0.674225747585297,1,,,,,,,,,,,,,,,,
,3870401604.85035,300.152313232422,140.087036132812,,,6,,,,31.7899998559058,,,1,,,,,,,,,,,,,,,,,,,,,,300.140258789063,300.174194335937,140.087036132812,140.087036132812,,,8.52821922302246,,1,0,0,0,0.0005340576171875,31.2805480957031,1,1,1,300.164367675781,0,4232058656,300.163061523438,,,0.000671756409562288,3.33712638154929E-5,0.000673586140512675,3.33736130148641E-5,0.917278110980988,0.960429906845093,32.0662460327148,INF,35,4,200,-0.164677619934082,-2.79107856750488,0.979317784309387,1,,,,,,,,,,,,,,,,
,3870401721.55532,300.21794128418,190.135589599609,,,6,,,,31.7899998559058,,,1,,,,,,,,,,,,,,,,,,,,,,300.210083007812,300.233459472656,190.135589599609,190.135589599609,,,8.53294658660889,,1,0,0,0,0.0138092041015625,30.7917900085449,1,1,1,300.225799560547,0,4232058592,300.225466918945,,,0.000837772675602089,4.16147544211478E-5,0.000840030940489518,4.16170173091172E-5,0.918386876583099,0.962491512298584,32.0655708312988,,35,4,200,-0.188421607017517,-3.55296802520752,0.949474990367889,1,,,,,,,,,,,,,,,,
,3870401836.48782,300.102493286133,240.049667358398,,,6,,,,31.7899998559058,,,1,,,,,,,,,,,,,,,,,,,,,,300.091979980469,300.115905761719,240.049667358398,240.049667358398,,,8.56002521514893,,1,0,0,0,0.016021728515625,30.7917900085449,1,1,1,300.113006591797,0,4232058624,300.108447265625,,,0.000988528089957474,4.90990198327438E-5,0.000991192568258188,4.91015545820315E-5,0.919440567493439,0.964929819107056,32.0657043457031,0,35,4,200,-0.196260586380959,-4.42835712432861,0.804849147796631,1,,,,,,,,,,,,,,,,
,3870401961.07613,299.962799072266,290.02490234375,,,6,,,,31.7899998559058,,,10,,,,,,,,,,,,,,,,,,,,,,299.950378417969,299.97509765625,290.02490234375,290.02490234375,,,8.59591960906982,,1,0,0,0,0.0138092041015625,30.7917900085449,1,1,1,299.950500488281,0,4232058592,299.966156005859,,,0.00112197102418188,5.57217408416487E-5,0.00112485627687046,5.57250979500113E-5,0.920605719089508,0.963855028152466,32.058536529541,0,35,4,200,-0.0196970626711845,-0.512177348136902,0.0738531798124313,1,,,,,,,,,,,,,,,,
,3870402075.4962,300.083450317383,340.220092773438,,,6,,,,31.7899998559058,,,10,,,,,,,,,,,,,,,,,,,,,,300.061248779297,300.103576660156,340.220092773438,340.220092773438,,,8.59777450561523,,1,0,0,0,0.0138092041015625,30.7917900085449,1,1,1,300.105651855469,0,4232058656,300.091091918945,,,0.00124017896263063,6.16012961107407E-5,0.00124350826674087,6.16043824548498E-5,0.918825268745422,0.963277280330658,32.0651817321777,INF,35,4,200,-0.0185782741755247,-0.575924932956696,0.0668150186538696,1,,,,,,,,,,,,,,,,
,3870402198.0731,300.260986328125,390.244201660156,,,6,,,,31.7899998559058,,,10,,,,,,,,,,,,,,,,,,,,,,300.254547119141,300.282562255859,390.244201660156,390.244201660156,,,8.56979084014893,,1,0,0,0,0.0145721435546875,31.2805480957031,1,1,1,300.267425537109,0,4232058688,300.271710205078,,,0.00134721064912434,6.69073485790447E-5,0.00135070679909731,6.69111778067126E-5,0.9207444190979,0.96490752696991,32.0598983764648,4.5011689508101E-5,35,4,200,-0.0164011158049107,-0.628158390522003,0.0794714465737343,1,,,,,,,,,,,,,,,,
,3870402313.07207,300.084442138672,440.194976806641,,,6,,,,31.7899998559058,,,10,,,,,,,,,,,,,,,,,,,,,,300.074340820313,300.099182128906,440.194976806641,440.194976806641,,,8.55197143554687,,1,0,0,0,0.0138092041015625,30.7917900085449,1,1,1,300.074951171875,0,4232058624,300.089450073242,,,0.00144406940204673,7.17159167328089E-5,0.00144777104970694,7.17193684489676E-5,0.921054720878601,0.964968085289001,32.0586776733398,4.44441102445126E-5,35,4,200,-0.0168830268085003,-0.616286754608154,0.13447667658329,1,,,,,,,,,,,,,,,,
,3870402432.06433,300.252349853516,490.121276855469,,,6,,,,31.7899998559058,,,10,,,,,,,,,,,,,,,,,,,,,,300.243041992188,300.277313232422,490.121276855469,490.121276855469,,,8.57259559631348,,1,0,0,0,0.0138092041015625,30.7917900085449,1,1,1,300.261657714844,0,4232058720,300.264547729492,,,0.00152771265789266,7.58621141263624E-5,0.00153158713587331,7.58664844873754E-5,0.922349810600281,0.966885328292847,32.056770324707,INF,35,4,200,-0.0160421896725893,-0.694459438323975,0.144817009568214,1,,,,,,,,,,,,,,,,
,3870402549.67652,300.192565917969,540.133178710937,,,6,,,,31.7899998559058,,,10,,,,,,,,,,,,,,,,,,,,,,300.167602539063,300.219024658203,540.133178710937,540.133178710937,,,8.60204124450684,,1,0,0,0,0.015106201171875,31.2805480957031,1,1,1,300.166107177734,0,4232058592,300.19853515625,,,0.00160241872058755,7.95681489124059E-5,0.00160643750425116,7.95718351801504E-5,0.92293906211853,0.967772901058197,32.0558853149414,INF,35,4,200,-0.0192262753844261,-0.673591673374176,0.151153638958931,1,,,,,,,,,,,,,,,,
,3870402663.5643,300.118576049805,590.365051269531,,,6,,,,31.7899998559058,,,10,,,,,,,,,,,,,,,,,,,,,,300.116119384766,300.132354736328,590.365051269531,590.365051269531,,,8.63579082489014,,1,0,0,0,0.0006866455078125,30.3030319213867,1,1,1,300.116119384766,0,4232058624,300.124359130859,,,0.00167134973820494,8.30094483514025E-5,0.00167574038014998,8.3013716646941E-5,0.920113027095795,0.964541435241699,32.06201171875,0,35,4,200,-0.0226846784353256,-0.682152807712555,0.164804756641388,1,,,,,,,,,,,,,,,,
,3870402779.51624,300.099166870117,640.438049316406,,,6,,,,31.7899998559058,,,10,,,,,,,,,,,,,,,,,,,,,,300.083282470703,300.115936279297,640.438049316406,640.438049316406,,,8.64439010620117,,1,0,0,0,0.01495361328125,30.7917900085449,1,1,1,300.115051269531,0,4232058624,300.105914306641,,,0.00173118014103025,8.59751415470782E-5,0.00173565212469847,8.59799271481931E-5,0.920966565608978,0.96511846780777,32.0593299865723,0,35,4,200,-0.0174749419093132,-0.714792788028717,0.175445452332497,1,,,,,,,,,,,,,,,,
,3870402895.13623,300.024475097656,690.339904785156,,,6,,,,31.7899998559058,,,10,,,,,,,,,,,,,,,,,,,,,,300.003509521484,300.044036865234,690.339904785156,690.339904785156,,,8.63451385498047,,1,0,0,0,0.0145721435546875,30.7917900085449,1,1,1,300.045440673828,0,4232058656,300.031045532227,,,0.00178092827860052,8.84582315840487E-5,0.00178562715247012,8.84630472766941E-5,0.919209063053131,0.962763547897339,32.0622863769531,0,35,4,200,-0.0256836265325546,-0.782381236553192,0.132406666874886,1,,,,,,,,,,,,,,,,
,3870403009.25142,300.138626098633,740.364013671875,,,6,,,,31.7899998559058,,,10,,,,,,,,,,,,,,,,,,,,,,300.124603271484,300.154541015625,740.364013671875,740.364013671875,,,8.61713600158691,,1,0,0,0,0.01495361328125,30.7917900085449,1,1,1,300.152648925781,0,4232058848,300.144787597656,,,0.0018353511605671,9.11363875802772E-5,0.00183989941519415,9.11406067864888E-5,0.922662138938904,0.966222882270813,32.0544281005859,0.000192827079445124,35,4,200,-0.0284204576164484,-0.813571333885193,0.140791177749634,1,,,,,,,,,,,,,,,,
,3870403125.78725,300.144683837891,790.485900878906,,,6,,,,31.7899998559058,,,10,,,,,,,,,,,,,,,,,,,,,,300.123901367188,300.169525146484,790.485900878906,790.485900878906,,,8.60322856903076,,1,0,0,0,0.0138092041015625,30.7917900085449,1,1,1,300.119842529297,0,4232058688,300.151473999023,,,0.00187510287019566,9.31150105940433E-5,0.00187997017643515,9.31200141396401E-5,0.922017872333527,0.968032240867615,32.0601959228516,0.16431288421154,35,4,200,-0.0253938790410757,-0.851913332939148,0.198396682739258,1,,,,,,,,,,,,,,,,
,3870403265.51295,299.979537963867,2500.28833007813,,,6,,,,31.7899998559058,,,10,,,,,,,,,,,,,,,,,,,,,,299.964935302734,299.995086669922,2500.28833007813,2500.28833007813,,,8.61957550048828,,1,0,0,0,0.0138092041015625,30.3030319213867,1,1,1,299.994140625,0,4232058560,299.986276245117,,,0.00235497923151604,0.000116977521413311,0.00236116356892211,0.000116983025304392,0.918547689914703,0.96121472120285,32.0615386962891,0,35,4,200,0.00598028907552361,-0.909412086009979,0.278238147497177,1,,,,,,,,,,,,,,,,
,3870403405.77456,300.046646118164,5000.25927734375,,,6,,,,31.7899998559058,,,10,,,,,,,,,,,,,,,,,,,,,,300.030242919922,300.064270019531,5000.25927734375,5000.25927734375,,,8.65500926971436,,1,0,0,0,0.0138092041015625,29.8142719268799,1,1,1,300.063049316406,0,4232058560,300.054730224609,,,0.00246235987963536,0.00012239182739961,0.00246960702116975,0.000122398524379316,0.910893440246582,0.953085362911224,32.0766983032227,0,35,4,200,0.0131149785593152,-0.941512107849121,0.344523549079895,1,,,,,,,,,,,,,,,,
,3870403546.19577,300.142242431641,7500.388671875,,,6,,,,31.7899998559058,,,10,,,,,,,,,,,,,,,,,,,,,,300.139801025391,300.158233642578,7500.388671875,7500.388671875,,,8.60888576507568,,1,0,0,0,0.0138092041015625,30.7917900085449,1,1,1,300.144683837891,0,4232058752,300.149584960937,,,0.00248427289134827,0.00012357209176673,0.00249234994387995,0.000123579066788578,0.903041481971741,0.944668114185333,32.0908203125,0.155912175774574,35,4,200,0.0172447971999645,-0.907446205615997,0.362884014844894,1,,,,,,,,,,,,,,,,
,3870403695.89171,300.302734375,10000.2607421875,,,6,,,,31.7899998559058,,,10,,,,,,,,,,,,,,,,,,,,,,300.289916992188,300.323883056641,10000.2607421875,10000.2607421875,,,8.6590633392334,,1,0,0,0,0.0138092041015625,30.3030319213867,1,1,1,300.289184570313,0,4232058624,300.310864257812,,,0.0024880585630008,0.000123876209137004,0.00249704405527184,0.000123884144878134,0.893920958042145,0.93499356508255,32.1063461303711,0,35,4,200,0.00942677725106478,-0.916336178779602,0.369046598672867,1,,,,,,,,,,,,,,,,
,3870403849.73676,300.108062744141,35000.359375,,,6,,,,31.7899998559058,,,10,,,,,,,,,,,,,,,,,,,,,,300.094482421875,300.134307861328,35000.359375,35000.359375,,,8.6460075378418,,1,0,0,0,0.0138092041015625,30.7917900085449,1,1,1,300.121643066406,0,4232058688,300.120910644531,,,0.00234325057163405,0.000118648154609345,0.00236256198504738,0.000118666437908035,0.790224730968475,0.83123117685318,32.2560043334961,0.183753564953804,35,4,200,0.0118773235008121,-0.800648808479309,0.473207801580429,1,,,,,,,,,,,,,,,,
,3870404003.37925,300.261703491211,60000.32421875,,,6,,,,31.7899998559058,,,10,,,,,,,,,,,,,,,,,,,,,,300.254608154297,300.284088134766,60000.32421875,60000.32421875,,,8.68547439575195,,1,0,0,0,0.0148773193359375,30.7917900085449,1,1,1,300.268798828125,0,4232058592,300.273397827148,,,0.0021561720476523,0.000113148455888108,0.0021907761280565,0.000113180468321854,0.668397843837738,0.714199006557465,32.4221839904785,4.97094678878784,35,4,200,0.0162831731140614,-0.76077789068222,0.719027638435364,1,,,,,,,,,,,,,,,,
,3870404160.0023,300.241973876953,55000.34765625,,,6,,,,31.7899998559058,,,10,,,,,,,,,,,,,,,,,,,,,,300.219116210937,300.267578125,55000.34765625,55000.34765625,,,8.64658737182617,,1,0,0,0,0,30.7917900085449,1,1,1,300.264831542969,0,4232058720,300.253979492188,,,0.0021992115215967,0.000114477013465815,0.00223053209815254,0.000114505026666742,0.691066145896912,0.735525250434876,32.3898620605469,0.19956462085247,35,4,200,-0.0232761893421412,-0.827945172786713,0.573085069656372,1,,,,,,,,,,,,,,,,
,3870404319.22684,300.114181518555,30000.220703125,,,6,,,,31.7899998559058,,,10,,,,,,,,,,,,,,,,,,,,,,300.110900878906,300.133209228516,30000.220703125,30000.220703125,,,8.70602798461914,,1,0,0,0,0.0138092041015625,30.7917900085449,1,1,1,300.110778808594,0,4232058592,300.123300170898,,,0.00238159740848395,0.000120057210117599,0.00239844275452083,0.000120072049868992,0.811572670936584,0.851492822170258,32.2244758605957,0,35,4,200,-0.0304043404757977,-0.985767483711243,0.438979297876358,1,,,,,,,,,,,,,,,,
,3870404479.37886,299.96369934082,9500.375,,,6,,,,31.7899998559058,,,10,,,,,,,,,,,,,,,,,,,,,,299.958160400391,299.979827880859,9500.375,9500.375,,,8.65496158599854,,1,0,0,0,0.0138092041015625,31.2805480957031,1,1,1,299.959136962891,0,4232058592,299.970306396484,,,0.00249098993451114,0.00012399644879609,0.00249975659525688,0.000124005065642638,0.895871043205261,0.936701953411102,32.1021995544434,5.66588020324707,35,4,200,-0.0485290922224522,-1.04707789421082,0.247590392827988,1,,,,,,,,,,,,,,,,
,3870404623.5027,300.118408203125,7000.30615234375,,,6,,,,31.7899998559058,,,10,,,,,,,,,,,,,,,,,,,,,,300.10595703125,300.139984130859,7000.30615234375,7000.30615234375,,,8.69637298583984,,1,0,0,0,0.0138092041015625,31.2805480957031,1,1,1,300.130859375,0,4232058720,300.129537963867,,,0.00248473359496954,0.000123574180882522,0.00249270047636154,0.000123583803993572,0.904776453971863,0.946538507938385,32.0879554748535,0.155882403254509,35,4,200,-0.0283909123390913,-1.02782118320465,0.250109672546387,1,,,,,,,,,,,,,,,,
,3870404768.34032,300.109924316406,4500.4091796875,,,6,,,,31.7899998559058,,,10,,,,,,,,,,,,,,,,,,,,,,300.1064453125,300.127471923828,4500.4091796875,4500.4091796875,,,8.63006210327148,,1,0,0,0,0.0138092041015625,31.2805480957031,1,1,1,300.113403320313,0,4232058592,300.118075561523,,,0.00245329859280111,0.000121925940770966,0.00246044242338844,0.000121933577057833,0.912322163581848,0.955000936985016,32.0749893188477,0.19050757586956,35,4,200,-0.027909804135561,-1.06421732902527,0.192034766077995,1,,,,,,,,,,,,,,,,
,3870404908.84309,300.057312011719,2000.19396972656,,,6,,,,31.7899998559058,,,10,,,,,,,,,,,,,,,,,,,,,,300.048004150391,300.073364257812,2000.19396972656,2000.19396972656,,,8.63293838500977,,1,0,0,0,0.0160980224609375,30.7917900085449,1,1,1,300.048492431641,0,4232058592,300.063400268555,,,0.00228945353266249,0.000113718301285569,0.00229552936272957,0.00011372461593849,0.919022500514984,0.962738752365112,32.0627593994141,,35,4,200,-0.0271390900015831,-0.979606091976166,0.189878240227699,1,,,,,,,,,,,,,,,,
,3870405043.00411,300.214019775391,780.256225585938,,,6,,,,31.7899998559058,,,10,,,,,,,,,,,,,,,,,,,,,,300.210113525391,300.233673095703,780.256225585938,780.256225585938,,,8.66274356842041,,1,0,0,0,0.0002288818359375,31.2805480957031,1,1,1,300.217926025391,0,4232058656,300.224038696289,,,0.0017987067457383,8.93142868574044E-5,0.00180309471801806,8.93185498512015E-5,0.923016607761383,0.965856790542602,32.0518341064453,0.132190763950348,35,4,200,0.00180708651896566,-0.737300932407379,0.150704845786095,1,,,,,,,,,,,,,,,,
,3870405157.10301,300.136734008789,730.378784179688,,,6,,,,31.7899998559058,,,10,,,,,,,,,,,,,,,,,,,,,,300.130706787109,300.153625488281,730.378784179688,730.378784179688,,,8.64272308349609,,1,0,0,0,0.0146484375,32.2580642700195,1,1,1,300.142761230469,0,4232058784,300.144860839844,,,0.00174515496811057,8.66569677263301E-5,0.00174919862262205,8.66609579335099E-5,0.922756433486938,0.961964666843414,32.0449714660645,0.190324723720551,35,4,200,0.0178249962627888,-0.672344744205475,0.23022697865963,1,,,,,,,,,,,,,,,,
,3870405273.41571,299.998825073242,680.366882324219,,,6,,,,31.7899998559058,,,10,,,,,,,,,,,,,,,,,,,,,,299.988037109375,300.012145996094,680.366882324219,680.366882324219,,,8.64045238494873,,1,0,0,0,0.0138092041015625,30.7917900085449,1,1,1,299.9892578125,0,4232058656,300.002850341797,,,0.00168954793139281,8.38988010850084E-5,0.0016935980832535,8.390336748537E-5,0.922289729118347,0.962899088859558,32.048957824707,,35,4,200,0.0163968969136477,-0.666587293148041,0.251519650220871,1,,,,,,,,,,,,,,,,
,3870405385.68628,300.134017944336,630.452758789063,,,6,,,,31.7899998559058,,,10,,,,,,,,,,,,,,,,,,,,,,300.120819091797,300.149993896484,630.452758789063,630.452758789063,,,8.61833477020264,,1,0,0,0,0.0138092041015625,30.7917900085449,1,1,1,300.120880126953,0,4232058656,300.139376831055,,,0.00162785748597623,8.08229295220373E-5,0.00163155859643062,8.08268546943E-5,0.924294471740723,0.963916182518005,32.0425148010254,8.63949026097544E-6,35,4,200,0.0178161635994911,-0.632229924201965,0.212955713272095,1,,,,,,,,,,,,,,,,
,3870405499.36217,300.117599487305,580.46533203125,,,6,,,,31.7899998559058,,,10,,,,,,,,,,,,,,,,,,,,,,300.089202880859,300.146179199219,580.46533203125,580.46533203125,,,8.62123203277588,,1,0,0,0,0.0138092041015625,30.7917900085449,1,1,1,300.089019775391,0,4232058624,300.119448852539,,,0.00155545439785556,7.72352878942543E-5,0.00155907189441722,7.723917118385E-5,0.923081994056702,0.962749898433685,32.0452880859375,6.5887656211853,35,4,200,0.017424326390028,-0.617578864097595,0.193142086267471,1,,,,,,,,,,,,,,,,
,3870405616.96272,300.0830078125,530.392333984375,,,6,,,,31.7899998559058,,,10,,,,,,,,,,,,,,,,,,,,,,300.071441650391,300.095581054687,530.392333984375,530.392333984375,,,8.62700176239014,,1,0,0,0,0.018310546875,32.2580642700195,1,1,1,300.072418212891,0,4232058624,300.086212158203,,,0.00147523220552406,7.32454189197499E-5,0.00147853894055652,7.32486704632712E-5,0.924231052398682,0.963022470474243,32.040901184082,0.19032995402813,35,4,200,0.0176418647170067,-0.575507283210754,0.194985628128052,1,,,,,,,,,,,,,,,,
,3870405726.43866,300.083526611328,480.392700195313,,,6,,,,31.7899998559058,,,10,,,,,,,,,,,,,,,,,,,,,,300.067047119141,300.101104736328,480.392700195313,480.392700195313,,,8.63798904418945,,1,0,0,0,0,30.3030319213867,1,1,1,300.100006103516,0,4232058752,300.090795898438,,,0.00138412624394018,6.87262096299572E-5,0.00138731673232876,6.87293100659643E-5,0.923430323600769,0.963058710098267,32.0443801879883,0,35,4,200,0.0183764286339283,-0.570825099945068,0.151064082980156,1,,,,,,,,,,,,,,,,
,3870405838.75057,300.153930664063,430.478576660156,,,6,,,,31.7899998559058,,,10,,,,,,,,,,,,,,,,,,,,,,300.144287109375,300.173980712891,430.478576660156,430.478576660156,,,8.64627838134766,,1,0,0,0,0.01708984375,32.7468223571777,1,1,1,300.16357421875,0,4232058656,300.163442993164,,,0.00128438935401818,6.37726532942952E-5,0.00128745010721659,6.37754721624137E-5,0.923698663711548,0.965850114822388,32.0489616394043,,35,4,200,0.0153144411742687,-0.515298783779144,0.199335008859634,1,,,,,,,,,,,,,,,,
,3870405950.97204,300.15641784668,380.356719970703,,,6,,,,31.7899998559058,,,10,,,,,,,,,,,,,,,,,,,,,,300.142852783203,300.172119140625,380.356719970703,380.356719970703,,,8.684983253479,,1,0,0,0,0.0138092041015625,30.7917900085449,1,1,1,300.142608642578,0,4232058656,300.161721801758,,,0.0011670238413038,5.79482773144406E-5,0.00116961764743599,5.79510849575883E-5,0.92301070690155,0.959995269775391,32.0394897460937,0,35,4,200,0.0182628761976957,-0.4215047955513,0.197034761309624,1,,,,,,,,,,,,,,,,
,3870406064.30368,300.152313232422,330.2470703125,,,6,,,,31.7899998559058,,,10,,,,,,,,,,,,,,,,,,,,,,300.150726318359,300.166137695313,330.2470703125,330.2470703125,,,8.67912197113037,,1,0,0,0,0.0165557861328125,31.2805480957031,1,1,1,300.153900146484,0,4232058656,300.158444213867,,,0.00103890815544618,5.15913089577184E-5,0.0010412860540654,5.15936704465374E-5,0.921876013278961,0.959505558013916,32.043384552002,5.66068744659424,35,4,200,0.0189471710473299,-0.39551654458046,0.159294530749321,1,,,,,,,,,,,,,,,,
,3870406179.78771,300.144165039063,280.284057617187,,,6,,,,31.7899998559058,,,10,,,,,,,,,,,,,,,,,,,,,,300.121612548828,300.166778564453,280.284057617187,280.284057617187,,,8.66078186035156,,1,0,0,0,0.0138092041015625,30.7917900085449,1,1,1,300.121551513672,0,4232058752,300.149682617188,,,0.000895485150915195,4.44661812503612E-5,0.000897514384565534,4.44677554795059E-5,0.922696650028229,0.960803806781769,32.0427665710449,0,35,4,200,0.0173835922032595,-0.343288838863373,0.14344622194767,1,,,,,,,,,,,,,,,,
,3870406295.17726,300.064529418945,230.247756958008,,,6,,,,31.7899998559058,,,10,,,,,,,,,,,,,,,,,,,,,,300.052642822266,300.078277587891,230.247756958008,230.247756958008,,,8.63796615600586,,1,0,0,0,0.0164794921875,30.7917900085449,1,1,1,300.053955078125,0,4232058368,300.068618774414,,,0.000736170215956467,3.65658714804026E-5,0.000737736373907016,3.65671513786625E-5,0.919049263000488,0.951098442077637,32.0346374511719,0,35,4,200,0.0185423959046602,-0.256327956914902,0.151080772280693,1,,,,,,,,,,,,,,,,
,3870406408.26076,300.084533691406,180.125869750977,,,6,,,,31.7899998559058,,,10,,,,,,,,,,,,,,,,,,,,,,300.071319580078,300.102020263672,180.125869750977,180.125869750977,,,8.63356113433838,,1,0,0,0,0,31.2805480957031,1,1,1,300.097747802734,0,4232058720,300.091870117188,,,0.000562520293286164,2.79394617884415E-5,0.000563763784588405,2.79405773478056E-5,0.919548213481903,0.953580260276794,32.0391502380371,0,35,4,200,0.0158241912722588,-0.205271080136299,0.128532007336617,1,,,,,,,,,,,,,,,,
,3870406526.20289,300.12223815918,130.456207275391,,,6,,,,31.7899998559058,,,10,,,,,,,,,,,,,,,,,,,,,,300.109771728516,300.141174316406,130.456207275391,130.456207275391,,,8.62978363037109,,1,0,0,0,0.0138092041015625,30.3030319213867,1,1,1,300.134704589844,0,4232058816,300.131799316406,,,0.000378911152932427,1.88183295226597E-5,0.000379732447968229,1.8818972283469E-5,0.920583724975586,0.954582333564758,32.0371513366699,0,35,4,200,0.0167172998189926,-0.148583441972733,0.0884761437773705,1,,,,,,,,,,,,,,,,
,3870406651.49919,300.159896850586,80.346549987793,,,6,,,,31.7899998559058,,,1,,,,,,,,,,,,,,,,,,,,,,300.144622802734,300.177612304687,80.346549987793,80.346549987793,,,8.66675758361816,,1,0,0,0,0.0147247314453125,30.7917900085449,1,1,1,300.175170898438,0,4232058624,300.16748046875,,,0.000181245094742535,9.02421879351136E-6,0.000181437786088034,9.02439115213059E-6,0.893574118614197,0.90376603603363,31.9622344970703,0,35,4,200,0.166762799024582,-0.859806597232819,0.562139093875885,1,,,,,,,,,,,,,,,,
,3870406770.28112,300.157836914063,30.3224506378174,,,6,,,,31.7899998559058,,,1,,,,,,,,,,,,,,,,,,,,,,300.152526855469,300.172058105469,30.3224506378174,30.3224506378174,,,8.6629695892334,,1,0,0,0,0.0151824951171875,30.7917900085449,1,1,1,300.163146972656,0,4232058720,300.163793945312,,,-1.7753676054445E-5,1.41083358709409E-6,-1.85610635824176E-5,1.41211675089147E-6,0.217771753668785,0.240692541003227,32.9658279418945,0.304779827594757,35,4,200,0.174364313483238,-0.488932311534882,1.02671349048614,1,,,,,,,,,,,,,,,,
,3870406883.96846,300.172744750977,-20.0194187164307,,,6,,,,31.7899998559058,,,1,,,,,,,,,,,,,,,,,,,,,,300.154663085937,300.195953369141,-20.0194187164307,-20.0194187164307,,,8.66051197052002,,1,0,0,0,0.01434326171875,30.7917900085449,1,1,1,300.190826416016,0,4232058848,300.183117675781,,,-0.000218938156647153,1.08997756730804E-5,-0.000219548131708291,1.09003986438827E-5,0.894591212272644,0.924456715583801,32.0706062316895,3.81152439117432,35,4,200,0.155898809432983,-0.451009482145309,1.10728311538696,1,,,,,,,,,,,,,,,,
,3870406999.30954,300.192825317383,-70.104621887207,,,6,,,,31.7899998559058,,,1,,,,,,,,,,,,,,,,,,,,,,300.176330566406,300.211029052734,-70.104621887207,-70.104621887207,,,8.65662670135498,,1,0,0,0,0.0140380859375,30.7917900085449,1,1,1,300.209320068359,0,4232058656,300.200894165039,,,-0.000415851050640311,2.06802513127767E-5,-0.000417156412945896,2.06814017929541E-5,0.905495405197144,0.946987330913544,32.0880546569824,0,35,4,200,0.168944627046585,-0.798790216445923,1.71824741363525,1,,,,,,,,,,,,,,,,
,3870407119.73999,300.274124145508,-119.957618713379,,,6,,,,31.7899998559058,,,1,,,,,,,,,,,,,,,,,,,,,,300.251129150391,300.298065185547,-119.957618713379,-119.957618713379,,,8.66207504272461,,1,0,0,0,0.0138092041015625,30.7917900085449,1,1,1,300.250183105469,0,4232058624,300.279849243164,,,-0.000598537911005872,2.97398222822796E-5,-0.000600214487290071,2.97412248766001E-5,0.91493958234787,0.958048343658447,32.0714111328125,5.24967670440674,35,4,200,0.174022868275642,-0.702504396438599,2.68541431427002,1,,,,,,,,,,,,,,,,
,3870407235.53392,300.134262084961,-169.981719970703,,,6,,,,31.7899998559058,,,1,,,,,,,,,,,,,,,,,,,,,,300.113494873047,300.156921386719,-169.981719970703,-169.981719970703,,,8.67140674591064,,1,0,0,0,0.015106201171875,30.7917900085449,1,1,1,300.155029296875,0,4232058656,300.145281982422,,,-0.000772811855122654,3.83843729437977E-5,-0.000774920856389188,3.83861366492098E-5,0.919528245925903,0.966273844242096,32.0679931640625,0.190412551164627,35,4,200,0.150072798132896,-0.85424941778183,3.77243733406067,1,,,,,,,,,,,,,,,,
,3870407355.40046,300.22200012207,-220.005828857422,,,6,,,,31.7899998559058,,,1,,,,,,,,,,,,,,,,,,,,,,300.200103759766,300.244415283203,-220.005828857422,-220.005828857422,,,8.71829319000244,,1,0,0,0,0.0138092041015625,30.3030319213867,1,1,1,300.199584960937,0,4232058592,300.225842285156,,,-0.000925474353345139,4.59700724701498E-5,-0.000927951566392414,4.59718170224057E-5,0.918674230575561,0.963059842586517,32.0654678344727,0,35,4,200,0.186092138290405,-0.775464773178101,4.14969968795776,1,,,,,,,,,,,,,,,,
,3870407470.9433,300.076477050781,-269.993255615234,,,6,,,,31.7899998559058,,,1,,,,,,,,,,,,,,,,,,,,,,300.065063476562,300.092010498047,-269.993255615234,-269.993255615234,,,8.71605777740478,,1,0,0,0,0.0164031982421875,30.7917900085449,1,1,1,300.087890625,0,4232058688,300.084088134766,,,-0.00106949230122287,5.31132073069233E-5,-0.00107229102721541,5.31152425258834E-5,0.921129703521729,0.966998696327209,32.0623817443848,0,35,4,200,0.174945577979088,-1.14832961559296,4.54493951797485,1,,,,,,,,,,,,,,,,
,3870407595.00301,300.087341308594,-320.017364501953,,,6,,,,31.7899998559058,,,10,,,,,,,,,,,,,,,,,,,,,,300.067626953125,300.108184814453,-320.017364501953,-320.017364501953,,,8.69844436645508,,1,0,0,0,0,30.7917900085449,1,1,1,300.066497802734,0,4232058624,300.09287109375,,,-0.00119324259712994,5.92516589883403E-5,-0.00119623754128494,5.92540423473621E-5,0.922690033912659,0.967425525188446,32.0564231872559,0,35,4,200,0.0178514700382948,-0.116588391363621,0.511181175708771,1,,,,,,,,,,,,,,,,
,3870407710.68789,300.02702331543,-370.004791259766,,,6,,,,31.7899998559058,,,10,,,,,,,,,,,,,,,,,,,,,,300.014678955078,300.0419921875,-370.004791259766,-370.004791259766,,,8.6953125,,1,0,0,0,0.01495361328125,30.7917900085449,1,1,1,300.015014648438,0,4232058624,300.031457519531,,,-0.00130594910455762,6.48485961109783E-5,-0.00130921007874121,6.48514359154966E-5,0.922614514827728,0.966748178005219,32.0555114746094,,35,4,200,0.0182850863784552,-0.151917934417725,0.590209186077118,1,,,,,,,,,,,,,,,,
,3870407827.19135,300.134155273438,-420.053314208984,,,6,,,,31.7899998559058,,,10,,,,,,,,,,,,,,,,,,,,,,300.118011474609,300.151153564453,-420.053314208984,-420.053314208984,,,8.70509815216065,,1,0,0,0,0.0138092041015625,30.7917900085449,1,1,1,300.117553710937,0,4232058624,300.140270996094,,,-0.00140581621884841,6.98099688683376E-5,-0.0014093681768045,6.98129907096039E-5,0.922183156013489,0.966638922691345,32.0570869445801,0,35,4,200,0.0172068607062101,-0.117145903408527,0.615685522556305,1,,,,,,,,,,,,,,,,
,3870407941.63608,300.111129760742,-470.028533935547,,,6,,,,31.7899998559058,,,10,,,,,,,,,,,,,,,,,,,,,,300.095092773438,300.128295898438,-470.028533935547,-470.028533935547,,,8.73069477081299,,1,0,0,0,0.0138092041015625,30.3030319213867,1,1,1,300.127166748047,0,4232058624,300.118615722656,,,-0.00149413553390543,7.42040111496124E-5,-0.00149801306649988,7.42078617374469E-5,0.920769393444061,0.965118706226349,32.0601844787598,0,35,4,200,0.0176384411752224,-0.119849026203156,0.653394401073456,1,,,,,,,,,,,,,,,,
,3870408060.26853,300.167236328125,-520.003784179687,,,6,,,,31.7899998559058,,,10,,,,,,,,,,,,,,,,,,,,,,300.141937255859,300.193756103516,-520.003784179687,-520.003784179687,,,8.7710018157959,,1,0,0,0,0.0138092041015625,30.7917900085449,1,1,1,300.140716552734,0,4232058624,300.171343994141,,,-0.00157481509185851,7.82127717001382E-5,-0.00157894532154868,7.82166434909677E-5,0.920458972454071,0.96526300907135,32.061882019043,0,35,4,200,0.018343610689044,-0.138661280274391,0.668883442878723,1,,,,,,,,,,,,,,,,
,3870408176.33034,300.151504516602,-570.101196289063,,,6,,,,31.7899998559058,,,10,,,,,,,,,,,,,,,,,,,,,,300.128082275391,300.175079345703,-570.101196289063,-570.101196289063,,,8.77867412567139,,1,0,0,0,0.015106201171875,30.7917900085449,1,1,1,300.1279296875,0,4232058624,300.155230712891,,,-0.00164594896089589,8.17658887826624E-5,-0.00165047628881667,8.17699015224306E-5,0.917421221733093,0.96197247505188,32.0685501098633,0.190418407320976,35,4,200,0.0214084703475237,-0.172655120491982,0.661820650100708,1,,,,,,,,,,,,,,,,
,3870408295.09088,300.100463867188,-620.113098144531,,,6,,,,31.7899998559058,,,100,,,,,,,,,,,,,,,,,,,,,,300.084930419922,300.120635986328,-620.113098144531,-620.113098144531,,,8.74907112121582,,1,0,0,0,0.0138092041015625,30.3030319213867,1,1,1,300.084930419922,0,4232058688,300.102293395996,,,-0.00168268643888906,8.35558923114745E-5,-0.00168664784143471,8.35590522356475E-5,0.922626435756683,0.962899386882782,32.0475082397461,0,35,4,200,-0.0014530282933265,-0.195190563797951,0.763774573802948,1,,,,,,,,,,,,,,,,
,3870408423.38819,299.987030029297,-669.990539550781,,,6,,,,31.7899998559058,,,10,,,,,,,,,,,,,,,,,,,,,,299.980895996094,299.999908447266,-669.990539550781,-669.990539550781,,,8.74123001098633,,1,0,0,0,0.017242431640625,30.3030319213867,1,1,1,299.98193359375,0,4232058592,299.99192199707,,,-0.00176398495450547,8.76150316523488E-5,-0.00176860448207756,8.76194004327546E-5,0.919440567493439,0.96286529302597,32.061710357666,5.25228834152222,35,4,200,0.0234726723283529,-0.197026029229164,0.79648619890213,1,,,,,,,,,,,,,,,,
,3870408539.63642,300.191329956055,-719.953491210937,,,6,,,,31.7899998559058,,,10,,,,,,,,,,,,,,,,,,,,,,300.180358886719,300.206756591797,-719.953491210937,-719.953491210937,,,8.73369979858398,,1,0,0,0,0.0138092041015625,30.7917900085449,1,1,1,300.180389404297,0,4232058688,300.197375488281,,,-0.00181340895109688,9.00820898425215E-5,-0.00181839225333075,9.00856842313252E-5,0.917785942554474,0.962953686714172,32.0690765380859,,35,4,200,0.0279951486736536,-0.138363882899284,0.810651481151581,1,,,,,,,,,,,,,,,,
,3870408653.53922,300.050262451172,-770.014282226563,,,6,,,,31.7899998559058,,,10,,,,,,,,,,,,,,,,,,,,,,300.028503417969,300.071228027344,-770.014282226563,-770.014282226563,,,8.75588417053223,,1,0,0,0,0.0189208984375,30.7917900085449,1,1,1,300.072021484375,0,4232058720,300.058569335937,,,-0.00185497835241455,9.21324993097265E-5,-0.00185976988189519,9.21362834576537E-5,0.919718503952026,0.962748229503632,32.0600051879883,5.2521824836731,35,4,200,0.0251016933470964,-0.212707921862602,0.818968892097473,1,,,,,,,,,,,,,,,,
,3870408778.42428,300.159042358398,-1499.79418945313,,,6,,,,31.7899998559058,,,10,,,,,,,,,,,,,,,,,,,,,,300.149627685547,300.178283691406,-1499.79418945313,-1499.79418945313,,,8.74657917022705,,1,0,0,0,0.0138092041015625,30.3030319213867,1,1,1,300.16845703125,0,4232058560,300.168325805664,,,-0.00219797860877904,0.000109161713612862,-0.00220364642488171,0.000109167285837216,0.920489490032196,0.964047491550446,32.0590744018555,5.00786663906183E-5,35,4,200,-0.000756024732254446,-0.275968909263611,0.803748250007629,1,,,,,,,,,,,,,,,,
,3870408893.04224,300.069412231445,-4000.41259765625,,,6,,,,31.7899998559058,,,10,,,,,,,,,,,,,,,,,,,,,,300.061218261719,300.086364746094,-4000.41259765625,-4000.41259765625,,,8.73470783233643,,1,0,0,0,0.0138092041015625,30.3030319213867,1,1,1,300.077606201172,0,4232058688,300.076867675781,,,-0.00244002524590476,0.00012124470099561,-0.00244686791383014,0.000121251636763731,0.914357185363769,0.956715643405914,32.0699424743652,5.24937915802002,35,4,200,-0.00427085813134909,-0.271974205970764,0.949358701705933,1,,,,,,,,,,,,,,,,
,3870409013.67689,300.123519897461,-6500.32177734375,,,6,,,,31.7899998559058,,,10,,,,,,,,,,,,,,,,,,,,,,300.107696533203,300.140716552734,-6500.32177734375,-6500.32177734375,,,8.72868156433105,,1,0,0,0,0.0177001953125,30.7917900085449,1,1,1,300.139343261719,0,4232058624,300.130807495117,,,-0.00248138978700559,0.000123387509210064,-0.00248909794171559,0.00012339457127439,0.906511127948761,0.948170483112335,32.0842628479004,0,35,4,200,-0.00858087930828333,-0.327067375183105,0.971803367137909,1,,,,,,,,,,,,,,,,
,3870409131.93653,300.214950561523,-9000.40234375,,,6,,,,31.7899998559058,,,10,,,,,,,,,,,,,,,,,,,,,,300.208374023438,300.235595703125,-9000.40234375,-9000.40234375,,,8.74253845214844,,1,0,0,0,0.016326904296875,30.3030319213867,1,1,1,300.221527099609,0,4232058624,300.225155639648,,,-0.00248971555460233,0.000123909970070075,-0.00249832401986668,0.000123917410854772,0.897651612758636,0.938842535018921,32.099910736084,0.189368650317192,35,4,200,-0.0107015091925859,-0.334164083003998,0.95583313703537,1,,,,,,,,,,,,,,,,
,3870409283.6174,300.122344970703,-25000.390625,,,6,,,,31.7899998559058,,,10,,,,,,,,,,,,,,,,,,,,,,300.115631103516,300.140991210937,-25000.390625,-25000.390625,,,8.76175022125244,,1,0,0,0,0,30.3030319213867,1,1,1,300.129058837891,0,4232058560,300.131048583984,,,-0.00241418341111738,0.000121181586149152,-0.00242874016320953,0.000121193396414218,0.834963798522949,0.874849855899811,32.1933670043945,5.67391967773438,35,4,200,-0.0156399868428707,-0.491062372922897,0.820061862468719,1,,,,,,,,,,,,,,,,
,3870409435.19026,300.152481079102,-50000.40234375,,,6,,,,31.7899998559058,,,10,,,,,,,,,,,,,,,,,,,,,,300.136932373047,300.173004150391,-50000.40234375,-50000.40234375,,,8.72921943664551,,1,0,0,0,0.0138092041015625,30.7917900085449,1,1,1,300.137359619141,0,4232058592,300.159921264648,,,-0.00223221095718194,0.000115196053420585,-0.0022597951688179,0.00011522003736536,0.717709600925446,0.760845839977264,32.3516578674316,,35,4,200,-0.0115096298977733,-0.585539102554321,0.766893982887268,1,,,,,,,,,,,,,,,,
,3870409557.44437,300.103454589844,-70000.359375,,,6,,,,31.7899998559058,,,10,,,,,,,,,,,,,,,,,,,,,,300.095062255859,300.117828369141,-70000.359375,-70000.359375,,,8.76620578765869,,1,0,0,0,0.0138092041015625,30.3030319213867,1,1,1,300.095489501953,0,4232058464,300.109057617188,,,-0.00207802564474327,0.000111263038513589,-0.00211954495425129,0.000111299749644332,0.619143545627594,0.66663384437561,32.4865608215332,0.00288700824603438,35,4,200,-0.0276366714388132,-0.788265943527222,0.622353494167328,1,,,,,,,,,,,,,,,,