File: Data/KMK245/TGA/KMK245_1000C_Air.txt
Filename	KMK245_1000C_Air
Instrument name	0650-0588 (172.23.191.35)
Operator	Kyle Kirkpatrick
rundate	1/18/2023
Sample name	KMK245_1000C_Air
proceduresegments	Blend Channel B (Air) at 100% with Channel A (N2); Equilibrate 30.00 °C; Ramp 10.00 °C/min to 1000.00 °C
[File Parameters]
Run date	1/18/2023 10:10:26 PM
Trios version	5.5.1.5
Original File Name
Current File Name	C:\Users\ucsdi\OneDrive\Desktop\Data\Rinehart\Kyle\Jan 18 2023\KMK245_1000C_Air.tri
User at run start	DESKTOP-JSQIMO4\ucsdi
[Procedure]
Procedure Name
Sample Name	KMK245_1000C_Air
Sample Mass	4.202841 mg
Pan Number	8
Reference Pan Number	30
Pan Type	Alumina 90 ul
Comments
Project Name
Operator	Kyle Kirkpatrick
Skip Weight Stabilization	False
Enable Air Cool	True
Air Cool Until Temperature Is Below	50
End of Test Delay	0
Stop on Gas Flow Error	No
Sample mass pre-weigh	Not Available
[Signal List]
Signal #1	Time (min)
Signal #2	Temperature (°C)
Signal #3	Sample Flow (mL/min)
Signal #4	Balance Flow (mL/min)
Signal #5	Set Point (°C)
Signal #6	Power Requested (W)
Signal #7	Power Delivered (W)
Signal #8	Temperature Rate (°C/min)
Signal #9	Weight (mg)
Signal #10	Heat Flow (mW)
Signal #11	Weight Corrected Heat Flow (W/g)
Signal #12	Weight Change (%)
Signal #13	Temperature Difference (°C)
Signal #14	Channel A Flow (mL/min)
Signal #15	Channel A Flow (%)
Signal #16	Channel B Flow (mL/min)
Signal #17	Channel B Flow (%)
[Configuration]
Company Name
Instrument Name	0650-0588
Instrument Type	SDT650
Serial Number	0650-0588
IP	172.23.191.35
Location of Instrument	MFG
DisplayType	TianmaV2andV3
Sample Interval 	0.1 s/pt
Gas 1	Nitrogen
Gas 2	Air
Gas 3	Oxygen
Gas 4	Nitrogen
Total Sample Flow	100
Channel B	0%
Channel A Gas Selected	1
Channel B Gas Selected	4
Thermocouple Type	Type R
Exotherm Direction	Up
Sampling Mode	Single Sample Mode
[Versions]
Common IDD Version	1
Cortex Version	VER 1.3.3.11
Driver	5.0.0.7
GDM Version	1.2.1.2
Blending GDM Version	1.2.1.2
Blending GDM Bootloader	2.0.0.5
TouchscreenVersion	1.0.3.1817
Transducer Version	1.1.0.32
Transducer Bootloader	2.0.0.5
PCU Version	1.2.0.15
PCU Bootloader	2.0.0.5
AutoSampler Version	2.0.4.19
Auto Sampler Bootloader	2.0.0.5
[Experiment Logs]
Experiment Log Entry # 1	Blending segment primary gas 4, percent 0, secondary gas 2
Experiment Log Entry # 3	Equilibrate Segment 30 (C) Started
Experiment Log Entry # 5	Ramp Segment 10 C/min to 1000 C Started
[Method Log]
Method Log Entry # 1	Blend Channel B at 100% with Channel A
Method Log Entry # 2	Equilibrate 30 °C
Method Log Entry # 3	(Ramp 691014) Ramp 10 °C/minute to 1000 °C
[Room Temperature Calibration]
Date Applied	2/24/2021 3:27:30 AM
Measured	22.351
Correct	22.200
[Furnace Room Temperature Calibration]
Date Applied	2/24/2021 3:27:30 AM
Measured	24.159
Correct	22.200
[DTA Signal Setup]
Date Applied	1/11/2023 5:48:48 PM
Description	From 200.000 °C to 1,450.000 °C at 20.000°C/min
Source Files 1	C:\Users\ucsdi\OneDrive\Desktop\Data\Sailor\Ricardo\Calibrations\1-11-23\Weight Calibration.tri
[Weight Calibration]
Date Applied	1/11/2023 5:48:48 PM
Reference Beam Weight	4892.573
Reference Beam Weight at 200 °C	435.1747
Reference Beam Gain	0.09938934
Sample Beam Weight	5794.918
Sample Beam Weight at 200 °C	439.0667
Sample Beam Gain	0.09625536
Weight Ratio	0.9274598
Reference Weight	341.1444
Sample Weight	336.5152
[Heat Flow Calibration]
Date Applied	1/12/2023 4:18:26 AM
Description	From 100.000 °C to 1,450.000 °C at 20.000°C/min
Source Files 1	C:\Users\ucsdi\OneDrive\Desktop\Data\Sailor\Ricardo\Calibrations\1-11-23\Heat Flow Sapphire Calibration(1).tri
Source Files 2	C:\Users\ucsdi\OneDrive\Desktop\Data\Sailor\Ricardo\Calibrations\1-11-23\Heat Flow Sapphire Calibration.tri
[Temperature Calibration]
Date Applied	1/11/2023 9:24:14 PM
Description	From 107.000 °C to 227.000 °C at 10.000°C/min
Gas Type	Nitrogen
Pan Type	Alumina 90 ul
Source Files 1	C:\Users\ucsdi\OneDrive\Desktop\Data\Sailor\Ricardo\Calibrations\1-11-23\Indium.tri
Source Files 2	C:\Users\ucsdi\OneDrive\Desktop\Data\Sailor\Ricardo\Calibrations\1-11-23\Zinc.tri
Source Files 3	C:\Users\ucsdi\OneDrive\Desktop\Data\Sailor\Ricardo\Calibrations\1-11-23\Tin.tri
Measured 1	155.275
Known 1	156.6
Measured 2	230.5534
Known 2	231.93
Measured 3	418.0948
Known 3	419.53
[Dual Weight]
Date Applied	1/12/2023 4:18:26 AM
[Dual DeltaT]
Date Applied	1/12/2023 4:18:26 AM
[Cell Constant Calibration]
Date Applied	4/21/2022 4:38:29 AM
Description	From 370.000 °C to 480.000 °C at 10.000°C/min
Gas Type	Nitrogen
Pan Type	Alumina 90 ul
Source Files 1	C:\Users\ucsdi\OneDrive\Desktop\Sailor\Ricardo\Calibrations\Zinc(2).tri
Cell Constant	1.029587
Temperature	419.53
[Rev Cp Calibration]
Date Applied	1/12/2023 5:11:31 PM
Description	From 210.000 °C to 1,500.000 °C at 2.000°C/min
Gas Type	Nitrogen
Pan Type	Alumina 90 ul
Source Files 1	C:\Users\ucsdi\OneDrive\Desktop\Data\Sailor\Ricardo\Calibrations\1-11-23\Sappphire calibration.tri
[step]
Ramp 10.00 °C/min to 1000.00 °C
Time	Temperature	Heat Flow (Normalized)	Weight	Heat Flow	Weight
min	°C	W/g	%	mW	mg
0.00			99.717		4.191
0.08	31.07	1.445	99.717	6.073	4.191
0.15	31.06	1.446	99.717	6.076	4.191
0.23	31.06	1.446	99.718	6.079	4.191
0.31	31.07	1.444	99.720	6.070	4.191
0.38	31.11	1.436	99.726	6.035	4.191
0.46	31.22	1.412	99.735	5.934	4.192
0.54	31.40	1.377	99.746	5.785	4.192
0.61	31.65	1.332	99.758	5.597	4.193
0.69	31.99	1.278	99.770	5.371	4.193
0.77	32.42	1.218	99.781	5.119	4.194
0.84	32.92	1.153	99.791	4.846	4.194
0.92	33.49	1.086	99.800	4.564	4.194
1.00	34.13	1.018	99.808	4.278	4.195
1.07	34.83	0.954	99.814	4.008	4.195
1.15	35.58	0.893	99.819	3.753	4.195
1.23	36.37	0.836	99.823	3.513	4.195
1.30	37.19	0.786	99.827	3.303	4.196
1.38	38.04	0.741	99.829	3.115	4.196
1.46	38.91	0.705	99.831	2.963	4.196
1.53	39.78	0.670	99.833	2.816	4.196
1.61	40.67	0.643	99.834	2.704	4.196
1.69	41.55	0.623	99.834	2.619	4.196
1.76	42.42	0.608	99.834	2.555	4.196
1.84	43.29	0.596	99.833	2.503	4.196
1.92	44.15	0.587	99.833	2.467	4.196
1.99	44.99	0.583	99.832	2.452	4.196
2.07	45.82	0.582	99.830	2.445	4.196
2.15	46.63	0.582	99.829	2.444	4.196
2.22	47.43	0.584	99.827	2.456	4.196
2.30	48.22	0.592	99.825	2.486	4.195
2.38	48.99	0.602	99.823	2.530	4.195
2.45	49.75	0.617	99.822	2.594	4.195
2.53	50.51	0.632	99.821	2.656	4.195
2.61	51.25	0.647	99.820	2.719	4.195
2.68	51.99	0.666	99.818	2.797	4.195
2.76	52.72	0.684	99.818	2.874	4.195
2.84	53.45	0.703	99.817	2.954	4.195
2.91	54.17	0.720	99.815	3.027	4.195
2.99	54.90	0.739	99.814	3.107	4.195
3.07	55.62	0.758	99.812	3.185	4.195
3.14	56.34	0.777	99.811	3.265	4.195
3.22	57.07	0.795	99.809	3.342	4.195
3.30	57.80	0.815	99.807	3.425	4.195
3.37	58.53	0.834	99.806	3.504	4.195
3.45	59.27	0.853	99.804	3.584	4.195
3.53	60.01	0.871	99.802	3.660	4.195
3.60	60.75	0.888	99.800	3.731	4.194
3.68	61.49	0.905	99.799	3.805	4.194
3.76	62.24	0.923	99.797	3.881	4.194
3.83	63.00	0.942	99.794	3.958	4.194
3.91	63.76	0.960	99.792	4.033	4.194
3.99	64.52	0.975	99.789	4.097	4.194
4.06	65.28	0.991	99.787	4.165	4.194
4.14	66.04	1.008	99.784	4.235	4.194
4.22	66.81	1.026	99.782	4.312	4.194
4.29	67.58	1.042	99.779	4.379	4.194
4.37	68.35	1.057	99.776	4.443	4.193
4.45	69.12	1.077	99.773	4.525	4.193
4.52	69.89	1.093	99.770	4.592	4.193
4.60	70.66	1.111	99.767	4.668	4.193
4.68	71.43	1.126	99.764	4.734	4.193
4.75	72.21	1.142	99.761	4.799	4.193
4.83	72.98	1.160	99.758	4.876	4.193
4.91	73.75	1.177	99.754	4.947	4.193
4.98	74.52	1.197	99.751	5.032	4.192
5.06	75.29	1.214	99.747	5.103	4.192
5.14	76.06	1.231	99.743	5.172	4.192
5.21	76.83	1.249	99.739	5.249	4.192
5.29	77.59	1.266	99.735	5.322	4.192
5.37	78.36	1.285	99.730	5.399	4.192
5.44	79.13	1.302	99.726	5.474	4.191
5.52	79.89	1.321	99.722	5.552	4.191
5.60	80.66	1.339	99.718	5.627	4.191
5.67	81.42	1.359	99.714	5.712	4.191
5.75	82.19	1.378	99.710	5.792	4.191
5.83	82.95	1.395	99.705	5.861	4.190
5.90	83.72	1.413	99.701	5.940	4.190
5.98	84.48	1.432	99.697	6.017	4.190
6.06	85.25	1.451	99.692	6.097	4.190
6.13	86.01	1.471	99.688	6.181	4.190
6.21	86.78	1.489	99.684	6.258	4.190
6.29	87.54	1.507	99.682	6.335	4.189
6.36	88.31	1.527	99.681	6.417	4.189
6.44	89.07	1.546	99.679	6.496	4.189
6.52	89.84	1.564	99.677	6.573	4.189
6.59	90.61	1.583	99.673	6.654	4.189
6.67	91.37	1.601	99.670	6.731	4.189
6.75	92.14	1.621	99.666	6.813	4.189
6.82	92.91	1.640	99.662	6.892	4.189
6.90	93.67	1.659	99.657	6.974	4.188
6.98	94.44	1.678	99.653	7.052	4.188
7.05	95.21	1.696	99.648	7.130	4.188
7.13	95.98	1.716	99.644	7.213	4.188
7.21	96.75	1.735	99.640	7.293	4.188
7.28	97.51	1.753	99.635	7.368	4.188
7.36	98.28	1.775	99.631	7.459	4.187
7.44	99.05	1.793	99.627	7.538	4.187
7.51	99.82	1.813	99.622	7.620	4.187
7.59	100.59	1.832	99.618	7.700	4.187
7.67	101.36	1.852	99.614	7.786	4.187
7.74	102.13	1.872	99.610	7.867	4.186
7.82	102.90	1.891	99.605	7.946	4.186
7.90	103.67	1.911	99.602	8.031	4.186
7.97	104.44	1.931	99.598	8.117	4.186
8.05	105.20	1.950	99.593	8.198	4.186
8.13	105.97	1.970	99.589	8.279	4.186
8.20	106.74	1.991	99.585	8.367	4.185
8.28	107.51	2.011	99.581	8.453	4.185
8.36	108.28	2.031	99.578	8.536	4.185
8.43	109.05	2.051	99.574	8.618	4.185
8.51	109.82	2.070	99.570	8.702	4.185
8.59	110.59	2.093	99.567	8.796	4.185
8.66	111.36	2.112	99.564	8.876	4.185
8.74	112.12	2.133	99.561	8.965	4.184
8.82	112.89	2.153	99.557	9.050	4.184
8.89	113.66	2.174	99.554	9.136	4.184
8.97	114.43	2.193	99.551	9.217	4.184
9.05	115.20	2.214	99.547	9.305	4.184
9.12	115.97	2.234	99.544	9.391	4.184
9.20	116.74	2.254	99.540	9.475	4.184
9.28	117.51	2.275	99.537	9.562	4.183
9.35	118.28	2.297	99.534	9.653	4.183
9.43	119.04	2.318	99.532	9.742	4.183
9.51	119.81	2.339	99.529	9.831	4.183
9.58	120.58	2.360	99.526	9.918	4.183
9.66	121.35	2.382	99.523	10.009	4.183
9.74	122.12	2.402	99.520	10.095	4.183
9.81	122.89	2.423	99.517	10.185	4.183
9.89	123.66	2.444	99.514	10.273	4.182
9.97	124.43	2.466	99.510	10.362	4.182
10.04	125.19	2.487	99.508	10.452	4.182
10.12	125.96	2.507	99.507	10.537	4.182
10.20	126.73	2.529	99.505	10.629	4.182
10.27	127.50	2.549	99.503	10.714	4.182
10.35	128.27	2.570	99.501	10.802	4.182
10.43	129.04	2.592	99.499	10.896	4.182
10.50	129.81	2.614	99.496	10.985	4.182
10.58	130.58	2.636	99.494	11.077	4.182
10.66	131.34	2.657	99.492	11.167	4.181
10.73	132.11	2.678	99.490	11.256	4.181
10.81	132.88	2.700	99.487	11.348	4.181
10.89	133.65	2.722	99.484	11.441	4.181
10.96	134.42	2.743	99.482	11.530	4.181
11.04	135.19	2.765	99.480	11.619	4.181
11.12	135.96	2.787	99.478	11.712	4.181
11.19	136.73	2.808	99.475	11.803	4.181
11.27	137.49	2.831	99.473	11.896	4.181
11.35	138.26	2.853	99.470	11.989	4.181
11.42	139.03	2.875	99.468	12.083	4.180
11.50	139.80	2.898	99.465	12.180	4.180
11.58	140.57	2.919	99.463	12.267	4.180
11.65	141.34	2.940	99.461	12.356	4.180
11.73	142.11	2.964	99.458	12.456	4.180
11.81	142.87	2.986	99.456	12.551	4.180
11.88	143.64	3.009	99.454	12.645	4.180
11.96	144.41	3.031	99.451	12.739	4.180
12.04	145.18	3.055	99.449	12.839	4.180
12.11	145.95	3.076	99.447	12.928	4.180
12.19	146.72	3.100	99.445	13.029	4.180
12.27	147.48	3.121	99.443	13.117	4.179
12.34	148.25	3.145	99.441	13.217	4.179
12.42	149.02	3.168	99.439	13.314	4.179
12.50	149.79	3.191	99.437	13.412	4.179
12.57	150.56	3.214	99.435	13.506	4.179
12.65	151.33	3.239	99.433	13.612	4.179
12.73	152.09	3.262	99.431	13.709	4.179
12.80	152.86	3.283	99.429	13.800	4.179
12.88	153.63	3.307	99.427	13.900	4.179
12.96	154.40	3.332	99.426	14.002	4.179
13.03	155.17	3.355	99.424	14.100	4.179
13.11	155.94	3.378	99.422	14.198	4.179
13.19	156.71	3.403	99.421	14.302	4.178
13.26	157.47	3.426	99.419	14.397	4.178
13.34	158.24	3.451	99.417	14.505	4.178
13.42	159.01	3.475	99.415	14.605	4.178
13.49	159.78	3.499	99.413	14.705	4.178
13.57	160.55	3.524	99.412	14.812	4.178
13.65	161.32	3.548	99.410	14.911	4.178
13.72	162.08	3.570	99.409	15.006	4.178
13.80	162.85	3.596	99.408	15.113	4.178
13.88	163.62	3.621	99.407	15.219	4.178
13.95	164.39	3.645	99.405	15.319	4.178
14.03	165.16	3.673	99.404	15.435	4.178
14.11	165.93	3.697	99.402	15.540	4.178
14.18	166.70	3.724	99.401	15.650	4.178
14.26	167.46	3.750	99.400	15.759	4.178
14.34	168.23	3.775	99.399	15.865	4.178
14.41	169.00	3.799	99.398	15.968	4.178
14.49	169.77	3.826	99.397	16.078	4.177
14.57	170.54	3.852	99.396	16.189	4.177
14.64	171.31	3.878	99.395	16.297	4.177
14.72	172.07	3.904	99.394	16.406	4.177
14.80	172.84	3.930	99.393	16.519	4.177
14.87	173.61	3.956	99.392	16.627	4.177
14.95	174.38	3.983	99.390	16.740	4.177
15.03	175.15	4.011	99.389	16.856	4.177
15.10	175.92	4.038	99.388	16.970	4.177
15.18	176.69	4.065	99.387	17.083	4.177
15.26	177.46	4.092	99.387	17.199	4.177
15.33	178.23	4.119	99.386	17.311	4.177
15.41	178.99	4.147	99.385	17.427	4.177
15.49	179.76	4.175	99.384	17.546	4.177
15.56	180.53	4.202	99.383	17.662	4.177
15.64	181.30	4.231	99.382	17.783	4.177
15.72	182.07	4.260	99.381	17.902	4.177
15.79	182.84	4.288	99.380	18.022	4.177
15.87	183.61	4.317	99.379	18.142	4.177
15.95	184.38	4.348	99.379	18.273	4.177
16.02	185.15	4.376	99.378	18.392	4.177
16.10	185.92	4.406	99.378	18.516	4.177
16.18	186.69	4.437	99.376	18.648	4.177
16.25	187.46	4.467	99.375	18.772	4.177
16.33	188.23	4.497	99.374	18.899	4.177
16.41	189.00	4.527	99.373	19.026	4.176
16.48	189.77	4.558	99.372	19.155	4.176
16.56	190.53	4.589	99.371	19.285	4.176
16.64	191.30	4.621	99.370	19.421	4.176
16.71	192.07	4.655	99.369	19.565	4.176
16.79	192.84	4.686	99.368	19.695	4.176
16.87	193.62	4.719	99.366	19.832	4.176
16.94	194.39	4.750	99.365	19.965	4.176
17.02	195.16	4.784	99.364	20.106	4.176
17.10	195.93	4.818	99.363	20.248	4.176
17.17	196.70	4.852	99.361	20.392	4.176
17.25	197.47	4.886	99.360	20.534	4.176
17.33	198.24	4.919	99.359	20.675	4.176
17.40	199.01	4.954	99.357	20.820	4.176
17.48	199.78	4.988	99.356	20.965	4.176
17.56	200.55	5.023	99.354	21.110	4.176
17.63	201.32	5.058	99.353	21.260	4.176
17.71	202.09	5.094	99.351	21.409	4.176
17.79	202.87	5.131	99.349	21.565	4.175
17.86	203.64	5.167	99.347	21.714	4.175
17.94	204.41	5.204	99.345	21.871	4.175
18.02	205.18	5.241	99.343	22.028	4.175
18.09	205.96	5.278	99.340	22.183	4.175
18.17	206.73	5.315	99.338	22.340	4.175
18.25	207.50	5.354	99.335	22.501	4.175
18.32	208.28	5.392	99.332	22.662	4.175
18.40	209.05	5.431	99.329	22.825	4.175
18.48	209.82	5.470	99.325	22.991	4.174
18.55	210.59	5.508	99.322	23.149	4.174
18.63	211.37	5.548	99.318	23.318	4.174
18.71	212.14	5.588	99.313	23.484	4.174
18.78	212.91	5.628	99.309	23.654	4.174
18.86	213.69	5.670	99.304	23.828	4.174
18.94	214.46	5.709	99.299	23.996	4.173
19.01	215.23	5.750	99.294	24.165	4.173
19.09	216.01	5.791	99.289	24.339	4.173
19.17	216.78	5.832	99.283	24.511	4.173
19.24	217.55	5.874	99.277	24.690	4.172
19.32	218.33	5.918	99.271	24.873	4.172
19.40	219.10	5.962	99.264	25.056	4.172
19.47	219.88	6.006	99.257	25.240	4.172
19.55	220.65	6.049	99.249	25.423	4.171
19.63	221.42	6.092	99.241	25.603	4.171
19.70	222.20	6.136	99.233	25.791	4.171
19.78	222.97	6.182	99.224	25.980	4.170
19.86	223.74	6.227	99.214	26.169	4.170
19.93	224.52	6.272	99.204	26.361	4.169
20.01	225.29	6.319	99.194	26.556	4.169
20.09	226.07	6.366	99.183	26.754	4.169
20.16	226.84	6.412	99.172	26.949	4.168
20.24	227.61	6.459	99.160	27.147	4.168
20.32	228.39	6.508	99.147	27.350	4.167
20.39	229.16	6.556	99.134	27.555	4.166
20.47	229.94	6.605	99.120	27.761	4.166
20.55	230.72	6.655	99.105	27.970	4.165
20.62	231.49	6.705	99.090	28.178	4.165
20.70	232.27	6.755	99.074	28.391	4.164
20.78	233.04	6.806	99.058	28.604	4.163
20.85	233.82	6.857	99.041	28.820	4.163
20.93	234.59	6.909	99.023	29.038	4.162
21.01	235.37	6.962	99.004	29.260	4.161
21.08	236.14	7.016	98.985	29.485	4.160
21.16	236.92	7.068	98.965	29.707	4.159
21.24	237.70	7.125	98.944	29.946	4.158
21.31	238.47	7.179	98.923	30.172	4.158
21.39	239.25	7.235	98.901	30.408	4.157
21.47	240.03	7.291	98.877	30.644	4.156
21.54	240.80	7.348	98.854	30.884	4.155
21.62	241.58	7.406	98.829	31.126	4.154
21.70	242.36	7.465	98.803	31.373	4.153
21.77	243.14	7.524	98.776	31.623	4.151
21.85	243.91	7.585	98.749	31.877	4.150
21.93	244.69	7.646	98.721	32.133	4.149
22.00	245.47	7.706	98.692	32.386	4.148
22.08	246.25	7.768	98.662	32.649	4.147
22.16	247.03	7.832	98.632	32.917	4.145
22.23	247.80	7.896	98.600	33.184	4.144
22.31	248.58	7.959	98.568	33.450	4.143
22.39	249.36	8.024	98.534	33.724	4.141
22.46	250.14	8.089	98.500	33.997	4.140
22.54	250.92	8.155	98.465	34.274	4.138
22.62	251.70	8.222	98.429	34.556	4.137
22.69	252.48	8.288	98.392	34.833	4.135
22.77	253.26	8.353	98.354	35.107	4.134
22.85	254.04	8.420	98.315	35.387	4.132
22.92	254.82	8.486	98.275	35.667	4.130
23.00	255.60	8.552	98.234	35.944	4.129
23.08	256.37	8.619	98.192	36.226	4.127
23.15	257.15	8.685	98.149	36.501	4.125
23.23	257.93	8.751	98.105	36.779	4.123
23.31	258.71	8.815	98.060	37.049	4.121
23.38	259.49	8.880	98.014	37.320	4.119
23.46	260.27	8.944	97.967	37.589	4.117
23.54	261.04	9.005	97.919	37.847	4.115
23.61	261.82	9.066	97.870	38.104	4.113
23.69	262.60	9.126	97.820	38.356	4.111
23.77	263.37	9.184	97.770	38.598	4.109
23.84	264.15	9.238	97.718	38.825	4.107
23.92	264.92	9.290	97.665	39.045	4.105
24.00	265.70	9.342	97.611	39.264	4.102
24.07	266.47	9.390	97.557	39.465	4.100
24.15	267.24	9.436	97.501	39.659	4.098
24.23	268.01	9.479	97.445	39.839	4.095
24.30	268.78	9.520	97.388	40.012	4.093
24.38	269.56	9.557	97.330	40.167	4.091
24.46	270.32	9.592	97.271	40.314	4.088
24.53	271.09	9.621	97.211	40.436	4.086
24.61	271.86	9.648	97.151	40.548	4.083
24.69	272.62	9.674	97.090	40.658	4.081
24.76	273.39	9.695	97.028	40.745	4.078
24.84	274.15	9.713	96.966	40.824	4.075
24.92	274.92	9.727	96.903	40.881	4.073
24.99	275.68	9.739	96.839	40.929	4.070
25.07	276.44	9.749	96.774	40.972	4.067
25.15	277.20	9.757	96.710	41.008	4.065
25.22	277.96	9.764	96.644	41.039	4.062
25.30	278.72	9.768	96.578	41.052	4.059
25.38	279.48	9.768	96.511	41.052	4.056
25.45	280.24	9.763	96.444	41.032	4.053
25.53	280.99	9.754	96.377	40.994	4.051
25.61	281.75	9.743	96.309	40.949	4.048
25.68	282.50	9.730	96.241	40.894	4.045
25.76	283.26	9.716	96.172	40.833	4.042
25.84	284.01	9.698	96.103	40.760	4.039
25.91	284.77	9.681	96.034	40.686	4.036
25.99	285.52	9.662	95.964	40.606	4.033
26.07	286.28	9.642	95.894	40.523	4.030
26.14	287.03	9.618	95.823	40.422	4.027
26.22	287.78	9.596	95.753	40.330	4.024
26.30	288.53	9.572	95.681	40.228	4.021
26.37	289.29	9.546	95.609	40.119	4.018
26.45	290.04	9.523	95.538	40.022	4.015
26.53	290.79	9.494	95.466	39.903	4.012
26.60	291.54	9.468	95.394	39.794	4.009
26.68	292.29	9.441	95.321	39.679	4.006
26.76	293.05	9.412	95.249	39.557	4.003
26.83	293.80	9.384	95.176	39.439	4.000
26.91	294.55	9.357	95.102	39.324	3.997
26.99	295.30	9.327	95.029	39.199	3.994
27.06	296.06	9.298	94.955	39.076	3.991
27.14	296.81	9.268	94.882	38.952	3.988
27.22	297.56	9.237	94.808	38.822	3.985
27.29	298.31	9.207	94.734	38.694	3.982
27.37	299.07	9.178	94.660	38.573	3.978
27.45	299.82	9.147	94.586	38.442	3.975
27.52	300.57	9.114	94.512	38.305	3.972
27.60	301.32	9.083	94.437	38.174	3.969
27.68	302.07	9.053	94.363	38.046	3.966
27.75	302.83	9.020	94.289	37.910	3.963
27.83	303.58	8.986	94.215	37.766	3.960
27.91	304.33	8.952	94.141	37.625	3.957
27.98	305.08	8.919	94.066	37.485	3.953
28.06	305.83	8.886	93.993	37.344	3.950
28.14	306.58	8.852	93.918	37.202	3.947
28.21	307.34	8.818	93.845	37.061	3.944
28.29	308.09	8.784	93.771	36.918	3.941
28.37	308.84	8.751	93.697	36.778	3.938
28.44	309.59	8.716	93.624	36.634	3.935
28.52	310.35	8.681	93.551	36.486	3.932
28.60	311.10	8.647	93.477	36.341	3.929
28.67	311.85	8.612	93.405	36.196	3.926
28.75	312.60	8.577	93.332	36.049	3.923
28.83	313.35	8.543	93.260	35.903	3.920
28.90	314.11	8.507	93.188	35.754	3.917
28.98	314.86	8.472	93.116	35.608	3.914
29.06	315.61	8.436	93.045	35.455	3.911
29.13	316.36	8.401	92.974	35.308	3.908
29.21	317.11	8.365	92.903	35.157	3.905
29.29	317.86	8.328	92.833	35.002	3.902
29.36	318.62	8.293	92.763	34.852	3.899
29.44	319.37	8.257	92.694	34.703	3.896
29.52	320.12	8.218	92.626	34.537	3.893
29.59	320.87	8.181	92.558	34.383	3.890
29.67	321.62	8.141	92.490	34.217	3.887
29.75	322.37	8.103	92.423	34.056	3.884
29.82	323.12	8.062	92.357	33.882	3.882
29.90	323.87	8.022	92.291	33.716	3.879
29.98	324.63	7.980	92.227	33.538	3.876
30.05	325.38	7.937	92.162	33.357	3.873
30.13	326.13	7.894	92.099	33.178	3.871
30.21	326.88	7.851	92.036	32.995	3.868
30.28	327.63	7.805	91.974	32.802	3.866
30.36	328.38	7.758	91.913	32.607	3.863
30.44	329.13	7.712	91.853	32.413	3.860
30.51	329.87	7.663	91.794	32.207	3.858
30.59	330.62	7.615	91.736	32.004	3.855
30.67	331.37	7.566	91.678	31.799	3.853
30.74	332.12	7.515	91.622	31.585	3.851
30.82	332.87	7.464	91.567	31.371	3.848
30.90	333.62	7.412	91.513	31.152	3.846
30.97	334.37	7.360	91.459	30.934	3.844
31.05	335.11	7.306	91.407	30.706	3.842
31.13	335.86	7.252	91.357	30.478	3.840
31.20	336.61	7.197	91.307	30.247	3.837
31.28	337.36	7.143	91.258	30.022	3.835
31.36	338.11	7.088	91.211	29.789	3.833
31.43	338.85	7.033	91.164	29.556	3.831
31.51	339.60	6.977	91.119	29.323	3.830
31.59	340.35	6.921	91.075	29.089	3.828
31.66	341.10	6.866	91.032	28.855	3.826
31.74	341.84	6.810	90.991	28.623	3.824
31.82	342.59	6.754	90.950	28.385	3.822
31.89	343.34	6.699	90.911	28.153	3.821
31.97	344.09	6.643	90.872	27.920	3.819
32.05	344.84	6.588	90.835	27.687	3.818
32.12	345.58	6.531	90.800	27.450	3.816
32.20	346.33	6.478	90.765	27.227	3.815
32.28	347.08	6.425	90.731	27.005	3.813
32.35	347.83	6.373	90.698	26.784	3.812
32.43	348.58	6.320	90.667	26.560	3.811
32.51	349.33	6.267	90.636	26.338	3.809
32.58	350.08	6.214	90.606	26.118	3.808
32.66	350.83	6.164	90.577	25.907	3.807
32.74	351.57	6.112	90.549	25.688	3.806
32.81	352.32	6.063	90.521	25.480	3.804
32.89	353.07	6.014	90.494	25.275	3.803
32.97	353.83	5.966	90.469	25.074	3.802
33.04	354.58	5.920	90.445	24.883	3.801
33.12	355.33	5.874	90.421	24.686	3.800
33.20	356.08	5.828	90.398	24.495	3.799
33.27	356.83	5.786	90.375	24.316	3.798
33.35	357.59	5.743	90.353	24.137	3.797
33.43	358.34	5.702	90.332	23.963	3.797
33.50	359.09	5.661	90.311	23.791	3.796
33.58	359.84	5.620	90.291	23.618	3.795
33.66	360.60	5.582	90.272	23.461	3.794
33.73	361.35	5.545	90.253	23.303	3.793
33.81	362.10	5.508	90.234	23.148	3.792
33.89	362.86	5.472	90.216	22.996	3.792
33.96	363.61	5.436	90.199	22.846	3.791
34.04	364.37	5.402	90.182	22.703	3.790
34.12	365.12	5.365	90.166	22.550	3.790
34.19	365.87	5.331	90.150	22.404	3.789
34.27	366.63	5.297	90.134	22.263	3.788
34.35	367.38	5.261	90.119	22.111	3.788
34.42	368.14	5.225	90.105	21.958	3.787
34.50	368.89	5.191	90.091	21.817	3.786
34.58	369.64	5.155	90.078	21.667	3.786
34.65	370.40	5.120	90.065	21.520	3.785
34.73	371.15	5.084	90.053	21.368	3.785
34.81	371.91	5.048	90.041	21.215	3.784
34.88	372.66	5.012	90.030	21.066	3.784
34.96	373.42	4.977	90.020	20.919	3.783
35.04	374.17	4.942	90.011	20.771	3.783
35.11	374.93	4.907	90.001	20.625	3.783
35.19	375.68	4.873	89.993	20.481	3.782
35.27	376.44	4.839	89.985	20.336	3.782
35.34	377.19	4.806	89.977	20.198	3.782
35.42	377.95	4.774	89.970	20.066	3.781
35.50	378.70	4.745	89.964	19.942	3.781
35.57	379.46	4.715	89.958	19.818	3.781
35.65	380.21	4.685	89.952	19.691	3.781
35.73	380.97	4.659	89.947	19.580	3.780
35.80	381.73	4.631	89.942	19.465	3.780
35.88	382.49	4.608	89.938	19.368	3.780
35.96	383.24	4.584	89.933	19.266	3.780
36.03	384.00	4.559	89.929	19.160	3.780
36.11	384.76	4.538	89.926	19.071	3.779
36.19	385.52	4.517	89.922	18.985	3.779
36.26	386.28	4.496	89.918	18.897	3.779
36.34	387.04	4.479	89.915	18.824	3.779
36.42	387.80	4.459	89.911	18.742	3.779
36.49	388.55	4.442	89.908	18.668	3.779
36.57	389.32	4.426	89.905	18.601	3.779
36.65	390.08	4.409	89.902	18.531	3.778
36.72	390.84	4.395	89.900	18.470	3.778
36.80	391.60	4.380	89.897	18.408	3.778
36.88	392.36	4.366	89.894	18.348	3.778
36.95	393.12	4.350	89.892	18.281	3.778
37.03	393.88	4.336	89.890	18.224	3.778
37.11	394.64	4.326	89.887	18.180	3.778
37.18	395.40	4.313	89.885	18.127	3.778
37.26	396.16	4.299	89.883	18.068	3.778
37.34	396.92	4.288	89.881	18.022	3.778
37.41	397.68	4.276	89.880	17.969	3.777
37.49	398.44	4.264	89.878	17.923	3.777
37.57	399.20	4.253	89.876	17.875	3.777
37.64	399.97	4.242	89.874	17.828	3.777
37.72	400.73	4.229	89.872	17.772	3.777
37.80	401.49	4.218	89.871	17.728	3.777
37.87	402.25	4.208	89.869	17.686	3.777
37.95	403.01	4.196	89.867	17.635	3.777
38.03	403.77	4.188	89.865	17.603	3.777
38.10	404.54	4.179	89.864	17.562	3.777
38.18	405.30	4.166	89.862	17.509	3.777
38.26	406.06	4.155	89.860	17.465	3.777
38.33	406.82	4.145	89.859	17.420	3.777
38.41	407.59	4.138	89.857	17.390	3.777
38.49	408.35	4.127	89.855	17.344	3.776
38.56	409.11	4.116	89.854	17.301	3.776
38.64	409.88	4.107	89.852	17.261	3.776
38.72	410.64	4.098	89.851	17.225	3.776
38.79	411.40	4.088	89.850	17.183	3.776
38.87	412.16	4.079	89.848	17.145	3.776
38.95	412.93	4.070	89.847	17.104	3.776
39.02	413.69	4.059	89.846	17.058	3.776
39.10	414.45	4.051	89.845	17.026	3.776
39.18	415.21	4.041	89.843	16.983	3.776
39.25	415.97	4.032	89.842	16.944	3.776
39.33	416.73	4.022	89.841	16.905	3.776
39.41	417.50	4.013	89.839	16.866	3.776
39.48	418.26	4.002	89.838	16.818	3.776
39.56	419.02	3.993	89.837	16.780	3.776
39.64	419.78	3.983	89.835	16.740	3.776
39.71	420.55	3.974	89.834	16.703	3.776
39.79	421.31	3.965	89.833	16.665	3.776
39.87	422.07	3.954	89.831	16.617	3.775
39.94	422.84	3.945	89.830	16.579	3.775
40.02	423.60	3.936	89.829	16.541	3.775
40.10	424.36	3.926	89.828	16.498	3.775
40.17	425.12	3.915	89.826	16.452	3.775
40.25	425.89	3.906	89.825	16.415	3.775
40.33	426.65	3.896	89.824	16.375	3.775
40.40	427.41	3.885	89.824	16.330	3.775
40.48	428.17	3.876	89.823	16.288	3.775
40.56	428.93	3.866	89.822	16.247	3.775
40.63	429.70	3.857	89.821	16.210	3.775
40.71	430.46	3.845	89.820	16.159	3.775
40.79	431.22	3.836	89.819	16.121	3.775
40.86	431.98	3.827	89.818	16.085	3.775
40.94	432.74	3.819	89.817	16.049	3.775
41.02	433.51	3.807	89.816	16.002	3.775
41.09	434.27	3.796	89.815	15.955	3.775
41.17	435.03	3.787	89.814	15.916	3.775
41.25	435.80	3.778	89.813	15.880	3.775
41.32	436.56	3.766	89.812	15.827	3.775
41.40	437.32	3.757	89.811	15.789	3.775
41.48	438.09	3.746	89.809	15.746	3.775
41.55	438.85	3.735	89.808	15.699	3.775
41.63	439.61	3.726	89.808	15.661	3.774
41.71	440.37	3.716	89.807	15.618	3.774
41.78	441.14	3.707	89.806	15.579	3.774
41.86	441.90	3.698	89.805	15.542	3.774
41.94	442.66	3.685	89.804	15.489	3.774
42.01	443.42	3.675	89.803	15.447	3.774
42.09	444.18	3.665	89.802	15.402	3.774
42.17	444.95	3.654	89.802	15.359	3.774
42.24	445.71	3.645	89.801	15.318	3.774
42.32	446.47	3.633	89.800	15.270	3.774
42.40	447.23	3.623	89.799	15.225	3.774
42.47	448.00	3.615	89.798	15.193	3.774
42.55	448.76	3.603	89.797	15.141	3.774
42.63	449.52	3.593	89.796	15.101	3.774
42.70	450.28	3.583	89.796	15.059	3.774
42.78	451.04	3.573	89.795	15.017	3.774
42.86	451.81	3.561	89.794	14.968	3.774
42.93	452.57	3.551	89.793	14.926	3.774
43.01	453.33	3.542	89.792	14.885	3.774
43.09	454.10	3.532	89.792	14.844	3.774
43.16	454.86	3.522	89.791	14.803	3.774
43.24	455.62	3.512	89.790	14.761	3.774
43.32	456.39	3.499	89.789	14.707	3.774
43.39	457.15	3.488	89.789	14.660	3.774
43.47	457.91	3.479	89.788	14.622	3.774
43.55	458.67	3.469	89.787	14.581	3.774
43.62	459.44	3.459	89.786	14.538	3.774
43.70	460.20	3.449	89.785	14.495	3.774
43.78	460.96	3.439	89.784	14.455	3.773
43.85	461.72	3.427	89.784	14.404	3.773
43.93	462.49	3.419	89.783	14.368	3.773
44.01	463.25	3.408	89.782	14.322	3.773
44.08	464.01	3.395	89.781	14.270	3.773
44.16	464.77	3.386	89.781	14.230	3.773
44.24	465.54	3.377	89.780	14.195	3.773
44.31	466.30	3.366	89.779	14.148	3.773
44.39	467.06	3.353	89.778	14.092	3.773
44.47	467.83	3.344	89.777	14.056	3.773
44.54	468.59	3.336	89.776	14.019	3.773
44.62	469.35	3.326	89.775	13.979	3.773
44.70	470.12	3.315	89.775	13.931	3.773
44.77	470.88	3.306	89.774	13.893	3.773
44.85	471.64	3.294	89.773	13.846	3.773
44.93	472.41	3.285	89.772	13.806	3.773
45.00	473.17	3.276	89.772	13.767	3.773
45.08	473.93	3.265	89.771	13.722	3.773
45.16	474.69	3.253	89.770	13.672	3.773
45.23	475.46	3.243	89.769	13.628	3.773
45.31	476.22	3.232	89.769	13.584	3.773
45.39	476.98	3.220	89.768	13.532	3.773
45.46	477.74	3.212	89.767	13.499	3.773
45.54	478.51	3.201	89.766	13.455	3.773
45.62	479.27	3.192	89.766	13.414	3.773
45.69	480.03	3.181	89.765	13.371	3.773
45.77	480.79	3.170	89.764	13.322	3.773
45.85	481.56	3.158	89.763	13.272	3.773
45.92	482.32	3.148	89.762	13.231	3.773
46.00	483.08	3.138	89.761	13.189	3.773
46.08	483.85	3.128	89.761	13.148	3.772
46.15	484.61	3.116	89.760	13.094	3.772
46.23	485.37	3.105	89.760	13.051	3.772
46.31	486.14	3.094	89.759	13.006	3.772
46.38	486.90	3.083	89.758	12.958	3.772
46.46	487.66	3.070	89.757	12.903	3.772
46.54	488.43	3.060	89.757	12.861	3.772
46.61	489.19	3.050	89.756	12.820	3.772
46.69	489.95	3.038	89.755	12.768	3.772
46.77	490.72	3.027	89.755	12.723	3.772
46.84	491.48	3.018	89.754	12.683	3.772
46.92	492.24	3.004	89.753	12.627	3.772
47.00	493.00	2.993	89.752	12.581	3.772
47.07	493.77	2.983	89.751	12.537	3.772
47.15	494.53	2.971	89.750	12.486	3.772
47.23	495.29	2.960	89.749	12.439	3.772
47.30	496.05	2.948	89.748	12.391	3.772
47.38	496.82	2.938	89.747	12.348	3.772
47.46	497.58	2.927	89.746	12.301	3.772
47.53	498.34	2.914	89.745	12.248	3.772
47.61	499.11	2.904	89.745	12.206	3.772
47.69	499.87	2.895	89.744	12.165	3.772
47.76	500.63	2.883	89.743	12.116	3.772
47.84	501.40	2.870	89.742	12.063	3.772
47.92	502.16	2.858	89.741	12.013	3.772
47.99	502.93	2.847	89.741	11.967	3.772
48.07	503.69	2.834	89.740	11.913	3.772
48.15	504.46	2.821	89.739	11.856	3.772
48.22	505.22	2.811	89.738	11.813	3.772
48.30	505.98	2.800	89.737	11.768	3.772
48.38	506.75	2.786	89.737	11.710	3.771
48.45	507.51	2.774	89.736	11.659	3.771
48.53	508.27	2.762	89.735	11.609	3.771
48.61	509.04	2.751	89.734	11.560	3.771
48.68	509.80	2.740	89.734	11.514	3.771
48.76	510.56	2.726	89.733	11.457	3.771
48.84	511.32	2.714	89.732	11.407	3.771
48.91	512.08	2.701	89.732	11.351	3.771
48.99	512.85	2.689	89.731	11.301	3.771
49.07	513.61	2.676	89.730	11.248	3.771
49.14	514.37	2.663	89.729	11.192	3.771
49.22	515.14	2.652	89.729	11.145	3.771
49.30	515.90	2.640	89.728	11.096	3.771
49.37	516.67	2.629	89.727	11.047	3.771
49.45	517.43	2.617	89.727	10.999	3.771
49.53	518.19	2.605	89.726	10.949	3.771
49.60	518.96	2.592	89.725	10.892	3.771
49.68	519.72	2.578	89.724	10.837	3.771
49.76	520.49	2.566	89.724	10.783	3.771
49.83	521.25	2.554	89.723	10.736	3.771
49.91	522.01	2.541	89.722	10.678	3.771
49.99	522.78	2.525	89.721	10.614	3.771
50.06	523.54	2.513	89.720	10.562	3.771
50.14	524.30	2.503	89.719	10.518	3.771
50.22	525.06	2.490	89.718	10.464	3.771
50.29	525.83	2.475	89.718	10.403	3.771
50.37	526.59	2.462	89.717	10.347	3.771
50.45	527.35	2.451	89.715	10.300	3.771
50.52	528.11	2.438	89.715	10.248	3.771
50.60	528.88	2.422	89.714	10.181	3.771
50.68	529.64	2.412	89.713	10.136	3.770
50.75	530.40	2.400	89.712	10.087	3.770
50.83	531.16	2.385	89.711	10.023	3.770
50.91	531.93	2.372	89.710	9.971	3.770
50.98	532.69	2.359	89.709	9.914	3.770
51.06	533.46	2.345	89.708	9.856	3.770
51.14	534.22	2.330	89.707	9.793	3.770
51.21	534.98	2.315	89.707	9.728	3.770
51.29	535.75	2.302	89.706	9.676	3.770
51.37	536.51	2.290	89.705	9.623	3.770
51.44	537.28	2.276	89.704	9.567	3.770
51.52	538.04	2.263	89.704	9.510	3.770
51.60	538.80	2.247	89.703	9.444	3.770
51.67	539.57	2.232	89.702	9.381	3.770
51.75	540.33	2.218	89.701	9.322	3.770
51.83	541.09	2.205	89.700	9.269	3.770
51.90	541.85	2.191	89.699	9.210	3.770
51.98	542.62	2.177	89.698	9.150	3.770
52.06	543.38	2.164	89.697	9.094	3.770
52.13	544.14	2.150	89.696	9.036	3.770
52.21	544.91	2.135	89.695	8.973	3.770
52.29	545.67	2.121	89.694	8.916	3.770
52.36	546.43	2.107	89.692	8.853	3.770
52.44	547.20	2.093	89.691	8.795	3.770
52.52	547.96	2.079	89.691	8.740	3.770
52.59	548.72	2.062	89.690	8.668	3.770
52.67	549.49	2.050	89.689	8.615	3.769
52.75	550.25	2.036	89.688	8.559	3.769
52.82	551.01	2.020	89.687	8.491	3.769
52.90	551.78	2.007	89.686	8.434	3.769
52.98	552.54	1.990	89.685	8.362	3.769
53.05	553.31	1.975	89.684	8.299	3.769
53.13	554.07	1.963	89.683	8.249	3.769
53.21	554.83	1.948	89.682	8.186	3.769
53.28	555.59	1.933	89.681	8.122	3.769
53.36	556.36	1.918	89.680	8.059	3.769
53.44	557.12	1.904	89.679	8.004	3.769
53.51	557.88	1.891	89.678	7.946	3.769
53.59	558.65	1.877	89.677	7.888	3.769
53.67	559.41	1.863	89.676	7.831	3.769
53.74	560.17	1.851	89.675	7.778	3.769
53.82	560.94	1.836	89.673	7.717	3.769
53.90	561.70	1.822	89.673	7.660	3.769
53.97	562.46	1.812	89.671	7.615	3.769
54.05	563.23	1.800	89.670	7.564	3.769
54.13	563.99	1.788	89.669	7.514	3.769
54.20	564.75	1.777	89.668	7.469	3.769
54.28	565.52	1.765	89.667	7.420	3.769
54.36	566.29	1.759	89.666	7.392	3.769
54.43	567.05	1.754	89.665	7.370	3.768
54.51	567.82	1.748	89.664	7.345	3.768
54.59	568.58	1.742	89.663	7.319	3.768
54.66	569.35	1.738	89.661	7.304	3.768
54.74	570.12	1.736	89.660	7.295	3.768
54.82	570.89	1.735	89.659	7.294	3.768
54.89	571.65	1.738	89.657	7.304	3.768
54.97	572.42	1.742	89.656	7.323	3.768
55.05	573.19	1.753	89.655	7.368	3.768
55.12	573.96	1.774	89.654	7.457	3.768
55.20	574.73	1.807	89.653	7.593	3.768
55.28	575.50	1.845	89.652	7.753	3.768
55.35	576.27	1.893	89.650	7.957	3.768
55.43	577.05	1.952	89.649	8.202	3.768
55.51	577.83	2.021	89.647	8.494	3.768
55.58	578.61	2.103	89.645	8.837	3.768
55.66	579.39	2.193	89.643	9.217	3.768
55.74	580.17	2.291	89.641	9.627	3.767
55.81	580.96	2.388	89.639	10.035	3.767
55.89	581.74	2.478	89.636	10.413	3.767
55.97	582.52	2.552	89.634	10.724	3.767
56.04	583.30	2.603	89.632	10.938	3.767
56.12	584.07	2.628	89.629	11.047	3.767
56.20	584.84	2.637	89.626	11.081	3.767
56.27	585.60	2.622	89.624	11.020	3.767
56.35	586.36	2.576	89.622	10.826	3.767
56.43	587.11	2.514	89.620	10.567	3.767
56.50	587.86	2.445	89.618	10.278	3.766
56.58	588.62	2.366	89.616	9.945	3.766
56.66	589.37	2.284	89.614	9.599	3.766
56.73	590.11	2.197	89.612	9.232	3.766
56.81	590.87	2.115	89.611	8.888	3.766
56.89	591.62	2.032	89.609	8.542	3.766
56.96	592.37	1.954	89.608	8.212	3.766
57.04	593.12	1.881	89.607	7.907	3.766
57.12	593.87	1.813	89.606	7.621	3.766
57.19	594.63	1.751	89.605	7.360	3.766
57.27	595.38	1.694	89.604	7.119	3.766
57.35	596.14	1.643	89.603	6.906	3.766
57.42	596.90	1.596	89.602	6.709	3.766
57.50	597.66	1.552	89.601	6.524	3.766
57.58	598.42	1.511	89.600	6.352	3.766
57.65	599.18	1.476	89.600	6.205	3.766
57.73	599.95	1.444	89.599	6.071	3.766
57.81	600.71	1.411	89.598	5.932	3.766
57.88	601.47	1.385	89.597	5.823	3.766
57.96	602.23	1.358	89.596	5.708	3.766
58.04	603.00	1.333	89.596	5.602	3.766
58.11	603.76	1.312	89.595	5.514	3.766
58.19	604.52	1.291	89.594	5.425	3.765
58.27	605.29	1.268	89.593	5.331	3.765
58.34	606.05	1.249	89.592	5.250	3.765
58.42	606.81	1.231	89.592	5.175	3.765
58.50	607.57	1.214	89.591	5.102	3.765
58.57	608.34	1.195	89.590	5.021	3.765
58.65	609.10	1.179	89.590	4.956	3.765
58.73	609.86	1.162	89.589	4.882	3.765
58.80	610.63	1.145	89.589	4.812	3.765
58.88	611.39	1.128	89.590	4.741	3.765
58.96	612.15	1.115	89.591	4.686	3.765
59.03	612.92	1.100	89.592	4.622	3.765
59.11	613.68	1.083	89.592	4.551	3.765
59.19	614.45	1.068	89.592	4.490	3.765
59.26	615.21	1.056	89.592	4.440	3.765
59.34	615.98	1.042	89.591	4.379	3.765
59.42	616.74	1.030	89.591	4.330	3.765
59.49	617.51	1.014	89.591	4.263	3.765
59.57	618.27	1.001	89.591	4.209	3.765
59.65	619.04	0.990	89.591	4.162	3.765
59.72	619.80	0.976	89.590	4.104	3.765
59.80	620.57	0.961	89.590	4.040	3.765
59.88	621.33	0.946	89.589	3.975	3.765
59.95	622.10	0.933	89.589	3.919	3.765
60.03	622.86	0.920	89.589	3.868	3.765
60.11	623.62	0.907	89.588	3.814	3.765
60.18	624.39	0.893	89.588	3.754	3.765
60.26	625.15	0.881	89.587	3.701	3.765
60.34	625.91	0.866	89.587	3.641	3.765
60.41	626.68	0.852	89.586	3.582	3.765
60.49	627.44	0.839	89.585	3.528	3.765
60.57	628.20	0.826	89.585	3.473	3.765
60.64	628.97	0.813	89.584	3.415	3.765
60.72	629.73	0.800	89.583	3.361	3.765
60.80	630.50	0.788	89.582	3.310	3.765
60.87	631.26	0.774	89.581	3.254	3.765
60.95	632.03	0.762	89.581	3.203	3.765
61.03	632.79	0.750	89.580	3.154	3.765
61.10	633.56	0.734	89.580	3.087	3.765
61.18	634.33	0.722	89.579	3.035	3.765
61.26	635.09	0.710	89.578	2.984	3.765
61.33	635.86	0.696	89.578	2.925	3.765
61.41	636.62	0.681	89.577	2.862	3.765
61.49	637.39	0.668	89.577	2.807	3.765
61.56	638.15	0.654	89.576	2.749	3.765
61.64	638.92	0.642	89.575	2.699	3.765
61.72	639.68	0.627	89.574	2.635	3.765
61.79	640.44	0.613	89.574	2.576	3.765
61.87	641.21	0.602	89.574	2.531	3.765
61.95	641.97	0.591	89.573	2.486	3.765
62.02	642.73	0.576	89.572	2.419	3.765
62.10	643.50	0.562	89.572	2.362	3.765
62.18	644.26	0.547	89.571	2.300	3.765
62.25	645.03	0.534	89.570	2.244	3.764
62.33	645.79	0.518	89.570	2.176	3.764
62.41	646.55	0.505	89.569	2.124	3.764
62.48	647.32	0.495	89.569	2.079	3.764
62.56	648.08	0.479	89.569	2.011	3.764
62.64	648.85	0.467	89.568	1.964	3.764
62.71	649.62	0.455	89.567	1.913	3.764
62.79	650.38	0.443	89.566	1.864	3.764
62.87	651.15	0.427	89.566	1.795	3.764
62.94	651.91	0.415	89.565	1.743	3.764
63.02	652.68	0.401	89.565	1.683	3.764
63.10	653.44	0.388	89.564	1.633	3.764
63.17	654.21	0.374	89.563	1.573	3.764
63.25	654.97	0.361	89.563	1.516	3.764
63.33	655.74	0.343	89.562	1.440	3.764
63.40	656.50	0.330	89.561	1.385	3.764
63.48	657.26	0.318	89.561	1.336	3.764
63.56	658.03	0.305	89.560	1.282	3.764
63.63	658.79	0.293	89.560	1.229	3.764
63.71	659.56	0.281	89.559	1.182	3.764
63.79	660.32	0.266	89.558	1.117	3.764
63.86	661.09	0.252	89.557	1.059	3.764
63.94	661.85	0.234	89.556	0.985	3.764
64.02	662.62	0.221	89.556	0.929	3.764
64.09	663.38	0.209	89.555	0.880	3.764
64.17	664.15	0.196	89.554	0.826	3.764
64.25	664.91	0.184	89.554	0.773	3.764
64.32	665.68	0.171	89.553	0.718	3.764
64.40	666.44	0.157	89.553	0.662	3.764
64.48	667.21	0.141	89.552	0.594	3.764
64.55	667.98	0.129	89.551	0.541	3.764
64.63	668.74	0.115	89.550	0.484	3.764
64.71	669.51	0.102	89.550	0.429	3.764
64.78	670.27	0.090	89.549	0.377	3.764
64.86	671.04	0.076	89.549	0.321	3.764
64.94	671.80	0.062	89.548	0.259	3.764
65.01	672.56	0.049	89.548	0.206	3.764
65.09	673.33	0.035	89.547	0.147	3.764
65.17	674.09	0.022	89.546	0.091	3.763
65.24	674.86	0.007	89.545	0.028	3.763
65.32	675.62	-0.005	89.545	-0.019	3.763
65.40	676.39	-0.018	89.544	-0.078	3.763
65.47	677.15	-0.029	89.543	-0.123	3.763
65.55	677.92	-0.042	89.543	-0.177	3.763
65.63	678.68	-0.057	89.542	-0.239	3.763
65.70	679.45	-0.072	89.541	-0.303	3.763
65.78	680.21	-0.084	89.541	-0.351	3.763
65.86	680.98	-0.096	89.540	-0.404	3.763
65.93	681.74	-0.106	89.540	-0.445	3.763
66.01	682.51	-0.117	89.539	-0.490	3.763
66.09	683.28	-0.129	89.538	-0.542	3.763
66.16	684.04	-0.142	89.538	-0.597	3.763
66.24	684.81	-0.155	89.537	-0.650	3.763
66.32	685.57	-0.167	89.536	-0.702	3.763
66.39	686.34	-0.179	89.536	-0.753	3.763
66.47	687.10	-0.192	89.535	-0.806	3.763
66.55	687.87	-0.206	89.534	-0.864	3.763
66.62	688.63	-0.217	89.533	-0.912	3.763
66.70	689.40	-0.228	89.532	-0.958	3.763
66.78	690.16	-0.241	89.531	-1.011	3.763
66.85	690.93	-0.253	89.531	-1.062	3.763
66.93	691.69	-0.266	89.530	-1.119	3.763
67.01	692.46	-0.280	89.529	-1.178	3.763
67.08	693.22	-0.296	89.528	-1.245	3.763
67.16	693.99	-0.308	89.528	-1.294	3.763
67.24	694.75	-0.320	89.527	-1.347	3.763
67.31	695.52	-0.332	89.527	-1.395	3.763
67.39	696.28	-0.344	89.526	-1.446	3.763
67.47	697.05	-0.357	89.526	-1.501	3.763
67.54	697.82	-0.369	89.525	-1.551	3.763
67.62	698.58	-0.384	89.524	-1.615	3.763
67.70	699.35	-0.396	89.523	-1.664	3.763
67.77	700.12	-0.408	89.523	-1.716	3.762
67.85	700.89	-0.424	89.522	-1.782	3.762
67.93	701.65	-0.438	89.521	-1.842	3.762
68.00	702.42	-0.453	89.520	-1.902	3.762
68.08	703.18	-0.469	89.519	-1.969	3.762
68.16	703.95	-0.483	89.518	-2.032	3.762
68.23	704.71	-0.498	89.518	-2.093	3.762
68.31	705.48	-0.511	89.517	-2.146	3.762
68.39	706.24	-0.523	89.516	-2.197	3.762
68.46	707.00	-0.538	89.515	-2.260	3.762
68.54	707.77	-0.550	89.515	-2.312	3.762
68.62	708.53	-0.564	89.514	-2.372	3.762
68.69	709.30	-0.580	89.513	-2.437	3.762
68.77	710.07	-0.592	89.512	-2.489	3.762
68.85	710.83	-0.606	89.512	-2.548	3.762
68.92	711.60	-0.621	89.512	-2.611	3.762
69.00	712.36	-0.638	89.511	-2.680	3.762
69.08	713.13	-0.655	89.510	-2.752	3.762
69.15	713.90	-0.668	89.509	-2.806	3.762
69.23	714.66	-0.685	89.508	-2.877	3.762
69.31	715.43	-0.698	89.507	-2.933	3.762
69.38	716.20	-0.713	89.507	-2.997	3.762
69.46	716.96	-0.726	89.506	-3.053	3.762
69.54	717.73	-0.745	89.506	-3.130	3.762
69.61	718.49	-0.762	89.505	-3.205	3.762
69.69	719.26	-0.777	89.504	-3.266	3.762
69.77	720.02	-0.793	89.503	-3.332	3.762
69.84	720.78	-0.809	89.502	-3.399	3.762
69.92	721.55	-0.825	89.501	-3.467	3.762
70.00	722.32	-0.840	89.500	-3.532	3.762
70.07	723.08	-0.857	89.499	-3.600	3.762
70.15	723.85	-0.873	89.498	-3.667	3.761
70.23	724.61	-0.889	89.497	-3.736	3.761
70.30	725.37	-0.906	89.496	-3.810	3.761
70.38	726.14	-0.924	89.495	-3.885	3.761
70.46	726.91	-0.941	89.495	-3.953	3.761
70.53	727.67	-0.958	89.494	-4.026	3.761
70.61	728.44	-0.973	89.494	-4.090	3.761
70.69	729.20	-0.989	89.493	-4.156	3.761
70.76	729.97	-1.007	89.492	-4.234	3.761
70.84	730.74	-1.024	89.491	-4.303	3.761
70.92	731.50	-1.040	89.490	-4.373	3.761
70.99	732.27	-1.057	89.489	-4.443	3.761
71.07	733.03	-1.074	89.488	-4.513	3.761
71.15	733.80	-1.093	89.487	-4.596	3.761
71.22	734.56	-1.110	89.486	-4.664	3.761
71.30	735.33	-1.126	89.485	-4.734	3.761
71.38	736.09	-1.148	89.484	-4.823	3.761
71.45	736.86	-1.167	89.483	-4.903	3.761
71.53	737.62	-1.183	89.482	-4.974	3.761
71.61	738.39	-1.204	89.481	-5.059	3.761
71.68	739.15	-1.221	89.480	-5.131	3.761
71.76	739.92	-1.240	89.479	-5.212	3.761
71.84	740.68	-1.260	89.478	-5.298	3.761
71.91	741.44	-1.279	89.478	-5.374	3.761
71.99	742.21	-1.301	89.477	-5.467	3.761
72.07	742.97	-1.321	89.476	-5.552	3.761
72.14	743.74	-1.338	89.475	-5.623	3.760
72.22	744.50	-1.356	89.474	-5.700	3.760
72.30	745.27	-1.378	89.472	-5.792	3.760
72.37	746.03	-1.397	89.471	-5.873	3.760
72.45	746.80	-1.416	89.470	-5.950	3.760
72.53	747.57	-1.436	89.469	-6.034	3.760
72.60	748.33	-1.457	89.468	-6.124	3.760
72.68	749.10	-1.479	89.467	-6.218	3.760
72.76	749.86	-1.499	89.466	-6.301	3.760
72.83	750.63	-1.521	89.465	-6.391	3.760
72.91	751.40	-1.541	89.464	-6.477	3.760
72.99	752.16	-1.562	89.463	-6.564	3.760
73.06	752.92	-1.584	89.462	-6.658	3.760
73.14	753.69	-1.608	89.460	-6.756	3.760
73.22	754.45	-1.631	89.459	-6.854	3.760
73.29	755.22	-1.653	89.458	-6.948	3.760
73.37	755.98	-1.673	89.457	-7.033	3.760
73.45	756.74	-1.694	89.456	-7.121	3.760
73.52	757.51	-1.715	89.455	-7.207	3.760
73.60	758.27	-1.741	89.454	-7.316	3.760
73.68	759.04	-1.764	89.453	-7.412	3.760
73.75	759.80	-1.784	89.451	-7.497	3.759
73.83	760.57	-1.806	89.450	-7.590	3.759
73.91	761.33	-1.827	89.449	-7.680	3.759
73.98	762.10	-1.852	89.447	-7.786	3.759
74.06	762.86	-1.878	89.446	-7.893	3.759
74.14	763.63	-1.899	89.444	-7.981	3.759
74.21	764.39	-1.926	89.443	-8.093	3.759
74.29	765.16	-1.947	89.442	-8.183	3.759
74.37	765.93	-1.972	89.440	-8.289	3.759
74.44	766.69	-1.995	89.439	-8.386	3.759
74.52	767.46	-2.020	89.438	-8.491	3.759
74.60	768.22	-2.049	89.437	-8.613	3.759
74.67	768.98	-2.075	89.435	-8.722	3.759
74.75	769.75	-2.100	89.434	-8.828	3.759
74.83	770.51	-2.124	89.432	-8.928	3.759
74.90	771.27	-2.151	89.430	-9.041	3.759
74.98	772.04	-2.180	89.429	-9.164	3.759
75.06	772.80	-2.209	89.427	-9.284	3.758
75.13	773.57	-2.230	89.426	-9.371	3.758
75.21	774.33	-2.256	89.424	-9.482	3.758
75.29	775.09	-2.285	89.422	-9.602	3.758
75.36	775.86	-2.311	89.421	-9.711	3.758
75.44	776.62	-2.338	89.419	-9.825	3.758
75.52	777.39	-2.364	89.418	-9.937	3.758
75.59	778.15	-2.389	89.416	-10.041	3.758
75.67	778.92	-2.417	89.415	-10.158	3.758
75.75	779.68	-2.446	89.413	-10.281	3.758
75.82	780.45	-2.470	89.411	-10.380	3.758
75.90	781.21	-2.496	89.410	-10.492	3.758
75.98	781.98	-2.527	89.408	-10.619	3.758
76.05	782.75	-2.553	89.407	-10.729	3.758
76.13	783.51	-2.581	89.405	-10.846	3.758
76.21	784.27	-2.611	89.404	-10.974	3.757
76.28	785.04	-2.639	89.402	-11.091	3.757
76.36	785.80	-2.667	89.400	-11.209	3.757
76.44	786.56	-2.700	89.398	-11.348	3.757
76.51	787.33	-2.727	89.397	-11.461	3.757
76.59	788.09	-2.756	89.396	-11.585	3.757
76.67	788.85	-2.788	89.395	-11.716	3.757
76.74	789.62	-2.816	89.394	-11.834	3.757
76.82	790.38	-2.845	89.393	-11.956	3.757
76.90	791.15	-2.873	89.392	-12.073	3.757
76.97	791.91	-2.903	89.390	-12.200	3.757
77.05	792.67	-2.933	89.389	-12.326	3.757
77.13	793.44	-2.966	89.387	-12.467	3.757
77.20	794.20	-2.994	89.385	-12.583	3.757
77.28	794.97	-3.024	89.383	-12.710	3.757
77.36	795.73	-3.057	89.381	-12.847	3.757
77.43	796.50	-3.085	89.379	-12.966	3.756
77.51	797.27	-3.117	89.377	-13.100	3.756
77.59	798.03	-3.148	89.375	-13.230	3.756
77.66	798.80	-3.181	89.373	-13.368	3.756
77.74	799.56	-3.213	89.371	-13.504	3.756
77.82	800.33	-3.247	89.369	-13.647	3.756
77.89	801.09	-3.279	89.367	-13.783	3.756
77.97	801.85	-3.308	89.365	-13.903	3.756
78.05	802.62	-3.344	89.363	-14.055	3.756
78.12	803.38	-3.373	89.360	-14.178	3.756
78.20	804.15	-3.407	89.358	-14.319	3.756
78.28	804.91	-3.442	89.356	-14.468	3.755
78.35	805.67	-3.474	89.353	-14.602	3.755
78.43	806.44	-3.509	89.352	-14.747	3.755
78.51	807.20	-3.539	89.350	-14.873	3.755
78.58	807.97	-3.574	89.348	-15.022	3.755
78.66	808.73	-3.608	89.346	-15.163	3.755
78.74	809.50	-3.643	89.344	-15.312	3.755
78.81	810.26	-3.678	89.342	-15.458	3.755
78.89	811.03	-3.712	89.339	-15.601	3.755
78.97	811.79	-3.744	89.337	-15.734	3.755
79.04	812.56	-3.780	89.335	-15.887	3.755
79.12	813.32	-3.815	89.333	-16.033	3.755
79.20	814.09	-3.849	89.331	-16.177	3.754
79.27	814.85	-3.883	89.329	-16.322	3.754
79.35	815.62	-3.923	89.327	-16.489	3.754
79.43	816.38	-3.958	89.325	-16.633	3.754
79.50	817.15	-3.993	89.323	-16.781	3.754
79.58	817.91	-4.032	89.321	-16.945	3.754
79.66	818.67	-4.070	89.319	-17.104	3.754
79.73	819.44	-4.107	89.317	-17.261	3.754
79.81	820.20	-4.144	89.315	-17.418	3.754
79.89	820.96	-4.178	89.314	-17.561	3.754
79.96	821.73	-4.215	89.312	-17.715	3.754
80.04	822.49	-4.254	89.310	-17.881	3.754
80.12	823.25	-4.294	89.308	-18.047	3.753
80.19	824.02	-4.332	89.306	-18.208	3.753
80.27	824.78	-4.369	89.304	-18.362	3.753
80.35	825.55	-4.406	89.303	-18.517	3.753
80.42	826.31	-4.444	89.301	-18.679	3.753
80.50	827.08	-4.482	89.299	-18.835	3.753
80.58	827.84	-4.514	89.298	-18.973	3.753
80.65	828.61	-4.554	89.296	-19.141	3.753
80.73	829.37	-4.591	89.294	-19.294	3.753
80.81	830.14	-4.630	89.293	-19.458	3.753
80.88	830.90	-4.671	89.291	-19.629	3.753
80.96	831.67	-4.707	89.289	-19.785	3.753
81.04	832.43	-4.745	89.288	-19.944	3.753
81.11	833.20	-4.784	89.286	-20.105	3.753
81.19	833.96	-4.823	89.284	-20.271	3.752
81.27	834.72	-4.862	89.283	-20.434	3.752
81.34	835.49	-4.903	89.281	-20.608	3.752
81.42	836.25	-4.942	89.279	-20.772	3.752
81.50	837.01	-4.983	89.277	-20.941	3.752
81.57	837.77	-5.023	89.275	-21.110	3.752
81.65	838.54	-5.061	89.274	-21.273	3.752
81.73	839.30	-5.100	89.272	-21.435	3.752
81.80	840.07	-5.141	89.270	-21.606	3.752
81.88	840.83	-5.178	89.268	-21.764	3.752
81.96	841.60	-5.216	89.267	-21.923	3.752
82.03	842.36	-5.256	89.265	-22.091	3.752
82.11	843.12	-5.296	89.263	-22.260	3.752
82.19	843.89	-5.336	89.262	-22.426	3.752
82.26	844.65	-5.378	89.260	-22.601	3.751
82.34	845.42	-5.417	89.258	-22.768	3.751
82.42	846.18	-5.455	89.256	-22.928	3.751
82.49	846.95	-5.494	89.255	-23.090	3.751
82.57	847.71	-5.534	89.253	-23.260	3.751
82.65	848.48	-5.574	89.251	-23.425	3.751
82.72	849.24	-5.616	89.250	-23.603	3.751
82.80	850.00	-5.658	89.248	-23.779	3.751
82.88	850.77	-5.699	89.247	-23.951	3.751
82.95	851.53	-5.737	89.245	-24.114	3.751
83.03	852.29	-5.777	89.243	-24.279	3.751
83.11	853.06	-5.823	89.242	-24.471	3.751
83.18	853.82	-5.862	89.240	-24.635	3.751
83.26	854.59	-5.900	89.239	-24.795	3.751
83.34	855.35	-5.938	89.237	-24.958	3.750
83.41	856.11	-5.980	89.236	-25.134	3.750
83.49	856.88	-6.021	89.234	-25.304	3.750
83.57	857.64	-6.062	89.233	-25.478	3.750
83.64	858.40	-6.107	89.231	-25.667	3.750
83.72	859.17	-6.144	89.230	-25.822	3.750
83.80	859.93	-6.187	89.228	-26.003	3.750
83.87	860.70	-6.229	89.226	-26.178	3.750
83.95	861.46	-6.269	89.225	-26.348	3.750
84.03	862.23	-6.313	89.224	-26.532	3.750
84.10	862.99	-6.355	89.223	-26.707	3.750
84.18	863.76	-6.394	89.221	-26.875	3.750
84.26	864.52	-6.439	89.220	-27.062	3.750
84.33	865.29	-6.488	89.219	-27.266	3.750
84.41	866.05	-6.530	89.218	-27.446	3.750
84.49	866.81	-6.573	89.219	-27.627	3.750
84.56	867.58	-6.620	89.222	-27.823	3.750
84.64	868.34	-6.660	89.224	-27.992	3.750
84.72	869.10	-6.709	89.225	-28.197	3.750
84.79	869.86	-6.751	89.225	-28.374	3.750
84.87	870.63	-6.794	89.225	-28.555	3.750
84.95	871.39	-6.838	89.225	-28.738	3.750
85.02	872.16	-6.879	89.224	-28.913	3.750
85.10	872.92	-6.921	89.223	-29.088	3.750
85.18	873.68	-6.968	89.223	-29.285	3.750
85.25	874.44	-7.013	89.222	-29.473	3.750
85.33	875.21	-7.051	89.221	-29.634	3.750
85.41	875.97	-7.094	89.220	-29.815	3.750
85.48	876.74	-7.135	89.219	-29.988	3.750
85.56	877.50	-7.179	89.218	-30.173	3.750
85.64	878.27	-7.222	89.217	-30.352	3.750
85.71	879.03	-7.266	89.215	-30.538	3.750
85.79	879.80	-7.311	89.214	-30.729	3.750
85.87	880.56	-7.351	89.213	-30.897	3.749
85.94	881.33	-7.399	89.212	-31.098	3.749
86.02	882.09	-7.440	89.211	-31.271	3.749
86.10	882.85	-7.485	89.210	-31.457	3.749
86.17	883.62	-7.530	89.209	-31.648	3.749
86.25	884.38	-7.575	89.209	-31.838	3.749
86.33	885.14	-7.621	89.209	-32.032	3.749
86.40	885.91	-7.661	89.211	-32.197	3.749
86.48	886.67	-7.707	89.214	-32.391	3.750
86.56	887.43	-7.751	89.217	-32.576	3.750
86.63	888.20	-7.797	89.219	-32.770	3.750
86.71	888.96	-7.843	89.220	-32.962	3.750
86.79	889.73	-7.883	89.221	-33.129	3.750
86.86	890.49	-7.925	89.221	-33.309	3.750
86.94	891.25	-7.971	89.220	-33.503	3.750
87.02	892.02	-8.015	89.220	-33.685	3.750
87.09	892.78	-8.056	89.219	-33.858	3.750
87.17	893.55	-8.101	89.218	-34.048	3.750
87.25	894.31	-8.144	89.217	-34.228	3.750
87.32	895.08	-8.190	89.216	-34.423	3.750
87.40	895.84	-8.235	89.214	-34.610	3.750
87.48	896.61	-8.279	89.213	-34.797	3.749
87.55	897.37	-8.322	89.212	-34.978	3.749
87.63	898.13	-8.370	89.211	-35.179	3.749
87.71	898.90	-8.417	89.210	-35.377	3.749
87.78	899.66	-8.465	89.208	-35.576	3.749
87.86	900.43	-8.505	89.207	-35.747	3.749
87.94	901.19	-8.557	89.206	-35.965	3.749
88.01	901.95	-8.597	89.205	-36.134	3.749
88.09	902.72	-8.643	89.203	-36.326	3.749
88.17	903.48	-8.695	89.202	-36.542	3.749
88.24	904.24	-8.737	89.201	-36.721	3.749
88.32	905.01	-8.785	89.199	-36.921	3.749
88.40	905.77	-8.829	89.198	-37.108	3.749
88.47	906.54	-8.877	89.196	-37.307	3.749
88.55	907.30	-8.923	89.195	-37.501	3.749
88.63	908.06	-8.968	89.194	-37.691	3.749
88.70	908.83	-9.014	89.193	-37.885	3.749
88.78	909.59	-9.057	89.191	-38.067	3.749
88.86	910.36	-9.106	89.190	-38.270	3.749
88.93	911.12	-9.154	89.188	-38.474	3.748
89.01	911.89	-9.201	89.187	-38.669	3.748
89.09	912.65	-9.247	89.185	-38.862	3.748
89.16	913.42	-9.291	89.184	-39.051	3.748
89.24	914.18	-9.336	89.182	-39.239	3.748
89.32	914.94	-9.384	89.181	-39.438	3.748
89.39	915.71	-9.431	89.179	-39.636	3.748
89.47	916.47	-9.480	89.178	-39.842	3.748
89.55	917.23	-9.526	89.177	-40.037	3.748
89.62	918.00	-9.569	89.175	-40.216	3.748
89.70	918.76	-9.614	89.174	-40.406	3.748
89.78	919.53	-9.663	89.173	-40.611	3.748
89.85	920.29	-9.707	89.171	-40.796	3.748
89.93	921.05	-9.753	89.170	-40.989	3.748
90.01	921.82	-9.799	89.168	-41.182	3.748
90.08	922.58	-9.848	89.167	-41.388	3.748
90.16	923.34	-9.894	89.165	-41.583	3.747
90.24	924.11	-9.935	89.164	-41.754	3.747
90.31	924.87	-9.984	89.162	-41.961	3.747
90.39	925.64	-10.028	89.161	-42.147	3.747
90.47	926.40	-10.074	89.159	-42.337	3.747
90.54	927.17	-10.117	89.158	-42.521	3.747
90.62	927.93	-10.164	89.156	-42.716	3.747
90.70	928.70	-10.213	89.154	-42.924	3.747
90.77	929.46	-10.257	89.153	-43.108	3.747
90.85	930.23	-10.307	89.151	-43.318	3.747
90.93	930.99	-10.353	89.150	-43.511	3.747
91.00	931.75	-10.402	89.149	-43.719	3.747
91.08	932.52	-10.449	89.147	-43.917	3.747
91.16	933.28	-10.495	89.145	-44.108	3.747
91.23	934.04	-10.539	89.144	-44.295	3.747
91.31	934.81	-10.589	89.142	-44.503	3.747
91.39	935.57	-10.633	89.141	-44.687	3.746
91.46	936.34	-10.675	89.139	-44.866	3.746
91.54	937.10	-10.724	89.137	-45.071	3.746
91.62	937.87	-10.769	89.136	-45.262	3.746
91.69	938.63	-10.816	89.134	-45.457	3.746
91.77	939.39	-10.862	89.132	-45.650	3.746
91.85	940.16	-10.911	89.131	-45.859	3.746
91.92	940.92	-10.956	89.129	-46.046	3.746
92.00	941.69	-11.002	89.127	-46.242	3.746
92.08	942.45	-11.048	89.126	-46.435	3.746
92.15	943.22	-11.093	89.124	-46.621	3.746
92.23	943.98	-11.139	89.122	-46.815	3.746
92.31	944.74	-11.189	89.121	-47.025	3.746
92.38	945.51	-11.237	89.119	-47.229	3.746
92.46	946.27	-11.287	89.118	-47.438	3.745
92.54	947.04	-11.334	89.116	-47.637	3.745
92.61	947.80	-11.379	89.115	-47.824	3.745
92.69	948.56	-11.428	89.113	-48.032	3.745
92.77	949.33	-11.479	89.111	-48.244	3.745
92.84	950.09	-11.526	89.109	-48.441	3.745
92.92	950.85	-11.573	89.107	-48.638	3.745
93.00	951.62	-11.622	89.106	-48.844	3.745
93.07	952.38	-11.666	89.104	-49.030	3.745
93.15	953.15	-11.717	89.103	-49.243	3.745
93.23	953.91	-11.767	89.101	-49.453	3.745
93.30	954.67	-11.814	89.099	-49.654	3.745
93.38	955.44	-11.864	89.098	-49.863	3.745
93.46	956.20	-11.913	89.096	-50.066	3.745
93.53	956.97	-11.959	89.094	-50.261	3.744
93.61	957.73	-12.006	89.092	-50.459	3.744
93.69	958.50	-12.052	89.090	-50.655	3.744
93.76	959.26	-12.101	89.088	-50.860	3.744
93.84	960.03	-12.152	89.086	-51.071	3.744
93.92	960.79	-12.200	89.084	-51.275	3.744
93.99	961.55	-12.252	89.083	-51.491	3.744
94.07	962.32	-12.303	89.081	-51.708	3.744
94.15	963.08	-12.352	89.079	-51.912	3.744
94.22	963.85	-12.401	89.078	-52.120	3.744
94.30	964.61	-12.453	89.076	-52.337	3.744
94.38	965.37	-12.499	89.075	-52.530	3.744
94.45	966.13	-12.549	89.073	-52.740	3.744
94.53	966.90	-12.600	89.071	-52.955	3.744
94.61	967.66	-12.647	89.069	-53.153	3.743
94.68	968.43	-12.692	89.067	-53.344	3.743
94.76	969.19	-12.745	89.066	-53.567	3.743
94.84	969.96	-12.797	89.064	-53.784	3.743
94.91	970.72	-12.847	89.062	-53.993	3.743
94.99	971.48	-12.897	89.060	-54.203	3.743
95.07	972.25	-12.946	89.059	-54.410	3.743
95.14	973.01	-12.997	89.057	-54.626	3.743
95.22	973.78	-13.046	89.055	-54.830	3.743
95.30	974.54	-13.096	89.053	-55.041	3.743
95.37	975.31	-13.151	89.051	-55.271	3.743
95.45	976.07	-13.197	89.049	-55.465	3.743
95.53	976.84	-13.244	89.047	-55.663	3.742
95.60	977.60	-13.299	89.045	-55.892	3.742
95.68	978.36	-13.351	89.042	-56.114	3.742
95.76	979.13	-13.406	89.041	-56.343	3.742
95.83	979.89	-13.455	89.039	-56.548	3.742
95.91	980.66	-13.508	89.037	-56.770	3.742
95.99	981.42	-13.559	89.035	-56.986	3.742
96.06	982.18	-13.609	89.033	-57.195	3.742
96.14	982.95	-13.659	89.031	-57.408	3.742
96.22	983.71	-13.712	89.029	-57.628	3.742
96.29	984.47	-13.761	89.027	-57.836	3.742
96.37	985.24	-13.813	89.026	-58.055	3.742
96.45	986.00	-13.864	89.024	-58.267	3.742
96.52	986.77	-13.915	89.022	-58.481	3.741
96.60	987.53	-13.967	89.020	-58.701	3.741
96.68	988.29	-14.016	89.018	-58.907	3.741
96.75	989.06	-14.070	89.017	-59.134	3.741
96.83	989.82	-14.119	89.015	-59.340	3.741
96.91	990.59	-14.170	89.013	-59.555	3.741
96.98			89.011		3.741
97.00			89.010		3.741