File: Data/KMK245S/ZFCFC/KMK245S_ZFCFC.dat
[Header]
; MPMS3 Data File (default extension .dat)
; Copyright (c) 2007, Quantum Design, Inc. All rights reserved.
TITLE,
FILEOPENTIME,3870437754.78232,08/23/2022,5:35 pm
BYAPP,MPMS3 w/ AC,1.0,1.1
INFO,MPMS3 Measurement Release 1.1.16 Build 424, MultiVu Release 2.3.4.19,APPNAME
INFO,Linear Motor Servo Controller,MOTOR_MODULE_NAME
INFO,3101-100 J0,MOTOR_HW_VERSION
INFO,MMC721,MOTOR_SERIAL_NUMBER
INFO,01.04.28,MOTOR_SOFTWARE_VERSION
INFO,Quantum Design Squid Module,SQUID_MODULE_NAME
INFO,3101-501 B0,SQUID_HW_VERSION
INFO,SQM195,SQUID_SERIAL_NUMBER
INFO,01.03.04,SQUID_SOFTWARE_VERSION
INFO,SQUID AC,AC_MODULE_NAME
INFO,3101-401 f1,AC_HW_VERSION
INFO,SAC107,AC_SERIAL_NUMBER
INFO,SQUID AC 00.95.07,AC_SOFTWARE_VERSION
INFO,TCI166,COIL_SERIAL_NUMBER
INFO,0,MOMENT_UNITS
INFO,KMK245S,SAMPLE_MATERIAL
INFO,,SAMPLE_COMMENT
INFO,1.6,SAMPLE_MASS
INFO,,SAMPLE_VOLUME
INFO,,SAMPLE_MOLECULAR_WEIGHT
INFO,,SAMPLE_SIZE
INFO,,SAMPLE_SHAPE
INFO,Straw,SAMPLE_HOLDER
INFO,Standard,SAMPLE_HOLDER_DETAIL
INFO,67.65,SAMPLE_OFFSET
DATATYPE,COMMENT,1
DATATYPE,TIME,2
STARTUPAXIS,X,2
STARTUPAXIS,Y1,5
FIELDGROUP, VSM,2,3,4,5,6,8,9,10,11,14,15
FIELDGROUP, DC, 2,3,4,14,56,57,58,59,60,61,62,63,64,65,66,67,68,69
FIELDGROUP, AC, 2,3,4,11,16,17,18,19,20,21,22,23,24,25,26,27,28,29,30
STARTUPGROUP, All
[Data]
Comment,Time Stamp (sec),Temperature (K),Magnetic Field (Oe),Moment (emu),M. Std. Err. (emu),Transport Action,Averaging Time (sec),Frequency (Hz),Peak Amplitude (mm),Center Position (mm),Lockin Signal' (V),Lockin Signal (V),Range,M. Quad. Signal (emu),AC Moment (emu),AC M. Std Err. (emu),AC Phase (deg),AC Phase Std. Err. (deg),AC Susceptibility (emu/Oe),AC Suscept. Std Err. (emu/Oe),AC X' (emu/Oe),AC X' Std Err. (emu/Oe),AC X'' (emu/Oe),AC X'' Std Err. (emu/Oe),AC Drive (Oe),AC Frequency (Hz),AC Averaging Time (sec),AC Cycles,AC Range,AC Measure Type,AC Signal' (V),AC Signal'' (V),AC Trim Coil Ratio,AC Trim Coil Phase,Min. Temperature (K),Max. Temperature (K),Min. Field (Oe),Max. Field (Oe),Mass (grams),Motor Lag (deg),Pressure (Torr),Measure Count,Measurement Number,SQUID Status (code),Motor Status (code),Measure Status (code),Motor Current (amps),Motor Temp. (C),Temp. Status (code),Field Status (code),Chamber Status (code),Chamber Temp (K),Redirection State,Evercool Status,Average Temp (K),Rotation Angle (deg),Rotator state,DC Moment Fixed Ctr (emu),DC Moment Err Fixed Ctr (emu),DC Moment Free Ctr (emu),DC Moment Err Free Ctr (emu),DC Fixed Fit,DC Free Fit,DC Calculated Center (mm),DC Calculated Center Err (mm),DC Scan Length (mm),DC Scan Time (s),DC Number of Points,DC Squid Drift,DC Min V (V),DC Max V (V),DC Scans per Measure,Map 01,Map 02,Map 03,Map 04,Map 05,Map 06,Map 07,Map 08,Map 09,Map 10,Map 11,Map 12,Map 13,Map 14,Map 15,Map 16
,3870438984.65631,5.00235652923584,100.084869384766,,,6,,,,30.5486103174982,,,10,,,,,,,,,,,,,,,,,,,,,,4.99769067764282,5.0024242401123,100.084869384766,100.084869384766,,,3.15279293060303,,1,0,0,0,0.0138092041015625,30.7917900085449,1,1,1,5.00264358520508,0,4232058720,5.00003152144583,,,0.000509804291778659,2.52766233379605E-5,0.000510551243921462,2.52771319216844E-5,0.945510983467102,0.990753352642059,30.3433074951172,2.23637198359938E-5,35,4,200,4.67296376882587E-5,-0.243158563971519,0.00349988299421966,1,,,,,,,,,,,,,,,,
,3870439045.4033,8.61270666122436,100.084869384766,,,6,,,,30.5486103174982,,,10,,,,,,,,,,,,,,,,,,,,,,8.22810649871826,8.95971775054932,100.084869384766,100.084869384766,,,3.76738786697388,,1,0,0,0,0.0138092041015625,30.7917900085449,6,1,1,8.99730682373047,0,4232058720,8.59954633712769,,,0.000535890608840516,2.65699356739457E-5,0.000536670170956676,2.65704888175867E-5,0.945566177368164,0.989911675453186,30.3441181182861,5.50854969024658,35,4,200,0.000107267231214792,-0.250143766403198,0.0098324166610837,1,,,,,,,,,,,,,,,,
,3870439094.16752,12.4301199913025,100.084869384766,,,6,,,,30.5486103174982,,,10,,,,,,,,,,,,,,,,,,,,,,12.0407695770264,12.7650079727173,100.084869384766,100.084869384766,,,4.1222882270813,,1,0,0,0,0.0138092041015625,30.7917900085449,6,1,1,12.8194704055786,0,4232058688,12.4131517410278,,,0.00058001268505756,2.87570600506138E-5,0.00058084568240123,2.875770441692E-5,0.945876836776733,0.989600837230682,30.3455486297607,0.136152014136314,35,4,200,0.000111579618533142,-0.264061123132706,0.0175859946757555,1,,,,,,,,,,,,,,,,
,3870439161.14862,17.8322887420654,100.084869384766,,,6,,,,30.5537051454417,,,10,,,,,,,,,,,,,,,,,,,,,,17.4438877105713,18.1670074462891,100.084869384766,100.084869384766,,,4.41279888153076,,1,0,0,0,0.0138092041015625,31.2805480957031,2,1,1,18.2206897735596,0,4232058656,17.8080451965332,,,0.000665912698432695,3.30167183491454E-5,0.000666880886666129,3.30174067664036E-5,0.945467114448547,0.989312648773193,30.3492679595947,0,35,4,200,0.000127875828184187,-0.2941634953022,0.0294501483440399,1,,,,,,,,,,,,,,,,
,3870439209.98505,21.7315111160278,100.084869384766,,,6,,,,30.5537051454417,,,10,,,,,,,,,,,,,,,,,,,,,,21.3542613983154,22.0682525634766,100.084869384766,100.084869384766,,,4.54201412200928,,1,0,0,0,0.0138092041015625,30.7917900085449,2,1,1,22.1087608337402,0,4232058848,21.7027601242065,,,0.000734801048103027,3.64304620107398E-5,0.000735835841046323,3.64312121214551E-5,0.946391761302948,0.989771962165833,30.3524894714355,0.190034419298172,35,4,200,0.000107338666566648,-0.319117695093155,0.0376104153692722,1,,,,,,,,,,,,,,,,
,3870439276.97322,27.0700750350952,100.084869384766,,,6,,,,30.5588367324748,,,10,,,,,,,,,,,,,,,,,,,,,,26.6854782104492,27.4101486206055,100.084869384766,100.084869384766,,,4.6727876663208,,1,0,0,0,0,30.7917900085449,2,1,1,27.4546718597412,0,4232058752,27.0441268920898,,,0.000822822909233769,4.07937156520445E-5,0.000823967691640997,4.07944293566042E-5,0.946740031242371,0.99025309085846,30.3586444854736,1.77033211912203E-6,35,4,200,7.85749434726313E-5,-0.351597309112549,0.0474925078451633,1,,,,,,,,,,,,,,,,
,3870439339.40096,32.0643844604492,100.084869384766,,,6,,,,30.5642844103485,,,10,,,,,,,,,,,,,,,,,,,,,,31.2957496643066,32.7730369567871,100.084869384766,100.084869384766,,,4.76849842071533,,1,0,0,0,0.0138092041015625,30.7917900085449,2,1,1,32.8330192565918,0,4232058752,32.0427733973453,,,0.000907709415820734,4.50005940138962E-5,0.000908940339347398,4.50012935950069E-5,0.947405278682709,0.990470707416534,30.3665065765381,0,35,4,200,0.000107423315057531,-0.382925152778625,0.0571579337120056,1,,,,,,,,,,,,,,,,
,3870439392.92689,36.3472194671631,100.084869384766,,,6,,,,30.5642844103485,,,10,,,,,,,,,,,,,,,,,,,,,,35.9601554870605,36.6757850646973,100.084869384766,100.084869384766,,,4.82371854782105,,1,0,0,0,0.0138092041015625,30.7917900085449,2,1,1,36.7342834472656,0,4232058688,36.3261245727539,,,0.000970706537082834,4.81193695489839E-5,0.00097194131890434,4.81203724283911E-5,0.949151039123535,0.990610063076019,30.3731918334961,1.9144186808262E-5,35,4,200,0.000112196568807121,-0.405977070331574,0.0644868984818458,1,,,,,,,,,,,,,,,,
,3870439459.89421,41.7304592132568,100.084869384766,,,6,,,,30.5694999441657,,,10,,,,,,,,,,,,,,,,,,,,,,41.3393898010254,42.0891304016113,100.084869384766,100.084869384766,,,4.88616418838501,,1,0,0,0,0.0138092041015625,30.7917900085449,2,1,1,42.1215286254883,0,4232058784,41.7214385986328,,,0.00105897168269228,5.24913532357458E-5,0.00106024738116847,5.24923152927154E-5,0.950464487075806,0.990749597549438,30.3834247589111,1.83830670721363E-5,35,4,200,9.58386663114652E-5,-0.438150376081467,0.0749618262052536,1,,,,,,,,,,,,,,,,
,3870439527.03974,47.1139755249023,100.084869384766,,,6,,,,30.574746269321,,,10,,,,,,,,,,,,,,,,,,,,,,46.7276153564453,47.4607772827148,100.084869384766,100.084869384766,,,4.93765163421631,,1,0,0,0,0.0138092041015625,30.7917900085449,2,1,1,47.5003356933594,0,4232058688,47.1032241821289,,,0.00114909539739225,5.695408483986E-5,0.00115038699044235,5.69550080962584E-5,0.952093720436096,0.990872442722321,30.3949337005615,0,35,4,200,0.000129312073113397,-0.470665961503983,0.0859033986926079,1,,,,,,,,,,,,,,,,
,3870439593.83783,52.5097427368164,100.084869384766,,,6,,,,30.5798443067963,,,10,,,,,,,,,,,,,,,,,,,,,,52.1290664672852,52.856689453125,100.084869384766,100.084869384766,,,4.98281574249268,,1,0,0,0,0.0138092041015625,30.7917900085449,2,1,1,52.8904190063477,0,4232058592,52.4877025604248,,,0.00123942413157232,6.14257829983752E-5,0.00124070933617521,6.1426769680628E-5,0.953960299491882,0.990987539291382,30.4072113037109,0,35,4,200,0.000101486133644357,-0.503072321414948,0.0970554649829864,1,,,,,,,,,,,,,,,,
,3870439660.9444,57.9520950317383,100.084869384766,,,6,,,,30.5855111422002,,,10,,,,,,,,,,,,,,,,,,,,,,57.5539703369141,58.3134460449219,100.084869384766,100.084869384766,,,7.13137817382813,,1,0,0,0,0.0138092041015625,30.3030319213867,2,1,1,58.3502197265625,0,4232058656,57.9249881744385,,,0.00132987850418212,6.59028939468523E-5,0.00133113064556928,6.590342845123E-5,0.955915331840515,0.991091430187225,30.4204177856445,0.109167158603668,35,4,200,0.000136155926156789,-0.535388827323914,0.10832417011261,1,,,,,,,,,,,,,,,,
,3870439727.98046,63.3676090240478,100.084869384766,,,6,,,,30.5906924163253,,,10,,,,,,,,,,,,,,,,,,,,,,62.9759368896484,63.7378959655762,100.084869384766,100.084869384766,,,7.17709302902222,,1,0,0,0,0.0138092041015625,30.7917900085449,2,1,1,63.7592811584473,0,4232058688,63.3493419647217,,,0.00141909641331941,7.03173836395784E-5,0.0014203047149197,7.03182821234081E-5,0.958135306835175,0.99119383096695,30.434211730957,0,35,4,200,0.000100941630080342,-0.567153096199036,0.11947687715292,1,,,,,,,,,,,,,,,,
,3870439808.25368,69.8680000305176,100.084869384766,,,6,,,,30.6022723057463,,,10,,,,,,,,,,,,,,,,,,,,,,69.1024932861328,70.6019668579102,100.084869384766,100.084869384766,,,7.23765707015991,,1,0,0,0,0.0138092041015625,30.7917900085449,2,1,1,70.6335067749023,0,4232058752,69.849230716103,,,0.0015286287436097,7.57390968045734E-5,0.0015298169466032,7.57401065294398E-5,0.959974646568298,0.991283535957336,30.452917098999,INF,35,4,200,0.000135724782012403,-0.606158673763275,0.133271425962448,1,,,,,,,,,,,,,,,,
,3870439879.86437,75.7687683105469,100.084869384766,,,6,,,,30.6076000609436,,,10,,,,,,,,,,,,,,,,,,,,,,75.3569412231445,76.1639862060547,100.084869384766,100.084869384766,,,7.25284481048584,,1,0,0,0,0.0138092041015625,30.7917900085449,2,1,1,76.1805953979492,0,4232058656,75.7902893066406,,,0.00161101063917279,7.98129485299283E-5,0.00161209788997861,7.98137126373357E-5,0.962535798549652,0.991375863552094,30.4682140350342,0,35,4,200,0.000138730858452618,-0.63531219959259,0.143649399280548,1,,,,,,,,,,,,,,,,
,3870439964.92954,82.6507301330566,100.084869384766,,,6,,,,30.618807867331,,,10,,,,,,,,,,,,,,,,,,,,,,82.2398071289063,83.0419998168945,100.084869384766,100.084869384766,,,7.2756781578064,,1,0,0,0,0.0138092041015625,30.7917900085449,2,1,1,83.061653137207,0,4232058592,82.666529083252,,,0.00170924990487917,8.46727361943684E-5,0.00171025299137494,8.4673235024379E-5,0.964874088764191,0.991455972194672,30.488561630249,0,35,4,200,8.90417068148963E-5,-0.670149087905884,0.155982568860054,1,,,,,,,,,,,,,,,,
,3870440045.27752,89.2637481689453,100.084869384766,,,6,,,,30.6311245589084,,,10,,,,,,,,,,,,,,,,,,,,,,88.4875640869141,89.9980926513672,100.084869384766,100.084869384766,,,7.28603649139404,,1,0,0,0,0.0138092041015625,30.7917900085449,2,1,1,90.0399322509766,0,4232058656,89.2412454705489,,,0.001799424572255,8.91329830598083E-5,0.00180034459171626,8.91335681509716E-5,0.967127084732056,0.991513073444366,30.5097160339355,5.26734972000122,35,4,200,7.72134444559924E-5,-0.702144324779511,0.16728675365448,1,,,,,,,,,,,,,,,,
,3870440135.46739,96.6980857849121,100.084869384766,,,6,,,,30.6417031890553,,,10,,,,,,,,,,,,,,,,,,,,,,96.2998199462891,97.0446701049805,100.084869384766,100.084869384766,,,7.30624675750732,,1,0,0,0,0.0138092041015625,30.7917900085449,2,1,1,97.0963516235352,0,4232058720,96.6877632141113,,,0.00188127789463293,9.31789716082332E-5,0.00188205750882329,9.3179066414068E-5,0.970043301582336,0.991562128067017,30.5318279266357,5.26816272735596,35,4,200,0.000127507082652301,-0.731118500232697,0.177521988749504,1,,,,,,,,,,,,,,,,
,3870440233.92528,104.894866943359,100.084869384766,,,6,,,,30.6587037534348,,,10,,,,,,,,,,,,,,,,,,,,,,104.120811462402,105.60563659668,100.084869384766,100.084869384766,,,7.32834339141846,,1,0,0,0,0.0138092041015625,30.7917900085449,2,1,1,105.668922424316,0,4232058688,104.860543100457,,,0.00196837472115172,9.74852832292993E-5,0.00196903800702876,9.74853594349173E-5,0.972750604152679,0.991601467132568,30.5596027374268,0,35,4,200,5.87337926845066E-5,-0.761978924274445,0.188374325633049,1,,,,,,,,,,,,,,,,
,3870440337.78001,113.449405670166,100.084869384766,,,6,,,,30.6768388398061,,,10,,,,,,,,,,,,,,,,,,,,,,112.66576385498,114.167037963867,100.084869384766,100.084869384766,,,7.36188697814941,,1,0,0,0,0.0119781494140625,30.3030319213867,2,1,1,114.233047485352,0,4232058752,113.41594414962,,,0.00204340987964465,0.000101193892104085,0.00204394675526517,0.000101193989851942,0.975645840167999,0.991643667221069,30.5893974304199,0,35,4,200,0.000115427399578039,-0.788688719272614,0.197718158364296,1,,,,,,,,,,,,,,,,
,3870440477.82262,125.036632537842,100.084869384766,,,6,,,,30.7057533901328,,,10,,,,,,,,,,,,,,,,,,,,,,124.254867553711,125.787590026855,100.084869384766,100.084869384766,,,7.41835308074951,,1,0,0,0,0.0138092041015625,30.3030319213867,2,1,1,125.818397521973,0,4232058656,125.017223960475,,,0.00212668328123784,0.000105310231246824,0.0021270898532895,0.000105310279345131,0.978763401508331,0.991652011871338,30.631103515625,0,35,4,200,0.000103538404800929,-0.818293392658234,0.20802965760231,1,,,,,,,,,,,,,,,,
,3870440618.09883,136.703002929688,100.084869384766,,,6,,,,30.737599383272,,,10,,,,,,,,,,,,,,,,,,,,,,135.900390625,137.458129882812,100.084869384766,100.084869384766,,,7.4283709526062,,1,0,0,0,0.0138092041015625,30.7917900085449,2,1,1,137.505615234375,0,4232058880,136.680871260794,,,0.00219180973104344,0.000108529217140513,0.00219210602153663,0.000108529227321227,0.981557309627533,0.99163144826889,30.674783706665,0,35,4,200,9.48077504290268E-5,-0.841489434242249,0.216071739792824,1,,,,,,,,,,,,,,,,
,3870440757.8444,148.267639160156,100.084869384766,,,6,,,,30.7719705473577,,,10,,,,,,,,,,,,,,,,,,,,,,147.477798461914,149.01806640625,100.084869384766,100.084869384766,,,7.4093074798584,,1,0,0,0,0.0145721435546875,30.7917900085449,2,1,1,149.057479858398,0,4232058688,148.256997359426,,,0.00224060422154834,0.000110940686824419,0.00224081549493888,0.00011094079190036,0.983975768089294,0.991626024246216,30.7197532653809,5.26993417739868,35,4,200,8.18726766738109E-5,-0.858822524547577,0.22203928232193,1,,,,,,,,,,,,,,,,
,3870440897.90287,159.897262573242,100.084869384766,,,6,,,,30.8093448826121,,,10,,,,,,,,,,,,,,,,,,,,,,159.092803955078,160.598571777344,100.084869384766,100.084869384766,,,7.4949779510498,,1,0,0,0,0.0138092041015625,30.7917900085449,2,1,1,160.701721191406,0,4232058656,159.84575131065,,,0.00227477349923888,0.000112629081782694,0.00227491583460325,0.00011262907461524,0.986015617847443,0.991614639759064,30.766565322876,4.46760452632589E-7,35,4,200,1.50743117046659E-5,-0.870973289012909,0.226180478930473,1,,,,,,,,,,,,,,,,
,3870441037.92055,171.514350891113,100.084869384766,,,6,,,,30.8496198470395,,,10,,,,,,,,,,,,,,,,,,,,,,170.730422973633,172.231674194336,100.084869384766,100.084869384766,,,7.48328971862793,,1,0,0,0,0.0138092041015625,30.7917900085449,2,1,1,172.298278808594,0,4232058688,171.483322946649,,,0.00229477423172782,0.000113616936896824,0.00229486831380548,0.000113616915010777,0.987645506858826,0.991617739200592,30.8149299621582,0,35,4,200,6.78364131090348E-6,-0.878091633319855,0.228569090366364,1,,,,,,,,,,,,,,,,
,3870441177.71647,183.097595214844,100.084869384766,,,6,,,,30.8925196095478,,,10,,,,,,,,,,,,,,,,,,,,,,182.293029785156,183.849655151367,100.084869384766,100.084869384766,,,7.50389909744263,,1,0,0,0,0.0138092041015625,30.7917900085449,2,1,1,183.902160644531,0,4232058656,183.077616641396,,,0.0023010827200369,0.000113927563172558,0.00230114414626275,0.000113927604625869,0.988916993141174,0.991622805595398,30.8647861480713,0,35,4,200,5.94128432567231E-5,-0.88033390045166,0.229258209466934,1,,,,,,,,,,,,,,,,
,3870441317.63298,194.732688903809,100.084869384766,,,6,,,,30.9385849735042,,,10,,,,,,,,,,,,,,,,,,,,,,193.924255371094,195.474868774414,100.084869384766,100.084869384766,,,7.54819869995117,,1,0,0,0,0.0138092041015625,30.7917900085449,2,1,1,195.541122436523,0,4232058752,194.696286653218,,,0.00229450500551062,0.000113600822214847,0.00229454361356028,0.000113600827044049,0.989793598651886,0.991597294807434,30.9164390563965,4.24167001256137E-6,35,4,200,5.36287479917519E-5,-0.878280520439148,0.228338748216629,1,,,,,,,,,,,,,,,,
,3870441457.35352,206.358825683594,100.084869384766,,,6,,,,30.9871199416708,,,10,,,,,,,,,,,,,,,,,,,,,,205.540267944336,207.098510742187,100.084869384766,100.084869384766,,,7.52159404754639,,1,0,0,0,0.0138092041015625,30.3030319213867,2,1,1,207.177383422852,0,4232058848,206.292617797852,,,0.00227653191959025,0.000112710331565999,0.00227655558806019,0.000112710307739304,0.99038553237915,0.991560578346252,30.9695167541504,0,35,4,200,4.57694914075546E-5,-0.872274875640869,0.22600594162941,1,,,,,,,,,,,,,,,,
,3870441596.85627,217.88842010498,100.084869384766,,,6,,,,31.0386250880922,,,10,,,,,,,,,,,,,,,,,,,,,,217.103103637695,218.622680664062,100.084869384766,100.084869384766,,,7.57252359390259,,1,0,0,0,0.0138092041015625,30.3030319213867,2,1,1,218.673736572266,0,4232058688,217.859909860711,,,0.00224906680497065,0.000111350197041272,0.00224908323042293,0.000111350192461184,0.990700662136078,0.991527080535889,31.0239791870117,0,35,4,200,-1.90659739018884E-5,-0.862755835056305,0.222411498427391,1,,,,,,,,,,,,,,,,
,3870441736.5714,229.490692138672,100.084869384766,,,6,,,,31.0928948718275,,,10,,,,,,,,,,,,,,,,,,,,,,228.699676513672,230.214691162109,100.084869384766,100.084869384766,,,7.54044675827026,,1,0,0,0,0.0138092041015625,30.3030319213867,2,1,1,230.281707763672,0,4232058656,229.456276341488,,,0.00221399941597682,0.000109613833357418,0.00221401051285733,0.000109613817433161,0.990913271903992,0.991499722003937,31.0806198120117,5.27000617980957,35,4,200,3.67205939255655E-5,-0.85049444437027,0.217932939529419,1,,,,,,,,,,,,,,,,
,3870441876.36723,241.114379882813,100.084869384766,,,6,,,,31.1500705431615,,,10,,,,,,,,,,,,,,,,,,,,,,240.32585144043,241.8525390625,100.084869384766,100.084869384766,,,7.63356304168701,,1,0,0,0,0.0138092041015625,30.3030319213867,2,1,1,241.902908325195,0,4232058688,241.087503533614,,,0.00217326837451787,0.000107597057779132,0.00217327527822276,0.000107597044094014,0.991115391254425,0.991495370864868,31.1402454376221,0,35,4,200,-2.11454753298312E-5,-0.836052179336548,0.212756305932999,1,,,,,,,,,,,,,,,,
,3870442016.47268,252.767768859863,100.084869384766,,,6,,,,31.210159367201,,,10,,,,,,,,,,,,,,,,,,,,,,251.993209838867,253.505233764648,100.084869384766,100.084869384766,,,7.79083108901978,,1,0,0,0,0.0138092041015625,30.7917900085449,2,1,1,253.542327880859,0,4232058688,252.747340152138,,,0.00212853482020861,0.000105382186654372,0.00212853865907992,0.000105382188990677,0.991288840770721,0.991495788097382,31.2029457092285,5.26978492736816,35,4,200,-2.46471281570848E-5,-0.820244073867798,0.207078501582146,1,,,,,,,,,,,,,,,,
,3870442155.92438,264.344314575195,100.084869384766,,,6,,,,31.2729948417702,,,10,,,,,,,,,,,,,,,,,,,,,,263.558471679687,265.097808837891,100.084869384766,100.084869384766,,,7.73431539535522,,1,0,0,0,0.0138092041015625,30.7917900085449,2,1,1,265.130157470703,0,4232058624,264.344983552632,,,0.0020807858531659,0.000103017984111563,0.0020807864108696,0.000103017982141996,0.991478145122528,0.991511881351471,31.2700977325439,,35,4,200,3.06725487462245E-5,-0.803370416164398,0.201016440987587,1,,,,,,,,,,,,,,,,
,3870442295.97679,275.960479736328,100.084869384766,,,6,,,,31.3384160999698,,,10,,,,,,,,,,,,,,,,,,,,,,275.163391113281,276.705871582031,100.084869384766,100.084869384766,,,7.78197956085205,,1,0,0,0,0.0138092041015625,30.7917900085449,2,1,1,276.757568359375,0,4232058592,275.93970208419,,,0.00203081095862524,0.000100543985278673,0.00203081720494005,0.000100543989015407,0.991216063499451,0.991569101810455,31.3478393554687,0,35,4,200,1.84105228981934E-5,-0.785578310489655,0.194721132516861,1,,,,,,,,,,,,,,,,
,3870442435.90337,287.602783203125,100.084869384766,,,6,,,,31.4069447121301,,,10,,,,,,,,,,,,,,,,,,,,,,286.799468994141,288.322540283203,100.084869384766,100.084869384766,,,7.79531288146973,,1,0,0,0,0.0138092041015625,30.7917900085449,2,1,1,288.406097412109,0,4232058720,287.555967632093,,,0.001979215358886,9.79935809419254E-5,0.00197930290984792,9.79935973144347E-5,0.987365186214447,0.991543352603912,31.4428253173828,0,35,4,200,2.73354962700978E-5,-0.767329037189484,0.188164100050926,1,,,,,,,,,,,,,,,,
,3870442575.4766,298.852844238281,100.084869384766,,,6,,,,31.4783993515815,,,10,,,,,,,,,,,,,,,,,,,,,,298.408172607422,299.275024414063,100.084869384766,100.084869384766,,,8.03518581390381,,1,0,0,0,0.0138092041015625,30.7917900085449,6,1,1,299.297515869141,0,4232058688,298.914083380448,,,0.00192799671519118,9.54670941284992E-5,0.00192827103059865,9.54670930370541E-5,0.981105089187622,0.991484344005585,31.5428791046143,0,35,4,200,1.34397841975442E-5,-0.749336123466492,0.180984780192375,1,,,,,,,,,,,,,,,,
,3870442647.02096,299.893951416016,100.084869384766,,,6,,,,31.4834690254442,,,10,,,,,,,,,,,,,,,,,,,,,,299.88037109375,299.90673828125,100.084869384766,100.084869384766,,,8.21987915039063,,1,0,0,0,0.0138092041015625,30.7917900085449,5,1,1,299.907531738281,0,4232058816,299.895394897461,,,0.00192231647923547,9.51871333102301E-5,0.00192262354449194,9.51875200483835E-5,0.980403125286102,0.991468489170074,31.5509052276611,1,35,4,200,4.29869214713108E-5,-0.746853649616241,0.18013097345829,1,,,,,,,,,,,,,,,,
,3870442720.52878,299.522918701172,100.084869384766,,,6,,,,31.4834690254442,,,10,,,,,,,,,,,,,,,,,,,,,,299.333190917969,299.730834960937,100.084869384766,100.084869384766,,,8.53307723999023,,1,0,0,0,0.0138092041015625,30.7917900085449,2,1,1,299.290832519531,0,4232056832,299.542124430339,,,0.00192284473483632,9.52132406886331E-5,0.00192315007684337,9.52135974241939E-5,0.980439484119415,0.99147891998291,31.5507698059082,0,35,4,200,0.000110280663648155,-0.748392820358276,0.179104655981064,1,,,,,,,,,,,,,,,,
,3870442812.46965,291.85546875,100.084869384766,,,6,,,,31.4378956100967,,,10,,,,,,,,,,,,,,,,,,,,,,291.466064453125,292.278991699219,100.084869384766,100.084869384766,,,8.96102333068848,,1,0,0,0,0.0138092041015625,30.7917900085449,2,1,1,291.431945800781,0,4232058752,291.872344970703,,,0.00196117220988181,9.71159349905271E-5,0.00196159255659652,9.71166457318068E-5,0.978029668331146,0.991704046726227,31.5156574249268,8.39245149109047E-6,35,4,200,0.000141317781526595,-0.759696006774902,0.186341747641563,1,,,,,,,,,,,,,,,,
,3870442904.56015,284.334228515625,100.084869384766,,,6,,,,31.3981196593057,,,10,,,,,,,,,,,,,,,,,,,,,,283.980682373047,284.736572265625,100.084869384766,100.084869384766,,,8.65957069396973,,1,0,0,0,0,30.7917900085449,2,1,1,283.931884765625,0,4232058688,284.378228759766,,,0.00200263529150375,9.91640480834445E-5,0.00200295971645808,9.91644575623327E-5,0.98050981760025,0.991985976696014,31.4660320281982,0,35,4,200,0.000123294637887739,-0.774696528911591,0.190968751907349,1,,,,,,,,,,,,,,,,
,3870442996.42971,276.832672119141,100.084869384766,,,6,,,,31.3594114961277,,,10,,,,,,,,,,,,,,,,,,,,,,276.471618652344,277.243469238281,100.084869384766,100.084869384766,,,8.48457908630371,,1,0,0,0,0.0138092041015625,31.2805480957031,2,1,1,276.421875,0,4232058688,276.854626464844,,,0.00203384556372013,0.000100699359472411,0.00203396542792081,0.00010069956070589,0.986638963222504,0.991958796977997,31.400203704834,0,35,4,200,6.28383713774383E-5,-0.786124110221863,0.194590508937836,1,,,,,,,,,,,,,,,,
,3870443088.91561,269.247619628906,100.084869384766,,,6,,,,31.3220850616916,,,10,,,,,,,,,,,,,,,,,,,,,,268.886108398438,269.667358398438,100.084869384766,100.084869384766,,,8.34559631347656,,1,0,0,0,0.0138092041015625,31.2805480957031,2,1,1,268.827880859375,0,4232058784,269.288748168945,,,0.00206755534369095,0.000102363934183539,0.00206758473650375,0.000102364019207287,0.990453600883484,0.991977214813232,31.3418617248535,,35,4,200,0.000115493734483607,-0.798067629337311,0.198895379900932,1,,,,,,,,,,,,,,,,
,3870443181.64627,261.56169128418,100.084869384766,,,6,,,,31.2858945040489,,,10,,,,,,,,,,,,,,,,,,,,,,261.187164306641,261.966247558594,100.084869384766,100.084869384766,,,8.23960590362549,,1,0,0,0,0.0138092041015625,30.7917900085449,2,1,1,261.157135009766,0,4232058656,261.587176513672,,,0.00209993786488898,0.000103965950929012,0.0020999412589511,0.000103965940222592,0.991766333580017,0.991977870464325,31.2929821014404,0.351255923509598,35,4,200,0.000103837548522279,-0.809497177600861,0.203102216124535,1,,,,,,,,,,,,,,,,
,3870443274.91761,253.77027130127,100.084869384766,,,6,,,,31.2507687847076,,,10,,,,,,,,,,,,,,,,,,,,,,253.404769897461,254.199020385742,100.084869384766,100.084869384766,,,8.11542892456055,,1,0,0,0,0.018157958984375,30.7917900085449,2,1,1,253.341522216797,0,4232058624,253.81544342041,,,0.0021327105963177,0.0001055883253274,0.00213271143557487,0.000105588337339513,0.991958260536194,0.991993129253387,31.2479095458984,5.5899829864502,35,4,200,7.71568302297965E-5,-0.821100533008575,0.207379251718521,1,,,,,,,,,,,,,,,,
,3870443367.82525,246.010704040527,100.084869384766,,,6,,,,31.2166829857185,,,10,,,,,,,,,,,,,,,,,,,,,,245.627883911133,246.437210083008,100.084869384766,100.084869384766,,,8.06877899169922,,1,0,0,0,0.0138092041015625,30.3030319213867,2,1,1,245.584197998047,0,4232058528,246.056649780273,,,0.00216398258639427,0.000107136914372237,0.00216399003786797,0.000107136907623907,0.991583287715912,0.992010712623596,31.2065620422363,2.58921522799938E-6,35,4,200,0.000141492389957421,-0.832225501537323,0.211419299244881,1,,,,,,,,,,,,,,,,
,3870443460.72287,238.038864135742,100.084869384766,,,6,,,,31.1837633556424,,,10,,,,,,,,,,,,,,,,,,,,,,237.665832519531,238.454772949219,100.084869384766,100.084869384766,,,8.01092433929443,,1,0,0,0,0.0138092041015625,30.7917900085449,2,1,1,237.622955322266,0,4232058816,238.076374816895,,,0.00219528572376609,0.000108687098145596,0.00219530193767166,0.000108687095256248,0.991170167922974,0.992053806781769,31.1690464019775,0,35,4,200,0.000135505964863114,-0.841898143291473,0.216569975018501,1,,,,,,,,,,,,,,,,
,3870443552.86992,230.361129760742,100.084869384766,,,6,,,,31.1531088628134,,,10,,,,,,,,,,,,,,,,,,,,,,230.015396118164,230.780639648438,100.084869384766,100.084869384766,,,7.97669839859009,,1,0,0,0,0.0145721435546875,30.7917900085449,2,1,1,229.941619873047,0,4232058688,230.411418151855,,,0.00222498038267788,0.000110157893190432,0.0022250120895997,0.000110157923151508,0.990516543388367,0.992127180099487,31.1329002380371,,35,4,200,0.000146147911436856,-0.852274358272552,0.220468863844872,1,,,,,,,,,,,,,,,,
,3870443645.42305,222.709373474121,100.084869384766,,,6,,,,31.1231178455746,,,10,,,,,,,,,,,,,,,,,,,,,,222.351669311523,223.123794555664,100.084869384766,100.084869384766,,,7.93131160736084,,1,0,0,0,0.0146484375,29.8142719268799,2,1,1,222.294952392578,0,4232058656,222.747102355957,,,0.00225310931913857,0.000111551547083054,0.00225316465830671,0.000111551675630831,0.989606380462647,0.992175996303558,31.0969619750977,1.54295412357897E-6,35,4,200,0.00015322350373026,-0.862054228782654,0.224253281950951,1,,,,,,,,,,,,,,,,
,3870443738.2801,214.96314239502,100.084869384766,,,6,,,,31.0935313894646,,,10,,,,,,,,,,,,,,,,,,,,,,214.598358154297,215.365173339844,100.084869384766,100.084869384766,,,7.88364553451538,,1,0,0,0,0.013885498046875,30.7917900085449,2,1,1,214.561111450195,0,4232058656,214.994355773926,,,0.00228008181718643,0.000112888452024141,0.00228016232333761,0.000112888324268211,0.988420307636261,0.992175817489624,31.0609016418457,,35,4,200,0.000129119493067265,-0.871444404125214,0.2279402166605,1,,,,,,,,,,,,,,,,
,3870443830.37286,207.242462158203,100.084869384766,,,6,,,,31.0648086997605,,,10,,,,,,,,,,,,,,,,,,,,,,206.855484008789,207.651870727539,100.084869384766,100.084869384766,,,7.84961318969727,,1,0,0,0,0.0138092041015625,30.7917900085449,2,1,1,206.833053588867,0,4232058560,207.278450012207,,,0.00230640856873337,0.000114194279082604,0.00230653933651322,0.000114194242067554,0.98675400018692,0.99216228723526,31.0239868164063,5.07706272401265E-6,35,4,200,0.000130946049466729,-0.880756676197052,0.231451958417892,1,,,,,,,,,,,,,,,,
,3870443922.61934,199.597381591797,100.084869384766,,,6,,,,31.0364608414517,,,10,,,,,,,,,,,,,,,,,,,,,,199.241851806641,200.020553588867,100.084869384766,100.084869384766,,,7.80407857894897,,1,0,0,0,0,30.7917900085449,2,1,1,199.174209594727,0,4232058624,199.639671325684,,,0.00233184522748118,0.000115456891343328,0.00233204574309176,0.000115456993979062,0.984795689582825,0.992189645767212,30.9865913391113,0.189768105745316,35,4,200,0.000145696612889878,-0.889699399471283,0.234739080071449,1,,,,,,,,,,,,,,,,
,3870444015.05555,191.873306274414,100.084869384766,,,6,,,,31.0083453229925,,,10,,,,,,,,,,,,,,,,,,,,,,191.50944519043,192.307052612305,100.084869384766,100.084869384766,,,7.7829213142395,,1,0,0,0,0.0138092041015625,31.7693061828613,2,1,1,191.439559936523,0,4232058624,191.916181945801,,,0.00235632742071111,0.000116672382278988,0.00235659428574805,0.000116672366265349,0.983037173748016,0.992189347743988,30.9507846832275,0,35,4,200,0.000146040503750555,-0.898322343826294,0.238004058599472,1,,,,,,,,,,,,,,,,
,3870444107.83987,184.125625610352,100.084869384766,,,6,,,,30.9805833030099,,,10,,,,,,,,,,,,,,,,,,,,,,183.756942749023,184.544952392578,100.084869384766,100.084869384766,,,7.7591028213501,,1,0,0,0,0.0145721435546875,30.3030319213867,2,1,1,183.706298828125,0,4232058688,184.166981506348,,,0.00237966458933423,0.000117831650430388,0.00238000937771407,0.000117831605142985,0.981256067752838,0.99219822883606,30.9154205322266,4.79637606076722E-7,35,4,200,6.59150100545958E-5,-0.906554758548737,0.241100534796715,1,,,,,,,,,,,,,,,,
,3870444199.87918,176.475860595703,100.084869384766,,,6,,,,30.9534328604958,,,10,,,,,,,,,,,,,,,,,,,,,,176.117034912109,176.877502441406,100.084869384766,100.084869384766,,,7.72051334381103,,1,0,0,0,0.0176239013671875,30.7917900085449,2,1,1,176.07421875,0,4232058720,176.505174255371,,,0.00240128559983221,0.000118906017385932,0.00240171617729157,0.000118906318413044,0.979633092880249,0.992166221141815,30.8815498352051,0.18603889644146,35,4,200,0.000129044681671076,-0.914149522781372,0.243983566761017,1,,,,,,,,,,,,,,,,
,3870444292.71086,168.715255737305,100.084869384766,,,6,,,,30.9267178224888,,,10,,,,,,,,,,,,,,,,,,,,,,168.347686767578,169.130081176758,100.084869384766,100.084869384766,,,7.67856884002686,,1,0,0,0,0.0177001953125,30.3030319213867,2,1,1,168.300430297852,0,4232058624,168.756108093262,,,0.00242257608286561,0.000119965003190045,0.00242310945949287,0.000119965471603538,0.977781236171722,0.992169737815857,30.8472194671631,5.51783386981697E-7,35,4,200,0.000123500183690339,-0.92152601480484,0.246769666671753,1,,,,,,,,,,,,,,,,
,3870444385.55337,160.956428527832,100.084869384766,,,6,,,,30.9004883949965,,,10,,,,,,,,,,,,,,,,,,,,,,160.576629638672,161.393432617187,100.084869384766,100.084869384766,,,7.64938354492188,,1,0,0,0,0.0182342529296875,30.7917900085449,2,1,1,160.519424438477,0,4232058560,160.979258728027,,,0.0024424154713083,0.000120952371841817,0.00244306329938148,0.000120953353884657,0.976013898849487,0.992169082164764,30.8138160705566,5.87425120102125E-7,35,4,200,7.16729264240712E-5,-0.9285768866539,0.249376758933067,1,,,,,,,,,,,,,,,,
,3870444478.08061,153.254211425781,100.084869384766,,,6,,,,30.8748637551844,,,10,,,,,,,,,,,,,,,,,,,,,,152.884384155273,153.67138671875,100.084869384766,100.084869384766,,,7.60190296173096,,1,0,0,0,0.015716552734375,31.2805480957031,2,1,1,152.837036132813,0,4232058624,153.292259216309,,,0.00246088912495589,0.000121872525446325,0.00246163158164521,0.000121872701057998,0.974271178245544,0.992141425609589,30.7812061309814,,35,4,200,0.000166656376677565,-0.935079514980316,0.251692026853561,1,,,,,,,,,,,,,,,,
,3870444552.79616,147.037590026855,100.084869384766,,,6,,,,30.8547789317482,,,10,,,,,,,,,,,,,,,,,,,,,,146.69157409668,147.44514465332,100.084869384766,100.084869384766,,,7.56044864654541,,1,0,0,0,0.017547607421875,30.7917900085449,2,1,1,146.630035400391,0,4232058752,147.073374938965,,,0.00247500267862984,0.000122576049511352,0.00247584909423582,0.000122576605110207,0.972859442234039,0.992120385169983,30.7554950714111,0,35,4,200,0.000156874637468718,-0.94012463092804,0.253585070371628,1,,,,,,,,,,,,,,,,
,3870444627.87996,140.747886657715,100.084869384766,,,6,,,,30.8348449295857,,,10,,,,,,,,,,,,,,,,,,,,,,140.370147705078,141.14176940918,100.084869384766,100.084869384766,,,7.59616756439209,,1,0,0,0,0.0138092041015625,30.7917900085449,2,1,1,140.35400390625,0,4232058656,140.766926574707,,,0.00248825196243494,0.000123236890847556,0.00248920021446646,0.000123237629769199,0.971509337425232,0.992126107215881,30.7301540374756,0,35,4,200,0.000139233146910556,-0.944780707359314,0.255353003740311,1,,,,,,,,,,,,,,,,
,3870444694.71004,135.217834472656,100.084869384766,,,6,,,,30.8202354034575,,,10,,,,,,,,,,,,,,,,,,,,,,134.852523803711,135.599731445312,100.084869384766,100.084869384766,,,7.53932237625122,,1,0,0,0,0.0199127197265625,30.3030319213867,2,1,1,134.8359375,0,4232058624,135.236561584473,,,0.00249943302744262,0.000123797334718927,0.00250051908459139,0.000123798004777575,0.969672679901123,0.992117285728455,30.70827293396,5.26795816421509,35,4,200,3.86563697247766E-5,-0.94882744550705,0.256766021251678,1,,,,,,,,,,,,,,,,
,3870444769.22386,129.008285522461,100.084869384766,,,6,,,,30.7988390276714,,,10,,,,,,,,,,,,,,,,,,,,,,128.617904663086,129.452133178711,100.084869384766,100.084869384766,,,7.49824047088623,,1,0,0,0,0.000152587890625,30.7917900085449,2,1,1,128.564437866211,0,4232058592,129.049464416504,,,0.00251140286854137,0.000124394066133885,0.00251258257058921,0.000124395208710311,0.968655943870544,0.992123007774353,30.6828727722168,INF,35,4,200,4.64760305476375E-5,-0.953001856803894,0.2584248483181,1,,,,,,,,,,,,,,,,
,3870444836.69927,123.348361968994,100.084869384766,,,6,,,,30.7846215351476,,,10,,,,,,,,,,,,,,,,,,,,,,123.00651550293,123.731857299805,100.084869384766,100.084869384766,,,7.50797462463379,,1,0,0,0,0.000152587890625,30.7917900085449,2,1,1,122.964866638184,0,4232058624,123.375889587402,,,0.00252101995506388,0.000124877497794584,0.00252233758153171,0.000124878152488311,0.966895043849945,0.992127060890198,30.661678314209,5.26742076873779,35,4,200,0.000113893627712969,-0.956525206565857,0.259725332260132,1,,,,,,,,,,,,,,,,
,3870444912.15099,117.159320831299,100.084869384766,,,6,,,,30.7640997526555,,,10,,,,,,,,,,,,,,,,,,,,,,116.799179077148,117.569816589355,100.084869384766,100.084869384766,,,7.4894962310791,,1,0,0,0,0.016326904296875,30.3030319213867,2,1,1,116.748825073242,0,4232058624,117.191458129883,,,0.00253171968503372,0.000125412199668546,0.00253313383198593,0.00012541268963146,0.965792715549469,0.99213832616806,30.6367950439453,8.04135140697326E-7,35,4,200,0.000131533350213431,-0.96019035577774,0.261289119720459,1,,,,,,,,,,,,,,,,
,3870444979.02572,111.430603027344,100.084869384766,,,6,,,,30.7504956663172,,,10,,,,,,,,,,,,,,,,,,,,,,111.090148925781,111.841018676758,100.084869384766,100.084869384766,,,7.41438961029053,,1,0,0,0,0.0138092041015625,30.7917900085449,2,1,1,111.02018737793,0,4232058432,111.460861206055,,,0.00254034376896593,0.000125846820199939,0.00254192950207937,0.000125848183403656,0.964117884635925,0.992127954959869,30.6166114807129,,35,4,200,6.96603319738642E-6,-0.96277129650116,0.262816101312637,1,,,,,,,,,,,,,,,,
,3870445054.48735,105.180877685547,100.084869384766,,,6,,,,30.7302860692975,,,10,,,,,,,,,,,,,,,,,,,,,,104.82218170166,105.572700500488,100.084869384766,100.084869384766,,,7.40309619903564,,1,0,0,0,0.0145721435546875,30.3030319213867,2,1,1,104.789054870605,0,4232058720,105.207656097412,,,0.00254947280021152,0.000126303593769944,0.00255114989116615,0.000126304639301956,0.963124513626099,0.99212110042572,30.5925235748291,0.189901351928711,35,4,200,3.73392722394783E-5,-0.966000556945801,0.264089405536652,1,,,,,,,,,,,,,,,,
,3870445120.72711,99.6432304382324,100.084869384766,,,6,,,,30.7173859416467,,,10,,,,,,,,,,,,,,,,,,,,,,99.2875900268555,100.04810333252,100.084869384766,100.084869384766,,,7.4142279624939,,1,0,0,0,0.0160980224609375,30.7917900085449,2,1,1,99.2383575439453,0,4232058624,99.6640411376953,,,0.00255660171391383,0.000126665861053785,0.00255846613707884,0.000126666914172931,0.961236476898193,0.992101907730103,30.5722808837891,0,35,4,200,0.000112035297206603,-0.968534529209137,0.265134692192078,1,,,,,,,,,,,,,,,,
,3870445196.36002,93.252742767334,100.084869384766,,,6,,,,30.6984318991612,,,10,,,,,,,,,,,,,,,,,,,,,,92.92431640625,93.6569595336914,100.084869384766,100.084869384766,,,7.34646034240723,,1,0,0,0,0.01739501953125,31.2805480957031,2,1,1,92.8485260009766,0,4232058624,93.2927841186524,,,0.00256448525657993,0.000127062481834128,0.00256647320426058,0.000127063328036247,0.960028171539307,0.992089569568634,30.5486164093018,0,35,4,200,0.000138959076139145,-0.971189796924591,0.266343057155609,1,,,,,,,,,,,,,,,,
,3870445262.90283,87.7781982421875,100.084869384766,,,6,,,,30.6863042746225,,,10,,,,,,,,,,,,,,,,,,,,,,87.3970260620117,88.190185546875,100.084869384766,100.084869384766,,,7.30905818939209,,1,0,0,0,0.016937255859375,30.3030319213867,2,1,1,87.3662109375,0,4232058656,87.7919998168945,,,0.00257031211397562,0.000127361613757081,0.00257253601861027,0.000127363491472975,0.958033502101898,0.992093205451965,30.5287017822266,0,35,4,200,0.000129849941004068,-0.973316073417664,0.267175823450089,1,,,,,,,,,,,,,,,,
,3870445337.62398,81.511287689209,100.084869384766,,,6,,,,30.6688042446263,,,10,,,,,,,,,,,,,,,,,,,,,,81.1238784790039,81.9286422729492,100.084869384766,100.084869384766,,,7.3057279586792,,1,0,0,0,0.0174713134765625,30.7917900085449,2,1,1,81.0939331054687,0,4232058752,81.5307754516602,,,0.00257666021087709,0.000127683391610477,0.00257903327881263,0.000127685160727848,0.956704437732697,0.99207216501236,30.506031036377,5.52322626113892,35,4,200,3.56104210368358E-5,-0.975324332714081,0.268229901790619,1,,,,,,,,,,,,,,,,
,3870445404.41144,75.8038139343262,100.084869384766,,,6,,,,30.6576099224946,,,10,,,,,,,,,,,,,,,,,,,,,,75.4203186035156,76.2063369750977,100.084869384766,100.084869384766,,,7.23360729217529,,1,0,0,0,0.0164794921875,30.7917900085449,2,1,1,75.4012908935547,0,4232058720,75.8223518371582,,,0.00258180932588812,0.000127950390605665,0.00258443145043384,0.000127952480992272,0.954628169536591,0.992050349712372,30.4868049621582,0,35,4,200,0.000131971275550313,-0.977188408374786,0.269100695848465,1,,,,,,,,,,,,,,,,
,3870445479.19405,69.5503807067871,100.084869384766,,,6,,,,30.6416587998837,,,10,,,,,,,,,,,,,,,,,,,,,,69.1653289794922,69.9684371948242,100.084869384766,100.084869384766,,,7.16149473190308,,1,0,0,0,0.0138092041015625,30.7917900085449,2,1,1,69.13232421875,0,4232058624,69.5666847229004,,,0.00258676380155985,0.000128204335404821,0.00258955727573383,0.000128206268441387,0.953206956386566,0.992032110691071,30.4653244018555,0,35,4,200,0.000107027750345878,-0.978600084781647,0.270068943500519,1,,,,,,,,,,,,,,,,
,3870445545.80348,63.9309921264648,100.084869384766,,,6,,,,30.6314607527673,,,10,,,,,,,,,,,,,,,,,,,,,,63.5365142822266,64.3510284423828,100.084869384766,100.084869384766,,,7.13962078094482,,1,0,0,0,0.0157928466796875,30.3030319213867,2,1,1,63.5109558105469,0,4232058752,63.9392356872559,,,0.00259052071668408,0.000128403064656769,0.00259357695232888,0.000128405280888759,0.951167106628418,0.992009222507477,30.447229385376,0,35,4,200,0.000106789811979979,-0.979857087135315,0.27081173658371,1,,,,,,,,,,,,,,,,
,3870445612.13727,58.3105697631836,100.084869384766,,,6,,,,30.6185150769931,,,10,,,,,,,,,,,,,,,,,,,,,,57.9465751647949,58.724494934082,100.084869384766,100.084869384766,,,7.06276655197144,,1,0,0,0,0.0138092041015625,30.7917900085449,2,1,1,57.8966445922852,0,4232058784,58.3441856384277,,,0.00259399504012745,0.000128583589971394,0.00259720787041828,0.000128585092454106,0.949871182441711,0.992010653018951,30.4292659759521,0.189976006746292,35,4,200,8.85034387465566E-5,-0.980696558952332,0.271555513143539,1,,,,,,,,,,,,,,,,
,3870445669.72917,53.4436569213867,100.084869384766,,,6,,,,30.6122884696433,,,10,,,,,,,,,,,,,,,,,,,,,,53.074535369873,53.8457260131836,100.084869384766,100.084869384766,,,6.99656438827515,,1,0,0,0,0.0138092041015625,30.7917900085449,2,1,1,53.0415878295898,0,4232058560,53.4769588470459,,,0.0025964383333642,0.00012871802487937,0.00259993577231848,0.000128720177524901,0.947852432727814,0.991981089115143,30.4152221679687,1.71739284269279E-5,35,4,200,0.000104170023405459,-0.981445968151092,0.272195637226105,1,,,,,,,,,,,,,,,,
,3870445735.81904,47.8514804840088,100.084869384766,,,6,,,,30.6006089768869,,,10,,,,,,,,,,,,,,,,,,,,,,47.4939498901367,48.2369041442871,100.084869384766,100.084869384766,,,6.98882818222046,,1,0,0,0,0.0138092041015625,30.7917900085449,2,1,1,47.4660568237305,0,4232058496,47.878071975708,,,0.00259898629728463,0.000128851709486162,0.00260264159290318,0.000128854118525521,0.946766912937164,0.991981983184814,30.3993511199951,,35,4,200,2.10992984648328E-5,-0.982087910175324,0.272881805896759,1,,,,,,,,,,,,,,,,
,3870445800.80241,42.3870544433594,100.084869384766,,,6,,,,30.5899096666469,,,10,,,,,,,,,,,,,,,,,,,,,,42.016185760498,42.7918815612793,100.084869384766,100.084869384766,,,6.88488483428955,,1,0,0,0,0.0138092041015625,32.2580642700195,2,1,1,41.9822273254395,0,4232058688,42.4010341644287,,,0.00260090647870458,0.000128954202818445,0.00260470853550105,0.000128956419063015,0.94571441411972,0.991991281509399,30.3845729827881,,35,4,200,2.00558151846053E-5,-0.982396066188812,0.27354770898819,1,,,,,,,,,,,,,,,,
,3870445858.16134,37.5374889373779,100.084869384766,,,6,,,,30.5848317448767,,,10,,,,,,,,,,,,,,,,,,,,,,37.1804542541504,37.9317054748535,100.084869384766,100.084869384766,,,4.97320795059204,,1,0,0,0,0.0138092041015625,30.3030319213867,2,1,1,37.1432723999023,0,4232058656,37.5708938598633,,,0.00260206109449201,0.000129023662345044,0.00260611422451969,0.000129026037507597,0.944005906581879,0.991988599300385,30.3728847503662,8.21882986201672E-6,35,4,200,8.48376294015907E-5,-0.982445418834686,0.274169534444809,1,,,,,,,,,,,,,,,,
,3870445915.57117,32.7210102081299,100.084869384766,,,6,,,,30.5787558740547,,,10,,,,,,,,,,,,,,,,,,,,,,32.3724517822266,33.0464820861816,100.084869384766,100.084869384766,,,4.89328193664551,,1,0,0,0,0.0138092041015625,31.7693061828613,2,1,1,32.3165817260742,0,4232058752,32.7037489149306,,,0.00260294494660525,0.000129076453644983,0.00260718188355742,0.000129078878990966,0.942781627178192,0.991997182369232,30.3620586395264,5.51017761230469,35,4,200,1.77780439116759E-5,-0.982439756393433,0.274746954441071,1,,,,,,,,,,,,,,,,
,3870445981.76374,27.1579351425171,100.084869384766,,,6,,,,30.5675372086235,,,10,,,,,,,,,,,,,,,,,,,,,,26.779541015625,27.5686206817627,100.084869384766,100.084869384766,,,4.77035760879517,,1,0,0,0,0.0138092041015625,30.7917900085449,2,1,1,26.7472496032715,0,4232058624,27.1819812774658,,,0.00260360583269271,0.000129109830882384,0.00260785872743382,0.000129112350075097,0.942694187164307,0.99199253320694,30.3505020141602,0,35,4,200,7.3973395046778E-5,-1.09083092212677,0.275276660919189,1,,,,,,,,,,,,,,,,
,3870446039.69097,22.3240928649902,100.084869384766,,,6,,,,30.5623276868239,,,10,,,,,,,,,,,,,,,,,,,,,,21.9561634063721,22.7083854675293,100.084869384766,100.084869384766,,,4.61014699935913,,1,0,0,0,0.0138092041015625,30.7917900085449,2,1,1,21.9398002624512,0,4232058464,22.3403568267822,,,0.00260339052176075,0.000129105456969784,0.00260777658265255,0.000129108294172414,0.941851079463959,0.991980731487274,30.3420295715332,8.78251557878684E-6,35,4,200,9.19299563975073E-5,-1.0902704000473,0.27578216791153,1,,,,,,,,,,,,,,,,
,3870446096.909,17.5794620513916,100.084869384766,,,6,,,,30.5563372216217,,,10,,,,,,,,,,,,,,,,,,,,,,17.2268962860107,17.971607208252,100.084869384766,100.084869384766,,,4.35526704788208,,1,0,0,0,0,30.7917900085449,2,1,1,17.1873168945313,0,4232058656,17.6011526107788,,,0.00260244810970275,0.000129061491485094,0.00260687690791859,0.000129063796682529,0.941490054130554,0.991978764533997,30.3346786499023,0,35,4,200,0.000100853976618964,-1.08940589427948,0.276188611984253,1,,,,,,,,,,,,,,,,
,3870446153.0779,13.0040059089661,100.084869384766,,,6,,,,30.5510169734876,,,10,,,,,,,,,,,,,,,,,,,,,,12.6516132354736,13.372932434082,100.084869384766,100.084869384766,,,3.98034977912903,,1,0,0,0,0.0138092041015625,30.7917900085449,2,1,1,12.6148338317871,0,4232058560,13.0124074935913,,,0.0026008099164998,0.000128981058422486,0.00260526837514385,0.00012898418105139,0.941386044025421,0.991978168487549,30.3289527893066,0,35,4,200,2.27632722271665E-6,-1.0883697271347,0.276511907577515,1,,,,,,,,,,,,,,,,
,3870446210.36986,8.75457429885864,100.084869384766,,,6,,,,30.5459600491191,,,10,,,,,,,,,,,,,,,,,,,,,,8.38474941253662,9.15864753723145,100.084869384766,100.084869384766,,,3.5433874130249,,1,0,0,0,0,30.7917900085449,6,1,1,8.35050106048584,0,4232059264,8.77397956848145,,,0.00259911795749142,0.000128893856832874,0.00260348253803799,0.000128895728363575,0.941818356513977,0.991988003253937,30.3255653381348,0,35,4,200,6.98160220053978E-5,-1.08834326267242,0.275617599487305,1,,,,,,,,,,,,,,,,
,3870446259.50381,5.02702283859253,100.084869384766,,,6,,,,30.5459600491191,,,10,,,,,,,,,,,,,,,,,,,,,,4.99520444869995,5.05072212219238,100.084869384766,100.084869384766,,,3.06953907012939,,1,0,0,0,0.0138092041015625,30.3030319213867,6,1,1,5.00332355499268,0,4232058848,5.00585255622864,,,0.00259825055223535,0.0001288501844162,0.00260260966947122,0.00012885248646498,0.941905379295349,0.992012083530426,30.325870513916,0,35,4,200,9.05470951693133E-5,-1.0876282453537,0.275892317295074,1,,,,,,,,,,,,,,,,
,3870446308.39213,5.00236320495605,100.084869384766,,,6,,,,30.5459600491191,,,10,,,,,,,,,,,,,,,,,,,,,,4.9980673789978,5.00286102294922,100.084869384766,100.084869384766,,,2.98933029174805,,1,0,0,0,0,30.7917900085449,5,1,1,5.0028247833252,0,4232058784,5.00015120506287,,,0.00259830910515793,0.000128851677353036,0.00260265752292031,0.000128854870334278,0.942094385623932,0.992003738880157,30.3266010284424,1.64701214089291E-6,35,4,200,7.06952196196653E-5,-1.08769011497498,0.275857001543045,1,,,,,,,,,,,,,,,,
,3870446328.08855,5.00236701965332,100.084869384766,,,6,,,,30.5459600491191,,,10,,,,,,,,,,,,,,,,,,,,,,4.99800109863281,5.00246238708496,100.084869384766,100.084869384766,,,2.98992705345154,,1,0,0,0,0.015869140625,30.7917900085449,1,1,1,5.00249004364014,0,4232058752,5.00002188682556,,,0.00259833268494253,0.000128852317622999,0.00260265711907893,0.000128854815245132,0.942160069942474,0.992001354694366,30.3268489837646,0,35,4,200,9.0070505393669E-5,-1.08771705627441,0.27582773566246,1,,,,,,,,,,,,,,,,