File: Data/KMK249/MvsH/KMK249_MvsH_300K.dat
[Header]
; MPMS3 Data File (default extension .dat)
; Copyright (c) 2007, Quantum Design, Inc. All rights reserved.
TITLE,
FILEOPENTIME,3889775217.47212,04/04/2023,2:08 pm
BYAPP,MPMS3 w/ AC,1.0,1.1
INFO,MPMS3 Measurement Release 1.1.16 Build 424, MultiVu Release 2.3.4.19,APPNAME
INFO,Linear Motor Servo Controller,MOTOR_MODULE_NAME
INFO,3101-100 J0,MOTOR_HW_VERSION
INFO,MMC721,MOTOR_SERIAL_NUMBER
INFO,01.04.28,MOTOR_SOFTWARE_VERSION
INFO,Quantum Design Squid Module,SQUID_MODULE_NAME
INFO,3101-501 B0,SQUID_HW_VERSION
INFO,SQM195,SQUID_SERIAL_NUMBER
INFO,01.03.04,SQUID_SOFTWARE_VERSION
INFO,SQUID AC,AC_MODULE_NAME
INFO,3101-401 f1,AC_HW_VERSION
INFO,SAC107,AC_SERIAL_NUMBER
INFO,SQUID AC 00.95.07,AC_SOFTWARE_VERSION
INFO,TCI166,COIL_SERIAL_NUMBER
INFO,0,MOMENT_UNITS
INFO,KMK249,SAMPLE_MATERIAL
INFO,,SAMPLE_COMMENT
INFO,2.6,SAMPLE_MASS
INFO,,SAMPLE_VOLUME
INFO,,SAMPLE_MOLECULAR_WEIGHT
INFO,,SAMPLE_SIZE
INFO,,SAMPLE_SHAPE
INFO,Straw,SAMPLE_HOLDER
INFO,Standard,SAMPLE_HOLDER_DETAIL
INFO,67.43,SAMPLE_OFFSET
DATATYPE,COMMENT,1
DATATYPE,TIME,2
STARTUPAXIS,X,2
STARTUPAXIS,Y1,5
FIELDGROUP, VSM,2,3,4,5,6,8,9,10,11,14,15
FIELDGROUP, DC, 2,3,4,14,56,57,58,59,60,61,62,63,64,65,66,67,68,69
FIELDGROUP, AC, 2,3,4,11,16,17,18,19,20,21,22,23,24,25,26,27,28,29,30
STARTUPGROUP, All
[Data]
Comment,Time Stamp (sec),Temperature (K),Magnetic Field (Oe),Moment (emu),M. Std. Err. (emu),Transport Action,Averaging Time (sec),Frequency (Hz),Peak Amplitude (mm),Center Position (mm),Lockin Signal' (V),Lockin Signal (V),Range,M. Quad. Signal (emu),AC Moment (emu),AC M. Std Err. (emu),AC Phase (deg),AC Phase Std. Err. (deg),AC Susceptibility (emu/Oe),AC Suscept. Std Err. (emu/Oe),AC X' (emu/Oe),AC X' Std Err. (emu/Oe),AC X'' (emu/Oe),AC X'' Std Err. (emu/Oe),AC Drive (Oe),AC Frequency (Hz),AC Averaging Time (sec),AC Cycles,AC Range,AC Measure Type,AC Signal' (V),AC Signal'' (V),AC Trim Coil Ratio,AC Trim Coil Phase,Min. Temperature (K),Max. Temperature (K),Min. Field (Oe),Max. Field (Oe),Mass (grams),Motor Lag (deg),Pressure (Torr),Measure Count,Measurement Number,SQUID Status (code),Motor Status (code),Measure Status (code),Motor Current (amps),Motor Temp. (C),Temp. Status (code),Field Status (code),Chamber Status (code),Chamber Temp (K),Redirection State,Evercool Status,Average Temp (K),Rotation Angle (deg),Rotator state,DC Moment Fixed Ctr (emu),DC Moment Err Fixed Ctr (emu),DC Moment Free Ctr (emu),DC Moment Err Free Ctr (emu),DC Fixed Fit,DC Free Fit,DC Calculated Center (mm),DC Calculated Center Err (mm),DC Scan Length (mm),DC Scan Time (s),DC Number of Points,DC Squid Drift,DC Min V (V),DC Max V (V),DC Scans per Measure,Map 01,Map 02,Map 03,Map 04,Map 05,Map 06,Map 07,Map 08,Map 09,Map 10,Map 11,Map 12,Map 13,Map 14,Map 15,Map 16
,3889775360.76062,300.052749633789,-70000.421875,,,6,,,,32.1014785766602,,,1000,,,,,,,,,,,,,,,,,,,,,,300.045623779297,300.064331054687,-70000.421875,-70000.421875,,,7.23952293395996,,1,0,0,0,0.013885498046875,32.7468223571777,1,1,1,300.054504394531,0,2084573184,300.056253533614,,,-0.136191534179248,0.0067964178522498,-0.136207734587039,0.00679643343602892,0.966552674770355,0.970240116119385,32.1594429016113,,35,4,200,-0.000341775768902153,-4.83472108840942,4.85903167724609,1,,,,,,,,,,,,,,,,
,3889775521.4922,300.04313659668,-45000.3984375,,,6,,,,32.1014785766602,,,1000,,,,,,,,,,,,,,,,,,,,,,300.029205322266,300.059783935547,-45000.3984375,-45000.3984375,,,7.34927558898926,,1,0,0,0,0.013885498046875,32.2580642700195,1,1,1,300.029693603516,0,2084574272,300.048376464844,,,-0.135121374796379,0.00674223295618715,-0.135132143503521,0.00674224366316898,0.970212638378143,0.972959220409393,32.1489524841309,0,35,4,200,0.000237933578318916,-0.127911821007729,0.531405806541443,1,,,,,,,,,,,,,,,,
,3889775675.52705,300.119934082031,-20000.2421875,,,6,,,,32.1014785766602,,,1000,,,,,,,,,,,,,,,,,,,,,,300.099548339844,300.140197753906,-20000.2421875,-20000.2421875,,,7.42779159545898,,1,0,0,0,0.013885498046875,32.7468223571777,1,1,1,300.099670410156,0,2084574592,300.125317382812,,,-0.133525114083444,0.00666220038010825,-0.133531655364658,0.00666220729772286,0.972219169139862,0.974001049995422,32.1386909484863,0,35,4,200,0.000251916470006108,-0.12429540604353,0.524787724018097,1,,,,,,,,,,,,,,,,
,3889775825.15628,300.112396240234,-8500.2353515625,,,6,,,,32.1014785766602,,,1000,,,,,,,,,,,,,,,,,,,,,,300.105285644531,300.130584716797,-8500.2353515625,-8500.2353515625,,,7.47961187362671,,1,0,0,0,0.0003814697265625,32.7468223571777,1,1,1,300.119506835937,0,2084575104,300.121200561523,,,-0.130722840138526,0.00652230821578678,-0.130729435796984,0.0065223176229191,0.972628653049469,0.97448068857193,32.139102935791,5.22882795333862,35,4,200,0.000335902703227475,-0.121412217617035,0.514837920665741,1,,,,,,,,,,,,,,,,
,3889775947.97471,300.164459228516,-6000.32568359375,,,6,,,,32.1014785766602,,,1000,,,,,,,,,,,,,,,,,,,,,,300.162689208984,300.180877685547,-6000.32568359375,-6000.32568359375,,,7.51690864562988,,1,0,0,0,0.013885498046875,32.7468223571777,1,1,1,300.166229248047,0,2084574944,300.171783447266,,,-0.128699847299419,0.00642138683081491,-0.128706948860635,0.00642140144028796,0.972543299198151,0.974541366100311,32.140567779541,5.66926527023315,35,4,200,0.000266895745880902,-0.118526123464108,0.507020354270935,1,,,,,,,,,,,,,,,,
,3889776066.34797,299.971588134766,-3500.42822265625,,,6,,,,32.1014785766602,,,1000,,,,,,,,,,,,,,,,,,,,,,299.953979492188,299.988922119141,-3500.42822265625,-3500.42822265625,,,7.54670906066895,,1,0,0,0,0.013885498046875,32.7468223571777,1,1,1,299.954254150391,0,2084574944,299.974951171875,,,-0.123284750047617,0.00615119077094624,-0.123291579807732,0.00615120314313055,0.972622156143188,0.974645495414734,32.1407470703125,,35,4,200,0.000209001125767827,-0.113825418055058,0.485639750957489,1,,,,,,,,,,,,,,,,
,3889776190.05282,300.142730712891,-1000.26202392578,,,6,,,,32.1014785766602,,,1000,,,,,,,,,,,,,,,,,,,,,,300.135711669922,300.161346435547,-1000.26202392578,-1000.26202392578,,,7.57418012619018,,1,0,0,0,0.013885498046875,32.7468223571777,1,1,1,300.149749755859,0,2084574912,300.151885986328,,,-0.0824387000983789,0.00411321915675922,-0.0824435411630471,0.0041132255450755,0.972538530826569,0.974704265594482,32.1421165466309,5.6694016456604,35,4,200,0.000111358887807,-0.0766458585858345,0.324025183916092,1,,,,,,,,,,,,,,,,
,3889776316.21994,300.219421386719,-760.175659179688,,,6,,,,32.1014785766602,,,1000,,,,,,,,,,,,,,,,,,,,,,300.214874267578,300.239410400391,-760.175659179688,-760.175659179688,,,7.60048198699951,,1,0,0,0,0.013885498046875,33.2355842590332,1,1,1,300.223968505859,0,2084574976,300.229260253906,,,-0.0684788166040494,0.00341668372946591,-0.06848259883219,0.00341669487154442,0.972731530666351,0.974707663059235,32.1402168273926,0,35,4,200,-0.000154537716298364,-0.0642803832888603,0.268887728452682,1,,,,,,,,,,,,,,,,
,3889776434.33415,300.161727905273,-710.322692871094,,,6,,,,32.1014785766602,,,1000,,,,,,,,,,,,,,,,,,,,,,300.159851074219,300.179565429687,-710.322692871094,-710.322692871094,,,7.61944627761841,,1,0,0,0,0.013885498046875,32.7468223571777,1,1,1,300.163604736328,0,2084574912,300.169714355469,,,-0.0650979834697692,0.00324799292633763,-0.0651012943105497,0.00324799754173901,0.972814381122589,0.974696815013885,32.1392631530762,0,35,4,200,-0.000172328800545074,-0.061131339520216,0.255568295717239,1,,,,,,,,,,,,,,,,
,3889776553.23485,300.209869384766,-660.274169921875,,,6,,,,32.1014785766602,,,1000,,,,,,,,,,,,,,,,,,,,,,300.203399658203,300.232940673828,-660.274169921875,-660.274169921875,,,7.63746786117554,,1,0,0,0,0,32.7468223571777,1,1,1,300.216339111328,0,2084574848,300.221850585937,,,-0.0614977328675098,0.00306835964632487,-0.0615006386835237,0.00306836178990351,0.972849786281586,0.974620938301086,32.1381454467773,0,35,4,200,-0.000153771601617336,-0.0580380782485008,0.241271942853928,1,,,,,,,,,,,,,,,,
,3889776671.20325,300.25178527832,-610.274475097656,,,6,,,,32.1014785766602,,,1000,,,,,,,,,,,,,,,,,,,,,,300.245269775391,300.273162841797,-610.274475097656,-610.274475097656,,,7.65197038650513,,1,0,0,0,0.013885498046875,32.7468223571777,1,1,1,300.25830078125,0,2084574976,300.2619140625,,,-0.0577196015737404,0.00287984879704347,-0.0577223818127834,0.00287985332707984,0.972910523414612,0.97468763589859,32.1381607055664,0,35,4,200,-0.000168185622896999,-0.0544233433902264,0.226477831602097,1,,,,,,,,,,,,,,,,
,3889776787.84041,300.235855102539,-560.177001953125,,,6,,,,32.1014785766602,,,1000,,,,,,,,,,,,,,,,,,,,,,300.234130859375,300.255249023438,-560.177001953125,-560.177001953125,,,7.66800165176392,,1,0,0,0,0.013885498046875,32.7468223571777,1,1,1,300.237579345703,0,2084575136,300.245364379883,,,-0.0537571868205759,0.00268214024936092,-0.0537595840859012,0.00268214534728604,0.973031640052795,0.974662959575653,32.1365928649902,5.22934913635254,35,4,200,-0.000163954828167334,-0.0507035814225674,0.210760191082954,1,,,,,,,,,,,,,,,,
,3889776896.95124,300.064636230469,-510.079620361328,,,6,,,,32.1014785766602,,,1000,,,,,,,,,,,,,,,,,,,,,,300.043792724609,300.082733154297,-510.079620361328,-510.079620361328,,,7.67921876907349,,1,0,0,0,0.013885498046875,32.2580642700195,1,1,1,300.085479736328,0,2084574944,300.072134399414,,,-0.0496020576551231,0.00247481405306229,-0.0496040417860308,0.00247481868731444,0.973209679126739,0.97467178106308,32.1346626281738,0,35,4,200,-0.000201856149942614,-0.0470248162746429,0.194367319345474,1,,,,,,,,,,,,,,,,
,3889777011.34402,300.15461730957,-460.128845214844,,,6,,,,32.1014785766602,,,1000,,,,,,,,,,,,,,,,,,,,,,300.137359619141,300.176055908203,-460.128845214844,-460.128845214844,,,7.69270467758179,,1,0,0,0,0.013885498046875,32.7468223571777,1,1,1,300.171875,0,2084574880,300.165115356445,,,-0.0452411538179503,0.00225723278507036,-0.0452429055073905,0.00225723670958815,0.97321879863739,0.974636197090149,32.1341590881348,0,35,4,200,-0.000185734854312614,-0.0426736064255238,0.177589774131775,1,,,,,,,,,,,,,,,,
,3889777132.29418,300.234848022461,-410.068084716797,,,6,,,,32.1014785766602,,,1000,,,,,,,,,,,,,,,,,,,,,,300.230102539063,300.254577636719,-410.068084716797,-410.068084716797,,,7.70574903488159,,1,0,0,0,0.013885498046875,32.7468223571777,1,1,1,300.239593505859,0,2084574944,300.244546508789,,,-0.040658925293133,0.00202861060476433,-0.0406604805903442,0.00202861418431813,0.973212480545044,0.974610090255737,32.1339378356934,0,35,4,200,-0.000177864072611555,-0.0385917350649834,0.159463331103325,1,,,,,,,,,,,,,,,,
,3889777248.76499,300.137222290039,-359.995086669922,,,6,,,,32.1014785766602,,,1000,,,,,,,,,,,,,,,,,,,,,,300.119598388672,300.155944824219,-359.995086669922,-359.995086669922,,,7.71608686447144,,1,0,0,0,0.013885498046875,32.2580642700195,1,1,1,300.119750976562,0,2084575040,300.142724609375,,,-0.0358796573470349,0.00179014846122481,-0.0358807900724295,0.00179015018094473,0.97339653968811,0.97457230091095,32.1312103271484,0,35,4,200,-0.000187322468264028,-0.0343938879668713,0.140444308519363,1,,,,,,,,,,,,,,,,
,3889777359.29719,300.076889038086,-309.970977783203,,,6,,,,32.1014785766602,,,1000,,,,,,,,,,,,,,,,,,,,,,300.051696777344,300.100036621094,-309.970977783203,-309.970977783203,,,7.72569990158081,,1,0,0,0,0.013885498046875,32.2580642700195,1,1,1,300.102081298828,0,2084575008,300.084420776367,,,-0.0308996376757906,0.00154167773492774,-0.030900572806274,0.00154167904867422,0.973439753055572,0.974570393562317,32.1306228637695,0,35,4,200,-0.000196614535525441,-0.0299239549785852,0.12086096405983,1,,,,,,,,,,,,,,,,
,3889777474.28821,300.132232666016,-259.885772705078,,,6,,,,32.1014785766602,,,100,,,,,,,,,,,,,,,,,,,,,,300.124084472656,300.1513671875,-259.885772705078,-259.885772705078,,,7.73650932312012,,1,0,0,0,0.013885498046875,33.2355842590332,1,1,1,300.125061035156,0,2084575008,300.140157599198,,,-0.0257580505009339,0.00128514835057696,-0.0257587203441234,0.00128514972504369,0.973434805870056,0.974389970302582,32.1283111572266,0,35,4,200,-0.00146314862649888,-0.2440405189991,1.01152205467224,1,,,,,,,,,,,,,,,,
,3889777588.86099,300.03825378418,-210.069442749023,,,6,,,,32.1014785766602,,,100,,,,,,,,,,,,,,,,,,,,,,300.031066894531,300.051605224609,-210.069442749023,-210.069442749023,,,7.74457168579102,,1,0,0,0,0.013885498046875,32.2580642700195,1,1,1,300.031402587891,0,2084574912,300.043322753906,,,-0.0202977199297542,0.0010127130877496,-0.0202981152012607,0.00101271390685402,0.973529756069183,0.974244058132172,32.1246910095215,0,35,4,200,-0.00192506308667362,-0.197468474507332,0.796030163764954,1,,,,,,,,,,,,,,,,
,3889777704.76882,300.188613891602,-159.996459960938,,,6,,,,32.1014785766602,,,100,,,,,,,,,,,,,,,,,,,,,,300.173370361328,300.210510253906,-159.996459960938,-159.996459960938,,,7.75302934646606,,1,0,0,0,0.013885498046875,32.2580642700195,1,1,1,300.203857421875,0,2084574912,300.198574829102,,,-0.0146908341940233,0.000732978632409707,-0.0146911089732448,0.000732979132161467,0.973042845726013,0.973719418048859,32.1242866516113,0,35,4,200,-0.0017102126730606,-0.145031213760376,0.575576305389404,1,,,,,,,,,,,,,,,,
,3889777817.92325,300.087799072266,-110.033462524414,,,6,,,,32.1014785766602,,,100,,,,,,,,,,,,,,,,,,,,,,300.067749023438,300.109924316406,-110.033462524414,-110.033462524414,,,7.7602014541626,,1,0,0,0,0.013885498046875,32.7468223571777,1,1,1,300.107849121094,0,2084574912,300.098413085938,,,-0.00890800370363682,0.00044446011573395,-0.00890815385971278,0.000444460885291826,0.972402453422546,0.972955644130707,32.1223678588867,,35,4,200,-0.00178121798671782,-0.0913920477032661,0.349297255277634,1,,,,,,,,,,,,,,,,
,3889777933.29062,300.22053527832,-59.9360313415527,,,6,,,,32.1014785766602,,,100,,,,,,,,,,,,,,,,,,,,,,300.216674804687,300.239959716797,-59.9360313415527,-59.9360313415527,,,7.76712512969971,,1,0,0,0,0.013885498046875,32.2580642700195,1,1,1,300.224395751953,0,2084574976,300.229931640625,,,-0.00294434299895489,0.000146933887867088,-0.00294437111286795,0.000146933988731517,0.966309666633606,0.966573417186737,32.1174468994141,0,35,4,200,-0.00173123960848898,-0.038051787763834,0.113314166665077,1,,,,,,,,,,,,,,,,
,3889778056.93534,300.162216186523,-9.91193389892578,,,6,,,,32.1014785766602,,,10,,,,,,,,,,,,,,,,,,,,,,300.143493652344,300.186248779297,-9.91193389892578,-9.91193389892578,,,7.77457237243652,,1,0,0,0,0.013885498046875,32.2580642700195,1,1,1,300.180938720703,0,2084574976,300.173431396484,,,0.00306828102402081,0.000153075557808886,0.00306835301617474,0.000153075689620046,0.976122498512268,0.977088093757629,32.1270790100098,0,35,4,200,-0.0162106435745955,-1.31449794769287,0.229880571365356,1,,,,,,,,,,,,,,,,
,3889778174.05841,300.280792236328,40.0143928527832,,,6,,,,32.1014785766602,,,10,,,,,,,,,,,,,,,,,,,,,,300.270599365234,300.299072265625,40.0143928527832,40.0143928527832,,,7.78172779083252,,1,0,0,0,0.013885498046875,31.7693061828613,1,1,1,300.270202636719,0,2084575008,300.288565063477,,,0.00901979784124831,0.000449999907431128,0.00902000828433669,0.000450000259652678,0.975655734539032,0.976599752902985,32.1270179748535,0,35,4,200,-0.0170743223279715,-3.62786722183228,0.802545607089996,1,,,,,,,,,,,,,,,,
,3889778301.0221,300.130264282227,90.0751571655273,,,6,,,,32.1014785766602,,,100,,,,,,,,,,,,,,,,,,,,,,300.120025634766,300.148040771484,90.0751571655273,90.0751571655273,,,7.78984498977661,,1,0,0,0,0.013885498046875,32.2580642700195,1,1,1,300.140502929687,0,2084575136,300.138534545898,,,0.0148116087954693,0.000738963377502233,0.0148119564318551,0.000738964290539569,0.975190758705139,0.976103186607361,32.1268310546875,5.22988605499268,35,4,200,-0.00162577617447823,-0.591005682945251,0.13665945827961,1,,,,,,,,,,,,,,,,
,3889778417.82987,300.14582824707,140.209243774414,,,6,,,,32.1014785766602,,,100,,,,,,,,,,,,,,,,,,,,,,300.137542724609,300.159851074219,140.209243774414,140.209243774414,,,7.79643297195435,,1,0,0,0,0.013885498046875,32.2580642700195,1,1,1,300.154113769531,0,2084575072,300.151556396484,,,0.0204413170996172,0.00101984788589804,0.0204418958539092,0.00101984838324751,0.974648535251617,0.975770235061646,32.1298370361328,0,35,4,200,-0.00173222494777292,-0.811157703399658,0.186148539185524,1,,,,,,,,,,,,,,,,
,3889778531.71645,300.072280883789,190.257797241211,,,6,,,,32.1014785766602,,,100,,,,,,,,,,,,,,,,,,,,,,300.050903320313,300.090698242188,190.257797241211,190.257797241211,,,7.80274534225464,,1,0,0,0,0.013885498046875,32.2580642700195,1,1,1,300.093658447266,0,2084574912,300.079809570312,,,0.0258465315781326,0.00128952831676784,0.025847329626719,0.00128952906533066,0.974471807479858,0.975686728954315,32.1310691833496,5.22975206375122,35,4,200,-0.00193753920029849,-1.0224289894104,0.236569732427597,1,,,,,,,,,,,,,,,,
,3889778648.53479,300.121398925781,240.123016357422,,,6,,,,32.1014785766602,,,100,,,,,,,,,,,,,,,,,,,,,,300.108825683594,300.140930175781,240.123016357422,240.123016357422,,,7.80935096740723,,1,0,0,0,0.013885498046875,32.2580642700195,1,1,1,300.133972167969,0,2084575104,300.130487060547,,,0.0309978448207855,0.00154654704431041,0.0309988713004551,0.00154654919454533,0.974190831184387,0.975449919700623,32.1317558288574,0,35,4,200,-0.00176213658414781,-1.22594940662384,0.283662796020508,1,,,,,,,,,,,,,,,,
,3889778765.19164,300.247085571289,290.208221435547,,,6,,,,32.1014785766602,,,100,,,,,,,,,,,,,,,,,,,,,,300.238586425781,300.270233154297,290.208221435547,290.208221435547,,,7.81571531295776,,1,0,0,0,0.013885498046875,32.2580642700195,1,1,1,300.255584716797,0,2084575136,300.258093261719,,,0.0359703239197415,0.00179465086545593,0.0359717927496246,0.00179465516547322,0.973842680454254,0.975354909896851,32.1348037719727,5.2298583984375,35,4,200,-0.00185706943739206,-1.42825472354889,0.321842074394226,1,,,,,,,,,,,,,,,,
,3889778883.49003,300.175140380859,340.281219482422,,,6,,,,32.1014785766602,,,100,,,,,,,,,,,,,,,,,,,,,,300.154724121094,300.196044921875,340.281219482422,340.281219482422,,,7.82033014297485,,1,0,0,0,0.013885498046875,32.2580642700195,1,1,1,300.154235839844,0,2084574912,300.181170654297,,,0.040762630253585,0.00203374903779092,0.0407641868202072,0.00203375122913464,0.973883330821991,0.975344121456146,32.134220123291,0,35,4,200,-0.00199953885748982,-1.61752915382385,0.375786244869232,1,,,,,,,,,,,,,,,,
,3889779002.13672,300.126739501953,390.341979980469,,,6,,,,32.1014785766602,,,100,,,,,,,,,,,,,,,,,,,,,,300.113494873047,300.147827148438,390.341979980469,390.341979980469,,,7.82504081726074,,1,0,0,0,0.013885498046875,32.2580642700195,1,1,1,300.139984130859,0,2084574912,300.137170410156,,,0.0453145370978218,0.00226087143702549,0.0453165145045041,0.00226087438475205,0.973597347736359,0.975251436233521,32.1364479064941,1,35,4,200,-0.00165506149642169,-1.79033207893372,0.414297372102737,1,,,,,,,,,,,,,,,,
,3889779116.33879,300.077362060547,440.109405517578,,,6,,,,32.1014785766602,,,100,,,,,,,,,,,,,,,,,,,,,,300.063201904297,300.093688964844,440.109405517578,440.109405517578,,,7.82993364334106,,1,0,0,0,0.013885498046875,32.2580642700195,1,1,1,300.063751220703,0,2084574912,300.0826171875,,,0.049672011790568,0.00247827612967103,0.0496740923468368,0.00247827786778868,0.973639786243439,0.975250363349914,32.1359748840332,,35,4,200,-0.00188842392526567,-1.96411037445068,0.451869517564774,1,,,,,,,,,,,,,,,,
,3889779232.27465,300.095687866211,490.145721435547,,,6,,,,32.1014785766602,,,100,,,,,,,,,,,,,,,,,,,,,,300.082672119141,300.110260009766,490.145721435547,490.145721435547,,,7.83558893203735,,1,0,0,0,0.013885498046875,32.2580642700195,1,1,1,300.108703613281,0,2084575040,300.101733398438,,,0.0538289471116219,0.00268569912341491,0.0538315157850557,0.00268570089367915,0.973329484462738,0.975155234336853,32.1383514404297,0,35,4,200,-0.00200094212777913,-2.12560939788818,0.491084069013596,1,,,,,,,,,,,,,,,,
,3889779348.96629,300.16487121582,540.2431640625,,,6,,,,32.1014785766602,,,100,,,,,,,,,,,,,,,,,,,,,,300.151763916016,300.182037353516,540.2431640625,540.2431640625,,,7.84065246582031,,1,0,0,0,0.0002288818359375,32.2580642700195,1,1,1,300.151428222656,0,2084575008,300.170620727539,,,0.0577836634959016,0.00288302435562046,0.0577866920628296,0.00288302992427777,0.973179161548615,0.975130975246429,32.1396636962891,0,35,4,200,-0.0020880673546344,-2.28957986831665,0.529609620571136,1,,,,,,,,,,,,,,,,
,3889779462.77362,300.100372314453,590.303955078125,,,6,,,,32.1014785766602,,,100,,,,,,,,,,,,,,,,,,,,,,300.093444824219,300.115081787109,590.303955078125,590.303955078125,,,7.84574317932129,,1,0,0,0,0,31.7693061828613,1,1,1,300.093902587891,0,2084575168,300.106115722656,,,0.0615590865110049,0.00307138942267345,0.0615622768372621,0.00307139579939503,0.973219633102417,0.975145220756531,32.1393852233887,7.09112555341562E-6,35,4,200,-0.00261450838297606,-2.43433618545532,0.56570702791214,1,,,,,,,,,,,,,,,,
,3889779578.1395,300.053939819336,640.376892089844,,,6,,,,32.1014785766602,,,100,,,,,,,,,,,,,,,,,,,,,,300.048370361328,300.066986083984,640.376892089844,640.376892089844,,,7.85027456283569,,1,0,0,0,0.013885498046875,32.2580642700195,1,1,1,300.049560546875,0,2084574912,300.058740234375,,,0.0651454307666721,0.00325032397379065,0.0651486622257793,0.00325032493859163,0.973221600055695,0.9751296043396,32.1392211914063,0.305964887142181,35,4,200,-0.00299941911362112,-2.57422375679016,0.59971809387207,1,,,,,,,,,,,,,,,,
,3889779695.11841,300.160629272461,690.30322265625,,,6,,,,32.1014785766602,,,100,,,,,,,,,,,,,,,,,,,,,,300.144683837891,300.176635742188,690.30322265625,690.30322265625,,,7.85464239120483,,1,0,0,0,0.013885498046875,33.2355842590332,1,1,1,300.144622802734,0,2084575072,300.164993286133,,,0.0675755134381325,0.00337165704083488,0.0675790607765896,0.00337166293171734,0.972269117832184,0.974162340164185,32.1397552490234,5.22938871383667,35,4,200,0.00399879273027182,-2.66007447242737,0.679573118686676,1,,,,,,,,,,,,,,,,
,3889779812.42109,300.111679077148,740.302917480469,,,6,,,,32.1014785766602,,,100,,,,,,,,,,,,,,,,,,,,,,300.101684570313,300.126617431641,740.302917480469,740.302917480469,,,7.85862064361572,,1,0,0,0,0,31.7693061828613,1,1,1,300.121673583984,0,2084574944,300.118423461914,,,0.0717131704051553,0.00357805626080142,0.0717174162136118,0.00357805686311934,0.972759187221527,0.975018560886383,32.1427726745605,0,35,4,200,-0.00323283928446472,-2.83472371101379,0.656047821044922,1,,,,,,,,,,,,,,,,
,3889779931.45434,300.206024169922,790.485900878906,,,6,,,,32.1014785766602,,,100,,,,,,,,,,,,,,,,,,,,,,300.187927246094,300.224182128906,790.485900878906,790.485900878906,,,7.86285209655762,,1,0,0,0,0.013885498046875,32.2580642700195,1,1,1,300.187866210937,0,2084574944,300.211233520508,,,0.0747575242047436,0.00372995687634893,0.0747623043386493,0.00372996548969516,0.972691774368286,0.975048780441284,32.1436729431152,0,35,4,200,-0.00325831118971109,-2.9567813873291,0.681477665901184,1,,,,,,,,,,,,,,,,
,3889780074.43615,300.149047851562,2500.25170898438,,,6,,,,32.1014785766602,,,100,,,,,,,,,,,,,,,,,,,,,,300.146362304687,300.170928955078,2500.25170898438,2500.25170898438,,,7.86790704727173,,1,0,0,0,0.013885498046875,31.7693061828613,1,1,1,300.151733398438,0,2084574944,300.159341430664,,,0.117735707948243,0.00587442247244073,0.117744007793669,0.00587444147873363,0.972023189067841,0.974538624286652,32.1455459594727,5.66970443725586,35,4,200,0.000239361834246665,-4.63492441177368,1.08469378948212,1,,,,,,,,,,,,,,,,
,3889780225.85983,300.078308105469,5000.271484375,,,6,,,,32.1014785766602,,,1000,,,,,,,,,,,,,,,,,,,,,,300.061187744141,300.096099853516,5000.271484375,5000.271484375,,,7.87294960021973,,1,0,0,0,0.013885498046875,31.7693061828613,1,1,1,300.061340332031,0,2084574880,300.083993530273,,,0.127372303959544,0.006355187171451,0.127379935024709,0.0063551979544444,0.972318232059479,0.974506139755249,32.1424789428711,3.83190369606018,35,4,200,0.000166599900694564,-0.502257585525513,0.117334805428982,1,,,,,,,,,,,,,,,,
,3889780365.9326,299.938751220703,7500.40087890625,,,6,,,,32.1014785766602,,,1000,,,,,,,,,,,,,,,,,,,,,,299.929016113281,299.953552246094,7500.40087890625,7500.40087890625,,,7.87743425369263,,1,0,0,0,0.013885498046875,32.2580642700195,1,1,1,299.929565429687,0,2084575040,299.94423828125,,,0.130167851916573,0.0064946514746464,0.130174677447277,0.00649465572906174,0.972424805164337,0.974369823932648,32.1401443481445,,35,4,200,0.000287282047793269,-0.512430787086487,0.120306082069874,1,,,,,,,,,,,,,,,,
,3889780513.66241,300.238830566406,10000.212890625,,,6,,,,32.1014785766602,,,1000,,,,,,,,,,,,,,,,,,,,,,300.226898193359,300.261535644531,10000.212890625,10000.212890625,,,7.88300657272339,,1,0,0,0,0.013885498046875,32.2580642700195,1,1,1,300.250762939453,0,2084574944,300.25055847168,,,0.131463193164772,0.00655934311560787,0.131471023524228,0.00655935430795067,0.972080945968628,0.974234759807587,32.1423454284668,5.6694221496582,35,4,200,0.000198243171325885,-0.517791986465454,0.120734602212906,1,,,,,,,,,,,,,,,,
,3889780665.75793,300.021499633789,35000.26171875,,,6,,,,32.1014785766602,,,1000,,,,,,,,,,,,,,,,,,,,,,300.018615722656,300.035095214844,35000.26171875,35000.26171875,,,7.88704586029053,,1,0,0,0,0.013885498046875,31.7693061828613,1,1,1,300.024383544922,0,2084574880,300.027743530273,,,0.134756029855905,0.00672391200643662,0.134765552191472,0.00672392179431261,0.970676779747009,0.973138332366943,32.1461601257324,9.35266234591836E-6,35,4,200,0.000250513228820637,-0.530335187911987,0.125897988677025,1,,,,,,,,,,,,,,,,
,3889780816.41703,300.054489135742,60000.25,,,6,,,,32.1014785766602,,,1000,,,,,,,,,,,,,,,,,,,,,,300.048309326172,300.071197509766,60000.25,60000.25,,,7.89253854751587,,1,0,0,0,0.013885498046875,31.2805480957031,1,1,1,300.060668945313,0,2084575008,300.062240600586,,,0.135710658022149,0.00677209077892186,0.13572707086003,0.00677211162666835,0.968038737773895,0.971963822841644,32.1597633361816,0,35,4,200,0.000291121221380308,-0.533304572105408,0.12827143073082,1,,,,,,,,,,,,,,,,
,3889780970.29737,300.160552978516,55000.36328125,,,6,,,,32.1014785766602,,,1000,,,,,,,,,,,,,,,,,,,,,,300.144775390625,300.183532714844,55000.36328125,55000.36328125,,,7.89717292785645,,1,0,0,0,0.013885498046875,31.7693061828613,1,1,1,300.176330566406,0,2084574816,300.172442626953,,,0.135547578713213,0.00676377253924705,0.135561196277196,0.00676377978085442,0.968886256217956,0.97226083278656,32.1550140380859,0.191232830286026,35,4,200,-0.000172828891663812,-0.533650994300842,0.127057209610939,1,,,,,,,,,,,,,,,,
,3889781125.16681,300.05680847168,30000.18359375,,,6,,,,32.1014785766602,,,1000,,,,,,,,,,,,,,,,,,,,,,300.035034179687,300.076416015625,30000.18359375,30000.18359375,,,7.90128946304321,,1,0,0,0,0.013885498046875,32.2580642700195,1,1,1,300.078582763672,0,2084574720,300.064794921875,,,0.134466751743974,0.00670935984085398,0.13447515120402,0.00670937256358446,0.971274435520172,0.973464787006378,32.1432838439941,4.58302929473575E-5,35,4,200,-0.000256614439422265,-0.530260145664215,0.124585337936878,1,,,,,,,,,,,,,,,,
,3889781285.86785,300.193450927734,9500.3251953125,,,6,,,,32.1014785766602,,,1000,,,,,,,,,,,,,,,,,,,,,,300.192108154297,300.214141845703,9500.3251953125,9500.3251953125,,,7.90575361251831,,1,0,0,0,0.013885498046875,32.7468223571777,1,1,1,300.194793701172,0,2084574944,300.203485107422,,,0.131253266815774,0.00654881062118646,0.131260274720987,0.00654881707269391,0.972396194934845,0.974363446235657,32.1403770446777,,35,4,200,-0.000504984869621694,-0.517946124076843,0.120335452258587,1,,,,,,,,,,,,,,,,
,3889781428.8851,300.262619018555,7000.40380859375,,,6,,,,32.1014785766602,,,1000,,,,,,,,,,,,,,,,,,,,,,300.261810302734,300.285217285156,7000.40380859375,7000.40380859375,,,7.9102840423584,,1,0,0,0,0.013885498046875,32.7468223571777,1,1,1,300.262512207031,0,2084575104,300.273941040039,,,0.129714671824096,0.0064720575564722,0.129722222174684,0.00647206971826745,0.972330570220947,0.974445641040802,32.1418075561523,,35,4,200,-0.000266319286311045,-0.512306213378906,0.118230164051056,1,,,,,,,,,,,,,,,,
,3889781573.03937,300.167739868164,4500.103515625,,,6,,,,32.1014785766602,,,1000,,,,,,,,,,,,,,,,,,,,,,300.16162109375,300.186065673828,4500.103515625,4500.103515625,,,7.91355657577515,,1,0,0,0,0.013885498046875,32.7468223571777,1,1,1,300.173858642578,0,2084574848,300.176705932617,,,0.126291941409947,0.00630129314875637,0.126299717300142,0.00630129944804769,0.972262144088745,0.974537551403046,32.1432991027832,0,35,4,200,-0.00027082723681815,-0.498918175697327,0.114963829517365,1,,,,,,,,,,,,,,,,
,3889781714.52258,300.01335144043,2000.32849121094,,,6,,,,32.1014785766602,,,1000,,,,,,,,,,,,,,,,,,,,,,300.009613037109,300.027893066406,2000.32849121094,2000.32849121094,,,7.91672611236572,,1,0,0,0,0.013885498046875,31.7693061828613,1,1,1,300.01708984375,0,2084575040,300.020031738281,,,0.11148293161006,0.00556241649341673,0.111490467091059,0.00556242528712924,0.972173750400543,0.974654853343964,32.1451377868652,0,35,4,200,-0.000254163256613538,-0.440396398305893,0.1017075330019,1,,,,,,,,,,,,,,,,
,3889781853.57613,300.054306030273,779.926208496094,,,6,,,,32.1014785766602,,,1000,,,,,,,,,,,,,,,,,,,,,,300.037109375,300.070648193359,779.926208496094,779.926208496094,,,7.91978693008423,,1,0,0,0,0.013885498046875,33.2355842590332,1,1,1,300.071502685547,0,2084574944,300.060955810547,,,0.0698463922298933,0.00348492813218052,0.0698503816715566,0.00348493396279188,0.972607731819153,0.974711120128632,32.141487121582,,35,4,200,-1.93091400433332E-5,-0.275885909795761,0.0634304061532021,1,,,,,,,,,,,,,,,,
,3889781973.17803,300.167373657227,730.060974121094,,,6,,,,32.1014785766602,,,1000,,,,,,,,,,,,,,,,,,,,,,300.165222167969,300.189483642578,730.060974121094,730.060974121094,,,7.92309093475342,,1,0,0,0,0.013885498046875,32.7468223571777,1,1,1,300.165679931641,0,2084574944,300.177145385742,,,0.0665334975689574,0.00331964096779497,0.0665373084758376,0.0033196447232048,0.972541511058807,0.974667072296143,32.1417388916016,0.078764796257019,35,4,200,0.000155740766786039,-0.262596815824509,0.0611380450427532,1,,,,,,,,,,,,,,,,
,3889782086.18955,300.184127807617,680.049133300781,,,6,,,,32.1014785766602,,,1000,,,,,,,,,,,,,,,,,,,,,,300.172882080078,300.205902099609,680.049133300781,680.049133300781,,,7.9260778427124,,1,0,0,0,0.013885498046875,32.7468223571777,1,1,1,300.195373535156,0,2084574944,300.19453125,,,0.0630211793866017,0.00314438922593602,0.0630246311801044,0.00314439364051782,0.972627103328705,0.974650084972382,32.1407356262207,5.66928005218506,35,4,200,0.000165811798069626,-0.248545825481415,0.0580883473157883,1,,,,,,,,,,,,,,,,
,3889782206.59739,300.191711425781,630.281677246094,,,6,,,,32.1014785766602,,,1000,,,,,,,,,,,,,,,,,,,,,,300.186431884766,300.210815429687,630.281677246094,630.281677246094,,,7.92878341674805,,1,0,0,0,0.013885498046875,32.7468223571777,1,1,1,300.199096679687,0,2084575104,300.202328152127,,,0.0593427433088119,0.00296085218260997,0.0593459624203961,0.00296085701699764,0.972679555416107,0.974676966667175,32.140453338623,0,35,4,200,0.000163862758199684,-0.234474897384644,0.0540935322642326,1,,,,,,,,,,,,,,,,
,3889782327.59072,300.232940673828,580.257568359375,,,6,,,,32.1014785766602,,,1000,,,,,,,,,,,,,,,,,,,,,,300.232543945313,300.251922607422,580.257568359375,580.257568359375,,,7.9318208694458,,1,0,0,0,0.013885498046875,32.2580642700195,1,1,1,300.233337402344,0,2084575168,300.242163085937,,,0.0554519796181244,0.00276672355208184,0.0554548674659006,0.00276672670567253,0.972712278366089,0.974646210670471,32.1398315429687,0,35,4,200,0.000177475056261756,-0.219037249684334,0.0507104620337486,1,,,,,,,,,,,,,,,,
,3889782441.06051,300.040466308594,530.209045410156,,,6,,,,32.1014785766602,,,1000,,,,,,,,,,,,,,,,,,,,,,300.021667480469,300.059478759766,530.209045410156,530.209045410156,,,7.93459415435791,,1,0,0,0,0.013885498046875,32.2580642700195,1,1,1,300.021453857422,0,2084574944,300.043838500977,,,0.0513813846767524,0.00256361009614011,0.0513836825964397,0.00256361114981028,0.972934186458588,0.974622905254364,32.1372489929199,0,35,4,200,0.000192891719052568,-0.203104645013809,0.046922605484724,1,,,,,,,,,,,,,,,,
,3889782554.29879,300.062454223633,480.160491943359,,,6,,,,32.1014785766602,,,1000,,,,,,,,,,,,,,,,,,,,,,300.048248291016,300.075012207031,480.160491943359,480.160491943359,,,7.936851978302,,1,0,0,0,0.013885498046875,32.7468223571777,1,1,1,300.049896240234,0,2084574944,300.064782714844,,,0.0471062231647512,0.0023503024437406,0.0471083337571574,0.00235030620090615,0.972992479801178,0.974641501903534,32.1368026733398,0,35,4,200,0.000199086978682317,-0.186134919524193,0.0431495569646358,1,,,,,,,,,,,,,,,,
,3889782664.55314,300.197708129883,430.063018798828,,,6,,,,32.1014785766602,,,1000,,,,,,,,,,,,,,,,,,,,,,300.170318603516,300.225250244141,430.063018798828,430.063018798828,,,7.93962240219116,,1,0,0,0,0.013885498046875,32.7468223571777,1,1,1,300.170166015625,0,2084574976,300.201452636719,,,0.0425944832646372,0.00212519215184828,0.0425962531014278,0.00212519445721495,0.973045110702515,0.97458952665329,32.1356620788574,0.0383420437574387,35,4,200,0.000195154992979951,-0.168351411819458,0.0390534177422524,1,,,,,,,,,,,,,,,,
,3889782774.78386,300.078887939453,380.051177978516,,,6,,,,32.1014785766602,,,1000,,,,,,,,,,,,,,,,,,,,,,300.062164306641,300.097717285156,380.051177978516,380.051177978516,,,7.94186544418335,,1,0,0,0,0.013885498046875,32.7468223571777,1,1,1,300.095611572266,0,2084574912,300.08825378418,,,0.0379356086032497,0.00189273803029861,0.0379370813230125,0.00189274066225824,0.973167538642883,0.974599778652191,32.1343574523926,5.66871738433838,35,4,200,0.000168200494954362,-0.150224179029465,0.034616231918335,1,,,,,,,,,,,,,,,,
,3889782893.20212,300.142730712891,330.075958251953,,,6,,,,32.1014785766602,,,1000,,,,,,,,,,,,,,,,,,,,,,300.134246826172,300.162750244141,330.075958251953,330.075958251953,,,7.9444465637207,,1,0,0,0,0.013885498046875,32.2580642700195,1,1,1,300.151214599609,0,2084575008,300.152221679687,,,0.0330316554514348,0.00164806229373984,0.0330328975441766,0.00164806416516756,0.973181009292602,0.974576056003571,32.1339302062988,,35,4,200,0.000183689364348538,-0.130590066313744,0.0303873904049397,1,,,,,,,,,,,,,,,,
,3889783005.652,300.046127319336,279.990753173828,,,6,,,,32.1014785766602,,,1000,,,,,,,,,,,,,,,,,,,,,,300.035858154297,300.060821533203,279.990753173828,279.990753173828,,,7.94690418243408,,1,0,0,0,0.013885498046875,32.7468223571777,1,1,1,300.036437988281,0,2084574400,300.051376342773,,,0.0279147748368016,0.00139275958760728,0.0279156393363081,0.00139276122392636,0.973276913166046,0.974415302276611,32.1308097839355,0,35,4,200,0.000198025998543017,-0.110485091805458,0.0256485305726528,1,,,,,,,,,,,,,,,,
,3889783123.61986,299.979949951172,229.917770385742,,,6,,,,32.1014785766602,,,100,,,,,,,,,,,,,,,,,,,,,,299.954498291016,300.003631591797,229.917770385742,229.917770385742,,,7.94928884506226,,1,0,0,0,0.013885498046875,32.2580642700195,1,1,1,300.005401611328,0,2084574912,299.98740234375,,,0.0225707754504236,0.00112613142277802,0.02257142868742,0.00112613177349953,0.973227620124817,0.974318444728851,32.1302299499512,0,35,4,200,0.00185590330511332,-0.892101526260376,0.210136279463768,1,,,,,,,,,,,,,,,,
,3889783239.31485,300.179077148438,180.199203491211,,,6,,,,32.1014785766602,,,100,,,,,,,,,,,,,,,,,,,,,,300.154907226562,300.202819824219,180.199203491211,180.199203491211,,,7.95146036148071,,1,0,0,0,0.013885498046875,33.2355842590332,1,1,1,300.155334472656,0,2084574976,300.183096313477,,,0.017067793838679,0.000851572978824654,0.0170682400820539,0.000851573475584803,0.973076999187469,0.974043130874634,32.1286430358887,5.00731330248527E-5,35,4,200,0.00184387259650975,-0.676236391067505,0.158854097127914,1,,,,,,,,,,,,,,,,
,3889783351.35152,300.137222290039,130.162872314453,,,6,,,,32.1014785766602,,,100,,,,,,,,,,,,,,,,,,,,,,300.121765136719,300.157623291016,130.162872314453,130.162872314453,,,7.95404100418091,,1,0,0,0,0.013885498046875,32.7468223571777,1,1,1,300.152679443359,0,2084575104,300.147546386719,,,0.0113677828966054,0.000567187155183649,0.0113680306729028,0.000567187047916201,0.972555994987488,0.973368525505066,32.1266708374023,,35,4,200,0.00173034274484962,-0.451050370931625,0.107692182064056,1,,,,,,,,,,,,,,,,
,3889783463.04454,300.135208129883,80.0654449462891,,,6,,,,32.1014785766602,,,100,,,,,,,,,,,,,,,,,,,,,,300.113128662109,300.154907226562,80.0654449462891,80.0654449462891,,,7.95656681060791,,1,0,0,0,0.013885498046875,32.2580642700195,1,1,1,300.157287597656,0,2084574976,300.143560791016,,,0.00543548114536842,0.000271217101341425,0.00543558599006724,0.000271217326430587,0.97025853395462,0.970885276794434,32.1245460510254,,35,4,200,0.00185502879321575,-0.210337892174721,0.0600093677639961,1,,,,,,,,,,,,,,,,
,3889783587.19599,300.207000732422,30.0902366638184,,,6,,,,32.1014785766602,,,10,,,,,,,,,,,,,,,,,,,,,,300.195587158203,300.22802734375,30.0902366638184,30.0902366638184,,,7.95911550521851,,1,0,0,0,0.013885498046875,32.2580642700195,1,1,1,300.218414306641,0,2084575040,300.217700195313,,,-0.000560985071071671,2.80382549593587E-5,-0.000561036579071593,2.80383312880322E-5,0.935235679149628,0.936620473861694,32.152759552002,0,35,4,200,0.0163087751716375,-0.039223600178957,0.285000920295715,1,,,,,,,,,,,,,,,,
,3889783698.43231,300.013000488281,-19.9705295562744,,,6,,,,32.1014785766602,,,10,,,,,,,,,,,,,,,,,,,,,,299.994750976562,300.030792236328,-19.9705295562744,-19.9705295562744,,,7.96038961410522,,1,0,0,0,0.013885498046875,31.7693061828613,1,1,1,299.995208740234,0,2084574976,300.016757202148,,,-0.00656095784843596,0.00032732813830166,-0.00656112763365202,0.000327328325955733,0.975612103939056,0.976672172546387,32.1285400390625,2.36835494433762E-5,35,4,200,0.0178539026528597,-0.634530484676361,2.64735722541809,1,,,,,,,,,,,,,,,,
,3889783816.36641,300.121948242188,-70.0190734863281,,,6,,,,32.1014785766602,,,10,,,,,,,,,,,,,,,,,,,,,,300.111114501953,300.140289306641,-70.0190734863281,-70.0190734863281,,,7.96303367614746,,1,0,0,0,0.013885498046875,31.7693061828613,1,1,1,300.132781982422,0,2084574976,300.13030090332,,,-0.0124176491938399,0.000619525454377558,-0.0124179898482973,0.000619526206358709,0.975281178951263,0.976364970207214,32.1290092468262,,35,4,200,0.0165968537330627,-1.17767512798309,4.9421968460083,1,,,,,,,,,,,,,,,,
,3889783942.68175,300.076522827148,-120.043174743652,,,6,,,,32.1014785766602,,,100,,,,,,,,,,,,,,,,,,,,,,300.061340332031,300.095306396484,-120.043174743652,-120.043174743652,,,7.96499347686768,,1,0,0,0,0.013885498046875,32.2580642700195,1,1,1,300.091705322266,0,2084574912,300.085620117188,,,-0.0181134368867322,0.000903706626484988,-0.0181140026967879,0.000903707621666177,0.974653124809265,0.975870549678802,32.1309928894043,0,35,4,200,0.00174647103995085,-0.16683554649353,0.717137098312378,1,,,,,,,,,,,,,,,,
,3889784056.0639,300.036636352539,-170.079498291016,,,6,,,,32.1014785766602,,,100,,,,,,,,,,,,,,,,,,,,,,300.015777587891,300.057495117188,-170.079498291016,-170.079498291016,,,7.96714401245117,,1,0,0,0,0.013885498046875,32.2580642700195,1,1,1,300.015777587891,0,2084574976,300.038641357422,,,-0.0236198470754226,0.00117843419094344,-0.0236205879120649,0.00117843539927518,0.9744912981987,0.975709021091461,32.1310882568359,,35,4,200,0.00183806789573282,-0.217535644769669,0.933785498142242,1,,,,,,,,,,,,,,,,
,3889784169.52354,299.990264892578,-220.103607177734,,,6,,,,32.1014785766602,,,100,,,,,,,,,,,,,,,,,,,,,,299.983123779297,300.003814697266,-220.103607177734,-220.103607177734,,,7.96850204467773,,1,0,0,0,0.013885498046875,31.7693061828613,1,1,1,299.983306884766,0,2084574944,299.995336914062,,,-0.0289042454652864,0.0014420927323329,-0.0289052728458567,0.00144209459366477,0.974196016788483,0.975558578968048,32.1329383850098,0,35,4,200,0.00208379444666207,-0.266718804836273,1.14000952243805,1,,,,,,,,,,,,,,,,
,3889784287.68485,300.160720825195,-270.066589355469,,,6,,,,32.1014785766602,,,100,,,,,,,,,,,,,,,,,,,,,,300.150329589844,300.174896240234,-270.066589355469,-270.066589355469,,,7.97133493423462,,1,0,0,0,0.013885498046875,32.2580642700195,1,1,1,300.150329589844,0,2084574976,300.165875244141,,,-0.0339539996136765,0.00169405547505938,-0.0339554916673804,0.00169405795800796,0.973744630813599,0.975414514541626,32.1365127563477,6.61920921629644E-6,35,4,200,0.00193613220471889,-0.316197723150253,1.3467093706131,1,,,,,,,,,,,,,,,,
,3889784402.82543,300.139175415039,-319.992919921875,,,6,,,,32.1014785766602,,,100,,,,,,,,,,,,,,,,,,,,,,300.123413085937,300.156585693359,-319.992919921875,-319.992919921875,,,7.97326183319092,,1,0,0,0,0.00152587890625,32.2580642700195,1,1,1,300.154937744141,0,2084575008,300.146279907227,,,-0.0388003725603109,0.00193586701738569,-0.038802296407703,0.00193587035313314,0.973473489284515,0.975342333316803,32.1386642456055,5.66909742355347,35,4,200,0.00200052768923342,-0.361323952674866,1.53692877292633,1,,,,,,,,,,,,,,,,
,3889784518.2132,300.070449829102,-369.992553710937,,,6,,,,32.1014785766602,,,100,,,,,,,,,,,,,,,,,,,,,,300.047027587891,300.093872070313,-369.992553710937,-369.992553710937,,,7.97516679763794,,1,0,0,0,0.013885498046875,31.7693061828613,1,1,1,300.047027587891,0,2084574976,300.073529052734,,,-0.0434478883747301,0.00216774701151344,-0.0434499339939678,0.00216774861703283,0.973455011844635,0.975260972976685,32.138069152832,6.88873569743009E-6,35,4,200,0.00195740023627877,-0.399343013763428,1.7137439250946,1,,,,,,,,,,,,,,,,
,3889784632.60053,300.196533203125,-420.041107177734,,,6,,,,32.1014785766602,,,100,,,,,,,,,,,,,,,,,,,,,,300.189086914063,300.217193603516,-420.041107177734,-420.041107177734,,,7.97764825820923,,1,0,0,0,0.013885498046875,32.2580642700195,1,1,1,300.203979492188,0,2084574912,300.207208251953,,,-0.0478646569467277,0.00238813691523447,-0.0478673848991448,0.00238814176754983,0.973093211650848,0.97521835565567,32.1413230895996,0,35,4,200,0.00172019528690726,-0.439156174659729,1.88939869403839,1,,,,,,,,,,,,,,,,
,3889784749.1355,300.10514831543,-469.991882324219,,,6,,,,32.1014785766602,,,100,,,,,,,,,,,,,,,,,,,,,,300.093109130859,300.123046875,-469.991882324219,-469.991882324219,,,7.9798059463501,,1,0,0,0,0.013885498046875,32.2580642700195,1,1,1,300.1171875,0,2084574944,300.113815307617,,,-0.0521072433216826,0.00259981590200595,-0.0521101184488043,0.00259981943326572,0.973073244094849,0.97515070438385,32.1409111022949,0,35,4,200,0.00175155466422439,-0.482039898633957,2.05189251899719,1,,,,,,,,,,,,,,,,
,3889784863.14462,300.128494262695,-520.003784179687,,,6,,,,32.1014785766602,,,100,,,,,,,,,,,,,,,,,,,,,,300.126068115234,300.143524169922,-520.003784179687,-520.003784179687,,,7.98161697387695,,1,0,0,0,0.013885498046875,31.7693061828613,1,1,1,300.126983642578,0,2084574912,300.134838867188,,,-0.0561554216425153,0.00280179159732008,-0.0561585234663422,0.00280179842043201,0.973095238208771,0.9751335978508,32.1405334472656,7.22373442840762E-6,35,4,200,0.00200636917725205,-0.515599727630615,2.21388673782349,1,,,,,,,,,,,,,,,,
,3889784981.07444,300.140487670898,-569.97900390625,,,6,,,,32.1014785766602,,,100,,,,,,,,,,,,,,,,,,,,,,300.116485595703,300.164581298828,-569.97900390625,-569.97900390625,,,7.98318672180176,,1,0,0,0,0.013885498046875,32.2580642700195,1,1,1,300.116394042969,0,2084575008,300.144207763672,,,-0.0600095083724898,0.00299410012996277,-0.0600129737287209,0.00299410196657995,0.972920656204224,0.975118160247803,32.1421012878418,5.66940069198608,35,4,200,0.0021835130173713,-0.548540651798248,2.36764931678772,1,,,,,,,,,,,,,,,,
,3889785098.52753,300.19743347168,-620.039733886719,,,6,,,,32.1014785766602,,,100,,,,,,,,,,,,,,,,,,,,,,300.187683105469,300.217498779297,-620.039733886719,-620.039733886719,,,7.98514652252197,,1,0,0,0,0.013885498046875,32.2580642700195,1,1,1,300.207183837891,0,2084574880,300.207183837891,,,-0.0636499621410707,0.00317575900284235,-0.0636541126053313,0.00317576037990375,0.97265750169754,0.975137233734131,32.1447334289551,0,35,4,200,0.00261586741544306,-0.584473669528961,2.51750516891479,1,,,,,,,,,,,,,,,,
,3889785217.01255,300.191329956055,-670.100463867187,,,6,,,,32.1014785766602,,,100,,,,,,,,,,,,,,,,,,,,,,300.179260253906,300.2138671875,-670.100463867187,-670.100463867187,,,7.98742389678955,,1,0,0,0,0.013885498046875,31.2805480957031,1,1,1,300.203399658203,0,2084575072,300.202603149414,,,-0.0671167990722499,0.00334874237177306,-0.0671213127033917,0.00334874811113128,0.972564995288849,0.975066065788269,32.1449851989746,7.67529581935378E-6,35,4,200,0.00288859661668539,-0.618106663227081,2.65123534202576,1,,,,,,,,,,,,,,,,
,3889785337.35418,300.211578369141,-720.0634765625,,,6,,,,32.1014785766602,,,100,,,,,,,,,,,,,,,,,,,,,,300.203552246094,300.230987548828,-720.0634765625,-720.0634765625,,,7.98938655853271,,1,0,0,0,0.013885498046875,32.2580642700195,1,1,1,300.219604492188,0,2084575104,300.221392822266,,,-0.0704070180709484,0.00351291019758164,-0.0704118552464239,0.00351291740264145,0.97251284122467,0.975053310394287,32.1453552246094,0,35,4,200,0.0031059558968991,-0.645364940166473,2.78227829933166,1,,,,,,,,,,,,,,,,
,3889785450.54517,300.037506103516,-770.124267578125,,,6,,,,32.1014785766602,,,100,,,,,,,,,,,,,,,,,,,,,,300.015869140625,300.058746337891,-770.124267578125,-770.124267578125,,,7.99101829528809,,1,0,0,0,0.013885498046875,32.2580642700195,1,1,1,300.016265869141,0,2084574976,300.040826416016,,,-0.0735629830346768,0.00367036043126393,-0.0735677730805332,0.00367036750903304,0.972660422325134,0.975076675415039,32.1442031860352,,35,4,200,0.00335175450891256,-0.674103915691376,2.90571618080139,1,,,,,,,,,,,,,,,,
,3889785583.60671,300.169830322266,-1499.623046875,,,6,,,,32.1014785766602,,,1000,,,,,,,,,,,,,,,,,,,,,,300.161254882812,300.189025878906,-1499.623046875,-1499.623046875,,,7.99301767349243,,1,0,0,0,0.013885498046875,31.7693061828613,1,1,1,300.178405761719,0,2084574912,300.178927612305,,,-0.102997340496537,0.00513910284504188,-0.103006174653186,0.00513912283452992,0.971667170524597,0.974719285964966,32.1501007080078,0,35,4,200,0.000127020219224505,-0.0954525098204613,0.405795216560364,1,,,,,,,,,,,,,,,,
,3889785701.6321,300.218460083008,-4000.36376953125,,,6,,,,32.1014785766602,,,1000,,,,,,,,,,,,,,,,,,,,,,300.217437744141,300.236419677734,-4000.36376953125,-4000.36376953125,,,7.9953351020813,,1,0,0,0,0.013885498046875,31.7693061828613,1,1,1,300.217590332031,0,2084575104,300.227221679687,,,-0.125137645279641,0.00624375601749347,-0.125146771937307,0.00624377401262845,0.971946537494659,0.974563777446747,32.1464538574219,0,35,4,200,-1.31931819851161E-5,-0.115707561373711,0.492446213960648,1,,,,,,,,,,,,,,,,
,3889785820.01259,300.20295715332,-6500.40771484375,,,6,,,,32.1014785766602,,,1000,,,,,,,,,,,,,,,,,,,,,,300.202423095703,300.222351074219,-6500.40771484375,-6500.40771484375,,,7.99648904800415,,1,0,0,0,0.013885498046875,32.2580642700195,1,1,1,300.203491210937,0,2084574944,300.212030029297,,,-0.129304216960891,0.00645162568483859,-0.129312222874174,0.00645162378932766,0.972073495388031,0.974395990371704,32.1438598632812,4.25748075940646E-5,35,4,200,-0.00012179724581074,-0.12030602991581,0.508455216884613,1,,,,,,,,,,,,,,,,
,3889785943.37428,300.085968017578,-9000.21875,,,6,,,,32.1014785766602,,,1000,,,,,,,,,,,,,,,,,,,,,,300.078826904297,300.106414794922,-9000.21875,-9000.21875,,,7.99807548522949,,1,0,0,0,0.013885498046875,32.2580642700195,1,1,1,300.093109130859,0,2084575168,300.095422363281,,,-0.131051405527392,0.00653880077403801,-0.131059391628679,0.00653880736745609,0.972063601016998,0.974296450614929,32.1430740356445,0,35,4,200,-0.00020695454441011,-0.12203436344862,0.514563381671906,1,,,,,,,,,,,,,,,,
,3889786100.83864,300.196838378906,-25000.40234375,,,6,,,,32.1014785766602,,,1000,,,,,,,,,,,,,,,,,,,,,,300.191741943359,300.217590332031,-25000.40234375,-25000.40234375,,,8.00185585021973,,1,0,0,0,0.013885498046875,32.2580642700195,1,1,1,300.201934814453,0,2084574944,300.20703125,,,-0.134069167359082,0.00668955610144993,-0.134078558838165,0.00668956193656519,0.971105873584747,0.97360634803772,32.1461563110352,0.191226214170456,35,4,200,-0.000278236868325621,-0.125825121998787,0.526068568229675,1,,,,,,,,,,,,,,,,
,3889786254.50432,300.154495239258,-50000.29296875,,,6,,,,32.1014785766602,,,1000,,,,,,,,,,,,,,,,,,,,,,300.145812988281,300.176147460937,-50000.29296875,-50000.29296875,,,8.00346279144287,,1,0,0,0,0.013885498046875,31.7693061828613,1,1,1,300.163177490234,0,2084574976,300.164929199219,,,-0.135380392389692,0.00675544077959,-0.135395079000039,0.00675545425513948,0.968838393688202,0.972463428974152,32.1568984985352,0,35,4,200,-0.000212653205380775,-0.129104122519493,0.530275344848633,1,,,,,,,,,,,,,,,,
,3889786375.44047,300.154327392578,-70000.3984375,,,6,,,,32.1014785766602,,,1000,,,,,,,,,,,,,,,,,,,,,,300.143859863281,300.170013427734,-70000.3984375,-70000.3984375,,,8.00473499298096,,1,0,0,0,0.013885498046875,32.2580642700195,1,1,1,300.144073486328,0,2084574944,300.159896850586,,,-0.135951379270673,0.00678451073874511,-0.135974254896994,0.00678452477591821,0.966214537620544,0.971549689769745,32.1706886291504,,35,4,200,-0.000413304078392684,-0.131635814905167,0.531974732875824,1,,,,,,,,,,,,,,,,