File: Data/KMK254S/ZFCFC/KMK254S_ZFCFC.dat
[Header]
; MPMS3 Data File (default extension .dat)
; Copyright (c) 2007, Quantum Design, Inc. All rights reserved.
TITLE,
FILEOPENTIME,3870501156.38832,08/24/2022,11:12 am
BYAPP,MPMS3 w/ AC,1.0,1.1
INFO,MPMS3 Measurement Release 1.1.16 Build 424, MultiVu Release 2.3.4.19,APPNAME
INFO,Linear Motor Servo Controller,MOTOR_MODULE_NAME
INFO,3101-100 J0,MOTOR_HW_VERSION
INFO,MMC721,MOTOR_SERIAL_NUMBER
INFO,01.04.28,MOTOR_SOFTWARE_VERSION
INFO,Quantum Design Squid Module,SQUID_MODULE_NAME
INFO,3101-501 B0,SQUID_HW_VERSION
INFO,SQM195,SQUID_SERIAL_NUMBER
INFO,01.03.04,SQUID_SOFTWARE_VERSION
INFO,SQUID AC,AC_MODULE_NAME
INFO,3101-401 f1,AC_HW_VERSION
INFO,SAC107,AC_SERIAL_NUMBER
INFO,SQUID AC 00.95.07,AC_SOFTWARE_VERSION
INFO,TCI166,COIL_SERIAL_NUMBER
INFO,0,MOMENT_UNITS
INFO,KMK254S,SAMPLE_MATERIAL
INFO,,SAMPLE_COMMENT
INFO,1.5,SAMPLE_MASS
INFO,,SAMPLE_VOLUME
INFO,,SAMPLE_MOLECULAR_WEIGHT
INFO,,SAMPLE_SIZE
INFO,,SAMPLE_SHAPE
INFO,Straw,SAMPLE_HOLDER
INFO,Standard,SAMPLE_HOLDER_DETAIL
INFO,66.55,SAMPLE_OFFSET
DATATYPE,COMMENT,1
DATATYPE,TIME,2
STARTUPAXIS,X,2
STARTUPAXIS,Y1,5
FIELDGROUP, VSM,2,3,4,5,6,8,9,10,11,14,15
FIELDGROUP, DC, 2,3,4,14,56,57,58,59,60,61,62,63,64,65,66,67,68,69
FIELDGROUP, AC, 2,3,4,11,16,17,18,19,20,21,22,23,24,25,26,27,28,29,30
STARTUPGROUP, All
[Data]
Comment,Time Stamp (sec),Temperature (K),Magnetic Field (Oe),Moment (emu),M. Std. Err. (emu),Transport Action,Averaging Time (sec),Frequency (Hz),Peak Amplitude (mm),Center Position (mm),Lockin Signal' (V),Lockin Signal (V),Range,M. Quad. Signal (emu),AC Moment (emu),AC M. Std Err. (emu),AC Phase (deg),AC Phase Std. Err. (deg),AC Susceptibility (emu/Oe),AC Suscept. Std Err. (emu/Oe),AC X' (emu/Oe),AC X' Std Err. (emu/Oe),AC X'' (emu/Oe),AC X'' Std Err. (emu/Oe),AC Drive (Oe),AC Frequency (Hz),AC Averaging Time (sec),AC Cycles,AC Range,AC Measure Type,AC Signal' (V),AC Signal'' (V),AC Trim Coil Ratio,AC Trim Coil Phase,Min. Temperature (K),Max. Temperature (K),Min. Field (Oe),Max. Field (Oe),Mass (grams),Motor Lag (deg),Pressure (Torr),Measure Count,Measurement Number,SQUID Status (code),Motor Status (code),Measure Status (code),Motor Current (amps),Motor Temp. (C),Temp. Status (code),Field Status (code),Chamber Status (code),Chamber Temp (K),Redirection State,Evercool Status,Average Temp (K),Rotation Angle (deg),Rotator state,DC Moment Fixed Ctr (emu),DC Moment Err Fixed Ctr (emu),DC Moment Free Ctr (emu),DC Moment Err Free Ctr (emu),DC Fixed Fit,DC Free Fit,DC Calculated Center (mm),DC Calculated Center Err (mm),DC Scan Length (mm),DC Scan Time (s),DC Number of Points,DC Squid Drift,DC Min V (V),DC Max V (V),DC Scans per Measure,Map 01,Map 02,Map 03,Map 04,Map 05,Map 06,Map 07,Map 08,Map 09,Map 10,Map 11,Map 12,Map 13,Map 14,Map 15,Map 16
,3870502382.132,5.00226306915283,100.097091674805,,,6,,,,31.8625479601338,,,10,,,,,,,,,,,,,,,,,,,,,,4.99796104431152,5.00255727767944,100.097091674805,100.097091674805,,,3.53474593162537,,1,0,0,0,0.0168609619140625,31.7693061828613,1,1,1,5.00196886062622,0,4232058752,5.00015048980713,,,0.000442833016519057,2.20090455155553E-5,0.000444276555906425,2.20099830583333E-5,0.91191703081131,0.963065445423126,31.5593490600586,0,35,4,200,6.61065205349587E-5,-0.185901418328285,0.0311377942562103,1,,,,,,,,,,,,,,,,
,3870502448.73055,9.31587600708008,100.097091674805,,,6,,,,31.8625479601338,,,10,,,,,,,,,,,,,,,,,,,,,,8.94822788238525,9.66943168640137,100.097091674805,100.097091674805,,,4.31369543075562,,1,0,0,0,0.000152587890625,31.2805480957031,6,1,1,9.6835241317749,0,4232058720,9.31210784912109,,,0.00049941360466185,2.48219319049708E-5,0.00050104420379498,2.48230291617617E-5,0.911558210849762,0.96230810880661,31.5591850280762,5.61775636672974,35,4,200,0.00017384477541782,-0.203870087862015,0.0426506362855434,1,,,,,,,,,,,,,,,,
,3870502516.59847,14.6572318077087,100.097091674805,,,6,,,,31.8675827965178,,,10,,,,,,,,,,,,,,,,,,,,,,14.2700605392456,15.0115089416504,100.097091674805,100.097091674805,,,4.78580713272095,,1,0,0,0,0.0002288818359375,30.7917900085449,6,1,1,15.0444030761719,0,4232058816,14.6355370521545,,,0.000612781007880727,3.04592098542949E-5,0.000614834218950846,3.04603708347755E-5,0.910574913024902,0.962395071983337,31.559850692749,0.190531641244888,35,4,200,0.000174478758708574,-0.242373272776604,0.060137327760458,1,,,,,,,,,,,,,,,,
,3870502575.39575,19.4033355712891,100.097091674805,,,6,,,,31.8675827965178,,,10,,,,,,,,,,,,,,,,,,,,,,19.0462226867676,19.7604484558105,100.097091674805,100.097091674805,,,5.90708351135254,,1,0,0,0,0.000152587890625,30.7917900085449,2,1,1,19.7604484558105,0,4232058656,19.4035758972168,,,0.000727991096292556,3.61835124193805E-5,0.000730396782562399,3.61852829571049E-5,0.911309957504273,0.962640941143036,31.5625171661377,6.47115230094641E-5,35,4,200,0.000149987521581352,-0.283914029598236,0.0750549137592316,1,,,,,,,,,,,,,,,,
,3870502642.74645,24.7688627243042,100.097091674805,,,6,,,,31.8728133832589,,,10,,,,,,,,,,,,,,,,,,,,,,24.3823890686035,25.1204929351807,100.097091674805,100.097091674805,,,6.06786870956421,,1,0,0,0,0.018768310546875,31.2805480957031,2,1,1,25.1553363800049,0,4232058688,24.7497102737427,,,0.000863143627078578,4.29010979408556E-5,0.000865999937760062,4.29028826873809E-5,0.911293029785156,0.962921142578125,31.5672168731689,0,35,4,200,0.000157552640303038,-0.33348360657692,0.0916446894407272,1,,,,,,,,,,,,,,,,
,3870502701.30679,29.4543561935425,100.097091674805,,,6,,,,31.8728133832589,,,10,,,,,,,,,,,,,,,,,,,,,,29.0757141113281,29.8006763458252,100.097091674805,100.097091674805,,,6.19644117355347,,1,0,0,0,0.0138092041015625,31.2805480957031,2,1,1,29.8329982757568,0,4232058784,29.4433620452881,,,0.000978707980861159,4.86387559358549E-5,0.000981830720985009,4.86410638589788E-5,0.912749886512756,0.963061094284058,31.5730381011963,5.61898899078369,35,4,200,0.00015162730414886,-0.375896543264389,0.105625621974468,1,,,,,,,,,,,,,,,,
,3870502768.97356,34.8577499389648,100.097091674805,,,6,,,,31.8778764528966,,,10,,,,,,,,,,,,,,,,,,,,,,34.5690231323242,35.2140693664551,100.097091674805,100.097091674805,,,6.32560873031616,,1,0,0,0,0.00030517578125,30.3030319213867,2,1,1,35.2285995483398,0,4232058688,34.8888070848253,,,0.00110729145423817,5.50248475129218E-5,0.00111074618643221,5.50274111555731E-5,0.913604557514191,0.963200807571411,31.5814533233643,0,35,4,200,0.000150880208821036,-0.422925025224686,0.12129907310009,1,,,,,,,,,,,,,,,,
,3870502836.60388,40.2757225036621,100.097091674805,,,6,,,,31.883121401006,,,10,,,,,,,,,,,,,,,,,,,,,,39.881290435791,40.6302452087402,100.097091674805,100.097091674805,,,6.37819290161133,,1,0,0,0,0,30.7917900085449,2,1,1,40.6903457641602,0,4232058400,40.2659473419189,,,0.00122833607219428,6.10334357461215E-5,0.00123204205871421,6.1036388064291E-5,0.914835512638092,0.963255167007446,31.5917663574219,,35,4,200,0.000115095790533815,-0.467246621847153,0.136046543717384,1,,,,,,,,,,,,,,,,
,3870502904.42119,45.740348815918,100.097091674805,,,6,,,,31.8884607020193,,,10,,,,,,,,,,,,,,,,,,,,,,45.3501853942871,46.08056640625,100.097091674805,100.097091674805,,,6.46677923202515,,1,0,0,0,0.0180816650390625,30.7917900085449,2,1,1,46.1305122375488,0,4232058624,45.720295715332,,,0.00133952067949597,6.65501363639691E-5,0.00134340518147449,6.65533171154039E-5,0.916220784187317,0.96329927444458,31.6028652191162,INF,35,4,200,0.00014743251085747,-0.507228016853333,0.150027826428413,1,,,,,,,,,,,,,,,,
,3870502971.64073,51.1719226837158,100.097091674805,,,6,,,,31.8936319271963,,,10,,,,,,,,,,,,,,,,,,,,,,50.7677803039551,51.5449600219727,100.097091674805,100.097091674805,,,6.51341724395752,,1,0,0,0,0.01617431640625,30.7917900085449,2,1,1,51.5760650634766,0,4232058720,51.1677921295166,,,0.00143701987243154,7.13839412011795E-5,0.00144097581907225,7.1386991282834E-5,0.917921304702759,0.963311433792114,31.6152114868164,6.6262116888538E-5,35,4,200,0.000135629656142555,-0.542423963546753,0.162143692374229,1,,,,,,,,,,,,,,,,
,3870503038.78433,56.6148662567139,100.097091674805,,,6,,,,31.899231857258,,,10,,,,,,,,,,,,,,,,,,,,,,56.2335510253906,56.9369087219238,100.097091674805,100.097091674805,,,6.55234003067017,,1,0,0,0,0.0196075439453125,31.2805480957031,2,1,1,56.9961814880371,0,4232058720,56.5892402648926,,,0.001520696346447,7.55294404777446E-5,0.0015246378841263,7.5531713172863E-5,0.919724702835083,0.963297188282013,31.6285343170166,0,35,4,200,8.30591379781254E-5,-0.572554290294647,0.172529101371765,1,,,,,,,,,,,,,,,,
,3870503106.19598,62.0717620849609,100.097091674805,,,6,,,,31.904508284514,,,10,,,,,,,,,,,,,,,,,,,,,,61.6638946533203,62.4549331665039,100.097091674805,100.097091674805,,,6.62150287628174,,1,0,0,0,0.019989013671875,31.2805480957031,2,1,1,62.4796295166016,0,4232058816,62.0647552490234,,,0.00159086427140128,7.90014077410906E-5,0.00159471929456733,7.9003762717118E-5,0.921805202960968,0.963239848613739,31.6428775787354,0,35,4,200,0.000108610613096971,-0.59784346818924,0.181192919611931,1,,,,,,,,,,,,,,,,
,3870503182.54104,68.2594337463379,100.097091674805,,,6,,,,31.9151661082741,,,10,,,,,,,,,,,,,,,,,,,,,,67.8397674560547,68.6131057739258,100.097091674805,100.097091674805,,,6.64614152908325,,1,0,0,0,0.0211334228515625,30.7917900085449,2,1,1,68.6791000366211,0,4232058656,68.2298217773437,,,0.00165388216118662,8.21216026906214E-5,0.00165771061167291,8.2124578813707E-5,0.923250198364258,0.963186919689178,31.6598682403564,0,35,4,200,0.000104166480014101,-0.620595395565033,0.1888667345047,1,,,,,,,,,,,,,,,,
,3870503250.47677,73.8020133972168,100.097091674805,,,6,,,,31.9203866949384,,,10,,,,,,,,,,,,,,,,,,,,,,73.4189834594727,74.1520156860352,100.097091674805,100.097091674805,,,6.65083742141724,,1,0,0,0,0.000152587890625,30.7917900085449,2,1,1,74.1850433349609,0,4232058784,73.7844261169434,,,0.00169636015690666,8.42155725661898E-5,0.00169996337303829,8.42180577169985E-5,0.925628304481506,0.963109254837036,31.6756381988525,0.0696320459246635,35,4,200,2.74020294455113E-5,-0.635949075222015,0.193914890289307,1,,,,,,,,,,,,,,,,
,3870503326.61668,80.0126152038574,100.097091674805,,,6,,,,31.9316869620571,,,10,,,,,,,,,,,,,,,,,,,,,,79.5857009887695,80.3817596435547,100.097091674805,100.097091674805,,,6.69300842285156,,1,0,0,0,0.0193023681640625,30.7917900085449,2,1,1,80.4395294189453,0,4232058688,79.9907829284668,,,0.00173031924735143,8.58909942657904E-5,0.00173378053332917,8.58935920199541E-5,0.927277743816376,0.963049113750458,31.6942710876465,0,35,4,200,8.25671959319152E-5,-0.648337006568909,0.197837114334106,1,,,,,,,,,,,,,,,,
,3870503394.71343,85.580436706543,100.097091674805,,,6,,,,31.9378033843494,,,10,,,,,,,,,,,,,,,,,,,,,,85.1521606445313,85.9886856079102,100.097091674805,100.097091674805,,,6.73906230926514,,1,0,0,0,0.017852783203125,30.7917900085449,2,1,1,86.0087127685547,0,4232058688,85.5755653381348,,,0.00174974694300734,8.68403158319401E-5,0.00175293694753135,8.68429065170084E-5,0.92968624830246,0.96295839548111,31.7112789154053,5.6678123655729E-5,35,4,200,6.70356312184595E-5,-0.655519187450409,0.199931472539902,1,,,,,,,,,,,,,,,,
,3870503471.32653,91.8967094421387,100.097091674805,,,6,,,,31.9480143928808,,,10,,,,,,,,,,,,,,,,,,,,,,91.4997100830078,92.2601470947266,100.097091674805,100.097091674805,,,6.73967361450195,,1,0,0,0,0.000152587890625,31.2805480957031,2,1,1,92.2937088012695,0,4232712416,91.8846450805664,,,0.00176096018145891,8.73842849583564E-5,0.00176388701315661,8.73857490019133E-5,0.931747794151306,0.962845921516418,31.7310352325439,0,35,4,200,5.60056287213229E-5,-0.659792304039001,0.200865387916565,1,,,,,,,,,,,,,,,,
,3870503547.77905,98.2097434997559,100.097091674805,,,6,,,,31.9589029837872,,,10,,,,,,,,,,,,,,,,,,,,,,97.8208694458008,98.5652694702148,100.097091674805,100.097091674805,,,6.76205205917358,,1,0,0,0,0.0174713134765625,30.7917900085449,2,1,1,98.5986175537109,0,4232058816,98.1932235717773,,,0.00176237569640719,8.74425502952866E-5,0.00176506213146831,8.74442471396513E-5,0.933775782585144,0.962760090827942,31.7513942718506,5.63483762741089,35,4,200,7.423555416608E-6,-0.660699605941772,0.200620576739311,1,,,,,,,,,,,,,,,,
,3870503624.38478,104.588928222656,100.097091674805,,,6,,,,31.9704152261132,,,10,,,,,,,,,,,,,,,,,,,,,,104.183578491211,104.944435119629,100.097091674805,100.097091674805,,,6.80651712417603,,1,0,0,0,0.0199127197265625,31.2805480957031,2,1,1,104.994277954102,0,4232058688,104.577669525146,,,0.00175581921455995,8.71059465063425E-5,0.00175825456719888,8.71073394736368E-5,0.935754001140594,0.9626504778862,31.7723541259766,5.25964021682739,35,4,200,-3.10734435515769E-7,-0.658826291561127,0.19936840236187,1,,,,,,,,,,,,,,,,
,3870503700.75974,110.874053955078,100.097091674805,,,6,,,,31.9826600980285,,,10,,,,,,,,,,,,,,,,,,,,,,110.471321105957,110.913017272949,100.097091674805,100.097091674805,,,6.81463003158569,,1,0,0,0,0.020599365234375,30.7917900085449,2,1,1,111.276786804199,0,4232058656,110.69904200236,,,0.0017427979567585,8.64495171397562E-5,0.00174499945312885,8.6451051026471E-5,0.937657356262207,0.962531685829163,31.7938823699951,5.63860654830933,35,4,200,4.45342448074371E-5,-0.654584169387817,0.197273701429367,1,,,,,,,,,,,,,,,,
,3870503785.38771,117.922878265381,100.097091674805,,,6,,,,32.0003991040533,,,10,,,,,,,,,,,,,,,,,,,,,,117.487983703613,118.301078796387,100.097091674805,100.097091674805,,,6.82519102096558,,1,0,0,0,0.0203704833984375,31.2805480957031,2,1,1,118.357772827148,0,4232058656,117.912497711182,,,0.00172238764239821,8.54293827192327E-5,0.00172438917371285,8.54305331662293E-5,0.939116537570953,0.962359249591827,31.8191204071045,0,35,4,200,-3.00968986266525E-5,-0.647824704647064,0.194158047437668,1,,,,,,,,,,,,,,,,
,3870503871.47721,125.03462600708,100.097091674805,,,6,,,,32.0184184155818,,,10,,,,,,,,,,,,,,,,,,,,,,124.653022766113,125.396324157715,100.097091674805,100.097091674805,,,6.83058309555054,,1,0,0,0,0.019378662109375,30.7917900085449,2,1,1,125.416229248047,0,4232058656,125.019232940674,,,0.0016963684183583,8.4130808763069E-5,0.00169816794266578,8.41319179251276E-5,0.940697073936462,0.96221262216568,31.8452930450439,0,35,4,200,2.84465731965611E-5,-0.638930976390839,0.190343290567398,1,,,,,,,,,,,,,,,,
,3870503957.16487,132.136390686035,100.097091674805,,,6,,,,32.0374859097693,,,10,,,,,,,,,,,,,,,,,,,,,,131.746978759766,132.492294311523,100.097091674805,100.097091674805,,,6.84955644607544,,1,0,0,0,0.0150299072265625,30.7917900085449,2,1,1,132.525802612305,0,4232058688,132.119096374512,,,0.0016664181400962,8.26384511680797E-5,0.00166803140975057,8.2639188298492E-5,0.942138969898224,0.962117969989777,31.8718147277832,0,35,4,200,2.45998726313701E-5,-0.628612220287323,0.186031877994537,1,,,,,,,,,,,,,,,,
,3870504043.49909,139.313217163086,100.097091674805,,,6,,,,32.0575829468658,,,10,,,,,,,,,,,,,,,,,,,,,,138.908477783203,139.674682617188,100.097091674805,100.097091674805,,,6.88183307647705,,1,0,0,0,0.0179290771484375,30.7917900085449,2,1,1,139.717956542969,0,4232058624,139.296539306641,,,0.0016330576030742,8.09776737071455E-5,0.00163449828430065,8.0978164414751E-5,0.94352000951767,0.962019085884094,31.8992710113525,5.26265335083008,35,4,200,1.2593174687936E-5,-0.617040693759918,0.181308016180992,1,,,,,,,,,,,,,,,,
,3870504129.03137,146.41650390625,100.097091674805,,,6,,,,32.0787658971081,,,10,,,,,,,,,,,,,,,,,,,,,,146.018127441406,146.770629882813,100.097091674805,100.097091674805,,,6.92082452774048,,1,0,0,0,0.0164031982421875,30.7917900085449,2,1,1,146.814880371094,0,4232058656,146.40411529541,,,0.00159779353541086,7.9223659739669E-5,0.00159908197989483,7.9223817100303E-5,0.944735646247864,0.961926221847534,31.9270553588867,5.65040302276611,35,4,200,-2.99382008961402E-5,-0.604740142822266,0.176371037960052,1,,,,,,,,,,,,,,,,
,3870504214.4432,153.475212097168,100.097091674805,,,6,,,,32.1009535602058,,,10,,,,,,,,,,,,,,,,,,,,,,153.069885253906,153.848205566406,100.097091674805,100.097091674805,,,6.92424726486206,,1,0,0,0,0.0182342529296875,31.2805480957031,2,1,1,153.88053894043,0,4232058720,153.465835571289,,,0.00156094076795188,7.73916833494474E-5,0.00156209835960286,7.73917996712091E-5,0.945841670036316,0.961832880973816,31.9554214477539,4.43838325736579E-5,35,4,200,-4.19697462348267E-5,-0.591855525970459,0.171233579516411,1,,,,,,,,,,,,,,,,
,3870504326.26632,162.755058288574,100.097091674805,,,6,,,,32.134175608861,,,10,,,,,,,,,,,,,,,,,,,,,,162.336380004883,163.097106933594,100.097091674805,100.097091674805,,,6.96815967559814,,1,0,0,0,0.019073486328125,31.2805480957031,2,1,1,163.173736572266,0,4232058656,162.720333862305,,,0.00151112542423519,7.49183103736888E-5,0.00151216543961727,7.49182997220139E-5,0.946709990501404,0.961705148220062,31.9938220977783,0,35,4,200,1.49993402374093E-5,-0.574382185935974,0.16438239812851,1,,,,,,,,,,,,,,,,
,3870504439.04401,172.118560791016,100.097091674805,,,6,,,,32.1670016662006,,,10,,,,,,,,,,,,,,,,,,,,,,171.723190307617,172.47346496582,100.097091674805,100.097091674805,,,6.97160577774048,,1,0,0,0,0.019073486328125,30.7917900085449,2,1,1,172.513931274414,0,4232058784,172.09660949707,,,0.00145996612902105,7.2377682591807E-5,0.00146088640795868,7.23780150301551E-5,0.947818338871002,0.961601436138153,32.0331878662109,,35,4,200,1.112965151151E-7,-0.556362926959991,0.157396614551544,1,,,,,,,,,,,,,,,,
,3870504551.30254,181.411819458008,100.097091674805,,,6,,,,32.2016068560491,,,10,,,,,,,,,,,,,,,,,,,,,,181.010101318359,181.780685424805,100.097091674805,100.097091674805,,,6.98474502563477,,1,0,0,0,0.018157958984375,31.2805480957031,2,1,1,181.813537597656,0,4232058848,181.392608642578,,,0.00140883797447775,6.98398159182469E-5,0.00140965803560149,6.98402260888124E-5,0.948705732822418,0.961511194705963,32.0732002258301,0,35,4,200,8.56693077366799E-6,-0.538266003131866,0.150464668869972,1,,,,,,,,,,,,,,,,
,3870504662.83903,190.688087463379,100.097091674805,,,6,,,,32.2376567551026,,,10,,,,,,,,,,,,,,,,,,,,,,190.273574829102,191.021545410156,100.097091674805,100.097091674805,,,7.00458145141602,,1,0,0,0,0.0164031982421875,31.2805480957031,2,1,1,191.102600097656,0,4232058752,190.657405090332,,,0.00135833629660599,6.73337880357714E-5,0.00135905965062339,6.73336643082E-5,0.949439525604248,0.961398541927338,32.1139945983887,5.26290607452393,35,4,200,6.09392054684577E-6,-0.520395159721375,0.143620565533638,1,,,,,,,,,,,,,,,,
,3870504774.52238,199.968688964844,100.097091674805,,,6,,,,32.2757333491304,,,10,,,,,,,,,,,,,,,,,,,,,,199.537521362305,200.338928222656,100.097091674805,100.097091674805,,,7.01286315917969,,1,0,0,0,0.0167083740234375,30.3030319213867,2,1,1,200.399856567383,0,4232058688,199.942338562012,,,0.00130833165372798,6.48531190307248E-5,0.00130898802072853,6.48531524622961E-5,0.950017273426056,0.961293518543243,32.1559791564941,0,35,4,200,4.2604601731E-6,-0.502680718898773,0.136907547712326,1,,,,,,,,,,,,,,,,
,3870504886.01085,209.245147705078,100.097091674805,,,6,,,,32.3154075475125,,,10,,,,,,,,,,,,,,,,,,,,,,208.850357055664,209.598693847656,100.097091674805,100.097091674805,,,7.037757396698,,1,0,0,0,0.0171661376953125,28.3479976654053,2,1,1,209.639938354492,0,4232058624,209.221876525879,,,0.00125954779503354,6.24336130937972E-5,0.00126015422018166,6.24339042244832E-5,0.950440227985382,0.961209654808044,32.1986045837402,5.67438125610352,35,4,200,1.61034236612068E-7,-0.485343992710114,0.130389839410782,1,,,,,,,,,,,,,,,,
,3870504997.89655,218.506141662598,100.097091674805,,,6,,,,32.3568899386541,,,10,,,,,,,,,,,,,,,,,,,,,,218.097152709961,218.865692138672,100.097091674805,100.097091674805,,,7.05601930618286,,1,0,0,0,0.000152587890625,30.7917900085449,2,1,1,218.915130615234,0,4232058688,218.495086669922,,,0.00121163440781289,6.00574841607833E-5,0.00121219191505621,6.00578324137227E-5,0.950833678245544,0.961132705211639,32.2428779602051,4.01040815631859E-5,35,4,200,-4.07070274377475E-6,-0.468337565660477,0.123993098735809,1,,,,,,,,,,,,,,,,
,3870505107.24716,227.562278747559,100.097091674805,,,6,,,,32.3992986873553,,,10,,,,,,,,,,,,,,,,,,,,,,227.134368896484,227.940795898438,100.097091674805,100.097091674805,,,7.07488441467285,,1,0,0,0,0.01617431640625,31.2805480957031,2,1,1,227.990188598633,0,4232058848,227.527285766602,,,0.00116613552023605,5.78015471806991E-5,0.0011666594266549,5.78020584412993E-5,0.951065838336945,0.961068868637085,32.287036895752,0,35,4,200,-2.8412599931471E-5,-0.45212185382843,0.117976941168308,1,,,,,,,,,,,,,,,,
,3870505219.05713,236.825576782227,100.097091674805,,,6,,,,32.4443050926331,,,10,,,,,,,,,,,,,,,,,,,,,,236.41455078125,237.206497192383,100.097091674805,100.097091674805,,,7.11438465118408,,1,0,0,0,0.0150299072265625,31.7693061828613,2,1,1,237.236602783203,0,4232058688,236.811248779297,,,0.00112077060575404,5.5552294288565E-5,0.00112125434252975,5.55525781891372E-5,0.951310455799103,0.961018979549408,32.3338394165039,5.26352405548096,35,4,200,3.26356439472875E-6,-0.435873091220856,0.112046234309673,1,,,,,,,,,,,,,,,,
,3870505330.40572,246.068748474121,100.097091674805,,,6,,,,32.4910611867045,,,10,,,,,,,,,,,,,,,,,,,,,,245.654800415039,246.466644287109,100.097091674805,100.097091674805,,,7.20927429199219,,1,0,0,0,0.0138092041015625,30.7917900085449,2,1,1,246.482696533203,0,4232058656,246.042657470703,,,0.00107702206652619,5.33832115225918E-5,0.00107747113296073,5.33834610249288E-5,0.951555550098419,0.960960566997528,32.3824615478516,0,35,4,200,-2.98957274935674E-5,-0.420180052518845,0.106349028646946,1,,,,,,,,,,,,,,,,
,3870505441.22158,255.224418640137,100.097091674805,,,6,,,,32.5392719721507,,,10,,,,,,,,,,,,,,,,,,,,,,254.856719970703,255.59211730957,100.097091674805,100.097091674805,,,7.36370038986206,,1,0,0,0,0.0159454345703125,31.2805480957031,2,1,1,255.59211730957,0,4232058656,255.222105407715,,,0.00103485696983235,5.12924311758963E-5,0.00103527229033118,5.12927743571537E-5,0.951895117759705,0.960929870605469,32.4330253601074,0,35,4,200,-3.07079972117208E-5,-0.405029803514481,0.10088362544775,1,,,,,,,,,,,,,,,,
,3870505551.80298,264.426971435547,100.097091674805,,,6,,,,32.5892406253621,,,10,,,,,,,,,,,,,,,,,,,,,,264.040283203125,264.763732910156,100.097091674805,100.097091674805,,,7.33506107330322,,1,0,0,0,0,31.2805480957031,2,1,1,264.813659667969,0,4232058752,264.406076049805,,,0.000993827900563416,4.92572507792624E-5,0.00099419463255435,4.92575411676536E-5,0.952567338943481,0.960947036743164,32.4873161315918,0,35,4,200,-3.00593092106283E-5,-0.390259087085724,0.0955659747123718,1,,,,,,,,,,,,,,,,
,3870505662.86989,273.623062133789,100.097091674805,,,6,,,,32.6412157040225,,,10,,,,,,,,,,,,,,,,,,,,,,273.226348876953,273.974517822266,100.097091674805,100.097091674805,,,7.33056020736694,,1,0,0,0,0.0146484375,31.2805480957031,2,1,1,274.019775390625,0,4232058688,273.606625366211,,,0.000954207700775768,4.72904625322801E-5,0.000954497489694965,4.72906204658026E-5,0.953955054283142,0.961005032062531,32.5485153198242,0.0930397659540176,35,4,200,-2.45604896917939E-5,-0.375976324081421,0.0904102697968483,1,,,,,,,,,,,,,,,,
,3870505773.41858,282.760406494141,100.097091674805,,,6,,,,32.6944270394625,,,10,,,,,,,,,,,,,,,,,,,,,,282.369812011719,283.114929199219,100.097091674805,100.097091674805,,,7.35016775131226,,1,0,0,0,0.0145721435546875,30.7917900085449,2,1,1,283.151000976562,0,4232058688,282.741732788086,,,0.000916279156685342,4.54056435451058E-5,0.000916458187015359,4.54057485260247E-5,0.956456780433655,0.961134195327759,32.6200981140137,3.3366621210007E-5,35,4,200,3.32160993821162E-6,-0.362267643213272,0.085552990436554,1,,,,,,,,,,,,,,,,
,3870505883.73199,291.923049926758,100.097091674805,,,6,,,,32.7496396343042,,,10,,,,,,,,,,,,,,,,,,,,,,291.50927734375,292.336822509766,100.097091674805,100.097091674805,,,7.43607521057129,,1,0,0,0,0.0138092041015625,30.7917900085449,2,1,1,292.336822509766,0,4232058624,291.919848632812,,,0.000879661758757822,4.3585826568347E-5,0.000879729251160661,4.35857668165911E-5,0.959317684173584,0.961281657218933,32.7023620605469,0,35,4,200,-1.71532101376215E-5,-0.349026679992676,0.0808774456381798,1,,,,,,,,,,,,,,,,
,3870505985.28588,299.399475097656,100.097091674805,,,6,,,,32.7961449565874,,,10,,,,,,,,,,,,,,,,,,,,,,299.294647216797,299.493377685547,100.097091674805,100.097091674805,,,7.63039541244507,,1,0,0,0,0.0138092041015625,31.2805480957031,6,1,1,299.504302978516,0,4232058656,299.402130126953,,,0.000849904794576923,4.21085038447879E-5,0.000849925665841426,4.21084660269539E-5,0.961053311824799,0.961711525917053,32.7691497802734,0,35,4,200,1.40535048558377E-5,-0.33858522772789,0.0765079483389854,1,,,,,,,,,,,,,,,,
,3870506043.8563,299.896469116211,100.097091674805,,,6,,,,32.7961449565874,,,10,,,,,,,,,,,,,,,,,,,,,,299.883819580078,299.907440185547,100.097091674805,100.097091674805,,,7.75454235076904,,1,0,0,0,0.0138092041015625,30.7917900085449,5,1,1,299.909118652344,0,4232058560,299.898358154297,,,0.000846785997703007,4.1953372828915E-5,0.000846798717652035,4.19533515460622E-5,0.961430311203003,0.96183443069458,32.7750587463379,8.32897130749188E-5,35,4,200,2.48693686444312E-5,-0.337291210889816,0.0761183425784111,1,,,,,,,,,,,,,,,,
,3870506136.59086,298.386871337891,100.097091674805,,,6,,,,32.7883321388848,,,10,,,,,,,,,,,,,,,,,,,,,,298.062744140625,298.752685546875,100.097091674805,100.097091674805,,,8.06489849090576,,1,0,0,0,0.0006866455078125,30.7917900085449,2,1,1,298.021057128906,0,4232058048,298.414636230469,,,0.000850464053560032,4.2135184424749E-5,0.000850476947148957,4.21351787954384E-5,0.961687862873077,0.962088584899902,32.767406463623,5.72428226470947,35,4,200,7.26314028725028E-5,-0.33928382396698,0.0761480405926704,1,,,,,,,,,,,,,,,,
,3870506247.9157,288.514984130859,100.097091674805,,,6,,,,32.7337085232683,,,10,,,,,,,,,,,,,,,,,,,,,,288.123229980469,288.945861816406,100.097091674805,100.097091674805,,,8.54505634307861,,1,0,0,0,0.0138092041015625,31.2805480957031,2,1,1,288.084106445313,0,4232058400,288.54792175293,,,0.000896525310401303,4.44172240790347E-5,0.000896527325293229,4.44172338887092E-5,0.961690723896027,0.961743593215942,32.7260932922363,0,35,4,200,8.23390073492192E-5,-0.353959381580353,0.0842602327466011,1,,,,,,,,,,,,,,,,
,3870506359.30956,279.374404907227,100.097091674805,,,6,,,,32.6862598362872,,,10,,,,,,,,,,,,,,,,,,,,,,279.035705566406,279.773345947266,100.097091674805,100.097091674805,,,8.25349521636963,,1,0,0,0,0.0138092041015625,30.7917900085449,2,1,1,278.975463867187,0,4232058592,279.405920410156,,,0.000936484668794497,4.639790379848E-5,0.000936523981610002,4.63979624734075E-5,0.961161553859711,0.962222814559937,32.6521148681641,1.96797464013798E-5,35,4,200,6.76493582432158E-5,-0.368961602449417,0.088439904153347,1,,,,,,,,,,,,,,,,
,3870506469.56654,270.148376464844,100.097091674805,,,6,,,,32.6402634901778,,,10,,,,,,,,,,,,,,,,,,,,,,269.743591308594,270.588928222656,100.097091674805,100.097091674805,,,8.07910823822022,,1,0,0,0,0.0138092041015625,30.7917900085449,2,1,1,269.707824707031,0,4232058528,270.201531982422,,,0.000975320015190817,4.83261587374321E-5,0.000975442091494877,4.83261515608796E-5,0.959010243415833,0.962185502052307,32.5803604125977,5.70792102813721,35,4,200,4.50667030236218E-5,-0.382643818855286,0.0937481299042702,1,,,,,,,,,,,,,,,,
,3870506579.75771,260.993591308594,100.097091674805,,,6,,,,32.5976825793021,,,10,,,,,,,,,,,,,,,,,,,,,,260.662780761719,261.422576904297,100.097091674805,100.097091674805,,,7.97586297988892,,1,0,0,0,0.0002288818359375,29.8142719268799,2,1,1,260.564605712891,0,4232058656,261.039959716797,,,0.00101617452201987,5.03552338427953E-5,0.00101639828250552,5.03553597502835E-5,0.95675778388977,0.962115168571472,32.5187301635742,3.0657603929285E-5,35,4,200,9.15207347134128E-5,-0.397280246019363,0.0991278067231178,1,,,,,,,,,,,,,,,,
,3870506691.43016,251.744735717773,100.097091674805,,,6,,,,32.5569232136897,,,10,,,,,,,,,,,,,,,,,,,,,,251.387115478516,252.152755737305,100.097091674805,100.097091674805,,,7.89513301849365,,1,0,0,0,0.015106201171875,30.7917900085449,2,1,1,251.336715698242,0,4232058656,251.77946472168,,,0.00105859827187143,5.24616664636419E-5,0.00105892072505725,5.24618797414294E-5,0.954956948757172,0.962198793888092,32.4641609191895,0,35,4,200,8.50558426463976E-5,-0.412380427122116,0.104713037610054,1,,,,,,,,,,,,,,,,
,3870506802.5763,242.485710144043,100.097091674805,,,6,,,,32.5181710240369,,,10,,,,,,,,,,,,,,,,,,,,,,242.128784179687,242.88200378418,100.097091674805,100.097091674805,,,7.82826900482178,,1,0,0,0,0.0009918212890625,31.2805480957031,2,1,1,242.089416503906,0,4232058624,242.510446166992,,,0.00110164715463688,5.45991734581474E-5,0.00110206701970955,5.45993819913892E-5,0.953322291374207,0.962241530418396,32.4142456054687,3.53850336978212E-5,35,4,200,7.69178222981282E-5,-0.42762166261673,0.110500454902649,1,,,,,,,,,,,,,,,,
,3870506914.07529,233.157234191895,100.097091674805,,,6,,,,32.4806154959975,,,10,,,,,,,,,,,,,,,,,,,,,,232.790878295898,233.562149047852,100.097091674805,100.097091674805,,,7.76391983032227,,1,0,0,0,0.01617431640625,30.3030319213867,2,1,1,232.752319335938,0,4232058688,233.18897857666,,,0.00114652722635122,5.68277285535513E-5,0.00114705778075456,5.68281009622377E-5,0.951757490634918,0.96235865354538,32.3663291931152,0,35,4,200,5.26568001077976E-5,-0.44355833530426,0.11649664491415,1,,,,,,,,,,,,,,,,
,3870507023.32431,224.090339660645,100.097091674805,,,6,,,,32.4450548707722,,,10,,,,,,,,,,,,,,,,,,,,,,223.731246948242,224.48176574707,100.097091674805,100.097091674805,,,7.69157981872559,,1,0,0,0,0.0159454345703125,30.7917900085449,2,1,1,223.698913574219,0,4232058592,224.118161010742,,,0.00119178210226775,5.90749762347869E-5,0.00119241700194965,5.90750236333221E-5,0.950308501720428,0.962480247020721,32.3216400146484,0,35,4,200,8.03245493443683E-5,-0.459705501794815,0.122550569474697,1,,,,,,,,,,,,,,,,
,3870507129.15842,215.278038024902,100.097091674805,,,6,,,,32.4109417273498,,,10,,,,,,,,,,,,,,,,,,,,,,214.904602050781,215.718338012695,100.097091674805,100.097091674805,,,7.65128231048584,,1,0,0,0,0.01495361328125,31.2805480957031,2,1,1,214.837738037109,0,4232058752,215.305424499512,,,0.00123762909869347,6.1352479591727E-5,0.00123839989143305,6.13530263601451E-5,0.948723077774048,0.96252453327179,32.2783737182617,0.189986169338226,35,4,200,4.52834756288212E-5,-0.475903987884521,0.12878255546093,1,,,,,,,,,,,,,,,,
,3870507234.29352,206.488563537598,100.097091674805,,,6,,,,32.3781443222044,,,10,,,,,,,,,,,,,,,,,,,,,,206.137023925781,206.880096435547,100.097091674805,100.097091674805,,,7.59433794021606,,1,0,0,0,0.0185394287109375,30.7917900085449,2,1,1,206.097030639648,0,4232058624,206.521998596191,,,0.00128275317076613,6.35944506825912E-5,0.00128365249091647,6.35951109809632E-5,0.947200179100037,0.962452590465546,32.2375373840332,1,35,4,200,8.33749072626233E-5,-0.492128521203995,0.134735658764839,1,,,,,,,,,,,,,,,,
,3870507339.49115,197.712539672852,100.097091674805,,,6,,,,32.3454739701246,,,10,,,,,,,,,,,,,,,,,,,,,,197.358032226562,198.115020751953,100.097091674805,100.097091674805,,,7.55016660690308,,1,0,0,0,0.017242431640625,31.2805480957031,2,1,1,197.31005859375,0,4232058560,197.746125793457,,,0.0013301725223231,6.59516682408041E-5,0.00133122712649005,6.59522999705095E-5,0.945415437221527,0.962356448173523,32.195743560791,,35,4,200,8.56533079058863E-5,-0.509029746055603,0.141076296567917,1,,,,,,,,,,,,,,,,
,3870507444.56102,188.999069213867,100.097091674805,,,6,,,,32.3138126878756,,,10,,,,,,,,,,,,,,,,,,,,,,188.647720336914,189.430694580078,100.097091674805,100.097091674805,,,7.51605653762817,,1,0,0,0,0.020599365234375,31.2805480957031,2,1,1,188.567443847656,0,4232058656,189.049403381348,,,0.00137873754992502,6.8366613043142E-5,0.00137996939361073,6.83672781700922E-5,0.943573832511902,0.962299585342407,32.1547737121582,0,35,4,200,0.000103868907899596,-0.526376307010651,0.14756952226162,1,,,,,,,,,,,,,,,,
,3870507556.2528,179.652473449707,100.097091674805,,,6,,,,32.2806781537898,,,10,,,,,,,,,,,,,,,,,,,,,,179.298629760742,180.080139160156,100.097091674805,100.097091674805,,,7.47820138931274,,1,0,0,0,0.0171661376953125,30.7917900085449,2,1,1,179.224807739258,0,4232058592,179.694931030273,,,0.00143060634755408,7.09458258481454E-5,0.00143203708143514,7.0946926142822E-5,0.941798329353332,0.962264001369476,32.1128273010254,0,35,4,200,6.75893315928988E-5,-0.544952571392059,0.154424399137497,1,,,,,,,,,,,,,,,,
,3870507668.67476,170.25659942627,100.097091674805,,,6,,,,32.2481211668408,,,10,,,,,,,,,,,,,,,,,,,,,,169.902770996094,170.678604125977,100.097091674805,100.097091674805,,,7.43737840652466,,1,0,0,0,0.0193023681640625,30.7917900085449,2,1,1,169.834594726562,0,4232058592,170.301843261719,,,0.00148367716924498,7.35856138690368E-5,0.00148531640773162,7.35866120466965E-5,0.93998396396637,0.962236762046814,32.0714073181152,,35,4,200,0.000110042696178425,-0.563855826854706,0.161510959267616,1,,,,,,,,,,,,,,,,
,3870507781.23483,160.943962097168,100.097091674805,,,6,,,,32.2162482038452,,,10,,,,,,,,,,,,,,,,,,,,,,160.573486328125,161.348403930664,100.097091674805,100.097091674805,,,7.41641664505005,,1,0,0,0,0.018463134765625,31.2805480957031,2,1,1,160.523529052734,0,4232058528,160.9734375,,,0.00153706290022658,7.62418887696592E-5,0.00153893956092439,7.62432969087038E-5,0.938154816627502,0.962215185165405,32.03076171875,0,35,4,200,0.000122346420539543,-0.582882761955261,0.168554037809372,1,,,,,,,,,,,,,,,,
,3870507893.7498,151.517196655273,100.097091674805,,,6,,,,32.1851906838095,,,10,,,,,,,,,,,,,,,,,,,,,,151.150894165039,151.942794799805,100.097091674805,100.097091674805,,,7.3899564743042,,1,0,0,0,0.0191497802734375,30.3030319213867,2,1,1,151.091598510742,0,4232058560,151.578521728516,,,0.00159084776470344,7.89183311775131E-5,0.00159294678845367,7.89186281455516E-5,0.936427116394043,0.962329268455505,31.9911270141602,0.190177500247955,35,4,200,0.000127917592180893,-0.602039635181427,0.175777360796928,1,,,,,,,,,,,,,,,,
,3870507988.72934,143.53165435791,100.097091674805,,,6,,,,32.1623363380493,,,10,,,,,,,,,,,,,,,,,,,,,,143.171188354492,143.938339233398,100.097091674805,100.097091674805,,,7.36509704589844,,1,0,0,0,0.0002288818359375,31.2805480957031,2,1,1,143.124969482422,0,4232058720,143.55718536377,,,0.00163575567452701,8.11567501753032E-5,0.00163815229794179,8.11576898502439E-5,0.934405446052551,0.962504088878632,31.958366394043,,35,4,200,0.000115745824587066,-0.618147015571594,0.181737020611763,1,,,,,,,,,,,,,,,,
,3870508083.62661,135.601234436035,100.097091674805,,,6,,,,32.1373024557692,,,10,,,,,,,,,,,,,,,,,,,,,,135.237533569336,136.008422851562,100.097091674805,100.097091674805,,,7.3305778503418,,1,0,0,0,0.016937255859375,31.2805480957031,2,1,1,135.194046020508,0,4232058720,135.62248840332,,,0.00168019804342769,8.33691272270378E-5,0.00168287398579739,8.33726315156219E-5,0.933071434497833,0.962719261646271,31.9266700744629,5.4459862440126E-5,35,4,200,0.000130584361613728,-0.63363516330719,0.18769508600235,1,,,,,,,,,,,,,,,,
,3870508168.09854,128.449066162109,100.097091674805,,,6,,,,32.1156260853234,,,10,,,,,,,,,,,,,,,,,,,,,,128.084442138672,128.845245361328,100.097091674805,100.097091674805,,,7.31726884841919,,1,0,0,0,0.0159454345703125,30.7917900085449,2,1,1,128.052886962891,0,4232058624,128.459916687012,,,0.00172031858088825,8.53683582182504E-5,0.00172323684294483,8.53719240166497E-5,0.931605100631714,0.962830185890198,31.8981266021729,,35,4,200,0.00011642283789115,-0.647380769252777,0.193641364574432,1,,,,,,,,,,,,,,,,
,3870508254.04751,121.323211669922,100.097091674805,,,6,,,,32.0942278314952,,,10,,,,,,,,,,,,,,,,,,,,,,120.971054077148,121.709426879883,100.097091674805,100.097091674805,,,7.30315446853638,,1,0,0,0,0.000152587890625,30.7917900085449,2,1,1,120.936996459961,0,4232058592,121.34380569458,,,0.00175961303916917,8.73267603374256E-5,0.00176274227489596,8.7327923058246E-5,0.930205285549164,0.963185012340546,31.8694305419922,0.000291574455332011,35,4,200,0.000124892234453,-0.661454558372498,0.198788523674011,1,,,,,,,,,,,,,,,,
,3870508339.59302,114.217060089111,100.097091674805,,,6,,,,32.0731182543482,,,10,,,,,,,,,,,,,,,,,,,,,,113.853408813477,114.600898742676,100.097091674805,100.097091674805,,,7.2800440788269,,1,0,0,0,0.0197601318359375,30.3030319213867,2,1,1,113.833221435547,0,4232058592,114.229784393311,,,0.0017973469509203,8.92081613763252E-5,0.00180073774997816,8.92095405937752E-5,0.928828179836273,0.963410913944244,31.8417358398438,,35,4,200,0.000116416726086754,-0.674712002277374,0.203824177384377,1,,,,,,,,,,,,,,,,
,3870508424.30851,107.216094970703,100.097091674805,,,6,,,,32.0530692898241,,,10,,,,,,,,,,,,,,,,,,,,,,106.85782623291,107.609375,100.097091674805,100.097091674805,,,7.22305297851562,,1,0,0,0,0.0002288818359375,30.7917900085449,2,1,1,106.822814941406,0,4232058720,107.24644317627,,,0.00183447006074912,9.10606433447495E-5,0.00183814618885692,9.10622938619602E-5,0.927319467067719,0.963558256626129,31.8146343231201,0.127230405807495,35,4,200,9.54365168581717E-5,-0.687816858291626,0.208845421671867,1,,,,,,,,,,,,,,,,
,3870508510.33101,100.028408050537,100.097091674805,,,6,,,,32.0332516760035,,,10,,,,,,,,,,,,,,,,,,,,,,99.6648101806641,100.438751220703,100.097091674805,100.097091674805,,,7.17730045318604,,1,0,0,0,0.0165557861328125,30.7917900085449,2,1,1,99.6180648803711,0,4232058432,100.053579711914,,,0.00187062728351489,9.28657757186937E-5,0.00187460051704534,9.28676711996547E-5,0.925811111927032,0.963728368282318,31.7878475189209,5.63807106018066,35,4,200,0.000106637438875623,-0.70046454668045,0.213832348585129,1,,,,,,,,,,,,,,,,
,3870508595.36448,92.9011001586914,100.097091674805,,,6,,,,32.014337121309,,,10,,,,,,,,,,,,,,,,,,,,,,92.5633773803711,93.2886810302734,100.097091674805,100.097091674805,,,7.14206075668335,,1,0,0,0,0.0189971923828125,30.7917900085449,2,1,1,92.5135192871094,0,4232058816,92.9362823486328,,,0.00190468218318748,9.45675663802826E-5,0.00190896934601455,9.45699402912363E-5,0.924240410327911,0.96382337808609,31.7619609832764,9.66470452112844E-6,35,4,200,0.000122469835332595,-0.712445139884949,0.218605577945709,1,,,,,,,,,,,,,,,,
,3870508680.70665,85.807201385498,100.097091674805,,,6,,,,31.9962737249242,,,10,,,,,,,,,,,,,,,,,,,,,,85.4494781494141,86.1979064941406,100.097091674805,100.097091674805,,,7.11961126327515,,1,0,0,0,0.0177764892578125,30.7917900085449,2,1,1,85.4164962768555,0,4232058400,85.82861328125,,,0.0019369032527169,9.61798043564679E-5,0.00194151086011626,9.61817083102284E-5,0.922559916973114,0.963920772075653,31.7363624572754,5.25256299972534,35,4,200,0.000124993137433194,-0.723649978637695,0.223193764686584,1,,,,,,,,,,,,,,,,
,3870508766.10124,78.5984916687012,100.097091674805,,,6,,,,31.9792205205477,,,10,,,,,,,,,,,,,,,,,,,,,,78.2326507568359,79.0120315551758,100.097091674805,100.097091674805,,,7.09742450714111,,1,0,0,0,0.0189971923828125,30.7917900085449,2,1,1,78.1849517822266,0,4232058592,78.6263580322266,,,0.00196659233736189,9.76679226980482E-5,0.00197162031327064,9.76730890329589E-5,0.920763432979584,0.963995635509491,31.7115669250488,5.25376558303833,35,4,200,6.05723616899922E-5,-0.842647850513458,0.227505788207054,1,,,,,,,,,,,,,,,,
,3870508851.96483,71.4007682800293,100.097091674805,,,6,,,,31.9628594942135,,,10,,,,,,,,,,,,,,,,,,,,,,71.0246200561523,71.80810546875,100.097091674805,100.097091674805,,,7.0643196105957,,1,0,0,0,0.0206756591796875,31.2805480957031,2,1,1,70.9934310913086,0,4232058688,71.402522277832,,,0.00199357466254091,9.90222983587553E-5,0.00199893033049477,9.90257969190283E-5,0.918965578079224,0.964050948619843,31.6874408721924,5.25281381607056,35,4,200,0.000130148080643266,-0.85204291343689,0.231489345431328,1,,,,,,,,,,,,,,,,
,3870508936.90207,64.2279758453369,100.097091674805,,,6,,,,31.9459412887072,,,10,,,,,,,,,,,,,,,,,,,,,,63.8450622558594,64.6592483520508,100.097091674805,100.097091674805,,,6.99851989746094,,1,0,0,0,0.0138092041015625,30.7917900085449,2,1,1,63.7967033386231,0,4232058688,64.2616485595703,,,0.00201731467903687,0.000100213848569715,0.00202297644446911,0.000100216934834783,0.917466640472412,0.964076280593872,31.6641540527344,0,35,4,200,9.42551487241872E-5,-0.860032677650452,0.234990045428276,1,,,,,,,,,,,,,,,,
,3870509014.01555,57.7322540283203,100.097091674805,,,6,,,,31.9330482216761,,,10,,,,,,,,,,,,,,,,,,,,,,57.3790245056152,58.1647872924805,100.097091674805,100.097091674805,,,6.92941474914551,,1,0,0,0,0,30.7917900085449,2,1,1,57.2997207641602,0,4232058496,57.7712005615234,,,0.00203595274828112,0.000101154270120437,0.0020420041351188,0.000101159607755581,0.915753781795502,0.96405953168869,31.6440486907959,0,35,4,200,7.8208431659732E-5,-0.866513311862946,0.237787112593651,1,,,,,,,,,,,,,,,,
,3870509090.14716,51.3080654144287,100.097091674805,,,6,,,,31.9211523716398,,,10,,,,,,,,,,,,,,,,,,,,,,50.9167442321777,51.7315979003906,100.097091674805,100.097091674805,,,6.87297916412354,,1,0,0,0,0.0138092041015625,30.7917900085449,2,1,1,50.8845329284668,0,4232058720,51.3230770111084,,,0.0020516052905538,0.000101945250675803,0.00205795337768597,0.000101949691082604,0.914230108261108,0.964068293571472,31.6257629394531,0,35,4,200,3.39473626809195E-6,-0.871720314025879,0.240310803055763,1,,,,,,,,,,,,,,,,
,3870509164.97071,44.9585590362549,100.097091674805,,,6,,,,31.9101737656868,,,10,,,,,,,,,,,,,,,,,,,,,,44.619800567627,45.3433036804199,100.097091674805,100.097091674805,,,6.82200145721436,,1,0,0,0,0.0138092041015625,30.7917900085449,2,1,1,44.5738143920898,0,4232058656,44.9807102203369,,,0.00206452669516781,0.00010260055889703,0.00207118936260191,0.000102605514368588,0.912751913070679,0.964040696620941,31.6086578369141,5.25019836425781,35,4,200,2.58226264122641E-5,-0.876074075698852,0.242514550685883,1,,,,,,,,,,,,,,,,
,3870509240.9803,38.571403503418,100.097091674805,,,6,,,,31.8999031060364,,,10,,,,,,,,,,,,,,,,,,,,,,38.1807060241699,38.9722633361816,100.097091674805,100.097091674805,,,6.69994974136353,,1,0,0,0,0.0138092041015625,30.3030319213867,2,1,1,38.1705436706543,0,4232058496,38.5847007751465,,,0.00207509179272872,0.000103137908490644,0.00208202067497584,0.000103142154652159,0.911408245563507,0.964028596878052,31.5927848815918,0,35,4,200,2.53492908086628E-5,-0.879436433315277,0.244491517543793,1,,,,,,,,,,,,,,,,
,3870509308.07662,32.9260654449463,100.097091674805,,,6,,,,31.8939046488216,,,10,,,,,,,,,,,,,,,,,,,,,,32.5563354492188,33.3459396362305,100.097091674805,100.097091674805,,,6.58656692504883,,1,0,0,0,0.0138092041015625,30.7917900085449,2,1,1,32.5061912536621,0,4232058624,32.9422756195068,,,0.00208220551779249,0.00010350616422201,0.00208947721044275,0.000103511517559002,0.909834086894989,0.964037835597992,31.5802726745605,7.0206127166748,35,4,200,7.07244398654439E-5,-0.881710052490234,0.246019095182419,1,,,,,,,,,,,,,,,,
,3870509382.9953,26.5948905944824,100.097091674805,,,6,,,,31.8829587993742,,,10,,,,,,,,,,,,,,,,,,,,,,26.2248554229736,26.9987182617187,100.097091674805,100.097091674805,,,6.43354415893555,,1,0,0,0,0.0138092041015625,31.2805480957031,2,1,1,26.1910629272461,0,4232058848,26.6177976608276,,,0.00208852256480664,0.000103824053239398,0.00209589287083507,0.000103829409223104,0.909424602985382,0.964019656181335,31.5676727294922,,35,4,200,8.2351834862493E-5,-0.883437573909759,0.247419282793999,1,,,,,,,,,,,,,,,,
,3870509449.14468,21.0646152496338,100.097091674805,,,6,,,,31.8779227061021,,,10,,,,,,,,,,,,,,,,,,,,,,20.7136974334717,21.4685745239258,100.097091674805,100.097091674805,,,6.18193244934082,,1,0,0,0,0.0138092041015625,30.3030319213867,2,1,1,20.6606559753418,0,4232058496,21.0975847244263,,,0.00209239966884923,0.000104026703980974,0.00209999377324567,0.000104032566634477,0.908384680747986,0.964013159275055,31.558277130127,3.80131506919861,35,4,200,7.21235483069904E-5,-0.884315490722656,0.248491838574409,1,,,,,,,,,,,,,,,,
,3870509515.53382,15.5583434104919,100.097091674805,,,6,,,,31.8722119947985,,,10,,,,,,,,,,,,,,,,,,,,,,15.2172193527222,15.9564342498779,100.097091674805,100.097091674805,,,4.777907371521,,1,0,0,0,0.0138092041015625,31.2805480957031,2,1,1,15.160252571106,0,4232058560,15.5930251121521,,,0.00209517339079311,0.000104170549713132,0.00210289998896849,0.000104176821455773,0.907767355442047,0.963933944702148,31.5501937866211,,35,4,200,7.98638138803653E-5,-0.884795844554901,0.249498829245567,1,,,,,,,,,,,,,,,,
,3870509589.83499,9.77135896682739,100.097091674805,,,6,,,,31.860956410902,,,10,,,,,,,,,,,,,,,,,,,,,,9.54067707061768,10.0469398498535,100.097091674805,100.097091674805,,,4.1291971206665,,1,0,0,0,0.0138092041015625,30.7917900085449,6,1,1,9.50334072113037,0,4232059168,9.80970458984375,,,0.00209695117863597,0.000104247096425682,0.0021044283600104,0.000104252300674623,0.908997178077698,0.963997185230255,31.5439205169678,,35,4,200,-1.84048767550848E-5,-0.885038077831268,0.249708145856857,1,,,,,,,,,,,,,,,,
,3870509648.1362,5.22070050239563,100.097091674805,,,6,,,,31.860956410902,,,10,,,,,,,,,,,,,,,,,,,,,,5.00535249710083,5.43680572509766,100.097091674805,100.097091674805,,,3.508225440979,,1,0,0,0,0.0157928466796875,30.7917900085449,2,1,1,5.0045952796936,0,4232058720,5.13027095794678,,,0.00209821280027965,0.000104309630018924,0.0021056917369916,0.000104314806429305,0.909018695354462,0.964024066925049,31.5439777374268,5.24881219863892,35,4,200,3.0906649044482E-5,-0.885798275470734,0.141156628727913,1,,,,,,,,,,,,,,,,
,3870509706.36187,5.00222110748291,100.097091674805,,,6,,,,31.860956410902,,,10,,,,,,,,,,,,,,,,,,,,,,4.99768590927124,5.00240325927734,100.097091674805,100.097091674805,,,3.4162483215332,,1,0,0,0,0.0138092041015625,30.7917900085449,5,1,1,5.00254964828491,0,4232058752,5.00002570152283,,,0.00209833139165763,0.000104313915711525,0.00210578534668903,0.000104319427765626,0.909185886383057,0.964025318622589,31.54465675354,0,35,4,200,6.06398043601075E-6,-0.885852515697479,0.249814033508301,1,,,,,,,,,,,,,,,,
,3870509716.05582,5.00254702568054,100.097091674805,,,6,,,,31.860956410902,,,10,,,,,,,,,,,,,,,,,,,,,,4.99759578704834,5.00254964828491,100.097091674805,100.097091674805,,,3.41697645187378,,1,0,0,0,0.0138092041015625,30.7917900085449,1,1,1,5.00254440307617,0,4232058752,4.99999222755432,,,0.00209835351305929,0.000104314593600833,0.0021057960556579,0.000104319964892881,0.909229516983032,0.964022159576416,31.5448303222656,0,35,4,200,8.81540108821355E-6,-0.885842978954315,0.249806344509125,1,,,,,,,,,,,,,,,,