File: Data/KMK242/ZFCFC/KMK242_ZFCFC.dat
[Header]
; MPMS3 Data File (default extension .dat)
; Copyright (c) 2007, Quantum Design, Inc. All rights reserved.
TITLE,
FILEOPENTIME,3842360837.24098,10/02/2021,6:27 pm
BYAPP,MPMS3 w/ AC,1.0,1.1
INFO,MPMS3 Measurement Release 1.1.16 Build 424, MultiVu Release 2.3.4.19,APPNAME
INFO,Linear Motor Servo Controller,MOTOR_MODULE_NAME
INFO,3101-100 J0,MOTOR_HW_VERSION
INFO,MMC721,MOTOR_SERIAL_NUMBER
INFO,01.04.28,MOTOR_SOFTWARE_VERSION
INFO,Quantum Design Squid Module,SQUID_MODULE_NAME
INFO,3101-501 B0,SQUID_HW_VERSION
INFO,SQM195,SQUID_SERIAL_NUMBER
INFO,01.03.04,SQUID_SOFTWARE_VERSION
INFO,SQUID AC,AC_MODULE_NAME
INFO,3101-401 f1,AC_HW_VERSION
INFO,SAC107,AC_SERIAL_NUMBER
INFO,SQUID AC 00.95.07,AC_SOFTWARE_VERSION
INFO,TCI166,COIL_SERIAL_NUMBER
INFO,0,MOMENT_UNITS
INFO,KMK242,SAMPLE_MATERIAL
INFO,,SAMPLE_COMMENT
INFO,2.1,SAMPLE_MASS
INFO,,SAMPLE_VOLUME
INFO,,SAMPLE_MOLECULAR_WEIGHT
INFO,,SAMPLE_SIZE
INFO,,SAMPLE_SHAPE
INFO,Straw,SAMPLE_HOLDER
INFO,Standard,SAMPLE_HOLDER_DETAIL
INFO,66.97,SAMPLE_OFFSET
DATATYPE,COMMENT,1
DATATYPE,TIME,2
STARTUPAXIS,X,2
STARTUPAXIS,Y1,5
FIELDGROUP, VSM,2,3,4,5,6,8,9,10,11,14,15
FIELDGROUP, DC, 2,3,4,14,56,57,58,59,60,61,62,63,64,65,66,67,68,69
FIELDGROUP, AC, 2,3,4,11,16,17,18,19,20,21,22,23,24,25,26,27,28,29,30
STARTUPGROUP, All
[Data]
Comment,Time Stamp (sec),Temperature (K),Magnetic Field (Oe),Moment (emu),M. Std. Err. (emu),Transport Action,Averaging Time (sec),Frequency (Hz),Peak Amplitude (mm),Center Position (mm),Lockin Signal' (V),Lockin Signal (V),Range,M. Quad. Signal (emu),AC Moment (emu),AC M. Std Err. (emu),AC Phase (deg),AC Phase Std. Err. (deg),AC Susceptibility (emu/Oe),AC Suscept. Std Err. (emu/Oe),AC X' (emu/Oe),AC X' Std Err. (emu/Oe),AC X'' (emu/Oe),AC X'' Std Err. (emu/Oe),AC Drive (Oe),AC Frequency (Hz),AC Averaging Time (sec),AC Cycles,AC Range,AC Measure Type,AC Signal' (V),AC Signal'' (V),AC Trim Coil Ratio,AC Trim Coil Phase,Min. Temperature (K),Max. Temperature (K),Min. Field (Oe),Max. Field (Oe),Mass (grams),Motor Lag (deg),Pressure (Torr),Measure Count,Measurement Number,SQUID Status (code),Motor Status (code),Measure Status (code),Motor Current (amps),Motor Temp. (C),Temp. Status (code),Field Status (code),Chamber Status (code),Chamber Temp (K),Redirection State,Evercool Status,Average Temp (K),Rotation Angle (deg),Rotator state,DC Moment Fixed Ctr (emu),DC Moment Err Fixed Ctr (emu),DC Moment Free Ctr (emu),DC Moment Err Free Ctr (emu),DC Fixed Fit,DC Free Fit,DC Calculated Center (mm),DC Calculated Center Err (mm),DC Scan Length (mm),DC Scan Time (s),DC Number of Points,DC Squid Drift,DC Min V (V),DC Max V (V),DC Scans per Measure,Map 01,Map 02,Map 03,Map 04,Map 05,Map 06,Map 07,Map 08,Map 09,Map 10,Map 11,Map 12,Map 13,Map 14,Map 15,Map 16
,3842361754.00653,5.00241851806641,100.011535644531,,,6,,,,31.721140613775,,,100,,,,,,,,,,,,,,,,,,,,,,4.99767065048218,5.0024995803833,100.011535644531,100.011535644531,,,3.76697206497192,,1,0,0,0,0.0138092041015625,32.2580642700195,1,1,1,5.00262689590454,0,2084573184,4.99992189407349,,,0.00540715674740792,0.000269591077306133,0.00544560458708905,0.000269623756794446,0.881583333015442,0.986093819141388,31.2713489532471,,35,4,200,2.21873960981611E-5,-0.215116292238235,0.0483171120285988,1,,,,,,,,,,,,,,,,
,3842361819.76898,9.39588308334351,100.011535644531,,,6,,,,31.721140613775,,,100,,,,,,,,,,,,,,,,,,,,,,9.03879165649414,9.71937561035156,100.011535644531,100.011535644531,,,4.58346462249756,,1,0,0,0,0.0145721435546875,32.2580642700195,6,1,1,9.75297451019287,0,2084573184,9.37834482192993,,,0.00567754655052435,0.000283066574313296,0.00571776250641607,0.000283100039719531,0.881746172904968,0.98577493429184,31.2721481323242,0.191105931997299,35,4,200,5.06023388879839E-5,-0.224575817584991,0.0525346845388412,1,,,,,,,,,,,,,,,,
,3842361886.89087,14.6689729690552,100.011535644531,,,6,,,,31.7262693579158,,,100,,,,,,,,,,,,,,,,,,,,,,14.2992839813232,15.0209865570068,100.011535644531,100.011535644531,,,5.62041997909546,,1,0,0,0,0.0145721435546875,31.7693061828613,6,1,1,15.0386619567871,0,2084573184,14.6709541320801,,,0.00607471842532923,0.000302896695389951,0.00611831142876406,0.000302932459533164,0.880972921848297,0.985722005367279,31.2743453979492,0,35,4,200,6.82042227708735E-5,-0.248235315084457,0.0580574981868267,1,,,,,,,,,,,,,,,,
,3842361945.93151,19.4375972747803,100.011535644531,,,6,,,,31.7262693579158,,,100,,,,,,,,,,,,,,,,,,,,,,19.0558471679687,19.7783584594727,100.011535644531,100.011535644531,,,5.85810613632202,,1,0,0,0,0.0145721435546875,32.7468223571777,2,1,1,19.8193473815918,0,2084573184,19.4057220458984,,,0.00646990974436533,0.000322562734416851,0.00651551977741387,0.000322599217733547,0.881977498531342,0.98572587966919,31.2782154083252,,35,4,200,6.63330720271915E-5,-0.262155145406723,0.0632539018988609,1,,,,,,,,,,,,,,,,
,3842362013.1535,24.7975778579712,100.011535644531,,,6,,,,31.7315646624353,,,100,,,,,,,,,,,,,,,,,,,,,,24.4249324798584,25.1538105010986,100.011535644531,100.011535644531,,,6.09543037414551,,1,0,0,0,0.0145721435546875,32.2580642700195,2,1,1,25.170223236084,0,2084573184,24.7838060379028,,,0.00686685642660762,0.000342347672383861,0.00691511791108694,0.000342383659199651,0.882107198238373,0.985885441303253,31.283971786499,0.0762599036097527,35,4,200,5.82058237341698E-5,-0.276496112346649,0.0683260187506676,1,,,,,,,,,,,,,,,,
,3842362072.4118,29.5270490646362,100.011535644531,,,6,,,,31.7315646624353,,,100,,,,,,,,,,,,,,,,,,,,,,29.1321830749512,29.8733139038086,100.011535644531,100.011535644531,,,6.18813610076904,,1,0,0,0,0.0145721435546875,31.7693061828613,2,1,1,29.9219150543213,0,2084573184,29.504333114624,,,0.0071636460276513,0.000357073119086908,0.00721262116271183,0.000357113514693908,0.883778512477875,0.985893428325653,31.2903709411621,INF,35,4,200,5.57190105610061E-5,-0.288055449724197,0.0612107068300247,1,,,,,,,,,,,,,,,,
,3842362140.03997,34.9200973510742,100.011535644531,,,6,,,,31.7366452515271,,,100,,,,,,,,,,,,,,,,,,,,,,34.5235862731934,35.265811920166,100.011535644531,100.011535644531,,,6.32457160949707,,1,0,0,0,0.0145721435546875,33.2355842590332,2,1,1,35.3166084289551,0,2084573184,34.9022037506104,,,0.00749319372751571,0.000373459470718607,0.00754360315587568,0.000373501160783775,0.884691953659058,0.985904395580292,31.2990264892578,,35,4,200,5.90389427088667E-5,-0.299823522567749,0.0654683336615562,1,,,,,,,,,,,,,,,,
,3842362207.28744,40.3354244232178,100.011535644531,,,6,,,,31.741916475287,,,100,,,,,,,,,,,,,,,,,,,,,,39.9525756835937,40.66943359375,100.011535644531,100.011535644531,,,6.40560436248779,,1,0,0,0,0.0145721435546875,32.7468223571777,2,1,1,40.7182731628418,0,2084573184,40.3097709655762,,,0.0078481768462623,0.000391095696327366,0.00789989283707914,0.000391141783221882,0.885924100875854,0.985910952091217,31.309024810791,,35,4,200,6.15508179180324E-5,-0.312492489814758,0.0701030194759369,1,,,,,,,,,,,,,,,,
,3842362275.22545,45.7877731323242,100.011535644531,,,6,,,,31.7472767740515,,,100,,,,,,,,,,,,,,,,,,,,,,45.3966064453125,46.1403427124023,100.011535644531,100.011535644531,,,6.4583306312561,,1,0,0,0,0.0145721435546875,32.2580642700195,2,1,1,46.1789398193359,0,2084573184,45.7745185852051,,,0.00824898841021394,0.000410997604071106,0.0083018063668246,0.000411041794718076,0.887443363666534,0.985863268375397,31.3203258514404,5.59645652770996,35,4,200,6.92393514327705E-5,-0.326790690422058,0.0753672197461128,1,,,,,,,,,,,,,,,,
,3842362343.0013,51.284704208374,100.011535644531,,,6,,,,31.7525441169461,,,100,,,,,,,,,,,,,,,,,,,,,,50.9042930603027,51.6228370666504,100.011535644531,100.011535644531,,,6.55953073501587,,1,0,0,0,0.0145721435546875,32.2580642700195,2,1,1,51.6651153564453,0,2084573184,51.2617736816406,,,0.00869342639114655,0.000433056012811692,0.00874735576392013,0.000433101799730912,0.889181435108185,0.985871613025665,31.33229637146,0,35,4,200,7.5553689384833E-5,-0.351968884468079,0.0812263861298561,1,,,,,,,,,,,,,,,,
,3842362410.24929,56.6784191131592,100.011535644531,,,6,,,,31.7582393617651,,,100,,,,,,,,,,,,,,,,,,,,,,56.2964286804199,57.0464706420898,100.011535644531,100.011535644531,,,6.56450176239014,,1,0,0,0,0.0145721435546875,32.2580642700195,2,1,1,57.0604095458984,0,2084573184,56.6806324005127,,,0.0091802751179675,0.000457215991669645,0.0092352491947852,0.000457258519358493,0.890988528728485,0.985864102840424,31.3450393676758,0.0885797068476677,35,4,200,8.13830993138254E-5,-0.369095087051392,0.0876204371452332,1,,,,,,,,,,,,,,,,
,3842362477.27215,62.150842666626,100.011535644531,,,6,,,,31.7634552187583,,,100,,,,,,,,,,,,,,,,,,,,,,61.8006477355957,62.550968170166,100.011535644531,100.011535644531,,,6.63248300552368,,1,0,0,0,0.0145721435546875,32.2580642700195,2,1,1,62.550968170166,0,2084573184,62.1808979034424,,,0.00970781218905702,0.000483373227489888,0.00976357230411826,0.000483417154183763,0.893195927143097,0.985872864723206,31.3587493896484,0.0677354708313942,35,4,200,9.06909626792185E-5,-0.387644737958908,0.0945897027850151,1,,,,,,,,,,,,,,,,
,3842362544.98794,67.6914901733398,100.011535644531,,,6,,,,31.769191855842,,,100,,,,,,,,,,,,,,,,,,,,,,67.2860641479492,68.0349273681641,100.011535644531,100.011535644531,,,6.64516115188599,,1,0,0,0,0.0138092041015625,31.7693061828613,2,1,1,68.0969161987305,0,2084573184,67.6494781494141,,,0.0102747576319625,0.000511473963119212,0.0103312136311564,0.000511522094545678,0.895549654960632,0.985899746417999,31.3736190795898,0,35,4,200,6.51571244816296E-5,-0.409128040075302,0.0912125483155251,1,,,,,,,,,,,,,,,,
,3842362620.69785,73.7861747741699,100.011535644531,,,6,,,,31.7803956072369,,,100,,,,,,,,,,,,,,,,,,,,,,73.4032821655273,74.1360015869141,100.011535644531,100.011535644531,,,6.6790623664856,,1,0,0,0,0.0145721435546875,32.2580642700195,2,1,1,74.1690673828125,0,2084573184,73.7664604187012,,,0.0109367273292849,0.000544327042856857,0.0109947842008269,0.000544377235280085,0.897294700145721,0.98585718870163,31.3916149139404,,35,4,200,6.96807983331382E-5,-0.441968470811844,0.0999403372406959,1,,,,,,,,,,,,,,,,
,3842362687.82318,79.2979888916016,100.011535644531,,,6,,,,31.7860097061473,,,100,,,,,,,,,,,,,,,,,,,,,,78.9095993041992,79.6103897094727,100.011535644531,100.011535644531,,,6.73376846313477,,1,0,0,0,0.0138092041015625,32.2580642700195,2,1,1,79.6863784790039,0,2084573568,79.2852157592774,,,0.0115315093681568,0.000573755856391712,0.0115890596509099,0.000573801390258733,0.90025669336319,0.985834181308746,31.408712387085,0,35,4,200,9.78376192506403E-5,-0.462771266698837,0.107770435512066,1,,,,,,,,,,,,,,,,
,3842362763.66812,85.4866905212402,100.011535644531,,,6,,,,31.7979560017451,,,100,,,,,,,,,,,,,,,,,,,,,,85.0970611572266,85.8202056884766,100.011535644531,100.011535644531,,,6.72009897232056,,1,0,0,0,0.0138092041015625,31.7693061828613,2,1,1,85.8763198852539,0,2084574432,85.4566398620605,,,0.0121896428082604,0.000606359949440384,0.0122475605289722,0.000606405770715014,0.902608036994934,0.98581200838089,31.4297370910645,1.32612685774802E-5,35,4,200,9.26102147786878E-5,-0.485870748758316,0.116437397897243,1,,,,,,,,,,,,,,,,
,3842362840.41898,91.8661651611328,100.011535644531,,,6,,,,31.8082609456818,,,100,,,,,,,,,,,,,,,,,,,,,,91.4822158813477,92.2189102172852,100.011535644531,100.011535644531,,,6.75512504577637,,1,0,0,0,0.0138092041015625,31.7693061828613,2,1,1,92.250114440918,0,2084573824,91.8508728027344,,,0.0128281377500941,0.000637925591044611,0.0128850319686355,0.000637968745026397,0.905776739120483,0.985775768756866,31.4523887634277,0,35,4,200,9.49673558352515E-5,-0.509772002696991,0.113899528980255,1,,,,,,,,,,,,,,,,
,3842362916.12411,98.0995788574219,100.011535644531,,,6,,,,31.81912882069,,,100,,,,,,,,,,,,,,,,,,,,,,97.6812591552734,98.434326171875,100.011535644531,100.011535644531,,,6.79187250137329,,1,0,0,0,0.0145721435546875,32.2580642700195,2,1,1,98.5178985595703,0,2084573856,98.062712097168,,,0.0134162816299424,0.000666969079930303,0.0134716799016411,0.00066701510323008,0.909051775932312,0.985766172409058,31.4759845733643,,35,4,200,5.99666782363784E-5,-0.539943993091583,0.121633052825928,1,,,,,,,,,,,,,,,,
,3842362991.82398,104.36682510376,100.011535644531,,,6,,,,31.8306105822064,,,100,,,,,,,,,,,,,,,,,,,,,,103.953819274902,104.744468688965,100.011535644531,100.011535644531,,,6.77840566635132,,1,0,0,0,0.0145721435546875,32.2580642700195,2,1,1,104.779830932617,0,2084574112,104.351659393311,,,0.0139584255276659,0.000693709966731104,0.0140116838479619,0.000693753163437217,0.912429571151733,0.985641062259674,31.5006275177002,0,35,4,200,5.71207601751666E-5,-0.559135496616364,0.128704562783241,1,,,,,,,,,,,,,,,,
,3842363067.86305,110.656253814697,100.011535644531,,,6,,,,31.8429414947592,,,100,,,,,,,,,,,,,,,,,,,,,,110.241539001465,111.037399291992,100.011535644531,100.011535644531,,,6.79908990859985,,1,0,0,0,0.0145721435546875,32.2580642700195,2,1,1,111.07096862793,0,2084573984,110.650204467773,,,0.0144471166003376,0.000717788077911035,0.0144978988663761,0.000717827091673543,0.915795147418976,0.985625147819519,31.5260753631592,,35,4,200,9.18968216865324E-5,-0.5762038230896,0.135083347558975,1,,,,,,,,,,,,,,,,
,3842363152.22887,117.650741577148,100.011535644531,,,6,,,,31.8608414324303,,,100,,,,,,,,,,,,,,,,,,,,,,117.256652832031,118.02269744873,100.011535644531,100.011535644531,,,6.85254192352295,,1,0,0,0,0.0138092041015625,32.2580642700195,2,1,1,118.044830322266,0,2084573888,117.63843536377,,,0.0149343642332321,0.000741805559480325,0.0149829521989169,0.000741845430719182,0.918886005878449,0.985426425933838,31.5561275482178,0.114067502319813,35,4,200,4.53017310064752E-5,-0.593295753002167,0.141475275158882,1,,,,,,,,,,,,,,,,
,3842363237.07889,124.687938690186,100.011535644531,,,6,,,,31.878690363108,,,100,,,,,,,,,,,,,,,,,,,,,,124.293380737305,125.044792175293,100.011535644531,100.011535644531,,,6.85542774200439,,1,0,0,0,0.0138092041015625,32.2580642700195,2,1,1,125.082496643066,0,2084574016,124.673627471924,,,0.0153606305303597,0.000762785152836862,0.0154066024535235,0.000762822987930125,0.922056496143341,0.985297918319702,31.5864505767822,4.94825944770128E-5,35,4,200,3.97871299355756E-5,-0.608330905437469,0.147046893835068,1,,,,,,,,,,,,,,,,
,3842363322.41288,131.785652160645,100.011535644531,,,6,,,,31.8977458986884,,,100,,,,,,,,,,,,,,,,,,,,,,131.453460693359,132.099075317383,100.011535644531,100.011535644531,,,6.8632664680481,,1,0,0,0,0.0138092041015625,30.7917900085449,2,1,1,132.182006835938,0,2084574112,131.776394314236,,,0.0157329483349023,0.000781087540265746,0.0157761030455797,0.000781119597616134,0.925159573554993,0.985150754451752,31.6176986694336,0.190293580293655,35,4,200,7.30367028154433E-5,-0.621969878673553,0.141032874584198,1,,,,,,,,,,,,,,,,
,3842363406.76703,138.816429138184,100.011535644531,,,6,,,,31.9175035404624,,,100,,,,,,,,,,,,,,,,,,,,,,138.434371948242,139.160308837891,100.011535644531,100.011535644531,,,6.89309644699097,,1,0,0,0,0.0145721435546875,31.7693061828613,2,1,1,139.198486328125,0,2084574048,138.79066619873,,,0.0160478056701839,0.000796549642738131,0.0160883486645226,0.000796580766018137,0.928045630455017,0.985080301761627,31.6488037109375,5.25639057159424,35,4,200,6.4570180256851E-5,-0.643102943897247,0.145145758986473,1,,,,,,,,,,,,,,,,
,3842363491.16763,145.810173034668,100.011535644531,,,6,,,,31.9384373089832,,,100,,,,,,,,,,,,,,,,,,,,,,145.422821044922,146.131271362305,100.011535644531,100.011535644531,,,6.93061876296997,,1,0,0,0,0.0145721435546875,32.2580642700195,2,1,1,146.197525024414,0,2084574112,145.782447814941,,,0.0163177451609806,0.000809790648685983,0.0163557188254855,0.000809819624522711,0.930785179138184,0.985004246234894,31.6805229187012,0,35,4,200,6.37677076156251E-5,-0.652483940124512,0.148613050580025,1,,,,,,,,,,,,,,,,
,3842363576.20403,152.86930847168,100.011535644531,,,6,,,,31.9604748566429,,,100,,,,,,,,,,,,,,,,,,,,,,152.450500488281,153.24787902832,100.011535644531,100.011535644531,,,6.9080171585083,,1,0,0,0,0.0138092041015625,31.7693061828613,2,1,1,153.288116455078,0,2084574112,152.840299987793,,,0.016554087669583,0.00082137447668571,0.0165895792666798,0.000821401505213525,0.933374345302582,0.984792053699493,31.7128925323486,5.25785350799561,35,4,200,2.45650917349849E-5,-0.660825788974762,0.151683390140533,1,,,,,,,,,,,,,,,,
,3842363669.31034,160.560668945313,100.011535644531,,,6,,,,31.9858329435743,,,100,,,,,,,,,,,,,,,,,,,,,,160.158508300781,160.929351806641,100.011535644531,100.011535644531,,,6.91511106491089,,1,0,0,0,0.0145721435546875,32.7468223571777,2,1,1,160.962829589844,0,2084574112,160.547575378418,,,0.0167693064530879,0.000831905802592633,0.0168022351452733,0.000831931413521011,0.936075150966644,0.984739005565643,31.7489280700684,7.56003555579809E-6,35,4,200,5.50491240574047E-5,-0.668375372886658,0.15441869199276,1,,,,,,,,,,,,,,,,
,3842363780.18548,169.747825622559,100.011535644531,,,6,,,,32.0176949437934,,,100,,,,,,,,,,,,,,,,,,,,,,169.362930297852,170.115798950195,100.011535644531,100.011535644531,,,6.93743848800659,,1,0,0,0,0.0145721435546875,31.7693061828613,2,1,1,170.132720947266,0,2084574240,169.737855529785,,,0.016985849211991,0.000842494222572903,0.0170159906172049,0.000842516060529928,0.938988268375397,0.984659314155579,31.792387008667,,35,4,200,5.99437407799996E-5,-0.676029145717621,0.157280042767525,1,,,,,,,,,,,,,,,,
,3842363890.29678,178.897033691406,100.011535644531,,,6,,,,32.051024054528,,,100,,,,,,,,,,,,,,,,,,,,,,178.499542236328,179.260848999023,100.011535644531,100.011535644531,,,6.9519739151001,,1,0,0,0,0.0145721435546875,31.7693061828613,2,1,1,179.294525146484,0,2084574240,178.883302307129,,,0.017169403170526,0.000851459297392985,0.0171969862244187,0.000851478974300022,0.94172066450119,0.984573364257812,31.836597442627,0,35,4,200,7.91191723692464E-6,-0.682544767856598,0.159638211131096,1,,,,,,,,,,,,,,,,
,3842364001.0728,188.112937927246,100.011535644531,,,6,,,,32.0864181634601,,,100,,,,,,,,,,,,,,,,,,,,,,187.725646972656,188.468124389648,100.011535644531,100.011535644531,,,6.95537662506104,,1,0,0,0,0.0146484375,31.7693061828613,2,1,1,188.500228881836,0,2084574272,188.105532836914,,,0.0173298269670162,0.000859288142374021,0.0173550216227071,0.000859305180008718,0.944302320480347,0.984471797943115,31.8823566436768,0,35,4,200,5.32032463524956E-5,-0.688129365444183,0.161749765276909,1,,,,,,,,,,,,,,,,
,3842364111.13624,197.217323303223,100.011535644531,,,6,,,,32.1231891749833,,,100,,,,,,,,,,,,,,,,,,,,,,196.810546875,197.587310791016,100.011535644531,100.011535644531,,,6.96090412139893,,1,0,0,0,0.0145721435546875,33.7243423461914,2,1,1,197.624099731445,0,2084574176,197.201942443848,,,0.0174698425398451,0.000866111686470373,0.0174928531132718,0.000866130692702978,0.946821987628937,0.984405696392059,31.9292411804199,5.26264762878418,35,4,200,5.54472935618833E-5,-0.693076074123383,0.16353902220726,1,,,,,,,,,,,,,,,,
,3842364221.21135,206.374496459961,100.011535644531,,,6,,,,32.161808878702,,,100,,,,,,,,,,,,,,,,,,,,,,205.968658447266,206.747146606445,100.011535644531,100.011535644531,,,6.9726676940918,,1,0,0,0,0.0138092041015625,31.7693061828613,2,1,1,206.780334472656,0,2084574368,206.36999206543,,,0.0175900979449251,0.000871964038370058,0.01761101545019,0.000871980877554308,0.949234008789063,0.984437465667725,31.9774875640869,5.6548638343811,35,4,200,4.81450042570941E-5,-0.696694552898407,0.16514278948307,1,,,,,,,,,,,,,,,,
,3842364331.37152,215.526634216309,100.011535644531,,,6,,,,32.2023397384273,,,100,,,,,,,,,,,,,,,,,,,,,,215.136474609375,215.883270263672,100.011535644531,100.011535644531,,,6.99176454544067,,1,0,0,0,0.0145721435546875,32.2580642700195,2,1,1,215.916793823242,0,2084574240,215.514790344238,,,0.0176971309022972,0.000877174605516973,0.0177161619707876,0.000877188653464222,0.951410114765167,0.984310209751129,32.0269165039063,0,35,4,200,4.03627527703065E-5,-0.701065123081207,0.166422083973885,1,,,,,,,,,,,,,,,,
,3842364442.12613,224.716896057129,100.011535644531,,,6,,,,32.2448136179753,,,100,,,,,,,,,,,,,,,,,,,,,,224.336303710938,225.09748840332,100.011535644531,100.011535644531,,,7.01663446426392,,1,0,0,0,0.0138092041015625,31.7693061828613,2,1,1,225.09748840332,0,2084574176,224.726203918457,,,0.0177874957692581,0.000881565646171779,0.0178048442900548,0.000881579687509191,0.953503251075745,0.984302282333374,32.0778846740723,5.55611404706724E-6,35,4,200,3.98889060306828E-5,-0.704202473163605,0.167611077427864,1,,,,,,,,,,,,,,,,
,3842364552.42076,233.881195068359,100.011535644531,,,6,,,,32.2887429859247,,,100,,,,,,,,,,,,,,,,,,,,,,233.491439819336,234.234741210938,100.011535644531,100.011535644531,,,7.04825735092163,,1,0,0,0,0.0146484375,32.2580642700195,2,1,1,234.270950317383,0,2084574336,233.869082641602,,,0.0178643586603143,0.000885291291293809,0.0178799443435852,0.000885301262466835,0.955582559108734,0.984087109565735,32.1305885314941,0,35,4,200,1.1621606290646E-6,-0.706716775894165,0.168627038598061,1,,,,,,,,,,,,,,,,
,3842364662.46167,243.030616760254,100.011535644531,,,6,,,,32.3343846682023,,,100,,,,,,,,,,,,,,,,,,,,,,242.632995605469,243.388793945313,100.011535644531,100.011535644531,,,7.09504222869873,,1,0,0,0,0.0138092041015625,31.7693061828613,2,1,1,243.428237915039,0,2084574432,243.01371307373,,,0.0179299547276925,0.000888462184569195,0.0179439369757407,0.000888472555023605,0.957656562328339,0.983911335468292,32.1850166320801,0.189920008182526,35,4,200,4.83208314108197E-5,-0.709370493888855,0.158533558249474,1,,,,,,,,,,,,,,,,
,3842364772.53469,252.175712585449,100.011535644531,,,6,,,,32.3818659284584,,,100,,,,,,,,,,,,,,,,,,,,,,251.776992797852,252.540878295898,100.011535644531,100.011535644531,,,7.18089008331299,,1,0,0,0,0.0146484375,33.2355842590332,2,1,1,252.574432373047,0,2084574368,252.16626739502,,,0.0179664152382526,0.00089018543716422,0.0179787834457798,0.000890194150161903,0.959921538829804,0.98416405916214,32.2414512634277,0,35,4,200,4.01851430069655E-5,-0.710683107376099,0.159140169620514,1,,,,,,,,,,,,,,,,
,3842364882.5035,261.321899414062,100.011535644531,,,6,,,,32.4310844349958,,,100,,,,,,,,,,,,,,,,,,,,,,260.936981201172,261.677429199219,100.011535644531,100.011535644531,,,7.15636539459229,,1,0,0,0,0.0138092041015625,31.7693061828613,2,1,1,261.706817626953,0,2084573184,261.311868286133,,,0.0179761606455245,0.000890599462058801,0.0179872739836525,0.000890607445041386,0.961889684200287,0.984661102294922,32.2980194091797,0,35,4,200,7.64710694056703E-6,-0.710546493530273,0.159207060933113,1,,,,,,,,,,,,,,,,
,3842364992.77012,270.47688293457,100.011535644531,,,6,,,,32.4820748909395,,,100,,,,,,,,,,,,,,,,,,,,,,270.087219238281,270.826873779297,100.011535644531,100.011535644531,,,7.14461851119995,,1,0,0,0,0.0145721435546875,31.7693061828613,2,1,1,270.866546630859,0,2084574400,270.458596801758,,,0.0179934226142201,0.000891377724153027,0.0180028841981514,0.000891385797095324,0.964223980903625,0.984270036220551,32.359546661377,0,35,4,200,4.4458472984843E-5,-0.711413204669952,0.159370452165604,1,,,,,,,,,,,,,,,,
,3842365103.23258,279.623413085938,100.011535644531,,,6,,,,32.5350035130782,,,100,,,,,,,,,,,,,,,,,,,,,,279.222076416016,279.991088867187,100.011535644531,100.011535644531,,,7.14821720123291,,1,0,0,0,0.0138092041015625,31.7693061828613,2,1,1,280.024749755859,0,2084574304,279.613821411133,,,0.0180041821608336,0.000891799708801972,0.0180110551783176,0.000891804184433925,0.967889785766602,0.983319103717804,32.4303970336914,INF,35,4,200,4.94984378747176E-5,-0.711896598339081,0.159573137760162,1,,,,,,,,,,,,,,,,
,3842365213.42446,288.768783569336,100.011535644531,,,6,,,,32.5893065615824,,,100,,,,,,,,,,,,,,,,,,,,,,288.356140136719,289.148071289063,100.011535644531,100.011535644531,,,7.20518255233765,,1,0,0,0,0.0145721435546875,31.7693061828613,2,1,1,289.181427001953,0,2084574112,288.762677001953,,,0.0179876776643185,0.000890830266542873,0.0179911777556351,0.000890832757767051,0.973727166652679,0.982480883598328,32.5146903991699,0,35,4,200,4.2692042256931E-7,-0.711286306381226,0.159167170524597,1,,,,,,,,,,,,,,,,
,3842365323.70954,297.961700439453,100.011535644531,,,6,,,,32.6456284187183,,,100,,,,,,,,,,,,,,,,,,,,,,297.5185546875,298.348358154297,100.011535644531,100.011535644531,,,7.34391069412231,,1,0,0,0,0.0138092041015625,31.7693061828613,2,1,1,298.404846191406,0,2084574144,297.973294067383,,,0.0179389320892246,0.000888294346279505,0.0179397148189327,0.000888294991226828,0.979598939418793,0.981822431087494,32.6103401184082,,35,4,200,4.12942099501379E-5,-0.709756970405579,0.158581852912903,1,,,,,,,,,,,,,,,,
,3842365391.06866,299.818084716797,100.011535644531,,,6,,,,32.6550083112967,,,100,,,,,,,,,,,,,,,,,,,,,,299.793395996094,299.840972900391,100.011535644531,100.011535644531,,,7.44367027282715,,1,0,0,0,0.0145721435546875,32.2580642700195,5,1,1,299.8427734375,0,2084574304,299.822143554687,,,0.0179284155223565,0.000887770982689612,0.0179290243585172,0.000887770860279322,0.979742884635925,0.981501817703247,32.6235542297363,2.69603460765211E-5,35,4,200,3.94557646359317E-5,-0.709543287754059,0.158388540148735,1,,,,,,,,,,,,,,,,
,3842366348.73376,5.62658524513245,100.011535644531,,,6,,,,31.7207402641051,,,100,,,,,,,,,,,,,,,,,,,,,,5.26322555541992,5.95263862609863,100.011535644531,100.011535644531,,,3.94474935531616,,1,0,0,0,0.0138092041015625,31.7693061828613,6,1,1,5.98994493484497,0,2084573184,5.60801548957825,,,0.0162363580234632,0.000809844826032777,0.0163576870116381,0.00080995181282364,0.878241777420044,0.982381045818329,31.2604579925537,0,35,4,200,1.3530460819311E-5,-0.653314113616943,0.148692458868027,1,,,,,,,,,,,,,,,,
,3842366407.17027,10.1278882026672,100.011535644531,,,6,,,,31.7207402641051,,,100,,,,,,,,,,,,,,,,,,,,,,9.76043891906738,10.4717597961426,100.011535644531,100.011535644531,,,4.64030027389526,,1,0,0,0,0.0138092041015625,32.2580642700195,6,1,1,10.4953374862671,0,2084573184,10.1137538909912,,,0.0162486553097319,0.000810424435448904,0.0163691203454701,0.000810519077129138,0.878582537174225,0.982323944568634,31.2618541717529,0,35,4,200,1.09967186290305E-5,-0.653962314128876,0.148803353309631,1,,,,,,,,,,,,,,,,
,3842366474.37232,15.4319243431091,100.011535644531,,,6,,,,31.7260844859856,,,100,,,,,,,,,,,,,,,,,,,,,,15.0072622299194,15.8269710540771,100.011535644531,100.011535644531,,,5.5036735534668,,1,0,0,0,0.0138092041015625,31.7693061828613,6,1,1,15.8565864562988,0,2084573184,15.4094703674316,,,0.0162639961370975,0.000811248573766598,0.0163858115794753,0.000811345022064267,0.877988457679748,0.982322335243225,31.2649078369141,,35,4,200,5.72861863474827E-5,-0.654402732849121,0.149061635136604,1,,,,,,,,,,,,,,,,
,3842366534.08644,20.2378664016724,100.011535644531,,,6,,,,31.7260844859856,,,100,,,,,,,,,,,,,,,,,,,,,,19.847770690918,20.5791645050049,100.011535644531,100.011535644531,,,5.72181701660156,,1,0,0,0,0.013885498046875,32.2580642700195,2,1,1,20.6279621124268,0,2084573184,20.1979400634766,,,0.0162800282876202,0.00081192669414538,0.0163995680659884,0.000812025391472664,0.879205942153931,0.982394158840179,31.26953125,0,35,4,200,4.10996653954498E-5,-0.655046164989471,0.149118438363075,1,,,,,,,,,,,,,,,,
,3842366601.38799,25.5910263061523,100.011535644531,,,6,,,,31.7311848915634,,,100,,,,,,,,,,,,,,,,,,,,,,25.2110919952393,25.9382095336914,100.011535644531,100.011535644531,,,5.94783020019531,,1,0,0,0,0.0145721435546875,32.2580642700195,2,1,1,25.9709606170654,0,2084573184,25.5756357192993,,,0.0162930304623843,0.00081251520326239,0.0164115760766245,0.000812619006136349,0.879812479019165,0.982483923435211,31.276927947998,0,35,4,200,2.88186402030988E-6,-0.65533173084259,0.149215444922447,1,,,,,,,,,,,,,,,,
,3842366660.4566,30.3314180374146,100.011535644531,,,6,,,,31.7311848915634,,,100,,,,,,,,,,,,,,,,,,,,,,29.9437294006348,30.6711330413818,100.011535644531,100.011535644531,,,6.03934955596924,,1,0,0,0,0.0145721435546875,31.7693061828613,2,1,1,30.7191066741943,0,2084573184,30.3146421432495,,,0.0163158405911312,0.000813454019913894,0.0164304065008906,0.000813553774354214,0.881829619407654,0.982296586036682,31.2848663330078,0,35,4,200,1.24971411423758E-5,-0.655940413475037,0.149258777499199,1,,,,,,,,,,,,,,,,
,3842366727.83756,35.715539932251,100.011535644531,,,6,,,,31.7363140643549,,,100,,,,,,,,,,,,,,,,,,,,,,35.3357772827148,36.0783996582031,100.011535644531,100.011535644531,,,6.18261671066284,,1,0,0,0,0.0145721435546875,32.2580642700195,2,1,1,36.0953025817871,0,2084573184,35.719295501709,,,0.0163372817929136,0.000814394043040349,0.0164491925860146,0.000814484024815573,0.883160173892975,0.9823037981987,31.2952098846436,0,35,4,200,5.17323169333395E-5,-0.65698379278183,0.149344652891159,1,,,,,,,,,,,,,,,,
,3842366795.30282,41.1338958740234,100.011535644531,,,6,,,,31.7417115247248,,,100,,,,,,,,,,,,,,,,,,,,,,40.7247047424316,41.5241775512695,100.011535644531,100.011535644531,,,6.23565864562988,,1,0,0,0,0.0145721435546875,31.7693061828613,2,1,1,41.5430870056152,0,2084573184,41.1404369354248,,,0.0163577290750488,0.00081524996485288,0.0164666235718389,0.000815347166486962,0.8848637342453,0.98229718208313,31.3072242736816,0,35,4,200,5.10426834807731E-5,-0.657801866531372,0.149535447359085,1,,,,,,,,,,,,,,,,
,3842366862.45875,46.5296783447266,100.011535644531,,,6,,,,31.7471751255642,,,100,,,,,,,,,,,,,,,,,,,,,,46.141429901123,46.8727760314941,100.011535644531,100.011535644531,,,6.31911611557007,,1,0,0,0,0.0145721435546875,31.7693061828613,2,1,1,46.9179267883301,0,2084573184,46.5148551940918,,,0.0163783516034848,0.000816091101035314,0.0164834473806242,0.000816179039274525,0.886841952800751,0.982382297515869,31.3202838897705,0.11812649667263,35,4,200,5.23662420164328E-5,-0.658279955387116,0.149605438113213,1,,,,,,,,,,,,,,,,
,3842366929.71485,51.9621467590332,100.011535644531,,,6,,,,31.7524194785359,,,100,,,,,,,,,,,,,,,,,,,,,,51.5702133178711,52.322940826416,100.011535644531,100.011535644531,,,6.39194679260254,,1,0,0,0,0.0145721435546875,32.2580642700195,2,1,1,52.3540802001953,0,2084573184,51.9565200805664,,,0.0164034998007699,0.000817127989421833,0.0165042521739958,0.000817209168106439,0.88917088508606,0.982361614704132,31.3345966339111,5.23731136322022,35,4,200,4.86357130284887E-5,-0.659252166748047,0.149878576397896,1,,,,,,,,,,,,,,,,
,3842366997.05472,57.443229675293,100.011535644531,,,6,,,,31.7582514636057,,,100,,,,,,,,,,,,,,,,,,,,,,57.0667877197266,57.7884712219238,100.011535644531,100.011535644531,,,6.43372249603271,,1,0,0,0,0.0145721435546875,31.2805480957031,2,1,1,57.8196716308594,0,2084573184,57.4310138702393,,,0.0164273906184623,0.000818097889987346,0.0165236804689994,0.000818171064702749,0.891599833965302,0.98238879442215,31.3498764038086,0.1538175791502,35,4,200,4.80408598377835E-5,-0.660005390644073,0.150137215852737,1,,,,,,,,,,,,,,,,
,3842367064.67229,62.9257621765137,100.011535644531,,,6,,,,31.7636115223286,,,100,,,,,,,,,,,,,,,,,,,,,,62.5396957397461,63.3118286132813,100.011535644531,100.011535644531,,,6.51808786392212,,1,0,0,0,0.0138092041015625,32.2580642700195,2,1,1,63.3118286132813,0,2084573184,62.9098480224609,,,0.0164530292884635,0.000819124126399238,0.0165445197063045,0.000819202009982464,0.894424378871918,0.982441365718842,31.3661651611328,0,35,4,200,4.87417964905035E-5,-0.6607306599617,0.150435581803322,1,,,,,,,,,,,,,,,,
,3842367131.9246,68.4154624938965,100.011535644531,,,6,,,,31.7694420590877,,,100,,,,,,,,,,,,,,,,,,,,,,68.013069152832,68.7629089355469,100.011535644531,100.011535644531,,,6.51135206222534,,1,0,0,0,0.0138092041015625,32.2580642700195,2,1,1,68.8178558349609,0,2084573184,68.3974990844727,,,0.016480758395805,0.000820256764781095,0.0165672382745077,0.000820326633411889,0.897294104099274,0.982460856437683,31.3830909729004,0,35,4,200,1.05574163171696E-5,-0.661617934703827,0.150677934288979,1,,,,,,,,,,,,,,,,
,3842367208.03198,74.5809783935547,100.011535644531,,,6,,,,31.7809644415275,,,100,,,,,,,,,,,,,,,,,,,,,,74.2036056518555,74.9268798828125,100.011535644531,100.011535644531,,,6.55511903762817,,1,0,0,0,0.0138092041015625,32.2580642700195,2,1,1,74.9583511352539,0,2084573184,74.5626502990723,,,0.0165108574373189,0.000821570072368899,0.0165936862530295,0.000821635652349447,0.899485349655151,0.982507109642029,31.4031257629395,5.60384893417358,35,4,200,9.93047251540702E-6,-0.66253262758255,0.151099771261215,1,,,,,,,,,,,,,,,,
,3842367275.02353,80.0209121704102,100.011535644531,,,6,,,,31.7865323064505,,,100,,,,,,,,,,,,,,,,,,,,,,79.6255264282227,80.3748931884766,100.011535644531,100.011535644531,,,6.58539199829102,,1,0,0,0,0.0145721435546875,32.2580642700195,2,1,1,80.4162979125977,0,2084573888,79.9976547241211,,,0.0165435652406611,0.000822929448806274,0.0166211539755597,0.000822996439996874,0.902748584747314,0.982461273670196,31.4214458465576,0,35,4,200,5.75695739826188E-5,-0.663513660430908,0.151448339223862,1,,,,,,,,,,,,,,,,
,3842367351.93142,86.3223190307617,100.011535644531,,,6,,,,31.7985947959932,,,100,,,,,,,,,,,,,,,,,,,,,,85.9429321289063,86.6799697875977,100.011535644531,100.011535644531,,,6.58529806137085,,1,0,0,0,0.0138092041015625,32.2580642700195,2,1,1,86.7017059326172,0,2084573728,86.3079071044922,,,0.0165800268953852,0.00082454873919813,0.0166537974435838,0.000824612376351623,0.905177474021912,0.982470333576202,31.4429321289063,0,35,4,200,8.80005245562643E-6,-0.664544343948364,0.151879236102104,1,,,,,,,,,,,,,,,,
,3842367427.46022,92.613899230957,100.011535644531,,,6,,,,31.8089865047243,,,100,,,,,,,,,,,,,,,,,,,,,,92.222770690918,92.9581680297852,100.011535644531,100.011535644531,,,6.63061237335205,,1,0,0,0,0.0145721435546875,31.7693061828613,2,1,1,93.0050277709961,0,2084573248,92.5887344360351,,,0.0166186810810284,0.000826238279637314,0.0166877594905668,0.000826293583623115,0.908168852329254,0.982495009899139,31.4649486541748,5.60936260223389,35,4,200,1.28152450997732E-5,-0.665798842906952,0.152335703372955,1,,,,,,,,,,,,,,,,
,3842367503.57862,98.8680076599121,100.011535644531,,,6,,,,31.8199389917335,,,100,,,,,,,,,,,,,,,,,,,,,,98.4562377929688,99.2306518554687,100.011535644531,100.011535644531,,,6.6533637046814,,1,0,0,0,0.0138092041015625,31.7693061828613,2,1,1,99.2797775268555,0,2084574016,98.8476547241211,,,0.0166624727288445,0.000828185901949478,0.0167270370650227,0.000828239277792748,0.911215007305145,0.982445597648621,31.487850189209,0.190502837300301,35,4,200,7.48629236113629E-6,-0.66713684797287,0.152823373675346,1,,,,,,,,,,,,,,,,
,3842367579.73595,105.2141456604,100.011535644531,,,6,,,,31.831632137782,,,100,,,,,,,,,,,,,,,,,,,,,,104.844635009766,105.566940307617,100.011535644531,100.011535644531,,,6.65565204620361,,1,0,0,0,0.0138092041015625,31.7693061828613,2,1,1,105.583656311035,0,2084573952,105.204923248291,,,0.0167094232724612,0.000830302950461636,0.0167698033787379,0.000830357379306874,0.914182543754578,0.982424676418304,31.5111656188965,0,35,4,200,4.91298305860255E-5,-0.668760001659393,0.153421893715858,1,,,,,,,,,,,,,,,,
,3842367655.75671,111.462543487549,100.011535644531,,,6,,,,31.8439921318537,,,100,,,,,,,,,,,,,,,,,,,,,,111.050506591797,111.842056274414,100.011535644531,100.011535644531,,,6.70115470886231,,1,0,0,0,0.0145721435546875,32.2580642700195,2,1,1,111.874580383301,0,2084574048,111.456010437012,,,0.0167619290304719,0.000832693245447804,0.0168178069732873,0.000832736239599864,0.917275428771973,0.982281684875488,31.5357532501221,0,35,4,200,5.44837239431217E-5,-0.670424520969391,0.154131218791008,1,,,,,,,,,,,,,,,,
,3842367740.00452,118.442440032959,100.011535644531,,,6,,,,31.8607453299668,,,100,,,,,,,,,,,,,,,,,,,,,,118.055221557617,118.796485900879,100.011535644531,100.011535644531,,,6.73109722137451,,1,0,0,0,0.0138092041015625,32.2580642700195,2,1,1,118.829658508301,0,2084574048,118.423135375977,,,0.0168217305071361,0.000835469892240654,0.0168738616775479,0.000835513312085231,0.920117676258087,0.982194602489471,31.5637187957764,0,35,4,200,1.24475845950656E-5,-0.672329306602478,0.154876708984375,1,,,,,,,,,,,,,,,,
,3842367824.82476,125.442573547363,100.011535644531,,,6,,,,31.8785673401425,,,100,,,,,,,,,,,,,,,,,,,,,,125.04402923584,125.815589904785,100.011535644531,100.011535644531,,,6.7246618270874,,1,0,0,0,0.0138092041015625,32.2580642700195,2,1,1,125.841117858887,0,2084574144,125.43673248291,,,0.0168890770241619,0.000838631113464347,0.0169375382292142,0.000838669257754393,0.922885537147522,0.981979012489319,31.592601776123,0.121624462306499,35,4,200,5.60770131414756E-5,-0.674517512321472,0.155658319592476,1,,,,,,,,,,,,,,,,
,3842367909.32567,132.453804016113,100.011535644531,,,6,,,,31.8972537982423,,,100,,,,,,,,,,,,,,,,,,,,,,132.027328491211,132.813369750977,100.011535644531,100.011535644531,,,6.74759197235107,,1,0,0,0,0.0138092041015625,31.7693061828613,2,1,1,132.880279541016,0,2084574400,132.424221801758,,,0.0169585411125289,0.000841900686000687,0.0170035767437819,0.000841940117229937,0.925686895847321,0.981913030147553,31.6223793029785,0,35,4,200,4.97085129609332E-5,-0.67704439163208,0.156511634588242,1,,,,,,,,,,,,,,,,
,3842367993.76945,139.433372497559,100.011535644531,,,6,,,,31.9171713618904,,,100,,,,,,,,,,,,,,,,,,,,,,139.034255981445,139.815856933594,100.011535644531,100.011535644531,,,6.78960084915161,,1,0,0,0,0.0145721435546875,31.7693061828613,2,1,1,139.832489013672,0,2084574080,139.438371276855,,,0.0170310194496307,0.000845341135656439,0.0170729377867311,0.000845376469944402,0.928230226039886,0.98180079460144,31.652437210083,0,35,4,200,4.85413656861056E-5,-0.679629385471344,0.157448619604111,1,,,,,,,,,,,,,,,,
,3842368078.51579,146.487762451172,100.011535644531,,,6,,,,31.938128374296,,,100,,,,,,,,,,,,,,,,,,,,,,146.09342956543,146.823654174805,100.011535644531,100.011535644531,,,6.78231811523437,,1,0,0,0,0.0145721435546875,32.2580642700195,2,1,1,146.882095336914,0,2084574144,146.459854125977,,,0.0171044195379643,0.000848833784398952,0.0171434411347766,0.000848867836998737,0.930733442306519,0.98177832365036,31.6833171844482,0,35,4,200,4.51161140517797E-5,-0.681924343109131,0.158327296376228,1,,,,,,,,,,,,,,,,
,3842368163.24275,153.518455505371,100.011535644531,,,6,,,,31.9600209245281,,,100,,,,,,,,,,,,,,,,,,,,,,153.117126464844,153.903457641602,100.011535644531,100.011535644531,,,6.77733993530273,,1,0,0,0,0.0145721435546875,31.7693061828613,2,1,1,153.919784545898,0,2084574176,153.517149353027,,,0.0171806479994483,0.000852472221887303,0.0172168188145576,0.000852502394248449,0.933211207389832,0.981690585613251,31.7151279449463,0,35,4,200,6.65669813315617E-6,-0.684572577476502,0.159318938851357,1,,,,,,,,,,,,,,,,
,3842368256.34403,161.266929626465,100.011535644531,,,6,,,,31.988078221877,,,100,,,,,,,,,,,,,,,,,,,,,,160.865386962891,161.627853393555,100.011535644531,100.011535644531,,,6.79777526855469,,1,0,0,0,0.0145721435546875,32.2580642700195,2,1,1,161.668472290039,0,2084574304,161.250289916992,,,0.0172672332882421,0.000856656853661237,0.017301253354952,0.000856684064503609,0.935182392597198,0.981639623641968,31.7511043548584,0,35,4,200,5.45188559044618E-5,-0.687542796134949,0.160556688904762,1,,,,,,,,,,,,,,,,
,3842368366.95969,170.442893981934,100.011535644531,,,6,,,,32.0199395367408,,,100,,,,,,,,,,,,,,,,,,,,,,170.053497314453,170.782516479492,100.011535644531,100.011535644531,,,6.81733560562134,,1,0,0,0,0.0145721435546875,32.2580642700195,2,1,1,170.832290649414,0,2084574336,170.422300720215,,,0.0173734465994966,0.000861767105867514,0.0174044038902728,0.000861792680306587,0.938088536262512,0.981585025787353,31.794620513916,0,35,4,200,4.52637323178351E-6,-0.691194295883179,0.161887899041176,1,,,,,,,,,,,,,,,,
,3842368477.28701,179.601356506348,100.011535644531,,,6,,,,32.0536054634018,,,100,,,,,,,,,,,,,,,,,,,,,,179.207412719727,179.958267211914,100.011535644531,100.011535644531,,,6.83199453353882,,1,0,0,0,0.0145721435546875,32.2580642700195,2,1,1,179.995300292969,0,2084573184,179.584786987305,,,0.0174779768283344,0.000866810112785022,0.0175061016086425,0.000866828144366895,0.940777540206909,0.981580317020416,31.839075088501,0,35,4,200,6.02778454776853E-5,-0.694864869117737,0.163254857063293,1,,,,,,,,,,,,,,,,
,3842368587.83333,188.832183837891,100.011535644531,,,6,,,,32.0890335341324,,,100,,,,,,,,,,,,,,,,,,,,,,188.451950073242,189.166381835938,100.011535644531,100.011535644531,,,6.84847164154053,,1,0,0,0,0.0146484375,31.7693061828613,2,1,1,189.212417602539,0,2084574368,188.808613586426,,,0.0175848573479953,0.000871978256817741,0.0176105033825736,0.000871999604494987,0.943397998809814,0.981476366519928,31.8851795196533,0,35,4,200,8.68788902153028E-6,-0.698548972606659,0.164697036147118,1,,,,,,,,,,,,,,,,
,3842368697.75071,197.884155273438,100.011535644531,,,6,,,,32.1259541776892,,,100,,,,,,,,,,,,,,,,,,,,,,197.485717773438,198.233612060547,100.011535644531,100.011535644531,,,6.85787534713745,,1,0,0,0,0.0145721435546875,31.7693061828613,2,1,1,198.282592773438,0,2084574112,197.858302307129,,,0.0176888512596156,0.000877012198090706,0.0177121202955302,0.000877031728251251,0.945915102958679,0.981432735919952,31.9323387145996,0,35,4,200,5.00378664582968E-5,-0.702340066432953,0.165969654917717,1,,,,,,,,,,,,,,,,
,3842368807.90495,207.035598754883,100.011535644531,,,6,,,,32.1646949594911,,,100,,,,,,,,,,,,,,,,,,,,,,206.633728027344,207.402725219727,100.011535644531,100.011535644531,,,6.86914777755737,,1,0,0,0,0.0145721435546875,31.7693061828613,2,1,1,207.437469482422,0,2084574272,207.024249267578,,,0.0177871348176839,0.000881777067102315,0.0178083141754449,0.000881795370845643,0.948226034641266,0.981410026550293,31.9805450439453,9.1228093879181E-6,35,4,200,4.163860285189E-5,-0.705676853656769,0.167295709252357,1,,,,,,,,,,,,,,,,
,3842368918.09299,216.206321716309,100.011535644531,,,6,,,,32.2053534309155,,,100,,,,,,,,,,,,,,,,,,,,,,215.823303222656,216.556076049805,100.011535644531,100.011535644531,,,6.87828063964844,,1,0,0,0,0.0145721435546875,31.7693061828613,2,1,1,216.589340209961,0,2084574528,216.185856628418,,,0.0178793486476637,0.000886252280430702,0.0178985214692416,0.000886265654186435,0.950359046459198,0.981189250946045,32.0302925109863,0,35,4,200,4.92542276333552E-5,-0.70898962020874,0.168520569801331,1,,,,,,,,,,,,,,,,
,3842369028.1675,225.354682922363,100.011535644531,,,6,,,,32.2477913330314,,,100,,,,,,,,,,,,,,,,,,,,,,224.959289550781,225.705841064453,100.011535644531,100.011535644531,,,6.89673805236816,,1,0,0,0,0.0138092041015625,32.2580642700195,2,1,1,225.750076293945,0,2084574400,225.334190368652,,,0.0179597370556794,0.000890147792233704,0.017977144449724,0.000890160105159111,0.952418148517609,0.98111492395401,32.0813674926758,0,35,4,200,4.50679035566282E-5,-0.711790978908539,0.169552892446518,1,,,,,,,,,,,,,,,,
,3842369138.47009,234.480628967285,100.011535644531,,,6,,,,32.2916944769108,,,100,,,,,,,,,,,,,,,,,,,,,,234.072387695313,234.854415893555,100.011535644531,100.011535644531,,,6.92095804214478,,1,0,0,0,0.0145721435546875,31.7693061828613,2,1,1,234.888870239258,0,2084574208,234.468571472168,,,0.0180303483227091,0.000893562931917049,0.018046113859863,0.00089357622742209,0.95444393157959,0.981047630310059,32.1338539123535,0,35,4,200,5.17858134116977E-5,-0.714199364185333,0.170440226793289,1,,,,,,,,,,,,,,,,
,3842369248.75781,243.686622619629,100.011535644531,,,6,,,,32.3375862034308,,,100,,,,,,,,,,,,,,,,,,,,,,243.290069580078,244.049392700195,100.011535644531,100.011535644531,,,6.97069501876831,,1,0,0,0,0.0138092041015625,31.7693061828613,2,1,1,244.08317565918,0,2084574208,243.667475891113,,,0.0180908018584707,0.000896477631622354,0.0181048839728355,0.000896488017911593,0.956469178199768,0.980931222438812,32.1884841918945,0,35,4,200,4.69193037133664E-5,-0.716256737709045,0.171188861131668,1,,,,,,,,,,,,,,,,
,3842369358.71115,252.761123657227,100.011535644531,,,6,,,,32.3849824518005,,,100,,,,,,,,,,,,,,,,,,,,,,252.355133056641,253.123413085938,100.011535644531,100.011535644531,,,7.03853225708008,,1,0,0,0,0.0146484375,31.7693061828613,2,1,1,253.167114257813,0,2084574208,252.748277282715,,,0.0181048888064425,0.000897081624309847,0.0181173227287378,0.000897089931477952,0.958950817584991,0.981783270835876,32.2447891235352,0,35,4,200,4.89677477162331E-5,-0.716784477233887,0.16069333255291,1,,,,,,,,,,,,,,,,
,3842369468.63095,261.958999633789,100.011535644531,,,6,,,,32.4343225056255,,,100,,,,,,,,,,,,,,,,,,,,,,261.578643798828,262.305816650391,100.011535644531,100.011535644531,,,7.01147699356079,,1,0,0,0,0.0145721435546875,31.7693061828613,2,1,1,262.33935546875,0,2084574112,261.941384887695,,,0.018115270697629,0.000897525872386039,0.0181264467002486,0.000897533187527104,0.960898339748383,0.982312023639679,32.3014221191406,0,35,4,200,4.02636578655802E-5,-0.71662425994873,0.160503402352333,1,,,,,,,,,,,,,,,,
,3842369578.68922,271.024307250977,100.011535644531,,,6,,,,32.485391875432,,,100,,,,,,,,,,,,,,,,,,,,,,270.62890625,271.365936279297,100.011535644531,100.011535644531,,,7.01919984817505,,1,0,0,0,0.0145721435546875,31.7693061828613,2,1,1,271.419708251953,0,2084574176,270.999252319336,,,0.0181231259138861,0.000897831889257562,0.0181326005753605,0.000897837572736787,0.963342607021332,0.982337474822998,32.3629760742188,0,35,4,200,4.47003512817901E-5,-0.716846227645874,0.16061569750309,1,,,,,,,,,,,,,,,,
,3842369689.0633,280.218673706055,100.011535644531,,,6,,,,32.5383751509133,,,100,,,,,,,,,,,,,,,,,,,,,,279.790985107422,280.596588134766,100.011535644531,100.011535644531,,,7.01596212387085,,1,0,0,0,0.0146484375,31.7693061828613,2,1,1,280.646362304687,0,2084574368,280.200506591797,,,0.0181222063782224,0.000897666602851124,0.0181288748778317,0.00089767137627109,0.967167556285858,0.981203436851501,32.4358253479004,,35,4,200,4.36069349234458E-5,-0.717049121856689,0.160684943199158,1,,,,,,,,,,,,,,,,
,3842369798.73157,289.274139404297,100.011535644531,,,6,,,,32.5924416396941,,,100,,,,,,,,,,,,,,,,,,,,,,288.904235839844,289.607391357422,100.011535644531,100.011535644531,,,7.07456016540527,,1,0,0,0,0.0145721435546875,32.2580642700195,2,1,1,289.664886474609,0,2084574368,289.257622612847,,,0.018100602315291,0.000896450524723994,0.018103837931979,0.000896451876247475,0.972570776939392,0.980047643184662,32.5207710266113,5.70120892007253E-6,35,4,200,4.49732942797709E-5,-0.716437816619873,0.160332769155502,1,,,,,,,,,,,,,,,,
,3842369909.1319,298.392547607422,100.011535644531,,,6,,,,32.6490084526224,,,100,,,,,,,,,,,,,,,,,,,,,,298.040405273438,298.720642089844,100.011535644531,100.011535644531,,,7.21147155761719,,1,0,0,0,0.0138092041015625,31.7693061828613,2,1,1,298.744689941406,0,2084574304,298.400274658203,,,0.0180360244808036,0.000893134450173093,0.0180366864723354,0.000893134541055706,0.977895438671112,0.979617595672607,32.6164398193359,2.08580277103465E-5,35,4,200,-9.58995406108443E-6,-0.714315354824066,0.159489706158638,1,,,,,,,,,,,,,,,,
,3842369976.28423,299.856628417969,100.011535644531,,,6,,,,32.6555185766413,,,100,,,,,,,,,,,,,,,,,,,,,,299.838134765625,299.873565673828,100.011535644531,100.011535644531,,,7.36326599121094,,1,0,0,0,0.0145721435546875,31.7693061828613,5,1,1,299.875122070313,0,2084574208,299.858764648438,,,0.0180253077831962,0.000892602491009511,0.0180258404579082,0.000892602567936145,0.977965176105499,0.979344964027405,32.6263008117676,0.189796850085258,35,4,200,4.21943550463766E-5,-0.71405029296875,0.159307479858398,1,,,,,,,,,,,,,,,,
,3842370005.54392,299.936676025391,100.011535644531,,,6,,,,32.6555185766413,,,100,,,,,,,,,,,,,,,,,,,,,,299.927947998047,299.943634033203,100.011535644531,100.011535644531,,,7.42370986938477,,1,0,0,0,0.0138092041015625,32.2580642700195,1,1,1,299.945404052734,0,2084574400,299.938150024414,,,0.0180264672634705,0.000892656755710767,0.0180269143185883,0.000892656378181704,0.978122353553772,0.979306757450104,32.6284866333008,,35,4,200,4.22656412411015E-5,-0.71413916349411,0.15932334959507,1,,,,,,,,,,,,,,,,