File: Data/KMK245S/MvsH/KMK245S_MvsH_300K.dat
[Header]
; MPMS3 Data File (default extension .dat)
; Copyright (c) 2007, Quantum Design, Inc. All rights reserved.
TITLE,
FILEOPENTIME,3889794326.59515,04/04/2023,7:27 pm
BYAPP,MPMS3 w/ AC,1.0,1.1
INFO,MPMS3 Measurement Release 1.1.16 Build 424, MultiVu Release 2.3.4.19,APPNAME
INFO,Linear Motor Servo Controller,MOTOR_MODULE_NAME
INFO,3101-100 J0,MOTOR_HW_VERSION
INFO,MMC721,MOTOR_SERIAL_NUMBER
INFO,01.04.28,MOTOR_SOFTWARE_VERSION
INFO,Quantum Design Squid Module,SQUID_MODULE_NAME
INFO,3101-501 B0,SQUID_HW_VERSION
INFO,SQM195,SQUID_SERIAL_NUMBER
INFO,01.03.04,SQUID_SOFTWARE_VERSION
INFO,SQUID AC,AC_MODULE_NAME
INFO,3101-401 f1,AC_HW_VERSION
INFO,SAC107,AC_SERIAL_NUMBER
INFO,SQUID AC 00.95.07,AC_SOFTWARE_VERSION
INFO,TCI166,COIL_SERIAL_NUMBER
INFO,0,MOMENT_UNITS
INFO,KMK245S,SAMPLE_MATERIAL
INFO,,SAMPLE_COMMENT
INFO,1.6,SAMPLE_MASS
INFO,,SAMPLE_VOLUME
INFO,,SAMPLE_MOLECULAR_WEIGHT
INFO,,SAMPLE_SIZE
INFO,,SAMPLE_SHAPE
INFO,Standard,SAMPLE_HOLDER
INFO,Standard,SAMPLE_HOLDER_DETAIL
INFO,66.64,SAMPLE_OFFSET
DATATYPE,COMMENT,1
DATATYPE,TIME,2
STARTUPAXIS,X,2
STARTUPAXIS,Y1,5
FIELDGROUP, VSM,2,3,4,5,6,8,9,10,11,14,15
FIELDGROUP, DC, 2,3,4,14,56,57,58,59,60,61,62,63,64,65,66,67,68,69
FIELDGROUP, AC, 2,3,4,11,16,17,18,19,20,21,22,23,24,25,26,27,28,29,30
STARTUPGROUP, All
[Data]
Comment,Time Stamp (sec),Temperature (K),Magnetic Field (Oe),Moment (emu),M. Std. Err. (emu),Transport Action,Averaging Time (sec),Frequency (Hz),Peak Amplitude (mm),Center Position (mm),Lockin Signal' (V),Lockin Signal (V),Range,M. Quad. Signal (emu),AC Moment (emu),AC M. Std Err. (emu),AC Phase (deg),AC Phase Std. Err. (deg),AC Susceptibility (emu/Oe),AC Suscept. Std Err. (emu/Oe),AC X' (emu/Oe),AC X' Std Err. (emu/Oe),AC X'' (emu/Oe),AC X'' Std Err. (emu/Oe),AC Drive (Oe),AC Frequency (Hz),AC Averaging Time (sec),AC Cycles,AC Range,AC Measure Type,AC Signal' (V),AC Signal'' (V),AC Trim Coil Ratio,AC Trim Coil Phase,Min. Temperature (K),Max. Temperature (K),Min. Field (Oe),Max. Field (Oe),Mass (grams),Motor Lag (deg),Pressure (Torr),Measure Count,Measurement Number,SQUID Status (code),Motor Status (code),Measure Status (code),Motor Current (amps),Motor Temp. (C),Temp. Status (code),Field Status (code),Chamber Status (code),Chamber Temp (K),Redirection State,Evercool Status,Average Temp (K),Rotation Angle (deg),Rotator state,DC Moment Fixed Ctr (emu),DC Moment Err Fixed Ctr (emu),DC Moment Free Ctr (emu),DC Moment Err Free Ctr (emu),DC Fixed Fit,DC Free Fit,DC Calculated Center (mm),DC Calculated Center Err (mm),DC Scan Length (mm),DC Scan Time (s),DC Number of Points,DC Squid Drift,DC Min V (V),DC Max V (V),DC Scans per Measure,Map 01,Map 02,Map 03,Map 04,Map 05,Map 06,Map 07,Map 08,Map 09,Map 10,Map 11,Map 12,Map 13,Map 14,Map 15,Map 16
,3889794461.83126,300.082443237305,-70000.4609375,,,6,,,,32.1933631896973,,,10,,,,,,,,,,,,,,,,,,,,,,300.079040527344,300.097503662109,-70000.4609375,-70000.4609375,,,7.49514961242676,,1,0,0,0,0.01953125,32.7468223571777,1,1,1,300.081481933594,0,2084575008,300.088653564453,,,-0.00400215971935133,0.000203984112527618,-0.00401198333448419,0.000203992809820966,0.794012129306793,0.805561244487762,32.4482154846191,0.000407245242968202,35,4,200,-0.0310079455375671,-0.998642802238464,1.35418772697449,1,,,,,,,,,,,,,,,,
,3889794618.07224,300.154876708984,-45000.19140625,,,6,,,,32.1933631896973,,,10,,,,,,,,,,,,,,,,,,,,,,300.138031005859,300.171295166016,-45000.19140625,-45000.19140625,,,7.55724000930786,,1,0,0,0,0.0186920166015625,32.7468223571777,1,1,1,300.171722412109,0,2084574880,300.162176513672,,,-0.00415198827429445,0.000209111054343695,-0.0041565249210958,0.000209116168928278,0.861041843891144,0.868800938129425,32.3652763366699,5.68904876708984,35,4,200,0.032841295003891,-0.681250810623169,1.59181582927704,1,,,,,,,,,,,,,,,,
,3889794774.41083,300.00895690918,-20000.302734375,,,6,,,,32.1933631896973,,,10,,,,,,,,,,,,,,,,,,,,,,299.994506835937,300.024780273438,-20000.302734375,-20000.302734375,,,7.60008096694946,,1,0,0,0,0.017242431640625,32.7468223571777,1,1,1,299.99609375,0,2084574784,300.013647460937,,,-0.00427378782399074,0.000213703244896509,-0.00427504442971824,0.000213704775922107,0.928556203842163,0.932669878005981,32.2835693359375,,35,4,200,0.031426727771759,-0.553204238414764,1.75324845314026,1,,,,,,,,,,,,,,,,
,3889794923.92215,300.026672363281,-8500.1982421875,,,6,,,,32.1933631896973,,,10,,,,,,,,,,,,,,,,,,,,,,300.018371582031,300.041931152344,-8500.1982421875,-8500.1982421875,,,7.63301372528076,,1,0,0,0,0.0199127197265625,33.2355842590332,1,1,1,300.020294189453,0,2084575040,300.032626681858,,,-0.00429775370030115,0.000214554342991954,-0.00429829544686916,0.000214555375221658,0.956634998321533,0.95952183008194,32.2523155212402,7.04247999191284,35,4,200,0.0340591594576836,-0.443417191505432,1.74732279777527,1,,,,,,,,,,,,,,,,
,3889795047.37444,299.974533081055,-6000.4111328125,,,6,,,,32.1933631896973,,,10,,,,,,,,,,,,,,,,,,,,,,299.970703125,299.989807128906,-6000.4111328125,-6000.4111328125,,,7.65271377563477,,1,0,0,0,0.0189971923828125,32.2580642700195,1,1,1,299.978363037109,0,2084574848,299.980847167969,,,-0.00428942001396573,0.000214088396401737,-0.00428983119496487,0.000214089067527614,0.96237325668335,0.964920461177826,32.2449836730957,5.22804021835327,35,4,200,0.0270991921424866,-0.463844567537308,1.74444985389709,1,,,,,,,,,,,,,,,,
,3889795173.16893,300.101013183594,-3500.3916015625,,,6,,,,32.1933631896973,,,10,,,,,,,,,,,,,,,,,,,,,,300.096954345703,300.121459960937,-3500.3916015625,-3500.3916015625,,,7.67104721069336,,1,0,0,0,0.0152587890625,32.7468223571777,1,1,1,300.105072021484,0,2084574848,300.110543823242,,,-0.00424782474090063,0.000211974648016552,-0.00424813203905382,0.000211974744424032,0.96743631362915,0.969721853733063,32.2388648986816,,35,4,200,0.0211894977837801,-0.382849097251892,1.71309506893158,1,,,,,,,,,,,,,,,,
,3889795295.7163,300.120315551758,-1000.22534179688,,,6,,,,32.1933631896973,,,10,,,,,,,,,,,,,,,,,,,,,,300.118103027344,300.136505126953,-1000.22534179688,-1000.22534179688,,,7.68806838989258,,1,0,0,0,0.013885498046875,32.7468223571777,1,1,1,300.119232177734,0,2084574912,300.127252197266,,,-0.00387689760999173,0.000193436881417954,-0.00387709944804642,0.000193437072840301,0.97219854593277,0.974099159240723,32.231761932373,0,35,4,200,0.0116112725809217,-0.386029094457626,1.56290555000305,1,,,,,,,,,,,,,,,,
,3889795424.15626,300.190170288086,-760.26123046875,,,6,,,,32.1933631896973,,,10,,,,,,,,,,,,,,,,,,,,,,300.189178466797,300.202056884766,-760.26123046875,-760.26123046875,,,7.70422792434692,,1,0,0,0,0.017852783203125,32.7468223571777,1,1,1,300.19091796875,0,2084575136,300.194995117188,,,-0.00370117885864097,0.000184673573920017,-0.00370132451967736,0.00018467362900607,0.971398413181305,0.972797095775604,32.2269287109375,8.04750379757024E-6,35,4,200,-0.0171034075319767,-0.431822270154953,1.41819858551025,1,,,,,,,,,,,,,,,,
,3889795541.79085,300.164474487305,-710.286010742188,,,6,,,,32.1933631896973,,,10,,,,,,,,,,,,,,,,,,,,,,300.162353515625,300.183563232422,-710.286010742188,-710.286010742188,,,7.71691226959229,,1,0,0,0,0.013885498046875,32.2580642700195,1,1,1,300.166595458984,0,2084575104,300.172128295898,,,-0.00365631185401751,0.000182430477994522,-0.0036564797093486,0.000182430534719203,0.972256124019623,0.973950147628784,32.2296447753906,,35,4,200,-0.0150686157867312,-0.447931855916977,1.38711106777191,1,,,,,,,,,,,,,,,,
,3889795658.43973,300.088760375977,-660.261901855469,,,6,,,,32.1933631896973,,,10,,,,,,,,,,,,,,,,,,,,,,300.07958984375,300.103149414063,-660.261901855469,-660.261901855469,,,7.72817993164062,,1,0,0,0,0.0150299072265625,32.7468223571777,1,1,1,300.082275390625,0,2084575008,300.092645263672,,,-0.003603570050561,0.000179797574910028,-0.00360372858619455,0.000179797893066812,0.972538650035858,0.974120676517487,32.2282829284668,3.86859428544994E-5,35,4,200,-0.0173517540097237,-0.391972064971924,1.40693461894989,1,,,,,,,,,,,,,,,,
,3889795771.32497,300.076141357422,-610.311157226563,,,6,,,,32.1933631896973,,,10,,,,,,,,,,,,,,,,,,,,,,300.063018798828,300.09033203125,-610.311157226563,-610.311157226563,,,7.73780536651611,,1,0,0,0,0,32.7468223571777,1,1,1,300.065063476562,0,2084574976,300.079803466797,,,-0.00354178026721487,0.00017671608140445,-0.00354191957842494,0.00017671617921677,0.972226977348328,0.973659157752991,32.2268180847168,0,35,4,200,-0.0181671548634768,-0.458345383405685,1.30818295478821,1,,,,,,,,,,,,,,,,
,3889795891.08233,300.20622253418,-560.384826660156,,,6,,,,32.1933631896973,,,10,,,,,,,,,,,,,,,,,,,,,,300.199371337891,300.224151611328,-560.384826660156,-560.384826660156,,,7.74724960327148,,1,0,0,0,0.013885498046875,32.2580642700195,1,1,1,300.213073730469,0,2084574976,300.214920043945,,,-0.00347010054856554,0.000173140364476972,-0.00347026086055283,0.000173140445454491,0.972085654735565,0.973773717880249,32.2296943664551,5.22957992553711,35,4,200,-0.0164514016360044,-0.430629879236221,1.34572458267212,1,,,,,,,,,,,,,,,,
,3889796005.99096,300.102493286133,-510.372924804687,,,6,,,,32.1933631896973,,,10,,,,,,,,,,,,,,,,,,,,,,300.080505371094,300.123718261719,-510.372924804687,-510.372924804687,,,7.7580680847168,,1,0,0,0,0.0164031982421875,32.7468223571777,1,1,1,300.081268310547,0,2084574912,300.107135009766,,,-0.00339358154720495,0.000169322445901431,-0.00339371572949246,0.000169322318815363,0.972087979316711,0.973569691181183,32.227466583252,0,35,4,200,-0.0172209460288286,-0.358851283788681,1.34105229377747,1,,,,,,,,,,,,,,,,
,3889796119.87928,300.080291748047,-460.373260498047,,,6,,,,32.1933631896973,,,10,,,,,,,,,,,,,,,,,,,,,,300.052215576172,300.104583740234,-460.373260498047,-460.373260498047,,,7.76756763458252,,1,0,0,0,0.013885498046875,32.2580642700195,1,1,1,300.108367919922,0,2084575040,300.087908935547,,,-0.00330133440531521,0.000164719079471071,-0.0033014845331149,0.000164719251430669,0.972228169441223,0.97387570142746,32.2291717529297,0,35,4,200,-0.0180137753486633,-0.403252393007278,1.29680395126343,1,,,,,,,,,,,,,,,,
,3889796236.39161,300.150375366211,-410.3125,,,6,,,,32.1933631896973,,,10,,,,,,,,,,,,,,,,,,,,,,300.135589599609,300.168395996094,-410.3125,-410.3125,,,7.77796077728271,,1,0,0,0,0.01708984375,32.2580642700195,1,1,1,300.165161132812,0,2084575072,300.158715820313,,,-0.00319487521824742,0.000159407896727131,-0.00319502548022942,0.000159408501799747,0.972110509872436,0.973705232143402,32.2286949157715,5.72456337977201E-5,35,4,200,-0.0203054714947939,-0.427146553993225,1.16816210746765,1,,,,,,,,,,,,,,,,
,3889796350.72981,300.09553527832,-360.288421630859,,,6,,,,32.1933631896973,,,10,,,,,,,,,,,,,,,,,,,,,,300.086090087891,300.108947753906,-360.288421630859,-360.288421630859,,,7.78748178482056,,1,0,0,0,0.01861572265625,31.2805480957031,1,1,1,300.087066650391,0,2084574976,300.099423217773,,,-0.00306826949178146,0.000153090020929361,-0.00306839657276644,0.000153090161106804,0.972316086292267,0.973818778991699,32.2275581359863,0,35,4,200,-0.018290676176548,-0.325490325689316,1.21190369129181,1,,,,,,,,,,,,,,,,
,3889796465.05578,300.169906616211,-310.154327392578,,,6,,,,32.1933631896973,,,10,,,,,,,,,,,,,,,,,,,,,,300.154968261719,300.187225341797,-310.154327392578,-310.154327392578,,,7.79638671875,,1,0,0,0,0.01617431640625,32.2580642700195,1,1,1,300.155700683594,0,2084574944,300.174606323242,,,-0.00291314907036651,0.000145352595456241,-0.0029132744280539,0.000145352765511724,0.971769213676453,0.973291993141174,32.2281227111816,5.67698192596436,35,4,200,-0.0190124083310366,-0.35854384303093,1.09954643249512,1,,,,,,,,,,,,,,,,
,3889796579.69188,300.129333496094,-260.117980957031,,,6,,,,32.1933631896973,,,10,,,,,,,,,,,,,,,,,,,,,,300.126708984375,300.149505615234,-260.117980957031,-260.117980957031,,,7.80254507064819,,1,0,0,0,0.01739501953125,32.7468223571777,1,1,1,300.131958007812,0,2084574976,300.138345336914,,,-0.00272492703461786,0.000135956319164983,-0.002725045020248,0.000135956516981212,0.973066866397858,0.974666893482208,32.2281303405762,0.197930157184601,35,4,200,-0.0168673116713762,-0.352241069078445,1.06306600570679,1,,,,,,,,,,,,,,,,
,3889796691.9932,299.988403320313,-210.093887329102,,,6,,,,32.1933631896973,,,10,,,,,,,,,,,,,,,,,,,,,,299.974212646484,300.001251220703,-210.093887329102,-210.093887329102,,,7.8080940246582,,1,0,0,0,0.013885498046875,32.7468223571777,1,1,1,300.002593994141,0,2084574944,299.993542480469,,,-0.0024654240839047,0.000123012826819849,-0.00246550730433244,0.00012301278994094,0.971874177455902,0.973111271858215,32.224723815918,,35,4,200,-0.0182905346155167,-0.292221873998642,0.952245116233826,1,,,,,,,,,,,,,,,,
,3889796807.29935,300.134948730469,-160.082000732422,,,6,,,,32.1933631896973,,,10,,,,,,,,,,,,,,,,,,,,,,300.1201171875,300.152099609375,-160.082000732422,-160.082000732422,,,7.81265449523926,,1,0,0,0,0.013885498046875,32.7468223571777,1,1,1,300.121215820313,0,2084574912,300.13942565918,,,-0.00209070011167859,0.000104317198555083,-0.00209078176775967,0.000104317305205436,0.971449136734009,0.97281277179718,32.2264976501465,,35,4,200,-0.0177458487451077,-0.242291197180748,0.82352089881897,1,,,,,,,,,,,,,,,,
,3889796922.05768,300.123321533203,-110.155685424805,,,6,,,,32.1933631896973,,,10,,,,,,,,,,,,,,,,,,,,,,300.112030029297,300.139221191406,-110.155685424805,-110.155685424805,,,7.8168420791626,,1,0,0,0,0.0176239013671875,32.7468223571777,1,1,1,300.134613037109,0,2084574944,300.130212402344,,,-0.00150730834229637,7.52112407329164E-5,-0.00150737097750348,7.52112493146819E-5,0.970138549804687,0.97155886888504,32.2279319763184,6.19036873104051E-5,35,4,200,-0.018355006352067,-0.231610998511314,0.550093650817871,1,,,,,,,,,,,,,,,,
,3889797036.04456,299.983489990234,-60.2415771484375,,,6,,,,32.1933631896973,,,10,,,,,,,,,,,,,,,,,,,,,,299.965454101562,300.000640869141,-60.2415771484375,-60.2415771484375,,,7.81976461410522,,1,0,0,0,0.013885498046875,32.7468223571777,1,1,1,299.966339111328,0,2084574976,299.984219360352,,,-0.000581059962479409,2.9003483289793E-5,-0.000581073334758974,2.90034871154069E-5,0.960321128368378,0.960901141166687,32.2190055847168,0,35,4,200,-0.0178445857018232,-0.113524094223976,0.219973549246788,1,,,,,,,,,,,,,,,,
,3889797160.65225,300.152984619141,-10.1930370330811,,,6,,,,32.1933631896973,,,1,,,,,,,,,,,,,,,,,,,,,,300.146209716797,300.168426513672,-10.1930370330811,-10.1930370330811,,,7.8265380859375,,1,0,0,0,0.0173187255859375,32.2580642700195,1,1,1,300.159759521484,0,2084574848,300.159530639648,,,0.000597512627781589,2.98147760953587E-5,0.000597554718992761,2.98148117989428E-5,0.96984589099884,0.972234964370728,32.2382316589355,,35,4,200,-0.15888150036335,-3.25993800163269,0.156356438994408,1,,,,,,,,,,,,,,,,
,3889797281.99054,300.020797729492,39.977725982666,,,6,,,,32.1933631896973,,,10,,,,,,,,,,,,,,,,,,,,,,300.003173828125,300.035949707031,39.977725982666,39.977725982666,,,7.8349084854126,,1,0,0,0,0.013885498046875,31.7693061828613,1,1,1,300.038421630859,0,2084575040,300.025717163086,,,0.00152891731291064,7.62842440107898E-5,0.00152903068164334,7.6284330419705E-5,0.972535252571106,0.975334584712982,32.2393493652344,0,35,4,200,-0.0170614458620548,-0.692663013935089,0.149869367480278,1,,,,,,,,,,,,,,,,
,3889797397.0309,300.102020263672,90.0751571655273,,,6,,,,32.1933631896973,,,10,,,,,,,,,,,,,,,,,,,,,,300.092254638672,300.118896484375,90.0751571655273,90.0751571655273,,,7.84251976013184,,1,0,0,0,0.0148773193359375,32.7468223571777,1,1,1,300.09423828125,0,2084573184,300.108480834961,,,0.00210149801558155,0.000104849138822188,0.00210161396774392,0.000104849212699427,0.973818063735962,0.975987017154694,32.2330513000488,0,35,4,200,-0.0194109454751015,-0.9193035364151,0.138145446777344,1,,,,,,,,,,,,,,,,
,3889797512.02091,300.100082397461,140.209243774414,,,6,,,,32.1933631896973,,,10,,,,,,,,,,,,,,,,,,,,,,300.088989257812,300.112274169922,140.209243774414,140.209243774414,,,7.84852027893066,,1,0,0,0,0.013885498046875,32.7468223571777,1,1,1,300.111175537109,0,2084575040,300.105352783203,,,0.0024736283219979,0.00012341747411439,0.00247378351764262,0.000123417734486276,0.973272502422333,0.975644707679748,32.2352294921875,0,35,4,200,-0.0182609651237726,-1.0297976732254,0.210814520716667,1,,,,,,,,,,,,,,,,
,3889797631.75494,300.148986816406,190.160018920898,,,6,,,,32.1933631896973,,,10,,,,,,,,,,,,,,,,,,,,,,300.142883300781,300.166107177734,190.160018920898,190.160018920898,,,7.85506105422974,,1,0,0,0,0,32.7468223571777,1,1,1,300.155090332031,0,2084574944,300.156451416016,,,0.00272957361446573,0.000136191723196693,0.00272977457009158,0.000136191955110249,0.972109436988831,0.974817633628845,32.2389526367188,,35,4,200,-0.0166440177708864,-1.13757002353668,0.228470727801323,1,,,,,,,,,,,,,,,,
,3889797749.02934,300.149826049805,240.159698486328,,,6,,,,32.1933631896973,,,10,,,,,,,,,,,,,,,,,,,,,,300.135101318359,300.165222167969,240.159698486328,240.159698486328,,,7.85858583450317,,1,0,0,0,0,32.2580642700195,1,1,1,300.135925292969,0,2084575008,300.153482055664,,,0.00292253186715711,0.000145819612585636,0.00292273586307921,0.000145819920003518,0.972051620483398,0.97458690404892,32.2375946044922,7.05196862327284E-6,35,4,200,-0.0182859618216753,-1.24133253097534,0.287032842636108,1,,,,,,,,,,,,,,,,
,3889797863.24052,300.005310058594,290.02490234375,,,6,,,,32.1933631896973,,,10,,,,,,,,,,,,,,,,,,,,,,299.990997314453,300.021209716797,290.02490234375,290.02490234375,,,7.86174154281616,,1,0,0,0,0.013885498046875,32.2580642700195,1,1,1,300.019622802734,0,2084575104,300.012225341797,,,0.00307872532315393,0.000153609096835897,0.00307891671031492,0.000153609569435743,0.972939014434814,0.975216865539551,32.234691619873,5.67756032943726,35,4,200,-0.0187017805874348,-1.237673163414,0.292998194694519,1,,,,,,,,,,,,,,,,
,3889797979.20465,300.06169128418,340.122314453125,,,6,,,,32.1933631896973,,,10,,,,,,,,,,,,,,,,,,,,,,300.055450439453,300.073577880859,340.122314453125,340.122314453125,,,7.86606645584106,,1,0,0,0,0.0148773193359375,31.7693061828613,1,1,1,300.057495117188,0,2084574944,300.06575012207,,,0.00320255008866616,0.000159787971700126,0.00320273073818288,0.000159788160731623,0.972763001918793,0.974870681762695,32.2333145141602,5.67743921279907,35,4,200,-0.018241984769702,-1.30654871463776,0.285228312015533,1,,,,,,,,,,,,,,,,
,3889798097.38612,300.045684814453,390.170867919922,,,6,,,,32.1933631896973,,,10,,,,,,,,,,,,,,,,,,,,,,300.030487060547,300.063568115234,390.170867919922,390.170867919922,,,7.87143898010254,,1,0,0,0,0.013885498046875,32.2580642700195,1,1,1,300.060882568359,0,2084575136,300.054092407227,,,0.003309204038301,0.000165107199085984,0.00330941018398376,0.000165107606958082,0.973241806030273,0.975578010082245,32.2349395751953,0,35,4,200,-0.0156752225011587,-1.40314030647278,0.257686764001846,1,,,,,,,,,,,,,,,,
,3889798212.95298,300.065658569336,440.170562744141,,,6,,,,32.1933631896973,,,10,,,,,,,,,,,,,,,,,,,,,,300.046539306641,300.084167480469,440.170562744141,440.170562744141,,,7.87690877914429,,1,0,0,0,0,32.7468223571777,1,1,1,300.047149658203,0,2084575008,300.07001953125,,,0.00339964149503313,0.00016962522464812,0.00339986829826779,0.000169625745656457,0.971989274024963,0.97435998916626,32.2362442016602,0.44441494345665,35,4,200,-0.016754599288106,-1.41635155677795,0.335113316774368,1,,,,,,,,,,,,,,,,
,3889798330.91838,300.04753112793,490.255737304687,,,6,,,,32.1933631896973,,,10,,,,,,,,,,,,,,,,,,,,,,300.024444580078,300.069610595703,490.255737304687,490.255737304687,,,7.88045215606689,,1,0,0,0,0.013885498046875,32.7468223571777,1,1,1,300.025451660156,0,2084575040,300.047982788086,,,0.00347946680249243,0.000173607586562501,0.00347969775650079,0.000173608265238371,0.972102046012878,0.974437236785889,32.2358512878418,7.00680902809836E-6,35,4,200,-0.017426498234272,-1.46342945098877,0.269942462444305,1,,,,,,,,,,,,,,,,
,3889798451.26046,300.087966918945,540.365356445313,,,6,,,,32.1933631896973,,,100,,,,,,,,,,,,,,,,,,,,,,300.075866699219,300.113525390625,540.365356445313,540.365356445313,,,7.88458061218262,,1,0,0,0,0.0162506103515625,32.2580642700195,1,1,1,300.100067138672,0,2084574976,300.09835494192,,,0.00352504081099339,0.000175882837066407,0.00352521542329803,0.00017588322801991,0.971835136413574,0.973566889762878,32.2303161621094,0,35,4,200,0.0015849363990128,-1.46842563152313,0.491811126470566,1,,,,,,,,,,,,,,,,
,3889798572.03163,300.122772216797,590.487243652344,,,6,,,,32.1933631896973,,,100,,,,,,,,,,,,,,,,,,,,,,300.104614257812,300.138763427734,590.487243652344,590.487243652344,,,7.88582944869995,,1,0,0,0,0.013885498046875,32.2580642700195,1,1,1,300.140930175781,0,2084574944,300.129580688477,,,0.0036104930329287,0.000180145068206791,0.00361074442911271,0.000180145904976438,0.972131311893463,0.974567890167236,32.236701965332,,35,4,200,-0.00188950449228287,-0.147795125842094,0.0309371799230576,1,,,,,,,,,,,,,,,,
,3889798690.34042,300.031997680664,640.499145507812,,,6,,,,32.1933631896973,,,100,,,,,,,,,,,,,,,,,,,,,,300.020263671875,300.042114257812,640.499145507812,640.499145507812,,,7.88582134246826,,1,0,0,0,0.013885498046875,33.2355842590332,1,1,1,300.043731689453,0,2084574944,300.035607910156,,,0.00366649692318123,0.000182943082547682,0.00366676229542804,0.000182943734722188,0.971398413181305,0.973912954330444,32.237964630127,0,35,4,200,-0.0023725728970021,-0.152937650680542,0.028349794447422,1,,,,,,,,,,,,,,,,
,3889798807.00439,300.13737487793,690.425476074219,,,6,,,,32.1933631896973,,,100,,,,,,,,,,,,,,,,,,,,,,300.134094238281,300.152862548828,690.425476074219,690.425476074219,,,7.88926267623901,,1,0,0,0,0.013885498046875,32.2580642700195,1,1,1,300.136505126953,0,2084574912,300.143035888672,,,0.0037096680479272,0.000185100330459959,0.00370996001097446,0.00018510074983858,0.97079336643219,0.973537266254425,32.2403602600098,8.07448759587714E-6,35,4,200,-0.00240446371026337,-0.157134383916855,0.0355457402765751,1,,,,,,,,,,,,,,,,
,3889798925.52978,300.149856567383,740.473999023437,,,6,,,,32.1933631896973,,,100,,,,,,,,,,,,,,,,,,,,,,300.142150878906,300.166534423828,740.473999023437,740.473999023437,,,7.89428424835205,,1,0,0,0,0.0168609619140625,32.2580642700195,1,1,1,300.157562255859,0,2084574976,300.157400512695,,,0.00375421782335559,0.000187331048373457,0.00375453861612828,0.000187331611023261,0.96941202878952,0.972235202789307,32.2421760559082,0,35,4,200,-0.00211642822250724,-0.158759981393814,0.0266546029597521,1,,,,,,,,,,,,,,,,
,3889799043.00982,300.019668579102,790.253723144531,,,6,,,,32.1933631896973,,,100,,,,,,,,,,,,,,,,,,,,,,300.003753662109,300.033508300781,790.253723144531,790.253723144531,,,7.89788007736206,,1,0,0,0,0.013885498046875,32.2580642700195,1,1,1,300.035583496094,0,2084575072,300.025573730469,,,0.0037995964782424,0.000189595213112413,0.00379996460884869,0.000189596302805049,0.969434142112732,0.972574532032013,32.2446899414063,5.2297739982605,35,4,200,-0.00271485233679414,-0.162852749228477,0.0327549763023853,1,,,,,,,,,,,,,,,,
,3889799183.44429,299.932754516602,2500.16625976562,,,6,,,,32.1933631896973,,,100,,,,,,,,,,,,,,,,,,,,,,299.918762207031,299.944946289063,2500.16625976562,2500.16625976562,,,7.90530776977539,,1,0,0,0,0.013885498046875,32.2580642700195,1,1,1,299.946746826172,0,2084574880,299.93720703125,,,0.00421303308194558,0.000210225454587165,0.00421341339124989,0.000210225623295893,0.969400584697723,0.972476363182068,32.2441673278809,0,35,4,200,0.00010332275996916,-0.168551802635193,0.0368714928627014,1,,,,,,,,,,,,,,,,
,3889799323.94354,300.021347045898,5000.17333984375,,,6,,,,32.1933631896973,,,100,,,,,,,,,,,,,,,,,,,,,,299.998657226562,300.048187255859,5000.17333984375,5000.17333984375,,,7.90744256973267,,1,0,0,0,0.013885498046875,32.2580642700195,1,1,1,300.048187255859,0,2084575040,300.030718994141,,,0.00428127803596699,0.000213669610323264,0.00428171685349817,0.000213670536770763,0.963948130607605,0.966778576374054,32.2464981079102,5.67859983444214,35,4,200,0.00138535944279283,-0.167417615652084,0.046974278986454,1,,,,,,,,,,,,,,,,
,3889799465.83054,300.002380371094,7500.486328125,,,6,,,,32.1933631896973,,,100,,,,,,,,,,,,,,,,,,,,,,299.988220214844,300.020782470703,7500.486328125,7500.486328125,,,7.91696357727051,,1,0,0,0,0.013885498046875,31.7693061828613,1,1,1,300.016540527344,0,2084574976,300.011181640625,,,0.00429785181384415,0.000214540344320187,0.00429839071087961,0.000214541112503988,0.958706080913544,0.961764216423035,32.2524909973145,INF,35,4,200,0.00174555578269064,-0.167152151465416,0.0471214652061462,1,,,,,,,,,,,,,,,,
,3889799616.33896,300.28190612793,10000.3349609375,,,6,,,,32.1933631896973,,,100,,,,,,,,,,,,,,,,,,,,,,300.272125244141,300.306640625,10000.3349609375,10000.3349609375,,,7.92307329177856,,1,0,0,0,0.01953125,32.2580642700195,1,1,1,300.291687011719,0,2084575040,300.294509887695,,,0.00430011457245045,0.000214711903634305,0.00430083504749265,0.000214713100204724,0.952563643455505,0.956102788448334,32.2614364624023,2.91485921479762E-5,35,4,200,0.00102157797664404,-0.171500787138939,0.0445720665156841,1,,,,,,,,,,,,,,,,
,3889799769.08073,300.001602172852,35000.296875,,,6,,,,32.1933631896973,,,100,,,,,,,,,,,,,,,,,,,,,,299.988433837891,300.017700195313,35000.296875,35000.296875,,,7.92620372772217,,1,0,0,0,0.013885498046875,32.2580642700195,1,1,1,299.989318847656,0,2084574912,300.006292724609,,,0.00420382812562166,0.000210932342309683,0.00420680485021061,0.000210936018168341,0.890670597553253,0.897103726863861,32.3322067260742,5.68614196777344,35,4,200,0.00141936086583883,-0.161246538162231,0.0672793611884117,1,,,,,,,,,,,,,,,,
,3889799925.4131,300.129318237305,60000.34375,,,6,,,,32.1933631896973,,,100,,,,,,,,,,,,,,,,,,,,,,300.128234863281,300.145660400391,60000.34375,60000.34375,,,7.93191242218018,,1,0,0,0,0.016632080078125,32.2580642700195,1,1,1,300.130401611328,0,2084574752,300.136074829102,,,0.00406333032122524,0.000205957699885943,0.00407095632612351,0.000205965564651829,0.821779251098633,0.832074165344238,32.4169769287109,,35,4,200,0.00174114748369902,-0.153401479125023,0.0858195573091507,1,,,,,,,,,,,,,,,,
,3889800082.37328,300.046081542969,55000.36328125,,,6,,,,32.1933631896973,,,100,,,,,,,,,,,,,,,,,,,,,,300.02734375,300.063659667969,55000.36328125,55000.36328125,,,7.93561410903931,,1,0,0,0,0.013885498046875,32.7468223571777,1,1,1,300.028656005859,0,2084575008,300.050894165039,,,0.00409935041106528,0.000207389101569126,0.00410594007133249,0.000207397271484909,0.832441508769989,0.841805696487427,32.4005432128906,5.69214773178101,35,4,200,-0.00282438355498016,-0.161383509635925,0.0770612508058548,1,,,,,,,,,,,,,,,,
,3889800239.9525,300.097457885742,30000.234375,,,6,,,,32.1933631896973,,,100,,,,,,,,,,,,,,,,,,,,,,300.078857421875,300.1162109375,30000.234375,30000.234375,,,7.93759107589722,,1,0,0,0,0,32.7468223571777,1,1,1,300.079315185547,0,2084574784,300.101760864258,,,0.00423328397340071,0.000212160657759876,0.00423571149971284,0.000212163954020134,0.901887118816376,0.907691895961762,32.3185272216797,5.20674180984497,35,4,200,-0.00341859622858465,-0.171125113964081,0.0575902126729488,1,,,,,,,,,,,,,,,,
,3889800401.82754,300.035018920898,9500.1669921875,,,6,,,,32.1933631896973,,,100,,,,,,,,,,,,,,,,,,,,,,300.028625488281,300.048400878906,9500.1669921875,9500.1669921875,,,7.94199752807617,,1,0,0,0,0,32.7468223571777,1,1,1,300.030822753906,0,2084575072,300.039526367187,,,0.00430224605248814,0.000214806665004079,0.00430289209923247,0.000214807728701265,0.953717052936554,0.956961810588837,32.2578582763672,2.65227827185299E-5,35,4,200,-0.0053173522464931,-0.179597407579422,0.0436493344604969,1,,,,,,,,,,,,,,,,
,3889800541.98546,300.112182617188,7000.3798828125,,,6,,,,32.1933631896973,,,100,,,,,,,,,,,,,,,,,,,,,,300.096099853516,300.133605957031,7000.3798828125,7000.3798828125,,,7.94780540466309,,1,0,0,0,0.013885498046875,32.7468223571777,1,1,1,300.128265380859,0,2084574944,300.122784423828,,,0.00429720969764569,0.000214496743374806,0.00429773549787312,0.000214498200606742,0.960031867027283,0.963031351566315,32.2509651184082,0,35,4,200,-0.00299802841618657,-0.178321808576584,0.0382128469645977,1,,,,,,,,,,,,,,,,
,3889800684.48051,300.088485717773,4500.4208984375,,,6,,,,32.1933631896973,,,100,,,,,,,,,,,,,,,,,,,,,,300.076812744141,300.108642578125,4500.4208984375,4500.4208984375,,,7.9493260383606,,1,0,0,0,0.013885498046875,32.7468223571777,1,1,1,300.100158691406,0,2084574880,300.097497558594,,,0.00427522465674698,0.000213360093941002,0.00427563178645778,0.000213360938716558,0.964930832386017,0.967634558677673,32.2446136474609,0,35,4,200,-0.00282092136330903,-0.1792032122612,0.0403917245566845,1,,,,,,,,,,,,,,,,
,3889800832.43187,300.044494628906,2000.13293457031,,,6,,,,32.1933631896973,,,100,,,,,,,,,,,,,,,,,,,,,,300.040374755859,300.059783935547,2000.13293457031,2000.13293457031,,,7.95937490463257,,1,0,0,0,0.013885498046875,32.7468223571777,1,1,1,300.048614501953,0,2084575040,300.050924682617,,,0.00415570691334924,0.000207361843010791,0.00415600850571261,0.000207362587430416,0.969884216785431,0.972267091274262,32.2379684448242,0.0379876792430878,35,4,200,-0.0024890061467886,-0.172002196311951,0.0339298583567142,1,,,,,,,,,,,,,,,,
,3889800966.77645,300.129028320313,780.219543457031,,,6,,,,32.1933631896973,,,100,,,,,,,,,,,,,,,,,,,,,,300.115386962891,300.145538330078,780.219543457031,780.219543457031,,,7.96088218688965,,1,0,0,0,0,32.7468223571777,1,1,1,300.115234375,0,2084575008,300.134234619141,,,0.00372751976066008,0.000185984265007688,0.0037277319175373,0.000185984743740139,0.972087681293487,0.974106073379517,32.232967376709,0,35,4,200,-0.000332428840920329,-0.153923645615578,0.0293142180889845,1,,,,,,,,,,,,,,,,
,3889801077.5194,300.115585327148,730.1220703125,,,6,,,,32.1933631896973,,,100,,,,,,,,,,,,,,,,,,,,,,300.085998535156,300.144653320313,730.1220703125,730.1220703125,,,7.96081066131592,,1,0,0,0,0.001068115234375,33.2355842590332,1,1,1,300.086517333984,0,2084574912,300.116516113281,,,0.00367867075923812,0.000183550285756552,0.00367885223205646,0.000183550728545498,0.97143965959549,0.973131239414215,32.2301559448242,5.67716073989868,35,4,200,0.00183567253407091,-0.141716316342354,0.041436031460762,1,,,,,,,,,,,,,,,,
,3889801198.10315,300.185470581055,680.159118652344,,,6,,,,32.1933631896973,,,100,,,,,,,,,,,,,,,,,,,,,,300.182556152344,300.203674316406,680.159118652344,680.159118652344,,,7.96099996566772,,1,0,0,0,0.013885498046875,32.7468223571777,1,1,1,300.188385009766,0,2084574976,300.193664550781,,,0.00362910590337478,0.000181073255440563,0.00362929443314593,0.000181073945732813,0.97222113609314,0.974010348320007,32.2306327819824,7.85264455771539E-6,35,4,200,0.00154693203512579,-0.145994111895561,0.0385064817965031,1,,,,,,,,,,,,,,,,
,3889801309.4738,300.043304443359,630.257202148438,,,6,,,,32.1933631896973,,,100,,,,,,,,,,,,,,,,,,,,,,300.025604248047,300.058410644531,630.257202148438,630.257202148438,,,7.96507263183594,,1,0,0,0,0.013885498046875,33.2355842590332,1,1,1,300.061004638672,0,2084574944,300.04748840332,,,0.0035700082257857,0.000178128246899767,0.0035701798323413,0.000178128571449919,0.971492528915405,0.973162472248077,32.2298965454102,0,35,4,200,0.00179377326276153,-0.138502478599548,0.0396354496479034,1,,,,,,,,,,,,,,,,
,3889801426.54609,300.023208618164,580.208679199219,,,6,,,,32.1933631896973,,,100,,,,,,,,,,,,,,,,,,,,,,300.013885498047,300.032318115234,580.208679199219,580.208679199219,,,7.9670524597168,,1,0,0,0,0,33.7243423461914,1,1,1,300.032531738281,0,2084575008,300.026510620117,,,0.00350372160519194,0.000174820485964359,0.00350391543451528,0.000174821038649893,0.971547484397888,0.973442316055298,32.2321586608887,0,35,4,200,0.00180897954851389,-0.139977782964706,0.0403186082839966,1,,,,,,,,,,,,,,,,
,3889801543.52676,300.137924194336,530.331237792969,,,6,,,,32.1933631896973,,,100,,,,,,,,,,,,,,,,,,,,,,300.127716064453,300.153045654297,530.331237792969,530.331237792969,,,7.97184324264526,,1,0,0,0,0,32.2580642700195,1,1,1,300.148132324219,0,2084575040,300.144909667969,,,0.00343135302318978,0.000171207520797563,0.0034315407270579,0.000171208027997856,0.971979200839996,0.973889350891113,32.2320098876953,,35,4,200,0.00160372816026211,-0.134946286678314,0.0368142537772655,1,,,,,,,,,,,,,,,,
,3889801657.21611,300.162582397461,480.30712890625,,,6,,,,32.1933631896973,,,100,,,,,,,,,,,,,,,,,,,,,,300.148315429687,300.181335449219,480.30712890625,480.30712890625,,,7.9755539894104,,1,0,0,0,0.013885498046875,32.2580642700195,1,1,1,300.176849365234,0,2084574976,300.171224975586,,,0.00334191430505004,0.000166748314327532,0.00334211671760449,0.000166748863127422,0.971289813518524,0.973357677459717,32.234016418457,,35,4,200,0.00177402363624424,-0.129994496703148,0.0374832339584827,1,,,,,,,,,,,,,,,,
,3889801774.63591,300.213790893555,430.4296875,,,6,,,,32.1933631896973,,,100,,,,,,,,,,,,,,,,,,,,,,300.203948974609,300.234252929687,430.4296875,430.4296875,,,7.97734117507935,,1,0,0,0,0.013885498046875,32.7468223571777,1,1,1,300.2236328125,0,2084574976,300.223580932617,,,0.00324468441533861,0.000161895421389527,0.0032448688810593,0.000161895977888431,0.97160816192627,0.973554730415344,32.2326240539551,,35,4,200,0.00170600321143866,-0.123620338737965,0.0393955111503601,1,,,,,,,,,,,,,,,,
,3889801892.32607,300.12858581543,380.393371582031,,,6,,,,32.1933631896973,,,100,,,,,,,,,,,,,,,,,,,,,,300.120330810547,300.143096923828,380.393371582031,380.393371582031,,,7.97642230987549,,1,0,0,0,0.013885498046875,32.7468223571777,1,1,1,300.121368408203,0,2084574976,300.133825683594,,,0.00312901541581792,0.000156122311626133,0.00312918573636801,0.000156122844948888,0.972011089324951,0.973895907402039,32.2317390441895,0,35,4,200,0.00167443428654224,-0.118479140102863,0.0385816022753716,1,,,,,,,,,,,,,,,,
,3889802010.45648,300.194808959961,330.357055664063,,,6,,,,32.1933631896973,,,100,,,,,,,,,,,,,,,,,,,,,,300.185485839844,300.214263916016,330.357055664063,330.357055664063,,,7.97598648071289,,1,0,0,0,0.013885498046875,33.2355842590332,1,1,1,300.204132080078,0,2084574944,300.203735351562,,,0.00298671766334377,0.000149022442790645,0.0029868743437256,0.000149022739178602,0.971976220607758,0.973837614059448,32.2315368652344,0,35,4,200,0.00168018776457757,-0.119603052735329,0.030467351898551,1,,,,,,,,,,,,,,,,
,3889802122.03051,300.057540893555,280.284057617187,,,6,,,,32.1933631896973,,,100,,,,,,,,,,,,,,,,,,,,,,300.041229248047,300.071258544922,280.284057617187,280.284057617187,,,7.97490358352661,,1,0,0,0,0.0167083740234375,32.7468223571777,1,1,1,300.073852539063,0,2084575008,300.06201171875,,,0.00281121269518964,0.000140266567263356,0.00281136679742674,0.000140267000575771,0.971747756004333,0.97364068031311,32.2320022583008,0,35,4,200,0.00181950896512717,-0.107422210276127,0.0338989160954952,1,,,,,,,,,,,,,,,,
,3889802247.4228,300.128799438477,230.333312988281,,,6,,,,32.1933631896973,,,10,,,,,,,,,,,,,,,,,,,,,,300.112976074219,300.143127441406,230.333312988281,230.333312988281,,,7.97546768188477,,1,0,0,0,0.0164031982421875,34.2131004333496,1,1,1,300.144622802734,0,2084574976,300.135092163086,,,0.00258441845370805,0.000128948976200059,0.00258456851384627,0.000128949538115298,0.972184419631958,0.974185764789581,32.2327461242676,,35,4,200,0.0165383275598288,-0.966386675834656,0.340957462787628,1,,,,,,,,,,,,,,,,
,3889802358.23229,300.091064453125,180.309204101562,,,6,,,,32.1933631896973,,,10,,,,,,,,,,,,,,,,,,,,,,300.069915771484,300.110076904297,180.309204101562,180.309204101562,,,7.97968196868897,,1,0,0,0,0.015869140625,33.2355842590332,1,1,1,300.112213134766,0,2084574912,300.097579956055,,,0.00226802469690228,0.000113166104169261,0.0022681184134961,0.00011316644206143,0.971085608005524,0.972442150115967,32.2266273498535,0,35,4,200,0.0167515072971582,-0.896675109863281,0.255433559417725,1,,,,,,,,,,,,,,,,
,3889802472.70465,300.164413452148,130.285110473633,,,6,,,,32.1933631896973,,,10,,,,,,,,,,,,,,,,,,,,,,300.162933349609,300.182250976562,130.285110473633,130.285110473633,,,7.98564147949219,,1,0,0,0,0.0148773193359375,32.7468223571777,1,1,1,300.163421630859,0,2084575072,300.172018432617,,,0.00178799895948584,8.92159613732028E-5,0.00178809758746488,8.9216244427302E-5,0.97055172920227,0.972371935844421,32.2320861816406,5.67733097076416,35,4,200,0.0161749962717295,-0.723173201084137,0.234212622046471,1,,,,,,,,,,,,,,,,
,3889802591.46993,300.268508911133,80.2365570068359,,,6,,,,32.1933631896973,,,10,,,,,,,,,,,,,,,,,,,,,,300.26611328125,300.283599853516,80.2365570068359,80.2365570068359,,,7.99312782287598,,1,0,0,0,0.013885498046875,32.2580642700195,1,1,1,300.268218994141,0,2084575168,300.274526977539,,,0.00101340654199289,5.05735574406623E-5,0.0010134728576001,5.0573787911774E-5,0.965884447097778,0.967716157436371,32.235237121582,5.22842836380005,35,4,200,0.0166284572333097,-0.414710342884064,0.171026855707169,1,,,,,,,,,,,,,,,,
,3889802713.20689,300.143249511719,30.3346729278564,,,6,,,,32.1933631896973,,,1,,,,,,,,,,,,,,,,,,,,,,300.136840820313,300.159393310547,30.3346729278564,30.3346729278564,,,7.99508047103882,,1,0,0,0,0.0183868408203125,32.2580642700195,1,1,1,300.138488769531,0,2084575008,300.149267578125,,,-0.000112241659448771,5.66058787782737E-6,-0.000112308783143666,5.66059496126679E-6,0.851828813552856,0.855823040008545,32.3265113830566,4.9437385314377E-6,35,4,200,0.155778840184212,-0.401488095521927,0.708900570869446,1,,,,,,,,,,,,,,,,
,3889802830.53958,300.128555297852,-19.9705295562744,,,6,,,,32.1933631896973,,,10,,,,,,,,,,,,,,,,,,,,,,300.125427246094,300.150451660156,-19.9705295562744,-19.9705295562744,,,7.99421310424805,,1,0,0,0,0.0159454345703125,32.2580642700195,1,1,1,300.131683349609,0,2084574976,300.13909269634,,,-0.00117549337719914,5.86463144973484E-5,-0.00117555983593858,5.86462864611103E-5,0.975211441516876,0.97762793302536,32.2339973449707,0,35,4,200,0.0105797946453094,-4.8832950592041,4.86105918884277,1,,,,,,,,,,,,,,,,
,3889802954.43832,300.260360717773,-70.0068588256836,,,6,,,,32.1933631896973,,,10,,,,,,,,,,,,,,,,,,,,,,300.251159667969,300.280944824219,-70.0068588256836,-70.0068588256836,,,7.99160051345825,,1,0,0,0,0.0148773193359375,31.7693061828613,1,1,1,300.269561767578,0,2084574976,300.270425415039,,,-0.00189524938895202,9.45641620980942E-5,-0.00189542262982383,9.45644239535286E-5,0.971763730049133,0.975097298622131,32.2439994812012,5.2288761138916,35,4,200,0.0158414542675018,-0.162614271044731,0.807337403297424,1,,,,,,,,,,,,,,,,
,3889803076.52125,300.278396606445,-120.018730163574,,,6,,,,32.1933631896973,,,10,,,,,,,,,,,,,,,,,,,,,,300.275512695313,300.297912597656,-120.018730163574,-120.018730163574,,,7.99404621124268,,1,0,0,0,0.016021728515625,32.2580642700195,1,1,1,300.281280517578,0,2084574976,300.287997436523,,,-0.00233549509814174,0.000116526972595161,-0.00233566278345175,0.000116527200449271,0.972811341285706,0.975512504577637,32.2383003234863,5.67787837982178,35,4,200,0.01545025780797,-0.234055712819099,0.952046394348145,1,,,,,,,,,,,,,,,,
,3889803194.284,300.175216674805,-170.079498291016,,,6,,,,32.1933631896973,,,10,,,,,,,,,,,,,,,,,,,,,,300.156585693359,300.194671630859,-170.079498291016,-170.079498291016,,,7.99487257003784,,1,0,0,0,0.013885498046875,32.2580642700195,1,1,1,300.157135009766,0,2084574976,300.181451416016,,,-0.00263500653787281,0.000131470579732079,-0.00263519531099211,0.000131471036028737,0.972860276699066,0.975498557090759,32.2377738952637,0,35,4,200,0.017481492832303,-0.200144290924072,1.12764537334442,1,,,,,,,,,,,,,,,,
,3889803316.70305,300.248352050781,-220.04248046875,,,6,,,,32.1933631896973,,,10,,,,,,,,,,,,,,,,,,,,,,300.245208740234,300.266174316406,-220.04248046875,-220.04248046875,,,7.99800586700439,,1,0,0,0,0.013885498046875,32.2580642700195,1,1,1,300.251495361328,0,2084575072,300.256597900391,,,-0.00284836339533176,0.000142115486501673,-0.00284856409990401,0.000142116099688612,0.972949922084808,0.975515246391296,32.2370910644531,0,35,4,200,0.0163640603423119,-0.275122821331024,1.16043865680695,1,,,,,,,,,,,,,,,,
,3889803430.93336,300.128921508789,-270.188812255859,,,6,,,,32.1933631896973,,,10,,,,,,,,,,,,,,,,,,,,,,300.115295410156,300.149536132812,-270.188812255859,-270.188812255859,,,7.99913311004639,,1,0,0,0,0.013885498046875,32.2580642700195,1,1,1,300.115783691406,0,2084575008,300.136447143555,,,-0.00301653835855251,0.000150511114301114,-0.00301675889975253,0.000150511634515807,0.971796810626984,0.974383234977722,32.2382278442383,0,35,4,200,0.0181208159774542,-0.232405543327332,1.2750551700592,1,,,,,,,,,,,,,,,,
,3889803548.60212,300.155868530273,-320.249572753906,,,6,,,,32.1933631896973,,,10,,,,,,,,,,,,,,,,,,,,,,300.145812988281,300.178680419922,-320.249572753906,-320.249572753906,,,8.00093650817871,,1,0,0,0,0.014801025390625,32.2580642700195,1,1,1,300.165924072266,0,2084575072,300.167031860352,,,-0.00315364444210577,0.000157349512036796,-0.00315388813968326,0.000157350122468374,0.972382187843323,0.975179433822632,32.2394142150879,7.42497604733217E-6,35,4,200,0.0165893752127886,-0.284303814172745,1.29363286495209,1,,,,,,,,,,,,,,,,
,3889803665.22597,300.18701171875,-370.212585449219,,,6,,,,32.1933631896973,,,10,,,,,,,,,,,,,,,,,,,,,,300.173767089844,300.206512451172,-370.212585449219,-370.212585449219,,,8.0012149810791,,1,0,0,0,0.013885498046875,32.2580642700195,1,1,1,300.200256347656,0,2084574880,300.196237182617,,,-0.00326768411088293,0.000163042751846432,-0.00326795317600295,0.000163043072179529,0.971653997898102,0.97464519739151,32.2415657043457,0,35,4,200,0.0164658725261688,-0.25852558016777,1.3729510307312,1,,,,,,,,,,,,,,,,
,3889803782.40148,300.098114013672,-420.273345947266,,,6,,,,32.1933631896973,,,10,,,,,,,,,,,,,,,,,,,,,,300.085601806641,300.111999511719,-420.273345947266,-420.273345947266,,,7.99731302261353,,1,0,0,0,0.013885498046875,31.7693061828613,1,1,1,300.110626220703,0,2084574976,300.104132080078,,,-0.00336534132221487,0.000167913451854185,-0.00336560340272206,0.000167913595409368,0.972075581550598,0.974983096122742,32.2405471801758,0,35,4,200,0.0170096345245838,-0.341390162706375,1.39338624477386,1,,,,,,,,,,,,,,,,
,3889803897.84719,300.160659790039,-470.285217285156,,,6,,,,32.1933631896973,,,10,,,,,,,,,,,,,,,,,,,,,,300.145050048828,300.179534912109,-470.285217285156,-470.285217285156,,,7.99882698059082,,1,0,0,0,0.0150299072265625,31.7693061828613,1,1,1,300.1455078125,0,2084575168,300.166000366211,,,-0.00344900040433523,0.00017209261088449,-0.00344927564789777,0.000172092866161758,0.971052587032318,0.973895668983459,32.2409324645996,0,35,4,200,0.0172145888209343,-0.347490608692169,1.37329864501953,1,,,,,,,,,,,,,,,,
,3889804014.90091,300.161071777344,-520.077087402344,,,6,,,,32.1933631896973,,,10,,,,,,,,,,,,,,,,,,,,,,300.143646240234,300.179077148438,-520.077087402344,-520.077087402344,,,8.00153064727783,,1,0,0,0,0.013885498046875,32.2580642700195,1,1,1,300.144073486328,0,2084574944,300.165069580078,,,-0.00352268474351549,0.000175764303682019,-0.00352293705989818,0.000175764903187497,0.972033321857452,0.974587261676788,32.2377548217773,5.6778302192688,35,4,200,0.0169017892330885,-0.295626133680344,1.46170747280121,1,,,,,,,,,,,,,,,,
,3889804130.7443,300.186874389648,-570.113464355469,,,6,,,,32.1933631896973,,,10,,,,,,,,,,,,,,,,,,,,,,300.174499511719,300.201690673828,-570.113464355469,-570.113464355469,,,8.00468826293945,,1,0,0,0,0,32.7468223571777,1,1,1,300.199249267578,0,2084575136,300.193884277344,,,-0.00358636296044202,0.000178943332288831,-0.00358663898202161,0.000178943243681364,0.971662521362305,0.974539995193481,32.2406845092773,5.67808818817139,35,4,200,0.0208131521940231,-0.312368094921112,1.46093511581421,1,,,,,,,,,,,,,,,,
,3889804247.34505,299.920562744141,-620.125305175781,,,6,,,,32.1933631896973,,,10,,,,,,,,,,,,,,,,,,,,,,299.893859863281,299.946472167969,-620.125305175781,-620.125305175781,,,8.00515842437744,,1,0,0,0,0,32.7468223571777,1,1,1,299.894653320313,0,2084575072,299.921560668945,,,-0.00364029751910814,0.000181631106271403,-0.00364052337864366,0.000181631360102783,0.972321689128876,0.974605441093445,32.2352066040039,0,35,4,200,0.0059191882610321,-0.381316125392914,1.42322659492493,1,,,,,,,,,,,,,,,,
,3889804360.93357,300.094146728516,-670.198303222656,,,6,,,,32.1933631896973,,,10,,,,,,,,,,,,,,,,,,,,,,300.089782714844,300.106384277344,-670.198303222656,-670.198303222656,,,8.00897407531738,,1,0,0,0,0.013885498046875,32.7468223571777,1,1,1,300.098510742188,0,2084574944,300.099160766602,,,-0.00369564042029498,0.000184408928278942,-0.00369599051121482,0.000184409096654926,0.969272196292877,0.972491264343262,32.245433807373,5.22905683517456,35,4,200,0.026707150042057,-0.364600241184235,1.48121702671051,1,,,,,,,,,,,,,,,,
,3889804479.66184,300.186721801758,-720.149047851562,,,6,,,,32.1933631896973,,,10,,,,,,,,,,,,,,,,,,,,,,300.179840087891,300.204040527344,-720.149047851562,-720.149047851562,,,8.00751876831055,,1,0,0,0,0,31.7693061828613,1,1,1,300.193603515625,0,2084575168,300.194409179687,,,-0.00373840360441466,0.000186538907717406,-0.00373873270587392,0.000186538933420718,0.969946026802063,0.973025858402252,32.2437477111816,0,35,4,200,0.0209836736321449,-0.372835397720337,1.47345292568207,1,,,,,,,,,,,,,,,,
,3889804599.16149,300.176132202148,-770.185363769531,,,6,,,,32.1933631896973,,,10,,,,,,,,,,,,,,,,,,,,,,300.145721435547,300.206695556641,-770.185363769531,-770.185363769531,,,8.00348567962647,,1,0,0,0,0.013885498046875,32.2580642700195,1,1,1,300.145568847656,0,2084573184,300.178012084961,,,-0.00378712547355327,0.00018898560903011,-0.00378753985504145,0.000188985841570779,0.967309415340424,0.970802128314972,32.2493057250977,0,35,4,200,0.0274403672665358,-0.350535750389099,1.60096633434296,1,,,,,,,,,,,,,,,,
,3889804727.60175,300.065719604492,-1499.98962402344,,,6,,,,32.1933631896973,,,10,,,,,,,,,,,,,,,,,,,,,,300.060302734375,300.083038330078,-1499.98962402344,-1499.98962402344,,,8.00163841247559,,1,0,0,0,0.0151824951171875,32.2580642700195,1,1,1,300.071136474609,0,2084575040,300.073428344727,,,-0.00408181491933297,0.000203674537244006,-0.00408216596824919,0.000203674644463088,0.969928860664368,0.972917437553406,32.2430458068848,5.22794914245605,35,4,200,0.00958693213760853,-0.400453269481659,1.64364910125732,1,,,,,,,,,,,,,,,,
,3889804847.831,300.229934692383,-4000.37573242188,,,6,,,,32.1933631896973,,,10,,,,,,,,,,,,,,,,,,,,,,300.227355957031,300.253173828125,-4000.37573242188,-4000.37573242188,,,8.00449848175049,,1,0,0,0,0.013885498046875,32.7468223571777,1,1,1,300.232513427734,0,2084574976,300.241314697266,,,-0.00426452275391416,0.000212822558345368,-0.00426494386811089,0.000212822307183203,0.96539568901062,0.968411564826965,32.2469940185547,0,35,4,200,-0.00149587262421846,-0.433602064847946,1.64916014671326,1,,,,,,,,,,,,,,,,
,3889804964.66903,300.004409790039,-6500.4443359375,,,6,,,,32.1933631896973,,,10,,,,,,,,,,,,,,,,,,,,,,300.000305175781,300.01953125,-6500.4443359375,-6500.4443359375,,,8.00835418701172,,1,0,0,0,0.013885498046875,31.7693061828613,1,1,1,300.008514404297,0,2084575040,300.01044921875,,,-0.00429383361482267,0.000214323349623035,-0.00429433527480824,0.000214323437339013,0.96060711145401,0.963677823543549,32.2511940002441,0,35,4,200,-0.00886099692434072,-0.446095794439316,1.69676792621613,1,,,,,,,,,,,,,,,,
,3889805081.51884,300.056594848633,-9000.28125,,,6,,,,32.1933631896973,,,10,,,,,,,,,,,,,,,,,,,,,,300.044799804687,300.071380615234,-9000.28125,-9000.28125,,,8.01115894317627,,1,0,0,0,0.013885498046875,32.7468223571777,1,1,1,300.068389892578,0,2084574944,300.062420654297,,,-0.00430062619434223,0.000214714890746547,-0.00430128562996754,0.000214715311703731,0.954828262329102,0.958306729793549,32.2592239379883,0.508076548576355,35,4,200,-0.0107969092205167,-0.532588362693787,1.62908565998077,1,,,,,,,,,,,,,,,,
,3889805229.7471,300.139572143555,-25000.35546875,,,6,,,,32.1933631896973,,,10,,,,,,,,,,,,,,,,,,,,,,300.120544433594,300.159454345703,-25000.35546875,-25000.35546875,,,8.00727081298828,,1,0,0,0,0,32.7468223571777,1,1,1,300.120391845703,0,2084574688,300.144738769531,,,-0.00425161855056388,0.000212802592057242,-0.00425354338106007,0.000212804167281735,0.916057586669922,0.921503126621246,32.3054275512695,0,35,4,200,-0.0187822338193655,-0.680906176567078,1.52879118919373,1,,,,,,,,,,,,,,,,
,3889805379.34518,300.076766967773,-50000.390625,,,6,,,,32.1933631896973,,,10,,,,,,,,,,,,,,,,,,,,,,300.058898925781,300.095306396484,-50000.390625,-50000.390625,,,8.01358795166016,,1,0,0,0,0.013885498046875,32.2580642700195,1,1,1,300.059356689453,0,2084575008,300.081924438477,,,-0.00412491331419561,0.000208058971277175,-0.00413040500315448,0.000208065533973257,0.850856781005859,0.859642088413239,32.3824272155762,0,35,4,200,-0.0145156150683761,-0.851002395153046,1.53535974025726,1,,,,,,,,,,,,,,,,
,3889805500.68197,299.975570678711,-70000.4140625,,,6,,,,32.1933631896973,,,10,,,,,,,,,,,,,,,,,,,,,,299.968963623047,299.988433837891,-70000.4140625,-70000.4140625,,,8.0154333114624,,1,0,0,0,0.0141143798828125,32.7468223571777,1,1,1,299.972137451172,0,2084574976,299.979629516602,,,-0.00400211630348269,0.000204014636988417,-0.00401249781419318,0.000204026305139619,0.793268501758575,0.805384397506714,32.4545822143555,0,35,4,200,-0.0293024498969316,-1.07769131660461,1.37306916713715,1,,,,,,,,,,,,,,,,